,ts_recv,ts_event,rtype,publisher_id,instrument_id,action,side,depth,price,size,flags,ts_in_delta,sequence,bid_px_00,bid_sz_00,bid_ct_00,ask_px_00,ask_sz_00,ask_ct_00,bid_px_01,bid_sz_01,bid_ct_01,ask_px_01,ask_sz_01,ask_ct_01,bid_px_02,bid_sz_02,bid_ct_02,ask_px_02,ask_sz_02,ask_ct_02,bid_px_03,bid_sz_03,bid_ct_03,ask_px_03,ask_sz_03,ask_ct_03,bid_px_04,bid_sz_04,bid_ct_04,ask_px_04,ask_sz_04,ask_ct_04,bid_px_05,bid_sz_05,bid_ct_05,ask_px_05,ask_sz_05,ask_ct_05,bid_px_06,bid_sz_06,bid_ct_06,ask_px_06,ask_sz_06,ask_ct_06,bid_px_07,bid_sz_07,bid_ct_07,ask_px_07,ask_sz_07,ask_ct_07,bid_px_08,bid_sz_08,bid_ct_08,ask_px_08,ask_sz_08,ask_ct_08,bid_px_09,bid_sz_09,bid_ct_09,ask_px_09,ask_sz_09,ask_ct_09,symbol,order_id
,2025-07-17T16:33:30.604472710Z,2025-07-17T16:33:30.604472710Z,10,2,1108,C,A,9,14.81,100,0,165162,302893497,13.11,100,1,13.95,2,1,12.98,200,2,14.23,200,2,12.9,2,1,14.34,100,1,12.86,100,1,14.35,200,2,12.73,100,1,14.48,1400,2,12.71,100,1,14.49,100,1,12.5,700,1,14.52,100,1,12.46,100,1,14.54,700,1,12.43,700,1,14.68,700,1,12.42,700,1,14.81,100,1,ARL,363613421
,2025-07-17T16:33:30.612356156Z,2025-07-17T16:33:30.612356156Z,10,2,1108,C,A,5,14.49,100,0,165565,302893537,13.11,100,1,13.95,2,1,12.98,200,2,14.23,200,2,12.9,2,1,14.34,100,1,12.86,100,1,14.35,200,2,12.73,100,1,14.48,1400,2,12.71,100,1,14.52,100,1,12.5,700,1,14.54,700,1,12.46,100,1,14.68,700,1,12.43,700,1,14.81,100,1,12.42,700,1,14.96,100,1,ARL,359404829
,2025-07-17T16:33:30.612356156Z,2025-07-17T16:33:30.612356156Z,10,2,1108,A,A,9,14.96,100,130,165565,302893537,13.11,100,1,13.95,2,1,12.98,200,2,14.23,200,2,12.9,2,1,14.34,100,1,12.86,100,1,14.35,200,2,12.73,100,1,14.48,1400,2,12.71,100,1,14.52,100,1,12.5,700,1,14.54,700,1,12.46,100,1,14.68,700,1,12.43,700,1,14.81,100,1,12.42,700,1,14.96,200,2,ARL,364862829
,2025-07-17T16:33:30.817076178Z,2025-07-17T16:33:30.817076178Z,10,2,1108,C,A,2,14.34,100,130,165758,302896626,13.11,100,1,13.95,2,1,12.98,200,2,14.23,200,2,12.9,2,1,14.35,200,2,12.86,100,1,14.48,1400,2,12.73,100,1,14.52,100,1,12.71,100,1,14.54,700,1,12.5,700,1,14.68,700,1,12.46,100,1,14.81,100,1,12.43,700,1,14.96,200,2,12.42,700,1,15.03,100,1,ARL,364850829
,2025-07-17T16:33:30.817425307Z,2025-07-17T16:33:30.817425307Z,10,2,1108,A,A,6,14.6,100,130,165622,302896627,13.11,100,1,13.95,2,1,12.98,200,2,14.23,200,2,12.9,2,1,14.35,200,2,12.86,100,1,14.48,1400,2,12.73,100,1,14.52,100,1,12.71,100,1,14.54,700,1,12.5,700,1,14.6,100,1,12.46,100,1,14.68,700,1,12.43,700,1,14.81,100,1,12.42,700,1,14.96,200,2,ARL,364866209
,2025-07-17T16:33:30.966062395Z,2025-07-17T16:33:30.966062395Z,10,2,1108,A,A,1,13.96,100,130,165270,302898973,13.11,100,1,13.95,2,1,12.98,200,2,13.96,100,1,12.9,2,1,14.23,200,2,12.86,100,1,14.35,200,2,12.73,100,1,14.48,1400,2,12.71,100,1,14.52,100,1,12.5,700,1,14.54,700,1,12.46,100,1,14.6,100,1,12.43,700,1,14.68,700,1,12.42,700,1,14.81,100,1,ARL,364868901
,2025-07-17T16:33:31.084610021Z,2025-07-17T16:33:31.084610021Z,10,2,1108,A,A,5,14.51,100,0,166411,302900128,13.11,100,1,13.95,2,1,12.98,200,2,13.96,100,1,12.9,2,1,14.23,200,2,12.86,100,1,14.35,200,2,12.73,100,1,14.48,1400,2,12.71,100,1,14.51,100,1,12.5,700,1,14.52,100,1,12.46,100,1,14.54,700,1,12.43,700,1,14.6,100,1,12.42,700,1,14.68,700,1,ARL,364870969
,2025-07-17T16:33:31.084610406Z,2025-07-17T16:33:31.084610406Z,10,2,1108,C,A,2,14.23,100,130,166026,302900129,13.11,100,1,13.95,2,1,12.98,200,2,13.96,100,1,12.9,2,1,14.23,100,1,12.86,100,1,14.35,200,2,12.73,100,1,14.48,1400,2,12.71,100,1,14.51,100,1,12.5,700,1,14.52,100,1,12.46,100,1,14.54,700,1,12.43,700,1,14.6,100,1,12.42,700,1,14.68,700,1,ARL,356878397
,2025-07-17T16:33:31.100868523Z,2025-07-17T16:33:31.100868523Z,10,2,1108,C,A,6,14.52,100,0,165315,302900253,13.11,100,1,13.95,2,1,12.98,200,2,13.96,100,1,12.9,2,1,14.23,100,1,12.86,100,1,14.35,200,2,12.73,100,1,14.48,1400,2,12.71,100,1,14.51,100,1,12.5,700,1,14.54,700,1,12.46,100,1,14.6,100,1,12.43,700,1,14.68,700,1,12.42,700,1,14.81,100,1,ARL,364850857
,2025-07-17T16:33:31.100868523Z,2025-07-17T16:33:31.100868523Z,10,2,1108,A,A,9,14.75,100,130,165315,302900253,13.11,100,1,13.95,2,1,12.98,200,2,13.96,100,1,12.9,2,1,14.23,100,1,12.86,100,1,14.35,200,2,12.73,100,1,14.48,1400,2,12.71,100,1,14.51,100,1,12.5,700,1,14.54,700,1,12.46,100,1,14.6,100,1,12.43,700,1,14.68,700,1,12.42,700,1,14.75,100,1,ARL,364871373
,2025-07-17T16:33:44.517994545Z,2025-07-17T16:33:44.517994545Z,10,2,1108,A,A,0,13.43,15,130,166295,303072465,13.11,100,1,13.43,15,1,12.98,200,2,13.95,2,1,12.9,2,1,13.96,100,1,12.86,100,1,14.23,100,1,12.73,100,1,14.35,200,2,12.71,100,1,14.48,1400,2,12.5,700,1,14.51,100,1,12.46,100,1,14.54,700,1,12.43,700,1,14.6,100,1,12.42,700,1,14.68,700,1,ARL,365099977
,2025-07-17T16:33:44.585985363Z,2025-07-17T16:33:44.585985363Z,10,2,1108,C,B,2,12.9,2,0,165333,303074172,13.11,100,1,13.43,15,1,12.98,200,2,13.95,2,1,12.86,100,1,13.96,100,1,12.73,100,1,14.23,100,1,12.71,100,1,14.35,200,2,12.5,700,1,14.48,1400,2,12.46,100,1,14.51,100,1,12.43,700,1,14.54,700,1,12.42,700,1,14.6,100,1,12.37,700,1,14.68,700,1,ARL,357261961
,2025-07-17T16:33:44.585985363Z,2025-07-17T16:33:44.585985363Z,10,2,1108,A,B,1,12.99,2,130,165333,303074172,13.11,100,1,13.43,15,1,12.99,2,1,13.95,2,1,12.98,200,2,13.96,100,1,12.86,100,1,14.23,100,1,12.73,100,1,14.35,200,2,12.71,100,1,14.48,1400,2,12.5,700,1,14.51,100,1,12.46,100,1,14.54,700,1,12.43,700,1,14.6,100,1,12.42,700,1,14.68,700,1,ARL,365101121
,2025-07-17T16:33:54.862565014Z,2025-07-17T16:33:54.862565014Z,10,2,1108,A,A,0,13.41,15,130,165356,303210030,13.11,100,1,13.41,15,1,12.99,2,1,13.43,15,1,12.98,200,2,13.95,2,1,12.86,100,1,13.96,100,1,12.73,100,1,14.23,100,1,12.71,100,1,14.35,200,2,12.5,700,1,14.48,1400,2,12.46,100,1,14.51,100,1,12.43,700,1,14.54,700,1,12.42,700,1,14.6,100,1,ARL,365283485
,2025-07-17T16:33:59.769246037Z,2025-07-17T16:33:59.769246037Z,10,2,1108,C,A,3,13.96,100,0,165501,303268214,13.11,100,1,13.41,15,1,12.99,2,1,13.43,15,1,12.98,200,2,13.95,2,1,12.86,100,1,14.23,100,1,12.73,100,1,14.35,200,2,12.71,100,1,14.48,1400,2,12.5,700,1,14.51,100,1,12.46,100,1,14.54,700,1,12.43,700,1,14.6,100,1,12.42,700,1,14.68,700,1,ARL,364868901
,2025-07-17T16:33:59.769246037Z,2025-07-17T16:33:59.769246037Z,10,2,1108,A,A,2,13.94,100,130,165501,303268214,13.11,100,1,13.41,15,1,12.99,2,1,13.43,15,1,12.98,200,2,13.94,100,1,12.86,100,1,13.95,2,1,12.73,100,1,14.23,100,1,12.71,100,1,14.35,200,2,12.5,700,1,14.48,1400,2,12.46,100,1,14.51,100,1,12.43,700,1,14.54,700,1,12.42,700,1,14.6,100,1,ARL,365359953
,2025-07-17T16:33:59.769531404Z,2025-07-17T16:33:59.769531404Z,10,2,1108,C,A,3,13.95,2,0,165409,303268221,13.11,100,1,13.41,15,1,12.99,2,1,13.43,15,1,12.98,200,2,13.94,100,1,12.86,100,1,14.23,100,1,12.73,100,1,14.35,200,2,12.71,100,1,14.48,1400,2,12.5,700,1,14.51,100,1,12.46,100,1,14.54,700,1,12.43,700,1,14.6,100,1,12.42,700,1,14.68,700,1,ARL,364850881
,2025-07-17T16:33:59.769531404Z,2025-07-17T16:33:59.769531404Z,10,2,1108,A,A,2,13.94,2,130,165409,303268221,13.11,100,1,13.41,15,1,12.99,2,1,13.43,15,1,12.98,200,2,13.94,102,2,12.86,100,1,14.23,100,1,12.73,100,1,14.35,200,2,12.71,100,1,14.48,1400,2,12.5,700,1,14.51,100,1,12.46,100,1,14.54,700,1,12.43,700,1,14.6,100,1,12.42,700,1,14.68,700,1,ARL,365359981
,2025-07-17T16:34:17.588187064Z,2025-07-17T16:34:17.588187064Z,10,2,1108,C,B,1,12.99,2,0,165496,303567720,13.11,100,1,13.41,15,1,12.98,200,2,13.43,15,1,12.86,100,1,13.94,102,2,12.73,100,1,14.23,100,1,12.71,100,1,14.35,200,2,12.5,700,1,14.48,1400,2,12.46,100,1,14.51,100,1,12.43,700,1,14.54,700,1,12.42,700,1,14.6,100,1,12.37,700,1,14.68,700,1,ARL,365101121
,2025-07-17T16:34:17.588187064Z,2025-07-17T16:34:17.588187064Z,10,2,1108,A,B,1,13.07,2,130,165496,303567720,13.11,100,1,13.41,15,1,13.07,2,1,13.43,15,1,12.98,200,2,13.94,102,2,12.86,100,1,14.23,100,1,12.73,100,1,14.35,200,2,12.71,100,1,14.48,1400,2,12.5,700,1,14.51,100,1,12.46,100,1,14.54,700,1,12.43,700,1,14.6,100,1,12.42,700,1,14.68,700,1,ARL,365743281
,2025-07-17T16:34:22.930728013Z,2025-07-17T16:34:22.930728013Z,10,2,1108,C,A,1,13.43,15,130,165255,303633305,13.11,100,1,13.41,15,1,13.07,2,1,13.94,102,2,12.98,200,2,14.23,100,1,12.86,100,1,14.35,200,2,12.73,100,1,14.48,1400,2,12.71,100,1,14.51,100,1,12.5,700,1,14.54,700,1,12.46,100,1,14.6,100,1,12.43,700,1,14.68,700,1,12.42,700,1,14.75,100,1,ARL,365099977
,2025-07-17T16:34:23.935500330Z,2025-07-17T16:34:23.935500330Z,10,2,1108,A,A,0,13.39,15,130,165383,303659749,13.11,100,1,13.39,15,1,13.07,2,1,13.41,15,1,12.98,200,2,13.94,102,2,12.86,100,1,14.23,100,1,12.73,100,1,14.35,200,2,12.71,100,1,14.48,1400,2,12.5,700,1,14.51,100,1,12.46,100,1,14.54,700,1,12.43,700,1,14.6,100,1,12.42,700,1,14.68,700,1,ARL,365868793
,2025-07-17T16:34:24.279370835Z,2025-07-17T16:34:24.279370835Z,10,2,1108,C,A,2,13.94,100,0,166087,303666139,13.11,100,1,13.39,15,1,13.07,2,1,13.41,15,1,12.98,200,2,13.94,2,1,12.86,100,1,14.23,100,1,12.73,100,1,14.35,200,2,12.71,100,1,14.48,1400,2,12.5,700,1,14.51,100,1,12.46,100,1,14.54,700,1,12.43,700,1,14.6,100,1,12.42,700,1,14.68,700,1,ARL,365359953
,2025-07-17T16:34:24.279370835Z,2025-07-17T16:34:24.279370835Z,10,2,1108,A,A,2,13.92,100,130,166087,303666139,13.11,100,1,13.39,15,1,13.07,2,1,13.41,15,1,12.98,200,2,13.92,100,1,12.86,100,1,13.94,2,1,12.73,100,1,14.23,100,1,12.71,100,1,14.35,200,2,12.5,700,1,14.48,1400,2,12.46,100,1,14.51,100,1,12.43,700,1,14.54,700,1,12.42,700,1,14.6,100,1,ARL,365876341
,2025-07-17T16:36:08.787533217Z,2025-07-17T16:36:08.787533217Z,10,2,1108,A,A,2,13.42,100,130,165339,305042754,13.11,100,1,13.39,15,1,13.07,2,1,13.41,15,1,12.98,200,2,13.42,100,1,12.86,100,1,13.92,100,1,12.73,100,1,13.94,2,1,12.71,100,1,14.23,100,1,12.5,700,1,14.35,200,2,12.46,100,1,14.48,1400,2,12.43,700,1,14.51,100,1,12.42,700,1,14.54,700,1,ARL,367721465
,2025-07-17T16:36:08.788277510Z,2025-07-17T16:36:08.788277510Z,10,2,1108,C,A,10,14.6,100,130,165286,305042787,13.11,100,1,13.39,15,1,13.07,2,1,13.41,15,1,12.98,200,2,13.42,100,1,12.86,100,1,13.92,100,1,12.73,100,1,13.94,2,1,12.71,100,1,14.23,100,1,12.5,700,1,14.35,200,2,12.46,100,1,14.48,1400,2,12.43,700,1,14.51,100,1,12.42,700,1,14.54,700,1,ARL,364866209
,2025-07-17T16:36:08.788305174Z,2025-07-17T16:36:08.788305174Z,10,2,1108,A,A,7,14.46,100,128,166535,305042788,13.11,100,1,13.39,15,1,13.07,2,1,13.41,15,1,12.98,200,2,13.42,100,1,12.86,100,1,13.92,100,1,12.73,100,1,13.94,2,1,12.71,100,1,14.23,100,1,12.5,700,1,14.35,200,2,12.46,100,1,14.46,100,1,12.43,700,1,14.48,1400,2,12.42,700,1,14.51,100,1,ARL,367721513
,2025-07-17T16:36:08.788673150Z,2025-07-17T16:36:08.788673150Z,10,2,1108,A,A,5,14.02,100,130,165494,305042798,13.11,100,1,13.39,15,1,13.07,2,1,13.41,15,1,12.98,200,2,13.42,100,1,12.86,100,1,13.92,100,1,12.73,100,1,13.94,2,1,12.71,100,1,14.02,100,1,12.5,700,1,14.23,100,1,12.46,100,1,14.35,200,2,12.43,700,1,14.46,100,1,12.42,700,1,14.48,1400,2,ARL,367721521
,2025-07-17T16:36:08.790998871Z,2025-07-17T16:36:08.790998871Z,10,2,1108,A,A,8,14.36,100,130,165781,305042843,13.11,100,1,13.39,15,1,13.07,2,1,13.41,15,1,12.98,200,2,13.42,100,1,12.86,100,1,13.92,100,1,12.73,100,1,13.94,2,1,12.71,100,1,14.02,100,1,12.5,700,1,14.23,100,1,12.46,100,1,14.35,200,2,12.43,700,1,14.36,100,1,12.42,700,1,14.46,100,1,ARL,367721617
,2025-07-17T16:36:08.813098222Z,2025-07-17T16:36:08.813098222Z,10,2,1108,C,A,6,14.23,100,130,165533,305043109,13.11,100,1,13.39,15,1,13.07,2,1,13.41,15,1,12.98,200,2,13.42,100,1,12.86,100,1,13.92,100,1,12.73,100,1,13.94,2,1,12.71,100,1,14.02,100,1,12.5,700,1,14.35,200,2,12.46,100,1,14.36,100,1,12.43,700,1,14.46,100,1,12.42,700,1,14.48,1400,2,ARL,364851745
,2025-07-17T16:36:08.813150617Z,2025-07-17T16:36:08.813150617Z,10,2,1108,A,A,3,13.69,100,130,165251,305043110,13.11,100,1,13.39,15,1,13.07,2,1,13.41,15,1,12.98,200,2,13.42,100,1,12.86,100,1,13.69,100,1,12.73,100,1,13.92,100,1,12.71,100,1,13.94,2,1,12.5,700,1,14.02,100,1,12.46,100,1,14.35,200,2,12.43,700,1,14.36,100,1,12.42,700,1,14.46,100,1,ARL,367721969
,2025-07-17T16:36:08.861139066Z,2025-07-17T16:36:08.861139066Z,10,2,1108,A,A,8,14.36,100,130,165570,305043519,13.11,100,1,13.39,15,1,13.07,2,1,13.41,15,1,12.98,200,2,13.42,100,1,12.86,100,1,13.69,100,1,12.73,100,1,13.92,100,1,12.71,100,1,13.94,2,1,12.5,700,1,14.02,100,1,12.46,100,1,14.35,200,2,12.43,700,1,14.36,200,2,12.42,700,1,14.46,100,1,ARL,367722697
,2025-07-17T16:36:08.927620800Z,2025-07-17T16:36:08.927620800Z,10,2,1108,A,A,7,14.22,100,130,165526,305044162,13.11,100,1,13.39,15,1,13.07,2,1,13.41,15,1,12.98,200,2,13.42,100,1,12.86,100,1,13.69,100,1,12.73,100,1,13.92,100,1,12.71,100,1,13.94,2,1,12.5,700,1,14.02,100,1,12.46,100,1,14.22,100,1,12.43,700,1,14.35,200,2,12.42,700,1,14.36,200,2,ARL,367724041
,2025-07-17T16:36:08.966685380Z,2025-07-17T16:36:08.966685380Z,10,2,1108,A,A,6,13.95,100,130,165345,305045055,13.11,100,1,13.39,15,1,13.07,2,1,13.41,15,1,12.98,200,2,13.42,100,1,12.86,100,1,13.69,100,1,12.73,100,1,13.92,100,1,12.71,100,1,13.94,2,1,12.5,700,1,13.95,100,1,12.46,100,1,14.02,100,1,12.43,700,1,14.22,100,1,12.42,700,1,14.35,200,2,ARL,367724713
,2025-07-17T16:36:08.984613329Z,2025-07-17T16:36:08.984613329Z,10,2,1108,A,A,8,14.21,100,130,165470,305045290,13.11,100,1,13.39,15,1,13.07,2,1,13.41,15,1,12.98,200,2,13.42,100,1,12.86,100,1,13.69,100,1,12.73,100,1,13.92,100,1,12.71,100,1,13.94,2,1,12.5,700,1,13.95,100,1,12.46,100,1,14.02,100,1,12.43,700,1,14.21,100,1,12.42,700,1,14.22,100,1,ARL,367724841
,2025-07-17T16:36:09.001859949Z,2025-07-17T16:36:09.001859949Z,10,2,1108,C,A,4,13.92,100,0,165541,305045747,13.11,100,1,13.39,15,1,13.07,2,1,13.41,15,1,12.98,200,2,13.42,100,1,12.86,100,1,13.69,100,1,12.73,100,1,13.94,2,1,12.71,100,1,13.95,100,1,12.5,700,1,14.02,100,1,12.46,100,1,14.21,100,1,12.43,700,1,14.22,100,1,12.42,700,1,14.35,200,2,ARL,365876341
,2025-07-17T16:36:09.001859949Z,2025-07-17T16:36:09.001859949Z,10,2,1108,A,A,3,13.43,100,130,165541,305045747,13.11,100,1,13.39,15,1,13.07,2,1,13.41,15,1,12.98,200,2,13.42,100,1,12.86,100,1,13.43,100,1,12.73,100,1,13.69,100,1,12.71,100,1,13.94,2,1,12.5,700,1,13.95,100,1,12.46,100,1,14.02,100,1,12.43,700,1,14.21,100,1,12.42,700,1,14.22,100,1,ARL,367725181
,2025-07-17T16:36:09.186148784Z,2025-07-17T16:36:09.186148784Z,10,2,1108,C,B,1,13.07,2,0,165548,305049492,13.11,100,1,13.39,15,1,12.98,200,2,13.41,15,1,12.86,100,1,13.42,100,1,12.73,100,1,13.43,100,1,12.71,100,1,13.69,100,1,12.5,700,1,13.94,2,1,12.46,100,1,13.95,100,1,12.43,700,1,14.02,100,1,12.42,700,1,14.21,100,1,12.37,700,1,14.22,100,1,ARL,365743281
,2025-07-17T16:36:09.186148784Z,2025-07-17T16:36:09.186148784Z,10,2,1108,A,B,1,12.99,2,130,165548,305049492,13.11,100,1,13.39,15,1,12.99,2,1,13.41,15,1,12.98,200,2,13.42,100,1,12.86,100,1,13.43,100,1,12.73,100,1,13.69,100,1,12.71,100,1,13.94,2,1,12.5,700,1,13.95,100,1,12.46,100,1,14.02,100,1,12.43,700,1,14.21,100,1,12.42,700,1,14.22,100,1,ARL,367731761
,2025-07-17T16:36:15.432181896Z,2025-07-17T16:36:15.432181896Z,10,2,1108,A,A,8,14.16,700,130,165321,305159106,13.11,100,1,13.39,15,1,12.99,2,1,13.41,15,1,12.98,200,2,13.42,100,1,12.86,100,1,13.43,100,1,12.73,100,1,13.69,100,1,12.71,100,1,13.94,2,1,12.5,700,1,13.95,100,1,12.46,100,1,14.02,100,1,12.43,700,1,14.16,700,1,12.42,700,1,14.21,100,1,ARL,367862613
,2025-07-17T16:36:15.789986725Z,2025-07-17T16:36:15.789986725Z,10,2,1108,C,A,5,13.94,2,0,165626,305163657,13.11,100,1,13.39,15,1,12.99,2,1,13.41,15,1,12.98,200,2,13.42,100,1,12.86,100,1,13.43,100,1,12.73,100,1,13.69,100,1,12.71,100,1,13.95,100,1,12.5,700,1,14.02,100,1,12.46,100,1,14.16,700,1,12.43,700,1,14.21,100,1,12.42,700,1,14.22,100,1,ARL,365359981
,2025-07-17T16:36:15.789986725Z,2025-07-17T16:36:15.789986725Z,10,2,1108,A,A,5,13.85,2,130,165626,305163657,13.11,100,1,13.39,15,1,12.99,2,1,13.41,15,1,12.98,200,2,13.42,100,1,12.86,100,1,13.43,100,1,12.73,100,1,13.69,100,1,12.71,100,1,13.85,2,1,12.5,700,1,13.95,100,1,12.46,100,1,14.02,100,1,12.43,700,1,14.16,700,1,12.42,700,1,14.21,100,1,ARL,367868161
,2025-07-17T16:36:25.985698920Z,2025-07-17T16:36:25.985698920Z,10,2,1108,C,A,5,13.85,2,0,165597,305274495,13.11,100,1,13.39,15,1,12.99,2,1,13.41,15,1,12.98,200,2,13.42,100,1,12.86,100,1,13.43,100,1,12.73,100,1,13.69,100,1,12.71,100,1,13.95,100,1,12.5,700,1,14.02,100,1,12.46,100,1,14.16,700,1,12.43,700,1,14.21,100,1,12.42,700,1,14.22,100,1,ARL,367868161
,2025-07-17T16:36:25.985698920Z,2025-07-17T16:36:25.985698920Z,10,2,1108,A,A,5,13.77,2,130,165597,305274495,13.11,100,1,13.39,15,1,12.99,2,1,13.41,15,1,12.98,200,2,13.42,100,1,12.86,100,1,13.43,100,1,12.73,100,1,13.69,100,1,12.71,100,1,13.77,2,1,12.5,700,1,13.95,100,1,12.46,100,1,14.02,100,1,12.43,700,1,14.16,700,1,12.42,700,1,14.21,100,1,ARL,368018937
,2025-07-17T16:37:00.789841841Z,2025-07-17T16:37:00.789841841Z,10,2,1108,C,A,5,13.77,2,0,165610,305798904,13.11,100,1,13.39,15,1,12.99,2,1,13.41,15,1,12.98,200,2,13.42,100,1,12.86,100,1,13.43,100,1,12.73,100,1,13.69,100,1,12.71,100,1,13.95,100,1,12.5,700,1,14.02,100,1,12.46,100,1,14.16,700,1,12.43,700,1,14.21,100,1,12.42,700,1,14.22,100,1,ARL,368018937
,2025-07-17T16:37:00.789841841Z,2025-07-17T16:37:00.789841841Z,10,2,1108,A,A,5,13.7,2,130,165610,305798904,13.11,100,1,13.39,15,1,12.99,2,1,13.41,15,1,12.98,200,2,13.42,100,1,12.86,100,1,13.43,100,1,12.73,100,1,13.69,100,1,12.71,100,1,13.7,2,1,12.5,700,1,13.95,100,1,12.46,100,1,14.02,100,1,12.43,700,1,14.16,700,1,12.42,700,1,14.21,100,1,ARL,368710393
,2025-07-17T16:37:37.386081296Z,2025-07-17T16:37:37.386081296Z,10,2,1108,C,B,1,12.99,2,0,165594,306324624,13.11,100,1,13.39,15,1,12.98,200,2,13.41,15,1,12.86,100,1,13.42,100,1,12.73,100,1,13.43,100,1,12.71,100,1,13.69,100,1,12.5,700,1,13.7,2,1,12.46,100,1,13.95,100,1,12.43,700,1,14.02,100,1,12.42,700,1,14.16,700,1,12.37,700,1,14.21,100,1,ARL,367731761
,2025-07-17T16:37:37.386081296Z,2025-07-17T16:37:37.386081296Z,10,2,1108,A,B,2,12.91,2,130,165594,306324624,13.11,100,1,13.39,15,1,12.98,200,2,13.41,15,1,12.91,2,1,13.42,100,1,12.86,100,1,13.43,100,1,12.73,100,1,13.69,100,1,12.71,100,1,13.7,2,1,12.5,700,1,13.95,100,1,12.46,100,1,14.02,100,1,12.43,700,1,14.16,700,1,12.42,700,1,14.21,100,1,ARL,369392197
,2025-07-17T16:38:28.877439870Z,2025-07-17T16:38:28.877439870Z,10,2,1108,C,A,2,13.42,100,130,165260,307157610,13.11,100,1,13.39,15,1,12.98,200,2,13.41,15,1,12.91,2,1,13.43,100,1,12.86,100,1,13.69,100,1,12.73,100,1,13.7,2,1,12.71,100,1,13.95,100,1,12.5,700,1,14.02,100,1,12.46,100,1,14.16,700,1,12.43,700,1,14.21,100,1,12.42,700,1,14.22,100,1,ARL,367721465
,2025-07-17T16:38:28.883590127Z,2025-07-17T16:38:28.883590127Z,10,2,1108,C,A,0,13.39,15,130,168274,307158368,13.11,100,1,13.41,15,1,12.98,200,2,13.43,100,1,12.91,2,1,13.69,100,1,12.86,100,1,13.7,2,1,12.73,100,1,13.95,100,1,12.71,100,1,14.02,100,1,12.5,700,1,14.16,700,1,12.46,100,1,14.21,100,1,12.43,700,1,14.22,100,1,12.42,700,1,14.35,200,2,ARL,365868793
,2025-07-17T16:38:28.883720539Z,2025-07-17T16:38:28.883720539Z,10,2,1108,C,A,0,13.41,15,130,166583,307158422,13.11,100,1,13.43,100,1,12.98,200,2,13.69,100,1,12.91,2,1,13.7,2,1,12.86,100,1,13.95,100,1,12.73,100,1,14.02,100,1,12.71,100,1,14.16,700,1,12.5,700,1,14.21,100,1,12.46,100,1,14.22,100,1,12.43,700,1,14.35,200,2,12.42,700,1,14.36,200,2,ARL,365283485
,2025-07-17T16:38:28.883766503Z,2025-07-17T16:38:28.883766503Z,10,2,1108,C,A,0,13.43,100,128,168217,307158437,13.11,100,1,13.69,100,1,12.98,200,2,13.7,2,1,12.91,2,1,13.95,100,1,12.86,100,1,14.02,100,1,12.73,100,1,14.16,700,1,12.71,100,1,14.21,100,1,12.5,700,1,14.22,100,1,12.46,100,1,14.35,200,2,12.43,700,1,14.36,200,2,12.42,700,1,14.46,100,1,ARL,367725181
,2025-07-17T16:38:28.884518373Z,2025-07-17T16:38:28.884518373Z,10,2,1108,C,A,3,14.02,100,128,168298,307158750,13.11,100,1,13.69,100,1,12.98,200,2,13.7,2,1,12.91,2,1,13.95,100,1,12.86,100,1,14.16,700,1,12.73,100,1,14.21,100,1,12.71,100,1,14.22,100,1,12.5,700,1,14.35,200,2,12.46,100,1,14.36,200,2,12.43,700,1,14.46,100,1,12.42,700,1,14.48,1400,2,ARL,367721521
,2025-07-17T16:38:28.884800337Z,2025-07-17T16:38:28.884800337Z,10,2,1108,C,A,8,14.46,100,0,169813,307158964,13.11,100,1,13.69,100,1,12.98,200,2,13.7,2,1,12.91,2,1,13.95,100,1,12.86,100,1,14.16,700,1,12.73,100,1,14.21,100,1,12.71,100,1,14.22,100,1,12.5,700,1,14.35,200,2,12.46,100,1,14.36,200,2,12.43,700,1,14.48,1400,2,12.42,700,1,14.54,700,1,ARL,367721513
,2025-07-17T16:38:28.884800337Z,2025-07-17T16:38:28.884800337Z,10,2,1108,A,A,10,14.75,100,128,169813,307158964,13.11,100,1,13.69,100,1,12.98,200,2,13.7,2,1,12.91,2,1,13.95,100,1,12.86,100,1,14.16,700,1,12.73,100,1,14.21,100,1,12.71,100,1,14.22,100,1,12.5,700,1,14.35,200,2,12.46,100,1,14.36,200,2,12.43,700,1,14.48,1400,2,12.42,700,1,14.54,700,1,ARL,370437189
,2025-07-17T16:38:28.884882340Z,2025-07-17T16:38:28.884882340Z,10,2,1108,A,A,6,14.3,100,128,170348,307159022,13.11,100,1,13.69,100,1,12.98,200,2,13.7,2,1,12.91,2,1,13.95,100,1,12.86,100,1,14.16,700,1,12.73,100,1,14.21,100,1,12.71,100,1,14.22,100,1,12.5,700,1,14.3,100,1,12.46,100,1,14.35,200,2,12.43,700,1,14.36,200,2,12.42,700,1,14.48,1400,2,ARL,370437229
,2025-07-17T16:38:28.885058824Z,2025-07-17T16:38:28.885058824Z,10,2,1108,C,A,3,14.16,700,128,169631,307159152,13.11,100,1,13.69,100,1,12.98,200,2,13.7,2,1,12.91,2,1,13.95,100,1,12.86,100,1,14.21,100,1,12.73,100,1,14.22,100,1,12.71,100,1,14.3,100,1,12.5,700,1,14.35,200,2,12.46,100,1,14.36,200,2,12.43,700,1,14.48,1400,2,12.42,700,1,14.54,700,1,ARL,367862613
,2025-07-17T16:38:28.885115892Z,2025-07-17T16:38:28.885115892Z,10,2,1108,A,A,8,14.38,700,128,167659,307159202,13.11,100,1,13.69,100,1,12.98,200,2,13.7,2,1,12.91,2,1,13.95,100,1,12.86,100,1,14.21,100,1,12.73,100,1,14.22,100,1,12.71,100,1,14.3,100,1,12.5,700,1,14.35,200,2,12.46,100,1,14.36,200,2,12.43,700,1,14.38,700,1,12.42,700,1,14.48,1400,2,ARL,370437313
,2025-07-17T16:38:28.887087949Z,2025-07-17T16:38:28.887087949Z,10,2,1108,C,A,3,14.21,100,0,165775,307160536,13.11,100,1,13.69,100,1,12.98,200,2,13.7,2,1,12.91,2,1,13.95,100,1,12.86,100,1,14.22,100,1,12.73,100,1,14.3,100,1,12.71,100,1,14.35,200,2,12.5,700,1,14.36,200,2,12.46,100,1,14.38,700,1,12.43,700,1,14.48,1400,2,12.42,700,1,14.54,700,1,ARL,367724841
,2025-07-17T16:38:28.887087949Z,2025-07-17T16:38:28.887087949Z,10,2,1108,A,A,8,14.48,100,130,165775,307160536,13.11,100,1,13.69,100,1,12.98,200,2,13.7,2,1,12.91,2,1,13.95,100,1,12.86,100,1,14.22,100,1,12.73,100,1,14.3,100,1,12.71,100,1,14.35,200,2,12.5,700,1,14.36,200,2,12.46,100,1,14.38,700,1,12.43,700,1,14.48,1500,3,12.42,700,1,14.54,700,1,ARL,370438201
,2025-07-17T16:38:28.890183678Z,2025-07-17T16:38:28.890183678Z,10,2,1108,C,A,0,13.69,100,130,165688,307160811,13.11,100,1,13.7,2,1,12.98,200,2,13.95,100,1,12.91,2,1,14.22,100,1,12.86,100,1,14.3,100,1,12.73,100,1,14.35,200,2,12.71,100,1,14.36,200,2,12.5,700,1,14.38,700,1,12.46,100,1,14.48,1500,3,12.43,700,1,14.54,700,1,12.42,700,1,14.75,100,1,ARL,367721969
,2025-07-17T16:38:28.890238112Z,2025-07-17T16:38:28.890238112Z,10,2,1108,A,A,2,13.96,100,130,165272,307160812,13.11,100,1,13.7,2,1,12.98,200,2,13.95,100,1,12.91,2,1,13.96,100,1,12.86,100,1,14.22,100,1,12.73,100,1,14.3,100,1,12.71,100,1,14.35,200,2,12.5,700,1,14.36,200,2,12.46,100,1,14.38,700,1,12.43,700,1,14.48,1500,3,12.42,700,1,14.54,700,1,ARL,370438445
,2025-07-17T16:38:28.890779005Z,2025-07-17T16:38:28.890779005Z,10,2,1108,C,A,6,14.36,100,0,165561,307160837,13.11,100,1,13.7,2,1,12.98,200,2,13.95,100,1,12.91,2,1,13.96,100,1,12.86,100,1,14.22,100,1,12.73,100,1,14.3,100,1,12.71,100,1,14.35,200,2,12.5,700,1,14.36,100,1,12.46,100,1,14.38,700,1,12.43,700,1,14.48,1500,3,12.42,700,1,14.54,700,1,ARL,367721617
,2025-07-17T16:38:28.890779005Z,2025-07-17T16:38:28.890779005Z,10,2,1108,A,A,10,14.65,100,130,165561,307160837,13.11,100,1,13.7,2,1,12.98,200,2,13.95,100,1,12.91,2,1,13.96,100,1,12.86,100,1,14.22,100,1,12.73,100,1,14.3,100,1,12.71,100,1,14.35,200,2,12.5,700,1,14.36,100,1,12.46,100,1,14.38,700,1,12.43,700,1,14.48,1500,3,12.42,700,1,14.54,700,1,ARL,370438481
,2025-07-17T16:38:28.891410504Z,2025-07-17T16:38:28.891410504Z,10,2,1108,C,A,7,14.38,700,130,165266,307160861,13.11,100,1,13.7,2,1,12.98,200,2,13.95,100,1,12.91,2,1,13.96,100,1,12.86,100,1,14.22,100,1,12.73,100,1,14.3,100,1,12.71,100,1,14.35,200,2,12.5,700,1,14.36,100,1,12.46,100,1,14.48,1500,3,12.43,700,1,14.54,700,1,12.42,700,1,14.65,100,1,ARL,370437313
,2025-07-17T16:38:28.896958047Z,2025-07-17T16:38:28.896958047Z,10,2,1108,C,A,9,14.65,100,0,165166,307161432,13.11,100,1,13.7,2,1,12.98,200,2,13.95,100,1,12.91,2,1,13.96,100,1,12.86,100,1,14.22,100,1,12.73,100,1,14.3,100,1,12.71,100,1,14.35,200,2,12.5,700,1,14.36,100,1,12.46,100,1,14.48,1500,3,12.43,700,1,14.54,700,1,12.42,700,1,14.75,100,1,ARL,370438481
,2025-07-17T16:38:28.897673510Z,2025-07-17T16:38:28.897673510Z,10,2,1108,C,A,2,13.96,100,130,164971,307161526,13.11,100,1,13.7,2,1,12.98,200,2,13.95,100,1,12.91,2,1,14.22,100,1,12.86,100,1,14.3,100,1,12.73,100,1,14.35,200,2,12.71,100,1,14.36,100,1,12.5,700,1,14.48,1500,3,12.46,100,1,14.54,700,1,12.43,700,1,14.75,100,1,12.42,700,1,14.77,100,1,ARL,370438445
,2025-07-17T16:38:28.897725631Z,2025-07-17T16:38:28.897725631Z,10,2,1108,A,A,2,14.19,100,130,166233,307161541,13.11,100,1,13.7,2,1,12.98,200,2,13.95,100,1,12.91,2,1,14.19,100,1,12.86,100,1,14.22,100,1,12.73,100,1,14.3,100,1,12.71,100,1,14.35,200,2,12.5,700,1,14.36,100,1,12.46,100,1,14.48,1500,3,12.43,700,1,14.54,700,1,12.42,700,1,14.75,100,1,ARL,370439549
,2025-07-17T16:38:28.898589292Z,2025-07-17T16:38:28.898589292Z,10,2,1108,C,A,0,13.7,2,0,165550,307161601,13.11,100,1,13.95,100,1,12.98,200,2,14.19,100,1,12.91,2,1,14.22,100,1,12.86,100,1,14.3,100,1,12.73,100,1,14.35,200,2,12.71,100,1,14.36,100,1,12.5,700,1,14.48,1500,3,12.46,100,1,14.54,700,1,12.43,700,1,14.75,100,1,12.42,700,1,14.77,100,1,ARL,368710393
,2025-07-17T16:38:28.898589292Z,2025-07-17T16:38:28.898589292Z,10,2,1108,A,A,0,13.95,2,130,165550,307161601,13.11,100,1,13.95,102,2,12.98,200,2,14.19,100,1,12.91,2,1,14.22,100,1,12.86,100,1,14.3,100,1,12.73,100,1,14.35,200,2,12.71,100,1,14.36,100,1,12.5,700,1,14.48,1500,3,12.46,100,1,14.54,700,1,12.43,700,1,14.75,100,1,12.42,700,1,14.77,100,1,ARL,370439617
,2025-07-17T16:38:28.918152257Z,2025-07-17T16:38:28.918152257Z,10,2,1108,A,A,1,13.96,100,130,165211,307162629,13.11,100,1,13.95,102,2,12.98,200,2,13.96,100,1,12.91,2,1,14.19,100,1,12.86,100,1,14.22,100,1,12.73,100,1,14.3,100,1,12.71,100,1,14.35,200,2,12.5,700,1,14.36,100,1,12.46,100,1,14.48,1500,3,12.43,700,1,14.54,700,1,12.42,700,1,14.75,100,1,ARL,370441181
,2025-07-17T16:38:28.927205812Z,2025-07-17T16:38:28.927205812Z,10,2,1108,C,A,10,14.77,100,0,165986,307163133,13.11,100,1,13.95,102,2,12.98,200,2,13.96,100,1,12.91,2,1,14.19,100,1,12.86,100,1,14.22,100,1,12.73,100,1,14.3,100,1,12.71,100,1,14.35,200,2,12.5,700,1,14.36,100,1,12.46,100,1,14.48,1500,3,12.43,700,1,14.54,700,1,12.42,700,1,14.75,100,1,ARL,367722305
,2025-07-17T16:38:28.935971160Z,2025-07-17T16:38:28.935971160Z,10,2,1108,C,A,9,14.75,100,0,165736,307163278,13.11,100,1,13.95,102,2,12.98,200,2,13.96,100,1,12.91,2,1,14.19,100,1,12.86,100,1,14.22,100,1,12.73,100,1,14.3,100,1,12.71,100,1,14.35,200,2,12.5,700,1,14.36,100,1,12.46,100,1,14.48,1500,3,12.43,700,1,14.54,700,1,12.42,700,1,14.93,100,1,ARL,370437189
,2025-07-17T16:38:28.935971160Z,2025-07-17T16:38:28.935971160Z,10,2,1108,A,A,10,15.03,100,130,165736,307163278,13.11,100,1,13.95,102,2,12.98,200,2,13.96,100,1,12.91,2,1,14.19,100,1,12.86,100,1,14.22,100,1,12.73,100,1,14.3,100,1,12.71,100,1,14.35,200,2,12.5,700,1,14.36,100,1,12.46,100,1,14.48,1500,3,12.43,700,1,14.54,700,1,12.42,700,1,14.93,100,1,ARL,370442005
,2025-07-17T16:38:28.952516142Z,2025-07-17T16:38:28.952516142Z,10,2,1108,C,A,6,14.36,100,0,165844,307163820,13.11,100,1,13.95,102,2,12.98,200,2,13.96,100,1,12.91,2,1,14.19,100,1,12.86,100,1,14.22,100,1,12.73,100,1,14.3,100,1,12.71,100,1,14.35,200,2,12.5,700,1,14.48,1500,3,12.46,100,1,14.54,700,1,12.43,700,1,14.93,100,1,12.42,700,1,15.03,100,1,ARL,367722697
,2025-07-17T16:38:28.952516142Z,2025-07-17T16:38:28.952516142Z,10,2,1108,A,A,8,14.93,100,130,165844,307163820,13.11,100,1,13.95,102,2,12.98,200,2,13.96,100,1,12.91,2,1,14.19,100,1,12.86,100,1,14.22,100,1,12.73,100,1,14.3,100,1,12.71,100,1,14.35,200,2,12.5,700,1,14.48,1500,3,12.46,100,1,14.54,700,1,12.43,700,1,14.93,200,2,12.42,700,1,15.03,100,1,ARL,370442725
,2025-07-17T16:38:29.032603839Z,2025-07-17T16:38:29.032603839Z,10,2,1108,A,A,8,14.65,700,130,165182,307165797,13.11,100,1,13.95,102,2,12.98,200,2,13.96,100,1,12.91,2,1,14.19,100,1,12.86,100,1,14.22,100,1,12.73,100,1,14.3,100,1,12.71,100,1,14.35,200,2,12.5,700,1,14.48,1500,3,12.46,100,1,14.54,700,1,12.43,700,1,14.65,700,1,12.42,700,1,14.93,200,2,ARL,370445145
,2025-07-17T16:38:29.148648535Z,2025-07-17T16:38:29.148648535Z,10,2,1108,A,A,9,14.78,100,130,165202,307167133,13.11,100,1,13.95,102,2,12.98,200,2,13.96,100,1,12.91,2,1,14.19,100,1,12.86,100,1,14.22,100,1,12.73,100,1,14.3,100,1,12.71,100,1,14.35,200,2,12.5,700,1,14.48,1500,3,12.46,100,1,14.54,700,1,12.43,700,1,14.65,700,1,12.42,700,1,14.78,100,1,ARL,370447077
,2025-07-17T16:38:29.148668992Z,2025-07-17T16:38:29.148668992Z,10,2,1108,C,A,3,14.22,100,130,165361,307167134,13.11,100,1,13.95,102,2,12.98,200,2,13.96,100,1,12.91,2,1,14.19,100,1,12.86,100,1,14.3,100,1,12.73,100,1,14.35,200,2,12.71,100,1,14.48,1500,3,12.5,700,1,14.54,700,1,12.46,100,1,14.65,700,1,12.43,700,1,14.78,100,1,12.42,700,1,14.93,200,2,ARL,367724041
,2025-07-17T16:38:29.426670903Z,2025-07-17T16:38:29.426670903Z,10,2,1108,C,A,3,14.3,100,130,165335,307173923,13.11,100,1,13.95,102,2,12.98,200,2,13.96,100,1,12.91,2,1,14.19,100,1,12.86,100,1,14.35,200,2,12.73,100,1,14.48,1500,3,12.71,100,1,14.54,700,1,12.5,700,1,14.65,700,1,12.46,100,1,14.78,100,1,12.43,700,1,14.93,200,2,12.42,700,1,15.03,100,1,ARL,370437229
,2025-07-17T16:38:29.427022633Z,2025-07-17T16:38:29.427022633Z,10,2,1108,A,A,6,14.57,100,130,165565,307173925,13.11,100,1,13.95,102,2,12.98,200,2,13.96,100,1,12.91,2,1,14.19,100,1,12.86,100,1,14.35,200,2,12.73,100,1,14.48,1500,3,12.71,100,1,14.54,700,1,12.5,700,1,14.57,100,1,12.46,100,1,14.65,700,1,12.43,700,1,14.78,100,1,12.42,700,1,14.93,200,2,ARL,370453877
,2025-07-17T16:38:29.676713920Z,2025-07-17T16:38:29.676713920Z,10,2,1108,C,A,0,13.95,100,130,165437,307176261,13.11,100,1,13.95,2,1,12.98,200,2,13.96,100,1,12.91,2,1,14.19,100,1,12.86,100,1,14.35,200,2,12.73,100,1,14.48,1500,3,12.71,100,1,14.54,700,1,12.5,700,1,14.57,100,1,12.46,100,1,14.65,700,1,12.43,700,1,14.78,100,1,12.42,700,1,14.93,200,2,ARL,367724713
,2025-07-17T16:38:29.676715468Z,2025-07-17T16:38:29.676715468Z,10,2,1108,A,A,5,14.5,100,130,165239,307176262,13.11,100,1,13.95,2,1,12.98,200,2,13.96,100,1,12.91,2,1,14.19,100,1,12.86,100,1,14.35,200,2,12.73,100,1,14.48,1500,3,12.71,100,1,14.5,100,1,12.5,700,1,14.54,700,1,12.46,100,1,14.57,100,1,12.43,700,1,14.65,700,1,12.42,700,1,14.78,100,1,ARL,370456865
,2025-07-17T16:38:29.885137793Z,2025-07-17T16:38:29.885137793Z,10,2,1108,A,A,0,13.45,15,130,165215,307178053,13.11,100,1,13.45,15,1,12.98,200,2,13.95,2,1,12.91,2,1,13.96,100,1,12.86,100,1,14.19,100,1,12.73,100,1,14.35,200,2,12.71,100,1,14.48,1500,3,12.5,700,1,14.5,100,1,12.46,100,1,14.54,700,1,12.43,700,1,14.57,100,1,12.42,700,1,14.65,700,1,ARL,370459453
,2025-07-17T16:38:29.888318043Z,2025-07-17T16:38:29.888318043Z,10,2,1108,C,A,5,14.48,100,130,165289,307178079,13.11,100,1,13.45,15,1,12.98,200,2,13.95,2,1,12.91,2,1,13.96,100,1,12.86,100,1,14.19,100,1,12.73,100,1,14.35,200,2,12.71,100,1,14.48,1400,2,12.5,700,1,14.5,100,1,12.46,100,1,14.54,700,1,12.43,700,1,14.57,100,1,12.42,700,1,14.65,700,1,ARL,370438201
,2025-07-17T16:38:29.888436890Z,2025-07-17T16:38:29.888436890Z,10,2,1108,A,A,10,14.75,100,130,165343,307178084,13.11,100,1,13.45,15,1,12.98,200,2,13.95,2,1,12.91,2,1,13.96,100,1,12.86,100,1,14.19,100,1,12.73,100,1,14.35,200,2,12.71,100,1,14.48,1400,2,12.5,700,1,14.5,100,1,12.46,100,1,14.54,700,1,12.43,700,1,14.57,100,1,12.42,700,1,14.65,700,1,ARL,370459493
,2025-07-17T16:38:29.940849318Z,2025-07-17T16:38:29.940849318Z,10,2,1108,C,A,2,13.96,100,0,165471,307179401,13.11,100,1,13.45,15,1,12.98,200,2,13.95,2,1,12.91,2,1,14.19,100,1,12.86,100,1,14.35,200,2,12.73,100,1,14.48,1400,2,12.71,100,1,14.5,100,1,12.5,700,1,14.54,700,1,12.46,100,1,14.57,100,1,12.43,700,1,14.65,700,1,12.42,700,1,14.75,100,1,ARL,370441181
,2025-07-17T16:38:29.940849318Z,2025-07-17T16:38:29.940849318Z,10,2,1108,A,A,1,13.46,100,130,165471,307179401,13.11,100,1,13.45,15,1,12.98,200,2,13.46,100,1,12.91,2,1,13.95,2,1,12.86,100,1,14.19,100,1,12.73,100,1,14.35,200,2,12.71,100,1,14.48,1400,2,12.5,700,1,14.5,100,1,12.46,100,1,14.54,700,1,12.43,700,1,14.57,100,1,12.42,700,1,14.65,700,1,ARL,370461533
,2025-07-17T16:38:29.941583872Z,2025-07-17T16:38:29.941583872Z,10,2,1108,A,A,6,14.5,100,0,166182,307179436,13.11,100,1,13.45,15,1,12.98,200,2,13.46,100,1,12.91,2,1,13.95,2,1,12.86,100,1,14.19,100,1,12.73,100,1,14.35,200,2,12.71,100,1,14.48,1400,2,12.5,700,1,14.5,200,2,12.46,100,1,14.54,700,1,12.43,700,1,14.57,100,1,12.42,700,1,14.65,700,1,ARL,370461549
,2025-07-17T16:38:29.941584913Z,2025-07-17T16:38:29.941584913Z,10,2,1108,C,A,8,14.57,100,130,165141,307179437,13.11,100,1,13.45,15,1,12.98,200,2,13.46,100,1,12.91,2,1,13.95,2,1,12.86,100,1,14.19,100,1,12.73,100,1,14.35,200,2,12.71,100,1,14.48,1400,2,12.5,700,1,14.5,200,2,12.46,100,1,14.54,700,1,12.43,700,1,14.65,700,1,12.42,700,1,14.75,100,1,ARL,370453877
,2025-07-17T16:38:29.941938640Z,2025-07-17T16:38:29.941938640Z,10,2,1108,A,A,3,14.06,100,130,165354,307179451,13.11,100,1,13.45,15,1,12.98,200,2,13.46,100,1,12.91,2,1,13.95,2,1,12.86,100,1,14.06,100,1,12.73,100,1,14.19,100,1,12.71,100,1,14.35,200,2,12.5,700,1,14.48,1400,2,12.46,100,1,14.5,200,2,12.43,700,1,14.54,700,1,12.42,700,1,14.65,700,1,ARL,370461553
,2025-07-17T16:38:29.942334155Z,2025-07-17T16:38:29.942334155Z,10,2,1108,A,A,6,14.41,100,130,165628,307179459,13.11,100,1,13.45,15,1,12.98,200,2,13.46,100,1,12.91,2,1,13.95,2,1,12.86,100,1,14.06,100,1,12.73,100,1,14.19,100,1,12.71,100,1,14.35,200,2,12.5,700,1,14.41,100,1,12.46,100,1,14.48,1400,2,12.43,700,1,14.5,200,2,12.42,700,1,14.54,700,1,ARL,370461565
,2025-07-17T16:38:29.947290480Z,2025-07-17T16:38:29.947290480Z,10,2,1108,C,A,2,13.95,2,0,165437,307179507,13.11,100,1,13.45,15,1,12.98,200,2,13.46,100,1,12.91,2,1,14.06,100,1,12.86,100,1,14.19,100,1,12.73,100,1,14.35,200,2,12.71,100,1,14.41,100,1,12.5,700,1,14.48,1400,2,12.46,100,1,14.5,200,2,12.43,700,1,14.54,700,1,12.42,700,1,14.65,700,1,ARL,370439617
,2025-07-17T16:38:29.947290480Z,2025-07-17T16:38:29.947290480Z,10,2,1108,A,A,2,13.67,2,130,165437,307179507,13.11,100,1,13.45,15,1,12.98,200,2,13.46,100,1,12.91,2,1,13.67,2,1,12.86,100,1,14.06,100,1,12.73,100,1,14.19,100,1,12.71,100,1,14.35,200,2,12.5,700,1,14.41,100,1,12.46,100,1,14.48,1400,2,12.43,700,1,14.5,200,2,12.42,700,1,14.54,700,1,ARL,370461621
,2025-07-17T16:38:29.947962321Z,2025-07-17T16:38:29.947962321Z,10,2,1108,C,A,4,14.19,100,130,165228,307179509,13.11,100,1,13.45,15,1,12.98,200,2,13.46,100,1,12.91,2,1,13.67,2,1,12.86,100,1,14.06,100,1,12.73,100,1,14.35,200,2,12.71,100,1,14.41,100,1,12.5,700,1,14.48,1400,2,12.46,100,1,14.5,200,2,12.43,700,1,14.54,700,1,12.42,700,1,14.65,700,1,ARL,370439549
,2025-07-17T16:38:29.948015176Z,2025-07-17T16:38:29.948015176Z,10,2,1108,A,A,3,13.73,100,130,165287,307179510,13.11,100,1,13.45,15,1,12.98,200,2,13.46,100,1,12.91,2,1,13.67,2,1,12.86,100,1,13.73,100,1,12.73,100,1,14.06,100,1,12.71,100,1,14.35,200,2,12.5,700,1,14.41,100,1,12.46,100,1,14.48,1400,2,12.43,700,1,14.5,200,2,12.42,700,1,14.54,700,1,ARL,370461625
,2025-07-17T16:38:29.970680913Z,2025-07-17T16:38:29.970680913Z,10,2,1108,A,A,6,14.41,100,130,165368,307179786,13.11,100,1,13.45,15,1,12.98,200,2,13.46,100,1,12.91,2,1,13.67,2,1,12.86,100,1,13.73,100,1,12.73,100,1,14.06,100,1,12.71,100,1,14.35,200,2,12.5,700,1,14.41,200,2,12.46,100,1,14.48,1400,2,12.43,700,1,14.5,200,2,12.42,700,1,14.54,700,1,ARL,370461885
,2025-07-17T16:38:30.253622210Z,2025-07-17T16:38:30.253622210Z,10,2,1108,A,A,5,14.26,100,130,165348,307185663,13.11,100,1,13.45,15,1,12.98,200,2,13.46,100,1,12.91,2,1,13.67,2,1,12.86,100,1,13.73,100,1,12.73,100,1,14.06,100,1,12.71,100,1,14.26,100,1,12.5,700,1,14.35,200,2,12.46,100,1,14.41,200,2,12.43,700,1,14.48,1400,2,12.42,700,1,14.5,200,2,ARL,370467237
,2025-07-17T16:38:30.903985079Z,2025-07-17T16:38:30.903985079Z,10,2,1108,A,A,5,14.25,100,130,165656,307190980,13.11,100,1,13.45,15,1,12.98,200,2,13.46,100,1,12.91,2,1,13.67,2,1,12.86,100,1,13.73,100,1,12.73,100,1,14.06,100,1,12.71,100,1,14.25,100,1,12.5,700,1,14.26,100,1,12.46,100,1,14.35,200,2,12.43,700,1,14.41,200,2,12.42,700,1,14.48,1400,2,ARL,370476497
,2025-07-17T16:38:31.559699014Z,2025-07-17T16:38:31.559699014Z,10,2,1108,C,A,10,14.5,100,130,165178,307199960,13.11,100,1,13.45,15,1,12.98,200,2,13.46,100,1,12.91,2,1,13.67,2,1,12.86,100,1,13.73,100,1,12.73,100,1,14.06,100,1,12.71,100,1,14.25,100,1,12.5,700,1,14.26,100,1,12.46,100,1,14.35,200,2,12.43,700,1,14.41,200,2,12.42,700,1,14.48,1400,2,ARL,370456865
,2025-07-17T16:38:31.559700071Z,2025-07-17T16:38:31.559700071Z,10,2,1108,A,A,4,13.99,100,130,165294,307199961,13.11,100,1,13.45,15,1,12.98,200,2,13.46,100,1,12.91,2,1,13.67,2,1,12.86,100,1,13.73,100,1,12.73,100,1,13.99,100,1,12.71,100,1,14.06,100,1,12.5,700,1,14.25,100,1,12.46,100,1,14.26,100,1,12.43,700,1,14.35,200,2,12.42,700,1,14.41,200,2,ARL,370489233
,2025-07-17T16:38:38.032718859Z,2025-07-17T16:38:38.032718859Z,10,2,1108,A,A,6,14.18,700,130,165380,307265517,13.11,100,1,13.45,15,1,12.98,200,2,13.46,100,1,12.91,2,1,13.67,2,1,12.86,100,1,13.73,100,1,12.73,100,1,13.99,100,1,12.71,100,1,14.06,100,1,12.5,700,1,14.18,700,1,12.46,100,1,14.25,100,1,12.43,700,1,14.26,100,1,12.42,700,1,14.35,200,2,ARL,370582469
,2025-07-17T16:38:40.070887680Z,2025-07-17T16:38:40.070887680Z,10,2,1108,C,A,1,13.46,100,130,165385,307283804,13.11,100,1,13.45,15,1,12.98,200,2,13.67,2,1,12.91,2,1,13.73,100,1,12.86,100,1,13.99,100,1,12.73,100,1,14.06,100,1,12.71,100,1,14.18,700,1,12.5,700,1,14.25,100,1,12.46,100,1,14.26,100,1,12.43,700,1,14.35,200,2,12.42,700,1,14.41,200,2,ARL,370461533
,2025-07-17T16:38:40.071154064Z,2025-07-17T16:38:40.071154064Z,10,2,1108,C,A,5,14.18,700,130,165007,307283810,13.11,100,1,13.45,15,1,12.98,200,2,13.67,2,1,12.91,2,1,13.73,100,1,12.86,100,1,13.99,100,1,12.73,100,1,14.06,100,1,12.71,100,1,14.25,100,1,12.5,700,1,14.26,100,1,12.46,100,1,14.35,200,2,12.43,700,1,14.41,200,2,12.42,700,1,14.48,1400,2,ARL,370582469
,2025-07-17T16:38:40.071198819Z,2025-07-17T16:38:40.071198819Z,10,2,1108,A,A,9,14.42,700,130,165198,307283812,13.11,100,1,13.45,15,1,12.98,200,2,13.67,2,1,12.91,2,1,13.73,100,1,12.86,100,1,13.99,100,1,12.73,100,1,14.06,100,1,12.71,100,1,14.25,100,1,12.5,700,1,14.26,100,1,12.46,100,1,14.35,200,2,12.43,700,1,14.41,200,2,12.42,700,1,14.42,700,1,ARL,370605993
,2025-07-17T16:38:40.071254343Z,2025-07-17T16:38:40.071254343Z,10,2,1108,A,A,0,13.43,15,130,165474,307283813,13.11,100,1,13.43,15,1,12.98,200,2,13.45,15,1,12.91,2,1,13.67,2,1,12.86,100,1,13.73,100,1,12.73,100,1,13.99,100,1,12.71,100,1,14.06,100,1,12.5,700,1,14.25,100,1,12.46,100,1,14.26,100,1,12.43,700,1,14.35,200,2,12.42,700,1,14.41,200,2,ARL,370606001
,2025-07-17T16:38:40.071629854Z,2025-07-17T16:38:40.071629854Z,10,2,1108,C,A,5,14.06,100,130,165102,307283822,13.11,100,1,13.43,15,1,12.98,200,2,13.45,15,1,12.91,2,1,13.67,2,1,12.86,100,1,13.73,100,1,12.73,100,1,13.99,100,1,12.71,100,1,14.25,100,1,12.5,700,1,14.26,100,1,12.46,100,1,14.35,200,2,12.43,700,1,14.41,200,2,12.42,700,1,14.42,700,1,ARL,370461553
,2025-07-17T16:38:40.071973553Z,2025-07-17T16:38:40.071973553Z,10,2,1108,C,A,8,14.41,100,0,165528,307283824,13.11,100,1,13.43,15,1,12.98,200,2,13.45,15,1,12.91,2,1,13.67,2,1,12.86,100,1,13.73,100,1,12.73,100,1,13.99,100,1,12.71,100,1,14.25,100,1,12.5,700,1,14.26,100,1,12.46,100,1,14.35,200,2,12.43,700,1,14.41,100,1,12.42,700,1,14.42,700,1,ARL,370461565
,2025-07-17T16:38:40.071991669Z,2025-07-17T16:38:40.071991669Z,10,2,1108,A,A,7,14.34,100,130,165126,307283825,13.11,100,1,13.43,15,1,12.98,200,2,13.45,15,1,12.91,2,1,13.67,2,1,12.86,100,1,13.73,100,1,12.73,100,1,13.99,100,1,12.71,100,1,14.25,100,1,12.5,700,1,14.26,100,1,12.46,100,1,14.34,100,1,12.43,700,1,14.35,200,2,12.42,700,1,14.41,100,1,ARL,370606029
,2025-07-17T16:38:40.074879393Z,2025-07-17T16:38:40.074879393Z,10,2,1108,C,A,5,14.25,100,130,165587,307283845,13.11,100,1,13.43,15,1,12.98,200,2,13.45,15,1,12.91,2,1,13.67,2,1,12.86,100,1,13.73,100,1,12.73,100,1,13.99,100,1,12.71,100,1,14.26,100,1,12.5,700,1,14.34,100,1,12.46,100,1,14.35,200,2,12.43,700,1,14.41,100,1,12.42,700,1,14.42,700,1,ARL,370476497
,2025-07-17T16:38:40.083823366Z,2025-07-17T16:38:40.083823366Z,10,2,1108,C,A,3,13.73,100,130,165282,307283911,13.11,100,1,13.43,15,1,12.98,200,2,13.45,15,1,12.91,2,1,13.67,2,1,12.86,100,1,13.99,100,1,12.73,100,1,14.26,100,1,12.71,100,1,14.34,100,1,12.5,700,1,14.35,200,2,12.46,100,1,14.41,100,1,12.43,700,1,14.42,700,1,12.42,700,1,14.48,1400,2,ARL,370461625
,2025-07-17T16:38:40.083854409Z,2025-07-17T16:38:40.083854409Z,10,2,1108,C,A,8,14.42,700,130,164837,307283912,13.11,100,1,13.43,15,1,12.98,200,2,13.45,15,1,12.91,2,1,13.67,2,1,12.86,100,1,13.99,100,1,12.73,100,1,14.26,100,1,12.71,100,1,14.34,100,1,12.5,700,1,14.35,200,2,12.46,100,1,14.41,100,1,12.43,700,1,14.48,1400,2,12.42,700,1,14.52,100,1,ARL,370605993
,2025-07-17T16:38:40.083877729Z,2025-07-17T16:38:40.083877729Z,10,2,1108,A,A,4,14.0,100,130,165233,307283913,13.11,100,1,13.43,15,1,12.98,200,2,13.45,15,1,12.91,2,1,13.67,2,1,12.86,100,1,13.99,100,1,12.73,100,1,14.0,100,1,12.71,100,1,14.26,100,1,12.5,700,1,14.34,100,1,12.46,100,1,14.35,200,2,12.43,700,1,14.41,100,1,12.42,700,1,14.48,1400,2,ARL,370606301
,2025-07-17T16:38:40.084817954Z,2025-07-17T16:38:40.084817954Z,10,2,1108,C,A,2,13.67,2,0,165439,307283919,13.11,100,1,13.43,15,1,12.98,200,2,13.45,15,1,12.91,2,1,13.99,100,1,12.86,100,1,14.0,100,1,12.73,100,1,14.26,100,1,12.71,100,1,14.34,100,1,12.5,700,1,14.35,200,2,12.46,100,1,14.41,100,1,12.43,700,1,14.48,1400,2,12.42,700,1,14.52,100,1,ARL,370461621
,2025-07-17T16:38:40.084817954Z,2025-07-17T16:38:40.084817954Z,10,2,1108,A,A,2,13.95,2,130,165439,307283919,13.11,100,1,13.43,15,1,12.98,200,2,13.45,15,1,12.91,2,1,13.95,2,1,12.86,100,1,13.99,100,1,12.73,100,1,14.0,100,1,12.71,100,1,14.26,100,1,12.5,700,1,14.34,100,1,12.46,100,1,14.35,200,2,12.43,700,1,14.41,100,1,12.42,700,1,14.48,1400,2,ARL,370606329
,2025-07-17T16:38:40.091311137Z,2025-07-17T16:38:40.091311137Z,10,2,1108,C,A,8,14.41,100,0,165386,307283939,13.11,100,1,13.43,15,1,12.98,200,2,13.45,15,1,12.91,2,1,13.95,2,1,12.86,100,1,13.99,100,1,12.73,100,1,14.0,100,1,12.71,100,1,14.26,100,1,12.5,700,1,14.34,100,1,12.46,100,1,14.35,200,2,12.43,700,1,14.48,1400,2,12.42,700,1,14.52,100,1,ARL,370461885
,2025-07-17T16:38:40.103890619Z,2025-07-17T16:38:40.103890619Z,10,2,1108,C,A,4,14.0,100,130,165426,307283993,13.11,100,1,13.43,15,1,12.98,200,2,13.45,15,1,12.91,2,1,13.95,2,1,12.86,100,1,13.99,100,1,12.73,100,1,14.26,100,1,12.71,100,1,14.34,100,1,12.5,700,1,14.35,200,2,12.46,100,1,14.48,1400,2,12.43,700,1,14.52,100,1,12.42,700,1,14.54,700,1,ARL,370606301
,2025-07-17T16:38:40.103938254Z,2025-07-17T16:38:40.103938254Z,10,2,1108,A,A,4,14.23,100,130,165166,307283994,13.11,100,1,13.43,15,1,12.98,200,2,13.45,15,1,12.91,2,1,13.95,2,1,12.86,100,1,13.99,100,1,12.73,100,1,14.23,100,1,12.71,100,1,14.26,100,1,12.5,700,1,14.34,100,1,12.46,100,1,14.35,200,2,12.43,700,1,14.48,1400,2,12.42,700,1,14.52,100,1,ARL,370606485
,2025-07-17T16:38:40.619739793Z,2025-07-17T16:38:40.619739793Z,10,2,1108,C,A,5,14.26,100,130,165480,307292058,13.11,100,1,13.43,15,1,12.98,200,2,13.45,15,1,12.91,2,1,13.95,2,1,12.86,100,1,13.99,100,1,12.73,100,1,14.23,100,1,12.71,100,1,14.34,100,1,12.5,700,1,14.35,200,2,12.46,100,1,14.48,1400,2,12.43,700,1,14.52,100,1,12.42,700,1,14.54,700,1,ARL,370467237
,2025-07-17T16:38:40.679449976Z,2025-07-17T16:38:40.679449976Z,10,2,1108,C,A,5,14.34,100,130,165163,307292662,13.11,100,1,13.43,15,1,12.98,200,2,13.45,15,1,12.91,2,1,13.95,2,1,12.86,100,1,13.99,100,1,12.73,100,1,14.23,100,1,12.71,100,1,14.35,200,2,12.5,700,1,14.48,1400,2,12.46,100,1,14.52,100,1,12.43,700,1,14.54,700,1,12.42,700,1,14.68,700,1,ARL,370606029
,2025-07-17T16:38:40.679797676Z,2025-07-17T16:38:40.679797676Z,10,2,1108,A,A,9,14.6,100,130,165383,307292683,13.11,100,1,13.43,15,1,12.98,200,2,13.45,15,1,12.91,2,1,13.95,2,1,12.86,100,1,13.99,100,1,12.73,100,1,14.23,100,1,12.71,100,1,14.35,200,2,12.5,700,1,14.48,1400,2,12.46,100,1,14.52,100,1,12.43,700,1,14.54,700,1,12.42,700,1,14.6,100,1,ARL,370617053
,2025-07-17T16:38:40.980719660Z,2025-07-17T16:38:40.980719660Z,10,2,1108,A,A,8,14.53,100,0,166527,307295303,13.11,100,1,13.43,15,1,12.98,200,2,13.45,15,1,12.91,2,1,13.95,2,1,12.86,100,1,13.99,100,1,12.73,100,1,14.23,100,1,12.71,100,1,14.35,200,2,12.5,700,1,14.48,1400,2,12.46,100,1,14.52,100,1,12.43,700,1,14.53,100,1,12.42,700,1,14.54,700,1,ARL,370619813
,2025-07-17T16:38:40.980720043Z,2025-07-17T16:38:40.980720043Z,10,2,1108,C,A,3,13.99,100,130,166144,307295304,13.11,100,1,13.43,15,1,12.98,200,2,13.45,15,1,12.91,2,1,13.95,2,1,12.86,100,1,14.23,100,1,12.73,100,1,14.35,200,2,12.71,100,1,14.48,1400,2,12.5,700,1,14.52,100,1,12.46,100,1,14.53,100,1,12.43,700,1,14.54,700,1,12.42,700,1,14.6,100,1,ARL,370489233
,2025-07-17T16:38:41.076921744Z,2025-07-17T16:38:41.076921744Z,10,2,1108,C,A,6,14.52,100,0,165600,307296322,13.11,100,1,13.43,15,1,12.98,200,2,13.45,15,1,12.91,2,1,13.95,2,1,12.86,100,1,14.23,100,1,12.73,100,1,14.35,200,2,12.71,100,1,14.48,1400,2,12.5,700,1,14.53,100,1,12.46,100,1,14.54,700,1,12.43,700,1,14.6,100,1,12.42,700,1,14.68,700,1,ARL,370606097
,2025-07-17T16:38:41.076921744Z,2025-07-17T16:38:41.076921744Z,10,2,1108,A,A,10,14.77,100,130,165600,307296322,13.11,100,1,13.43,15,1,12.98,200,2,13.45,15,1,12.91,2,1,13.95,2,1,12.86,100,1,14.23,100,1,12.73,100,1,14.35,200,2,12.71,100,1,14.48,1400,2,12.5,700,1,14.53,100,1,12.46,100,1,14.54,700,1,12.43,700,1,14.6,100,1,12.42,700,1,14.68,700,1,ARL,370622009
,2025-07-17T16:38:42.070895211Z,2025-07-17T16:38:42.070895211Z,10,2,1108,A,A,1,13.44,100,130,165248,307311258,13.11,100,1,13.43,15,1,12.98,200,2,13.44,100,1,12.91,2,1,13.45,15,1,12.86,100,1,13.95,2,1,12.73,100,1,14.23,100,1,12.71,100,1,14.35,200,2,12.5,700,1,14.48,1400,2,12.46,100,1,14.53,100,1,12.43,700,1,14.54,700,1,12.42,700,1,14.6,100,1,ARL,370638733
,2025-07-17T16:38:42.071631589Z,2025-07-17T16:38:42.071631589Z,10,2,1108,C,A,9,14.6,100,130,165511,307311262,13.11,100,1,13.43,15,1,12.98,200,2,13.44,100,1,12.91,2,1,13.45,15,1,12.86,100,1,13.95,2,1,12.73,100,1,14.23,100,1,12.71,100,1,14.35,200,2,12.5,700,1,14.48,1400,2,12.46,100,1,14.53,100,1,12.43,700,1,14.54,700,1,12.42,700,1,14.68,700,1,ARL,370617053
,2025-07-17T16:38:42.071632569Z,2025-07-17T16:38:42.071632569Z,10,2,1108,A,A,6,14.48,100,130,166383,307311263,13.11,100,1,13.43,15,1,12.98,200,2,13.44,100,1,12.91,2,1,13.45,15,1,12.86,100,1,13.95,2,1,12.73,100,1,14.23,100,1,12.71,100,1,14.35,200,2,12.5,700,1,14.48,1500,3,12.46,100,1,14.53,100,1,12.43,700,1,14.54,700,1,12.42,700,1,14.68,700,1,ARL,370638757
,2025-07-17T16:38:42.071984594Z,2025-07-17T16:38:42.071984594Z,10,2,1108,A,A,4,14.04,100,130,165204,307311265,13.11,100,1,13.43,15,1,12.98,200,2,13.44,100,1,12.91,2,1,13.45,15,1,12.86,100,1,13.95,2,1,12.73,100,1,14.04,100,1,12.71,100,1,14.23,100,1,12.5,700,1,14.35,200,2,12.46,100,1,14.48,1500,3,12.43,700,1,14.53,100,1,12.42,700,1,14.54,700,1,ARL,370638761
,2025-07-17T16:38:42.072063883Z,2025-07-17T16:38:42.072063883Z,10,2,1108,A,A,7,14.39,100,130,166104,307311266,13.11,100,1,13.43,15,1,12.98,200,2,13.44,100,1,12.91,2,1,13.45,15,1,12.86,100,1,13.95,2,1,12.73,100,1,14.04,100,1,12.71,100,1,14.23,100,1,12.5,700,1,14.35,200,2,12.46,100,1,14.39,100,1,12.43,700,1,14.48,1500,3,12.42,700,1,14.53,100,1,ARL,370638765
,2025-07-17T16:38:42.074046298Z,2025-07-17T16:38:42.074046298Z,10,2,1108,C,A,3,13.95,2,0,165454,307311292,13.11,100,1,13.43,15,1,12.98,200,2,13.44,100,1,12.91,2,1,13.45,15,1,12.86,100,1,14.04,100,1,12.73,100,1,14.23,100,1,12.71,100,1,14.35,200,2,12.5,700,1,14.39,100,1,12.46,100,1,14.48,1500,3,12.43,700,1,14.53,100,1,12.42,700,1,14.54,700,1,ARL,370606329
,2025-07-17T16:38:42.074046298Z,2025-07-17T16:38:42.074046298Z,10,2,1108,A,A,3,13.71,2,130,165454,307311292,13.11,100,1,13.43,15,1,12.98,200,2,13.44,100,1,12.91,2,1,13.45,15,1,12.86,100,1,13.71,2,1,12.73,100,1,14.04,100,1,12.71,100,1,14.23,100,1,12.5,700,1,14.35,200,2,12.46,100,1,14.39,100,1,12.43,700,1,14.48,1500,3,12.42,700,1,14.53,100,1,ARL,370638805
,2025-07-17T16:38:42.078067093Z,2025-07-17T16:38:42.078067093Z,10,2,1108,C,A,5,14.23,100,130,165131,307311344,13.11,100,1,13.43,15,1,12.98,200,2,13.44,100,1,12.91,2,1,13.45,15,1,12.86,100,1,13.71,2,1,12.73,100,1,14.04,100,1,12.71,100,1,14.35,200,2,12.5,700,1,14.39,100,1,12.46,100,1,14.48,1500,3,12.43,700,1,14.53,100,1,12.42,700,1,14.54,700,1,ARL,370606485
,2025-07-17T16:38:42.078116589Z,2025-07-17T16:38:42.078116589Z,10,2,1108,A,A,3,13.71,100,130,165229,307311345,13.11,100,1,13.43,15,1,12.98,200,2,13.44,100,1,12.91,2,1,13.45,15,1,12.86,100,1,13.71,102,2,12.73,100,1,14.04,100,1,12.71,100,1,14.35,200,2,12.5,700,1,14.39,100,1,12.46,100,1,14.48,1500,3,12.43,700,1,14.53,100,1,12.42,700,1,14.54,700,1,ARL,370638829
,2025-07-17T16:38:42.078400348Z,2025-07-17T16:38:42.078400348Z,10,2,1108,A,A,5,14.23,100,130,165169,307311347,13.11,100,1,13.43,15,1,12.98,200,2,13.44,100,1,12.91,2,1,13.45,15,1,12.86,100,1,13.71,102,2,12.73,100,1,14.04,100,1,12.71,100,1,14.23,100,1,12.5,700,1,14.35,200,2,12.46,100,1,14.39,100,1,12.43,700,1,14.48,1500,3,12.42,700,1,14.53,100,1,ARL,370638833
,2025-07-17T16:38:42.088481675Z,2025-07-17T16:38:42.088481675Z,10,2,1108,A,A,7,14.39,100,130,165360,307311591,13.11,100,1,13.43,15,1,12.98,200,2,13.44,100,1,12.91,2,1,13.45,15,1,12.86,100,1,13.71,102,2,12.73,100,1,14.04,100,1,12.71,100,1,14.23,100,1,12.5,700,1,14.35,200,2,12.46,100,1,14.39,200,2,12.43,700,1,14.48,1500,3,12.42,700,1,14.53,100,1,ARL,370638997
,2025-07-17T16:38:42.253631195Z,2025-07-17T16:38:42.253631195Z,10,2,1108,A,A,6,14.24,100,130,165356,307313171,13.11,100,1,13.43,15,1,12.98,200,2,13.44,100,1,12.91,2,1,13.45,15,1,12.86,100,1,13.71,102,2,12.73,100,1,14.04,100,1,12.71,100,1,14.23,100,1,12.5,700,1,14.24,100,1,12.46,100,1,14.35,200,2,12.43,700,1,14.39,200,2,12.42,700,1,14.48,1500,3,ARL,370641493
,2025-07-17T16:38:42.858701545Z,2025-07-17T16:38:42.858701545Z,10,2,1108,A,A,4,13.97,100,0,166282,307318631,13.11,100,1,13.43,15,1,12.98,200,2,13.44,100,1,12.91,2,1,13.45,15,1,12.86,100,1,13.71,102,2,12.73,100,1,13.97,100,1,12.71,100,1,14.04,100,1,12.5,700,1,14.23,100,1,12.46,100,1,14.24,100,1,12.43,700,1,14.35,200,2,12.42,700,1,14.39,200,2,ARL,370648729
,2025-07-17T16:38:47.232753264Z,2025-07-17T16:38:47.232753264Z,10,2,1108,A,A,6,14.17,700,130,165280,307383998,13.11,100,1,13.43,15,1,12.98,200,2,13.44,100,1,12.91,2,1,13.45,15,1,12.86,100,1,13.71,102,2,12.73,100,1,13.97,100,1,12.71,100,1,14.04,100,1,12.5,700,1,14.17,700,1,12.46,100,1,14.23,100,1,12.43,700,1,14.24,100,1,12.42,700,1,14.35,200,2,ARL,370738933
,2025-07-17T16:39:58.874128495Z,2025-07-17T16:39:58.874128495Z,10,2,1108,C,A,0,13.43,15,130,165028,309108049,13.11,100,1,13.44,100,1,12.98,200,2,13.45,15,1,12.91,2,1,13.71,102,2,12.86,100,1,13.97,100,1,12.73,100,1,14.04,100,1,12.71,100,1,14.17,700,1,12.5,700,1,14.23,100,1,12.46,100,1,14.24,100,1,12.43,700,1,14.35,200,2,12.42,700,1,14.39,200,2,ARL,370606001
,2025-07-17T16:40:01.981419959Z,2025-07-17T16:40:01.981419959Z,10,2,1108,A,A,0,13.42,15,128,166008,309194219,13.11,100,1,13.42,15,1,12.98,200,2,13.44,100,1,12.91,2,1,13.45,15,1,12.86,100,1,13.71,102,2,12.73,100,1,13.97,100,1,12.71,100,1,14.04,100,1,12.5,700,1,14.17,700,1,12.46,100,1,14.23,100,1,12.43,700,1,14.24,100,1,12.42,700,1,14.35,200,2,ARL,372913209
,2025-07-17T16:40:02.086515046Z,2025-07-17T16:40:02.086515046Z,10,2,1108,C,A,1,13.44,100,0,166901,309196660,13.11,100,1,13.42,15,1,12.98,200,2,13.45,15,1,12.91,2,1,13.71,102,2,12.86,100,1,13.97,100,1,12.73,100,1,14.04,100,1,12.71,100,1,14.17,700,1,12.5,700,1,14.23,100,1,12.46,100,1,14.24,100,1,12.43,700,1,14.35,200,2,12.42,700,1,14.39,200,2,ARL,370638733
,2025-07-17T16:40:02.086515046Z,2025-07-17T16:40:02.086515046Z,10,2,1108,A,A,1,13.43,100,130,166901,309196660,13.11,100,1,13.42,15,1,12.98,200,2,13.43,100,1,12.91,2,1,13.45,15,1,12.86,100,1,13.71,102,2,12.73,100,1,13.97,100,1,12.71,100,1,14.04,100,1,12.5,700,1,14.17,700,1,12.46,100,1,14.23,100,1,12.43,700,1,14.24,100,1,12.42,700,1,14.35,200,2,ARL,372916289
,2025-07-17T16:40:24.333742996Z,2025-07-17T16:40:24.333742996Z,10,2,1108,C,A,0,13.42,15,128,173301,309657551,13.11,100,1,13.43,100,1,12.98,200,2,13.45,15,1,12.91,2,1,13.71,102,2,12.86,100,1,13.97,100,1,12.73,100,1,14.04,100,1,12.71,100,1,14.17,700,1,12.5,700,1,14.23,100,1,12.46,100,1,14.24,100,1,12.43,700,1,14.35,200,2,12.42,700,1,14.39,200,2,ARL,372913209
,2025-07-17T16:40:24.333748583Z,2025-07-17T16:40:24.333748583Z,10,2,1108,C,A,1,13.45,15,128,176743,309657561,13.11,100,1,13.43,100,1,12.98,200,2,13.71,102,2,12.91,2,1,13.97,100,1,12.86,100,1,14.04,100,1,12.73,100,1,14.17,700,1,12.71,100,1,14.23,100,1,12.5,700,1,14.24,100,1,12.46,100,1,14.35,200,2,12.43,700,1,14.39,200,2,12.42,700,1,14.48,1500,3,ARL,370459453
,2025-07-17T16:40:27.510832450Z,2025-07-17T16:40:27.510832450Z,10,2,1108,A,A,0,13.43,15,130,165422,309727211,13.11,100,1,13.43,115,2,12.98,200,2,13.71,102,2,12.91,2,1,13.97,100,1,12.86,100,1,14.04,100,1,12.73,100,1,14.17,700,1,12.71,100,1,14.23,100,1,12.5,700,1,14.24,100,1,12.46,100,1,14.35,200,2,12.43,700,1,14.39,200,2,12.42,700,1,14.48,1500,3,ARL,373568805
,2025-07-17T16:40:30.874522389Z,2025-07-17T16:40:30.874522389Z,10,2,1108,C,A,0,13.43,15,130,165310,309772472,13.11,100,1,13.43,100,1,12.98,200,2,13.71,102,2,12.91,2,1,13.97,100,1,12.86,100,1,14.04,100,1,12.73,100,1,14.17,700,1,12.71,100,1,14.23,100,1,12.5,700,1,14.24,100,1,12.46,100,1,14.35,200,2,12.43,700,1,14.39,200,2,12.42,700,1,14.48,1500,3,ARL,373568805
,2025-07-17T16:41:16.989178019Z,2025-07-17T16:41:16.989178019Z,10,2,1108,C,A,1,13.71,2,0,165652,310649827,13.11,100,1,13.43,100,1,12.98,200,2,13.71,100,1,12.91,2,1,13.97,100,1,12.86,100,1,14.04,100,1,12.73,100,1,14.17,700,1,12.71,100,1,14.23,100,1,12.5,700,1,14.24,100,1,12.46,100,1,14.35,200,2,12.43,700,1,14.39,200,2,12.42,700,1,14.48,1500,3,ARL,370638805
,2025-07-17T16:41:16.989178019Z,2025-07-17T16:41:16.989178019Z,10,2,1108,A,A,1,13.64,2,130,165652,310649827,13.11,100,1,13.43,100,1,12.98,200,2,13.64,2,1,12.91,2,1,13.71,100,1,12.86,100,1,13.97,100,1,12.73,100,1,14.04,100,1,12.71,100,1,14.17,700,1,12.5,700,1,14.23,100,1,12.46,100,1,14.24,100,1,12.43,700,1,14.35,200,2,12.42,700,1,14.39,200,2,ARL,374709161
,2025-07-17T16:41:43.138931223Z,2025-07-17T16:41:43.138931223Z,10,2,1108,C,A,0,13.43,100,130,165422,311182878,13.11,100,1,13.64,2,1,12.98,200,2,13.71,100,1,12.91,2,1,13.97,100,1,12.86,100,1,14.04,100,1,12.73,100,1,14.17,700,1,12.71,100,1,14.23,100,1,12.5,700,1,14.24,100,1,12.46,100,1,14.35,200,2,12.43,700,1,14.39,200,2,12.42,700,1,14.48,1500,3,ARL,372916289
,2025-07-17T16:41:43.139202376Z,2025-07-17T16:41:43.139202376Z,10,2,1108,C,A,4,14.17,700,130,165479,311182881,13.11,100,1,13.64,2,1,12.98,200,2,13.71,100,1,12.91,2,1,13.97,100,1,12.86,100,1,14.04,100,1,12.73,100,1,14.23,100,1,12.71,100,1,14.24,100,1,12.5,700,1,14.35,200,2,12.46,100,1,14.39,200,2,12.43,700,1,14.48,1500,3,12.42,700,1,14.54,700,1,ARL,370738933
,2025-07-17T16:41:43.139245098Z,2025-07-17T16:41:43.139245098Z,10,2,1108,A,A,8,14.4,700,130,165571,311182882,13.11,100,1,13.64,2,1,12.98,200,2,13.71,100,1,12.91,2,1,13.97,100,1,12.86,100,1,14.04,100,1,12.73,100,1,14.23,100,1,12.71,100,1,14.24,100,1,12.5,700,1,14.35,200,2,12.46,100,1,14.39,200,2,12.43,700,1,14.4,700,1,12.42,700,1,14.48,1500,3,ARL,375327817
,2025-07-17T16:41:43.139668821Z,2025-07-17T16:41:43.139668821Z,10,2,1108,C,A,3,14.04,100,130,165374,311182892,13.11,100,1,13.64,2,1,12.98,200,2,13.71,100,1,12.91,2,1,13.97,100,1,12.86,100,1,14.23,100,1,12.73,100,1,14.24,100,1,12.71,100,1,14.35,200,2,12.5,700,1,14.39,200,2,12.46,100,1,14.4,700,1,12.43,700,1,14.48,1500,3,12.42,700,1,14.54,700,1,ARL,370638761
,2025-07-17T16:41:43.139683114Z,2025-07-17T16:41:43.139683114Z,10,2,1108,C,A,8,14.48,100,0,165596,311182893,13.11,100,1,13.64,2,1,12.98,200,2,13.71,100,1,12.91,2,1,13.97,100,1,12.86,100,1,14.23,100,1,12.73,100,1,14.24,100,1,12.71,100,1,14.35,200,2,12.5,700,1,14.39,200,2,12.46,100,1,14.4,700,1,12.43,700,1,14.48,1400,2,12.42,700,1,14.54,700,1,ARL,370638757
,2025-07-17T16:41:43.139683114Z,2025-07-17T16:41:43.139683114Z,10,2,1108,A,A,9,14.54,100,130,165596,311182893,13.11,100,1,13.64,2,1,12.98,200,2,13.71,100,1,12.91,2,1,13.97,100,1,12.86,100,1,14.23,100,1,12.73,100,1,14.24,100,1,12.71,100,1,14.35,200,2,12.5,700,1,14.39,200,2,12.46,100,1,14.4,700,1,12.43,700,1,14.48,1400,2,12.42,700,1,14.54,800,2,ARL,375327841
,2025-07-17T16:41:43.139975016Z,2025-07-17T16:41:43.139975016Z,10,2,1108,C,A,6,14.39,100,0,165604,311182897,13.11,100,1,13.64,2,1,12.98,200,2,13.71,100,1,12.91,2,1,13.97,100,1,12.86,100,1,14.23,100,1,12.73,100,1,14.24,100,1,12.71,100,1,14.35,200,2,12.5,700,1,14.39,100,1,12.46,100,1,14.4,700,1,12.43,700,1,14.48,1400,2,12.42,700,1,14.54,800,2,ARL,370638765
,2025-07-17T16:41:43.139975016Z,2025-07-17T16:41:43.139975016Z,10,2,1108,A,A,10,14.67,100,130,165604,311182897,13.11,100,1,13.64,2,1,12.98,200,2,13.71,100,1,12.91,2,1,13.97,100,1,12.86,100,1,14.23,100,1,12.73,100,1,14.24,100,1,12.71,100,1,14.35,200,2,12.5,700,1,14.39,100,1,12.46,100,1,14.4,700,1,12.43,700,1,14.48,1400,2,12.42,700,1,14.54,800,2,ARL,375327849
,2025-07-17T16:41:43.140025431Z,2025-07-17T16:41:43.140025431Z,10,2,1108,A,A,5,14.32,100,130,165422,311182898,13.11,100,1,13.64,2,1,12.98,200,2,13.71,100,1,12.91,2,1,13.97,100,1,12.86,100,1,14.23,100,1,12.73,100,1,14.24,100,1,12.71,100,1,14.32,100,1,12.5,700,1,14.35,200,2,12.46,100,1,14.39,100,1,12.43,700,1,14.4,700,1,12.42,700,1,14.48,1400,2,ARL,375327857
,2025-07-17T16:41:43.143238309Z,2025-07-17T16:41:43.143238309Z,10,2,1108,C,A,7,14.39,100,0,165712,311182938,13.11,100,1,13.64,2,1,12.98,200,2,13.71,100,1,12.91,2,1,13.97,100,1,12.86,100,1,14.23,100,1,12.73,100,1,14.24,100,1,12.71,100,1,14.32,100,1,12.5,700,1,14.35,200,2,12.46,100,1,14.4,700,1,12.43,700,1,14.48,1400,2,12.42,700,1,14.54,800,2,ARL,370638997
,2025-07-17T16:41:43.143238309Z,2025-07-17T16:41:43.143238309Z,10,2,1108,A,A,10,14.67,100,130,165712,311182938,13.11,100,1,13.64,2,1,12.98,200,2,13.71,100,1,12.91,2,1,13.97,100,1,12.86,100,1,14.23,100,1,12.73,100,1,14.24,100,1,12.71,100,1,14.32,100,1,12.5,700,1,14.35,200,2,12.46,100,1,14.4,700,1,12.43,700,1,14.48,1400,2,12.42,700,1,14.54,800,2,ARL,375327925
,2025-07-17T16:41:43.144477498Z,2025-07-17T16:41:43.144477498Z,10,2,1108,C,A,3,14.23,100,0,165721,311182962,13.11,100,1,13.64,2,1,12.98,200,2,13.71,100,1,12.91,2,1,13.97,100,1,12.86,100,1,14.24,100,1,12.73,100,1,14.32,100,1,12.71,100,1,14.35,200,2,12.5,700,1,14.4,700,1,12.46,100,1,14.48,1400,2,12.43,700,1,14.54,800,2,12.42,700,1,14.67,200,2,ARL,370638833
,2025-07-17T16:41:43.144477498Z,2025-07-17T16:41:43.144477498Z,10,2,1108,A,A,8,14.5,100,130,165721,311182962,13.11,100,1,13.64,2,1,12.98,200,2,13.71,100,1,12.91,2,1,13.97,100,1,12.86,100,1,14.24,100,1,12.73,100,1,14.32,100,1,12.71,100,1,14.35,200,2,12.5,700,1,14.4,700,1,12.46,100,1,14.48,1400,2,12.43,700,1,14.5,100,1,12.42,700,1,14.54,800,2,ARL,375327933
,2025-07-17T16:41:43.156111360Z,2025-07-17T16:41:43.156111360Z,10,2,1108,C,A,1,13.71,100,130,165467,311183103,13.11,100,1,13.64,2,1,12.98,200,2,13.97,100,1,12.91,2,1,14.24,100,1,12.86,100,1,14.32,100,1,12.73,100,1,14.35,200,2,12.71,100,1,14.4,700,1,12.5,700,1,14.48,1400,2,12.46,100,1,14.5,100,1,12.43,700,1,14.54,800,2,12.42,700,1,14.67,200,2,ARL,370638829
,2025-07-17T16:41:43.156143472Z,2025-07-17T16:41:43.156143472Z,10,2,1108,C,A,5,14.4,700,130,165731,311183104,13.11,100,1,13.64,2,1,12.98,200,2,13.97,100,1,12.91,2,1,14.24,100,1,12.86,100,1,14.32,100,1,12.73,100,1,14.35,200,2,12.71,100,1,14.48,1400,2,12.5,700,1,14.5,100,1,12.46,100,1,14.54,800,2,12.43,700,1,14.67,200,2,12.42,700,1,15.09,200,2,ARL,375327817
,2025-07-17T16:41:43.156160068Z,2025-07-17T16:41:43.156160068Z,10,2,1108,A,A,2,13.98,100,130,165475,311183105,13.11,100,1,13.64,2,1,12.98,200,2,13.97,100,1,12.91,2,1,13.98,100,1,12.86,100,1,14.24,100,1,12.73,100,1,14.32,100,1,12.71,100,1,14.35,200,2,12.5,700,1,14.48,1400,2,12.46,100,1,14.5,100,1,12.43,700,1,14.54,800,2,12.42,700,1,14.67,200,2,ARL,375328129
,2025-07-17T16:41:43.158515465Z,2025-07-17T16:41:43.158515465Z,10,2,1108,C,A,9,14.67,100,0,165406,311183123,13.11,100,1,13.64,2,1,12.98,200,2,13.97,100,1,12.91,2,1,13.98,100,1,12.86,100,1,14.24,100,1,12.73,100,1,14.32,100,1,12.71,100,1,14.35,200,2,12.5,700,1,14.48,1400,2,12.46,100,1,14.5,100,1,12.43,700,1,14.54,800,2,12.42,700,1,14.67,100,1,ARL,375327849
,2025-07-17T16:41:43.158515465Z,2025-07-17T16:41:43.158515465Z,10,2,1108,A,A,10,14.95,100,130,165406,311183123,13.11,100,1,13.64,2,1,12.98,200,2,13.97,100,1,12.91,2,1,13.98,100,1,12.86,100,1,14.24,100,1,12.73,100,1,14.32,100,1,12.71,100,1,14.35,200,2,12.5,700,1,14.48,1400,2,12.46,100,1,14.5,100,1,12.43,700,1,14.54,800,2,12.42,700,1,14.67,100,1,ARL,375328181
,2025-07-17T16:41:43.162246276Z,2025-07-17T16:41:43.162246276Z,10,2,1108,C,A,0,13.64,2,0,165711,311183140,13.11,100,1,13.97,100,1,12.98,200,2,13.98,100,1,12.91,2,1,14.24,100,1,12.86,100,1,14.32,100,1,12.73,100,1,14.35,200,2,12.71,100,1,14.48,1400,2,12.5,700,1,14.5,100,1,12.46,100,1,14.54,800,2,12.43,700,1,14.67,100,1,12.42,700,1,14.95,100,1,ARL,374709161
,2025-07-17T16:41:43.162246276Z,2025-07-17T16:41:43.162246276Z,10,2,1108,A,A,0,13.97,2,130,165711,311183140,13.11,100,1,13.97,102,2,12.98,200,2,13.98,100,1,12.91,2,1,14.24,100,1,12.86,100,1,14.32,100,1,12.73,100,1,14.35,200,2,12.71,100,1,14.48,1400,2,12.5,700,1,14.5,100,1,12.46,100,1,14.54,800,2,12.43,700,1,14.67,100,1,12.42,700,1,14.95,100,1,ARL,375328205
,2025-07-17T16:41:43.170391935Z,2025-07-17T16:41:43.170391935Z,10,2,1108,C,A,8,14.67,100,0,165424,311183283,13.11,100,1,13.97,102,2,12.98,200,2,13.98,100,1,12.91,2,1,14.24,100,1,12.86,100,1,14.32,100,1,12.73,100,1,14.35,200,2,12.71,100,1,14.48,1400,2,12.5,700,1,14.5,100,1,12.46,100,1,14.54,800,2,12.43,700,1,14.95,100,1,12.42,700,1,15.09,200,2,ARL,375327925
,2025-07-17T16:41:43.170391935Z,2025-07-17T16:41:43.170391935Z,10,2,1108,A,A,8,14.95,100,130,165424,311183283,13.11,100,1,13.97,102,2,12.98,200,2,13.98,100,1,12.91,2,1,14.24,100,1,12.86,100,1,14.32,100,1,12.73,100,1,14.35,200,2,12.71,100,1,14.48,1400,2,12.5,700,1,14.5,100,1,12.46,100,1,14.54,800,2,12.43,700,1,14.95,200,2,12.42,700,1,15.09,200,2,ARL,375328333
,2025-07-17T16:41:43.171482095Z,2025-07-17T16:41:43.171482095Z,10,2,1108,C,A,1,13.98,100,130,165582,311183345,13.11,100,1,13.97,102,2,12.98,200,2,14.24,100,1,12.91,2,1,14.32,100,1,12.86,100,1,14.35,200,2,12.73,100,1,14.48,1400,2,12.71,100,1,14.5,100,1,12.5,700,1,14.54,800,2,12.46,100,1,14.95,200,2,12.43,700,1,15.09,200,2,12.42,700,1,15.3,100,1,ARL,375328129
,2025-07-17T16:41:43.171531790Z,2025-07-17T16:41:43.171531790Z,10,2,1108,A,A,1,14.21,100,130,165282,311183361,13.11,100,1,13.97,102,2,12.98,200,2,14.21,100,1,12.91,2,1,14.24,100,1,12.86,100,1,14.32,100,1,12.73,100,1,14.35,200,2,12.71,100,1,14.48,1400,2,12.5,700,1,14.5,100,1,12.46,100,1,14.54,800,2,12.43,700,1,14.95,200,2,12.42,700,1,15.09,200,2,ARL,375328497
,2025-07-17T16:41:43.189819838Z,2025-07-17T16:41:43.189819838Z,10,2,1108,C,A,7,14.54,100,0,165529,311183848,13.11,100,1,13.97,102,2,12.98,200,2,14.21,100,1,12.91,2,1,14.24,100,1,12.86,100,1,14.32,100,1,12.73,100,1,14.35,200,2,12.71,100,1,14.48,1400,2,12.5,700,1,14.5,100,1,12.46,100,1,14.54,700,1,12.43,700,1,14.95,200,2,12.42,700,1,15.09,200,2,ARL,375327841
,2025-07-17T16:41:43.189819838Z,2025-07-17T16:41:43.189819838Z,10,2,1108,A,A,9,15.05,100,130,165529,311183848,13.11,100,1,13.97,102,2,12.98,200,2,14.21,100,1,12.91,2,1,14.24,100,1,12.86,100,1,14.32,100,1,12.73,100,1,14.35,200,2,12.71,100,1,14.48,1400,2,12.5,700,1,14.5,100,1,12.46,100,1,14.54,700,1,12.43,700,1,14.95,200,2,12.42,700,1,15.05,100,1,ARL,375329021
,2025-07-17T16:41:43.209078680Z,2025-07-17T16:41:43.209078680Z,10,2,1108,C,A,0,13.97,100,130,165725,311184224,13.11,100,1,13.97,2,1,12.98,200,2,14.21,100,1,12.91,2,1,14.24,100,1,12.86,100,1,14.32,100,1,12.73,100,1,14.35,200,2,12.71,100,1,14.48,1400,2,12.5,700,1,14.5,100,1,12.46,100,1,14.54,700,1,12.43,700,1,14.95,200,2,12.42,700,1,15.05,100,1,ARL,370648729
,2025-07-17T16:41:43.209079728Z,2025-07-17T16:41:43.209079728Z,10,2,1108,A,A,3,14.26,100,130,165443,311184225,13.11,100,1,13.97,2,1,12.98,200,2,14.21,100,1,12.91,2,1,14.24,100,1,12.86,100,1,14.26,100,1,12.73,100,1,14.32,100,1,12.71,100,1,14.35,200,2,12.5,700,1,14.48,1400,2,12.46,100,1,14.5,100,1,12.43,700,1,14.54,700,1,12.42,700,1,14.95,200,2,ARL,375329381
,2025-07-17T16:41:43.209117671Z,2025-07-17T16:41:43.209117671Z,10,2,1108,A,A,9,14.67,700,130,165343,311184226,13.11,100,1,13.97,2,1,12.98,200,2,14.21,100,1,12.91,2,1,14.24,100,1,12.86,100,1,14.26,100,1,12.73,100,1,14.32,100,1,12.71,100,1,14.35,200,2,12.5,700,1,14.48,1400,2,12.46,100,1,14.5,100,1,12.43,700,1,14.54,700,1,12.42,700,1,14.67,700,1,ARL,375329385
,2025-07-17T16:41:43.490705448Z,2025-07-17T16:41:43.490705448Z,10,2,1108,A,A,10,14.81,100,130,165463,311188689,13.11,100,1,13.97,2,1,12.98,200,2,14.21,100,1,12.91,2,1,14.24,100,1,12.86,100,1,14.26,100,1,12.73,100,1,14.32,100,1,12.71,100,1,14.35,200,2,12.5,700,1,14.48,1400,2,12.46,100,1,14.5,100,1,12.43,700,1,14.54,700,1,12.42,700,1,14.67,700,1,ARL,375334157
,2025-07-17T16:41:43.490718665Z,2025-07-17T16:41:43.490718665Z,10,2,1108,C,A,2,14.24,100,130,165446,311188690,13.11,100,1,13.97,2,1,12.98,200,2,14.21,100,1,12.91,2,1,14.26,100,1,12.86,100,1,14.32,100,1,12.73,100,1,14.35,200,2,12.71,100,1,14.48,1400,2,12.5,700,1,14.5,100,1,12.46,100,1,14.54,700,1,12.43,700,1,14.67,700,1,12.42,700,1,14.81,100,1,ARL,370641493
,2025-07-17T16:41:43.752453166Z,2025-07-17T16:41:43.752453166Z,10,2,1108,C,A,3,14.32,100,130,165059,311195553,13.11,100,1,13.97,2,1,12.98,200,2,14.21,100,1,12.91,2,1,14.26,100,1,12.86,100,1,14.35,200,2,12.73,100,1,14.48,1400,2,12.71,100,1,14.5,100,1,12.5,700,1,14.54,700,1,12.46,100,1,14.67,700,1,12.43,700,1,14.81,100,1,12.42,700,1,14.95,200,2,ARL,375327857
,2025-07-17T16:41:43.752800607Z,2025-07-17T16:41:43.752800607Z,10,2,1108,A,A,7,14.6,100,130,165517,311195557,13.11,100,1,13.97,2,1,12.98,200,2,14.21,100,1,12.91,2,1,14.26,100,1,12.86,100,1,14.35,200,2,12.73,100,1,14.48,1400,2,12.71,100,1,14.5,100,1,12.5,700,1,14.54,700,1,12.46,100,1,14.6,100,1,12.43,700,1,14.67,700,1,12.42,700,1,14.81,100,1,ARL,375342121
,2025-07-17T16:41:43.860518846Z,2025-07-17T16:41:43.860518846Z,10,2,1108,A,A,1,13.98,100,130,165440,311202685,13.11,100,1,13.97,2,1,12.98,200,2,13.98,100,1,12.91,2,1,14.21,100,1,12.86,100,1,14.26,100,1,12.73,100,1,14.35,200,2,12.71,100,1,14.48,1400,2,12.5,700,1,14.5,100,1,12.46,100,1,14.54,700,1,12.43,700,1,14.6,100,1,12.42,700,1,14.67,700,1,ARL,375348505
,2025-07-17T16:41:44.145986128Z,2025-07-17T16:41:44.145986128Z,10,2,1108,C,A,6,14.5,100,130,165573,311210358,13.11,100,1,13.97,2,1,12.98,200,2,13.98,100,1,12.91,2,1,14.21,100,1,12.86,100,1,14.26,100,1,12.73,100,1,14.35,200,2,12.71,100,1,14.48,1400,2,12.5,700,1,14.54,700,1,12.46,100,1,14.6,100,1,12.43,700,1,14.67,700,1,12.42,700,1,14.81,100,1,ARL,375327933
,2025-07-17T16:41:44.146116212Z,2025-07-17T16:41:44.146116212Z,10,2,1108,A,A,9,14.77,100,130,165473,311210359,13.11,100,1,13.97,2,1,12.98,200,2,13.98,100,1,12.91,2,1,14.21,100,1,12.86,100,1,14.26,100,1,12.73,100,1,14.35,200,2,12.71,100,1,14.48,1400,2,12.5,700,1,14.54,700,1,12.46,100,1,14.6,100,1,12.43,700,1,14.67,700,1,12.42,700,1,14.77,100,1,ARL,375358061
,2025-07-17T16:41:53.592475714Z,2025-07-17T16:41:53.592475714Z,10,2,1108,C,B,2,12.91,2,0,165712,311376251,13.11,100,1,13.97,2,1,12.98,200,2,13.98,100,1,12.86,100,1,14.21,100,1,12.73,100,1,14.26,100,1,12.71,100,1,14.35,200,2,12.5,700,1,14.48,1400,2,12.46,100,1,14.54,700,1,12.43,700,1,14.6,100,1,12.42,700,1,14.67,700,1,12.37,700,1,14.77,100,1,ARL,369392197
,2025-07-17T16:41:53.592475714Z,2025-07-17T16:41:53.592475714Z,10,2,1108,A,B,1,12.99,2,130,165712,311376251,13.11,100,1,13.97,2,1,12.99,2,1,13.98,100,1,12.98,200,2,14.21,100,1,12.86,100,1,14.26,100,1,12.73,100,1,14.35,200,2,12.71,100,1,14.48,1400,2,12.5,700,1,14.54,700,1,12.46,100,1,14.6,100,1,12.43,700,1,14.67,700,1,12.42,700,1,14.77,100,1,ARL,375577225
,2025-07-17T16:42:04.386385514Z,2025-07-17T16:42:04.386385514Z,10,2,1108,C,B,1,12.99,2,0,165707,311568668,13.11,100,1,13.97,2,1,12.98,200,2,13.98,100,1,12.86,100,1,14.21,100,1,12.73,100,1,14.26,100,1,12.71,100,1,14.35,200,2,12.5,700,1,14.48,1400,2,12.46,100,1,14.54,700,1,12.43,700,1,14.6,100,1,12.42,700,1,14.67,700,1,12.37,700,1,14.77,100,1,ARL,375577225
,2025-07-17T16:42:04.386385514Z,2025-07-17T16:42:04.386385514Z,10,2,1108,A,B,1,13.06,2,130,165707,311568668,13.11,100,1,13.97,2,1,13.06,2,1,13.98,100,1,12.98,200,2,14.21,100,1,12.86,100,1,14.26,100,1,12.73,100,1,14.35,200,2,12.71,100,1,14.48,1400,2,12.5,700,1,14.54,700,1,12.46,100,1,14.6,100,1,12.43,700,1,14.67,700,1,12.42,700,1,14.77,100,1,ARL,375823217
,2025-07-17T16:42:36.878663385Z,2025-07-17T16:42:36.878663385Z,10,2,1108,A,A,0,13.45,15,130,165224,312149208,13.11,100,1,13.45,15,1,13.06,2,1,13.97,2,1,12.98,200,2,13.98,100,1,12.86,100,1,14.21,100,1,12.73,100,1,14.26,100,1,12.71,100,1,14.35,200,2,12.5,700,1,14.48,1400,2,12.46,100,1,14.54,700,1,12.43,700,1,14.6,100,1,12.42,700,1,14.67,700,1,ARL,376539701
,2025-07-17T16:42:37.985847507Z,2025-07-17T16:42:37.985847507Z,10,2,1108,C,B,1,13.06,2,0,165498,312159909,13.11,100,1,13.45,15,1,12.98,200,2,13.97,2,1,12.86,100,1,13.98,100,1,12.73,100,1,14.21,100,1,12.71,100,1,14.26,100,1,12.5,700,1,14.35,200,2,12.46,100,1,14.48,1400,2,12.43,700,1,14.54,700,1,12.42,700,1,14.6,100,1,12.37,700,1,14.67,700,1,ARL,375823217
,2025-07-17T16:42:37.985847507Z,2025-07-17T16:42:37.985847507Z,10,2,1108,A,B,0,13.11,2,130,165498,312159909,13.11,102,2,13.45,15,1,12.98,200,2,13.97,2,1,12.86,100,1,13.98,100,1,12.73,100,1,14.21,100,1,12.71,100,1,14.26,100,1,12.5,700,1,14.35,200,2,12.46,100,1,14.48,1400,2,12.43,700,1,14.54,700,1,12.42,700,1,14.6,100,1,12.37,700,1,14.67,700,1,ARL,376553221
,2025-07-17T16:42:38.270716854Z,2025-07-17T16:42:38.270716854Z,10,2,1108,C,A,2,13.98,100,0,165560,312165198,13.11,102,2,13.45,15,1,12.98,200,2,13.97,2,1,12.86,100,1,14.21,100,1,12.73,100,1,14.26,100,1,12.71,100,1,14.35,200,2,12.5,700,1,14.48,1400,2,12.46,100,1,14.54,700,1,12.43,700,1,14.6,100,1,12.42,700,1,14.67,700,1,12.37,700,1,14.77,100,1,ARL,375348505
,2025-07-17T16:42:38.270716854Z,2025-07-17T16:42:38.270716854Z,10,2,1108,A,A,1,13.46,100,130,165560,312165198,13.11,102,2,13.45,15,1,12.98,200,2,13.46,100,1,12.86,100,1,13.97,2,1,12.73,100,1,14.21,100,1,12.71,100,1,14.26,100,1,12.5,700,1,14.35,200,2,12.46,100,1,14.48,1400,2,12.43,700,1,14.54,700,1,12.42,700,1,14.6,100,1,12.37,700,1,14.67,700,1,ARL,376560477
,2025-07-17T16:42:38.271038120Z,2025-07-17T16:42:38.271038120Z,10,2,1108,C,B,0,13.11,2,0,165377,312165204,13.11,100,1,13.45,15,1,12.98,200,2,13.46,100,1,12.86,100,1,13.97,2,1,12.73,100,1,14.21,100,1,12.71,100,1,14.26,100,1,12.5,700,1,14.35,200,2,12.46,100,1,14.48,1400,2,12.43,700,1,14.54,700,1,12.42,700,1,14.6,100,1,12.37,700,1,14.67,700,1,ARL,376553221
,2025-07-17T16:42:38.271038120Z,2025-07-17T16:42:38.271038120Z,10,2,1108,A,B,1,13.0,2,130,165377,312165204,13.11,100,1,13.45,15,1,13.0,2,1,13.46,100,1,12.98,200,2,13.97,2,1,12.86,100,1,14.21,100,1,12.73,100,1,14.26,100,1,12.71,100,1,14.35,200,2,12.5,700,1,14.48,1400,2,12.46,100,1,14.54,700,1,12.43,700,1,14.6,100,1,12.42,700,1,14.67,700,1,ARL,376560493
,2025-07-17T16:42:38.271457684Z,2025-07-17T16:42:38.271457684Z,10,2,1108,A,A,7,14.5,100,130,165408,312165206,13.11,100,1,13.45,15,1,13.0,2,1,13.46,100,1,12.98,200,2,13.97,2,1,12.86,100,1,14.21,100,1,12.73,100,1,14.26,100,1,12.71,100,1,14.35,200,2,12.5,700,1,14.48,1400,2,12.46,100,1,14.5,100,1,12.43,700,1,14.54,700,1,12.42,700,1,14.6,100,1,ARL,376560501
,2025-07-17T16:42:38.271462148Z,2025-07-17T16:42:38.271462148Z,10,2,1108,C,A,9,14.6,100,130,165182,312165207,13.11,100,1,13.45,15,1,13.0,2,1,13.46,100,1,12.98,200,2,13.97,2,1,12.86,100,1,14.21,100,1,12.73,100,1,14.26,100,1,12.71,100,1,14.35,200,2,12.5,700,1,14.48,1400,2,12.46,100,1,14.5,100,1,12.43,700,1,14.54,700,1,12.42,700,1,14.67,700,1,ARL,375342121
,2025-07-17T16:42:38.271829580Z,2025-07-17T16:42:38.271829580Z,10,2,1108,A,A,3,14.06,100,130,165439,312165213,13.11,100,1,13.45,15,1,13.0,2,1,13.46,100,1,12.98,200,2,13.97,2,1,12.86,100,1,14.06,100,1,12.73,100,1,14.21,100,1,12.71,100,1,14.26,100,1,12.5,700,1,14.35,200,2,12.46,100,1,14.48,1400,2,12.43,700,1,14.5,100,1,12.42,700,1,14.54,700,1,ARL,376560525
,2025-07-17T16:42:38.273091716Z,2025-07-17T16:42:38.273091716Z,10,2,1108,A,A,7,14.41,100,130,165360,312165226,13.11,100,1,13.45,15,1,13.0,2,1,13.46,100,1,12.98,200,2,13.97,2,1,12.86,100,1,14.06,100,1,12.73,100,1,14.21,100,1,12.71,100,1,14.26,100,1,12.5,700,1,14.35,200,2,12.46,100,1,14.41,100,1,12.43,700,1,14.48,1400,2,12.42,700,1,14.5,100,1,ARL,376560553
,2025-07-17T16:42:38.274525240Z,2025-07-17T16:42:38.274525240Z,10,2,1108,A,A,5,14.25,100,130,165987,312165251,13.11,100,1,13.45,15,1,13.0,2,1,13.46,100,1,12.98,200,2,13.97,2,1,12.86,100,1,14.06,100,1,12.73,100,1,14.21,100,1,12.71,100,1,14.25,100,1,12.5,700,1,14.26,100,1,12.46,100,1,14.35,200,2,12.43,700,1,14.41,100,1,12.42,700,1,14.48,1400,2,ARL,376560581
,2025-07-17T16:42:38.278789456Z,2025-07-17T16:42:38.278789456Z,10,2,1108,A,A,8,14.41,100,130,165588,312165295,13.11,100,1,13.45,15,1,13.0,2,1,13.46,100,1,12.98,200,2,13.97,2,1,12.86,100,1,14.06,100,1,12.73,100,1,14.21,100,1,12.71,100,1,14.25,100,1,12.5,700,1,14.26,100,1,12.46,100,1,14.35,200,2,12.43,700,1,14.41,200,2,12.42,700,1,14.48,1400,2,ARL,376560685
,2025-07-17T16:42:38.283170473Z,2025-07-17T16:42:38.283170473Z,10,2,1108,C,A,4,14.21,100,130,165353,312165435,13.11,100,1,13.45,15,1,13.0,2,1,13.46,100,1,12.98,200,2,13.97,2,1,12.86,100,1,14.06,100,1,12.73,100,1,14.25,100,1,12.71,100,1,14.26,100,1,12.5,700,1,14.35,200,2,12.46,100,1,14.41,200,2,12.43,700,1,14.48,1400,2,12.42,700,1,14.5,100,1,ARL,375328497
,2025-07-17T16:42:38.283220234Z,2025-07-17T16:42:38.283220234Z,10,2,1108,A,A,2,13.73,100,130,165273,312165438,13.11,100,1,13.45,15,1,13.0,2,1,13.46,100,1,12.98,200,2,13.73,100,1,12.86,100,1,13.97,2,1,12.73,100,1,14.06,100,1,12.71,100,1,14.25,100,1,12.5,700,1,14.26,100,1,12.46,100,1,14.35,200,2,12.43,700,1,14.41,200,2,12.42,700,1,14.48,1400,2,ARL,376560813
,2025-07-17T16:42:38.873668683Z,2025-07-17T16:42:38.873668683Z,10,2,1108,A,A,6,14.26,100,130,165526,312171488,13.11,100,1,13.45,15,1,13.0,2,1,13.46,100,1,12.98,200,2,13.73,100,1,12.86,100,1,13.97,2,1,12.73,100,1,14.06,100,1,12.71,100,1,14.25,100,1,12.5,700,1,14.26,200,2,12.46,100,1,14.35,200,2,12.43,700,1,14.41,200,2,12.42,700,1,14.48,1400,2,ARL,376569293
,2025-07-17T16:42:40.989690505Z,2025-07-17T16:42:40.989690505Z,10,2,1108,C,A,3,13.97,2,0,165531,312198414,13.11,100,1,13.45,15,1,13.0,2,1,13.46,100,1,12.98,200,2,13.73,100,1,12.86,100,1,14.06,100,1,12.73,100,1,14.25,100,1,12.71,100,1,14.26,200,2,12.5,700,1,14.35,200,2,12.46,100,1,14.41,200,2,12.43,700,1,14.48,1400,2,12.42,700,1,14.5,100,1,ARL,375328205
,2025-07-17T16:42:40.989690505Z,2025-07-17T16:42:40.989690505Z,10,2,1108,A,A,3,13.87,2,130,165531,312198414,13.11,100,1,13.45,15,1,13.0,2,1,13.46,100,1,12.98,200,2,13.73,100,1,12.86,100,1,13.87,2,1,12.73,100,1,14.06,100,1,12.71,100,1,14.25,100,1,12.5,700,1,14.26,200,2,12.46,100,1,14.35,200,2,12.43,700,1,14.41,200,2,12.42,700,1,14.48,1400,2,ARL,376604133
,2025-07-17T16:42:46.433709548Z,2025-07-17T16:42:46.433709548Z,10,2,1108,A,A,5,14.18,700,130,165596,312255078,13.11,100,1,13.45,15,1,13.0,2,1,13.46,100,1,12.98,200,2,13.73,100,1,12.86,100,1,13.87,2,1,12.73,100,1,14.06,100,1,12.71,100,1,14.18,700,1,12.5,700,1,14.25,100,1,12.46,100,1,14.26,200,2,12.43,700,1,14.35,200,2,12.42,700,1,14.41,200,2,ARL,376682393
,2025-07-17T16:42:48.190716226Z,2025-07-17T16:42:48.190716226Z,10,2,1108,C,A,3,13.87,2,0,165459,312275865,13.11,100,1,13.45,15,1,13.0,2,1,13.46,100,1,12.98,200,2,13.73,100,1,12.86,100,1,14.06,100,1,12.73,100,1,14.18,700,1,12.71,100,1,14.25,100,1,12.5,700,1,14.26,200,2,12.46,100,1,14.35,200,2,12.43,700,1,14.41,200,2,12.42,700,1,14.48,1400,2,ARL,376604133
,2025-07-17T16:42:48.190716226Z,2025-07-17T16:42:48.190716226Z,10,2,1108,A,A,3,13.79,2,130,165459,312275865,13.11,100,1,13.45,15,1,13.0,2,1,13.46,100,1,12.98,200,2,13.73,100,1,12.86,100,1,13.79,2,1,12.73,100,1,14.06,100,1,12.71,100,1,14.18,700,1,12.5,700,1,14.25,100,1,12.46,100,1,14.26,200,2,12.43,700,1,14.35,200,2,12.42,700,1,14.41,200,2,ARL,376710049
,2025-07-17T16:42:53.413840345Z,2025-07-17T16:42:53.413840345Z,10,2,1108,C,A,0,13.45,15,130,165417,312346120,13.11,100,1,13.46,100,1,13.0,2,1,13.73,100,1,12.98,200,2,13.79,2,1,12.86,100,1,14.06,100,1,12.73,100,1,14.18,700,1,12.71,100,1,14.25,100,1,12.5,700,1,14.26,200,2,12.46,100,1,14.35,200,2,12.43,700,1,14.41,200,2,12.42,700,1,14.48,1400,2,ARL,376539701
,2025-07-17T16:42:53.419392154Z,2025-07-17T16:42:53.419392154Z,10,2,1108,A,A,0,13.45,15,130,165478,312346353,13.11,100,1,13.45,15,1,13.0,2,1,13.46,100,1,12.98,200,2,13.73,100,1,12.86,100,1,13.79,2,1,12.73,100,1,14.06,100,1,12.71,100,1,14.18,700,1,12.5,700,1,14.25,100,1,12.46,100,1,14.26,200,2,12.43,700,1,14.35,200,2,12.42,700,1,14.41,200,2,ARL,376801517
,2025-07-17T16:43:01.389646878Z,2025-07-17T16:43:01.389646878Z,10,2,1108,C,A,3,13.79,2,0,165763,312450189,13.11,100,1,13.45,15,1,13.0,2,1,13.46,100,1,12.98,200,2,13.73,100,1,12.86,100,1,14.06,100,1,12.73,100,1,14.18,700,1,12.71,100,1,14.25,100,1,12.5,700,1,14.26,200,2,12.46,100,1,14.35,200,2,12.43,700,1,14.41,200,2,12.42,700,1,14.48,1400,2,ARL,376710049
,2025-07-17T16:43:01.389646878Z,2025-07-17T16:43:01.389646878Z,10,2,1108,A,A,2,13.72,2,130,165763,312450189,13.11,100,1,13.45,15,1,13.0,2,1,13.46,100,1,12.98,200,2,13.72,2,1,12.86,100,1,13.73,100,1,12.73,100,1,14.06,100,1,12.71,100,1,14.18,700,1,12.5,700,1,14.25,100,1,12.46,100,1,14.26,200,2,12.43,700,1,14.35,200,2,12.42,700,1,14.41,200,2,ARL,376932045
,2025-07-17T16:44:05.065987790Z,2025-07-17T16:44:05.065987790Z,10,2,1108,C,A,0,13.45,15,130,165510,313334368,13.11,100,1,13.46,100,1,13.0,2,1,13.72,2,1,12.98,200,2,13.73,100,1,12.86,100,1,14.06,100,1,12.73,100,1,14.18,700,1,12.71,100,1,14.25,100,1,12.5,700,1,14.26,200,2,12.46,100,1,14.35,200,2,12.43,700,1,14.41,200,2,12.42,700,1,14.48,1400,2,ARL,376801517
,2025-07-17T16:44:10.386132925Z,2025-07-17T16:44:10.386132925Z,10,2,1108,C,A,1,13.72,2,0,165653,313428705,13.11,100,1,13.46,100,1,13.0,2,1,13.73,100,1,12.98,200,2,14.06,100,1,12.86,100,1,14.18,700,1,12.73,100,1,14.25,100,1,12.71,100,1,14.26,200,2,12.5,700,1,14.35,200,2,12.46,100,1,14.41,200,2,12.43,700,1,14.48,1400,2,12.42,700,1,14.5,100,1,ARL,376932045
,2025-07-17T16:44:10.386132925Z,2025-07-17T16:44:10.386132925Z,10,2,1108,A,A,1,13.66,2,130,165653,313428705,13.11,100,1,13.46,100,1,13.0,2,1,13.66,2,1,12.98,200,2,13.73,100,1,12.86,100,1,14.06,100,1,12.73,100,1,14.18,700,1,12.71,100,1,14.25,100,1,12.5,700,1,14.26,200,2,12.46,100,1,14.35,200,2,12.43,700,1,14.41,200,2,12.42,700,1,14.48,1400,2,ARL,378209833
,2025-07-17T16:44:28.874556092Z,2025-07-17T16:44:28.874556092Z,10,2,1108,A,A,0,13.45,15,130,166018,313679060,13.11,100,1,13.45,15,1,13.0,2,1,13.46,100,1,12.98,200,2,13.66,2,1,12.86,100,1,13.73,100,1,12.73,100,1,14.06,100,1,12.71,100,1,14.18,700,1,12.5,700,1,14.25,100,1,12.46,100,1,14.26,200,2,12.43,700,1,14.35,200,2,12.42,700,1,14.41,200,2,ARL,378572841
,2025-07-17T16:44:33.445416279Z,2025-07-17T16:44:33.445416279Z,10,2,1108,C,A,0,13.45,15,128,167600,313731687,13.11,100,1,13.46,100,1,13.0,2,1,13.66,2,1,12.98,200,2,13.73,100,1,12.86,100,1,14.06,100,1,12.73,100,1,14.18,700,1,12.71,100,1,14.25,100,1,12.5,700,1,14.26,200,2,12.46,100,1,14.35,200,2,12.43,700,1,14.41,200,2,12.42,700,1,14.48,1400,2,ARL,378572841
,2025-07-17T16:44:43.947504113Z,2025-07-17T16:44:43.947504113Z,10,2,1108,C,A,0,13.46,100,130,165135,313928874,13.11,100,1,13.66,2,1,13.0,2,1,13.73,100,1,12.98,200,2,14.06,100,1,12.86,100,1,14.18,700,1,12.73,100,1,14.25,100,1,12.71,100,1,14.26,200,2,12.5,700,1,14.35,200,2,12.46,100,1,14.41,200,2,12.43,700,1,14.48,1400,2,12.42,700,1,14.5,100,1,ARL,376560477
,2025-07-17T16:44:43.947777103Z,2025-07-17T16:44:43.947777103Z,10,2,1108,C,A,3,14.18,700,130,165843,313928881,13.11,100,1,13.66,2,1,13.0,2,1,13.73,100,1,12.98,200,2,14.06,100,1,12.86,100,1,14.25,100,1,12.73,100,1,14.26,200,2,12.71,100,1,14.35,200,2,12.5,700,1,14.41,200,2,12.46,100,1,14.48,1400,2,12.43,700,1,14.5,100,1,12.42,700,1,14.54,700,1,ARL,376682393
,2025-07-17T16:44:43.947828206Z,2025-07-17T16:44:43.947828206Z,10,2,1108,A,A,7,14.42,700,130,165324,313928882,13.11,100,1,13.66,2,1,13.0,2,1,13.73,100,1,12.98,200,2,14.06,100,1,12.86,100,1,14.25,100,1,12.73,100,1,14.26,200,2,12.71,100,1,14.35,200,2,12.5,700,1,14.41,200,2,12.46,100,1,14.42,700,1,12.43,700,1,14.48,1400,2,12.42,700,1,14.5,100,1,ARL,378884161
,2025-07-17T16:44:43.948249121Z,2025-07-17T16:44:43.948249121Z,10,2,1108,C,A,2,14.06,100,130,165455,313928891,13.11,100,1,13.66,2,1,13.0,2,1,13.73,100,1,12.98,200,2,14.25,100,1,12.86,100,1,14.26,200,2,12.73,100,1,14.35,200,2,12.71,100,1,14.41,200,2,12.5,700,1,14.42,700,1,12.46,100,1,14.48,1400,2,12.43,700,1,14.5,100,1,12.42,700,1,14.54,700,1,ARL,376560525
,2025-07-17T16:44:43.948256940Z,2025-07-17T16:44:43.948256940Z,10,2,1108,C,A,8,14.5,100,0,165778,313928892,13.11,100,1,13.66,2,1,13.0,2,1,13.73,100,1,12.98,200,2,14.25,100,1,12.86,100,1,14.26,200,2,12.73,100,1,14.35,200,2,12.71,100,1,14.41,200,2,12.5,700,1,14.42,700,1,12.46,100,1,14.48,1400,2,12.43,700,1,14.54,700,1,12.42,700,1,14.81,200,2,ARL,376560501
,2025-07-17T16:44:43.948256940Z,2025-07-17T16:44:43.948256940Z,10,2,1108,A,A,9,14.56,100,130,165778,313928892,13.11,100,1,13.66,2,1,13.0,2,1,13.73,100,1,12.98,200,2,14.25,100,1,12.86,100,1,14.26,200,2,12.73,100,1,14.35,200,2,12.71,100,1,14.41,200,2,12.5,700,1,14.42,700,1,12.46,100,1,14.48,1400,2,12.43,700,1,14.54,700,1,12.42,700,1,14.56,100,1,ARL,378884201
,2025-07-17T16:44:43.948601956Z,2025-07-17T16:44:43.948601956Z,10,2,1108,A,A,4,14.34,100,130,165291,313928894,13.11,100,1,13.66,2,1,13.0,2,1,13.73,100,1,12.98,200,2,14.25,100,1,12.86,100,1,14.26,200,2,12.73,100,1,14.34,100,1,12.71,100,1,14.35,200,2,12.5,700,1,14.41,200,2,12.46,100,1,14.42,700,1,12.43,700,1,14.48,1400,2,12.42,700,1,14.54,700,1,ARL,378884205
,2025-07-17T16:44:43.949133566Z,2025-07-17T16:44:43.949133566Z,10,2,1108,C,A,6,14.41,100,0,165644,313928896,13.11,100,1,13.66,2,1,13.0,2,1,13.73,100,1,12.98,200,2,14.25,100,1,12.86,100,1,14.26,200,2,12.73,100,1,14.34,100,1,12.71,100,1,14.35,200,2,12.5,700,1,14.41,100,1,12.46,100,1,14.42,700,1,12.43,700,1,14.48,1400,2,12.42,700,1,14.54,700,1,ARL,376560553
,2025-07-17T16:44:43.950178776Z,2025-07-17T16:44:43.950178776Z,10,2,1108,C,A,6,14.41,100,0,165502,313928909,13.11,100,1,13.66,2,1,13.0,2,1,13.73,100,1,12.98,200,2,14.25,100,1,12.86,100,1,14.26,200,2,12.73,100,1,14.34,100,1,12.71,100,1,14.35,200,2,12.5,700,1,14.42,700,1,12.46,100,1,14.48,1400,2,12.43,700,1,14.54,700,1,12.42,700,1,14.56,100,1,ARL,376560685
,2025-07-17T16:44:43.950178776Z,2025-07-17T16:44:43.950178776Z,10,2,1108,A,A,10,14.7,100,130,165502,313928909,13.11,100,1,13.66,2,1,13.0,2,1,13.73,100,1,12.98,200,2,14.25,100,1,12.86,100,1,14.26,200,2,12.73,100,1,14.34,100,1,12.71,100,1,14.35,200,2,12.5,700,1,14.42,700,1,12.46,100,1,14.48,1400,2,12.43,700,1,14.54,700,1,12.42,700,1,14.56,100,1,ARL,378884245
,2025-07-17T16:44:43.960172259Z,2025-07-17T16:44:43.960172259Z,10,2,1108,C,A,2,14.25,100,130,165340,313928963,13.11,100,1,13.66,2,1,13.0,2,1,13.73,100,1,12.98,200,2,14.26,200,2,12.86,100,1,14.34,100,1,12.73,100,1,14.35,200,2,12.71,100,1,14.42,700,1,12.5,700,1,14.48,1400,2,12.46,100,1,14.54,700,1,12.43,700,1,14.56,100,1,12.42,700,1,14.7,200,2,ARL,376560581
,2025-07-17T16:44:43.960295032Z,2025-07-17T16:44:43.960295032Z,10,2,1108,A,A,7,14.52,100,130,165215,313928965,13.11,100,1,13.66,2,1,13.0,2,1,13.73,100,1,12.98,200,2,14.26,200,2,12.86,100,1,14.34,100,1,12.73,100,1,14.35,200,2,12.71,100,1,14.42,700,1,12.5,700,1,14.48,1400,2,12.46,100,1,14.52,100,1,12.43,700,1,14.54,700,1,12.42,700,1,14.56,100,1,ARL,378884345
,2025-07-17T16:44:43.965436032Z,2025-07-17T16:44:43.965436032Z,10,2,1108,C,A,1,13.73,100,130,165443,313928980,13.11,100,1,13.66,2,1,13.0,2,1,14.26,200,2,12.98,200,2,14.34,100,1,12.86,100,1,14.35,200,2,12.73,100,1,14.42,700,1,12.71,100,1,14.48,1400,2,12.5,700,1,14.52,100,1,12.46,100,1,14.54,700,1,12.43,700,1,14.56,100,1,12.42,700,1,14.7,200,2,ARL,376560813
,2025-07-17T16:44:43.965467685Z,2025-07-17T16:44:43.965467685Z,10,2,1108,C,A,4,14.42,700,130,165034,313928981,13.11,100,1,13.66,2,1,13.0,2,1,14.26,200,2,12.98,200,2,14.34,100,1,12.86,100,1,14.35,200,2,12.73,100,1,14.48,1400,2,12.71,100,1,14.52,100,1,12.5,700,1,14.54,700,1,12.46,100,1,14.56,100,1,12.43,700,1,14.7,200,2,12.42,700,1,15.11,200,2,ARL,378884161
,2025-07-17T16:44:43.965487362Z,2025-07-17T16:44:43.965487362Z,10,2,1108,A,A,1,14.0,100,130,165343,313928982,13.11,100,1,13.66,2,1,13.0,2,1,14.0,100,1,12.98,200,2,14.26,200,2,12.86,100,1,14.34,100,1,12.73,100,1,14.35,200,2,12.71,100,1,14.48,1400,2,12.5,700,1,14.52,100,1,12.46,100,1,14.54,700,1,12.43,700,1,14.56,100,1,12.42,700,1,14.7,200,2,ARL,378884369
,2025-07-17T16:44:43.966610475Z,2025-07-17T16:44:43.966610475Z,10,2,1108,C,A,9,14.7,100,0,165629,313928996,13.11,100,1,13.66,2,1,13.0,2,1,14.0,100,1,12.98,200,2,14.26,200,2,12.86,100,1,14.34,100,1,12.73,100,1,14.35,200,2,12.71,100,1,14.48,1400,2,12.5,700,1,14.52,100,1,12.46,100,1,14.54,700,1,12.43,700,1,14.56,100,1,12.42,700,1,14.7,100,1,ARL,378884209
,2025-07-17T16:44:43.966610475Z,2025-07-17T16:44:43.966610475Z,10,2,1108,A,A,10,14.93,100,130,165629,313928996,13.11,100,1,13.66,2,1,13.0,2,1,14.0,100,1,12.98,200,2,14.26,200,2,12.86,100,1,14.34,100,1,12.73,100,1,14.35,200,2,12.71,100,1,14.48,1400,2,12.5,700,1,14.52,100,1,12.46,100,1,14.54,700,1,12.43,700,1,14.56,100,1,12.42,700,1,14.7,100,1,ARL,378884389
,2025-07-17T16:44:43.967334622Z,2025-07-17T16:44:43.967334622Z,10,2,1108,C,B,1,13.0,2,0,165327,313929001,13.11,100,1,13.66,2,1,12.98,200,2,14.0,100,1,12.86,100,1,14.26,200,2,12.73,100,1,14.34,100,1,12.71,100,1,14.35,200,2,12.5,700,1,14.48,1400,2,12.46,100,1,14.52,100,1,12.43,700,1,14.54,700,1,12.42,700,1,14.56,100,1,12.37,700,1,14.7,100,1,ARL,376560493
,2025-07-17T16:44:43.967334622Z,2025-07-17T16:44:43.967334622Z,10,2,1108,A,B,2,12.88,2,130,165327,313929001,13.11,100,1,13.66,2,1,12.98,200,2,14.0,100,1,12.88,2,1,14.26,200,2,12.86,100,1,14.34,100,1,12.73,100,1,14.35,200,2,12.71,100,1,14.48,1400,2,12.5,700,1,14.52,100,1,12.46,100,1,14.54,700,1,12.43,700,1,14.56,100,1,12.42,700,1,14.7,100,1,ARL,378884417
,2025-07-17T16:44:43.967336268Z,2025-07-17T16:44:43.967336268Z,10,2,1108,C,A,0,13.66,2,0,165307,313929002,13.11,100,1,14.0,100,1,12.98,200,2,14.26,200,2,12.88,2,1,14.34,100,1,12.86,100,1,14.35,200,2,12.73,100,1,14.48,1400,2,12.71,100,1,14.52,100,1,12.5,700,1,14.54,700,1,12.46,100,1,14.56,100,1,12.43,700,1,14.7,100,1,12.42,700,1,14.93,100,1,ARL,378209833
,2025-07-17T16:44:43.967336268Z,2025-07-17T16:44:43.967336268Z,10,2,1108,A,A,0,13.98,2,130,165307,313929002,13.11,100,1,13.98,2,1,12.98,200,2,14.0,100,1,12.88,2,1,14.26,200,2,12.86,100,1,14.34,100,1,12.73,100,1,14.35,200,2,12.71,100,1,14.48,1400,2,12.5,700,1,14.52,100,1,12.46,100,1,14.54,700,1,12.43,700,1,14.56,100,1,12.42,700,1,14.7,100,1,ARL,378884421
,2025-07-17T16:44:43.968238011Z,2025-07-17T16:44:43.968238011Z,10,2,1108,C,A,9,14.7,100,0,165404,313929006,13.11,100,1,13.98,2,1,12.98,200,2,14.0,100,1,12.88,2,1,14.26,200,2,12.86,100,1,14.34,100,1,12.73,100,1,14.35,200,2,12.71,100,1,14.48,1400,2,12.5,700,1,14.52,100,1,12.46,100,1,14.54,700,1,12.43,700,1,14.56,100,1,12.42,700,1,14.93,100,1,ARL,378884245
,2025-07-17T16:44:43.968238011Z,2025-07-17T16:44:43.968238011Z,10,2,1108,A,A,10,14.96,100,130,165404,313929006,13.11,100,1,13.98,2,1,12.98,200,2,14.0,100,1,12.88,2,1,14.26,200,2,12.86,100,1,14.34,100,1,12.73,100,1,14.35,200,2,12.71,100,1,14.48,1400,2,12.5,700,1,14.52,100,1,12.46,100,1,14.54,700,1,12.43,700,1,14.56,100,1,12.42,700,1,14.93,100,1,ARL,378884425
,2025-07-17T16:44:43.998398734Z,2025-07-17T16:44:43.998398734Z,10,2,1108,C,A,8,14.56,100,0,165357,313929166,13.11,100,1,13.98,2,1,12.98,200,2,14.0,100,1,12.88,2,1,14.26,200,2,12.86,100,1,14.34,100,1,12.73,100,1,14.35,200,2,12.71,100,1,14.48,1400,2,12.5,700,1,14.52,100,1,12.46,100,1,14.54,700,1,12.43,700,1,14.93,100,1,12.42,700,1,14.96,100,1,ARL,378884201
,2025-07-17T16:44:43.998398734Z,2025-07-17T16:44:43.998398734Z,10,2,1108,A,A,10,15.03,100,130,165357,313929166,13.11,100,1,13.98,2,1,12.98,200,2,14.0,100,1,12.88,2,1,14.26,200,2,12.86,100,1,14.34,100,1,12.73,100,1,14.35,200,2,12.71,100,1,14.48,1400,2,12.5,700,1,14.52,100,1,12.46,100,1,14.54,700,1,12.43,700,1,14.93,100,1,12.42,700,1,14.96,100,1,ARL,378884749
,2025-07-17T16:44:43.998551330Z,2025-07-17T16:44:43.998551330Z,10,2,1108,C,A,1,14.0,100,130,165123,313929167,13.11,100,1,13.98,2,1,12.98,200,2,14.26,200,2,12.88,2,1,14.34,100,1,12.86,100,1,14.35,200,2,12.73,100,1,14.48,1400,2,12.71,100,1,14.52,100,1,12.5,700,1,14.54,700,1,12.46,100,1,14.93,100,1,12.43,700,1,14.96,100,1,12.42,700,1,15.03,100,1,ARL,378884369
,2025-07-17T16:44:43.998602131Z,2025-07-17T16:44:43.998602131Z,10,2,1108,A,A,1,14.23,100,130,165275,313929168,13.11,100,1,13.98,2,1,12.98,200,2,14.23,100,1,12.88,2,1,14.26,200,2,12.86,100,1,14.34,100,1,12.73,100,1,14.35,200,2,12.71,100,1,14.48,1400,2,12.5,700,1,14.52,100,1,12.46,100,1,14.54,700,1,12.43,700,1,14.93,100,1,12.42,700,1,14.96,100,1,ARL,378884757
,2025-07-17T16:44:44.034024501Z,2025-07-17T16:44:44.034024501Z,10,2,1108,A,A,8,14.68,700,130,165978,313929291,13.11,100,1,13.98,2,1,12.98,200,2,14.23,100,1,12.88,2,1,14.26,200,2,12.86,100,1,14.34,100,1,12.73,100,1,14.35,200,2,12.71,100,1,14.48,1400,2,12.5,700,1,14.52,100,1,12.46,100,1,14.54,700,1,12.43,700,1,14.68,700,1,12.42,700,1,14.93,100,1,ARL,378885133
,2025-07-17T16:44:44.140729032Z,2025-07-17T16:44:44.140729032Z,10,2,1108,A,A,9,14.81,100,130,165329,313931073,13.11,100,1,13.98,2,1,12.98,200,2,14.23,100,1,12.88,2,1,14.26,200,2,12.86,100,1,14.34,100,1,12.73,100,1,14.35,200,2,12.71,100,1,14.48,1400,2,12.5,700,1,14.52,100,1,12.46,100,1,14.54,700,1,12.43,700,1,14.68,700,1,12.42,700,1,14.81,100,1,ARL,378887673
,2025-07-17T16:44:44.140742632Z,2025-07-17T16:44:44.140742632Z,10,2,1108,C,A,2,14.26,100,130,165301,313931074,13.11,100,1,13.98,2,1,12.98,200,2,14.23,100,1,12.88,2,1,14.26,100,1,12.86,100,1,14.34,100,1,12.73,100,1,14.35,200,2,12.71,100,1,14.48,1400,2,12.5,700,1,14.52,100,1,12.46,100,1,14.54,700,1,12.43,700,1,14.68,700,1,12.42,700,1,14.81,100,1,ARL,376569293
,2025-07-17T16:44:44.228054315Z,2025-07-17T16:44:44.228054315Z,10,2,1108,A,A,1,13.99,100,130,165343,313931853,13.11,100,1,13.98,2,1,12.98,200,2,13.99,100,1,12.88,2,1,14.23,100,1,12.86,100,1,14.26,100,1,12.73,100,1,14.34,100,1,12.71,100,1,14.35,200,2,12.5,700,1,14.48,1400,2,12.46,100,1,14.52,100,1,12.43,700,1,14.54,700,1,12.42,700,1,14.68,700,1,ARL,378888877
,2025-07-17T16:44:44.522897140Z,2025-07-17T16:44:44.522897140Z,10,2,1108,A,A,0,13.45,15,130,165398,313938755,13.11,100,1,13.45,15,1,12.98,200,2,13.98,2,1,12.88,2,1,13.99,100,1,12.86,100,1,14.23,100,1,12.73,100,1,14.26,100,1,12.71,100,1,14.34,100,1,12.5,700,1,14.35,200,2,12.46,100,1,14.48,1400,2,12.43,700,1,14.52,100,1,12.42,700,1,14.54,700,1,ARL,378899025
,2025-07-17T16:44:44.570690672Z,2025-07-17T16:44:44.570690672Z,10,2,1108,C,A,5,14.34,100,130,165594,313939672,13.11,100,1,13.45,15,1,12.98,200,2,13.98,2,1,12.88,2,1,13.99,100,1,12.86,100,1,14.23,100,1,12.73,100,1,14.26,100,1,12.71,100,1,14.35,200,2,12.5,700,1,14.48,1400,2,12.46,100,1,14.52,100,1,12.43,700,1,14.54,700,1,12.42,700,1,14.68,700,1,ARL,378884205
,2025-07-17T16:44:44.571040568Z,2025-07-17T16:44:44.571040568Z,10,2,1108,A,A,9,14.6,100,130,165486,313939677,13.11,100,1,13.45,15,1,12.98,200,2,13.98,2,1,12.88,2,1,13.99,100,1,12.86,100,1,14.23,100,1,12.73,100,1,14.26,100,1,12.71,100,1,14.35,200,2,12.5,700,1,14.48,1400,2,12.46,100,1,14.52,100,1,12.43,700,1,14.54,700,1,12.42,700,1,14.6,100,1,ARL,378900061
,2025-07-17T16:44:44.961344305Z,2025-07-17T16:44:44.961344305Z,10,2,1108,C,A,7,14.52,100,0,165532,313943280,13.11,100,1,13.45,15,1,12.98,200,2,13.98,2,1,12.88,2,1,13.99,100,1,12.86,100,1,14.23,100,1,12.73,100,1,14.26,100,1,12.71,100,1,14.35,200,2,12.5,700,1,14.48,1400,2,12.46,100,1,14.54,700,1,12.43,700,1,14.6,100,1,12.42,700,1,14.68,700,1,ARL,378884345
,2025-07-17T16:44:44.961344305Z,2025-07-17T16:44:44.961344305Z,10,2,1108,A,A,10,14.77,100,130,165532,313943280,13.11,100,1,13.45,15,1,12.98,200,2,13.98,2,1,12.88,2,1,13.99,100,1,12.86,100,1,14.23,100,1,12.73,100,1,14.26,100,1,12.71,100,1,14.35,200,2,12.5,700,1,14.48,1400,2,12.46,100,1,14.54,700,1,12.43,700,1,14.6,100,1,12.42,700,1,14.68,700,1,ARL,378905145
,2025-07-17T16:44:46.881722229Z,2025-07-17T16:44:46.881722229Z,10,2,1108,C,A,0,13.45,15,130,165364,313964658,13.11,100,1,13.98,2,1,12.98,200,2,13.99,100,1,12.88,2,1,14.23,100,1,12.86,100,1,14.26,100,1,12.73,100,1,14.35,200,2,12.71,100,1,14.48,1400,2,12.5,700,1,14.54,700,1,12.46,100,1,14.6,100,1,12.43,700,1,14.68,700,1,12.42,700,1,14.77,100,1,ARL,378899025
,2025-07-17T16:44:49.387476653Z,2025-07-17T16:44:49.387476653Z,10,2,1108,C,B,2,12.88,2,0,165891,313994239,13.11,100,1,13.98,2,1,12.98,200,2,13.99,100,1,12.86,100,1,14.23,100,1,12.73,100,1,14.26,100,1,12.71,100,1,14.35,200,2,12.5,700,1,14.48,1400,2,12.46,100,1,14.54,700,1,12.43,700,1,14.6,100,1,12.42,700,1,14.68,700,1,12.37,700,1,14.77,100,1,ARL,378884417
,2025-07-17T16:44:49.387476653Z,2025-07-17T16:44:49.387476653Z,10,2,1108,A,B,2,12.97,2,130,165891,313994239,13.11,100,1,13.98,2,1,12.98,200,2,13.99,100,1,12.97,2,1,14.23,100,1,12.86,100,1,14.26,100,1,12.73,100,1,14.35,200,2,12.71,100,1,14.48,1400,2,12.5,700,1,14.54,700,1,12.46,100,1,14.6,100,1,12.43,700,1,14.68,700,1,12.42,700,1,14.77,100,1,ARL,378976465
,2025-07-17T16:44:54.882874395Z,2025-07-17T16:44:54.882874395Z,10,2,1108,A,A,0,13.45,15,130,165405,314081248,13.11,100,1,13.45,15,1,12.98,200,2,13.98,2,1,12.97,2,1,13.99,100,1,12.86,100,1,14.23,100,1,12.73,100,1,14.26,100,1,12.71,100,1,14.35,200,2,12.5,700,1,14.48,1400,2,12.46,100,1,14.54,700,1,12.43,700,1,14.6,100,1,12.42,700,1,14.68,700,1,ARL,379094717
,2025-07-17T16:44:54.909111232Z,2025-07-17T16:44:54.909111232Z,10,2,1108,C,A,2,13.99,100,0,165352,314082223,13.11,100,1,13.45,15,1,12.98,200,2,13.98,2,1,12.97,2,1,14.23,100,1,12.86,100,1,14.26,100,1,12.73,100,1,14.35,200,2,12.71,100,1,14.48,1400,2,12.5,700,1,14.54,700,1,12.46,100,1,14.6,100,1,12.43,700,1,14.68,700,1,12.42,700,1,14.77,100,1,ARL,378888877
,2025-07-17T16:44:54.909111232Z,2025-07-17T16:44:54.909111232Z,10,2,1108,A,A,1,13.46,100,130,165352,314082223,13.11,100,1,13.45,15,1,12.98,200,2,13.46,100,1,12.97,2,1,13.98,2,1,12.86,100,1,14.23,100,1,12.73,100,1,14.26,100,1,12.71,100,1,14.35,200,2,12.5,700,1,14.48,1400,2,12.46,100,1,14.54,700,1,12.43,700,1,14.6,100,1,12.42,700,1,14.68,700,1,ARL,379095909
,2025-07-17T16:44:54.909412092Z,2025-07-17T16:44:54.909412092Z,10,2,1108,C,A,2,13.98,2,0,165508,314082230,13.11,100,1,13.45,15,1,12.98,200,2,13.46,100,1,12.97,2,1,14.23,100,1,12.86,100,1,14.26,100,1,12.73,100,1,14.35,200,2,12.71,100,1,14.48,1400,2,12.5,700,1,14.54,700,1,12.46,100,1,14.6,100,1,12.43,700,1,14.68,700,1,12.42,700,1,14.77,100,1,ARL,378884421
,2025-07-17T16:44:54.909412092Z,2025-07-17T16:44:54.909412092Z,10,2,1108,A,A,2,13.79,2,130,165508,314082230,13.11,100,1,13.45,15,1,12.98,200,2,13.46,100,1,12.97,2,1,13.79,2,1,12.86,100,1,14.23,100,1,12.73,100,1,14.26,100,1,12.71,100,1,14.35,200,2,12.5,700,1,14.48,1400,2,12.46,100,1,14.54,700,1,12.43,700,1,14.6,100,1,12.42,700,1,14.68,700,1,ARL,379095929
,2025-07-17T16:44:54.909846352Z,2025-07-17T16:44:54.909846352Z,10,2,1108,A,A,7,14.5,100,130,165436,314082244,13.11,100,1,13.45,15,1,12.98,200,2,13.46,100,1,12.97,2,1,13.79,2,1,12.86,100,1,14.23,100,1,12.73,100,1,14.26,100,1,12.71,100,1,14.35,200,2,12.5,700,1,14.48,1400,2,12.46,100,1,14.5,100,1,12.43,700,1,14.54,700,1,12.42,700,1,14.6,100,1,ARL,379095949
,2025-07-17T16:44:54.909848730Z,2025-07-17T16:44:54.909848730Z,10,2,1108,C,A,9,14.6,100,130,165354,314082245,13.11,100,1,13.45,15,1,12.98,200,2,13.46,100,1,12.97,2,1,13.79,2,1,12.86,100,1,14.23,100,1,12.73,100,1,14.26,100,1,12.71,100,1,14.35,200,2,12.5,700,1,14.48,1400,2,12.46,100,1,14.5,100,1,12.43,700,1,14.54,700,1,12.42,700,1,14.68,700,1,ARL,378900061
,2025-07-17T16:44:54.910148272Z,2025-07-17T16:44:54.910148272Z,10,2,1108,A,A,6,14.41,100,130,165289,314082257,13.11,100,1,13.45,15,1,12.98,200,2,13.46,100,1,12.97,2,1,13.79,2,1,12.86,100,1,14.23,100,1,12.73,100,1,14.26,100,1,12.71,100,1,14.35,200,2,12.5,700,1,14.41,100,1,12.46,100,1,14.48,1400,2,12.43,700,1,14.5,100,1,12.42,700,1,14.54,700,1,ARL,379095977
,2025-07-17T16:44:54.910209882Z,2025-07-17T16:44:54.910209882Z,10,2,1108,A,A,3,14.06,100,130,165424,314082259,13.11,100,1,13.45,15,1,12.98,200,2,13.46,100,1,12.97,2,1,13.79,2,1,12.86,100,1,14.06,100,1,12.73,100,1,14.23,100,1,12.71,100,1,14.26,100,1,12.5,700,1,14.35,200,2,12.46,100,1,14.41,100,1,12.43,700,1,14.48,1400,2,12.42,700,1,14.5,100,1,ARL,379095981
,2025-07-17T16:44:54.915718215Z,2025-07-17T16:44:54.915718215Z,10,2,1108,C,A,4,14.23,100,130,165087,314082353,13.11,100,1,13.45,15,1,12.98,200,2,13.46,100,1,12.97,2,1,13.79,2,1,12.86,100,1,14.06,100,1,12.73,100,1,14.26,100,1,12.71,100,1,14.35,200,2,12.5,700,1,14.41,100,1,12.46,100,1,14.48,1400,2,12.43,700,1,14.5,100,1,12.42,700,1,14.54,700,1,ARL,378884757
,2025-07-17T16:44:54.915775814Z,2025-07-17T16:44:54.915775814Z,10,2,1108,A,A,2,13.73,100,130,165668,314082354,13.11,100,1,13.45,15,1,12.98,200,2,13.46,100,1,12.97,2,1,13.73,100,1,12.86,100,1,13.79,2,1,12.73,100,1,14.06,100,1,12.71,100,1,14.26,100,1,12.5,700,1,14.35,200,2,12.46,100,1,14.41,100,1,12.43,700,1,14.48,1400,2,12.42,700,1,14.5,100,1,ARL,379096113
,2025-07-17T16:44:54.946424043Z,2025-07-17T16:44:54.946424043Z,10,2,1108,A,A,5,14.25,100,130,165264,314082941,13.11,100,1,13.45,15,1,12.98,200,2,13.46,100,1,12.97,2,1,13.73,100,1,12.86,100,1,13.79,2,1,12.73,100,1,14.06,100,1,12.71,100,1,14.25,100,1,12.5,700,1,14.26,100,1,12.46,100,1,14.35,200,2,12.43,700,1,14.41,100,1,12.42,700,1,14.48,1400,2,ARL,379096805
,2025-07-17T16:44:54.966510936Z,2025-07-17T16:44:54.966510936Z,10,2,1108,A,A,8,14.41,100,130,165786,314083184,13.11,100,1,13.45,15,1,12.98,200,2,13.46,100,1,12.97,2,1,13.73,100,1,12.86,100,1,13.79,2,1,12.73,100,1,14.06,100,1,12.71,100,1,14.25,100,1,12.5,700,1,14.26,100,1,12.46,100,1,14.35,200,2,12.43,700,1,14.41,200,2,12.42,700,1,14.48,1400,2,ARL,379096981
,2025-07-17T16:44:55.300763037Z,2025-07-17T16:44:55.300763037Z,10,2,1108,A,A,6,14.26,100,130,165170,314089820,13.11,100,1,13.45,15,1,12.98,200,2,13.46,100,1,12.97,2,1,13.73,100,1,12.86,100,1,13.79,2,1,12.73,100,1,14.06,100,1,12.71,100,1,14.25,100,1,12.5,700,1,14.26,200,2,12.46,100,1,14.35,200,2,12.43,700,1,14.41,200,2,12.42,700,1,14.48,1400,2,ARL,379107445
,2025-07-17T16:44:59.834173908Z,2025-07-17T16:44:59.834173908Z,10,2,1108,A,A,5,14.18,700,130,165230,314166592,13.11,100,1,13.45,15,1,12.98,200,2,13.46,100,1,12.97,2,1,13.73,100,1,12.86,100,1,13.79,2,1,12.73,100,1,14.06,100,1,12.71,100,1,14.18,700,1,12.5,700,1,14.25,100,1,12.46,100,1,14.26,200,2,12.43,700,1,14.35,200,2,12.42,700,1,14.41,200,2,ARL,379214721
,2025-07-17T16:45:03.007238453Z,2025-07-17T16:45:03.007238453Z,10,2,1108,C,A,3,13.79,2,0,166382,314215324,13.11,100,1,13.45,15,1,12.98,200,2,13.46,100,1,12.97,2,1,13.73,100,1,12.86,100,1,14.06,100,1,12.73,100,1,14.18,700,1,12.71,100,1,14.25,100,1,12.5,700,1,14.26,200,2,12.46,100,1,14.35,200,2,12.43,700,1,14.41,200,2,12.42,700,1,14.48,1400,2,ARL,379095929
,2025-07-17T16:45:03.007238453Z,2025-07-17T16:45:03.007238453Z,10,2,1108,A,A,2,13.71,2,130,166382,314215324,13.11,100,1,13.45,15,1,12.98,200,2,13.46,100,1,12.97,2,1,13.71,2,1,12.86,100,1,13.73,100,1,12.73,100,1,14.06,100,1,12.71,100,1,14.18,700,1,12.5,700,1,14.25,100,1,12.46,100,1,14.26,200,2,12.43,700,1,14.35,200,2,12.42,700,1,14.41,200,2,ARL,379278349
,2025-07-17T16:45:27.018599302Z,2025-07-17T16:45:27.018599302Z,10,2,1108,A,A,2,13.49,100,130,165149,314585155,13.11,100,1,13.45,15,1,12.98,200,2,13.46,100,1,12.97,2,1,13.49,100,1,12.86,100,1,13.71,2,1,12.73,100,1,13.73,100,1,12.71,100,1,14.06,100,1,12.5,700,1,14.18,700,1,12.46,100,1,14.25,100,1,12.43,700,1,14.26,200,2,12.42,700,1,14.35,200,2,ARL,379736825
,2025-07-17T16:45:30.185938975Z,2025-07-17T16:45:30.185938975Z,10,2,1108,C,A,3,13.71,2,0,165564,314635721,13.11,100,1,13.45,15,1,12.98,200,2,13.46,100,1,12.97,2,1,13.49,100,1,12.86,100,1,13.73,100,1,12.73,100,1,14.06,100,1,12.71,100,1,14.18,700,1,12.5,700,1,14.25,100,1,12.46,100,1,14.26,200,2,12.43,700,1,14.35,200,2,12.42,700,1,14.41,200,2,ARL,379278349
,2025-07-17T16:45:30.185938975Z,2025-07-17T16:45:30.185938975Z,10,2,1108,A,A,3,13.65,2,130,165564,314635721,13.11,100,1,13.45,15,1,12.98,200,2,13.46,100,1,12.97,2,1,13.49,100,1,12.86,100,1,13.65,2,1,12.73,100,1,13.73,100,1,12.71,100,1,14.06,100,1,12.5,700,1,14.18,700,1,12.46,100,1,14.25,100,1,12.43,700,1,14.26,200,2,12.42,700,1,14.35,200,2,ARL,379801189
,2025-07-17T16:46:28.859642188Z,2025-07-17T16:46:28.859642188Z,10,2,1108,A,B,0,13.11,10,130,165325,315728525,13.11,110,2,13.45,15,1,12.98,200,2,13.46,100,1,12.97,2,1,13.49,100,1,12.86,100,1,13.65,2,1,12.73,100,1,13.73,100,1,12.71,100,1,14.06,100,1,12.5,700,1,14.18,700,1,12.46,100,1,14.25,100,1,12.43,700,1,14.26,200,2,12.42,700,1,14.35,200,2,ARL,381110009
,2025-07-17T16:46:36.884693968Z,2025-07-17T16:46:36.884693968Z,10,2,1108,C,B,0,13.11,10,130,165990,315927907,13.11,100,1,13.45,15,1,12.98,200,2,13.46,100,1,12.97,2,1,13.49,100,1,12.86,100,1,13.65,2,1,12.73,100,1,13.73,100,1,12.71,100,1,14.06,100,1,12.5,700,1,14.18,700,1,12.46,100,1,14.25,100,1,12.43,700,1,14.26,200,2,12.42,700,1,14.35,200,2,ARL,381110009
,2025-07-17T16:46:37.794540840Z,2025-07-17T16:46:37.794540840Z,10,2,1108,A,A,2,13.47,100,130,165202,315954210,13.11,100,1,13.45,15,1,12.98,200,2,13.46,100,1,12.97,2,1,13.47,100,1,12.86,100,1,13.49,100,1,12.73,100,1,13.65,2,1,12.71,100,1,13.73,100,1,12.5,700,1,14.06,100,1,12.46,100,1,14.18,700,1,12.43,700,1,14.25,100,1,12.42,700,1,14.26,200,2,ARL,381366917
,2025-07-17T16:46:37.801930526Z,2025-07-17T16:46:37.801930526Z,10,2,1108,C,A,3,13.49,100,130,165354,315954275,13.11,100,1,13.45,15,1,12.98,200,2,13.46,100,1,12.97,2,1,13.47,100,1,12.86,100,1,13.65,2,1,12.73,100,1,13.73,100,1,12.71,100,1,14.06,100,1,12.5,700,1,14.18,700,1,12.46,100,1,14.25,100,1,12.43,700,1,14.26,200,2,12.42,700,1,14.35,200,2,ARL,379736825
,2025-07-17T16:46:38.884538478Z,2025-07-17T16:46:38.884538478Z,10,2,1108,A,A,0,13.43,15,130,165212,315968206,13.11,100,1,13.43,15,1,12.98,200,2,13.45,15,1,12.97,2,1,13.46,100,1,12.86,100,1,13.47,100,1,12.73,100,1,13.65,2,1,12.71,100,1,13.73,100,1,12.5,700,1,14.06,100,1,12.46,100,1,14.18,700,1,12.43,700,1,14.25,100,1,12.42,700,1,14.26,200,2,ARL,381385565
,2025-07-17T16:46:39.214664841Z,2025-07-17T16:46:39.214664841Z,10,2,1108,C,A,2,13.46,100,0,165437,315973473,13.11,100,1,13.43,15,1,12.98,200,2,13.45,15,1,12.97,2,1,13.47,100,1,12.86,100,1,13.65,2,1,12.73,100,1,13.73,100,1,12.71,100,1,14.06,100,1,12.5,700,1,14.18,700,1,12.46,100,1,14.25,100,1,12.43,700,1,14.26,200,2,12.42,700,1,14.35,200,2,ARL,379095909
,2025-07-17T16:46:39.214664841Z,2025-07-17T16:46:39.214664841Z,10,2,1108,A,A,1,13.44,100,130,165437,315973473,13.11,100,1,13.43,15,1,12.98,200,2,13.44,100,1,12.97,2,1,13.45,15,1,12.86,100,1,13.47,100,1,12.73,100,1,13.65,2,1,12.71,100,1,13.73,100,1,12.5,700,1,14.06,100,1,12.46,100,1,14.18,700,1,12.43,700,1,14.25,100,1,12.42,700,1,14.26,200,2,ARL,381389921
,2025-07-17T16:46:39.495672905Z,2025-07-17T16:46:39.495672905Z,10,2,1108,A,A,6,13.97,100,130,165231,315977251,13.11,100,1,13.43,15,1,12.98,200,2,13.44,100,1,12.97,2,1,13.45,15,1,12.86,100,1,13.47,100,1,12.73,100,1,13.65,2,1,12.71,100,1,13.73,100,1,12.5,700,1,13.97,100,1,12.46,100,1,14.06,100,1,12.43,700,1,14.18,700,1,12.42,700,1,14.25,100,1,ARL,381395205
,2025-07-17T16:46:39.495673898Z,2025-07-17T16:46:39.495673898Z,10,2,1108,C,A,10,14.26,100,130,165379,315977252,13.11,100,1,13.43,15,1,12.98,200,2,13.44,100,1,12.97,2,1,13.45,15,1,12.86,100,1,13.47,100,1,12.73,100,1,13.65,2,1,12.71,100,1,13.73,100,1,12.5,700,1,13.97,100,1,12.46,100,1,14.06,100,1,12.43,700,1,14.18,700,1,12.42,700,1,14.25,100,1,ARL,375329381
,2025-07-17T16:47:10.013892892Z,2025-07-17T16:47:10.013892892Z,10,2,1108,C,A,1,13.44,100,130,165326,316423218,13.11,100,1,13.43,15,1,12.98,200,2,13.45,15,1,12.97,2,1,13.47,100,1,12.86,100,1,13.65,2,1,12.73,100,1,13.73,100,1,12.71,100,1,13.97,100,1,12.5,700,1,14.06,100,1,12.46,100,1,14.18,700,1,12.43,700,1,14.25,100,1,12.42,700,1,14.26,100,1,ARL,381389921
,2025-07-17T16:47:10.015510357Z,2025-07-17T16:47:10.015510357Z,10,2,1108,C,A,1,13.45,15,130,165205,316423231,13.11,100,1,13.43,15,1,12.98,200,2,13.47,100,1,12.97,2,1,13.65,2,1,12.86,100,1,13.73,100,1,12.73,100,1,13.97,100,1,12.71,100,1,14.06,100,1,12.5,700,1,14.18,700,1,12.46,100,1,14.25,100,1,12.43,700,1,14.26,100,1,12.42,700,1,14.35,200,2,ARL,379094717
,2025-07-17T16:47:11.017528057Z,2025-07-17T16:47:11.017528057Z,10,2,1108,A,A,0,13.4,15,130,165344,316439018,13.11,100,1,13.4,15,1,12.98,200,2,13.43,15,1,12.97,2,1,13.47,100,1,12.86,100,1,13.65,2,1,12.73,100,1,13.73,100,1,12.71,100,1,13.97,100,1,12.5,700,1,14.06,100,1,12.46,100,1,14.18,700,1,12.43,700,1,14.25,100,1,12.42,700,1,14.26,100,1,ARL,381931621
,2025-07-17T16:47:11.276507069Z,2025-07-17T16:47:11.276507069Z,10,2,1108,A,A,2,13.44,100,130,165165,316442554,13.11,100,1,13.4,15,1,12.98,200,2,13.43,15,1,12.97,2,1,13.44,100,1,12.86,100,1,13.47,100,1,12.73,100,1,13.65,2,1,12.71,100,1,13.73,100,1,12.5,700,1,13.97,100,1,12.46,100,1,14.06,100,1,12.43,700,1,14.18,700,1,12.42,700,1,14.25,100,1,ARL,381937585
,2025-07-17T16:47:20.734111066Z,2025-07-17T16:47:20.734111066Z,10,2,1108,C,A,0,13.4,15,130,165393,316605363,13.11,100,1,13.43,15,1,12.98,200,2,13.44,100,1,12.97,2,1,13.47,100,1,12.86,100,1,13.65,2,1,12.73,100,1,13.73,100,1,12.71,100,1,13.97,100,1,12.5,700,1,14.06,100,1,12.46,100,1,14.18,700,1,12.43,700,1,14.25,100,1,12.42,700,1,14.26,100,1,ARL,381931621
,2025-07-17T16:47:20.735283296Z,2025-07-17T16:47:20.735283296Z,10,2,1108,C,A,0,13.43,15,130,165219,316605399,13.11,100,1,13.44,100,1,12.98,200,2,13.47,100,1,12.97,2,1,13.65,2,1,12.86,100,1,13.73,100,1,12.73,100,1,13.97,100,1,12.71,100,1,14.06,100,1,12.5,700,1,14.18,700,1,12.46,100,1,14.25,100,1,12.43,700,1,14.26,100,1,12.42,700,1,14.35,200,2,ARL,381385565
,2025-07-17T16:47:39.209310686Z,2025-07-17T16:47:39.209310686Z,10,2,1108,A,A,0,13.39,15,130,165232,316885657,13.11,100,1,13.39,15,1,12.98,200,2,13.44,100,1,12.97,2,1,13.47,100,1,12.86,100,1,13.65,2,1,12.73,100,1,13.73,100,1,12.71,100,1,13.97,100,1,12.5,700,1,14.06,100,1,12.46,100,1,14.18,700,1,12.43,700,1,14.25,100,1,12.42,700,1,14.26,100,1,ARL,382444445
,2025-07-17T16:47:46.798089272Z,2025-07-17T16:47:46.798089272Z,10,2,1108,C,A,2,13.47,100,130,165361,316999429,13.11,100,1,13.39,15,1,12.98,200,2,13.44,100,1,12.97,2,1,13.65,2,1,12.86,100,1,13.73,100,1,12.73,100,1,13.97,100,1,12.71,100,1,14.06,100,1,12.5,700,1,14.18,700,1,12.46,100,1,14.25,100,1,12.43,700,1,14.26,100,1,12.42,700,1,14.35,200,2,ARL,381366917
,2025-07-17T16:47:46.799129468Z,2025-07-17T16:47:46.799129468Z,10,2,1108,A,A,0,13.37,15,130,165509,316999432,13.11,100,1,13.37,15,1,12.98,200,2,13.39,15,1,12.97,2,1,13.44,100,1,12.86,100,1,13.65,2,1,12.73,100,1,13.73,100,1,12.71,100,1,13.97,100,1,12.5,700,1,14.06,100,1,12.46,100,1,14.18,700,1,12.43,700,1,14.25,100,1,12.42,700,1,14.26,100,1,ARL,382585849
,2025-07-17T16:47:56.799193045Z,2025-07-17T16:47:56.799193045Z,10,2,1108,C,A,1,13.39,15,130,165947,317127138,13.11,100,1,13.37,15,1,12.98,200,2,13.44,100,1,12.97,2,1,13.65,2,1,12.86,100,1,13.73,100,1,12.73,100,1,13.97,100,1,12.71,100,1,14.06,100,1,12.5,700,1,14.18,700,1,12.46,100,1,14.25,100,1,12.43,700,1,14.26,100,1,12.42,700,1,14.35,200,2,ARL,382444445
,2025-07-17T16:48:45.976405116Z,2025-07-17T16:48:45.976405116Z,10,2,1108,A,A,0,13.35,15,130,165394,317969792,13.11,100,1,13.35,15,1,12.98,200,2,13.37,15,1,12.97,2,1,13.44,100,1,12.86,100,1,13.65,2,1,12.73,100,1,13.73,100,1,12.71,100,1,13.97,100,1,12.5,700,1,14.06,100,1,12.46,100,1,14.18,700,1,12.43,700,1,14.25,100,1,12.42,700,1,14.26,100,1,ARL,383773141
,2025-07-17T16:49:41.077352984Z,2025-07-17T16:49:41.077352984Z,10,2,1108,C,A,1,13.37,15,130,165302,318962185,13.11,100,1,13.35,15,1,12.98,200,2,13.44,100,1,12.97,2,1,13.65,2,1,12.86,100,1,13.73,100,1,12.73,100,1,13.97,100,1,12.71,100,1,14.06,100,1,12.5,700,1,14.18,700,1,12.46,100,1,14.25,100,1,12.43,700,1,14.26,100,1,12.42,700,1,14.35,200,2,ARL,382585849
,2025-07-17T16:49:42.080880890Z,2025-07-17T16:49:42.080880890Z,10,2,1108,A,A,0,13.33,15,130,165429,318972429,13.11,100,1,13.33,15,1,12.98,200,2,13.35,15,1,12.97,2,1,13.44,100,1,12.86,100,1,13.65,2,1,12.73,100,1,13.73,100,1,12.71,100,1,13.97,100,1,12.5,700,1,14.06,100,1,12.46,100,1,14.18,700,1,12.43,700,1,14.25,100,1,12.42,700,1,14.26,100,1,ARL,384964609
,2025-07-17T16:49:42.080966181Z,2025-07-17T16:49:42.080966181Z,10,2,1108,C,A,10,14.35,100,0,165502,318972430,13.11,100,1,13.33,15,1,12.98,200,2,13.35,15,1,12.97,2,1,13.44,100,1,12.86,100,1,13.65,2,1,12.73,100,1,13.73,100,1,12.71,100,1,13.97,100,1,12.5,700,1,14.06,100,1,12.46,100,1,14.18,700,1,12.43,700,1,14.25,100,1,12.42,700,1,14.26,100,1,ARL,360438973
,2025-07-17T16:49:42.080966181Z,2025-07-17T16:49:42.080966181Z,10,2,1108,A,A,8,14.23,100,130,165502,318972430,13.11,100,1,13.33,15,1,12.98,200,2,13.35,15,1,12.97,2,1,13.44,100,1,12.86,100,1,13.65,2,1,12.73,100,1,13.73,100,1,12.71,100,1,13.97,100,1,12.5,700,1,14.06,100,1,12.46,100,1,14.18,700,1,12.43,700,1,14.23,100,1,12.42,700,1,14.25,100,1,ARL,384964613
,2025-07-17T16:49:42.081026152Z,2025-07-17T16:49:42.081026152Z,10,2,1108,A,A,8,14.23,100,130,165626,318972432,13.11,100,1,13.33,15,1,12.98,200,2,13.35,15,1,12.97,2,1,13.44,100,1,12.86,100,1,13.65,2,1,12.73,100,1,13.73,100,1,12.71,100,1,13.97,100,1,12.5,700,1,14.06,100,1,12.46,100,1,14.18,700,1,12.43,700,1,14.23,200,2,12.42,700,1,14.25,100,1,ARL,384964617
,2025-07-17T16:50:35.554910694Z,2025-07-17T16:50:35.554910694Z,10,2,1108,C,A,0,13.33,15,130,167360,319771042,13.11,100,1,13.35,15,1,12.98,200,2,13.44,100,1,12.97,2,1,13.65,2,1,12.86,100,1,13.73,100,1,12.73,100,1,13.97,100,1,12.71,100,1,14.06,100,1,12.5,700,1,14.18,700,1,12.46,100,1,14.23,200,2,12.43,700,1,14.25,100,1,12.42,700,1,14.26,100,1,ARL,384964609
,2025-07-17T16:50:35.568627090Z,2025-07-17T16:50:35.568627090Z,10,2,1108,C,A,0,13.35,15,130,169996,319772565,13.11,100,1,13.44,100,1,12.98,200,2,13.65,2,1,12.97,2,1,13.73,100,1,12.86,100,1,13.97,100,1,12.73,100,1,14.06,100,1,12.71,100,1,14.18,700,1,12.5,700,1,14.23,200,2,12.46,100,1,14.25,100,1,12.43,700,1,14.26,100,1,12.42,700,1,14.41,200,2,ARL,383773141
,2025-07-17T16:50:37.518305138Z,2025-07-17T16:50:37.518305138Z,10,2,1108,A,A,0,13.33,15,130,166701,319815357,13.11,100,1,13.33,15,1,12.98,200,2,13.44,100,1,12.97,2,1,13.65,2,1,12.86,100,1,13.73,100,1,12.73,100,1,13.97,100,1,12.71,100,1,14.06,100,1,12.5,700,1,14.18,700,1,12.46,100,1,14.23,200,2,12.43,700,1,14.25,100,1,12.42,700,1,14.26,100,1,ARL,386002397
,2025-07-17T16:50:50.893077384Z,2025-07-17T16:50:50.893077384Z,10,2,1108,A,A,0,13.31,15,130,165746,320022719,13.11,100,1,13.31,15,1,12.98,200,2,13.33,15,1,12.97,2,1,13.44,100,1,12.86,100,1,13.65,2,1,12.73,100,1,13.73,100,1,12.71,100,1,13.97,100,1,12.5,700,1,14.06,100,1,12.46,100,1,14.18,700,1,12.43,700,1,14.23,200,2,12.42,700,1,14.25,100,1,ARL,386239877
,2025-07-17T16:51:49.202985817Z,2025-07-17T16:51:49.202985817Z,10,2,1108,T,B,0,13.11,100,130,166096,320804609,12.98,200,2,13.31,15,1,12.97,2,1,13.33,15,1,12.86,100,1,13.44,100,1,12.73,100,1,13.65,2,1,12.71,100,1,13.73,100,1,12.5,700,1,13.97,100,1,12.46,100,1,14.06,100,1,12.43,700,1,14.18,700,1,12.42,700,1,14.23,200,2,12.37,700,1,14.25,100,1,ARL,0
,2025-07-17T16:51:49.203017730Z,2025-07-17T16:51:49.203017730Z,10,2,1108,A,A,0,13.27,12,130,165349,320804610,12.98,200,2,13.27,12,1,12.97,2,1,13.31,15,1,12.86,100,1,13.33,15,1,12.73,100,1,13.44,100,1,12.71,100,1,13.65,2,1,12.5,700,1,13.73,100,1,12.46,100,1,13.97,100,1,12.43,700,1,14.06,100,1,12.42,700,1,14.18,700,1,12.37,700,1,14.23,200,2,ARL,387208141
,2025-07-17T16:51:49.203297464Z,2025-07-17T16:51:49.203297464Z,10,2,1108,A,A,8,14.18,700,130,165256,320804615,12.98,200,2,13.27,12,1,12.97,2,1,13.31,15,1,12.86,100,1,13.33,15,1,12.73,100,1,13.44,100,1,12.71,100,1,13.65,2,1,12.5,700,1,13.73,100,1,12.46,100,1,13.97,100,1,12.43,700,1,14.06,100,1,12.42,700,1,14.18,1400,2,12.37,700,1,14.23,200,2,ARL,387208149
,2025-07-17T16:51:49.203325727Z,2025-07-17T16:51:49.203325727Z,10,2,1108,C,B,0,12.98,100,130,165580,320804616,12.98,100,1,13.27,12,1,12.97,2,1,13.31,15,1,12.86,100,1,13.33,15,1,12.73,100,1,13.44,100,1,12.71,100,1,13.65,2,1,12.5,700,1,13.73,100,1,12.46,100,1,13.97,100,1,12.43,700,1,14.06,100,1,12.42,700,1,14.18,1400,2,12.37,700,1,14.23,200,2,ARL,328489377
,2025-07-17T16:51:49.203327079Z,2025-07-17T16:51:49.203327079Z,10,2,1108,C,B,0,12.98,100,130,165376,320804617,12.97,2,1,13.27,12,1,12.86,100,1,13.31,15,1,12.73,100,1,13.33,15,1,12.71,100,1,13.44,100,1,12.5,700,1,13.65,2,1,12.46,100,1,13.73,100,1,12.43,700,1,13.97,100,1,12.42,700,1,14.06,100,1,12.37,700,1,14.18,1400,2,12.33,100,1,14.23,200,2,ARL,328489385
,2025-07-17T16:51:49.203372483Z,2025-07-17T16:51:49.203372483Z,10,2,1108,C,B,8,12.37,700,130,165566,320804619,12.97,2,1,13.27,12,1,12.86,100,1,13.31,15,1,12.73,100,1,13.33,15,1,12.71,100,1,13.44,100,1,12.5,700,1,13.65,2,1,12.46,100,1,13.73,100,1,12.43,700,1,13.97,100,1,12.42,700,1,14.06,100,1,12.33,100,1,14.18,1400,2,12.22,200,2,14.23,200,2,ARL,45025165
,2025-07-17T16:51:49.203373534Z,2025-07-17T16:51:49.203373534Z,10,2,1108,C,B,6,12.43,700,130,165536,320804620,12.97,2,1,13.27,12,1,12.86,100,1,13.31,15,1,12.73,100,1,13.33,15,1,12.71,100,1,13.44,100,1,12.5,700,1,13.65,2,1,12.46,100,1,13.73,100,1,12.42,700,1,13.97,100,1,12.33,100,1,14.06,100,1,12.22,200,2,14.18,1400,2,12.2,200,2,14.23,200,2,ARL,47383873
,2025-07-17T16:51:49.203417555Z,2025-07-17T16:51:49.203417555Z,10,2,1108,A,B,9,12.21,700,130,165365,320804621,12.97,2,1,13.27,12,1,12.86,100,1,13.31,15,1,12.73,100,1,13.33,15,1,12.71,100,1,13.44,100,1,12.5,700,1,13.65,2,1,12.46,100,1,13.73,100,1,12.42,700,1,13.97,100,1,12.33,100,1,14.06,100,1,12.22,200,2,14.18,1400,2,12.21,700,1,14.23,200,2,ARL,387208153
,2025-07-17T16:51:49.203728024Z,2025-07-17T16:51:49.203728024Z,10,2,1108,C,B,3,12.71,100,130,165746,320804626,12.97,2,1,13.27,12,1,12.86,100,1,13.31,15,1,12.73,100,1,13.33,15,1,12.5,700,1,13.44,100,1,12.46,100,1,13.65,2,1,12.42,700,1,13.73,100,1,12.33,100,1,13.97,100,1,12.22,200,2,14.06,100,1,12.21,700,1,14.18,1400,2,12.2,200,2,14.23,200,2,ARL,285586093
,2025-07-17T16:51:49.204082713Z,2025-07-17T16:51:49.204082713Z,10,2,1108,A,B,7,12.29,100,130,165292,320804630,12.97,2,1,13.27,12,1,12.86,100,1,13.31,15,1,12.73,100,1,13.33,15,1,12.5,700,1,13.44,100,1,12.46,100,1,13.65,2,1,12.42,700,1,13.73,100,1,12.33,100,1,13.97,100,1,12.29,100,1,14.06,100,1,12.22,200,2,14.18,1400,2,12.21,700,1,14.23,200,2,ARL,387208173
,2025-07-17T16:51:49.204097932Z,2025-07-17T16:51:49.204097932Z,10,2,1108,C,B,5,12.42,700,130,165358,320804631,12.97,2,1,13.27,12,1,12.86,100,1,13.31,15,1,12.73,100,1,13.33,15,1,12.5,700,1,13.44,100,1,12.46,100,1,13.65,2,1,12.33,100,1,13.73,100,1,12.29,100,1,13.97,100,1,12.22,200,2,14.06,100,1,12.21,700,1,14.18,1400,2,12.2,200,2,14.23,200,2,ARL,44720357
,2025-07-17T16:51:49.204505724Z,2025-07-17T16:51:49.204505724Z,10,2,1108,A,B,10,12.18,700,130,165493,320804633,12.97,2,1,13.27,12,1,12.86,100,1,13.31,15,1,12.73,100,1,13.33,15,1,12.5,700,1,13.44,100,1,12.46,100,1,13.65,2,1,12.33,100,1,13.73,100,1,12.29,100,1,13.97,100,1,12.22,200,2,14.06,100,1,12.21,700,1,14.18,1400,2,12.2,200,2,14.23,200,2,ARL,387208181
,2025-07-17T16:51:49.204850120Z,2025-07-17T16:51:49.204850120Z,10,2,1108,C,B,9,12.2,100,0,165533,320804636,12.97,2,1,13.27,12,1,12.86,100,1,13.31,15,1,12.73,100,1,13.33,15,1,12.5,700,1,13.44,100,1,12.46,100,1,13.65,2,1,12.33,100,1,13.73,100,1,12.29,100,1,13.97,100,1,12.22,200,2,14.06,100,1,12.21,700,1,14.18,1400,2,12.2,100,1,14.23,200,2,ARL,327112385
,2025-07-17T16:51:49.204893061Z,2025-07-17T16:51:49.204893061Z,10,2,1108,C,B,9,12.2,100,0,165412,320804638,12.97,2,1,13.27,12,1,12.86,100,1,13.31,15,1,12.73,100,1,13.33,15,1,12.5,700,1,13.44,100,1,12.46,100,1,13.65,2,1,12.33,100,1,13.73,100,1,12.29,100,1,13.97,100,1,12.22,200,2,14.06,100,1,12.21,700,1,14.18,1400,2,12.18,700,1,14.23,200,2,ARL,327112393
,2025-07-17T16:51:49.205347703Z,2025-07-17T16:51:49.205347703Z,10,2,1108,C,B,5,12.33,100,0,165638,320804639,12.97,2,1,13.27,12,1,12.86,100,1,13.31,15,1,12.73,100,1,13.33,15,1,12.5,700,1,13.44,100,1,12.46,100,1,13.65,2,1,12.29,100,1,13.73,100,1,12.22,200,2,13.97,100,1,12.21,700,1,14.06,100,1,12.18,700,1,14.18,1400,2,12.15,700,1,14.23,200,2,ARL,327114465
,2025-07-17T16:51:49.205347703Z,2025-07-17T16:51:49.205347703Z,10,2,1108,A,B,10,12.08,100,130,165638,320804639,12.97,2,1,13.27,12,1,12.86,100,1,13.31,15,1,12.73,100,1,13.33,15,1,12.5,700,1,13.44,100,1,12.46,100,1,13.65,2,1,12.29,100,1,13.73,100,1,12.22,200,2,13.97,100,1,12.21,700,1,14.06,100,1,12.18,700,1,14.18,1400,2,12.15,700,1,14.23,200,2,ARL,387208201
,2025-07-17T16:51:49.207976677Z,2025-07-17T16:51:49.207976677Z,10,2,1108,C,A,2,13.33,15,130,165260,320804643,12.97,2,1,13.27,12,1,12.86,100,1,13.31,15,1,12.73,100,1,13.44,100,1,12.5,700,1,13.65,2,1,12.46,100,1,13.73,100,1,12.29,100,1,13.97,100,1,12.22,200,2,14.06,100,1,12.21,700,1,14.18,1400,2,12.18,700,1,14.23,200,2,12.15,700,1,14.25,100,1,ARL,386002397
,2025-07-17T16:51:49.209264359Z,2025-07-17T16:51:49.209264359Z,10,2,1108,C,B,0,12.97,2,0,165442,320804652,12.86,100,1,13.27,12,1,12.73,100,1,13.31,15,1,12.5,700,1,13.44,100,1,12.46,100,1,13.65,2,1,12.29,100,1,13.73,100,1,12.22,200,2,13.97,100,1,12.21,700,1,14.06,100,1,12.18,700,1,14.18,1400,2,12.15,700,1,14.23,200,2,12.08,100,1,14.25,100,1,ARL,378976465
,2025-07-17T16:51:49.209264359Z,2025-07-17T16:51:49.209264359Z,10,2,1108,A,B,0,12.86,2,130,165442,320804652,12.86,102,2,13.27,12,1,12.73,100,1,13.31,15,1,12.5,700,1,13.44,100,1,12.46,100,1,13.65,2,1,12.29,100,1,13.73,100,1,12.22,200,2,13.97,100,1,12.21,700,1,14.06,100,1,12.18,700,1,14.18,1400,2,12.15,700,1,14.23,200,2,12.08,100,1,14.25,100,1,ARL,387208221
,2025-07-17T16:51:49.227895926Z,2025-07-17T16:51:49.227895926Z,10,2,1108,C,B,0,12.86,100,130,165588,320804783,12.86,2,1,13.27,12,1,12.73,100,1,13.31,15,1,12.5,700,1,13.44,100,1,12.46,100,1,13.65,2,1,12.29,100,1,13.73,100,1,12.22,200,2,13.97,100,1,12.21,700,1,14.06,100,1,12.18,700,1,14.18,1400,2,12.15,700,1,14.23,200,2,12.08,100,1,14.25,100,1,ARL,327112577
,2025-07-17T16:51:49.227918298Z,2025-07-17T16:51:49.227918298Z,10,2,1108,C,A,0,13.27,12,130,165095,320804784,12.86,2,1,13.31,15,1,12.73,100,1,13.44,100,1,12.5,700,1,13.65,2,1,12.46,100,1,13.73,100,1,12.29,100,1,13.97,100,1,12.22,200,2,14.06,100,1,12.21,700,1,14.18,1400,2,12.18,700,1,14.23,200,2,12.15,700,1,14.25,100,1,12.08,100,1,14.26,100,1,ARL,387208141
,2025-07-17T16:51:49.227950521Z,2025-07-17T16:51:49.227950521Z,10,2,1108,A,B,2,12.72,100,130,165313,320804785,12.86,2,1,13.31,15,1,12.73,100,1,13.44,100,1,12.72,100,1,13.65,2,1,12.5,700,1,13.73,100,1,12.46,100,1,13.97,100,1,12.29,100,1,14.06,100,1,12.22,200,2,14.18,1400,2,12.21,700,1,14.23,200,2,12.18,700,1,14.25,100,1,12.15,700,1,14.26,100,1,ARL,387208393
,2025-07-17T16:51:49.228027215Z,2025-07-17T16:51:49.228027215Z,10,2,1108,A,A,1,13.35,100,130,165075,320804787,12.86,2,1,13.31,15,1,12.73,100,1,13.35,100,1,12.72,100,1,13.44,100,1,12.5,700,1,13.65,2,1,12.46,100,1,13.73,100,1,12.29,100,1,13.97,100,1,12.22,200,2,14.06,100,1,12.21,700,1,14.18,1400,2,12.18,700,1,14.23,200,2,12.15,700,1,14.25,100,1,ARL,387208401
,2025-07-17T16:51:49.228776421Z,2025-07-17T16:51:49.228776421Z,10,2,1108,C,B,2,12.72,100,130,164940,320804797,12.86,2,1,13.31,15,1,12.73,100,1,13.35,100,1,12.5,700,1,13.44,100,1,12.46,100,1,13.65,2,1,12.29,100,1,13.73,100,1,12.22,200,2,13.97,100,1,12.21,700,1,14.06,100,1,12.18,700,1,14.18,1400,2,12.15,700,1,14.23,200,2,12.08,100,1,14.25,100,1,ARL,387208393
,2025-07-17T16:51:49.228824994Z,2025-07-17T16:51:49.228824994Z,10,2,1108,A,B,2,12.6,100,130,165157,320804800,12.86,2,1,13.31,15,1,12.73,100,1,13.35,100,1,12.6,100,1,13.44,100,1,12.5,700,1,13.65,2,1,12.46,100,1,13.73,100,1,12.29,100,1,13.97,100,1,12.22,200,2,14.06,100,1,12.21,700,1,14.18,1400,2,12.18,700,1,14.23,200,2,12.15,700,1,14.25,100,1,ARL,387208445
,2025-07-17T16:51:49.229017895Z,2025-07-17T16:51:49.229017895Z,10,2,1108,C,B,3,12.5,700,130,165208,320804802,12.86,2,1,13.31,15,1,12.73,100,1,13.35,100,1,12.6,100,1,13.44,100,1,12.46,100,1,13.65,2,1,12.29,100,1,13.73,100,1,12.22,200,2,13.97,100,1,12.21,700,1,14.06,100,1,12.18,700,1,14.18,1400,2,12.15,700,1,14.23,200,2,12.08,100,1,14.25,100,1,ARL,216223005
,2025-07-17T16:51:49.247917413Z,2025-07-17T16:51:49.247917413Z,10,2,1108,C,B,2,12.6,100,130,165039,320804925,12.86,2,1,13.31,15,1,12.73,100,1,13.35,100,1,12.46,100,1,13.44,100,1,12.29,100,1,13.65,2,1,12.22,200,2,13.73,100,1,12.21,700,1,13.97,100,1,12.18,700,1,14.06,100,1,12.15,700,1,14.18,1400,2,12.08,100,1,14.23,200,2,11.97,100,1,14.25,100,1,ARL,387208445
,2025-07-17T16:51:49.247956413Z,2025-07-17T16:51:49.247956413Z,10,2,1108,C,A,4,13.73,100,130,165288,320804926,12.86,2,1,13.31,15,1,12.73,100,1,13.35,100,1,12.46,100,1,13.44,100,1,12.29,100,1,13.65,2,1,12.22,200,2,13.97,100,1,12.21,700,1,14.06,100,1,12.18,700,1,14.18,1400,2,12.15,700,1,14.23,200,2,12.08,100,1,14.25,100,1,11.97,100,1,14.26,100,1,ARL,379096113
,2025-07-17T16:51:49.247966903Z,2025-07-17T16:51:49.247966903Z,10,2,1108,A,B,2,12.48,100,130,165118,320804927,12.86,2,1,13.31,15,1,12.73,100,1,13.35,100,1,12.48,100,1,13.44,100,1,12.46,100,1,13.65,2,1,12.29,100,1,13.97,100,1,12.22,200,2,14.06,100,1,12.21,700,1,14.18,1400,2,12.18,700,1,14.23,200,2,12.15,700,1,14.25,100,1,12.08,100,1,14.26,100,1,ARL,387208693
,2025-07-17T16:51:49.248005919Z,2025-07-17T16:51:49.248005919Z,10,2,1108,A,A,3,13.62,100,130,165158,320804928,12.86,2,1,13.31,15,1,12.73,100,1,13.35,100,1,12.48,100,1,13.44,100,1,12.46,100,1,13.62,100,1,12.29,100,1,13.65,2,1,12.22,200,2,13.97,100,1,12.21,700,1,14.06,100,1,12.18,700,1,14.18,1400,2,12.15,700,1,14.23,200,2,12.08,100,1,14.25,100,1,ARL,387208697
,2025-07-17T16:51:49.253111250Z,2025-07-17T16:51:49.253111250Z,10,2,1108,C,B,10,11.97,100,0,165326,320804945,12.86,2,1,13.31,15,1,12.73,100,1,13.35,100,1,12.48,100,1,13.44,100,1,12.46,100,1,13.62,100,1,12.29,100,1,13.65,2,1,12.22,200,2,13.97,100,1,12.21,700,1,14.06,100,1,12.18,700,1,14.18,1400,2,12.15,700,1,14.23,200,2,12.08,100,1,14.25,100,1,ARL,387208165
,2025-07-17T16:51:49.486625091Z,2025-07-17T16:51:49.486625091Z,10,2,1108,A,B,10,11.97,100,130,165049,320807855,12.86,2,1,13.31,15,1,12.73,100,1,13.35,100,1,12.48,100,1,13.44,100,1,12.46,100,1,13.62,100,1,12.29,100,1,13.65,2,1,12.22,200,2,13.97,100,1,12.21,700,1,14.06,100,1,12.18,700,1,14.18,1400,2,12.15,700,1,14.23,200,2,12.08,100,1,14.25,100,1,ARL,387211505
,2025-07-17T16:51:49.486638813Z,2025-07-17T16:51:49.486638813Z,10,2,1108,C,B,3,12.46,100,130,165371,320807856,12.86,2,1,13.31,15,1,12.73,100,1,13.35,100,1,12.48,100,1,13.44,100,1,12.29,100,1,13.62,100,1,12.22,200,2,13.65,2,1,12.21,700,1,13.97,100,1,12.18,700,1,14.06,100,1,12.15,700,1,14.18,1400,2,12.08,100,1,14.23,200,2,11.97,100,1,14.25,100,1,ARL,43804025
,2025-07-17T16:51:49.800370631Z,2025-07-17T16:51:49.800370631Z,10,2,1108,C,B,1,12.73,100,130,165436,320817705,12.86,2,1,13.31,15,1,12.48,100,1,13.35,100,1,12.29,100,1,13.44,100,1,12.22,200,2,13.62,100,1,12.21,700,1,13.65,2,1,12.18,700,1,13.97,100,1,12.15,700,1,14.06,100,1,12.08,100,1,14.18,1400,2,11.97,100,1,14.23,200,2,11.95,200,2,14.25,100,1,ARL,44066409
,2025-07-17T16:51:49.800372140Z,2025-07-17T16:51:49.800372140Z,10,2,1108,A,B,3,12.22,100,130,165233,320817706,12.86,2,1,13.31,15,1,12.48,100,1,13.35,100,1,12.29,100,1,13.44,100,1,12.22,300,3,13.62,100,1,12.21,700,1,13.65,2,1,12.18,700,1,13.97,100,1,12.15,700,1,14.06,100,1,12.08,100,1,14.18,1400,2,11.97,100,1,14.23,200,2,11.95,200,2,14.25,100,1,ARL,387224049
,2025-07-17T16:51:49.800684387Z,2025-07-17T16:51:49.800684387Z,10,2,1108,C,B,4,12.21,700,130,165357,320817711,12.86,2,1,13.31,15,1,12.48,100,1,13.35,100,1,12.29,100,1,13.44,100,1,12.22,300,3,13.62,100,1,12.18,700,1,13.65,2,1,12.15,700,1,13.97,100,1,12.08,100,1,14.06,100,1,11.97,100,1,14.18,1400,2,11.95,200,2,14.23,200,2,11.9,700,1,14.25,100,1,ARL,387208153
,2025-07-17T16:51:49.800726814Z,2025-07-17T16:51:49.800726814Z,10,2,1108,A,B,7,12.04,700,130,165337,320817712,12.86,2,1,13.31,15,1,12.48,100,1,13.35,100,1,12.29,100,1,13.44,100,1,12.22,300,3,13.62,100,1,12.18,700,1,13.65,2,1,12.15,700,1,13.97,100,1,12.08,100,1,14.06,100,1,12.04,700,1,14.18,1400,2,11.97,100,1,14.23,200,2,11.95,200,2,14.25,100,1,ARL,387224057
,2025-07-17T16:51:49.802991246Z,2025-07-17T16:51:49.802991246Z,10,2,1108,C,B,9,11.95,100,0,165324,320817732,12.86,2,1,13.31,15,1,12.48,100,1,13.35,100,1,12.29,100,1,13.44,100,1,12.22,300,3,13.62,100,1,12.18,700,1,13.65,2,1,12.15,700,1,13.97,100,1,12.08,100,1,14.06,100,1,12.04,700,1,14.18,1400,2,11.97,100,1,14.23,200,2,11.95,100,1,14.25,100,1,ARL,387208189
,2025-07-17T16:51:49.859256253Z,2025-07-17T16:51:49.859256253Z,10,2,1108,C,B,9,11.95,100,0,165242,320818164,12.86,2,1,13.31,15,1,12.48,100,1,13.35,100,1,12.29,100,1,13.44,100,1,12.22,300,3,13.62,100,1,12.18,700,1,13.65,2,1,12.15,700,1,13.97,100,1,12.08,100,1,14.06,100,1,12.04,700,1,14.18,1400,2,11.97,100,1,14.23,200,2,11.9,700,1,14.25,100,1,ARL,387208197
,2025-07-17T16:51:49.859256253Z,2025-07-17T16:51:49.859256253Z,10,2,1108,A,B,10,11.79,100,130,165242,320818164,12.86,2,1,13.31,15,1,12.48,100,1,13.35,100,1,12.29,100,1,13.44,100,1,12.22,300,3,13.62,100,1,12.18,700,1,13.65,2,1,12.15,700,1,13.97,100,1,12.08,100,1,14.06,100,1,12.04,700,1,14.18,1400,2,11.97,100,1,14.23,200,2,11.9,700,1,14.25,100,1,ARL,387224437
,2025-07-17T16:51:49.859301062Z,2025-07-17T16:51:49.859301062Z,10,2,1108,C,B,5,12.15,700,0,165642,320818165,12.86,2,1,13.31,15,1,12.48,100,1,13.35,100,1,12.29,100,1,13.44,100,1,12.22,300,3,13.62,100,1,12.18,700,1,13.65,2,1,12.08,100,1,13.97,100,1,12.04,700,1,14.06,100,1,11.97,100,1,14.18,1400,2,11.9,700,1,14.23,200,2,11.79,200,2,14.25,100,1,ARL,387208157
,2025-07-17T16:51:49.859301512Z,2025-07-17T16:51:49.859301512Z,10,2,1108,C,B,6,12.04,700,130,165192,320818166,12.86,2,1,13.31,15,1,12.48,100,1,13.35,100,1,12.29,100,1,13.44,100,1,12.22,300,3,13.62,100,1,12.18,700,1,13.65,2,1,12.08,100,1,13.97,100,1,11.97,100,1,14.06,100,1,11.9,700,1,14.18,1400,2,11.79,200,2,14.23,200,2,11.76,100,1,14.25,100,1,ARL,387224057
,2025-07-17T16:51:49.859340670Z,2025-07-17T16:51:49.859340670Z,10,2,1108,A,B,8,11.85,700,130,165286,320818167,12.86,2,1,13.31,15,1,12.48,100,1,13.35,100,1,12.29,100,1,13.44,100,1,12.22,300,3,13.62,100,1,12.18,700,1,13.65,2,1,12.08,100,1,13.97,100,1,11.97,100,1,14.06,100,1,11.9,700,1,14.18,1400,2,11.85,700,1,14.23,200,2,11.79,200,2,14.25,100,1,ARL,387224445
,2025-07-17T16:51:49.859351324Z,2025-07-17T16:51:49.859351324Z,10,2,1108,A,B,9,11.79,700,130,165306,320818168,12.86,2,1,13.31,15,1,12.48,100,1,13.35,100,1,12.29,100,1,13.44,100,1,12.22,300,3,13.62,100,1,12.18,700,1,13.65,2,1,12.08,100,1,13.97,100,1,11.97,100,1,14.06,100,1,11.9,700,1,14.18,1400,2,11.85,700,1,14.23,200,2,11.79,900,3,14.25,100,1,ARL,387224449
,2025-07-17T16:51:49.859680717Z,2025-07-17T16:51:49.859680717Z,10,2,1108,C,B,0,12.86,2,0,165955,320818176,12.48,100,1,13.31,15,1,12.29,100,1,13.35,100,1,12.22,300,3,13.44,100,1,12.18,700,1,13.62,100,1,12.08,100,1,13.65,2,1,11.97,100,1,13.97,100,1,11.9,700,1,14.06,100,1,11.85,700,1,14.18,1400,2,11.79,900,3,14.23,200,2,11.76,100,1,14.25,100,1,ARL,387208221
,2025-07-17T16:51:49.859680717Z,2025-07-17T16:51:49.859680717Z,10,2,1108,A,B,0,12.48,2,130,165955,320818176,12.48,102,2,13.31,15,1,12.29,100,1,13.35,100,1,12.22,300,3,13.44,100,1,12.18,700,1,13.62,100,1,12.08,100,1,13.65,2,1,11.97,100,1,13.97,100,1,11.9,700,1,14.06,100,1,11.85,700,1,14.18,1400,2,11.79,900,3,14.23,200,2,11.76,100,1,14.25,100,1,ARL,387224461
,2025-07-17T16:51:49.859735317Z,2025-07-17T16:51:49.859735317Z,10,2,1108,C,B,10,11.74,100,0,165559,320818178,12.48,102,2,13.31,15,1,12.29,100,1,13.35,100,1,12.22,300,3,13.44,100,1,12.18,700,1,13.62,100,1,12.08,100,1,13.65,2,1,11.97,100,1,13.97,100,1,11.9,700,1,14.06,100,1,11.85,700,1,14.18,1400,2,11.79,900,3,14.23,200,2,11.76,100,1,14.25,100,1,ARL,387208725
,2025-07-17T16:51:49.859735317Z,2025-07-17T16:51:49.859735317Z,10,2,1108,A,B,10,11.69,100,130,165559,320818178,12.48,102,2,13.31,15,1,12.29,100,1,13.35,100,1,12.22,300,3,13.44,100,1,12.18,700,1,13.62,100,1,12.08,100,1,13.65,2,1,11.97,100,1,13.97,100,1,11.9,700,1,14.06,100,1,11.85,700,1,14.18,1400,2,11.79,900,3,14.23,200,2,11.76,100,1,14.25,100,1,ARL,387224465
,2025-07-17T16:51:49.859769986Z,2025-07-17T16:51:49.859769986Z,10,2,1108,C,B,1,12.29,100,130,165019,320818179,12.48,102,2,13.31,15,1,12.22,300,3,13.35,100,1,12.18,700,1,13.44,100,1,12.08,100,1,13.62,100,1,11.97,100,1,13.65,2,1,11.9,700,1,13.97,100,1,11.85,700,1,14.06,100,1,11.79,900,3,14.18,1400,2,11.76,100,1,14.23,200,2,11.69,100,1,14.25,100,1,ARL,387208173
,2025-07-17T16:51:49.859810002Z,2025-07-17T16:51:49.859810002Z,10,2,1108,C,B,2,12.18,700,130,165260,320818180,12.48,102,2,13.31,15,1,12.22,300,3,13.35,100,1,12.08,100,1,13.44,100,1,11.97,100,1,13.62,100,1,11.9,700,1,13.65,2,1,11.85,700,1,13.97,100,1,11.79,900,3,14.06,100,1,11.76,100,1,14.18,1400,2,11.69,100,1,14.23,200,2,11.57,200,2,14.25,100,1,ARL,387208181
,2025-07-17T16:51:49.860119158Z,2025-07-17T16:51:49.860119158Z,10,2,1108,A,B,4,11.92,100,130,165298,320818186,12.48,102,2,13.31,15,1,12.22,300,3,13.35,100,1,12.08,100,1,13.44,100,1,11.97,100,1,13.62,100,1,11.92,100,1,13.65,2,1,11.9,700,1,13.97,100,1,11.85,700,1,14.06,100,1,11.79,900,3,14.18,1400,2,11.76,100,1,14.23,200,2,11.69,100,1,14.25,100,1,ARL,387224477
,2025-07-17T16:51:49.860256159Z,2025-07-17T16:51:49.860256159Z,10,2,1108,A,B,7,11.82,700,130,165241,320818196,12.48,102,2,13.31,15,1,12.22,300,3,13.35,100,1,12.08,100,1,13.44,100,1,11.97,100,1,13.62,100,1,11.92,100,1,13.65,2,1,11.9,700,1,13.97,100,1,11.85,700,1,14.06,100,1,11.82,700,1,14.18,1400,2,11.79,900,3,14.23,200,2,11.76,100,1,14.25,100,1,ARL,387224481
,2025-07-17T16:51:49.861191695Z,2025-07-17T16:51:49.861191695Z,10,2,1108,C,B,8,11.79,100,0,165285,320818220,12.48,102,2,13.31,15,1,12.22,300,3,13.35,100,1,12.08,100,1,13.44,100,1,11.97,100,1,13.62,100,1,11.92,100,1,13.65,2,1,11.9,700,1,13.97,100,1,11.85,700,1,14.06,100,1,11.82,700,1,14.18,1400,2,11.79,800,2,14.23,200,2,11.76,100,1,14.25,100,1,ARL,387224105
,2025-07-17T16:51:49.866210978Z,2025-07-17T16:51:49.866210978Z,10,2,1108,C,B,0,12.48,100,130,165541,320818236,12.48,2,1,13.31,15,1,12.22,300,3,13.35,100,1,12.08,100,1,13.44,100,1,11.97,100,1,13.62,100,1,11.92,100,1,13.65,2,1,11.9,700,1,13.97,100,1,11.85,700,1,14.06,100,1,11.82,700,1,14.18,1400,2,11.79,800,2,14.23,200,2,11.76,100,1,14.25,100,1,ARL,387208693
,2025-07-17T16:51:49.866261553Z,2025-07-17T16:51:49.866261553Z,10,2,1108,A,B,1,12.23,100,130,165639,320818237,12.48,2,1,13.31,15,1,12.23,100,1,13.35,100,1,12.22,300,3,13.44,100,1,12.08,100,1,13.62,100,1,11.97,100,1,13.65,2,1,11.92,100,1,13.97,100,1,11.9,700,1,14.06,100,1,11.85,700,1,14.18,1400,2,11.82,700,1,14.23,200,2,11.79,800,2,14.25,100,1,ARL,387224537
,2025-07-17T16:51:49.883908795Z,2025-07-17T16:51:49.883908795Z,10,2,1108,C,B,9,11.79,100,0,165168,320818367,12.48,2,1,13.31,15,1,12.23,100,1,13.35,100,1,12.22,300,3,13.44,100,1,12.08,100,1,13.62,100,1,11.97,100,1,13.65,2,1,11.92,100,1,13.97,100,1,11.9,700,1,14.06,100,1,11.85,700,1,14.18,1400,2,11.82,700,1,14.23,200,2,11.79,700,1,14.25,100,1,ARL,387224437
,2025-07-17T16:51:50.208210239Z,2025-07-17T16:51:50.208210239Z,10,2,1108,C,B,3,12.08,100,130,165108,320822967,12.48,2,1,13.31,15,1,12.23,100,1,13.35,100,1,12.22,300,3,13.44,100,1,11.97,100,1,13.62,100,1,11.92,100,1,13.65,2,1,11.9,700,1,13.97,100,1,11.85,700,1,14.06,100,1,11.82,700,1,14.18,1400,2,11.79,700,1,14.23,200,2,11.76,100,1,14.25,100,1,ARL,387208201
,2025-07-17T16:51:50.208317118Z,2025-07-17T16:51:50.208317118Z,10,2,1108,A,B,10,11.72,100,130,165336,320822970,12.48,2,1,13.31,15,1,12.23,100,1,13.35,100,1,12.22,300,3,13.44,100,1,11.97,100,1,13.62,100,1,11.92,100,1,13.65,2,1,11.9,700,1,13.97,100,1,11.85,700,1,14.06,100,1,11.82,700,1,14.18,1400,2,11.79,700,1,14.23,200,2,11.76,100,1,14.25,100,1,ARL,387229905
,2025-07-17T16:51:50.698845651Z,2025-07-17T16:51:50.698845651Z,10,2,1108,A,A,0,13.29,15,130,165515,320827751,12.48,2,1,13.29,15,1,12.23,100,1,13.31,15,1,12.22,300,3,13.35,100,1,11.97,100,1,13.44,100,1,11.92,100,1,13.62,100,1,11.9,700,1,13.65,2,1,11.85,700,1,13.97,100,1,11.82,700,1,14.06,100,1,11.79,700,1,14.18,1400,2,11.76,100,1,14.23,200,2,ARL,387234697
,2025-07-17T16:51:51.700995710Z,2025-07-17T16:51:51.700995710Z,10,2,1108,A,A,2,13.33,100,130,165423,320835508,12.48,2,1,13.29,15,1,12.23,100,1,13.31,15,1,12.22,300,3,13.33,100,1,11.97,100,1,13.35,100,1,11.92,100,1,13.44,100,1,11.9,700,1,13.62,100,1,11.85,700,1,13.65,2,1,11.82,700,1,13.97,100,1,11.79,700,1,14.06,100,1,11.76,100,1,14.18,1400,2,ARL,387246049
,2025-07-17T16:51:51.713795931Z,2025-07-17T16:51:51.713795931Z,10,2,1108,A,A,9,14.11,100,130,165595,320835557,12.48,2,1,13.29,15,1,12.23,100,1,13.31,15,1,12.22,300,3,13.33,100,1,11.97,100,1,13.35,100,1,11.92,100,1,13.44,100,1,11.9,700,1,13.62,100,1,11.85,700,1,13.65,2,1,11.82,700,1,13.97,100,1,11.79,700,1,14.06,100,1,11.76,100,1,14.11,100,1,ARL,387246169
,2025-07-17T16:51:51.724992350Z,2025-07-17T16:51:51.724992350Z,10,2,1108,C,A,3,13.35,100,130,165438,320835691,12.48,2,1,13.29,15,1,12.23,100,1,13.31,15,1,12.22,300,3,13.33,100,1,11.97,100,1,13.44,100,1,11.92,100,1,13.62,100,1,11.9,700,1,13.65,2,1,11.85,700,1,13.97,100,1,11.82,700,1,14.06,100,1,11.79,700,1,14.11,100,1,11.76,100,1,14.18,1400,2,ARL,387208401
,2025-07-17T16:51:54.352829325Z,2025-07-17T16:51:54.352829325Z,10,2,1108,A,A,7,14.06,700,130,165656,320864203,12.48,2,1,13.29,15,1,12.23,100,1,13.31,15,1,12.22,300,3,13.33,100,1,11.97,100,1,13.44,100,1,11.92,100,1,13.62,100,1,11.9,700,1,13.65,2,1,11.85,700,1,13.97,100,1,11.82,700,1,14.06,800,2,11.79,700,1,14.11,100,1,11.76,100,1,14.18,1400,2,ARL,387277657
,2025-07-17T16:51:57.165852611Z,2025-07-17T16:51:57.165852611Z,10,2,1108,A,A,10,14.2,700,130,165368,320905527,12.48,2,1,13.29,15,1,12.23,100,1,13.31,15,1,12.22,300,3,13.33,100,1,11.97,100,1,13.44,100,1,11.92,100,1,13.62,100,1,11.9,700,1,13.65,2,1,11.85,700,1,13.97,100,1,11.82,700,1,14.06,800,2,11.79,700,1,14.11,100,1,11.76,100,1,14.18,1400,2,ARL,387313797
,2025-07-17T16:52:09.189496109Z,2025-07-17T16:52:09.189496109Z,10,2,1108,C,A,5,13.65,2,0,165831,321054296,12.48,2,1,13.29,15,1,12.23,100,1,13.31,15,1,12.22,300,3,13.33,100,1,11.97,100,1,13.44,100,1,11.92,100,1,13.62,100,1,11.9,700,1,13.97,100,1,11.85,700,1,14.06,800,2,11.82,700,1,14.11,100,1,11.79,700,1,14.18,1400,2,11.76,100,1,14.2,700,1,ARL,379801189
,2025-07-17T16:52:09.189496109Z,2025-07-17T16:52:09.189496109Z,10,2,1108,A,A,3,13.4,2,130,165831,321054296,12.48,2,1,13.29,15,1,12.23,100,1,13.31,15,1,12.22,300,3,13.33,100,1,11.97,100,1,13.4,2,1,11.92,100,1,13.44,100,1,11.9,700,1,13.62,100,1,11.85,700,1,13.97,100,1,11.82,700,1,14.06,800,2,11.79,700,1,14.11,100,1,11.76,100,1,14.18,1400,2,ARL,387521285
,2025-07-17T16:52:25.385796835Z,2025-07-17T16:52:25.385796835Z,10,2,1108,C,A,3,13.4,2,0,165648,321280124,12.48,2,1,13.29,15,1,12.23,100,1,13.31,15,1,12.22,300,3,13.33,100,1,11.97,100,1,13.44,100,1,11.92,100,1,13.62,100,1,11.9,700,1,13.97,100,1,11.85,700,1,14.06,800,2,11.82,700,1,14.11,100,1,11.79,700,1,14.18,1400,2,11.76,100,1,14.2,700,1,ARL,387521285
,2025-07-17T16:52:25.385796835Z,2025-07-17T16:52:25.385796835Z,10,2,1108,A,A,3,13.34,2,130,165648,321280124,12.48,2,1,13.29,15,1,12.23,100,1,13.31,15,1,12.22,300,3,13.33,100,1,11.97,100,1,13.34,2,1,11.92,100,1,13.44,100,1,11.9,700,1,13.62,100,1,11.85,700,1,13.97,100,1,11.82,700,1,14.06,800,2,11.79,700,1,14.11,100,1,11.76,100,1,14.18,1400,2,ARL,387814377
,2025-07-17T16:52:44.599769693Z,2025-07-17T16:52:44.599769693Z,10,2,1108,C,A,1,13.31,15,130,166793,321507803,12.48,2,1,13.29,15,1,12.23,100,1,13.33,100,1,12.22,300,3,13.34,2,1,11.97,100,1,13.44,100,1,11.92,100,1,13.62,100,1,11.9,700,1,13.97,100,1,11.85,700,1,14.06,800,2,11.82,700,1,14.11,100,1,11.79,700,1,14.18,1400,2,11.76,100,1,14.2,700,1,ARL,386239877
,2025-07-17T16:52:45.910353639Z,2025-07-17T16:52:45.910353639Z,10,2,1108,A,A,0,13.27,15,130,165383,321528658,12.48,2,1,13.27,15,1,12.23,100,1,13.29,15,1,12.22,300,3,13.33,100,1,11.97,100,1,13.34,2,1,11.92,100,1,13.44,100,1,11.9,700,1,13.62,100,1,11.85,700,1,13.97,100,1,11.82,700,1,14.06,800,2,11.79,700,1,14.11,100,1,11.76,100,1,14.18,1400,2,ARL,388154969
,2025-07-17T16:52:45.913010349Z,2025-07-17T16:52:45.913010349Z,10,2,1108,A,A,2,13.31,100,130,165135,321528927,12.48,2,1,13.27,15,1,12.23,100,1,13.29,15,1,12.22,300,3,13.31,100,1,11.97,100,1,13.33,100,1,11.92,100,1,13.34,2,1,11.9,700,1,13.44,100,1,11.85,700,1,13.62,100,1,11.82,700,1,13.97,100,1,11.79,700,1,14.06,800,2,11.76,100,1,14.11,100,1,ARL,388155109
,2025-07-17T16:52:45.915732713Z,2025-07-17T16:52:45.915732713Z,10,2,1108,C,A,3,13.33,100,130,165255,321528989,12.48,2,1,13.27,15,1,12.23,100,1,13.29,15,1,12.22,300,3,13.31,100,1,11.97,100,1,13.34,2,1,11.92,100,1,13.44,100,1,11.9,700,1,13.62,100,1,11.85,700,1,13.97,100,1,11.82,700,1,14.06,800,2,11.79,700,1,14.11,100,1,11.76,100,1,14.18,1400,2,ARL,387246049
,2025-07-17T16:53:02.591772327Z,2025-07-17T16:53:02.591772327Z,10,2,1108,C,A,3,13.34,2,0,165627,321769923,12.48,2,1,13.27,15,1,12.23,100,1,13.29,15,1,12.22,300,3,13.31,100,1,11.97,100,1,13.44,100,1,11.92,100,1,13.62,100,1,11.9,700,1,13.97,100,1,11.85,700,1,14.06,800,2,11.82,700,1,14.11,100,1,11.79,700,1,14.18,1400,2,11.76,100,1,14.2,700,1,ARL,387814377
,2025-07-17T16:53:02.591772327Z,2025-07-17T16:53:02.591772327Z,10,2,1108,A,A,2,13.31,2,130,165627,321769923,12.48,2,1,13.27,15,1,12.23,100,1,13.29,15,1,12.22,300,3,13.31,102,2,11.97,100,1,13.44,100,1,11.92,100,1,13.62,100,1,11.9,700,1,13.97,100,1,11.85,700,1,14.06,800,2,11.82,700,1,14.11,100,1,11.79,700,1,14.18,1400,2,11.76,100,1,14.2,700,1,ARL,388467165
,2025-07-17T16:53:04.318857617Z,2025-07-17T16:53:04.318857617Z,10,2,1108,C,A,0,13.27,15,128,169881,321820208,12.48,2,1,13.29,15,1,12.23,100,1,13.31,102,2,12.22,300,3,13.44,100,1,11.97,100,1,13.62,100,1,11.92,100,1,13.97,100,1,11.9,700,1,14.06,800,2,11.85,700,1,14.11,100,1,11.82,700,1,14.18,1400,2,11.79,700,1,14.2,700,1,11.76,100,1,14.23,200,2,ARL,388154969
,2025-07-17T16:53:04.327496343Z,2025-07-17T16:53:04.327496343Z,10,2,1108,C,A,0,13.29,15,130,165382,321823264,12.48,2,1,13.31,102,2,12.23,100,1,13.44,100,1,12.22,300,3,13.62,100,1,11.97,100,1,13.97,100,1,11.92,100,1,14.06,800,2,11.9,700,1,14.11,100,1,11.85,700,1,14.18,1400,2,11.82,700,1,14.2,700,1,11.79,700,1,14.23,200,2,11.76,100,1,14.26,100,1,ARL,387234697
,2025-07-17T16:53:05.349324407Z,2025-07-17T16:53:05.349324407Z,10,2,1108,A,A,0,13.27,15,130,165302,321852281,12.48,2,1,13.27,15,1,12.23,100,1,13.31,102,2,12.22,300,3,13.44,100,1,11.97,100,1,13.62,100,1,11.92,100,1,13.97,100,1,11.9,700,1,14.06,800,2,11.85,700,1,14.11,100,1,11.82,700,1,14.18,1400,2,11.79,700,1,14.2,700,1,11.76,100,1,14.23,200,2,ARL,388572113
,2025-07-17T16:53:06.896211496Z,2025-07-17T16:53:06.896211496Z,10,2,1108,C,A,0,13.27,15,130,165855,321876648,12.48,2,1,13.31,102,2,12.23,100,1,13.44,100,1,12.22,300,3,13.62,100,1,11.97,100,1,13.97,100,1,11.92,100,1,14.06,800,2,11.9,700,1,14.11,100,1,11.85,700,1,14.18,1400,2,11.82,700,1,14.2,700,1,11.79,700,1,14.23,200,2,11.76,100,1,14.26,100,1,ARL,388572113
,2025-07-17T16:53:26.171430778Z,2025-07-17T16:53:26.171430778Z,10,2,1108,C,A,0,13.31,100,130,165819,322130469,12.48,2,1,13.31,2,1,12.23,100,1,13.44,100,1,12.22,300,3,13.62,100,1,11.97,100,1,13.97,100,1,11.92,100,1,14.06,800,2,11.9,700,1,14.11,100,1,11.85,700,1,14.18,1400,2,11.82,700,1,14.2,700,1,11.79,700,1,14.23,200,2,11.76,100,1,14.26,100,1,ARL,388155109
,2025-07-17T16:53:26.190494051Z,2025-07-17T16:53:26.190494051Z,10,2,1108,C,A,2,13.62,100,130,165507,322130570,12.48,2,1,13.31,2,1,12.23,100,1,13.44,100,1,12.22,300,3,13.97,100,1,11.97,100,1,14.06,800,2,11.92,100,1,14.11,100,1,11.9,700,1,14.18,1400,2,11.85,700,1,14.2,700,1,11.82,700,1,14.23,200,2,11.79,700,1,14.26,100,1,11.76,100,1,14.27,200,2,ARL,387208697
,2025-07-17T16:53:26.190544047Z,2025-07-17T16:53:26.190544047Z,10,2,1108,A,A,2,13.71,100,130,165353,322130571,12.48,2,1,13.31,2,1,12.23,100,1,13.44,100,1,12.22,300,3,13.71,100,1,11.97,100,1,13.97,100,1,11.92,100,1,14.06,800,2,11.9,700,1,14.11,100,1,11.85,700,1,14.18,1400,2,11.82,700,1,14.2,700,1,11.79,700,1,14.23,200,2,11.76,100,1,14.26,100,1,ARL,388943785
,2025-07-17T16:53:30.899381745Z,2025-07-17T16:53:30.899381745Z,10,2,1108,A,A,0,13.25,15,130,165283,322188510,12.48,2,1,13.25,15,1,12.23,100,1,13.31,2,1,12.22,300,3,13.44,100,1,11.97,100,1,13.71,100,1,11.92,100,1,13.97,100,1,11.9,700,1,14.06,800,2,11.85,700,1,14.11,100,1,11.82,700,1,14.18,1400,2,11.79,700,1,14.2,700,1,11.76,100,1,14.23,200,2,ARL,389031981
,2025-07-17T16:53:40.523811512Z,2025-07-17T16:53:40.523811512Z,10,2,1108,A,A,1,13.29,100,130,165539,322295689,12.48,2,1,13.25,15,1,12.23,100,1,13.29,100,1,12.22,300,3,13.31,2,1,11.97,100,1,13.44,100,1,11.92,100,1,13.71,100,1,11.9,700,1,13.97,100,1,11.85,700,1,14.06,800,2,11.82,700,1,14.11,100,1,11.79,700,1,14.18,1400,2,11.76,100,1,14.2,700,1,ARL,389168405
,2025-07-17T16:53:40.543834425Z,2025-07-17T16:53:40.543834425Z,10,2,1108,C,A,4,13.71,100,130,165539,322295865,12.48,2,1,13.25,15,1,12.23,100,1,13.29,100,1,12.22,300,3,13.31,2,1,11.97,100,1,13.44,100,1,11.92,100,1,13.97,100,1,11.9,700,1,14.06,800,2,11.85,700,1,14.11,100,1,11.82,700,1,14.18,1400,2,11.79,700,1,14.2,700,1,11.76,100,1,14.23,200,2,ARL,388943785
,2025-07-17T16:53:40.543887042Z,2025-07-17T16:53:40.543887042Z,10,2,1108,A,A,4,13.56,100,130,165262,322295866,12.48,2,1,13.25,15,1,12.23,100,1,13.29,100,1,12.22,300,3,13.31,2,1,11.97,100,1,13.44,100,1,11.92,100,1,13.56,100,1,11.9,700,1,13.97,100,1,11.85,700,1,14.06,800,2,11.82,700,1,14.11,100,1,11.79,700,1,14.18,1400,2,11.76,100,1,14.2,700,1,ARL,389168529
,2025-07-17T16:53:58.389483902Z,2025-07-17T16:53:58.389483902Z,10,2,1108,C,A,2,13.31,2,0,165642,322603434,12.48,2,1,13.25,15,1,12.23,100,1,13.29,100,1,12.22,300,3,13.44,100,1,11.97,100,1,13.56,100,1,11.92,100,1,13.97,100,1,11.9,700,1,14.06,800,2,11.85,700,1,14.11,100,1,11.82,700,1,14.18,1400,2,11.79,700,1,14.2,700,1,11.76,100,1,14.23,200,2,ARL,388467165
,2025-07-17T16:53:58.389483902Z,2025-07-17T16:53:58.389483902Z,10,2,1108,A,A,1,13.29,2,130,165642,322603434,12.48,2,1,13.25,15,1,12.23,100,1,13.29,102,2,12.22,300,3,13.44,100,1,11.97,100,1,13.56,100,1,11.92,100,1,13.97,100,1,11.9,700,1,14.06,800,2,11.85,700,1,14.11,100,1,11.82,700,1,14.18,1400,2,11.79,700,1,14.2,700,1,11.76,100,1,14.23,200,2,ARL,389540593
,2025-07-17T16:54:21.081881368Z,2025-07-17T16:54:21.081881368Z,10,2,1108,A,A,1,13.27,100,130,165365,322944902,12.48,2,1,13.25,15,1,12.23,100,1,13.27,100,1,12.22,300,3,13.29,102,2,11.97,100,1,13.44,100,1,11.92,100,1,13.56,100,1,11.9,700,1,13.97,100,1,11.85,700,1,14.06,800,2,11.82,700,1,14.11,100,1,11.79,700,1,14.18,1400,2,11.76,100,1,14.2,700,1,ARL,389948353
,2025-07-17T16:54:21.084582385Z,2025-07-17T16:54:21.084582385Z,10,2,1108,C,A,2,13.29,100,128,167248,322945104,12.48,2,1,13.25,15,1,12.23,100,1,13.27,100,1,12.22,300,3,13.29,2,1,11.97,100,1,13.44,100,1,11.92,100,1,13.56,100,1,11.9,700,1,13.97,100,1,11.85,700,1,14.06,800,2,11.82,700,1,14.11,100,1,11.79,700,1,14.18,1400,2,11.76,100,1,14.2,700,1,ARL,389168405
,2025-07-17T16:54:22.887832854Z,2025-07-17T16:54:22.887832854Z,10,2,1108,C,A,10,14.23,100,0,165655,323001879,12.48,2,1,13.25,15,1,12.23,100,1,13.27,100,1,12.22,300,3,13.29,2,1,11.97,100,1,13.44,100,1,11.92,100,1,13.56,100,1,11.9,700,1,13.97,100,1,11.85,700,1,14.06,800,2,11.82,700,1,14.11,100,1,11.79,700,1,14.18,1400,2,11.76,100,1,14.2,700,1,ARL,384964617
,2025-07-17T16:54:22.887832854Z,2025-07-17T16:54:22.887832854Z,10,2,1108,A,A,7,14.11,100,130,165655,323001879,12.48,2,1,13.25,15,1,12.23,100,1,13.27,100,1,12.22,300,3,13.29,2,1,11.97,100,1,13.44,100,1,11.92,100,1,13.56,100,1,11.9,700,1,13.97,100,1,11.85,700,1,14.06,800,2,11.82,700,1,14.11,200,2,11.79,700,1,14.18,1400,2,11.76,100,1,14.2,700,1,ARL,390012165
,2025-07-17T16:54:22.888082967Z,2025-07-17T16:54:22.888082967Z,10,2,1108,C,A,10,14.23,100,0,165751,323001880,12.48,2,1,13.25,15,1,12.23,100,1,13.27,100,1,12.22,300,3,13.29,2,1,11.97,100,1,13.44,100,1,11.92,100,1,13.56,100,1,11.9,700,1,13.97,100,1,11.85,700,1,14.06,800,2,11.82,700,1,14.11,200,2,11.79,700,1,14.18,1400,2,11.76,100,1,14.2,700,1,ARL,384964613
,2025-07-17T16:54:22.888082967Z,2025-07-17T16:54:22.888082967Z,10,2,1108,A,A,7,14.11,100,130,165751,323001880,12.48,2,1,13.25,15,1,12.23,100,1,13.27,100,1,12.22,300,3,13.29,2,1,11.97,100,1,13.44,100,1,11.92,100,1,13.56,100,1,11.9,700,1,13.97,100,1,11.85,700,1,14.06,800,2,11.82,700,1,14.11,300,3,11.79,700,1,14.18,1400,2,11.76,100,1,14.2,700,1,ARL,390012177
,2025-07-17T16:54:22.889930161Z,2025-07-17T16:54:22.889930161Z,10,2,1108,A,A,0,13.23,15,130,165544,323001883,12.48,2,1,13.23,15,1,12.23,100,1,13.25,15,1,12.22,300,3,13.27,100,1,11.97,100,1,13.29,2,1,11.92,100,1,13.44,100,1,11.9,700,1,13.56,100,1,11.85,700,1,13.97,100,1,11.82,700,1,14.06,800,2,11.79,700,1,14.11,300,3,11.76,100,1,14.18,1400,2,ARL,390012185
,2025-07-17T16:54:25.387036791Z,2025-07-17T16:54:25.387036791Z,10,2,1108,C,A,3,13.29,2,0,165639,323044153,12.48,2,1,13.23,15,1,12.23,100,1,13.25,15,1,12.22,300,3,13.27,100,1,11.97,100,1,13.44,100,1,11.92,100,1,13.56,100,1,11.9,700,1,13.97,100,1,11.85,700,1,14.06,800,2,11.82,700,1,14.11,300,3,11.79,700,1,14.18,1400,2,11.76,100,1,14.2,700,1,ARL,389540593
,2025-07-17T16:54:25.387036791Z,2025-07-17T16:54:25.387036791Z,10,2,1108,A,A,2,13.27,2,130,165639,323044153,12.48,2,1,13.23,15,1,12.23,100,1,13.25,15,1,12.22,300,3,13.27,102,2,11.97,100,1,13.44,100,1,11.92,100,1,13.56,100,1,11.9,700,1,13.97,100,1,11.85,700,1,14.06,800,2,11.82,700,1,14.11,300,3,11.79,700,1,14.18,1400,2,11.76,100,1,14.2,700,1,ARL,390060109
,2025-07-17T16:54:29.752451645Z,2025-07-17T16:54:29.752451645Z,10,2,1108,A,A,1,13.25,100,130,165650,323103133,12.48,2,1,13.23,15,1,12.23,100,1,13.25,115,2,12.22,300,3,13.27,102,2,11.97,100,1,13.44,100,1,11.92,100,1,13.56,100,1,11.9,700,1,13.97,100,1,11.85,700,1,14.06,800,2,11.82,700,1,14.11,300,3,11.79,700,1,14.18,1400,2,11.76,100,1,14.2,700,1,ARL,390133645
,2025-07-17T16:54:29.752502545Z,2025-07-17T16:54:29.752502545Z,10,2,1108,T,A,0,13.23,15,0,169818,323103134,12.48,2,1,13.25,115,2,12.23,100,1,13.27,102,2,12.22,300,3,13.44,100,1,11.97,100,1,13.56,100,1,11.92,100,1,13.97,100,1,11.9,700,1,14.06,800,2,11.85,700,1,14.11,300,3,11.82,700,1,14.18,1400,2,11.79,700,1,14.2,700,1,11.76,100,1,14.26,100,1,ARL,0
,2025-07-17T16:54:29.752502545Z,2025-07-17T16:54:29.752502545Z,10,2,1108,T,N,0,13.24,50,0,169818,323103135,12.48,2,1,13.25,115,2,12.23,100,1,13.27,102,2,12.22,300,3,13.44,100,1,11.97,100,1,13.56,100,1,11.92,100,1,13.97,100,1,11.9,700,1,14.06,800,2,11.85,700,1,14.11,300,3,11.82,700,1,14.18,1400,2,11.79,700,1,14.2,700,1,11.76,100,1,14.26,100,1,ARL,0
,2025-07-17T16:54:29.752502545Z,2025-07-17T16:54:29.752502545Z,10,2,1108,T,A,0,13.25,15,0,169818,323103136,12.48,2,1,13.25,100,1,12.23,100,1,13.27,102,2,12.22,300,3,13.44,100,1,11.97,100,1,13.56,100,1,11.92,100,1,13.97,100,1,11.9,700,1,14.06,800,2,11.85,700,1,14.11,300,3,11.82,700,1,14.18,1400,2,11.79,700,1,14.2,700,1,11.76,100,1,14.26,100,1,ARL,0
,2025-07-17T16:54:29.752502545Z,2025-07-17T16:54:29.752502545Z,10,2,1108,T,A,0,13.25,50,130,169818,323103137,12.48,2,1,13.25,50,1,12.23,100,1,13.27,102,2,12.22,300,3,13.44,100,1,11.97,100,1,13.56,100,1,11.92,100,1,13.97,100,1,11.9,700,1,14.06,800,2,11.85,700,1,14.11,300,3,11.82,700,1,14.18,1400,2,11.79,700,1,14.2,700,1,11.76,100,1,14.26,100,1,ARL,0
,2025-07-17T16:54:29.752536458Z,2025-07-17T16:54:29.752536458Z,10,2,1108,A,B,0,12.86,5,130,165240,323103138,12.86,5,1,13.25,50,1,12.48,2,1,13.27,102,2,12.23,100,1,13.44,100,1,12.22,300,3,13.56,100,1,11.97,100,1,13.97,100,1,11.92,100,1,14.06,800,2,11.9,700,1,14.11,300,3,11.85,700,1,14.18,1400,2,11.82,700,1,14.2,700,1,11.79,700,1,14.26,100,1,ARL,390133657
,2025-07-17T16:54:29.752550566Z,2025-07-17T16:54:29.752550566Z,10,2,1108,A,B,0,12.86,1,130,165104,323103139,12.86,6,2,13.25,50,1,12.48,2,1,13.27,102,2,12.23,100,1,13.44,100,1,12.22,300,3,13.56,100,1,11.97,100,1,13.97,100,1,11.92,100,1,14.06,800,2,11.9,700,1,14.11,300,3,11.85,700,1,14.18,1400,2,11.82,700,1,14.2,700,1,11.79,700,1,14.26,100,1,ARL,390133665
,2025-07-17T16:54:29.752572767Z,2025-07-17T16:54:29.752572767Z,10,2,1108,A,B,1,12.63,3,130,165142,323103140,12.86,6,2,13.25,50,1,12.63,3,1,13.27,102,2,12.48,2,1,13.44,100,1,12.23,100,1,13.56,100,1,12.22,300,3,13.97,100,1,11.97,100,1,14.06,800,2,11.92,100,1,14.11,300,3,11.9,700,1,14.18,1400,2,11.85,700,1,14.2,700,1,11.82,700,1,14.26,100,1,ARL,390133673
,2025-07-17T16:54:29.752820958Z,2025-07-17T16:54:29.752820958Z,10,2,1108,A,B,0,13.12,1,128,168417,323103150,13.12,1,1,13.25,50,1,12.86,6,2,13.27,102,2,12.63,3,1,13.44,100,1,12.48,2,1,13.56,100,1,12.23,100,1,13.97,100,1,12.22,300,3,14.06,800,2,11.97,100,1,14.11,300,3,11.92,100,1,14.18,1400,2,11.9,700,1,14.2,700,1,11.85,700,1,14.26,100,1,ARL,390133713
,2025-07-17T16:54:29.753192989Z,2025-07-17T16:54:29.753192989Z,10,2,1108,C,A,5,14.06,100,130,165701,323103186,13.12,1,1,13.25,50,1,12.86,6,2,13.27,102,2,12.63,3,1,13.44,100,1,12.48,2,1,13.56,100,1,12.23,100,1,13.97,100,1,12.22,300,3,14.06,700,1,11.97,100,1,14.11,300,3,11.92,100,1,14.18,1400,2,11.9,700,1,14.2,700,1,11.85,700,1,14.26,100,1,ARL,379095981
,2025-07-17T16:54:29.753550555Z,2025-07-17T16:54:29.753550555Z,10,2,1108,A,A,4,13.86,100,130,165193,323103207,13.12,1,1,13.25,50,1,12.86,6,2,13.27,102,2,12.63,3,1,13.44,100,1,12.48,2,1,13.56,100,1,12.23,100,1,13.86,100,1,12.22,300,3,13.97,100,1,11.97,100,1,14.06,700,1,11.92,100,1,14.11,300,3,11.9,700,1,14.18,1400,2,11.85,700,1,14.2,700,1,ARL,390133893
,2025-07-17T16:54:29.753552806Z,2025-07-17T16:54:29.753552806Z,10,2,1108,C,B,1,12.86,5,130,165434,323103208,13.12,1,1,13.25,50,1,12.86,1,1,13.27,102,2,12.63,3,1,13.44,100,1,12.48,2,1,13.56,100,1,12.23,100,1,13.86,100,1,12.22,300,3,13.97,100,1,11.97,100,1,14.06,700,1,11.92,100,1,14.11,300,3,11.9,700,1,14.18,1400,2,11.85,700,1,14.2,700,1,ARL,390133657
,2025-07-17T16:54:29.753564036Z,2025-07-17T16:54:29.753564036Z,10,2,1108,C,B,1,12.86,1,130,164986,323103209,13.12,1,1,13.25,50,1,12.63,3,1,13.27,102,2,12.48,2,1,13.44,100,1,12.23,100,1,13.56,100,1,12.22,300,3,13.86,100,1,11.97,100,1,13.97,100,1,11.92,100,1,14.06,700,1,11.9,700,1,14.11,300,3,11.85,700,1,14.18,1400,2,11.82,700,1,14.2,700,1,ARL,390133665
,2025-07-17T16:54:29.753868181Z,2025-07-17T16:54:29.753868181Z,10,2,1108,C,B,0,13.12,1,130,164799,323103214,12.63,3,1,13.25,50,1,12.48,2,1,13.27,102,2,12.23,100,1,13.44,100,1,12.22,300,3,13.56,100,1,11.97,100,1,13.86,100,1,11.92,100,1,13.97,100,1,11.9,700,1,14.06,700,1,11.85,700,1,14.11,300,3,11.82,700,1,14.18,1400,2,11.79,700,1,14.2,700,1,ARL,390133713
,2025-07-17T16:54:29.755508553Z,2025-07-17T16:54:29.755508553Z,10,2,1108,C,A,1,13.27,100,130,165611,323103374,12.63,3,1,13.25,50,1,12.48,2,1,13.27,2,1,12.23,100,1,13.44,100,1,12.22,300,3,13.56,100,1,11.97,100,1,13.86,100,1,11.92,100,1,13.97,100,1,11.9,700,1,14.06,700,1,11.85,700,1,14.11,300,3,11.82,700,1,14.18,1400,2,11.79,700,1,14.2,700,1,ARL,389948353
,2025-07-17T16:54:29.765107655Z,2025-07-17T16:54:29.765107655Z,10,2,1108,C,A,3,13.56,100,130,165288,323103685,12.63,3,1,13.25,50,1,12.48,2,1,13.27,2,1,12.23,100,1,13.44,100,1,12.22,300,3,13.86,100,1,11.97,100,1,13.97,100,1,11.92,100,1,14.06,700,1,11.9,700,1,14.11,300,3,11.85,700,1,14.18,1400,2,11.82,700,1,14.2,700,1,11.79,700,1,14.26,100,1,ARL,389168529
,2025-07-17T16:54:29.765130910Z,2025-07-17T16:54:29.765130910Z,10,2,1108,C,B,0,12.63,3,130,165457,323103690,12.48,2,1,13.25,50,1,12.23,100,1,13.27,2,1,12.22,300,3,13.44,100,1,11.97,100,1,13.86,100,1,11.92,100,1,13.97,100,1,11.9,700,1,14.06,700,1,11.85,700,1,14.11,300,3,11.82,700,1,14.18,1400,2,11.79,700,1,14.2,700,1,11.76,100,1,14.26,100,1,ARL,390133673
,2025-07-17T16:54:29.765159050Z,2025-07-17T16:54:29.765159050Z,10,2,1108,A,A,3,13.71,100,130,165203,323103691,12.48,2,1,13.25,50,1,12.23,100,1,13.27,2,1,12.22,300,3,13.44,100,1,11.97,100,1,13.71,100,1,11.92,100,1,13.86,100,1,11.9,700,1,13.97,100,1,11.85,700,1,14.06,700,1,11.82,700,1,14.11,300,3,11.79,700,1,14.18,1400,2,11.76,100,1,14.2,700,1,ARL,390134597
,2025-07-17T16:54:29.901984378Z,2025-07-17T16:54:29.901984378Z,10,2,1108,C,A,0,13.25,50,130,165531,323105144,12.48,2,1,13.27,2,1,12.23,100,1,13.44,100,1,12.22,300,3,13.71,100,1,11.97,100,1,13.86,100,1,11.92,100,1,13.97,100,1,11.9,700,1,14.06,700,1,11.85,700,1,14.11,300,3,11.82,700,1,14.18,1400,2,11.79,700,1,14.2,700,1,11.76,100,1,14.26,100,1,ARL,390133645
,2025-07-17T16:54:29.902034700Z,2025-07-17T16:54:29.902034700Z,10,2,1108,C,A,1,13.44,100,130,165364,323105146,12.48,2,1,13.27,2,1,12.23,100,1,13.71,100,1,12.22,300,3,13.86,100,1,11.97,100,1,13.97,100,1,11.92,100,1,14.06,700,1,11.9,700,1,14.11,300,3,11.85,700,1,14.18,1400,2,11.82,700,1,14.2,700,1,11.79,700,1,14.26,100,1,11.76,100,1,14.27,200,2,ARL,381937585
,2025-07-17T16:54:29.902759016Z,2025-07-17T16:54:29.902759016Z,10,2,1108,C,A,10,14.48,100,0,165274,323105157,12.48,2,1,13.27,2,1,12.23,100,1,13.71,100,1,12.22,300,3,13.86,100,1,11.97,100,1,13.97,100,1,11.92,100,1,14.06,700,1,11.9,700,1,14.11,300,3,11.85,700,1,14.18,1400,2,11.82,700,1,14.2,700,1,11.79,700,1,14.26,100,1,11.76,100,1,14.27,200,2,ARL,390135069
,2025-07-17T16:54:29.902759016Z,2025-07-17T16:54:29.902759016Z,10,2,1108,A,A,10,14.54,100,130,165274,323105157,12.48,2,1,13.27,2,1,12.23,100,1,13.71,100,1,12.22,300,3,13.86,100,1,11.97,100,1,13.97,100,1,11.92,100,1,14.06,700,1,11.9,700,1,14.11,300,3,11.85,700,1,14.18,1400,2,11.82,700,1,14.2,700,1,11.79,700,1,14.26,100,1,11.76,100,1,14.27,200,2,ARL,390136225
,2025-07-17T16:54:29.903453684Z,2025-07-17T16:54:29.903453684Z,10,2,1108,C,A,6,14.18,700,130,165258,323105162,12.48,2,1,13.27,2,1,12.23,100,1,13.71,100,1,12.22,300,3,13.86,100,1,11.97,100,1,13.97,100,1,11.92,100,1,14.06,700,1,11.9,700,1,14.11,300,3,11.85,700,1,14.18,700,1,11.82,700,1,14.2,700,1,11.79,700,1,14.26,100,1,11.76,100,1,14.27,200,2,ARL,387208149
,2025-07-17T16:54:29.903454701Z,2025-07-17T16:54:29.903454701Z,10,2,1108,C,A,6,14.18,700,130,165126,323105163,12.48,2,1,13.27,2,1,12.23,100,1,13.71,100,1,12.22,300,3,13.86,100,1,11.97,100,1,13.97,100,1,11.92,100,1,14.06,700,1,11.9,700,1,14.11,300,3,11.85,700,1,14.2,700,1,11.82,700,1,14.26,100,1,11.79,700,1,14.27,200,2,11.76,100,1,14.54,100,1,ARL,379214721
,2025-07-17T16:54:29.903499198Z,2025-07-17T16:54:29.903499198Z,10,2,1108,A,A,9,14.4,700,0,166797,323105164,12.48,2,1,13.27,2,1,12.23,100,1,13.71,100,1,12.22,300,3,13.86,100,1,11.97,100,1,13.97,100,1,11.92,100,1,14.06,700,1,11.9,700,1,14.11,300,3,11.85,700,1,14.2,700,1,11.82,700,1,14.26,100,1,11.79,700,1,14.27,200,2,11.76,100,1,14.4,700,1,ARL,390136249
,2025-07-17T16:54:29.903499925Z,2025-07-17T16:54:29.903499925Z,10,2,1108,A,A,10,14.47,700,130,166070,323105165,12.48,2,1,13.27,2,1,12.23,100,1,13.71,100,1,12.22,300,3,13.86,100,1,11.97,100,1,13.97,100,1,11.92,100,1,14.06,700,1,11.9,700,1,14.11,300,3,11.85,700,1,14.2,700,1,11.82,700,1,14.26,100,1,11.79,700,1,14.27,200,2,11.76,100,1,14.4,700,1,ARL,390136253
,2025-07-17T16:54:29.903986354Z,2025-07-17T16:54:29.903986354Z,10,2,1108,C,A,4,14.06,700,130,165157,323105172,12.48,2,1,13.27,2,1,12.23,100,1,13.71,100,1,12.22,300,3,13.86,100,1,11.97,100,1,13.97,100,1,11.92,100,1,14.11,300,3,11.9,700,1,14.2,700,1,11.85,700,1,14.26,100,1,11.82,700,1,14.27,200,2,11.79,700,1,14.4,700,1,11.76,100,1,14.47,700,1,ARL,387277657
,2025-07-17T16:54:29.904429181Z,2025-07-17T16:54:29.904429181Z,10,2,1108,A,A,9,14.43,700,130,165419,323105173,12.48,2,1,13.27,2,1,12.23,100,1,13.71,100,1,12.22,300,3,13.86,100,1,11.97,100,1,13.97,100,1,11.92,100,1,14.11,300,3,11.9,700,1,14.2,700,1,11.85,700,1,14.26,100,1,11.82,700,1,14.27,200,2,11.79,700,1,14.4,700,1,11.76,100,1,14.43,700,1,ARL,390136281
,2025-07-17T16:54:29.904545815Z,2025-07-17T16:54:29.904545815Z,10,2,1108,C,A,7,14.27,100,0,165886,323105174,12.48,2,1,13.27,2,1,12.23,100,1,13.71,100,1,12.22,300,3,13.86,100,1,11.97,100,1,13.97,100,1,11.92,100,1,14.11,300,3,11.9,700,1,14.2,700,1,11.85,700,1,14.26,100,1,11.82,700,1,14.27,100,1,11.79,700,1,14.4,700,1,11.76,100,1,14.43,700,1,ARL,387246077
,2025-07-17T16:54:29.905981039Z,2025-07-17T16:54:29.905981039Z,10,2,1108,C,A,4,14.11,100,130,165942,323105179,12.48,2,1,13.27,2,1,12.23,100,1,13.71,100,1,12.22,300,3,13.86,100,1,11.97,100,1,13.97,100,1,11.92,100,1,14.11,200,2,11.9,700,1,14.2,700,1,11.85,700,1,14.26,100,1,11.82,700,1,14.27,100,1,11.79,700,1,14.4,700,1,11.76,100,1,14.43,700,1,ARL,387246169
,2025-07-17T16:54:29.913200271Z,2025-07-17T16:54:29.913200271Z,10,2,1108,C,A,7,14.27,100,0,165758,323105271,12.48,2,1,13.27,2,1,12.23,100,1,13.71,100,1,12.22,300,3,13.86,100,1,11.97,100,1,13.97,100,1,11.92,100,1,14.11,200,2,11.9,700,1,14.2,700,1,11.85,700,1,14.26,100,1,11.82,700,1,14.4,700,1,11.79,700,1,14.43,700,1,11.76,100,1,14.47,700,1,ARL,387246189
,2025-07-17T16:54:29.941034461Z,2025-07-17T16:54:29.941034461Z,10,2,1108,C,A,1,13.71,100,130,165141,323105451,12.48,2,1,13.27,2,1,12.23,100,1,13.86,100,1,12.22,300,3,13.97,100,1,11.97,100,1,14.11,200,2,11.92,100,1,14.2,700,1,11.9,700,1,14.26,100,1,11.85,700,1,14.4,700,1,11.82,700,1,14.43,700,1,11.79,700,1,14.47,700,1,11.76,100,1,14.49,100,1,ARL,390134597
,2025-07-17T16:54:29.941070856Z,2025-07-17T16:54:29.941070856Z,10,2,1108,C,A,6,14.4,700,130,165001,323105452,12.48,2,1,13.27,2,1,12.23,100,1,13.86,100,1,12.22,300,3,13.97,100,1,11.97,100,1,14.11,200,2,11.92,100,1,14.2,700,1,11.9,700,1,14.26,100,1,11.85,700,1,14.43,700,1,11.82,700,1,14.47,700,1,11.79,700,1,14.49,100,1,11.76,100,1,14.54,100,1,ARL,390136249
,2025-07-17T16:54:29.941083801Z,2025-07-17T16:54:29.941083801Z,10,2,1108,A,A,3,13.98,100,130,165175,323105453,12.48,2,1,13.27,2,1,12.23,100,1,13.86,100,1,12.22,300,3,13.97,100,1,11.97,100,1,13.98,100,1,11.92,100,1,14.11,200,2,11.9,700,1,14.2,700,1,11.85,700,1,14.26,100,1,11.82,700,1,14.43,700,1,11.79,700,1,14.47,700,1,11.76,100,1,14.49,100,1,ARL,390136733
,2025-07-17T16:54:29.941340365Z,2025-07-17T16:54:29.941340365Z,10,2,1108,C,B,0,12.48,2,130,165511,323105457,12.23,100,1,13.27,2,1,12.22,300,3,13.86,100,1,11.97,100,1,13.97,100,1,11.92,100,1,13.98,100,1,11.9,700,1,14.11,200,2,11.85,700,1,14.2,700,1,11.82,700,1,14.26,100,1,11.79,700,1,14.43,700,1,11.76,100,1,14.47,700,1,11.72,100,1,14.49,100,1,ARL,387224461
,2025-07-17T16:54:29.941342597Z,2025-07-17T16:54:29.941342597Z,10,2,1108,C,A,0,13.27,2,130,165184,323105458,12.23,100,1,13.86,100,1,12.22,300,3,13.97,100,1,11.97,100,1,13.98,100,1,11.92,100,1,14.11,200,2,11.9,700,1,14.2,700,1,11.85,700,1,14.26,100,1,11.82,700,1,14.43,700,1,11.79,700,1,14.47,700,1,11.76,100,1,14.49,100,1,11.72,100,1,14.54,100,1,ARL,390060109
,2025-07-17T16:54:29.941721119Z,2025-07-17T16:54:29.941721119Z,10,2,1108,C,B,1,12.22,100,0,165757,323105460,12.23,100,1,13.86,100,1,12.22,200,2,13.97,100,1,11.97,100,1,13.98,100,1,11.92,100,1,14.11,200,2,11.9,700,1,14.2,700,1,11.85,700,1,14.26,100,1,11.82,700,1,14.43,700,1,11.79,700,1,14.47,700,1,11.76,100,1,14.49,100,1,11.72,100,1,14.54,100,1,ARL,342029561
,2025-07-17T16:54:29.941775542Z,2025-07-17T16:54:29.941775542Z,10,2,1108,C,A,3,14.11,100,0,165483,323105461,12.23,100,1,13.86,100,1,12.22,200,2,13.97,100,1,11.97,100,1,13.98,100,1,11.92,100,1,14.11,100,1,11.9,700,1,14.2,700,1,11.85,700,1,14.26,100,1,11.82,700,1,14.43,700,1,11.79,700,1,14.47,700,1,11.76,100,1,14.49,100,1,11.72,100,1,14.54,100,1,ARL,390012177
,2025-07-17T16:54:29.941775542Z,2025-07-17T16:54:29.941775542Z,10,2,1108,A,A,6,14.33,100,130,165483,323105461,12.23,100,1,13.86,100,1,12.22,200,2,13.97,100,1,11.97,100,1,13.98,100,1,11.92,100,1,14.11,100,1,11.9,700,1,14.2,700,1,11.85,700,1,14.26,100,1,11.82,700,1,14.33,100,1,11.79,700,1,14.43,700,1,11.76,100,1,14.47,700,1,11.72,100,1,14.49,100,1,ARL,390136761
,2025-07-17T16:54:29.942110273Z,2025-07-17T16:54:29.942110273Z,10,2,1108,C,B,1,12.22,100,0,165525,323105463,12.23,100,1,13.86,100,1,12.22,100,1,13.97,100,1,11.97,100,1,13.98,100,1,11.92,100,1,14.11,100,1,11.9,700,1,14.2,700,1,11.85,700,1,14.26,100,1,11.82,700,1,14.33,100,1,11.79,700,1,14.43,700,1,11.76,100,1,14.47,700,1,11.72,100,1,14.49,100,1,ARL,342029581
,2025-07-17T16:54:29.942181221Z,2025-07-17T16:54:29.942181221Z,10,2,1108,C,A,3,14.11,100,0,165469,323105465,12.23,100,1,13.86,100,1,12.22,100,1,13.97,100,1,11.97,100,1,13.98,100,1,11.92,100,1,14.2,700,1,11.9,700,1,14.26,100,1,11.85,700,1,14.33,100,1,11.82,700,1,14.43,700,1,11.79,700,1,14.47,700,1,11.76,100,1,14.49,100,1,11.72,100,1,14.54,100,1,ARL,390012165
,2025-07-17T16:54:29.942181221Z,2025-07-17T16:54:29.942181221Z,10,2,1108,A,A,5,14.33,100,130,165469,323105465,12.23,100,1,13.86,100,1,12.22,100,1,13.97,100,1,11.97,100,1,13.98,100,1,11.92,100,1,14.2,700,1,11.9,700,1,14.26,100,1,11.85,700,1,14.33,200,2,11.82,700,1,14.43,700,1,11.79,700,1,14.47,700,1,11.76,100,1,14.49,100,1,11.72,100,1,14.54,100,1,ARL,390136777
,2025-07-17T16:54:29.942890449Z,2025-07-17T16:54:29.942890449Z,10,2,1108,C,A,10,14.67,100,0,165297,323105470,12.23,100,1,13.86,100,1,12.22,100,1,13.97,100,1,11.97,100,1,13.98,100,1,11.92,100,1,14.2,700,1,11.9,700,1,14.26,100,1,11.85,700,1,14.33,200,2,11.82,700,1,14.43,700,1,11.79,700,1,14.47,700,1,11.76,100,1,14.49,100,1,11.72,100,1,14.54,100,1,ARL,390136285
,2025-07-17T16:54:29.942920302Z,2025-07-17T16:54:29.942920302Z,10,2,1108,C,A,10,14.67,100,0,165465,323105472,12.23,100,1,13.86,100,1,12.22,100,1,13.97,100,1,11.97,100,1,13.98,100,1,11.92,100,1,14.2,700,1,11.9,700,1,14.26,100,1,11.85,700,1,14.33,200,2,11.82,700,1,14.43,700,1,11.79,700,1,14.47,700,1,11.76,100,1,14.49,100,1,11.72,100,1,14.54,100,1,ARL,390136577
,2025-07-17T16:54:29.943330033Z,2025-07-17T16:54:29.943330033Z,10,2,1108,C,A,10,14.81,100,0,165495,323105484,12.23,100,1,13.86,100,1,12.22,100,1,13.97,100,1,11.97,100,1,13.98,100,1,11.92,100,1,14.2,700,1,11.9,700,1,14.26,100,1,11.85,700,1,14.33,200,2,11.82,700,1,14.43,700,1,11.79,700,1,14.47,700,1,11.76,100,1,14.49,100,1,11.72,100,1,14.54,100,1,ARL,379095997
,2025-07-17T16:54:29.943358872Z,2025-07-17T16:54:29.943358872Z,10,2,1108,C,A,10,14.81,100,0,165817,323105485,12.23,100,1,13.86,100,1,12.22,100,1,13.97,100,1,11.97,100,1,13.98,100,1,11.92,100,1,14.2,700,1,11.9,700,1,14.26,100,1,11.85,700,1,14.33,200,2,11.82,700,1,14.43,700,1,11.79,700,1,14.47,700,1,11.76,100,1,14.49,100,1,11.72,100,1,14.54,100,1,ARL,379096977
,2025-07-17T16:54:29.949651286Z,2025-07-17T16:54:29.949651286Z,10,2,1108,C,A,2,13.98,100,130,165362,323105536,12.23,100,1,13.86,100,1,12.22,100,1,13.97,100,1,11.97,100,1,14.2,700,1,11.92,100,1,14.26,100,1,11.9,700,1,14.33,200,2,11.85,700,1,14.43,700,1,11.82,700,1,14.47,700,1,11.79,700,1,14.49,100,1,11.76,100,1,14.54,100,1,11.72,100,1,14.84,200,2,ARL,390136733
,2025-07-17T16:54:29.949698550Z,2025-07-17T16:54:29.949698550Z,10,2,1108,A,A,2,14.14,100,130,165328,323105537,12.23,100,1,13.86,100,1,12.22,100,1,13.97,100,1,11.97,100,1,14.14,100,1,11.92,100,1,14.2,700,1,11.9,700,1,14.26,100,1,11.85,700,1,14.33,200,2,11.82,700,1,14.43,700,1,11.79,700,1,14.47,700,1,11.76,100,1,14.49,100,1,11.72,100,1,14.54,100,1,ARL,390136953
,2025-07-17T16:54:29.952969836Z,2025-07-17T16:54:29.952969836Z,10,2,1108,C,A,9,14.54,100,0,165424,323105548,12.23,100,1,13.86,100,1,12.22,100,1,13.97,100,1,11.97,100,1,14.14,100,1,11.92,100,1,14.2,700,1,11.9,700,1,14.26,100,1,11.85,700,1,14.33,200,2,11.82,700,1,14.43,700,1,11.79,700,1,14.47,700,1,11.76,100,1,14.49,100,1,11.72,100,1,14.84,200,2,ARL,390136225
,2025-07-17T16:54:29.952969836Z,2025-07-17T16:54:29.952969836Z,10,2,1108,A,A,10,14.93,100,130,165424,323105548,12.23,100,1,13.86,100,1,12.22,100,1,13.97,100,1,11.97,100,1,14.14,100,1,11.92,100,1,14.2,700,1,11.9,700,1,14.26,100,1,11.85,700,1,14.33,200,2,11.82,700,1,14.43,700,1,11.79,700,1,14.47,700,1,11.76,100,1,14.49,100,1,11.72,100,1,14.84,200,2,ARL,390136969
,2025-07-17T16:54:29.957872826Z,2025-07-17T16:54:29.957872826Z,10,2,1108,A,A,9,14.56,700,130,165247,323105616,12.23,100,1,13.86,100,1,12.22,100,1,13.97,100,1,11.97,100,1,14.14,100,1,11.92,100,1,14.2,700,1,11.9,700,1,14.26,100,1,11.85,700,1,14.33,200,2,11.82,700,1,14.43,700,1,11.79,700,1,14.47,700,1,11.76,100,1,14.49,100,1,11.72,100,1,14.56,700,1,ARL,390137005
,2025-07-17T16:54:29.980450077Z,2025-07-17T16:54:29.980450077Z,10,2,1108,A,A,1,13.87,100,130,165264,323106126,12.23,100,1,13.86,100,1,12.22,100,1,13.87,100,1,11.97,100,1,13.97,100,1,11.92,100,1,14.14,100,1,11.9,700,1,14.2,700,1,11.85,700,1,14.26,100,1,11.82,700,1,14.33,200,2,11.79,700,1,14.43,700,1,11.76,100,1,14.47,700,1,11.72,100,1,14.49,100,1,ARL,390137561
,2025-07-17T16:54:30.291453478Z,2025-07-17T16:54:30.291453478Z,10,2,1108,C,A,0,13.86,100,130,165099,323111095,12.23,100,1,13.87,100,1,12.22,100,1,13.97,100,1,11.97,100,1,14.14,100,1,11.92,100,1,14.2,700,1,11.9,700,1,14.26,100,1,11.85,700,1,14.33,200,2,11.82,700,1,14.43,700,1,11.79,700,1,14.47,700,1,11.76,100,1,14.49,100,1,11.72,100,1,14.56,700,1,ARL,390133893
,2025-07-17T16:54:30.291805387Z,2025-07-17T16:54:30.291805387Z,10,2,1108,A,A,8,14.48,100,130,165222,323111099,12.23,100,1,13.87,100,1,12.22,100,1,13.97,100,1,11.97,100,1,14.14,100,1,11.92,100,1,14.2,700,1,11.9,700,1,14.26,100,1,11.85,700,1,14.33,200,2,11.82,700,1,14.43,700,1,11.79,700,1,14.47,700,1,11.76,100,1,14.48,100,1,11.72,100,1,14.49,100,1,ARL,390141957
,2025-07-17T16:54:30.389668907Z,2025-07-17T16:54:30.389668907Z,10,2,1108,C,A,4,14.26,100,130,165235,323116867,12.23,100,1,13.87,100,1,12.22,100,1,13.97,100,1,11.97,100,1,14.14,100,1,11.92,100,1,14.2,700,1,11.9,700,1,14.33,200,2,11.85,700,1,14.43,700,1,11.82,700,1,14.47,700,1,11.79,700,1,14.48,100,1,11.76,100,1,14.49,100,1,11.72,100,1,14.56,700,1,ARL,379107445
,2025-07-17T16:54:30.880608525Z,2025-07-17T16:54:30.880608525Z,10,2,1108,C,A,1,13.97,100,130,165468,323122333,12.23,100,1,13.87,100,1,12.22,100,1,14.14,100,1,11.97,100,1,14.2,700,1,11.92,100,1,14.33,200,2,11.9,700,1,14.43,700,1,11.85,700,1,14.47,700,1,11.82,700,1,14.48,100,1,11.79,700,1,14.49,100,1,11.76,100,1,14.56,700,1,11.72,100,1,14.69,100,1,ARL,381395205
,2025-07-17T16:54:30.880610836Z,2025-07-17T16:54:30.880610836Z,10,2,1108,A,A,4,14.42,100,130,165642,323122334,12.23,100,1,13.87,100,1,12.22,100,1,14.14,100,1,11.97,100,1,14.2,700,1,11.92,100,1,14.33,200,2,11.9,700,1,14.42,100,1,11.85,700,1,14.43,700,1,11.82,700,1,14.47,700,1,11.79,700,1,14.48,100,1,11.76,100,1,14.49,100,1,11.72,100,1,14.56,700,1,ARL,390153597
,2025-07-17T16:54:30.908587894Z,2025-07-17T16:54:30.908587894Z,10,2,1108,C,A,8,14.49,100,0,165432,323122430,12.23,100,1,13.87,100,1,12.22,100,1,14.14,100,1,11.97,100,1,14.2,700,1,11.92,100,1,14.33,200,2,11.9,700,1,14.42,100,1,11.85,700,1,14.43,700,1,11.82,700,1,14.47,700,1,11.79,700,1,14.48,100,1,11.76,100,1,14.56,700,1,11.72,100,1,14.69,100,1,ARL,390136305
,2025-07-17T16:54:30.908587894Z,2025-07-17T16:54:30.908587894Z,10,2,1108,A,A,9,14.65,100,130,165432,323122430,12.23,100,1,13.87,100,1,12.22,100,1,14.14,100,1,11.97,100,1,14.2,700,1,11.92,100,1,14.33,200,2,11.9,700,1,14.42,100,1,11.85,700,1,14.43,700,1,11.82,700,1,14.47,700,1,11.79,700,1,14.48,100,1,11.76,100,1,14.56,700,1,11.72,100,1,14.65,100,1,ARL,390153953
,2025-07-17T16:54:30.982648521Z,2025-07-17T16:54:30.982648521Z,10,2,1108,A,B,1,12.22,100,130,165479,323123335,12.23,100,1,13.87,100,1,12.22,200,2,14.14,100,1,11.97,100,1,14.2,700,1,11.92,100,1,14.33,200,2,11.9,700,1,14.42,100,1,11.85,700,1,14.43,700,1,11.82,700,1,14.47,700,1,11.79,700,1,14.48,100,1,11.76,100,1,14.56,700,1,11.72,100,1,14.65,100,1,ARL,390155937
,2025-07-17T16:54:30.989615198Z,2025-07-17T16:54:30.989615198Z,10,2,1108,A,B,1,12.22,100,130,165726,323123542,12.23,100,1,13.87,100,1,12.22,300,3,14.14,100,1,11.97,100,1,14.2,700,1,11.92,100,1,14.33,200,2,11.9,700,1,14.42,100,1,11.85,700,1,14.43,700,1,11.82,700,1,14.47,700,1,11.79,700,1,14.48,100,1,11.76,100,1,14.56,700,1,11.72,100,1,14.65,100,1,ARL,390156205
,2025-07-17T16:54:33.001823770Z,2025-07-17T16:54:33.001823770Z,10,2,1108,A,B,0,13.1,10,130,165294,323145588,13.1,10,1,13.87,100,1,12.23,100,1,14.14,100,1,12.22,300,3,14.2,700,1,11.97,100,1,14.33,200,2,11.92,100,1,14.42,100,1,11.9,700,1,14.43,700,1,11.85,700,1,14.47,700,1,11.82,700,1,14.48,100,1,11.79,700,1,14.56,700,1,11.76,100,1,14.65,100,1,ARL,390188869
,2025-07-17T16:54:36.494842320Z,2025-07-17T16:54:36.494842320Z,10,2,1108,A,A,0,13.45,10,130,165133,323190336,13.1,10,1,13.45,10,1,12.23,100,1,13.87,100,1,12.22,300,3,14.14,100,1,11.97,100,1,14.2,700,1,11.92,100,1,14.33,200,2,11.9,700,1,14.42,100,1,11.85,700,1,14.43,700,1,11.82,700,1,14.47,700,1,11.79,700,1,14.48,100,1,11.76,100,1,14.56,700,1,ARL,390244445
,2025-07-17T16:54:39.639240088Z,2025-07-17T16:54:39.639240088Z,10,2,1108,C,B,0,13.1,10,128,166275,323229343,12.23,100,1,13.45,10,1,12.22,300,3,13.87,100,1,11.97,100,1,14.14,100,1,11.92,100,1,14.2,700,1,11.9,700,1,14.33,200,2,11.85,700,1,14.42,100,1,11.82,700,1,14.43,700,1,11.79,700,1,14.47,700,1,11.76,100,1,14.48,100,1,11.72,100,1,14.56,700,1,ARL,390188869
,2025-07-17T16:54:39.640376331Z,2025-07-17T16:54:39.640376331Z,10,2,1108,C,B,1,12.22,100,0,165723,323229401,12.23,100,1,13.45,10,1,12.22,200,2,13.87,100,1,11.97,100,1,14.14,100,1,11.92,100,1,14.2,700,1,11.9,700,1,14.33,200,2,11.85,700,1,14.42,100,1,11.82,700,1,14.43,700,1,11.79,700,1,14.47,700,1,11.76,100,1,14.48,100,1,11.72,100,1,14.56,700,1,ARL,390155937
,2025-07-17T16:54:39.640376331Z,2025-07-17T16:54:39.640376331Z,10,2,1108,A,B,10,11.63,100,130,165723,323229401,12.23,100,1,13.45,10,1,12.22,200,2,13.87,100,1,11.97,100,1,14.14,100,1,11.92,100,1,14.2,700,1,11.9,700,1,14.33,200,2,11.85,700,1,14.42,100,1,11.82,700,1,14.43,700,1,11.79,700,1,14.47,700,1,11.76,100,1,14.48,100,1,11.72,100,1,14.56,700,1,ARL,390290997
,2025-07-17T16:54:39.641052077Z,2025-07-17T16:54:39.641052077Z,10,2,1108,C,B,1,12.22,100,0,165810,323229423,12.23,100,1,13.45,10,1,12.22,100,1,13.87,100,1,11.97,100,1,14.14,100,1,11.92,100,1,14.2,700,1,11.9,700,1,14.33,200,2,11.85,700,1,14.42,100,1,11.82,700,1,14.43,700,1,11.79,700,1,14.47,700,1,11.76,100,1,14.48,100,1,11.72,100,1,14.56,700,1,ARL,390156205
,2025-07-17T16:54:39.641052077Z,2025-07-17T16:54:39.641052077Z,10,2,1108,A,B,10,11.63,100,130,165810,323229423,12.23,100,1,13.45,10,1,12.22,100,1,13.87,100,1,11.97,100,1,14.14,100,1,11.92,100,1,14.2,700,1,11.9,700,1,14.33,200,2,11.85,700,1,14.42,100,1,11.82,700,1,14.43,700,1,11.79,700,1,14.47,700,1,11.76,100,1,14.48,100,1,11.72,100,1,14.56,700,1,ARL,390291089
,2025-07-17T16:54:39.742481344Z,2025-07-17T16:54:39.742481344Z,10,2,1108,C,A,1,13.87,100,0,165539,323233034,12.23,100,1,13.45,10,1,12.22,100,1,14.14,100,1,11.97,100,1,14.2,700,1,11.92,100,1,14.33,200,2,11.9,700,1,14.42,100,1,11.85,700,1,14.43,700,1,11.82,700,1,14.47,700,1,11.79,700,1,14.48,100,1,11.76,100,1,14.56,700,1,11.72,100,1,14.65,100,1,ARL,390137561
,2025-07-17T16:54:39.742481344Z,2025-07-17T16:54:39.742481344Z,10,2,1108,A,A,1,13.46,100,130,165539,323233034,12.23,100,1,13.45,10,1,12.22,100,1,13.46,100,1,11.97,100,1,14.14,100,1,11.92,100,1,14.2,700,1,11.9,700,1,14.33,200,2,11.85,700,1,14.42,100,1,11.82,700,1,14.43,700,1,11.79,700,1,14.47,700,1,11.76,100,1,14.48,100,1,11.72,100,1,14.56,700,1,ARL,390297413
,2025-07-17T16:54:39.743220634Z,2025-07-17T16:54:39.743220634Z,10,2,1108,C,A,8,14.48,100,130,165140,323233082,12.23,100,1,13.45,10,1,12.22,100,1,13.46,100,1,11.97,100,1,14.14,100,1,11.92,100,1,14.2,700,1,11.9,700,1,14.33,200,2,11.85,700,1,14.42,100,1,11.82,700,1,14.43,700,1,11.79,700,1,14.47,700,1,11.76,100,1,14.56,700,1,11.72,100,1,14.65,100,1,ARL,390141957
,2025-07-17T16:54:39.743224193Z,2025-07-17T16:54:39.743224193Z,10,2,1108,A,A,8,14.5,100,130,165512,323233083,12.23,100,1,13.45,10,1,12.22,100,1,13.46,100,1,11.97,100,1,14.14,100,1,11.92,100,1,14.2,700,1,11.9,700,1,14.33,200,2,11.85,700,1,14.42,100,1,11.82,700,1,14.43,700,1,11.79,700,1,14.47,700,1,11.76,100,1,14.5,100,1,11.72,100,1,14.56,700,1,ARL,390297517
,2025-07-17T16:54:39.743571651Z,2025-07-17T16:54:39.743571651Z,10,2,1108,A,A,2,14.06,100,128,166421,323233099,12.23,100,1,13.45,10,1,12.22,100,1,13.46,100,1,11.97,100,1,14.06,100,1,11.92,100,1,14.14,100,1,11.9,700,1,14.2,700,1,11.85,700,1,14.33,200,2,11.82,700,1,14.42,100,1,11.79,700,1,14.43,700,1,11.76,100,1,14.47,700,1,11.72,100,1,14.5,100,1,ARL,390297545
,2025-07-17T16:54:39.745075591Z,2025-07-17T16:54:39.745075591Z,10,2,1108,A,A,6,14.41,100,130,165396,323233188,12.23,100,1,13.45,10,1,12.22,100,1,13.46,100,1,11.97,100,1,14.06,100,1,11.92,100,1,14.14,100,1,11.9,700,1,14.2,700,1,11.85,700,1,14.33,200,2,11.82,700,1,14.41,100,1,11.79,700,1,14.42,100,1,11.76,100,1,14.43,700,1,11.72,100,1,14.47,700,1,ARL,390297581
,2025-07-17T16:54:39.746718759Z,2025-07-17T16:54:39.746718759Z,10,2,1108,C,A,3,14.14,100,130,165514,323233222,12.23,100,1,13.45,10,1,12.22,100,1,13.46,100,1,11.97,100,1,14.06,100,1,11.92,100,1,14.2,700,1,11.9,700,1,14.33,200,2,11.85,700,1,14.41,100,1,11.82,700,1,14.42,100,1,11.79,700,1,14.43,700,1,11.76,100,1,14.47,700,1,11.72,100,1,14.5,100,1,ARL,390136953
,2025-07-17T16:54:39.746770470Z,2025-07-17T16:54:39.746770470Z,10,2,1108,A,A,2,13.73,100,130,165510,323233223,12.23,100,1,13.45,10,1,12.22,100,1,13.46,100,1,11.97,100,1,13.73,100,1,11.92,100,1,14.06,100,1,11.9,700,1,14.2,700,1,11.85,700,1,14.33,200,2,11.82,700,1,14.41,100,1,11.79,700,1,14.42,100,1,11.76,100,1,14.43,700,1,11.72,100,1,14.47,700,1,ARL,390297625
,2025-07-17T16:54:39.749455133Z,2025-07-17T16:54:39.749455133Z,10,2,1108,A,B,0,12.49,2,130,165335,323233314,12.49,2,1,13.45,10,1,12.23,100,1,13.46,100,1,12.22,100,1,13.73,100,1,11.97,100,1,14.06,100,1,11.92,100,1,14.2,700,1,11.9,700,1,14.33,200,2,11.85,700,1,14.41,100,1,11.82,700,1,14.42,100,1,11.79,700,1,14.43,700,1,11.76,100,1,14.47,700,1,ARL,390297773
,2025-07-17T16:54:39.749457160Z,2025-07-17T16:54:39.749457160Z,10,2,1108,A,A,1,13.46,2,130,165309,323233315,12.49,2,1,13.45,10,1,12.23,100,1,13.46,102,2,12.22,100,1,13.73,100,1,11.97,100,1,14.06,100,1,11.92,100,1,14.2,700,1,11.9,700,1,14.33,200,2,11.85,700,1,14.41,100,1,11.82,700,1,14.42,100,1,11.79,700,1,14.43,700,1,11.76,100,1,14.47,700,1,ARL,390297777
,2025-07-17T16:54:39.754488276Z,2025-07-17T16:54:39.754488276Z,10,2,1108,A,A,5,14.24,100,130,165305,323233451,12.49,2,1,13.45,10,1,12.23,100,1,13.46,102,2,12.22,100,1,13.73,100,1,11.97,100,1,14.06,100,1,11.92,100,1,14.2,700,1,11.9,700,1,14.24,100,1,11.85,700,1,14.33,200,2,11.82,700,1,14.41,100,1,11.79,700,1,14.42,100,1,11.76,100,1,14.43,700,1,ARL,390297949
,2025-07-17T16:54:39.856189932Z,2025-07-17T16:54:39.856189932Z,10,2,1108,A,A,7,14.41,100,130,165478,323234881,12.49,2,1,13.45,10,1,12.23,100,1,13.46,102,2,12.22,100,1,13.73,100,1,11.97,100,1,14.06,100,1,11.92,100,1,14.2,700,1,11.9,700,1,14.24,100,1,11.85,700,1,14.33,200,2,11.82,700,1,14.41,200,2,11.79,700,1,14.42,100,1,11.76,100,1,14.43,700,1,ARL,390300213
,2025-07-17T16:54:39.925701041Z,2025-07-17T16:54:39.925701041Z,10,2,1108,A,A,6,14.26,100,130,165651,323235398,12.49,2,1,13.45,10,1,12.23,100,1,13.46,102,2,12.22,100,1,13.73,100,1,11.97,100,1,14.06,100,1,11.92,100,1,14.2,700,1,11.9,700,1,14.24,100,1,11.85,700,1,14.26,100,1,11.82,700,1,14.33,200,2,11.79,700,1,14.41,200,2,11.76,100,1,14.42,100,1,ARL,390301509
,2025-07-17T16:54:40.360069276Z,2025-07-17T16:54:40.360069276Z,10,2,1108,A,A,3,13.99,100,130,165355,323249703,12.49,2,1,13.45,10,1,12.23,100,1,13.46,102,2,12.22,100,1,13.73,100,1,11.97,100,1,13.99,100,1,11.92,100,1,14.06,100,1,11.9,700,1,14.2,700,1,11.85,700,1,14.24,100,1,11.82,700,1,14.26,100,1,11.79,700,1,14.33,200,2,11.76,100,1,14.41,200,2,ARL,390315289
,2025-07-17T16:54:40.360071501Z,2025-07-17T16:54:40.360071501Z,10,2,1108,C,A,10,14.42,100,130,165373,323249704,12.49,2,1,13.45,10,1,12.23,100,1,13.46,102,2,12.22,100,1,13.73,100,1,11.97,100,1,13.99,100,1,11.92,100,1,14.06,100,1,11.9,700,1,14.2,700,1,11.85,700,1,14.24,100,1,11.82,700,1,14.26,100,1,11.79,700,1,14.33,200,2,11.76,100,1,14.41,200,2,ARL,390153597
,2025-07-17T16:54:40.657858797Z,2025-07-17T16:54:40.657858797Z,10,2,1108,A,B,2,12.22,100,130,165446,323252340,12.49,2,1,13.45,10,1,12.23,100,1,13.46,102,2,12.22,200,2,13.73,100,1,11.97,100,1,13.99,100,1,11.92,100,1,14.06,100,1,11.9,700,1,14.2,700,1,11.85,700,1,14.24,100,1,11.82,700,1,14.26,100,1,11.79,700,1,14.33,200,2,11.76,100,1,14.41,200,2,ARL,390318665
,2025-07-17T16:54:40.672319951Z,2025-07-17T16:54:40.672319951Z,10,2,1108,A,B,2,12.22,100,130,165364,323252412,12.49,2,1,13.45,10,1,12.23,100,1,13.46,102,2,12.22,300,3,13.73,100,1,11.97,100,1,13.99,100,1,11.92,100,1,14.06,100,1,11.9,700,1,14.2,700,1,11.85,700,1,14.24,100,1,11.82,700,1,14.26,100,1,11.79,700,1,14.33,200,2,11.76,100,1,14.41,200,2,ARL,390318917
,2025-07-17T16:54:48.636571204Z,2025-07-17T16:54:48.636571204Z,10,2,1108,A,A,5,14.14,700,130,165414,323339823,12.49,2,1,13.45,10,1,12.23,100,1,13.46,102,2,12.22,300,3,13.73,100,1,11.97,100,1,13.99,100,1,11.92,100,1,14.06,100,1,11.9,700,1,14.14,700,1,11.85,700,1,14.2,700,1,11.82,700,1,14.24,100,1,11.79,700,1,14.26,100,1,11.76,100,1,14.33,200,2,ARL,390418545
,2025-07-17T16:55:18.860820293Z,2025-07-17T16:55:18.860820293Z,10,2,1108,C,A,0,13.45,10,128,167809,323792027,12.49,2,1,13.46,102,2,12.23,100,1,13.73,100,1,12.22,300,3,13.99,100,1,11.97,100,1,14.06,100,1,11.92,100,1,14.14,700,1,11.9,700,1,14.2,700,1,11.85,700,1,14.24,100,1,11.82,700,1,14.26,100,1,11.79,700,1,14.33,200,2,11.76,100,1,14.41,200,2,ARL,390244445
,2025-07-17T17:10:10.000893422Z,2025-07-17T17:10:10.000893422Z,10,2,1108,C,A,0,13.46,2,0,165667,336433579,12.49,2,1,13.46,100,1,12.23,100,1,13.73,100,1,12.22,300,3,13.99,100,1,11.97,100,1,14.06,100,1,11.92,100,1,14.14,700,1,11.9,700,1,14.2,700,1,11.85,700,1,14.24,100,1,11.82,700,1,14.26,100,1,11.79,700,1,14.33,200,2,11.76,100,1,14.41,200,2,ARL,390297777
,2025-07-17T17:10:10.000893422Z,2025-07-17T17:10:10.000893422Z,10,2,1108,A,A,0,13.44,2,130,165667,336433579,12.49,2,1,13.44,2,1,12.23,100,1,13.46,100,1,12.22,300,3,13.73,100,1,11.97,100,1,13.99,100,1,11.92,100,1,14.06,100,1,11.9,700,1,14.14,700,1,11.85,700,1,14.2,700,1,11.82,700,1,14.24,100,1,11.79,700,1,14.26,100,1,11.76,100,1,14.33,200,2,ARL,407450073
,2025-07-17T17:10:10.361772221Z,2025-07-17T17:10:10.361772221Z,10,2,1108,C,A,1,13.46,100,0,165555,336439763,12.49,2,1,13.44,2,1,12.23,100,1,13.73,100,1,12.22,300,3,13.99,100,1,11.97,100,1,14.06,100,1,11.92,100,1,14.14,700,1,11.9,700,1,14.2,700,1,11.85,700,1,14.24,100,1,11.82,700,1,14.26,100,1,11.79,700,1,14.33,200,2,11.76,100,1,14.41,200,2,ARL,390297413
,2025-07-17T17:10:10.361772221Z,2025-07-17T17:10:10.361772221Z,10,2,1108,A,A,1,13.45,100,130,165555,336439763,12.49,2,1,13.44,2,1,12.23,100,1,13.45,100,1,12.22,300,3,13.73,100,1,11.97,100,1,13.99,100,1,11.92,100,1,14.06,100,1,11.9,700,1,14.14,700,1,11.85,700,1,14.2,700,1,11.82,700,1,14.24,100,1,11.79,700,1,14.26,100,1,11.76,100,1,14.33,200,2,ARL,407456589
,2025-07-17T17:10:43.029659505Z,2025-07-17T17:10:43.029659505Z,10,2,1108,C,A,1,13.45,100,130,165315,336947991,12.49,2,1,13.44,2,1,12.23,100,1,13.73,100,1,12.22,300,3,13.99,100,1,11.97,100,1,14.06,100,1,11.92,100,1,14.14,700,1,11.9,700,1,14.2,700,1,11.85,700,1,14.24,100,1,11.82,700,1,14.26,100,1,11.79,700,1,14.33,200,2,11.76,100,1,14.41,200,2,ARL,407456589
,2025-07-17T17:10:43.031388893Z,2025-07-17T17:10:43.031388893Z,10,2,1108,A,A,2,13.74,100,130,165550,336948067,12.49,2,1,13.44,2,1,12.23,100,1,13.73,100,1,12.22,300,3,13.74,100,1,11.97,100,1,13.99,100,1,11.92,100,1,14.06,100,1,11.9,700,1,14.14,700,1,11.85,700,1,14.2,700,1,11.82,700,1,14.24,100,1,11.79,700,1,14.26,100,1,11.76,100,1,14.33,200,2,ARL,408122037
,2025-07-17T17:14:42.263977687Z,2025-07-17T17:14:42.263977687Z,10,2,1108,A,A,0,13.44,4,130,165490,340033053,12.49,2,1,13.44,6,2,12.23,100,1,13.73,100,1,12.22,300,3,13.74,100,1,11.97,100,1,13.99,100,1,11.92,100,1,14.06,100,1,11.9,700,1,14.14,700,1,11.85,700,1,14.2,700,1,11.82,700,1,14.24,100,1,11.79,700,1,14.26,100,1,11.76,100,1,14.33,200,2,ARL,412198129
,2025-07-17T17:24:42.260738507Z,2025-07-17T17:24:42.260738507Z,10,2,1108,C,A,0,13.44,4,130,165482,347925516,12.49,2,1,13.44,2,1,12.23,100,1,13.73,100,1,12.22,300,3,13.74,100,1,11.97,100,1,13.99,100,1,11.92,100,1,14.06,100,1,11.9,700,1,14.14,700,1,11.85,700,1,14.2,700,1,11.82,700,1,14.24,100,1,11.79,700,1,14.26,100,1,11.76,100,1,14.33,200,2,ARL,412198129
,2025-07-17T17:24:42.261761757Z,2025-07-17T17:24:42.261761757Z,10,2,1108,C,A,2,13.74,100,0,165545,347925524,12.49,2,1,13.44,2,1,12.23,100,1,13.73,100,1,12.22,300,3,13.99,100,1,11.97,100,1,14.06,100,1,11.92,100,1,14.14,700,1,11.9,700,1,14.2,700,1,11.85,700,1,14.24,100,1,11.82,700,1,14.26,100,1,11.79,700,1,14.33,200,2,11.76,100,1,14.41,200,2,ARL,408122037
,2025-07-17T17:24:42.261761757Z,2025-07-17T17:24:42.261761757Z,10,2,1108,A,A,1,13.45,100,130,165545,347925524,12.49,2,1,13.44,2,1,12.23,100,1,13.45,100,1,12.22,300,3,13.73,100,1,11.97,100,1,13.99,100,1,11.92,100,1,14.06,100,1,11.9,700,1,14.14,700,1,11.85,700,1,14.2,700,1,11.82,700,1,14.24,100,1,11.79,700,1,14.26,100,1,11.76,100,1,14.33,200,2,ARL,422564177
,2025-07-17T17:24:42.262806771Z,2025-07-17T17:24:42.262806771Z,10,2,1108,C,B,2,12.22,100,0,165707,347925526,12.49,2,1,13.44,2,1,12.23,100,1,13.45,100,1,12.22,200,2,13.73,100,1,11.97,100,1,13.99,100,1,11.92,100,1,14.06,100,1,11.9,700,1,14.14,700,1,11.85,700,1,14.2,700,1,11.82,700,1,14.24,100,1,11.79,700,1,14.26,100,1,11.76,100,1,14.33,200,2,ARL,390318917
,2025-07-17T17:24:42.262822690Z,2025-07-17T17:24:42.262822690Z,10,2,1108,C,B,2,12.22,100,0,165355,347925527,12.49,2,1,13.44,2,1,12.23,100,1,13.45,100,1,12.22,100,1,13.73,100,1,11.97,100,1,13.99,100,1,11.92,100,1,14.06,100,1,11.9,700,1,14.14,700,1,11.85,700,1,14.2,700,1,11.82,700,1,14.24,100,1,11.79,700,1,14.26,100,1,11.76,100,1,14.33,200,2,ARL,390318665
,2025-07-17T17:24:42.548027809Z,2025-07-17T17:24:42.548027809Z,10,2,1108,C,A,1,13.45,100,130,165151,347929285,12.49,2,1,13.44,2,1,12.23,100,1,13.73,100,1,12.22,100,1,13.99,100,1,11.97,100,1,14.06,100,1,11.92,100,1,14.14,700,1,11.9,700,1,14.2,700,1,11.85,700,1,14.24,100,1,11.82,700,1,14.26,100,1,11.79,700,1,14.33,200,2,11.76,100,1,14.41,200,2,ARL,422564177
,2025-07-17T17:24:42.549392732Z,2025-07-17T17:24:42.549392732Z,10,2,1108,A,A,2,13.74,100,130,165451,347929289,12.49,2,1,13.44,2,1,12.23,100,1,13.73,100,1,12.22,100,1,13.74,100,1,11.97,100,1,13.99,100,1,11.92,100,1,14.06,100,1,11.9,700,1,14.14,700,1,11.85,700,1,14.2,700,1,11.82,700,1,14.24,100,1,11.79,700,1,14.26,100,1,11.76,100,1,14.33,200,2,ARL,422568905
,2025-07-17T17:56:30.441768063Z,2025-07-17T17:56:30.441768063Z,10,2,1108,A,A,0,13.43,10,130,165852,374792938,12.49,2,1,13.43,10,1,12.23,100,1,13.44,2,1,12.22,100,1,13.73,100,1,11.97,100,1,13.74,100,1,11.92,100,1,13.99,100,1,11.9,700,1,14.06,100,1,11.85,700,1,14.14,700,1,11.82,700,1,14.2,700,1,11.79,700,1,14.24,100,1,11.76,100,1,14.26,100,1,ARL,457191725
,2025-07-17T17:56:30.636700055Z,2025-07-17T17:56:30.636700055Z,10,2,1108,C,A,3,13.74,100,0,165458,374794445,12.49,2,1,13.43,10,1,12.23,100,1,13.44,2,1,12.22,100,1,13.73,100,1,11.97,100,1,13.99,100,1,11.92,100,1,14.06,100,1,11.9,700,1,14.14,700,1,11.85,700,1,14.2,700,1,11.82,700,1,14.24,100,1,11.79,700,1,14.26,100,1,11.76,100,1,14.33,200,2,ARL,422568905
,2025-07-17T17:56:30.636700055Z,2025-07-17T17:56:30.636700055Z,10,2,1108,A,A,2,13.45,100,130,165458,374794445,12.49,2,1,13.43,10,1,12.23,100,1,13.44,2,1,12.22,100,1,13.45,100,1,11.97,100,1,13.73,100,1,11.92,100,1,13.99,100,1,11.9,700,1,14.06,100,1,11.85,700,1,14.14,700,1,11.82,700,1,14.2,700,1,11.79,700,1,14.24,100,1,11.76,100,1,14.26,100,1,ARL,457194033
,2025-07-17T17:57:00.747417750Z,2025-07-17T17:57:00.747417750Z,10,2,1108,A,B,3,12.05,100,130,167002,375114806,12.49,2,1,13.43,10,1,12.23,100,1,13.44,2,1,12.22,100,1,13.45,100,1,12.05,100,1,13.73,100,1,11.97,100,1,13.99,100,1,11.92,100,1,14.06,100,1,11.9,700,1,14.14,700,1,11.85,700,1,14.2,700,1,11.82,700,1,14.24,100,1,11.79,700,1,14.26,100,1,ARL,457630209
,2025-07-17T17:57:00.748171838Z,2025-07-17T17:57:00.748171838Z,10,2,1108,A,B,3,12.05,100,130,165554,375114814,12.49,2,1,13.43,10,1,12.23,100,1,13.44,2,1,12.22,100,1,13.45,100,1,12.05,200,2,13.73,100,1,11.97,100,1,13.99,100,1,11.92,100,1,14.06,100,1,11.9,700,1,14.14,700,1,11.85,700,1,14.2,700,1,11.82,700,1,14.24,100,1,11.79,700,1,14.26,100,1,ARL,457630269
,2025-07-17T18:02:45.504573741Z,2025-07-17T18:02:45.504573741Z,10,2,1108,A,A,0,13.37,1,130,165344,380174467,12.49,2,1,13.37,1,1,12.23,100,1,13.43,10,1,12.22,100,1,13.44,2,1,12.05,200,2,13.45,100,1,11.97,100,1,13.73,100,1,11.92,100,1,13.99,100,1,11.9,700,1,14.06,100,1,11.85,700,1,14.14,700,1,11.82,700,1,14.2,700,1,11.79,700,1,14.24,100,1,ARL,464268809
,2025-07-17T18:02:45.511528908Z,2025-07-17T18:02:45.511528908Z,10,2,1108,A,A,0,13.37,10,130,165350,380174502,12.49,2,1,13.37,11,2,12.23,100,1,13.43,10,1,12.22,100,1,13.44,2,1,12.05,200,2,13.45,100,1,11.97,100,1,13.73,100,1,11.92,100,1,13.99,100,1,11.9,700,1,14.06,100,1,11.85,700,1,14.14,700,1,11.82,700,1,14.2,700,1,11.79,700,1,14.24,100,1,ARL,464268845
,2025-07-17T18:02:45.604569852Z,2025-07-17T18:02:45.604569852Z,10,2,1108,C,A,0,13.37,1,130,164995,380175836,12.49,2,1,13.37,10,1,12.23,100,1,13.43,10,1,12.22,100,1,13.44,2,1,12.05,200,2,13.45,100,1,11.97,100,1,13.73,100,1,11.92,100,1,13.99,100,1,11.9,700,1,14.06,100,1,11.85,700,1,14.14,700,1,11.82,700,1,14.2,700,1,11.79,700,1,14.24,100,1,ARL,464268809
,2025-07-17T18:02:45.758288837Z,2025-07-17T18:02:45.758288837Z,10,2,1108,A,B,1,12.48,19,130,165185,380177351,12.49,2,1,13.37,10,1,12.48,19,1,13.43,10,1,12.23,100,1,13.44,2,1,12.22,100,1,13.45,100,1,12.05,200,2,13.73,100,1,11.97,100,1,13.99,100,1,11.92,100,1,14.06,100,1,11.9,700,1,14.14,700,1,11.85,700,1,14.2,700,1,11.82,700,1,14.24,100,1,ARL,464272409
,2025-07-17T18:03:28.674884242Z,2025-07-17T18:03:28.674884242Z,10,2,1108,C,A,0,13.37,10,130,166146,380875617,12.49,2,1,13.43,10,1,12.48,19,1,13.44,2,1,12.23,100,1,13.45,100,1,12.22,100,1,13.73,100,1,12.05,200,2,13.99,100,1,11.97,100,1,14.06,100,1,11.92,100,1,14.14,700,1,11.9,700,1,14.2,700,1,11.85,700,1,14.24,100,1,11.82,700,1,14.26,100,1,ARL,464268845
,2025-07-17T18:03:28.675033913Z,2025-07-17T18:03:28.675033913Z,10,2,1108,C,A,0,13.43,10,130,165396,380875662,12.49,2,1,13.44,2,1,12.48,19,1,13.45,100,1,12.23,100,1,13.73,100,1,12.22,100,1,13.99,100,1,12.05,200,2,14.06,100,1,11.97,100,1,14.14,700,1,11.92,100,1,14.2,700,1,11.9,700,1,14.24,100,1,11.85,700,1,14.26,100,1,11.82,700,1,14.33,200,2,ARL,457191725
,2025-07-17T18:03:37.156700909Z,2025-07-17T18:03:37.156700909Z,10,2,1108,A,A,0,13.43,10,130,165340,381033247,12.49,2,1,13.43,10,1,12.48,19,1,13.44,2,1,12.23,100,1,13.45,100,1,12.22,100,1,13.73,100,1,12.05,200,2,13.99,100,1,11.97,100,1,14.06,100,1,11.92,100,1,14.14,700,1,11.9,700,1,14.2,700,1,11.85,700,1,14.24,100,1,11.82,700,1,14.26,100,1,ARL,465436101
,2025-07-17T18:03:39.024464975Z,2025-07-17T18:03:39.024464975Z,10,2,1108,C,A,0,13.43,10,130,164971,381055717,12.49,2,1,13.44,2,1,12.48,19,1,13.45,100,1,12.23,100,1,13.73,100,1,12.22,100,1,13.99,100,1,12.05,200,2,14.06,100,1,11.97,100,1,14.14,700,1,11.92,100,1,14.2,700,1,11.9,700,1,14.24,100,1,11.85,700,1,14.26,100,1,11.82,700,1,14.33,200,2,ARL,465436101
,2025-07-17T18:03:45.510423349Z,2025-07-17T18:03:45.510423349Z,10,2,1108,A,A,0,13.43,10,130,165311,381155408,12.49,2,1,13.43,10,1,12.48,19,1,13.44,2,1,12.23,100,1,13.45,100,1,12.22,100,1,13.73,100,1,12.05,200,2,13.99,100,1,11.97,100,1,14.06,100,1,11.92,100,1,14.14,700,1,11.9,700,1,14.2,700,1,11.85,700,1,14.24,100,1,11.82,700,1,14.26,100,1,ARL,465595785
,2025-07-17T18:03:55.373753982Z,2025-07-17T18:03:55.373753982Z,10,2,1108,C,A,0,13.43,10,128,174956,381294591,12.49,2,1,13.44,2,1,12.48,19,1,13.45,100,1,12.23,100,1,13.73,100,1,12.22,100,1,13.99,100,1,12.05,200,2,14.06,100,1,11.97,100,1,14.14,700,1,11.92,100,1,14.2,700,1,11.9,700,1,14.24,100,1,11.85,700,1,14.26,100,1,11.82,700,1,14.33,200,2,ARL,465595785
,2025-07-17T18:04:03.101919454Z,2025-07-17T18:04:03.101919454Z,10,2,1108,A,A,0,13.43,10,128,167128,381395570,12.49,2,1,13.43,10,1,12.48,19,1,13.44,2,1,12.23,100,1,13.45,100,1,12.22,100,1,13.73,100,1,12.05,200,2,13.99,100,1,11.97,100,1,14.06,100,1,11.92,100,1,14.14,700,1,11.9,700,1,14.2,700,1,11.85,700,1,14.24,100,1,11.82,700,1,14.26,100,1,ARL,465889901
,2025-07-17T18:04:45.575158670Z,2025-07-17T18:04:45.575158670Z,10,2,1108,A,A,0,13.43,10,130,165602,382020181,12.49,2,1,13.43,20,2,12.48,19,1,13.44,2,1,12.23,100,1,13.45,100,1,12.22,100,1,13.73,100,1,12.05,200,2,13.99,100,1,11.97,100,1,14.06,100,1,11.92,100,1,14.14,700,1,11.9,700,1,14.2,700,1,11.85,700,1,14.24,100,1,11.82,700,1,14.26,100,1,ARL,466717245
,2025-07-17T18:08:14.760305571Z,2025-07-17T18:08:14.760305571Z,10,2,1108,C,B,1,12.48,19,130,165370,384965197,12.49,2,1,13.43,20,2,12.23,100,1,13.44,2,1,12.22,100,1,13.45,100,1,12.05,200,2,13.73,100,1,11.97,100,1,13.99,100,1,11.92,100,1,14.06,100,1,11.9,700,1,14.14,700,1,11.85,700,1,14.2,700,1,11.82,700,1,14.24,100,1,11.79,700,1,14.26,100,1,ARL,464272409
,2025-07-17T18:19:43.054558147Z,2025-07-17T18:19:43.054558147Z,10,2,1108,C,A,0,13.43,10,130,165419,394283063,12.49,2,1,13.43,10,1,12.23,100,1,13.44,2,1,12.22,100,1,13.45,100,1,12.05,200,2,13.73,100,1,11.97,100,1,13.99,100,1,11.92,100,1,14.06,100,1,11.9,700,1,14.14,700,1,11.85,700,1,14.2,700,1,11.82,700,1,14.24,100,1,11.79,700,1,14.26,100,1,ARL,465889901
,2025-07-17T18:19:47.055249706Z,2025-07-17T18:19:47.055249706Z,10,2,1108,A,A,0,13.43,10,130,165320,394326337,12.49,2,1,13.43,20,2,12.23,100,1,13.44,2,1,12.22,100,1,13.45,100,1,12.05,200,2,13.73,100,1,11.97,100,1,13.99,100,1,11.92,100,1,14.06,100,1,11.9,700,1,14.14,700,1,11.85,700,1,14.2,700,1,11.82,700,1,14.24,100,1,11.79,700,1,14.26,100,1,ARL,482798553
,2025-07-17T18:19:50.478297341Z,2025-07-17T18:19:50.478297341Z,10,2,1108,C,B,3,12.05,100,0,165511,394363038,12.49,2,1,13.43,20,2,12.23,100,1,13.44,2,1,12.22,100,1,13.45,100,1,12.05,100,1,13.73,100,1,11.97,100,1,13.99,100,1,11.92,100,1,14.06,100,1,11.9,700,1,14.14,700,1,11.85,700,1,14.2,700,1,11.82,700,1,14.24,100,1,11.79,700,1,14.26,100,1,ARL,457630209
,2025-07-17T18:19:50.478404811Z,2025-07-17T18:19:50.478404811Z,10,2,1108,C,B,3,12.05,100,0,165790,394363039,12.49,2,1,13.43,20,2,12.23,100,1,13.44,2,1,12.22,100,1,13.45,100,1,11.97,100,1,13.73,100,1,11.92,100,1,13.99,100,1,11.9,700,1,14.06,100,1,11.85,700,1,14.14,700,1,11.82,700,1,14.2,700,1,11.79,700,1,14.24,100,1,11.76,100,1,14.26,100,1,ARL,457630269
,2025-07-17T18:19:50.487934498Z,2025-07-17T18:19:50.487934498Z,10,2,1108,C,A,2,13.45,100,130,165254,394363891,12.49,2,1,13.43,20,2,12.23,100,1,13.44,2,1,12.22,100,1,13.73,100,1,11.97,100,1,13.99,100,1,11.92,100,1,14.06,100,1,11.9,700,1,14.14,700,1,11.85,700,1,14.2,700,1,11.82,700,1,14.24,100,1,11.79,700,1,14.26,100,1,11.76,100,1,14.33,200,2,ARL,457194033
,2025-07-17T18:19:50.492220295Z,2025-07-17T18:19:50.492220295Z,10,2,1108,A,A,3,13.74,100,130,165226,394364230,12.49,2,1,13.43,20,2,12.23,100,1,13.44,2,1,12.22,100,1,13.73,100,1,11.97,100,1,13.74,100,1,11.92,100,1,13.99,100,1,11.9,700,1,14.06,100,1,11.85,700,1,14.14,700,1,11.82,700,1,14.2,700,1,11.79,700,1,14.24,100,1,11.76,100,1,14.26,100,1,ARL,482851573
,2025-07-17T18:19:50.980530549Z,2025-07-17T18:19:50.980530549Z,10,2,1108,C,A,3,13.74,100,0,165332,394370279,12.49,2,1,13.43,20,2,12.23,100,1,13.44,2,1,12.22,100,1,13.73,100,1,11.97,100,1,13.99,100,1,11.92,100,1,14.06,100,1,11.9,700,1,14.14,700,1,11.85,700,1,14.2,700,1,11.82,700,1,14.24,100,1,11.79,700,1,14.26,100,1,11.76,100,1,14.33,200,2,ARL,482851573
,2025-07-17T18:19:50.980530549Z,2025-07-17T18:19:50.980530549Z,10,2,1108,A,A,2,13.45,100,130,165332,394370279,12.49,2,1,13.43,20,2,12.23,100,1,13.44,2,1,12.22,100,1,13.45,100,1,11.97,100,1,13.73,100,1,11.92,100,1,13.99,100,1,11.9,700,1,14.06,100,1,11.85,700,1,14.14,700,1,11.82,700,1,14.2,700,1,11.79,700,1,14.24,100,1,11.76,100,1,14.26,100,1,ARL,482863949
,2025-07-17T18:20:07.054794050Z,2025-07-17T18:20:07.054794050Z,10,2,1108,C,A,0,13.43,10,130,165248,394619081,12.49,2,1,13.43,10,1,12.23,100,1,13.44,2,1,12.22,100,1,13.45,100,1,11.97,100,1,13.73,100,1,11.92,100,1,13.99,100,1,11.9,700,1,14.06,100,1,11.85,700,1,14.14,700,1,11.82,700,1,14.2,700,1,11.79,700,1,14.24,100,1,11.76,100,1,14.26,100,1,ARL,482798553
,2025-07-17T18:20:13.055117687Z,2025-07-17T18:20:13.055117687Z,10,2,1108,A,A,0,13.43,10,130,165461,394709628,12.49,2,1,13.43,20,2,12.23,100,1,13.44,2,1,12.22,100,1,13.45,100,1,11.97,100,1,13.73,100,1,11.92,100,1,13.99,100,1,11.9,700,1,14.06,100,1,11.85,700,1,14.14,700,1,11.82,700,1,14.2,700,1,11.79,700,1,14.24,100,1,11.76,100,1,14.26,100,1,ARL,483298361
,2025-07-17T18:20:18.733857768Z,2025-07-17T18:20:18.733857768Z,10,2,1108,C,A,0,13.43,10,130,165209,394792459,12.49,2,1,13.43,10,1,12.23,100,1,13.44,2,1,12.22,100,1,13.45,100,1,11.97,100,1,13.73,100,1,11.92,100,1,13.99,100,1,11.9,700,1,14.06,100,1,11.85,700,1,14.14,700,1,11.82,700,1,14.2,700,1,11.79,700,1,14.24,100,1,11.76,100,1,14.26,100,1,ARL,483298361
,2025-07-17T18:20:31.890228636Z,2025-07-17T18:20:31.890228636Z,10,2,1108,A,A,0,13.43,10,130,166612,394964577,12.49,2,1,13.43,20,2,12.23,100,1,13.44,2,1,12.22,100,1,13.45,100,1,11.97,100,1,13.73,100,1,11.92,100,1,13.99,100,1,11.9,700,1,14.06,100,1,11.85,700,1,14.14,700,1,11.82,700,1,14.2,700,1,11.79,700,1,14.24,100,1,11.76,100,1,14.26,100,1,ARL,483612169
,2025-07-17T18:21:34.342574608Z,2025-07-17T18:21:34.342574608Z,10,2,1108,C,B,0,12.49,2,0,167003,395825259,12.23,100,1,13.43,20,2,12.22,100,1,13.44,2,1,11.97,100,1,13.45,100,1,11.92,100,1,13.73,100,1,11.9,700,1,13.99,100,1,11.85,700,1,14.06,100,1,11.82,700,1,14.14,700,1,11.79,700,1,14.2,700,1,11.76,100,1,14.24,100,1,11.72,100,1,14.26,100,1,ARL,390297773
,2025-07-17T18:21:34.342574608Z,2025-07-17T18:21:34.342574608Z,10,2,1108,A,B,0,12.37,2,130,167003,395825259,12.37,2,1,13.43,20,2,12.23,100,1,13.44,2,1,12.22,100,1,13.45,100,1,11.97,100,1,13.73,100,1,11.92,100,1,13.99,100,1,11.9,700,1,14.06,100,1,11.85,700,1,14.14,700,1,11.82,700,1,14.2,700,1,11.79,700,1,14.24,100,1,11.76,100,1,14.26,100,1,ARL,484764453
,2025-07-17T18:21:41.375189503Z,2025-07-17T18:21:41.375189503Z,10,2,1108,C,A,0,13.43,10,130,165230,395912308,12.37,2,1,13.43,10,1,12.23,100,1,13.44,2,1,12.22,100,1,13.45,100,1,11.97,100,1,13.73,100,1,11.92,100,1,13.99,100,1,11.9,700,1,14.06,100,1,11.85,700,1,14.14,700,1,11.82,700,1,14.2,700,1,11.79,700,1,14.24,100,1,11.76,100,1,14.26,100,1,ARL,483612169
,2025-07-17T18:21:42.509963215Z,2025-07-17T18:21:42.509963215Z,10,2,1108,A,A,0,13.43,10,130,165257,395938501,12.37,2,1,13.43,20,2,12.23,100,1,13.44,2,1,12.22,100,1,13.45,100,1,11.97,100,1,13.73,100,1,11.92,100,1,13.99,100,1,11.9,700,1,14.06,100,1,11.85,700,1,14.14,700,1,11.82,700,1,14.2,700,1,11.79,700,1,14.24,100,1,11.76,100,1,14.26,100,1,ARL,484908201
,2025-07-17T18:21:43.021411133Z,2025-07-17T18:21:43.021411133Z,10,2,1108,C,A,0,13.43,10,130,165314,395964087,12.37,2,1,13.43,10,1,12.23,100,1,13.44,2,1,12.22,100,1,13.45,100,1,11.97,100,1,13.73,100,1,11.92,100,1,13.99,100,1,11.9,700,1,14.06,100,1,11.85,700,1,14.14,700,1,11.82,700,1,14.2,700,1,11.79,700,1,14.24,100,1,11.76,100,1,14.26,100,1,ARL,484908201
,2025-07-17T18:21:52.394059116Z,2025-07-17T18:21:52.394059116Z,10,2,1108,C,A,1,13.44,2,0,165619,396204170,12.37,2,1,13.43,10,1,12.23,100,1,13.45,100,1,12.22,100,1,13.73,100,1,11.97,100,1,13.99,100,1,11.92,100,1,14.06,100,1,11.9,700,1,14.14,700,1,11.85,700,1,14.2,700,1,11.82,700,1,14.24,100,1,11.79,700,1,14.26,100,1,11.76,100,1,14.33,200,2,ARL,407450073
,2025-07-17T18:21:52.394059116Z,2025-07-17T18:21:52.394059116Z,10,2,1108,A,A,2,13.56,2,130,165619,396204170,12.37,2,1,13.43,10,1,12.23,100,1,13.45,100,1,12.22,100,1,13.56,2,1,11.97,100,1,13.73,100,1,11.92,100,1,13.99,100,1,11.9,700,1,14.06,100,1,11.85,700,1,14.14,700,1,11.82,700,1,14.2,700,1,11.79,700,1,14.24,100,1,11.76,100,1,14.26,100,1,ARL,485232841
,2025-07-17T18:21:55.669141274Z,2025-07-17T18:21:55.669141274Z,10,2,1108,C,A,1,13.45,100,0,165597,396249515,12.37,2,1,13.43,10,1,12.23,100,1,13.56,2,1,12.22,100,1,13.73,100,1,11.97,100,1,13.99,100,1,11.92,100,1,14.06,100,1,11.9,700,1,14.14,700,1,11.85,700,1,14.2,700,1,11.82,700,1,14.24,100,1,11.79,700,1,14.26,100,1,11.76,100,1,14.33,200,2,ARL,482863949
,2025-07-17T18:21:55.669141274Z,2025-07-17T18:21:55.669141274Z,10,2,1108,A,A,1,13.44,100,130,165597,396249515,12.37,2,1,13.43,10,1,12.23,100,1,13.44,100,1,12.22,100,1,13.56,2,1,11.97,100,1,13.73,100,1,11.92,100,1,13.99,100,1,11.9,700,1,14.06,100,1,11.85,700,1,14.14,700,1,11.82,700,1,14.2,700,1,11.79,700,1,14.24,100,1,11.76,100,1,14.26,100,1,ARL,485292661
,2025-07-17T18:21:55.669742041Z,2025-07-17T18:21:55.669742041Z,10,2,1108,A,A,4,13.74,4,130,165086,396249524,12.37,2,1,13.43,10,1,12.23,100,1,13.44,100,1,12.22,100,1,13.56,2,1,11.97,100,1,13.73,100,1,11.92,100,1,13.74,4,1,11.9,700,1,13.99,100,1,11.85,700,1,14.06,100,1,11.82,700,1,14.14,700,1,11.79,700,1,14.2,700,1,11.76,100,1,14.24,100,1,ARL,485292677
,2025-07-17T18:22:01.058506892Z,2025-07-17T18:22:01.058506892Z,10,2,1108,A,A,0,13.43,10,130,165369,396320334,12.37,2,1,13.43,20,2,12.23,100,1,13.44,100,1,12.22,100,1,13.56,2,1,11.97,100,1,13.73,100,1,11.92,100,1,13.74,4,1,11.9,700,1,13.99,100,1,11.85,700,1,14.06,100,1,11.82,700,1,14.14,700,1,11.79,700,1,14.2,700,1,11.76,100,1,14.24,100,1,ARL,485391097
,2025-07-17T18:22:13.435844247Z,2025-07-17T18:22:13.435844247Z,10,2,1108,C,A,0,13.43,10,130,165056,396492898,12.37,2,1,13.43,10,1,12.23,100,1,13.44,100,1,12.22,100,1,13.56,2,1,11.97,100,1,13.73,100,1,11.92,100,1,13.74,4,1,11.9,700,1,13.99,100,1,11.85,700,1,14.06,100,1,11.82,700,1,14.14,700,1,11.79,700,1,14.2,700,1,11.76,100,1,14.24,100,1,ARL,485391097
,2025-07-17T18:22:39.060839850Z,2025-07-17T18:22:39.060839850Z,10,2,1108,A,A,0,13.43,10,130,165490,396801846,12.37,2,1,13.43,20,2,12.23,100,1,13.44,100,1,12.22,100,1,13.56,2,1,11.97,100,1,13.73,100,1,11.92,100,1,13.74,4,1,11.9,700,1,13.99,100,1,11.85,700,1,14.06,100,1,11.82,700,1,14.14,700,1,11.79,700,1,14.2,700,1,11.76,100,1,14.24,100,1,ARL,486051129
,2025-07-17T18:24:02.569341036Z,2025-07-17T18:24:02.569341036Z,10,2,1108,C,A,0,13.43,10,130,165169,397768837,12.37,2,1,13.43,10,1,12.23,100,1,13.44,100,1,12.22,100,1,13.56,2,1,11.97,100,1,13.73,100,1,11.92,100,1,13.74,4,1,11.9,700,1,13.99,100,1,11.85,700,1,14.06,100,1,11.82,700,1,14.14,700,1,11.79,700,1,14.2,700,1,11.76,100,1,14.24,100,1,ARL,486051129
,2025-07-17T18:24:05.242489364Z,2025-07-17T18:24:05.242489364Z,10,2,1108,A,A,0,13.43,10,130,165253,397805897,12.37,2,1,13.43,20,2,12.23,100,1,13.44,100,1,12.22,100,1,13.56,2,1,11.97,100,1,13.73,100,1,11.92,100,1,13.74,4,1,11.9,700,1,13.99,100,1,11.85,700,1,14.06,100,1,11.82,700,1,14.14,700,1,11.79,700,1,14.2,700,1,11.76,100,1,14.24,100,1,ARL,487432113
,2025-07-17T18:24:20.246982063Z,2025-07-17T18:24:20.246982063Z,10,2,1108,C,A,0,13.43,10,130,166084,398013865,12.37,2,1,13.43,10,1,12.23,100,1,13.44,100,1,12.22,100,1,13.56,2,1,11.97,100,1,13.73,100,1,11.92,100,1,13.74,4,1,11.9,700,1,13.99,100,1,11.85,700,1,14.06,100,1,11.82,700,1,14.14,700,1,11.79,700,1,14.2,700,1,11.76,100,1,14.24,100,1,ARL,487432113
,2025-07-17T18:25:00.146030189Z,2025-07-17T18:25:00.146030189Z,10,2,1108,A,A,0,13.43,10,128,177493,398730846,12.37,2,1,13.43,20,2,12.23,100,1,13.44,100,1,12.22,100,1,13.56,2,1,11.97,100,1,13.73,100,1,11.92,100,1,13.74,4,1,11.9,700,1,13.99,100,1,11.85,700,1,14.06,100,1,11.82,700,1,14.14,700,1,11.79,700,1,14.2,700,1,11.76,100,1,14.24,100,1,ARL,488547681
,2025-07-17T18:25:04.834777122Z,2025-07-17T18:25:04.834777122Z,10,2,1108,C,A,0,13.43,10,130,165334,398832320,12.37,2,1,13.43,10,1,12.23,100,1,13.44,100,1,12.22,100,1,13.56,2,1,11.97,100,1,13.73,100,1,11.92,100,1,13.74,4,1,11.9,700,1,13.99,100,1,11.85,700,1,14.06,100,1,11.82,700,1,14.14,700,1,11.79,700,1,14.2,700,1,11.76,100,1,14.24,100,1,ARL,488547681
,2025-07-17T18:25:13.233934332Z,2025-07-17T18:25:13.233934332Z,10,2,1108,A,A,0,13.43,10,130,165613,398973618,12.37,2,1,13.43,20,2,12.23,100,1,13.44,100,1,12.22,100,1,13.56,2,1,11.97,100,1,13.73,100,1,11.92,100,1,13.74,4,1,11.9,700,1,13.99,100,1,11.85,700,1,14.06,100,1,11.82,700,1,14.14,700,1,11.79,700,1,14.2,700,1,11.76,100,1,14.24,100,1,ARL,488839225
,2025-07-17T18:25:32.715248018Z,2025-07-17T18:25:32.715248018Z,10,2,1108,A,B,9,11.76,100,130,165488,399247257,12.37,2,1,13.43,20,2,12.23,100,1,13.44,100,1,12.22,100,1,13.56,2,1,11.97,100,1,13.73,100,1,11.92,100,1,13.74,4,1,11.9,700,1,13.99,100,1,11.85,700,1,14.06,100,1,11.82,700,1,14.14,700,1,11.79,700,1,14.2,700,1,11.76,200,2,14.24,100,1,ARL,489200865
,2025-07-17T18:25:32.715715815Z,2025-07-17T18:25:32.715715815Z,10,2,1108,A,B,9,11.76,100,130,165427,399247258,12.37,2,1,13.43,20,2,12.23,100,1,13.44,100,1,12.22,100,1,13.56,2,1,11.97,100,1,13.73,100,1,11.92,100,1,13.74,4,1,11.9,700,1,13.99,100,1,11.85,700,1,14.06,100,1,11.82,700,1,14.14,700,1,11.79,700,1,14.2,700,1,11.76,300,3,14.24,100,1,ARL,489200877
,2025-07-17T18:28:52.016623464Z,2025-07-17T18:28:52.016623464Z,10,2,1108,C,A,0,13.43,10,130,166192,401929725,12.37,2,1,13.43,10,1,12.23,100,1,13.44,100,1,12.22,100,1,13.56,2,1,11.97,100,1,13.73,100,1,11.92,100,1,13.74,4,1,11.9,700,1,13.99,100,1,11.85,700,1,14.06,100,1,11.82,700,1,14.14,700,1,11.79,700,1,14.2,700,1,11.76,300,3,14.24,100,1,ARL,488839225
,2025-07-17T18:28:53.050696982Z,2025-07-17T18:28:53.050696982Z,10,2,1108,A,A,0,13.43,10,130,165292,401946425,12.37,2,1,13.43,20,2,12.23,100,1,13.44,100,1,12.22,100,1,13.56,2,1,11.97,100,1,13.73,100,1,11.92,100,1,13.74,4,1,11.9,700,1,13.99,100,1,11.85,700,1,14.06,100,1,11.82,700,1,14.14,700,1,11.79,700,1,14.2,700,1,11.76,300,3,14.24,100,1,ARL,492865077
,2025-07-17T18:29:05.900193653Z,2025-07-17T18:29:05.900193653Z,10,2,1108,A,A,0,13.3,10,130,165356,402134637,12.37,2,1,13.3,10,1,12.23,100,1,13.43,20,2,12.22,100,1,13.44,100,1,11.97,100,1,13.56,2,1,11.92,100,1,13.73,100,1,11.9,700,1,13.74,4,1,11.85,700,1,13.99,100,1,11.82,700,1,14.06,100,1,11.79,700,1,14.14,700,1,11.76,300,3,14.2,700,1,ARL,493143705
,2025-07-17T18:29:05.901152755Z,2025-07-17T18:29:05.901152755Z,10,2,1108,A,A,9,14.17,100,130,165553,402134673,12.37,2,1,13.3,10,1,12.23,100,1,13.43,20,2,12.22,100,1,13.44,100,1,11.97,100,1,13.56,2,1,11.92,100,1,13.73,100,1,11.9,700,1,13.74,4,1,11.85,700,1,13.99,100,1,11.82,700,1,14.06,100,1,11.79,700,1,14.14,700,1,11.76,300,3,14.17,100,1,ARL,493143725
