,ts_recv,ts_event,rtype,publisher_id,instrument_id,action,side,depth,price,size,flags,ts_in_delta,sequence,bid_px_00,bid_sz_00,bid_ct_00,ask_px_00,ask_sz_00,ask_ct_00,bid_px_01,bid_sz_01,bid_ct_01,ask_px_01,ask_sz_01,ask_ct_01,bid_px_02,bid_sz_02,bid_ct_02,ask_px_02,ask_sz_02,ask_ct_02,bid_px_03,bid_sz_03,bid_ct_03,ask_px_03,ask_sz_03,ask_ct_03,bid_px_04,bid_sz_04,bid_ct_04,ask_px_04,ask_sz_04,ask_ct_04,bid_px_05,bid_sz_05,bid_ct_05,ask_px_05,ask_sz_05,ask_ct_05,bid_px_06,bid_sz_06,bid_ct_06,ask_px_06,ask_sz_06,ask_ct_06,bid_px_07,bid_sz_07,bid_ct_07,ask_px_07,ask_sz_07,ask_ct_07,bid_px_08,bid_sz_08,bid_ct_08,ask_px_08,ask_sz_08,ask_ct_08,bid_px_09,bid_sz_09,bid_ct_09,ask_px_09,ask_sz_09,ask_ct_09,symbol,order_id
,2025-07-17T16:02:20.663241882Z,2025-07-17T16:02:20.663241882Z,10,2,1108,C,A,5,14.53,700,130,164979,271676275,13.27,10,1,13.83,15,1,13.26,100,1,13.92,2,1,13.03,100,1,14.28,100,1,12.91,2,1,14.45,100,1,12.73,100,1,14.51,100,1,12.71,100,1,14.56,800,2,12.5,700,1,14.6,700,1,12.46,200,2,14.63,100,1,12.43,700,1,14.64,100,1,12.42,700,1,14.68,700,1,ARL,325714545
,2025-07-17T16:02:20.663261632Z,2025-07-17T16:02:20.663261632Z,10,2,1108,A,A,2,14.11,100,130,165342,271676276,13.27,10,1,13.83,15,1,13.26,100,1,13.92,2,1,13.03,100,1,14.11,100,1,12.91,2,1,14.28,100,1,12.73,100,1,14.45,100,1,12.71,100,1,14.51,100,1,12.5,700,1,14.56,800,2,12.46,200,2,14.6,700,1,12.43,700,1,14.63,100,1,12.42,700,1,14.64,100,1,ARL,325714905
,2025-07-17T16:02:20.669536385Z,2025-07-17T16:02:20.669536385Z,10,2,1108,C,A,2,14.11,100,130,165067,271676398,13.27,10,1,13.83,15,1,13.26,100,1,13.92,2,1,13.03,100,1,14.28,100,1,12.91,2,1,14.45,100,1,12.73,100,1,14.51,100,1,12.71,100,1,14.56,800,2,12.5,700,1,14.6,700,1,12.46,200,2,14.63,100,1,12.43,700,1,14.64,100,1,12.42,700,1,14.68,700,1,ARL,325714905
,2025-07-17T16:02:20.669583810Z,2025-07-17T16:02:20.669583810Z,10,2,1108,A,A,2,14.26,100,130,165144,271676399,13.27,10,1,13.83,15,1,13.26,100,1,13.92,2,1,13.03,100,1,14.26,100,1,12.91,2,1,14.28,100,1,12.73,100,1,14.45,100,1,12.71,100,1,14.51,100,1,12.5,700,1,14.56,800,2,12.46,200,2,14.6,700,1,12.43,700,1,14.63,100,1,12.42,700,1,14.64,100,1,ARL,325715045
,2025-07-17T16:02:20.669587514Z,2025-07-17T16:02:20.669587514Z,10,2,1108,C,A,5,14.51,100,0,165465,271676400,13.27,10,1,13.83,15,1,13.26,100,1,13.92,2,1,13.03,100,1,14.26,100,1,12.91,2,1,14.28,100,1,12.73,100,1,14.45,100,1,12.71,100,1,14.56,800,2,12.5,700,1,14.6,700,1,12.46,200,2,14.63,100,1,12.43,700,1,14.64,100,1,12.42,700,1,14.68,700,1,ARL,325177757
,2025-07-17T16:02:20.685086585Z,2025-07-17T16:02:20.685086585Z,10,2,1108,C,A,8,14.64,100,0,165464,271676621,13.27,10,1,13.83,15,1,13.26,100,1,13.92,2,1,13.03,100,1,14.26,100,1,12.91,2,1,14.28,100,1,12.73,100,1,14.45,100,1,12.71,100,1,14.56,800,2,12.5,700,1,14.6,700,1,12.46,200,2,14.63,100,1,12.43,700,1,14.68,700,1,12.42,700,1,14.73,200,2,ARL,325714169
,2025-07-17T16:02:20.831947250Z,2025-07-17T16:02:20.831947250Z,10,2,1108,A,A,8,14.68,700,130,165387,271678584,13.27,10,1,13.83,15,1,13.26,100,1,13.92,2,1,13.03,100,1,14.26,100,1,12.91,2,1,14.28,100,1,12.73,100,1,14.45,100,1,12.71,100,1,14.56,800,2,12.5,700,1,14.6,700,1,12.46,200,2,14.63,100,1,12.43,700,1,14.68,1400,2,12.42,700,1,14.73,200,2,ARL,325716945
,2025-07-17T16:02:20.936622241Z,2025-07-17T16:02:20.936622241Z,10,2,1108,C,B,1,13.26,100,130,165177,271679553,13.27,10,1,13.83,15,1,13.03,100,1,13.92,2,1,12.91,2,1,14.26,100,1,12.73,100,1,14.28,100,1,12.71,100,1,14.45,100,1,12.5,700,1,14.56,800,2,12.46,200,2,14.6,700,1,12.43,700,1,14.63,100,1,12.42,700,1,14.68,1400,2,12.37,700,1,14.73,200,2,ARL,325714729
,2025-07-17T16:02:20.936672130Z,2025-07-17T16:02:20.936672130Z,10,2,1108,A,A,1,13.91,5,130,165481,271679555,13.27,10,1,13.83,15,1,13.03,100,1,13.91,5,1,12.91,2,1,13.92,2,1,12.73,100,1,14.26,100,1,12.71,100,1,14.28,100,1,12.5,700,1,14.45,100,1,12.46,200,2,14.56,800,2,12.43,700,1,14.6,700,1,12.42,700,1,14.63,100,1,12.37,700,1,14.68,1400,2,ARL,325718477
,2025-07-17T16:02:20.936748894Z,2025-07-17T16:02:20.936748894Z,10,2,1108,T,N,0,13.28,11,130,166007,271679557,13.27,10,1,13.83,15,1,13.03,100,1,13.91,5,1,12.91,2,1,13.92,2,1,12.73,100,1,14.26,100,1,12.71,100,1,14.28,100,1,12.5,700,1,14.45,100,1,12.46,200,2,14.56,800,2,12.43,700,1,14.6,700,1,12.42,700,1,14.63,100,1,12.37,700,1,14.68,1400,2,ARL,0
,2025-07-17T16:02:20.936833988Z,2025-07-17T16:02:20.936833988Z,10,2,1108,A,A,1,13.84,100,130,165223,271679558,13.27,10,1,13.83,15,1,13.03,100,1,13.84,100,1,12.91,2,1,13.91,5,1,12.73,100,1,13.92,2,1,12.71,100,1,14.26,100,1,12.5,700,1,14.28,100,1,12.46,200,2,14.45,100,1,12.43,700,1,14.56,800,2,12.42,700,1,14.6,700,1,12.37,700,1,14.63,100,1,ARL,325718485
,2025-07-17T16:02:20.937142186Z,2025-07-17T16:02:20.937142186Z,10,2,1108,T,N,0,13.28,11,130,165749,271679562,13.27,10,1,13.83,15,1,13.03,100,1,13.84,100,1,12.91,2,1,13.91,5,1,12.73,100,1,13.92,2,1,12.71,100,1,14.26,100,1,12.5,700,1,14.28,100,1,12.46,200,2,14.45,100,1,12.43,700,1,14.56,800,2,12.42,700,1,14.6,700,1,12.37,700,1,14.63,100,1,ARL,0
,2025-07-17T16:02:20.937736247Z,2025-07-17T16:02:20.937736247Z,10,2,1108,C,A,2,13.91,5,130,165046,271679567,13.27,10,1,13.83,15,1,13.03,100,1,13.84,100,1,12.91,2,1,13.92,2,1,12.73,100,1,14.26,100,1,12.71,100,1,14.28,100,1,12.5,700,1,14.45,100,1,12.46,200,2,14.56,800,2,12.43,700,1,14.6,700,1,12.42,700,1,14.63,100,1,12.37,700,1,14.68,1400,2,ARL,325718477
,2025-07-17T16:02:20.939389367Z,2025-07-17T16:02:20.939389367Z,10,2,1108,A,B,2,13.02,100,130,165319,271679578,13.27,10,1,13.83,15,1,13.03,100,1,13.84,100,1,13.02,100,1,13.92,2,1,12.91,2,1,14.26,100,1,12.73,100,1,14.28,100,1,12.71,100,1,14.45,100,1,12.5,700,1,14.56,800,2,12.46,200,2,14.6,700,1,12.43,700,1,14.63,100,1,12.42,700,1,14.68,1400,2,ARL,325718561
,2025-07-17T16:02:20.946240970Z,2025-07-17T16:02:20.946240970Z,10,2,1108,C,A,3,14.26,100,130,165232,271679616,13.27,10,1,13.83,15,1,13.03,100,1,13.84,100,1,13.02,100,1,13.92,2,1,12.91,2,1,14.28,100,1,12.73,100,1,14.45,100,1,12.71,100,1,14.56,800,2,12.5,700,1,14.6,700,1,12.46,200,2,14.63,100,1,12.43,700,1,14.68,1400,2,12.42,700,1,14.73,200,2,ARL,325715045
,2025-07-17T16:02:20.946291345Z,2025-07-17T16:02:20.946291345Z,10,2,1108,A,A,3,14.12,100,130,165441,271679617,13.27,10,1,13.83,15,1,13.03,100,1,13.84,100,1,13.02,100,1,13.92,2,1,12.91,2,1,14.12,100,1,12.73,100,1,14.28,100,1,12.71,100,1,14.45,100,1,12.5,700,1,14.56,800,2,12.46,200,2,14.6,700,1,12.43,700,1,14.63,100,1,12.42,700,1,14.68,1400,2,ARL,325718637
,2025-07-17T16:02:20.956886401Z,2025-07-17T16:02:20.956886401Z,10,2,1108,C,B,2,13.02,100,0,165212,271679685,13.27,10,1,13.83,15,1,13.03,100,1,13.84,100,1,12.91,2,1,13.92,2,1,12.73,100,1,14.12,100,1,12.71,100,1,14.28,100,1,12.5,700,1,14.45,100,1,12.46,200,2,14.56,800,2,12.43,700,1,14.6,700,1,12.42,700,1,14.63,100,1,12.37,700,1,14.68,1400,2,ARL,325718561
,2025-07-17T16:02:20.956886401Z,2025-07-17T16:02:20.956886401Z,10,2,1108,A,B,1,13.26,100,130,165212,271679685,13.27,10,1,13.83,15,1,13.26,100,1,13.84,100,1,13.03,100,1,13.92,2,1,12.91,2,1,14.12,100,1,12.73,100,1,14.28,100,1,12.71,100,1,14.45,100,1,12.5,700,1,14.56,800,2,12.46,200,2,14.6,700,1,12.43,700,1,14.63,100,1,12.42,700,1,14.68,1400,2,ARL,325718821
,2025-07-17T16:02:20.956923753Z,2025-07-17T16:02:20.956923753Z,10,2,1108,A,B,2,13.12,100,130,165390,271679686,13.27,10,1,13.83,15,1,13.26,100,1,13.84,100,1,13.12,100,1,13.92,2,1,13.03,100,1,14.12,100,1,12.91,2,1,14.28,100,1,12.73,100,1,14.45,100,1,12.71,100,1,14.56,800,2,12.5,700,1,14.6,700,1,12.46,200,2,14.63,100,1,12.43,700,1,14.68,1400,2,ARL,325718833
,2025-07-17T16:02:20.956925447Z,2025-07-17T16:02:20.956925447Z,10,2,1108,A,B,2,13.12,100,130,165037,271679687,13.27,10,1,13.83,15,1,13.26,100,1,13.84,100,1,13.12,200,2,13.92,2,1,13.03,100,1,14.12,100,1,12.91,2,1,14.28,100,1,12.73,100,1,14.45,100,1,12.71,100,1,14.56,800,2,12.5,700,1,14.6,700,1,12.46,200,2,14.63,100,1,12.43,700,1,14.68,1400,2,ARL,325718837
,2025-07-17T16:02:20.988490644Z,2025-07-17T16:02:20.988490644Z,10,2,1108,A,A,3,13.98,100,130,165226,271679923,13.27,10,1,13.83,15,1,13.26,100,1,13.84,100,1,13.12,200,2,13.92,2,1,13.03,100,1,13.98,100,1,12.91,2,1,14.12,100,1,12.73,100,1,14.28,100,1,12.71,100,1,14.45,100,1,12.5,700,1,14.56,800,2,12.46,200,2,14.6,700,1,12.43,700,1,14.63,100,1,ARL,325719353
,2025-07-17T16:02:20.988491826Z,2025-07-17T16:02:20.988491826Z,10,2,1108,A,A,3,13.98,100,130,165118,271679924,13.27,10,1,13.83,15,1,13.26,100,1,13.84,100,1,13.12,200,2,13.92,2,1,13.03,100,1,13.98,200,2,12.91,2,1,14.12,100,1,12.73,100,1,14.28,100,1,12.71,100,1,14.45,100,1,12.5,700,1,14.56,800,2,12.46,200,2,14.6,700,1,12.43,700,1,14.63,100,1,ARL,325719357
,2025-07-17T16:02:30.805028316Z,2025-07-17T16:02:30.805028316Z,10,2,1108,C,B,0,13.27,10,130,165379,271818376,13.26,100,1,13.83,15,1,13.12,200,2,13.84,100,1,13.03,100,1,13.92,2,1,12.91,2,1,13.98,200,2,12.73,100,1,14.12,100,1,12.71,100,1,14.28,100,1,12.5,700,1,14.45,100,1,12.46,200,2,14.56,800,2,12.43,700,1,14.6,700,1,12.42,700,1,14.63,100,1,ARL,325714717
,2025-07-17T16:02:34.987005787Z,2025-07-17T16:02:34.987005787Z,10,2,1108,C,B,3,12.91,2,0,165610,271871706,13.26,100,1,13.83,15,1,13.12,200,2,13.84,100,1,13.03,100,1,13.92,2,1,12.73,100,1,13.98,200,2,12.71,100,1,14.12,100,1,12.5,700,1,14.28,100,1,12.46,200,2,14.45,100,1,12.43,700,1,14.56,800,2,12.42,700,1,14.6,700,1,12.37,700,1,14.63,100,1,ARL,325714741
,2025-07-17T16:02:34.987005787Z,2025-07-17T16:02:34.987005787Z,10,2,1108,A,B,3,13.0,2,130,165610,271871706,13.26,100,1,13.83,15,1,13.12,200,2,13.84,100,1,13.03,100,1,13.92,2,1,13.0,2,1,13.98,200,2,12.73,100,1,14.12,100,1,12.71,100,1,14.28,100,1,12.5,700,1,14.45,100,1,12.46,200,2,14.56,800,2,12.43,700,1,14.6,700,1,12.42,700,1,14.63,100,1,ARL,325967705
,2025-07-17T16:02:39.809299504Z,2025-07-17T16:02:39.809299504Z,10,2,1108,A,A,0,13.79,15,130,165457,271952021,13.26,100,1,13.79,15,1,13.12,200,2,13.83,15,1,13.03,100,1,13.84,100,1,13.0,2,1,13.92,2,1,12.73,100,1,13.98,200,2,12.71,100,1,14.12,100,1,12.5,700,1,14.28,100,1,12.46,200,2,14.45,100,1,12.43,700,1,14.56,800,2,12.42,700,1,14.6,700,1,ARL,326077141
,2025-07-17T16:02:40.007306432Z,2025-07-17T16:02:40.007306432Z,10,2,1108,C,A,2,13.84,100,0,165588,271957331,13.26,100,1,13.79,15,1,13.12,200,2,13.83,15,1,13.03,100,1,13.92,2,1,13.0,2,1,13.98,200,2,12.73,100,1,14.12,100,1,12.71,100,1,14.28,100,1,12.5,700,1,14.45,100,1,12.46,200,2,14.56,800,2,12.43,700,1,14.6,700,1,12.42,700,1,14.63,100,1,ARL,325718485
,2025-07-17T16:02:40.007306432Z,2025-07-17T16:02:40.007306432Z,10,2,1108,A,A,1,13.8,100,130,165588,271957331,13.26,100,1,13.79,15,1,13.12,200,2,13.8,100,1,13.03,100,1,13.83,15,1,13.0,2,1,13.92,2,1,12.73,100,1,13.98,200,2,12.71,100,1,14.12,100,1,12.5,700,1,14.28,100,1,12.46,200,2,14.45,100,1,12.43,700,1,14.56,800,2,12.42,700,1,14.6,700,1,ARL,326082329
,2025-07-17T16:02:40.794847674Z,2025-07-17T16:02:40.794847674Z,10,2,1108,C,A,0,13.79,15,130,166797,271972417,13.26,100,1,13.8,100,1,13.12,200,2,13.83,15,1,13.03,100,1,13.92,2,1,13.0,2,1,13.98,200,2,12.73,100,1,14.12,100,1,12.71,100,1,14.28,100,1,12.5,700,1,14.45,100,1,12.46,200,2,14.56,800,2,12.43,700,1,14.6,700,1,12.42,700,1,14.63,100,1,ARL,326077141
,2025-07-17T16:02:40.806140621Z,2025-07-17T16:02:40.806140621Z,10,2,1108,C,A,1,13.83,15,130,165274,271973288,13.26,100,1,13.8,100,1,13.12,200,2,13.92,2,1,13.03,100,1,13.98,200,2,13.0,2,1,14.12,100,1,12.73,100,1,14.28,100,1,12.71,100,1,14.45,100,1,12.5,700,1,14.56,800,2,12.46,200,2,14.6,700,1,12.43,700,1,14.63,100,1,12.42,700,1,14.68,1400,2,ARL,325714721
,2025-07-17T16:02:43.834262065Z,2025-07-17T16:02:43.834262065Z,10,2,1108,T,N,0,13.28,100,130,166097,272014629,13.26,100,1,13.8,100,1,13.12,200,2,13.92,2,1,13.03,100,1,13.98,200,2,13.0,2,1,14.12,100,1,12.73,100,1,14.28,100,1,12.71,100,1,14.45,100,1,12.5,700,1,14.56,800,2,12.46,200,2,14.6,700,1,12.43,700,1,14.63,100,1,12.42,700,1,14.68,1400,2,ARL,0
,2025-07-17T16:02:43.841686908Z,2025-07-17T16:02:43.841686908Z,10,2,1108,C,B,0,13.26,100,130,165522,272014658,13.12,200,2,13.8,100,1,13.03,100,1,13.92,2,1,13.0,2,1,13.98,200,2,12.73,100,1,14.12,100,1,12.71,100,1,14.28,100,1,12.5,700,1,14.45,100,1,12.46,200,2,14.56,800,2,12.43,700,1,14.6,700,1,12.42,700,1,14.63,100,1,12.37,700,1,14.68,1400,2,ARL,325718821
,2025-07-17T16:02:43.841746626Z,2025-07-17T16:02:43.841746626Z,10,2,1108,A,A,1,13.9,4,130,165427,272014659,13.12,200,2,13.8,100,1,13.03,100,1,13.9,4,1,13.0,2,1,13.92,2,1,12.73,100,1,13.98,200,2,12.71,100,1,14.12,100,1,12.5,700,1,14.28,100,1,12.46,200,2,14.45,100,1,12.43,700,1,14.56,800,2,12.42,700,1,14.6,700,1,12.37,700,1,14.63,100,1,ARL,326158809
,2025-07-17T16:02:43.842130114Z,2025-07-17T16:02:43.842130114Z,10,2,1108,C,A,0,13.8,100,130,165313,272014661,13.12,200,2,13.9,4,1,13.03,100,1,13.92,2,1,13.0,2,1,13.98,200,2,12.73,100,1,14.12,100,1,12.71,100,1,14.28,100,1,12.5,700,1,14.45,100,1,12.46,200,2,14.56,800,2,12.43,700,1,14.6,700,1,12.42,700,1,14.63,100,1,12.37,700,1,14.68,1400,2,ARL,326082329
,2025-07-17T16:02:43.842941514Z,2025-07-17T16:02:43.842941514Z,10,2,1108,A,B,1,13.11,100,130,165235,272014674,13.12,200,2,13.9,4,1,13.11,100,1,13.92,2,1,13.03,100,1,13.98,200,2,13.0,2,1,14.12,100,1,12.73,100,1,14.28,100,1,12.71,100,1,14.45,100,1,12.5,700,1,14.56,800,2,12.46,200,2,14.6,700,1,12.43,700,1,14.63,100,1,12.42,700,1,14.68,1400,2,ARL,326158877
,2025-07-17T16:02:43.843039530Z,2025-07-17T16:02:43.843039530Z,10,2,1108,C,A,0,13.9,4,130,165162,272014681,13.12,200,2,13.92,2,1,13.11,100,1,13.98,200,2,13.03,100,1,14.12,100,1,13.0,2,1,14.28,100,1,12.73,100,1,14.45,100,1,12.71,100,1,14.56,800,2,12.5,700,1,14.6,700,1,12.46,200,2,14.63,100,1,12.43,700,1,14.68,1400,2,12.42,700,1,14.73,200,2,ARL,326158809
,2025-07-17T16:02:43.844636465Z,2025-07-17T16:02:43.844636465Z,10,2,1108,C,A,10,14.81,100,0,165486,272014698,13.12,200,2,13.92,2,1,13.11,100,1,13.98,200,2,13.03,100,1,14.12,100,1,13.0,2,1,14.28,100,1,12.73,100,1,14.45,100,1,12.71,100,1,14.56,800,2,12.5,700,1,14.6,700,1,12.46,200,2,14.63,100,1,12.43,700,1,14.68,1400,2,12.42,700,1,14.73,200,2,ARL,325718517
,2025-07-17T16:02:43.846861336Z,2025-07-17T16:02:43.846861336Z,10,2,1108,C,A,0,13.92,2,0,165459,272014713,13.12,200,2,13.98,200,2,13.11,100,1,14.12,100,1,13.03,100,1,14.28,100,1,13.0,2,1,14.45,100,1,12.73,100,1,14.56,800,2,12.71,100,1,14.6,700,1,12.5,700,1,14.63,100,1,12.46,200,2,14.68,1400,2,12.43,700,1,14.73,200,2,12.42,700,1,14.92,100,1,ARL,325297093
,2025-07-17T16:02:43.846861336Z,2025-07-17T16:02:43.846861336Z,10,2,1108,A,A,1,14.03,2,130,165459,272014713,13.12,200,2,13.98,200,2,13.11,100,1,14.03,2,1,13.03,100,1,14.12,100,1,13.0,2,1,14.28,100,1,12.73,100,1,14.45,100,1,12.71,100,1,14.56,800,2,12.5,700,1,14.6,700,1,12.46,200,2,14.63,100,1,12.43,700,1,14.68,1400,2,12.42,700,1,14.73,200,2,ARL,326159041
,2025-07-17T16:02:43.847666979Z,2025-07-17T16:02:43.847666979Z,10,2,1108,C,A,9,14.73,100,0,165279,272014721,13.12,200,2,13.98,200,2,13.11,100,1,14.03,2,1,13.03,100,1,14.12,100,1,13.0,2,1,14.28,100,1,12.73,100,1,14.45,100,1,12.71,100,1,14.56,800,2,12.5,700,1,14.6,700,1,12.46,200,2,14.63,100,1,12.43,700,1,14.68,1400,2,12.42,700,1,14.73,100,1,ARL,325714613
,2025-07-17T16:02:43.847666979Z,2025-07-17T16:02:43.847666979Z,10,2,1108,A,A,10,14.87,100,130,165279,272014721,13.12,200,2,13.98,200,2,13.11,100,1,14.03,2,1,13.03,100,1,14.12,100,1,13.0,2,1,14.28,100,1,12.73,100,1,14.45,100,1,12.71,100,1,14.56,800,2,12.5,700,1,14.6,700,1,12.46,200,2,14.63,100,1,12.43,700,1,14.68,1400,2,12.42,700,1,14.73,100,1,ARL,326159049
,2025-07-17T16:02:43.847981726Z,2025-07-17T16:02:43.847981726Z,10,2,1108,C,A,9,14.73,100,0,165472,272014724,13.12,200,2,13.98,200,2,13.11,100,1,14.03,2,1,13.03,100,1,14.12,100,1,13.0,2,1,14.28,100,1,12.73,100,1,14.45,100,1,12.71,100,1,14.56,800,2,12.5,700,1,14.6,700,1,12.46,200,2,14.63,100,1,12.43,700,1,14.68,1400,2,12.42,700,1,14.87,100,1,ARL,325714577
,2025-07-17T16:02:43.847981726Z,2025-07-17T16:02:43.847981726Z,10,2,1108,A,A,9,14.87,100,130,165472,272014724,13.12,200,2,13.98,200,2,13.11,100,1,14.03,2,1,13.03,100,1,14.12,100,1,13.0,2,1,14.28,100,1,12.73,100,1,14.45,100,1,12.71,100,1,14.56,800,2,12.5,700,1,14.6,700,1,12.46,200,2,14.63,100,1,12.43,700,1,14.68,1400,2,12.42,700,1,14.87,200,2,ARL,326159061
,2025-07-17T16:02:43.860034354Z,2025-07-17T16:02:43.860034354Z,10,2,1108,C,A,2,14.12,100,130,165293,272014788,13.12,200,2,13.98,200,2,13.11,100,1,14.03,2,1,13.03,100,1,14.28,100,1,13.0,2,1,14.45,100,1,12.73,100,1,14.56,800,2,12.71,100,1,14.6,700,1,12.5,700,1,14.63,100,1,12.46,200,2,14.68,1400,2,12.43,700,1,14.87,200,2,12.42,700,1,14.92,100,1,ARL,325718637
,2025-07-17T16:02:43.860087215Z,2025-07-17T16:02:43.860087215Z,10,2,1108,A,A,2,14.26,100,130,165231,272014789,13.12,200,2,13.98,200,2,13.11,100,1,14.03,2,1,13.03,100,1,14.26,100,1,13.0,2,1,14.28,100,1,12.73,100,1,14.45,100,1,12.71,100,1,14.56,800,2,12.5,700,1,14.6,700,1,12.46,200,2,14.63,100,1,12.43,700,1,14.68,1400,2,12.42,700,1,14.87,200,2,ARL,326159201
,2025-07-17T16:02:43.893011012Z,2025-07-17T16:02:43.893011012Z,10,2,1108,C,A,10,14.92,100,0,165300,272014986,13.12,200,2,13.98,200,2,13.11,100,1,14.03,2,1,13.03,100,1,14.26,100,1,13.0,2,1,14.28,100,1,12.73,100,1,14.45,100,1,12.71,100,1,14.56,800,2,12.5,700,1,14.6,700,1,12.46,200,2,14.63,100,1,12.43,700,1,14.68,1400,2,12.42,700,1,14.87,200,2,ARL,326158869
,2025-07-17T16:02:43.946801538Z,2025-07-17T16:02:43.946801538Z,10,2,1108,C,A,7,14.63,100,0,165599,272015584,13.12,200,2,13.98,200,2,13.11,100,1,14.03,2,1,13.03,100,1,14.26,100,1,13.0,2,1,14.28,100,1,12.73,100,1,14.45,100,1,12.71,100,1,14.56,800,2,12.5,700,1,14.6,700,1,12.46,200,2,14.68,1400,2,12.43,700,1,14.87,200,2,12.42,700,1,14.96,200,2,ARL,325714653
,2025-07-17T16:02:43.946801538Z,2025-07-17T16:02:43.946801538Z,10,2,1108,A,A,8,14.77,100,130,165599,272015584,13.12,200,2,13.98,200,2,13.11,100,1,14.03,2,1,13.03,100,1,14.26,100,1,13.0,2,1,14.28,100,1,12.73,100,1,14.45,100,1,12.71,100,1,14.56,800,2,12.5,700,1,14.6,700,1,12.46,200,2,14.68,1400,2,12.43,700,1,14.77,100,1,12.42,700,1,14.87,200,2,ARL,326160141
,2025-07-17T16:02:44.664054457Z,2025-07-17T16:02:44.664054457Z,10,2,1108,A,A,1,13.99,100,130,165327,272021808,13.12,200,2,13.98,200,2,13.11,100,1,13.99,100,1,13.03,100,1,14.03,2,1,13.0,2,1,14.26,100,1,12.73,100,1,14.28,100,1,12.71,100,1,14.45,100,1,12.5,700,1,14.56,800,2,12.46,200,2,14.6,700,1,12.43,700,1,14.68,1400,2,12.42,700,1,14.77,100,1,ARL,326167529
,2025-07-17T16:03:02.985818199Z,2025-07-17T16:03:02.985818199Z,10,2,1108,C,A,10,14.87,100,0,169399,272331833,13.12,200,2,13.98,200,2,13.11,100,1,13.99,100,1,13.03,100,1,14.03,2,1,13.0,2,1,14.26,100,1,12.73,100,1,14.28,100,1,12.71,100,1,14.45,100,1,12.5,700,1,14.56,800,2,12.46,200,2,14.6,700,1,12.43,700,1,14.68,1400,2,12.42,700,1,14.77,100,1,ARL,326159049
,2025-07-17T16:03:02.985818199Z,2025-07-17T16:03:02.985818199Z,10,2,1108,A,A,9,14.7,100,128,169399,272331833,13.12,200,2,13.98,200,2,13.11,100,1,13.99,100,1,13.03,100,1,14.03,2,1,13.0,2,1,14.26,100,1,12.73,100,1,14.28,100,1,12.71,100,1,14.45,100,1,12.5,700,1,14.56,800,2,12.46,200,2,14.6,700,1,12.43,700,1,14.68,1400,2,12.42,700,1,14.7,100,1,ARL,326551237
,2025-07-17T16:03:02.987797728Z,2025-07-17T16:03:02.987797728Z,10,2,1108,A,A,9,14.7,100,128,172001,272332718,13.12,200,2,13.98,200,2,13.11,100,1,13.99,100,1,13.03,100,1,14.03,2,1,13.0,2,1,14.26,100,1,12.73,100,1,14.28,100,1,12.71,100,1,14.45,100,1,12.5,700,1,14.56,800,2,12.46,200,2,14.6,700,1,12.43,700,1,14.68,1400,2,12.42,700,1,14.7,200,2,ARL,326551829
,2025-07-17T16:03:10.807281669Z,2025-07-17T16:03:10.807281669Z,10,2,1108,A,A,0,13.72,15,130,165306,272474575,13.12,200,2,13.72,15,1,13.11,100,1,13.98,200,2,13.03,100,1,13.99,100,1,13.0,2,1,14.03,2,1,12.73,100,1,14.26,100,1,12.71,100,1,14.28,100,1,12.5,700,1,14.45,100,1,12.46,200,2,14.56,800,2,12.43,700,1,14.6,700,1,12.42,700,1,14.68,1400,2,ARL,326729677
,2025-07-17T16:03:10.807548848Z,2025-07-17T16:03:10.807548848Z,10,2,1108,C,A,2,13.99,100,0,165573,272474576,13.12,200,2,13.72,15,1,13.11,100,1,13.98,200,2,13.03,100,1,14.03,2,1,13.0,2,1,14.26,100,1,12.73,100,1,14.28,100,1,12.71,100,1,14.45,100,1,12.5,700,1,14.56,800,2,12.46,200,2,14.6,700,1,12.43,700,1,14.68,1400,2,12.42,700,1,14.7,200,2,ARL,326167529
,2025-07-17T16:03:10.807548848Z,2025-07-17T16:03:10.807548848Z,10,2,1108,A,A,1,13.73,100,130,165573,272474576,13.12,200,2,13.72,15,1,13.11,100,1,13.73,100,1,13.03,100,1,13.98,200,2,13.0,2,1,14.03,2,1,12.73,100,1,14.26,100,1,12.71,100,1,14.28,100,1,12.5,700,1,14.45,100,1,12.46,200,2,14.56,800,2,12.43,700,1,14.6,700,1,12.42,700,1,14.68,1400,2,ARL,326729685
,2025-07-17T16:03:10.809541651Z,2025-07-17T16:03:10.809541651Z,10,2,1108,A,A,10,14.7,100,130,165623,272474585,13.12,200,2,13.72,15,1,13.11,100,1,13.73,100,1,13.03,100,1,13.98,200,2,13.0,2,1,14.03,2,1,12.73,100,1,14.26,100,1,12.71,100,1,14.28,100,1,12.5,700,1,14.45,100,1,12.46,200,2,14.56,800,2,12.43,700,1,14.6,700,1,12.42,700,1,14.68,1400,2,ARL,326729721
,2025-07-17T16:03:10.809894317Z,2025-07-17T16:03:10.809894317Z,10,2,1108,A,A,7,14.52,100,130,165125,272474597,13.12,200,2,13.72,15,1,13.11,100,1,13.73,100,1,13.03,100,1,13.98,200,2,13.0,2,1,14.03,2,1,12.73,100,1,14.26,100,1,12.71,100,1,14.28,100,1,12.5,700,1,14.45,100,1,12.46,200,2,14.52,100,1,12.43,700,1,14.56,800,2,12.42,700,1,14.6,700,1,ARL,326729729
,2025-07-17T16:03:10.817700664Z,2025-07-17T16:03:10.817700664Z,10,2,1108,C,A,4,14.26,100,130,165402,272474675,13.12,200,2,13.72,15,1,13.11,100,1,13.73,100,1,13.03,100,1,13.98,200,2,13.0,2,1,14.03,2,1,12.73,100,1,14.28,100,1,12.71,100,1,14.45,100,1,12.5,700,1,14.52,100,1,12.46,200,2,14.56,800,2,12.43,700,1,14.6,700,1,12.42,700,1,14.68,1400,2,ARL,326159201
,2025-07-17T16:03:10.817754737Z,2025-07-17T16:03:10.817754737Z,10,2,1108,A,A,3,14.0,100,130,165233,272474676,13.12,200,2,13.72,15,1,13.11,100,1,13.73,100,1,13.03,100,1,13.98,200,2,13.0,2,1,14.0,100,1,12.73,100,1,14.03,2,1,12.71,100,1,14.28,100,1,12.5,700,1,14.45,100,1,12.46,200,2,14.52,100,1,12.43,700,1,14.56,800,2,12.42,700,1,14.6,700,1,ARL,326729929
,2025-07-17T16:03:10.843448998Z,2025-07-17T16:03:10.843448998Z,10,2,1108,C,A,2,13.98,100,0,166539,272474828,13.12,200,2,13.72,15,1,13.11,100,1,13.73,100,1,13.03,100,1,13.98,100,1,13.0,2,1,14.0,100,1,12.73,100,1,14.03,2,1,12.71,100,1,14.28,100,1,12.5,700,1,14.45,100,1,12.46,200,2,14.52,100,1,12.43,700,1,14.56,800,2,12.42,700,1,14.6,700,1,ARL,325719357
,2025-07-17T16:03:10.843449402Z,2025-07-17T16:03:10.843449402Z,10,2,1108,C,A,2,13.98,100,130,166135,272474829,13.12,200,2,13.72,15,1,13.11,100,1,13.73,100,1,13.03,100,1,14.0,100,1,13.0,2,1,14.03,2,1,12.73,100,1,14.28,100,1,12.71,100,1,14.45,100,1,12.5,700,1,14.52,100,1,12.46,200,2,14.56,800,2,12.43,700,1,14.6,700,1,12.42,700,1,14.68,1400,2,ARL,325719353
,2025-07-17T16:03:10.843462898Z,2025-07-17T16:03:10.843462898Z,10,2,1108,A,A,2,13.87,100,130,165348,272474830,13.12,200,2,13.72,15,1,13.11,100,1,13.73,100,1,13.03,100,1,13.87,100,1,13.0,2,1,14.0,100,1,12.73,100,1,14.03,2,1,12.71,100,1,14.28,100,1,12.5,700,1,14.45,100,1,12.46,200,2,14.52,100,1,12.43,700,1,14.56,800,2,12.42,700,1,14.6,700,1,ARL,326730517
,2025-07-17T16:03:10.843464369Z,2025-07-17T16:03:10.843464369Z,10,2,1108,A,A,2,13.87,100,130,165264,272474831,13.12,200,2,13.72,15,1,13.11,100,1,13.73,100,1,13.03,100,1,13.87,200,2,13.0,2,1,14.0,100,1,12.73,100,1,14.03,2,1,12.71,100,1,14.28,100,1,12.5,700,1,14.45,100,1,12.46,200,2,14.52,100,1,12.43,700,1,14.56,800,2,12.42,700,1,14.6,700,1,ARL,326730521
,2025-07-17T16:03:16.348023740Z,2025-07-17T16:03:16.348023740Z,10,2,1108,A,A,0,13.69,15,130,165337,272557172,13.12,200,2,13.69,15,1,13.11,100,1,13.72,15,1,13.03,100,1,13.73,100,1,13.0,2,1,13.87,200,2,12.73,100,1,14.0,100,1,12.71,100,1,14.03,2,1,12.5,700,1,14.28,100,1,12.46,200,2,14.45,100,1,12.43,700,1,14.52,100,1,12.42,700,1,14.56,800,2,ARL,326835877
,2025-07-17T16:03:16.348302787Z,2025-07-17T16:03:16.348302787Z,10,2,1108,A,A,10,14.58,100,130,166037,272557230,13.12,200,2,13.69,15,1,13.11,100,1,13.72,15,1,13.03,100,1,13.73,100,1,13.0,2,1,13.87,200,2,12.73,100,1,14.0,100,1,12.71,100,1,14.03,2,1,12.5,700,1,14.28,100,1,12.46,200,2,14.45,100,1,12.43,700,1,14.52,100,1,12.42,700,1,14.56,800,2,ARL,326835885
,2025-07-17T16:03:16.349513354Z,2025-07-17T16:03:16.349513354Z,10,2,1108,A,A,10,14.58,100,130,166595,272557430,13.12,200,2,13.69,15,1,13.11,100,1,13.72,15,1,13.03,100,1,13.73,100,1,13.0,2,1,13.87,200,2,12.73,100,1,14.0,100,1,12.71,100,1,14.03,2,1,12.5,700,1,14.28,100,1,12.46,200,2,14.45,100,1,12.43,700,1,14.52,100,1,12.42,700,1,14.56,800,2,ARL,326836085
,2025-07-17T16:03:16.351845457Z,2025-07-17T16:03:16.351845457Z,10,2,1108,C,A,2,13.73,100,0,166374,272557789,13.12,200,2,13.69,15,1,13.11,100,1,13.72,15,1,13.03,100,1,13.87,200,2,13.0,2,1,14.0,100,1,12.73,100,1,14.03,2,1,12.71,100,1,14.28,100,1,12.5,700,1,14.45,100,1,12.46,200,2,14.52,100,1,12.43,700,1,14.56,800,2,12.42,700,1,14.58,200,2,ARL,326729685
,2025-07-17T16:03:16.351845457Z,2025-07-17T16:03:16.351845457Z,10,2,1108,A,A,1,13.7,100,130,166374,272557789,13.12,200,2,13.69,15,1,13.11,100,1,13.7,100,1,13.03,100,1,13.72,15,1,13.0,2,1,13.87,200,2,12.73,100,1,14.0,100,1,12.71,100,1,14.03,2,1,12.5,700,1,14.28,100,1,12.46,200,2,14.45,100,1,12.43,700,1,14.52,100,1,12.42,700,1,14.56,800,2,ARL,326836533
,2025-07-17T16:03:18.804159952Z,2025-07-17T16:03:18.804159952Z,10,2,1108,C,A,0,13.69,15,130,165126,272609485,13.12,200,2,13.7,100,1,13.11,100,1,13.72,15,1,13.03,100,1,13.87,200,2,13.0,2,1,14.0,100,1,12.73,100,1,14.03,2,1,12.71,100,1,14.28,100,1,12.5,700,1,14.45,100,1,12.46,200,2,14.52,100,1,12.43,700,1,14.56,800,2,12.42,700,1,14.58,200,2,ARL,326835877
,2025-07-17T16:03:18.804202246Z,2025-07-17T16:03:18.804202246Z,10,2,1108,C,A,0,13.7,100,130,165314,272609486,13.12,200,2,13.72,15,1,13.11,100,1,13.87,200,2,13.03,100,1,14.0,100,1,13.0,2,1,14.03,2,1,12.73,100,1,14.28,100,1,12.71,100,1,14.45,100,1,12.5,700,1,14.52,100,1,12.46,200,2,14.56,800,2,12.43,700,1,14.58,200,2,12.42,700,1,14.6,700,1,ARL,326836533
,2025-07-17T16:03:18.805283236Z,2025-07-17T16:03:18.805283236Z,10,2,1108,C,A,0,13.72,15,130,165853,272609541,13.12,200,2,13.87,200,2,13.11,100,1,14.0,100,1,13.03,100,1,14.03,2,1,13.0,2,1,14.28,100,1,12.73,100,1,14.45,100,1,12.71,100,1,14.52,100,1,12.5,700,1,14.56,800,2,12.46,200,2,14.58,200,2,12.43,700,1,14.6,700,1,12.42,700,1,14.68,1400,2,ARL,326729677
,2025-07-17T16:03:18.806370373Z,2025-07-17T16:03:18.806370373Z,10,2,1108,C,A,7,14.58,100,0,165530,272609577,13.12,200,2,13.87,200,2,13.11,100,1,14.0,100,1,13.03,100,1,14.03,2,1,13.0,2,1,14.28,100,1,12.73,100,1,14.45,100,1,12.71,100,1,14.52,100,1,12.5,700,1,14.56,800,2,12.46,200,2,14.58,100,1,12.43,700,1,14.6,700,1,12.42,700,1,14.68,1400,2,ARL,326835885
,2025-07-17T16:03:18.806637004Z,2025-07-17T16:03:18.806637004Z,10,2,1108,C,A,7,14.58,100,0,165585,272609583,13.12,200,2,13.87,200,2,13.11,100,1,14.0,100,1,13.03,100,1,14.03,2,1,13.0,2,1,14.28,100,1,12.73,100,1,14.45,100,1,12.71,100,1,14.52,100,1,12.5,700,1,14.56,800,2,12.46,200,2,14.6,700,1,12.43,700,1,14.68,1400,2,12.42,700,1,14.7,100,1,ARL,326836085
,2025-07-17T16:03:18.806637004Z,2025-07-17T16:03:18.806637004Z,10,2,1108,A,A,10,14.76,100,130,165585,272609583,13.12,200,2,13.87,200,2,13.11,100,1,14.0,100,1,13.03,100,1,14.03,2,1,13.0,2,1,14.28,100,1,12.73,100,1,14.45,100,1,12.71,100,1,14.52,100,1,12.5,700,1,14.56,800,2,12.46,200,2,14.6,700,1,12.43,700,1,14.68,1400,2,12.42,700,1,14.7,100,1,ARL,326892825
,2025-07-17T16:03:18.809540733Z,2025-07-17T16:03:18.809540733Z,10,2,1108,C,A,5,14.52,100,0,165601,272609656,13.12,200,2,13.87,200,2,13.11,100,1,14.0,100,1,13.03,100,1,14.03,2,1,13.0,2,1,14.28,100,1,12.73,100,1,14.45,100,1,12.71,100,1,14.56,800,2,12.5,700,1,14.6,700,1,12.46,200,2,14.68,1400,2,12.43,700,1,14.7,100,1,12.42,700,1,14.76,200,2,ARL,326729729
,2025-07-17T16:03:18.809540733Z,2025-07-17T16:03:18.809540733Z,10,2,1108,A,A,7,14.66,100,130,165601,272609656,13.12,200,2,13.87,200,2,13.11,100,1,14.0,100,1,13.03,100,1,14.03,2,1,13.0,2,1,14.28,100,1,12.73,100,1,14.45,100,1,12.71,100,1,14.56,800,2,12.5,700,1,14.6,700,1,12.46,200,2,14.66,100,1,12.43,700,1,14.68,1400,2,12.42,700,1,14.7,100,1,ARL,326892885
,2025-07-17T16:03:18.818080239Z,2025-07-17T16:03:18.818080239Z,10,2,1108,C,A,1,14.0,100,130,165390,272609768,13.12,200,2,13.87,200,2,13.11,100,1,14.03,2,1,13.03,100,1,14.28,100,1,13.0,2,1,14.45,100,1,12.73,100,1,14.56,800,2,12.71,100,1,14.6,700,1,12.5,700,1,14.66,100,1,12.46,200,2,14.68,1400,2,12.43,700,1,14.7,100,1,12.42,700,1,14.76,200,2,ARL,326729929
,2025-07-17T16:03:18.818135688Z,2025-07-17T16:03:18.818135688Z,10,2,1108,A,A,2,14.15,100,130,165455,272609769,13.12,200,2,13.87,200,2,13.11,100,1,14.03,2,1,13.03,100,1,14.15,100,1,13.0,2,1,14.28,100,1,12.73,100,1,14.45,100,1,12.71,100,1,14.56,800,2,12.5,700,1,14.6,700,1,12.46,200,2,14.66,100,1,12.43,700,1,14.68,1400,2,12.42,700,1,14.7,100,1,ARL,326893213
,2025-07-17T16:03:18.868254768Z,2025-07-17T16:03:18.868254768Z,10,2,1108,C,A,9,14.7,100,0,165735,272610397,13.12,200,2,13.87,200,2,13.11,100,1,14.03,2,1,13.03,100,1,14.15,100,1,13.0,2,1,14.28,100,1,12.73,100,1,14.45,100,1,12.71,100,1,14.56,800,2,12.5,700,1,14.6,700,1,12.46,200,2,14.66,100,1,12.43,700,1,14.68,1400,2,12.42,700,1,14.76,200,2,ARL,326729821
,2025-07-17T16:03:18.868254768Z,2025-07-17T16:03:18.868254768Z,10,2,1108,A,A,10,14.85,100,130,165735,272610397,13.12,200,2,13.87,200,2,13.11,100,1,14.03,2,1,13.03,100,1,14.15,100,1,13.0,2,1,14.28,100,1,12.73,100,1,14.45,100,1,12.71,100,1,14.56,800,2,12.5,700,1,14.6,700,1,12.46,200,2,14.66,100,1,12.43,700,1,14.68,1400,2,12.42,700,1,14.76,200,2,ARL,326893961
,2025-07-17T16:03:19.191054306Z,2025-07-17T16:03:19.191054306Z,10,2,1108,A,A,1,13.88,100,130,165201,272614303,13.12,200,2,13.87,200,2,13.11,100,1,13.88,100,1,13.03,100,1,14.03,2,1,13.0,2,1,14.15,100,1,12.73,100,1,14.28,100,1,12.71,100,1,14.45,100,1,12.5,700,1,14.56,800,2,12.46,200,2,14.6,700,1,12.43,700,1,14.66,100,1,12.42,700,1,14.68,1400,2,ARL,326899125
,2025-07-17T16:03:27.433791643Z,2025-07-17T16:03:27.433791643Z,10,2,1108,T,N,0,13.28,40,130,166289,272788756,13.12,200,2,13.87,200,2,13.11,100,1,13.88,100,1,13.03,100,1,14.03,2,1,13.0,2,1,14.15,100,1,12.73,100,1,14.28,100,1,12.71,100,1,14.45,100,1,12.5,700,1,14.56,800,2,12.46,200,2,14.6,700,1,12.43,700,1,14.66,100,1,12.42,700,1,14.68,1400,2,ARL,0
,2025-07-17T16:03:27.436158395Z,2025-07-17T16:03:27.436158395Z,10,2,1108,A,A,4,14.25,53,130,165556,272788767,13.12,200,2,13.87,200,2,13.11,100,1,13.88,100,1,13.03,100,1,14.03,2,1,13.0,2,1,14.15,100,1,12.73,100,1,14.25,53,1,12.71,100,1,14.28,100,1,12.5,700,1,14.45,100,1,12.46,200,2,14.56,800,2,12.43,700,1,14.6,700,1,12.42,700,1,14.66,100,1,ARL,327112281
,2025-07-17T16:03:27.453845141Z,2025-07-17T16:03:27.453845141Z,10,2,1108,C,B,2,13.03,100,130,165214,272788897,13.12,200,2,13.87,200,2,13.11,100,1,13.88,100,1,13.0,2,1,14.03,2,1,12.73,100,1,14.15,100,1,12.71,100,1,14.25,53,1,12.5,700,1,14.28,100,1,12.46,200,2,14.45,100,1,12.43,700,1,14.56,800,2,12.42,700,1,14.6,700,1,12.37,700,1,14.66,100,1,ARL,285586293
,2025-07-17T16:03:27.453894425Z,2025-07-17T16:03:27.453894425Z,10,2,1108,A,B,3,12.95,100,130,165294,272788898,13.12,200,2,13.87,200,2,13.11,100,1,13.88,100,1,13.0,2,1,14.03,2,1,12.95,100,1,14.15,100,1,12.73,100,1,14.25,53,1,12.71,100,1,14.28,100,1,12.5,700,1,14.45,100,1,12.46,200,2,14.56,800,2,12.43,700,1,14.6,700,1,12.42,700,1,14.66,100,1,ARL,327112565
,2025-07-17T16:03:27.454726901Z,2025-07-17T16:03:27.454726901Z,10,2,1108,C,B,3,12.95,100,130,165420,272788942,13.12,200,2,13.87,200,2,13.11,100,1,13.88,100,1,13.0,2,1,14.03,2,1,12.73,100,1,14.15,100,1,12.71,100,1,14.25,53,1,12.5,700,1,14.28,100,1,12.46,200,2,14.45,100,1,12.43,700,1,14.56,800,2,12.42,700,1,14.6,700,1,12.37,700,1,14.66,100,1,ARL,327112565
,2025-07-17T16:03:27.454773691Z,2025-07-17T16:03:27.454773691Z,10,2,1108,A,B,3,12.86,100,130,165909,272788943,13.12,200,2,13.87,200,2,13.11,100,1,13.88,100,1,13.0,2,1,14.03,2,1,12.86,100,1,14.15,100,1,12.73,100,1,14.25,53,1,12.71,100,1,14.28,100,1,12.5,700,1,14.45,100,1,12.46,200,2,14.56,800,2,12.43,700,1,14.6,700,1,12.42,700,1,14.66,100,1,ARL,327112577
,2025-07-17T16:03:27.517585374Z,2025-07-17T16:03:27.517585374Z,10,2,1108,C,B,7,12.46,100,130,165896,272790695,13.12,200,2,13.87,200,2,13.11,100,1,13.88,100,1,13.0,2,1,14.03,2,1,12.86,100,1,14.15,100,1,12.73,100,1,14.25,53,1,12.71,100,1,14.28,100,1,12.5,700,1,14.45,100,1,12.46,100,1,14.56,800,2,12.43,700,1,14.6,700,1,12.42,700,1,14.66,100,1,ARL,285587281
,2025-07-17T16:03:27.536178718Z,2025-07-17T16:03:27.536178718Z,10,2,1108,C,A,4,14.25,53,130,165225,272791410,13.12,200,2,13.87,200,2,13.11,100,1,13.88,100,1,13.0,2,1,14.03,2,1,12.86,100,1,14.15,100,1,12.73,100,1,14.28,100,1,12.71,100,1,14.45,100,1,12.5,700,1,14.56,800,2,12.46,100,1,14.6,700,1,12.43,700,1,14.66,100,1,12.42,700,1,14.68,1400,2,ARL,327112281
,2025-07-17T16:03:56.548182793Z,2025-07-17T16:03:56.548182793Z,10,2,1108,A,A,0,13.8,15,130,165254,273208310,13.12,200,2,13.8,15,1,13.11,100,1,13.87,200,2,13.0,2,1,13.88,100,1,12.86,100,1,14.03,2,1,12.73,100,1,14.15,100,1,12.71,100,1,14.28,100,1,12.5,700,1,14.45,100,1,12.46,100,1,14.56,800,2,12.43,700,1,14.6,700,1,12.42,700,1,14.66,100,1,ARL,327675057
,2025-07-17T16:03:56.548446336Z,2025-07-17T16:03:56.548446336Z,10,2,1108,C,A,2,13.88,100,0,165380,273208316,13.12,200,2,13.8,15,1,13.11,100,1,13.87,200,2,13.0,2,1,14.03,2,1,12.86,100,1,14.15,100,1,12.73,100,1,14.28,100,1,12.71,100,1,14.45,100,1,12.5,700,1,14.56,800,2,12.46,100,1,14.6,700,1,12.43,700,1,14.66,100,1,12.42,700,1,14.68,1400,2,ARL,326899125
,2025-07-17T16:03:56.548446336Z,2025-07-17T16:03:56.548446336Z,10,2,1108,A,A,1,13.81,100,130,165380,273208316,13.12,200,2,13.8,15,1,13.11,100,1,13.81,100,1,13.0,2,1,13.87,200,2,12.86,100,1,14.03,2,1,12.73,100,1,14.15,100,1,12.71,100,1,14.28,100,1,12.5,700,1,14.45,100,1,12.46,100,1,14.56,800,2,12.43,700,1,14.6,700,1,12.42,700,1,14.66,100,1,ARL,327675065
,2025-07-17T16:04:06.233692491Z,2025-07-17T16:04:06.233692491Z,10,2,1108,A,A,9,14.64,100,130,166120,273345719,13.12,200,2,13.8,15,1,13.11,100,1,13.81,100,1,13.0,2,1,13.87,200,2,12.86,100,1,14.03,2,1,12.73,100,1,14.15,100,1,12.71,100,1,14.28,100,1,12.5,700,1,14.45,100,1,12.46,100,1,14.56,800,2,12.43,700,1,14.6,700,1,12.42,700,1,14.64,100,1,ARL,327856297
,2025-07-17T16:04:06.234433294Z,2025-07-17T16:04:06.234433294Z,10,2,1108,A,A,9,14.64,100,130,166904,273345721,13.12,200,2,13.8,15,1,13.11,100,1,13.81,100,1,13.0,2,1,13.87,200,2,12.86,100,1,14.03,2,1,12.73,100,1,14.15,100,1,12.71,100,1,14.28,100,1,12.5,700,1,14.45,100,1,12.46,100,1,14.56,800,2,12.43,700,1,14.6,700,1,12.42,700,1,14.64,200,2,ARL,327856309
,2025-07-17T16:04:06.510748731Z,2025-07-17T16:04:06.510748731Z,10,2,1108,A,A,0,13.72,15,130,165370,273352664,13.12,200,2,13.72,15,1,13.11,100,1,13.8,15,1,13.0,2,1,13.81,100,1,12.86,100,1,13.87,200,2,12.73,100,1,14.03,2,1,12.71,100,1,14.15,100,1,12.5,700,1,14.28,100,1,12.46,100,1,14.45,100,1,12.43,700,1,14.56,800,2,12.42,700,1,14.6,700,1,ARL,327863853
,2025-07-17T16:04:06.512244746Z,2025-07-17T16:04:06.512244746Z,10,2,1108,C,A,2,13.81,100,0,168356,273352888,13.12,200,2,13.72,15,1,13.11,100,1,13.8,15,1,13.0,2,1,13.87,200,2,12.86,100,1,14.03,2,1,12.73,100,1,14.15,100,1,12.71,100,1,14.28,100,1,12.5,700,1,14.45,100,1,12.46,100,1,14.56,800,2,12.43,700,1,14.6,700,1,12.42,700,1,14.64,200,2,ARL,327675065
,2025-07-17T16:04:06.512244746Z,2025-07-17T16:04:06.512244746Z,10,2,1108,A,A,1,13.73,100,128,168356,273352888,13.12,200,2,13.72,15,1,13.11,100,1,13.73,100,1,13.0,2,1,13.8,15,1,12.86,100,1,13.87,200,2,12.73,100,1,14.03,2,1,12.71,100,1,14.15,100,1,12.5,700,1,14.28,100,1,12.46,100,1,14.45,100,1,12.43,700,1,14.56,800,2,12.42,700,1,14.6,700,1,ARL,327864137
,2025-07-17T16:04:06.525385108Z,2025-07-17T16:04:06.525385108Z,10,2,1108,C,A,5,14.15,100,130,165707,273358260,13.12,200,2,13.72,15,1,13.11,100,1,13.73,100,1,13.0,2,1,13.8,15,1,12.86,100,1,13.87,200,2,12.73,100,1,14.03,2,1,12.71,100,1,14.28,100,1,12.5,700,1,14.45,100,1,12.46,100,1,14.56,800,2,12.43,700,1,14.6,700,1,12.42,700,1,14.64,200,2,ARL,326893213
,2025-07-17T16:04:06.525442486Z,2025-07-17T16:04:06.525442486Z,10,2,1108,A,A,4,14.0,100,128,166260,273358273,13.12,200,2,13.72,15,1,13.11,100,1,13.73,100,1,13.0,2,1,13.8,15,1,12.86,100,1,13.87,200,2,12.73,100,1,14.0,100,1,12.71,100,1,14.03,2,1,12.5,700,1,14.28,100,1,12.46,100,1,14.45,100,1,12.43,700,1,14.56,800,2,12.42,700,1,14.6,700,1,ARL,327869193
,2025-07-17T16:04:06.528161631Z,2025-07-17T16:04:06.528161631Z,10,2,1108,A,A,8,14.52,100,128,167417,273358642,13.12,200,2,13.72,15,1,13.11,100,1,13.73,100,1,13.0,2,1,13.8,15,1,12.86,100,1,13.87,200,2,12.73,100,1,14.0,100,1,12.71,100,1,14.03,2,1,12.5,700,1,14.28,100,1,12.46,100,1,14.45,100,1,12.43,700,1,14.52,100,1,12.42,700,1,14.56,800,2,ARL,327869529
,2025-07-17T16:04:06.805335354Z,2025-07-17T16:04:06.805335354Z,10,2,1108,C,A,0,13.72,15,130,165169,273364089,13.12,200,2,13.73,100,1,13.11,100,1,13.8,15,1,13.0,2,1,13.87,200,2,12.86,100,1,14.0,100,1,12.73,100,1,14.03,2,1,12.71,100,1,14.28,100,1,12.5,700,1,14.45,100,1,12.46,100,1,14.52,100,1,12.43,700,1,14.56,800,2,12.42,700,1,14.6,700,1,ARL,327863853
,2025-07-17T16:04:06.806052396Z,2025-07-17T16:04:06.806052396Z,10,2,1108,C,A,1,13.8,15,130,165188,273364090,13.12,200,2,13.73,100,1,13.11,100,1,13.87,200,2,13.0,2,1,14.0,100,1,12.86,100,1,14.03,2,1,12.73,100,1,14.28,100,1,12.71,100,1,14.45,100,1,12.5,700,1,14.52,100,1,12.46,100,1,14.56,800,2,12.43,700,1,14.6,700,1,12.42,700,1,14.64,200,2,ARL,327675057
,2025-07-17T16:04:21.276976977Z,2025-07-17T16:04:21.276976977Z,10,2,1108,A,A,1,13.77,100,130,165685,273687857,13.12,200,2,13.73,100,1,13.11,100,1,13.77,100,1,13.0,2,1,13.87,200,2,12.86,100,1,14.0,100,1,12.73,100,1,14.03,2,1,12.71,100,1,14.28,100,1,12.5,700,1,14.45,100,1,12.46,100,1,14.52,100,1,12.43,700,1,14.56,800,2,12.42,700,1,14.6,700,1,ARL,328239293
,2025-07-17T16:04:27.790889618Z,2025-07-17T16:04:27.790889618Z,10,2,1108,C,A,4,14.03,2,0,165528,273775264,13.12,200,2,13.73,100,1,13.11,100,1,13.77,100,1,13.0,2,1,13.87,200,2,12.86,100,1,14.0,100,1,12.73,100,1,14.28,100,1,12.71,100,1,14.45,100,1,12.5,700,1,14.52,100,1,12.46,100,1,14.56,800,2,12.43,700,1,14.6,700,1,12.42,700,1,14.64,200,2,ARL,326159041
,2025-07-17T16:04:27.790889618Z,2025-07-17T16:04:27.790889618Z,10,2,1108,A,A,3,13.94,2,130,165528,273775264,13.12,200,2,13.73,100,1,13.11,100,1,13.77,100,1,13.0,2,1,13.87,200,2,12.86,100,1,13.94,2,1,12.73,100,1,14.0,100,1,12.71,100,1,14.28,100,1,12.5,700,1,14.45,100,1,12.46,100,1,14.52,100,1,12.43,700,1,14.56,800,2,12.42,700,1,14.6,700,1,ARL,328351217
,2025-07-17T16:04:31.231887784Z,2025-07-17T16:04:31.231887784Z,10,2,1108,A,A,0,13.68,15,130,165370,273846737,13.12,200,2,13.68,15,1,13.11,100,1,13.73,100,1,13.0,2,1,13.77,100,1,12.86,100,1,13.87,200,2,12.73,100,1,13.94,2,1,12.71,100,1,14.0,100,1,12.5,700,1,14.28,100,1,12.46,100,1,14.45,100,1,12.43,700,1,14.52,100,1,12.42,700,1,14.56,800,2,ARL,328437797
,2025-07-17T16:04:31.232440773Z,2025-07-17T16:04:31.232440773Z,10,2,1108,A,A,1,13.72,100,130,165667,273846745,13.12,200,2,13.68,15,1,13.11,100,1,13.72,100,1,13.0,2,1,13.73,100,1,12.86,100,1,13.77,100,1,12.73,100,1,13.87,200,2,12.71,100,1,13.94,2,1,12.5,700,1,14.0,100,1,12.46,100,1,14.28,100,1,12.43,700,1,14.45,100,1,12.42,700,1,14.52,100,1,ARL,328437805
,2025-07-17T16:04:31.246515467Z,2025-07-17T16:04:31.246515467Z,10,2,1108,C,A,3,13.77,100,130,165695,273847000,13.12,200,2,13.68,15,1,13.11,100,1,13.72,100,1,13.0,2,1,13.73,100,1,12.86,100,1,13.87,200,2,12.73,100,1,13.94,2,1,12.71,100,1,14.0,100,1,12.5,700,1,14.28,100,1,12.46,100,1,14.45,100,1,12.43,700,1,14.52,100,1,12.42,700,1,14.56,800,2,ARL,328239293
,2025-07-17T16:04:32.836635838Z,2025-07-17T16:04:32.836635838Z,10,2,1108,C,A,2,13.73,100,0,166273,273882084,13.12,200,2,13.68,15,1,13.11,100,1,13.72,100,1,13.0,2,1,13.87,200,2,12.86,100,1,13.94,2,1,12.73,100,1,14.0,100,1,12.71,100,1,14.28,100,1,12.5,700,1,14.45,100,1,12.46,100,1,14.52,100,1,12.43,700,1,14.56,800,2,12.42,700,1,14.6,700,1,ARL,327864137
,2025-07-17T16:04:32.836635838Z,2025-07-17T16:04:32.836635838Z,10,2,1108,A,A,1,13.69,100,130,166273,273882084,13.12,200,2,13.68,15,1,13.11,100,1,13.69,100,1,13.0,2,1,13.72,100,1,12.86,100,1,13.87,200,2,12.73,100,1,13.94,2,1,12.71,100,1,14.0,100,1,12.5,700,1,14.28,100,1,12.46,100,1,14.45,100,1,12.43,700,1,14.52,100,1,12.42,700,1,14.56,800,2,ARL,328489153
,2025-07-17T16:04:32.837000154Z,2025-07-17T16:04:32.837000154Z,10,2,1108,C,B,0,13.12,100,130,165277,273882201,13.12,100,1,13.68,15,1,13.11,100,1,13.69,100,1,13.0,2,1,13.72,100,1,12.86,100,1,13.87,200,2,12.73,100,1,13.94,2,1,12.71,100,1,14.0,100,1,12.5,700,1,14.28,100,1,12.46,100,1,14.45,100,1,12.43,700,1,14.52,100,1,12.42,700,1,14.56,800,2,ARL,325718833
,2025-07-17T16:04:32.837002825Z,2025-07-17T16:04:32.837002825Z,10,2,1108,C,B,0,13.12,100,128,166258,273882202,13.11,100,1,13.68,15,1,13.0,2,1,13.69,100,1,12.86,100,1,13.72,100,1,12.73,100,1,13.87,200,2,12.71,100,1,13.94,2,1,12.5,700,1,14.0,100,1,12.46,100,1,14.28,100,1,12.43,700,1,14.45,100,1,12.42,700,1,14.52,100,1,12.37,700,1,14.56,800,2,ARL,325718837
,2025-07-17T16:04:32.837013456Z,2025-07-17T16:04:32.837013456Z,10,2,1108,A,B,2,12.98,100,130,166112,273882207,13.11,100,1,13.68,15,1,13.0,2,1,13.69,100,1,12.98,100,1,13.72,100,1,12.86,100,1,13.87,200,2,12.73,100,1,13.94,2,1,12.71,100,1,14.0,100,1,12.5,700,1,14.28,100,1,12.46,100,1,14.45,100,1,12.43,700,1,14.52,100,1,12.42,700,1,14.56,800,2,ARL,328489377
,2025-07-17T16:04:32.837016087Z,2025-07-17T16:04:32.837016087Z,10,2,1108,A,B,2,12.98,100,130,165495,273882208,13.11,100,1,13.68,15,1,13.0,2,1,13.69,100,1,12.98,200,2,13.72,100,1,12.86,100,1,13.87,200,2,12.73,100,1,13.94,2,1,12.71,100,1,14.0,100,1,12.5,700,1,14.28,100,1,12.46,100,1,14.45,100,1,12.43,700,1,14.52,100,1,12.42,700,1,14.56,800,2,ARL,328489385
,2025-07-17T16:04:36.810551890Z,2025-07-17T16:04:36.810551890Z,10,2,1108,A,A,0,13.65,15,130,165256,273963456,13.11,100,1,13.65,15,1,13.0,2,1,13.68,15,1,12.98,200,2,13.69,100,1,12.86,100,1,13.72,100,1,12.73,100,1,13.87,200,2,12.71,100,1,13.94,2,1,12.5,700,1,14.0,100,1,12.46,100,1,14.28,100,1,12.43,700,1,14.45,100,1,12.42,700,1,14.52,100,1,ARL,328603377
,2025-07-17T16:04:37.026771973Z,2025-07-17T16:04:37.026771973Z,10,2,1108,A,A,2,13.69,100,130,165520,273965417,13.11,100,1,13.65,15,1,13.0,2,1,13.68,15,1,12.98,200,2,13.69,200,2,12.86,100,1,13.72,100,1,12.73,100,1,13.87,200,2,12.71,100,1,13.94,2,1,12.5,700,1,14.0,100,1,12.46,100,1,14.28,100,1,12.43,700,1,14.45,100,1,12.42,700,1,14.52,100,1,ARL,328606289
,2025-07-17T16:04:37.033389265Z,2025-07-17T16:04:37.033389265Z,10,2,1108,C,A,3,13.72,100,130,165292,273965562,13.11,100,1,13.65,15,1,13.0,2,1,13.68,15,1,12.98,200,2,13.69,200,2,12.86,100,1,13.87,200,2,12.73,100,1,13.94,2,1,12.71,100,1,14.0,100,1,12.5,700,1,14.28,100,1,12.46,100,1,14.45,100,1,12.43,700,1,14.52,100,1,12.42,700,1,14.56,800,2,ARL,328437805
,2025-07-17T16:04:37.542795711Z,2025-07-17T16:04:37.542795711Z,10,2,1108,C,A,2,13.69,100,0,165450,273971021,13.11,100,1,13.65,15,1,13.0,2,1,13.68,15,1,12.98,200,2,13.69,100,1,12.86,100,1,13.87,200,2,12.73,100,1,13.94,2,1,12.71,100,1,14.0,100,1,12.5,700,1,14.28,100,1,12.46,100,1,14.45,100,1,12.43,700,1,14.52,100,1,12.42,700,1,14.56,800,2,ARL,328489153
,2025-07-17T16:04:37.542795711Z,2025-07-17T16:04:37.542795711Z,10,2,1108,A,A,1,13.66,100,130,165450,273971021,13.11,100,1,13.65,15,1,13.0,2,1,13.66,100,1,12.98,200,2,13.68,15,1,12.86,100,1,13.69,100,1,12.73,100,1,13.87,200,2,12.71,100,1,13.94,2,1,12.5,700,1,14.0,100,1,12.46,100,1,14.28,100,1,12.43,700,1,14.45,100,1,12.42,700,1,14.52,100,1,ARL,328614509
,2025-07-17T16:04:37.543063240Z,2025-07-17T16:04:37.543063240Z,10,2,1108,C,A,4,13.87,100,0,167440,273971035,13.11,100,1,13.65,15,1,13.0,2,1,13.66,100,1,12.98,200,2,13.68,15,1,12.86,100,1,13.69,100,1,12.73,100,1,13.87,100,1,12.71,100,1,13.94,2,1,12.5,700,1,14.0,100,1,12.46,100,1,14.28,100,1,12.43,700,1,14.45,100,1,12.42,700,1,14.52,100,1,ARL,326730517
,2025-07-17T16:04:37.543064690Z,2025-07-17T16:04:37.543064690Z,10,2,1108,C,A,4,13.87,100,130,165990,273971037,13.11,100,1,13.65,15,1,13.0,2,1,13.66,100,1,12.98,200,2,13.68,15,1,12.86,100,1,13.69,100,1,12.73,100,1,13.94,2,1,12.71,100,1,14.0,100,1,12.5,700,1,14.28,100,1,12.46,100,1,14.45,100,1,12.43,700,1,14.52,100,1,12.42,700,1,14.56,800,2,ARL,326730521
,2025-07-17T16:04:37.543077174Z,2025-07-17T16:04:37.543077174Z,10,2,1108,A,A,4,13.8,100,130,165216,273971040,13.11,100,1,13.65,15,1,13.0,2,1,13.66,100,1,12.98,200,2,13.68,15,1,12.86,100,1,13.69,100,1,12.73,100,1,13.8,100,1,12.71,100,1,13.94,2,1,12.5,700,1,14.0,100,1,12.46,100,1,14.28,100,1,12.43,700,1,14.45,100,1,12.42,700,1,14.52,100,1,ARL,328614525
,2025-07-17T16:04:37.543078532Z,2025-07-17T16:04:37.543078532Z,10,2,1108,A,A,4,13.8,100,130,165661,273971041,13.11,100,1,13.65,15,1,13.0,2,1,13.66,100,1,12.98,200,2,13.68,15,1,12.86,100,1,13.69,100,1,12.73,100,1,13.8,200,2,12.71,100,1,13.94,2,1,12.5,700,1,14.0,100,1,12.46,100,1,14.28,100,1,12.43,700,1,14.45,100,1,12.42,700,1,14.52,100,1,ARL,328614529
,2025-07-17T16:04:37.549519006Z,2025-07-17T16:04:37.549519006Z,10,2,1108,C,A,6,14.0,100,130,165707,273973481,13.11,100,1,13.65,15,1,13.0,2,1,13.66,100,1,12.98,200,2,13.68,15,1,12.86,100,1,13.69,100,1,12.73,100,1,13.8,200,2,12.71,100,1,13.94,2,1,12.5,700,1,14.28,100,1,12.46,100,1,14.45,100,1,12.43,700,1,14.52,100,1,12.42,700,1,14.56,800,2,ARL,327869193
,2025-07-17T16:04:37.549570649Z,2025-07-17T16:04:37.549570649Z,10,2,1108,A,A,5,13.93,100,130,165175,273973485,13.11,100,1,13.65,15,1,13.0,2,1,13.66,100,1,12.98,200,2,13.68,15,1,12.86,100,1,13.69,100,1,12.73,100,1,13.8,200,2,12.71,100,1,13.93,100,1,12.5,700,1,13.94,2,1,12.46,100,1,14.28,100,1,12.43,700,1,14.45,100,1,12.42,700,1,14.52,100,1,ARL,328616925
,2025-07-17T16:04:44.524360626Z,2025-07-17T16:04:44.524360626Z,10,2,1108,C,A,2,13.68,15,130,165919,274066152,13.11,100,1,13.65,15,1,13.0,2,1,13.66,100,1,12.98,200,2,13.69,100,1,12.86,100,1,13.8,200,2,12.73,100,1,13.93,100,1,12.71,100,1,13.94,2,1,12.5,700,1,14.28,100,1,12.46,100,1,14.45,100,1,12.43,700,1,14.52,100,1,12.42,700,1,14.56,800,2,ARL,328437797
,2025-07-17T16:04:45.527835033Z,2025-07-17T16:04:45.527835033Z,10,2,1108,A,A,0,13.63,15,130,165110,274088918,13.11,100,1,13.63,15,1,13.0,2,1,13.65,15,1,12.98,200,2,13.66,100,1,12.86,100,1,13.69,100,1,12.73,100,1,13.8,200,2,12.71,100,1,13.93,100,1,12.5,700,1,13.94,2,1,12.46,100,1,14.28,100,1,12.43,700,1,14.45,100,1,12.42,700,1,14.52,100,1,ARL,328780565
,2025-07-17T16:04:45.528464092Z,2025-07-17T16:04:45.528464092Z,10,2,1108,A,A,9,14.52,100,130,165521,274088922,13.11,100,1,13.63,15,1,13.0,2,1,13.65,15,1,12.98,200,2,13.66,100,1,12.86,100,1,13.69,100,1,12.73,100,1,13.8,200,2,12.71,100,1,13.93,100,1,12.5,700,1,13.94,2,1,12.46,100,1,14.28,100,1,12.43,700,1,14.45,100,1,12.42,700,1,14.52,200,2,ARL,328780577
,2025-07-17T16:04:45.530252804Z,2025-07-17T16:04:45.530252804Z,10,2,1108,A,A,9,14.52,100,130,165474,274088937,13.11,100,1,13.63,15,1,13.0,2,1,13.65,15,1,12.98,200,2,13.66,100,1,12.86,100,1,13.69,100,1,12.73,100,1,13.8,200,2,12.71,100,1,13.93,100,1,12.5,700,1,13.94,2,1,12.46,100,1,14.28,100,1,12.43,700,1,14.45,100,1,12.42,700,1,14.52,300,3,ARL,328780597
,2025-07-17T16:04:45.532901874Z,2025-07-17T16:04:45.532901874Z,10,2,1108,C,A,2,13.66,100,0,165155,274088955,13.11,100,1,13.63,15,1,13.0,2,1,13.65,15,1,12.98,200,2,13.69,100,1,12.86,100,1,13.8,200,2,12.73,100,1,13.93,100,1,12.71,100,1,13.94,2,1,12.5,700,1,14.28,100,1,12.46,100,1,14.45,100,1,12.43,700,1,14.52,300,3,12.42,700,1,14.56,800,2,ARL,328614509
,2025-07-17T16:04:45.532901874Z,2025-07-17T16:04:45.532901874Z,10,2,1108,A,A,1,13.64,100,130,165155,274088955,13.11,100,1,13.63,15,1,13.0,2,1,13.64,100,1,12.98,200,2,13.65,15,1,12.86,100,1,13.69,100,1,12.73,100,1,13.8,200,2,12.71,100,1,13.93,100,1,12.5,700,1,13.94,2,1,12.46,100,1,14.28,100,1,12.43,700,1,14.45,100,1,12.42,700,1,14.52,300,3,ARL,328780669
,2025-07-17T16:04:45.533705428Z,2025-07-17T16:04:45.533705428Z,10,2,1108,A,A,3,13.67,100,130,165283,274088959,13.11,100,1,13.63,15,1,13.0,2,1,13.64,100,1,12.98,200,2,13.65,15,1,12.86,100,1,13.67,100,1,12.73,100,1,13.69,100,1,12.71,100,1,13.8,200,2,12.5,700,1,13.93,100,1,12.46,100,1,13.94,2,1,12.43,700,1,14.28,100,1,12.42,700,1,14.45,100,1,ARL,328780689
,2025-07-17T16:04:45.562972204Z,2025-07-17T16:04:45.562972204Z,10,2,1108,C,A,4,13.69,100,130,165239,274089319,13.11,100,1,13.63,15,1,13.0,2,1,13.64,100,1,12.98,200,2,13.65,15,1,12.86,100,1,13.67,100,1,12.73,100,1,13.8,200,2,12.71,100,1,13.93,100,1,12.5,700,1,13.94,2,1,12.46,100,1,14.28,100,1,12.43,700,1,14.45,100,1,12.42,700,1,14.52,300,3,ARL,328606289
,2025-07-17T16:04:56.809584701Z,2025-07-17T16:04:56.809584701Z,10,2,1108,C,A,2,13.65,15,130,165272,274293432,13.11,100,1,13.63,15,1,13.0,2,1,13.64,100,1,12.98,200,2,13.67,100,1,12.86,100,1,13.8,200,2,12.73,100,1,13.93,100,1,12.71,100,1,13.94,2,1,12.5,700,1,14.28,100,1,12.46,100,1,14.45,100,1,12.43,700,1,14.52,300,3,12.42,700,1,14.56,800,2,ARL,328603377
,2025-07-17T16:04:57.826913717Z,2025-07-17T16:04:57.826913717Z,10,2,1108,A,A,0,13.61,15,130,165292,274310244,13.11,100,1,13.61,15,1,13.0,2,1,13.63,15,1,12.98,200,2,13.64,100,1,12.86,100,1,13.67,100,1,12.73,100,1,13.8,200,2,12.71,100,1,13.93,100,1,12.5,700,1,13.94,2,1,12.46,100,1,14.28,100,1,12.43,700,1,14.45,100,1,12.42,700,1,14.52,300,3,ARL,329068341
,2025-07-17T16:04:57.970451236Z,2025-07-17T16:04:57.970451236Z,10,2,1108,C,A,2,13.64,100,0,165374,274316281,13.11,100,1,13.61,15,1,13.0,2,1,13.63,15,1,12.98,200,2,13.67,100,1,12.86,100,1,13.8,200,2,12.73,100,1,13.93,100,1,12.71,100,1,13.94,2,1,12.5,700,1,14.28,100,1,12.46,100,1,14.45,100,1,12.43,700,1,14.52,300,3,12.42,700,1,14.56,800,2,ARL,328780669
,2025-07-17T16:04:57.970451236Z,2025-07-17T16:04:57.970451236Z,10,2,1108,A,A,1,13.62,100,130,165374,274316281,13.11,100,1,13.61,15,1,13.0,2,1,13.62,100,1,12.98,200,2,13.63,15,1,12.86,100,1,13.67,100,1,12.73,100,1,13.8,200,2,12.71,100,1,13.93,100,1,12.5,700,1,13.94,2,1,12.46,100,1,14.28,100,1,12.43,700,1,14.45,100,1,12.42,700,1,14.52,300,3,ARL,329074609
,2025-07-17T16:04:57.971193734Z,2025-07-17T16:04:57.971193734Z,10,2,1108,C,A,8,14.45,100,128,166610,274316507,13.11,100,1,13.61,15,1,13.0,2,1,13.62,100,1,12.98,200,2,13.63,15,1,12.86,100,1,13.67,100,1,12.73,100,1,13.8,200,2,12.71,100,1,13.93,100,1,12.5,700,1,13.94,2,1,12.46,100,1,14.28,100,1,12.43,700,1,14.52,300,3,12.42,700,1,14.56,800,2,ARL,325714601
,2025-07-17T16:04:57.971552262Z,2025-07-17T16:04:57.971552262Z,10,2,1108,A,A,7,14.23,100,130,165249,274316527,13.11,100,1,13.61,15,1,13.0,2,1,13.62,100,1,12.98,200,2,13.63,15,1,12.86,100,1,13.67,100,1,12.73,100,1,13.8,200,2,12.71,100,1,13.93,100,1,12.5,700,1,13.94,2,1,12.46,100,1,14.23,100,1,12.43,700,1,14.28,100,1,12.42,700,1,14.52,300,3,ARL,329074833
,2025-07-17T16:04:57.991966904Z,2025-07-17T16:04:57.991966904Z,10,2,1108,C,A,0,13.61,15,130,164974,274318490,13.11,100,1,13.62,100,1,13.0,2,1,13.63,15,1,12.98,200,2,13.67,100,1,12.86,100,1,13.8,200,2,12.73,100,1,13.93,100,1,12.71,100,1,13.94,2,1,12.5,700,1,14.23,100,1,12.46,100,1,14.28,100,1,12.43,700,1,14.52,300,3,12.42,700,1,14.56,800,2,ARL,329068341
,2025-07-17T16:04:57.992976406Z,2025-07-17T16:04:57.992976406Z,10,2,1108,C,A,0,13.62,100,130,165032,274318579,13.11,100,1,13.63,15,1,13.0,2,1,13.67,100,1,12.98,200,2,13.8,200,2,12.86,100,1,13.93,100,1,12.73,100,1,13.94,2,1,12.71,100,1,14.23,100,1,12.5,700,1,14.28,100,1,12.46,100,1,14.52,300,3,12.43,700,1,14.56,800,2,12.42,700,1,14.6,700,1,ARL,329074609
,2025-07-17T16:04:57.993143873Z,2025-07-17T16:04:57.993143873Z,10,2,1108,C,A,0,13.63,15,130,165688,274318603,13.11,100,1,13.67,100,1,13.0,2,1,13.8,200,2,12.98,200,2,13.93,100,1,12.86,100,1,13.94,2,1,12.73,100,1,14.23,100,1,12.71,100,1,14.28,100,1,12.5,700,1,14.52,300,3,12.46,100,1,14.56,800,2,12.43,700,1,14.6,700,1,12.42,700,1,14.68,1400,2,ARL,328780565
,2025-07-17T16:04:58.002094377Z,2025-07-17T16:04:58.002094377Z,10,2,1108,C,A,0,13.67,100,130,165338,274319058,13.11,100,1,13.8,200,2,13.0,2,1,13.93,100,1,12.98,200,2,13.94,2,1,12.86,100,1,14.23,100,1,12.73,100,1,14.28,100,1,12.71,100,1,14.52,300,3,12.5,700,1,14.56,800,2,12.46,100,1,14.6,700,1,12.43,700,1,14.68,1400,2,12.42,700,1,14.7,300,3,ARL,328780689
,2025-07-17T16:04:58.002823841Z,2025-07-17T16:04:58.002823841Z,10,2,1108,C,A,9,14.7,100,0,165589,274319069,13.11,100,1,13.8,200,2,13.0,2,1,13.93,100,1,12.98,200,2,13.94,2,1,12.86,100,1,14.23,100,1,12.73,100,1,14.28,100,1,12.71,100,1,14.52,300,3,12.5,700,1,14.56,800,2,12.46,100,1,14.6,700,1,12.43,700,1,14.68,1400,2,12.42,700,1,14.7,200,2,ARL,328780685
,2025-07-17T16:04:58.002823841Z,2025-07-17T16:04:58.002823841Z,10,2,1108,A,A,10,14.87,100,130,165589,274319069,13.11,100,1,13.8,200,2,13.0,2,1,13.93,100,1,12.98,200,2,13.94,2,1,12.86,100,1,14.23,100,1,12.73,100,1,14.28,100,1,12.71,100,1,14.52,300,3,12.5,700,1,14.56,800,2,12.46,100,1,14.6,700,1,12.43,700,1,14.68,1400,2,12.42,700,1,14.7,200,2,ARL,329078553
,2025-07-17T16:04:58.013739242Z,2025-07-17T16:04:58.013739242Z,10,2,1108,C,A,1,13.93,100,130,165455,274319298,13.11,100,1,13.8,200,2,13.0,2,1,13.94,2,1,12.98,200,2,14.23,100,1,12.86,100,1,14.28,100,1,12.73,100,1,14.52,300,3,12.71,100,1,14.56,800,2,12.5,700,1,14.6,700,1,12.46,100,1,14.68,1400,2,12.43,700,1,14.7,200,2,12.42,700,1,14.87,100,1,ARL,328616925
,2025-07-17T16:04:58.013793974Z,2025-07-17T16:04:58.013793974Z,10,2,1108,A,A,2,14.08,100,130,165259,274319304,13.11,100,1,13.8,200,2,13.0,2,1,13.94,2,1,12.98,200,2,14.08,100,1,12.86,100,1,14.23,100,1,12.73,100,1,14.28,100,1,12.71,100,1,14.52,300,3,12.5,700,1,14.56,800,2,12.46,100,1,14.6,700,1,12.43,700,1,14.68,1400,2,12.42,700,1,14.7,200,2,ARL,329078953
,2025-07-17T16:04:58.536452621Z,2025-07-17T16:04:58.536452621Z,10,2,1108,A,A,1,13.81,100,130,165296,274326535,13.11,100,1,13.8,200,2,13.0,2,1,13.81,100,1,12.98,200,2,13.94,2,1,12.86,100,1,14.08,100,1,12.73,100,1,14.23,100,1,12.71,100,1,14.28,100,1,12.5,700,1,14.52,300,3,12.46,100,1,14.56,800,2,12.43,700,1,14.6,700,1,12.42,700,1,14.68,1400,2,ARL,329088265
,2025-07-17T16:05:46.593966383Z,2025-07-17T16:05:46.593966383Z,10,2,1108,A,A,0,13.76,100,130,165281,275083968,13.11,100,1,13.76,100,1,13.0,2,1,13.8,200,2,12.98,200,2,13.81,100,1,12.86,100,1,13.94,2,1,12.73,100,1,14.08,100,1,12.71,100,1,14.23,100,1,12.5,700,1,14.28,100,1,12.46,100,1,14.52,300,3,12.43,700,1,14.56,800,2,12.42,700,1,14.6,700,1,ARL,330066537
,2025-07-17T16:05:46.995837526Z,2025-07-17T16:05:46.995837526Z,10,2,1108,C,A,2,13.81,100,0,166026,275092978,13.11,100,1,13.76,100,1,13.0,2,1,13.8,200,2,12.98,200,2,13.94,2,1,12.86,100,1,14.08,100,1,12.73,100,1,14.23,100,1,12.71,100,1,14.28,100,1,12.5,700,1,14.52,300,3,12.46,100,1,14.56,800,2,12.43,700,1,14.6,700,1,12.42,700,1,14.68,1400,2,ARL,329088265
,2025-07-17T16:05:46.995837526Z,2025-07-17T16:05:46.995837526Z,10,2,1108,A,A,1,13.77,100,130,166026,275092978,13.11,100,1,13.76,100,1,13.0,2,1,13.77,100,1,12.98,200,2,13.8,200,2,12.86,100,1,13.94,2,1,12.73,100,1,14.08,100,1,12.71,100,1,14.23,100,1,12.5,700,1,14.28,100,1,12.46,100,1,14.52,300,3,12.43,700,1,14.56,800,2,12.42,700,1,14.6,700,1,ARL,330075425
,2025-07-17T16:05:50.680167632Z,2025-07-17T16:05:50.680167632Z,10,2,1108,A,A,0,13.68,15,130,165519,275152014,13.11,100,1,13.68,15,1,13.0,2,1,13.76,100,1,12.98,200,2,13.77,100,1,12.86,100,1,13.8,200,2,12.73,100,1,13.94,2,1,12.71,100,1,14.08,100,1,12.5,700,1,14.23,100,1,12.46,100,1,14.28,100,1,12.43,700,1,14.52,300,3,12.42,700,1,14.56,800,2,ARL,330143813
,2025-07-17T16:05:50.697005084Z,2025-07-17T16:05:50.697005084Z,10,2,1108,A,A,1,13.72,100,130,165236,275152383,13.11,100,1,13.68,15,1,13.0,2,1,13.72,100,1,12.98,200,2,13.76,100,1,12.86,100,1,13.77,100,1,12.73,100,1,13.8,200,2,12.71,100,1,13.94,2,1,12.5,700,1,14.08,100,1,12.46,100,1,14.23,100,1,12.43,700,1,14.28,100,1,12.42,700,1,14.52,300,3,ARL,330144301
,2025-07-17T16:05:50.704366332Z,2025-07-17T16:05:50.704366332Z,10,2,1108,C,A,2,13.76,100,130,165416,275152443,13.11,100,1,13.68,15,1,13.0,2,1,13.72,100,1,12.98,200,2,13.77,100,1,12.86,100,1,13.8,200,2,12.73,100,1,13.94,2,1,12.71,100,1,14.08,100,1,12.5,700,1,14.23,100,1,12.46,100,1,14.28,100,1,12.43,700,1,14.52,300,3,12.42,700,1,14.56,800,2,ARL,330066537
,2025-07-17T16:05:50.708714027Z,2025-07-17T16:05:50.708714027Z,10,2,1108,C,A,5,14.08,100,130,165284,275152465,13.11,100,1,13.68,15,1,13.0,2,1,13.72,100,1,12.98,200,2,13.77,100,1,12.86,100,1,13.8,200,2,12.73,100,1,13.94,2,1,12.71,100,1,14.23,100,1,12.5,700,1,14.28,100,1,12.46,100,1,14.52,300,3,12.43,700,1,14.56,800,2,12.42,700,1,14.6,700,1,ARL,329078953
,2025-07-17T16:05:50.708766050Z,2025-07-17T16:05:50.708766050Z,10,2,1108,A,A,5,13.99,100,130,165139,275152466,13.11,100,1,13.68,15,1,13.0,2,1,13.72,100,1,12.98,200,2,13.77,100,1,12.86,100,1,13.8,200,2,12.73,100,1,13.94,2,1,12.71,100,1,13.99,100,1,12.5,700,1,14.23,100,1,12.46,100,1,14.28,100,1,12.43,700,1,14.52,300,3,12.42,700,1,14.56,800,2,ARL,330144513
,2025-07-17T16:05:50.913310799Z,2025-07-17T16:05:50.913310799Z,10,2,1108,C,A,2,13.77,100,0,165469,275159685,13.11,100,1,13.68,15,1,13.0,2,1,13.72,100,1,12.98,200,2,13.8,200,2,12.86,100,1,13.94,2,1,12.73,100,1,13.99,100,1,12.71,100,1,14.23,100,1,12.5,700,1,14.28,100,1,12.46,100,1,14.52,300,3,12.43,700,1,14.56,800,2,12.42,700,1,14.6,700,1,ARL,330075425
,2025-07-17T16:05:50.913310799Z,2025-07-17T16:05:50.913310799Z,10,2,1108,A,A,1,13.69,100,130,165469,275159685,13.11,100,1,13.68,15,1,13.0,2,1,13.69,100,1,12.98,200,2,13.72,100,1,12.86,100,1,13.8,200,2,12.73,100,1,13.94,2,1,12.71,100,1,13.99,100,1,12.5,700,1,14.23,100,1,12.46,100,1,14.28,100,1,12.43,700,1,14.52,300,3,12.42,700,1,14.56,800,2,ARL,330151389
,2025-07-17T16:05:59.704790753Z,2025-07-17T16:05:59.704790753Z,10,2,1108,A,A,0,13.64,15,130,165217,275325555,13.11,100,1,13.64,15,1,13.0,2,1,13.68,15,1,12.98,200,2,13.69,100,1,12.86,100,1,13.72,100,1,12.73,100,1,13.8,200,2,12.71,100,1,13.94,2,1,12.5,700,1,13.99,100,1,12.46,100,1,14.23,100,1,12.43,700,1,14.28,100,1,12.42,700,1,14.52,300,3,ARL,330357473
,2025-07-17T16:05:59.714925412Z,2025-07-17T16:05:59.714925412Z,10,2,1108,A,A,1,13.68,100,130,165250,275325807,13.11,100,1,13.64,15,1,13.0,2,1,13.68,115,2,12.98,200,2,13.69,100,1,12.86,100,1,13.72,100,1,12.73,100,1,13.8,200,2,12.71,100,1,13.94,2,1,12.5,700,1,13.99,100,1,12.46,100,1,14.23,100,1,12.43,700,1,14.28,100,1,12.42,700,1,14.52,300,3,ARL,330357633
,2025-07-17T16:05:59.722730507Z,2025-07-17T16:05:59.722730507Z,10,2,1108,C,A,3,13.72,100,130,165243,275325854,13.11,100,1,13.64,15,1,13.0,2,1,13.68,115,2,12.98,200,2,13.69,100,1,12.86,100,1,13.8,200,2,12.73,100,1,13.94,2,1,12.71,100,1,13.99,100,1,12.5,700,1,14.23,100,1,12.46,100,1,14.28,100,1,12.43,700,1,14.52,300,3,12.42,700,1,14.56,800,2,ARL,330144301
,2025-07-17T16:05:59.802596747Z,2025-07-17T16:05:59.802596747Z,10,2,1108,C,A,2,13.69,100,0,165340,275327082,13.11,100,1,13.64,15,1,13.0,2,1,13.68,115,2,12.98,200,2,13.8,200,2,12.86,100,1,13.94,2,1,12.73,100,1,13.99,100,1,12.71,100,1,14.23,100,1,12.5,700,1,14.28,100,1,12.46,100,1,14.52,300,3,12.43,700,1,14.56,800,2,12.42,700,1,14.6,700,1,ARL,330151389
,2025-07-17T16:05:59.802596747Z,2025-07-17T16:05:59.802596747Z,10,2,1108,A,A,1,13.65,100,130,165340,275327082,13.11,100,1,13.64,15,1,13.0,2,1,13.65,100,1,12.98,200,2,13.68,115,2,12.86,100,1,13.8,200,2,12.73,100,1,13.94,2,1,12.71,100,1,13.99,100,1,12.5,700,1,14.23,100,1,12.46,100,1,14.28,100,1,12.43,700,1,14.52,300,3,12.42,700,1,14.56,800,2,ARL,330359197
,2025-07-17T16:05:59.827622529Z,2025-07-17T16:05:59.827622529Z,10,2,1108,C,A,5,13.99,100,130,165308,275327416,13.11,100,1,13.64,15,1,13.0,2,1,13.65,100,1,12.98,200,2,13.68,115,2,12.86,100,1,13.8,200,2,12.73,100,1,13.94,2,1,12.71,100,1,14.23,100,1,12.5,700,1,14.28,100,1,12.46,100,1,14.52,300,3,12.43,700,1,14.56,800,2,12.42,700,1,14.6,700,1,ARL,330144513
,2025-07-17T16:05:59.827674437Z,2025-07-17T16:05:59.827674437Z,10,2,1108,A,A,4,13.92,100,130,165365,275327417,13.11,100,1,13.64,15,1,13.0,2,1,13.65,100,1,12.98,200,2,13.68,115,2,12.86,100,1,13.8,200,2,12.73,100,1,13.92,100,1,12.71,100,1,13.94,2,1,12.5,700,1,14.23,100,1,12.46,100,1,14.28,100,1,12.43,700,1,14.52,300,3,12.42,700,1,14.56,800,2,ARL,330359625
,2025-07-17T16:06:02.724280161Z,2025-07-17T16:06:02.724280161Z,10,2,1108,C,A,2,13.68,15,128,166176,275430576,13.11,100,1,13.64,15,1,13.0,2,1,13.65,100,1,12.98,200,2,13.68,100,1,12.86,100,1,13.8,200,2,12.73,100,1,13.92,100,1,12.71,100,1,13.94,2,1,12.5,700,1,14.23,100,1,12.46,100,1,14.28,100,1,12.43,700,1,14.52,300,3,12.42,700,1,14.56,800,2,ARL,330143813
,2025-07-17T16:06:03.729212428Z,2025-07-17T16:06:03.729212428Z,10,2,1108,A,A,0,13.62,15,130,165342,275517342,13.11,100,1,13.62,15,1,13.0,2,1,13.64,15,1,12.98,200,2,13.65,100,1,12.86,100,1,13.68,100,1,12.73,100,1,13.8,200,2,12.71,100,1,13.92,100,1,12.5,700,1,13.94,2,1,12.46,100,1,14.23,100,1,12.43,700,1,14.28,100,1,12.42,700,1,14.52,300,3,ARL,330577045
,2025-07-17T16:06:03.738332427Z,2025-07-17T16:06:03.738332427Z,10,2,1108,A,A,2,13.65,100,130,165218,275517997,13.11,100,1,13.62,15,1,13.0,2,1,13.64,15,1,12.98,200,2,13.65,200,2,12.86,100,1,13.68,100,1,12.73,100,1,13.8,200,2,12.71,100,1,13.92,100,1,12.5,700,1,13.94,2,1,12.46,100,1,14.23,100,1,12.43,700,1,14.28,100,1,12.42,700,1,14.52,300,3,ARL,330577773
,2025-07-17T16:06:03.747330178Z,2025-07-17T16:06:03.747330178Z,10,2,1108,C,A,3,13.68,100,130,165491,275518621,13.11,100,1,13.62,15,1,13.0,2,1,13.64,15,1,12.98,200,2,13.65,200,2,12.86,100,1,13.8,200,2,12.73,100,1,13.92,100,1,12.71,100,1,13.94,2,1,12.5,700,1,14.23,100,1,12.46,100,1,14.28,100,1,12.43,700,1,14.52,300,3,12.42,700,1,14.56,800,2,ARL,330357633
,2025-07-17T16:06:03.887107153Z,2025-07-17T16:06:03.887107153Z,10,2,1108,C,A,2,13.65,100,0,167517,275532429,13.11,100,1,13.62,15,1,13.0,2,1,13.64,15,1,12.98,200,2,13.65,100,1,12.86,100,1,13.8,200,2,12.73,100,1,13.92,100,1,12.71,100,1,13.94,2,1,12.5,700,1,14.23,100,1,12.46,100,1,14.28,100,1,12.43,700,1,14.52,300,3,12.42,700,1,14.56,800,2,ARL,330359197
,2025-07-17T16:06:03.887107153Z,2025-07-17T16:06:03.887107153Z,10,2,1108,A,A,1,13.63,100,130,167517,275532429,13.11,100,1,13.62,15,1,13.0,2,1,13.63,100,1,12.98,200,2,13.64,15,1,12.86,100,1,13.65,100,1,12.73,100,1,13.8,200,2,12.71,100,1,13.92,100,1,12.5,700,1,13.94,2,1,12.46,100,1,14.23,100,1,12.43,700,1,14.28,100,1,12.42,700,1,14.52,300,3,ARL,330592465
,2025-07-17T16:06:07.509885114Z,2025-07-17T16:06:07.509885114Z,10,2,1108,C,A,2,13.64,15,130,165644,275647392,13.11,100,1,13.62,15,1,13.0,2,1,13.63,100,1,12.98,200,2,13.65,100,1,12.86,100,1,13.8,200,2,12.73,100,1,13.92,100,1,12.71,100,1,13.94,2,1,12.5,700,1,14.23,100,1,12.46,100,1,14.28,100,1,12.43,700,1,14.52,300,3,12.42,700,1,14.56,800,2,ARL,330357473
,2025-07-17T16:06:09.884978592Z,2025-07-17T16:06:09.884978592Z,10,2,1108,A,A,0,13.6,15,130,165317,275699092,13.11,100,1,13.6,15,1,13.0,2,1,13.62,15,1,12.98,200,2,13.63,100,1,12.86,100,1,13.65,100,1,12.73,100,1,13.8,200,2,12.71,100,1,13.92,100,1,12.5,700,1,13.94,2,1,12.46,100,1,14.23,100,1,12.43,700,1,14.28,100,1,12.42,700,1,14.52,300,3,ARL,330788421
,2025-07-17T16:06:09.967442600Z,2025-07-17T16:06:09.967442600Z,10,2,1108,C,A,2,13.63,100,0,165461,275700261,13.11,100,1,13.6,15,1,13.0,2,1,13.62,15,1,12.98,200,2,13.65,100,1,12.86,100,1,13.8,200,2,12.73,100,1,13.92,100,1,12.71,100,1,13.94,2,1,12.5,700,1,14.23,100,1,12.46,100,1,14.28,100,1,12.43,700,1,14.52,300,3,12.42,700,1,14.56,800,2,ARL,330592465
,2025-07-17T16:06:09.967442600Z,2025-07-17T16:06:09.967442600Z,10,2,1108,A,A,1,13.61,100,130,165461,275700261,13.11,100,1,13.6,15,1,13.0,2,1,13.61,100,1,12.98,200,2,13.62,15,1,12.86,100,1,13.65,100,1,12.73,100,1,13.8,200,2,12.71,100,1,13.92,100,1,12.5,700,1,13.94,2,1,12.46,100,1,14.23,100,1,12.43,700,1,14.28,100,1,12.42,700,1,14.52,300,3,ARL,330789481
,2025-07-17T16:06:20.470724464Z,2025-07-17T16:06:20.470724464Z,10,2,1108,A,A,3,13.63,100,130,165387,275896138,13.11,100,1,13.6,15,1,13.0,2,1,13.61,100,1,12.98,200,2,13.62,15,1,12.86,100,1,13.63,100,1,12.73,100,1,13.65,100,1,12.71,100,1,13.8,200,2,12.5,700,1,13.92,100,1,12.46,100,1,13.94,2,1,12.43,700,1,14.23,100,1,12.42,700,1,14.28,100,1,ARL,331018065
,2025-07-17T16:06:20.477432988Z,2025-07-17T16:06:20.477432988Z,10,2,1108,C,A,4,13.65,100,130,165590,275896242,13.11,100,1,13.6,15,1,13.0,2,1,13.61,100,1,12.98,200,2,13.62,15,1,12.86,100,1,13.63,100,1,12.73,100,1,13.8,200,2,12.71,100,1,13.92,100,1,12.5,700,1,13.94,2,1,12.46,100,1,14.23,100,1,12.43,700,1,14.28,100,1,12.42,700,1,14.52,300,3,ARL,330577773
,2025-07-17T16:06:20.810998706Z,2025-07-17T16:06:20.810998706Z,10,2,1108,C,A,2,13.62,15,130,165472,275900161,13.11,100,1,13.6,15,1,13.0,2,1,13.61,100,1,12.98,200,2,13.63,100,1,12.86,100,1,13.8,200,2,12.73,100,1,13.92,100,1,12.71,100,1,13.94,2,1,12.5,700,1,14.23,100,1,12.46,100,1,14.28,100,1,12.43,700,1,14.52,300,3,12.42,700,1,14.56,800,2,ARL,330577045
,2025-07-17T16:06:22.151057292Z,2025-07-17T16:06:22.151057292Z,10,2,1108,A,A,0,13.58,15,130,165527,275926927,13.11,100,1,13.58,15,1,13.0,2,1,13.6,15,1,12.98,200,2,13.61,100,1,12.86,100,1,13.63,100,1,12.73,100,1,13.8,200,2,12.71,100,1,13.92,100,1,12.5,700,1,13.94,2,1,12.46,100,1,14.23,100,1,12.43,700,1,14.28,100,1,12.42,700,1,14.52,300,3,ARL,331050981
,2025-07-17T16:06:22.151326300Z,2025-07-17T16:06:22.151326300Z,10,2,1108,C,A,2,13.61,100,0,165532,275926940,13.11,100,1,13.58,15,1,13.0,2,1,13.6,15,1,12.98,200,2,13.63,100,1,12.86,100,1,13.8,200,2,12.73,100,1,13.92,100,1,12.71,100,1,13.94,2,1,12.5,700,1,14.23,100,1,12.46,100,1,14.28,100,1,12.43,700,1,14.52,300,3,12.42,700,1,14.56,800,2,ARL,330789481
,2025-07-17T16:06:22.151326300Z,2025-07-17T16:06:22.151326300Z,10,2,1108,A,A,1,13.59,100,130,165532,275926940,13.11,100,1,13.58,15,1,13.0,2,1,13.59,100,1,12.98,200,2,13.6,15,1,12.86,100,1,13.63,100,1,12.73,100,1,13.8,200,2,12.71,100,1,13.92,100,1,12.5,700,1,13.94,2,1,12.46,100,1,14.23,100,1,12.43,700,1,14.28,100,1,12.42,700,1,14.52,300,3,ARL,331050989
,2025-07-17T16:06:22.151595415Z,2025-07-17T16:06:22.151595415Z,10,2,1108,C,A,4,13.8,100,0,165914,275926966,13.11,100,1,13.58,15,1,13.0,2,1,13.59,100,1,12.98,200,2,13.6,15,1,12.86,100,1,13.63,100,1,12.73,100,1,13.8,100,1,12.71,100,1,13.92,100,1,12.5,700,1,13.94,2,1,12.46,100,1,14.23,100,1,12.43,700,1,14.28,100,1,12.42,700,1,14.52,300,3,ARL,328614525
,2025-07-17T16:06:22.151595781Z,2025-07-17T16:06:22.151595781Z,10,2,1108,C,A,4,13.8,100,130,165548,275926967,13.11,100,1,13.58,15,1,13.0,2,1,13.59,100,1,12.98,200,2,13.6,15,1,12.86,100,1,13.63,100,1,12.73,100,1,13.92,100,1,12.71,100,1,13.94,2,1,12.5,700,1,14.23,100,1,12.46,100,1,14.28,100,1,12.43,700,1,14.52,300,3,12.42,700,1,14.56,800,2,ARL,328614529
,2025-07-17T16:06:22.153749481Z,2025-07-17T16:06:22.153749481Z,10,2,1108,A,A,9,14.55,100,130,166688,275927046,13.11,100,1,13.58,15,1,13.0,2,1,13.59,100,1,12.98,200,2,13.6,15,1,12.86,100,1,13.63,100,1,12.73,100,1,13.92,100,1,12.71,100,1,13.94,2,1,12.5,700,1,14.23,100,1,12.46,100,1,14.28,100,1,12.43,700,1,14.52,300,3,12.42,700,1,14.55,100,1,ARL,331051173
,2025-07-17T16:06:22.155905240Z,2025-07-17T16:06:22.155905240Z,10,2,1108,C,A,8,14.52,100,0,165458,275927117,13.11,100,1,13.58,15,1,13.0,2,1,13.59,100,1,12.98,200,2,13.6,15,1,12.86,100,1,13.63,100,1,12.73,100,1,13.92,100,1,12.71,100,1,13.94,2,1,12.5,700,1,14.23,100,1,12.46,100,1,14.28,100,1,12.43,700,1,14.52,200,2,12.42,700,1,14.55,100,1,ARL,327869529
,2025-07-17T16:06:22.155905240Z,2025-07-17T16:06:22.155905240Z,10,2,1108,A,A,8,14.38,100,130,165458,275927117,13.11,100,1,13.58,15,1,13.0,2,1,13.59,100,1,12.98,200,2,13.6,15,1,12.86,100,1,13.63,100,1,12.73,100,1,13.92,100,1,12.71,100,1,13.94,2,1,12.5,700,1,14.23,100,1,12.46,100,1,14.28,100,1,12.43,700,1,14.38,100,1,12.42,700,1,14.52,200,2,ARL,331051369
,2025-07-17T16:06:22.177879233Z,2025-07-17T16:06:22.177879233Z,10,2,1108,A,A,10,14.55,100,130,165442,275927444,13.11,100,1,13.58,15,1,13.0,2,1,13.59,100,1,12.98,200,2,13.6,15,1,12.86,100,1,13.63,100,1,12.73,100,1,13.92,100,1,12.71,100,1,13.94,2,1,12.5,700,1,14.23,100,1,12.46,100,1,14.28,100,1,12.43,700,1,14.38,100,1,12.42,700,1,14.52,200,2,ARL,331052197
,2025-07-17T16:06:24.519345743Z,2025-07-17T16:06:24.519345743Z,10,2,1108,A,A,2,13.6,100,130,165385,275968354,13.11,100,1,13.58,15,1,13.0,2,1,13.59,100,1,12.98,200,2,13.6,115,2,12.86,100,1,13.63,100,1,12.73,100,1,13.92,100,1,12.71,100,1,13.94,2,1,12.5,700,1,14.23,100,1,12.46,100,1,14.28,100,1,12.43,700,1,14.38,100,1,12.42,700,1,14.52,200,2,ARL,331104725
,2025-07-17T16:06:24.526194457Z,2025-07-17T16:06:24.526194457Z,10,2,1108,C,A,3,13.63,100,130,165259,275968393,13.11,100,1,13.58,15,1,13.0,2,1,13.59,100,1,12.98,200,2,13.6,115,2,12.86,100,1,13.92,100,1,12.73,100,1,13.94,2,1,12.71,100,1,14.23,100,1,12.5,700,1,14.28,100,1,12.46,100,1,14.38,100,1,12.43,700,1,14.52,200,2,12.42,700,1,14.55,200,2,ARL,331018065
,2025-07-17T16:06:26.610180184Z,2025-07-17T16:06:26.610180184Z,10,2,1108,C,A,4,13.94,2,0,165616,276013080,13.11,100,1,13.58,15,1,13.0,2,1,13.59,100,1,12.98,200,2,13.6,115,2,12.86,100,1,13.92,100,1,12.73,100,1,14.23,100,1,12.71,100,1,14.28,100,1,12.5,700,1,14.38,100,1,12.46,100,1,14.52,200,2,12.43,700,1,14.55,200,2,12.42,700,1,14.56,800,2,ARL,328351217
,2025-07-17T16:06:26.610180184Z,2025-07-17T16:06:26.610180184Z,10,2,1108,A,A,3,13.85,2,130,165616,276013080,13.11,100,1,13.58,15,1,13.0,2,1,13.59,100,1,12.98,200,2,13.6,115,2,12.86,100,1,13.85,2,1,12.73,100,1,13.92,100,1,12.71,100,1,14.23,100,1,12.5,700,1,14.28,100,1,12.46,100,1,14.38,100,1,12.43,700,1,14.52,200,2,12.42,700,1,14.55,200,2,ARL,331155889
,2025-07-17T16:06:30.625711923Z,2025-07-17T16:06:30.625711923Z,10,2,1108,A,A,6,14.27,700,130,165291,276103282,13.11,100,1,13.58,15,1,13.0,2,1,13.59,100,1,12.98,200,2,13.6,115,2,12.86,100,1,13.85,2,1,12.73,100,1,13.92,100,1,12.71,100,1,14.23,100,1,12.5,700,1,14.27,700,1,12.46,100,1,14.28,100,1,12.43,700,1,14.38,100,1,12.42,700,1,14.52,200,2,ARL,331257169
,2025-07-17T16:06:31.127662311Z,2025-07-17T16:06:31.127662311Z,10,2,1108,A,A,9,14.48,700,130,165494,276118990,13.11,100,1,13.58,15,1,13.0,2,1,13.59,100,1,12.98,200,2,13.6,115,2,12.86,100,1,13.85,2,1,12.73,100,1,13.92,100,1,12.71,100,1,14.23,100,1,12.5,700,1,14.27,700,1,12.46,100,1,14.28,100,1,12.43,700,1,14.38,100,1,12.42,700,1,14.48,700,1,ARL,331272997
,2025-07-17T16:06:31.990483799Z,2025-07-17T16:06:31.990483799Z,10,2,1108,C,A,2,13.6,15,130,165430,276135226,13.11,100,1,13.58,15,1,13.0,2,1,13.59,100,1,12.98,200,2,13.6,100,1,12.86,100,1,13.85,2,1,12.73,100,1,13.92,100,1,12.71,100,1,14.23,100,1,12.5,700,1,14.27,700,1,12.46,100,1,14.28,100,1,12.43,700,1,14.38,100,1,12.42,700,1,14.48,700,1,ARL,330788421
,2025-07-17T16:06:42.812641697Z,2025-07-17T16:06:42.812641697Z,10,2,1108,A,A,0,13.56,15,130,165399,276276783,13.11,100,1,13.56,15,1,13.0,2,1,13.58,15,1,12.98,200,2,13.59,100,1,12.86,100,1,13.6,100,1,12.73,100,1,13.85,2,1,12.71,100,1,13.92,100,1,12.5,700,1,14.23,100,1,12.46,100,1,14.27,700,1,12.43,700,1,14.28,100,1,12.42,700,1,14.38,100,1,ARL,331488089
,2025-07-17T16:06:43.012799164Z,2025-07-17T16:06:43.012799164Z,10,2,1108,C,A,2,13.59,100,0,166793,276279311,13.11,100,1,13.56,15,1,13.0,2,1,13.58,15,1,12.98,200,2,13.6,100,1,12.86,100,1,13.85,2,1,12.73,100,1,13.92,100,1,12.71,100,1,14.23,100,1,12.5,700,1,14.27,700,1,12.46,100,1,14.28,100,1,12.43,700,1,14.38,100,1,12.42,700,1,14.48,700,1,ARL,331050989
,2025-07-17T16:06:43.012799164Z,2025-07-17T16:06:43.012799164Z,10,2,1108,A,A,1,13.57,100,128,166793,276279311,13.11,100,1,13.56,15,1,13.0,2,1,13.57,100,1,12.98,200,2,13.58,15,1,12.86,100,1,13.6,100,1,12.73,100,1,13.85,2,1,12.71,100,1,13.92,100,1,12.5,700,1,14.23,100,1,12.46,100,1,14.27,700,1,12.43,700,1,14.28,100,1,12.42,700,1,14.38,100,1,ARL,331491049
,2025-07-17T16:06:43.024490355Z,2025-07-17T16:06:43.024490355Z,10,2,1108,C,A,5,13.92,100,130,165668,276279620,13.11,100,1,13.56,15,1,13.0,2,1,13.57,100,1,12.98,200,2,13.58,15,1,12.86,100,1,13.6,100,1,12.73,100,1,13.85,2,1,12.71,100,1,14.23,100,1,12.5,700,1,14.27,700,1,12.46,100,1,14.28,100,1,12.43,700,1,14.38,100,1,12.42,700,1,14.48,700,1,ARL,330359625
,2025-07-17T16:06:43.024543099Z,2025-07-17T16:06:43.024543099Z,10,2,1108,A,A,4,13.84,100,130,165205,276279621,13.11,100,1,13.56,15,1,13.0,2,1,13.57,100,1,12.98,200,2,13.58,15,1,12.86,100,1,13.6,100,1,12.73,100,1,13.84,100,1,12.71,100,1,13.85,2,1,12.5,700,1,14.23,100,1,12.46,100,1,14.27,700,1,12.43,700,1,14.28,100,1,12.42,700,1,14.38,100,1,ARL,331491269
,2025-07-17T16:06:49.613776144Z,2025-07-17T16:06:49.613776144Z,10,2,1108,C,A,2,13.58,15,130,165677,276382302,13.11,100,1,13.56,15,1,13.0,2,1,13.57,100,1,12.98,200,2,13.6,100,1,12.86,100,1,13.84,100,1,12.73,100,1,13.85,2,1,12.71,100,1,14.23,100,1,12.5,700,1,14.27,700,1,12.46,100,1,14.28,100,1,12.43,700,1,14.38,100,1,12.42,700,1,14.48,700,1,ARL,331050981
,2025-07-17T16:06:50.618504506Z,2025-07-17T16:06:50.618504506Z,10,2,1108,A,A,0,13.54,15,130,165337,276408477,13.11,100,1,13.54,15,1,13.0,2,1,13.56,15,1,12.98,200,2,13.57,100,1,12.86,100,1,13.6,100,1,12.73,100,1,13.84,100,1,12.71,100,1,13.85,2,1,12.5,700,1,14.23,100,1,12.46,100,1,14.27,700,1,12.43,700,1,14.28,100,1,12.42,700,1,14.38,100,1,ARL,331666961
,2025-07-17T16:06:50.626272828Z,2025-07-17T16:06:50.626272828Z,10,2,1108,A,A,3,13.58,100,130,165377,276408566,13.11,100,1,13.54,15,1,13.0,2,1,13.56,15,1,12.98,200,2,13.57,100,1,12.86,100,1,13.58,100,1,12.73,100,1,13.6,100,1,12.71,100,1,13.84,100,1,12.5,700,1,13.85,2,1,12.46,100,1,14.23,100,1,12.43,700,1,14.27,700,1,12.42,700,1,14.28,100,1,ARL,331667121
,2025-07-17T16:06:50.632947998Z,2025-07-17T16:06:50.632947998Z,10,2,1108,C,A,4,13.6,100,130,165559,276408644,13.11,100,1,13.54,15,1,13.0,2,1,13.56,15,1,12.98,200,2,13.57,100,1,12.86,100,1,13.58,100,1,12.73,100,1,13.84,100,1,12.71,100,1,13.85,2,1,12.5,700,1,14.23,100,1,12.46,100,1,14.27,700,1,12.43,700,1,14.28,100,1,12.42,700,1,14.38,100,1,ARL,331104725
,2025-07-17T16:06:51.754410704Z,2025-07-17T16:06:51.754410704Z,10,2,1108,C,A,2,13.57,100,0,165618,276428315,13.11,100,1,13.54,15,1,13.0,2,1,13.56,15,1,12.98,200,2,13.58,100,1,12.86,100,1,13.84,100,1,12.73,100,1,13.85,2,1,12.71,100,1,14.23,100,1,12.5,700,1,14.27,700,1,12.46,100,1,14.28,100,1,12.43,700,1,14.38,100,1,12.42,700,1,14.48,700,1,ARL,331491049
,2025-07-17T16:06:51.754410704Z,2025-07-17T16:06:51.754410704Z,10,2,1108,A,A,1,13.55,100,130,165618,276428315,13.11,100,1,13.54,15,1,13.0,2,1,13.55,100,1,12.98,200,2,13.56,15,1,12.86,100,1,13.58,100,1,12.73,100,1,13.84,100,1,12.71,100,1,13.85,2,1,12.5,700,1,14.23,100,1,12.46,100,1,14.27,700,1,12.43,700,1,14.28,100,1,12.42,700,1,14.38,100,1,ARL,331694265
,2025-07-17T16:06:51.757237300Z,2025-07-17T16:06:51.757237300Z,10,2,1108,C,B,1,13.0,2,0,165809,276428333,13.11,100,1,13.54,15,1,12.98,200,2,13.55,100,1,12.86,100,1,13.56,15,1,12.73,100,1,13.58,100,1,12.71,100,1,13.84,100,1,12.5,700,1,13.85,2,1,12.46,100,1,14.23,100,1,12.43,700,1,14.27,700,1,12.42,700,1,14.28,100,1,12.37,700,1,14.38,100,1,ARL,325967705
,2025-07-17T16:06:51.757237300Z,2025-07-17T16:06:51.757237300Z,10,2,1108,A,B,2,12.9,2,130,165809,276428333,13.11,100,1,13.54,15,1,12.98,200,2,13.55,100,1,12.9,2,1,13.56,15,1,12.86,100,1,13.58,100,1,12.73,100,1,13.84,100,1,12.71,100,1,13.85,2,1,12.5,700,1,14.23,100,1,12.46,100,1,14.27,700,1,12.43,700,1,14.28,100,1,12.42,700,1,14.38,100,1,ARL,331694297
,2025-07-17T16:06:55.056135380Z,2025-07-17T16:06:55.056135380Z,10,2,1108,C,A,0,13.54,15,130,165481,276516227,13.11,100,1,13.55,100,1,12.98,200,2,13.56,15,1,12.9,2,1,13.58,100,1,12.86,100,1,13.84,100,1,12.73,100,1,13.85,2,1,12.71,100,1,14.23,100,1,12.5,700,1,14.27,700,1,12.46,100,1,14.28,100,1,12.43,700,1,14.38,100,1,12.42,700,1,14.48,700,1,ARL,331666961
,2025-07-17T16:06:55.056301001Z,2025-07-17T16:06:55.056301001Z,10,2,1108,C,A,1,13.56,15,130,165230,276516239,13.11,100,1,13.55,100,1,12.98,200,2,13.58,100,1,12.9,2,1,13.84,100,1,12.86,100,1,13.85,2,1,12.73,100,1,14.23,100,1,12.71,100,1,14.27,700,1,12.5,700,1,14.28,100,1,12.46,100,1,14.38,100,1,12.43,700,1,14.48,700,1,12.42,700,1,14.52,200,2,ARL,331488089
,2025-07-17T16:07:00.010829521Z,2025-07-17T16:07:00.010829521Z,10,2,1108,C,A,0,13.55,100,130,166037,276611719,13.11,100,1,13.58,100,1,12.98,200,2,13.84,100,1,12.9,2,1,13.85,2,1,12.86,100,1,14.23,100,1,12.73,100,1,14.27,700,1,12.71,100,1,14.28,100,1,12.5,700,1,14.38,100,1,12.46,100,1,14.48,700,1,12.43,700,1,14.52,200,2,12.42,700,1,14.55,200,2,ARL,331694265
,2025-07-17T16:07:00.023683961Z,2025-07-17T16:07:00.023683961Z,10,2,1108,C,A,0,13.58,100,130,165219,276613073,13.11,100,1,13.84,100,1,12.98,200,2,13.85,2,1,12.9,2,1,14.23,100,1,12.86,100,1,14.27,700,1,12.73,100,1,14.28,100,1,12.71,100,1,14.38,100,1,12.5,700,1,14.48,700,1,12.46,100,1,14.52,200,2,12.43,700,1,14.55,200,2,12.42,700,1,14.56,800,2,ARL,331667121
,2025-07-17T16:07:00.023752163Z,2025-07-17T16:07:00.023752163Z,10,2,1108,C,A,3,14.27,700,130,165380,276613077,13.11,100,1,13.84,100,1,12.98,200,2,13.85,2,1,12.9,2,1,14.23,100,1,12.86,100,1,14.28,100,1,12.73,100,1,14.38,100,1,12.71,100,1,14.48,700,1,12.5,700,1,14.52,200,2,12.46,100,1,14.55,200,2,12.43,700,1,14.56,800,2,12.42,700,1,14.6,700,1,ARL,331257169
,2025-07-17T16:07:00.023815326Z,2025-07-17T16:07:00.023815326Z,10,2,1108,A,A,6,14.51,700,130,165479,276613078,13.11,100,1,13.84,100,1,12.98,200,2,13.85,2,1,12.9,2,1,14.23,100,1,12.86,100,1,14.28,100,1,12.73,100,1,14.38,100,1,12.71,100,1,14.48,700,1,12.5,700,1,14.51,700,1,12.46,100,1,14.52,200,2,12.43,700,1,14.55,200,2,12.42,700,1,14.56,800,2,ARL,331926981
,2025-07-17T16:07:00.025064913Z,2025-07-17T16:07:00.025064913Z,10,2,1108,C,A,2,14.23,100,130,166251,276613157,13.11,100,1,13.84,100,1,12.98,200,2,13.85,2,1,12.9,2,1,14.28,100,1,12.86,100,1,14.38,100,1,12.73,100,1,14.48,700,1,12.71,100,1,14.51,700,1,12.5,700,1,14.52,200,2,12.46,100,1,14.55,200,2,12.43,700,1,14.56,800,2,12.42,700,1,14.6,700,1,ARL,329074833
,2025-07-17T16:07:00.025422082Z,2025-07-17T16:07:00.025422082Z,10,2,1108,A,A,4,14.46,100,130,165467,276613175,13.11,100,1,13.84,100,1,12.98,200,2,13.85,2,1,12.9,2,1,14.28,100,1,12.86,100,1,14.38,100,1,12.73,100,1,14.46,100,1,12.71,100,1,14.48,700,1,12.5,700,1,14.51,700,1,12.46,100,1,14.52,200,2,12.43,700,1,14.55,200,2,12.42,700,1,14.56,800,2,ARL,331927161
,2025-07-17T16:07:00.025628157Z,2025-07-17T16:07:00.025628157Z,10,2,1108,A,A,0,13.59,100,130,165103,276613194,13.11,100,1,13.59,100,1,12.98,200,2,13.84,100,1,12.9,2,1,13.85,2,1,12.86,100,1,14.28,100,1,12.73,100,1,14.38,100,1,12.71,100,1,14.46,100,1,12.5,700,1,14.48,700,1,12.46,100,1,14.51,700,1,12.43,700,1,14.52,200,2,12.42,700,1,14.55,200,2,ARL,331927177
,2025-07-17T16:07:00.026833761Z,2025-07-17T16:07:00.026833761Z,10,2,1108,C,A,0,13.59,100,130,164934,276613224,13.11,100,1,13.84,100,1,12.98,200,2,13.85,2,1,12.9,2,1,14.28,100,1,12.86,100,1,14.38,100,1,12.73,100,1,14.46,100,1,12.71,100,1,14.48,700,1,12.5,700,1,14.51,700,1,12.46,100,1,14.52,200,2,12.43,700,1,14.55,200,2,12.42,700,1,14.56,800,2,ARL,331927177
,2025-07-17T16:07:00.032596898Z,2025-07-17T16:07:00.032596898Z,10,2,1108,C,A,3,14.38,100,130,165284,276613329,13.11,100,1,13.84,100,1,12.98,200,2,13.85,2,1,12.9,2,1,14.28,100,1,12.86,100,1,14.46,100,1,12.73,100,1,14.48,700,1,12.71,100,1,14.51,700,1,12.5,700,1,14.52,200,2,12.46,100,1,14.55,200,2,12.43,700,1,14.56,800,2,12.42,700,1,14.6,700,1,ARL,331051369
,2025-07-17T16:07:00.032711777Z,2025-07-17T16:07:00.032711777Z,10,2,1108,A,A,10,14.63,100,130,165170,276613336,13.11,100,1,13.84,100,1,12.98,200,2,13.85,2,1,12.9,2,1,14.28,100,1,12.86,100,1,14.46,100,1,12.73,100,1,14.48,700,1,12.71,100,1,14.51,700,1,12.5,700,1,14.52,200,2,12.46,100,1,14.55,200,2,12.43,700,1,14.56,800,2,12.42,700,1,14.6,700,1,ARL,331927477
,2025-07-17T16:07:00.045359807Z,2025-07-17T16:07:00.045359807Z,10,2,1108,C,A,0,13.84,100,130,165240,276613663,13.11,100,1,13.85,2,1,12.98,200,2,14.28,100,1,12.9,2,1,14.46,100,1,12.86,100,1,14.48,700,1,12.73,100,1,14.51,700,1,12.71,100,1,14.52,200,2,12.5,700,1,14.55,200,2,12.46,100,1,14.56,800,2,12.43,700,1,14.6,700,1,12.42,700,1,14.63,100,1,ARL,331491269
,2025-07-17T16:07:00.045394317Z,2025-07-17T16:07:00.045394317Z,10,2,1108,C,A,4,14.51,700,130,164955,276613664,13.11,100,1,13.85,2,1,12.98,200,2,14.28,100,1,12.9,2,1,14.46,100,1,12.86,100,1,14.48,700,1,12.73,100,1,14.52,200,2,12.71,100,1,14.55,200,2,12.5,700,1,14.56,800,2,12.46,100,1,14.6,700,1,12.43,700,1,14.63,100,1,12.42,700,1,14.88,100,1,ARL,331926981
,2025-07-17T16:07:00.045409635Z,2025-07-17T16:07:00.045409635Z,10,2,1108,A,A,1,14.09,100,130,165151,276613665,13.11,100,1,13.85,2,1,12.98,200,2,14.09,100,1,12.9,2,1,14.28,100,1,12.86,100,1,14.46,100,1,12.73,100,1,14.48,700,1,12.71,100,1,14.52,200,2,12.5,700,1,14.55,200,2,12.46,100,1,14.56,800,2,12.43,700,1,14.6,700,1,12.42,700,1,14.63,100,1,ARL,331927857
,2025-07-17T16:07:00.046672908Z,2025-07-17T16:07:00.046672908Z,10,2,1108,C,A,1,14.09,100,130,165694,276613680,13.11,100,1,13.85,2,1,12.98,200,2,14.28,100,1,12.9,2,1,14.46,100,1,12.86,100,1,14.48,700,1,12.73,100,1,14.52,200,2,12.71,100,1,14.55,200,2,12.5,700,1,14.56,800,2,12.46,100,1,14.6,700,1,12.43,700,1,14.63,100,1,12.42,700,1,14.88,100,1,ARL,331927857
,2025-07-17T16:07:00.046721624Z,2025-07-17T16:07:00.046721624Z,10,2,1108,A,A,1,13.86,100,130,165381,276613681,13.11,100,1,13.85,2,1,12.98,200,2,13.86,100,1,12.9,2,1,14.28,100,1,12.86,100,1,14.46,100,1,12.73,100,1,14.48,700,1,12.71,100,1,14.52,200,2,12.5,700,1,14.55,200,2,12.46,100,1,14.56,800,2,12.43,700,1,14.6,700,1,12.42,700,1,14.63,100,1,ARL,331927877
,2025-07-17T16:07:00.047544064Z,2025-07-17T16:07:00.047544064Z,10,2,1108,C,A,1,13.86,100,130,164872,276613692,13.11,100,1,13.85,2,1,12.98,200,2,14.28,100,1,12.9,2,1,14.46,100,1,12.86,100,1,14.48,700,1,12.73,100,1,14.52,200,2,12.71,100,1,14.55,200,2,12.5,700,1,14.56,800,2,12.46,100,1,14.6,700,1,12.43,700,1,14.63,100,1,12.42,700,1,14.88,100,1,ARL,331927877
,2025-07-17T16:07:00.047590313Z,2025-07-17T16:07:00.047590313Z,10,2,1108,A,A,1,14.12,100,130,165185,276613693,13.11,100,1,13.85,2,1,12.98,200,2,14.12,100,1,12.9,2,1,14.28,100,1,12.86,100,1,14.46,100,1,12.73,100,1,14.48,700,1,12.71,100,1,14.52,200,2,12.5,700,1,14.55,200,2,12.46,100,1,14.56,800,2,12.43,700,1,14.6,700,1,12.42,700,1,14.63,100,1,ARL,331927921
,2025-07-17T16:07:00.053283700Z,2025-07-17T16:07:00.053283700Z,10,2,1108,C,A,1,14.12,100,130,164970,276613731,13.11,100,1,13.85,2,1,12.98,200,2,14.28,100,1,12.9,2,1,14.46,100,1,12.86,100,1,14.48,700,1,12.73,100,1,14.52,200,2,12.71,100,1,14.55,200,2,12.5,700,1,14.56,800,2,12.46,100,1,14.6,700,1,12.43,700,1,14.63,100,1,12.42,700,1,14.88,100,1,ARL,331927921
,2025-07-17T16:07:00.053329959Z,2025-07-17T16:07:00.053329959Z,10,2,1108,A,A,1,14.26,100,130,165136,276613732,13.11,100,1,13.85,2,1,12.98,200,2,14.26,100,1,12.9,2,1,14.28,100,1,12.86,100,1,14.46,100,1,12.73,100,1,14.48,700,1,12.71,100,1,14.52,200,2,12.5,700,1,14.55,200,2,12.46,100,1,14.56,800,2,12.43,700,1,14.6,700,1,12.42,700,1,14.63,100,1,ARL,331928009
,2025-07-17T16:07:00.057644427Z,2025-07-17T16:07:00.057644427Z,10,2,1108,C,A,6,14.55,100,0,165430,276613800,13.11,100,1,13.85,2,1,12.98,200,2,14.26,100,1,12.9,2,1,14.28,100,1,12.86,100,1,14.46,100,1,12.73,100,1,14.48,700,1,12.71,100,1,14.52,200,2,12.5,700,1,14.55,100,1,12.46,100,1,14.56,800,2,12.43,700,1,14.6,700,1,12.42,700,1,14.63,100,1,ARL,331052197
,2025-07-17T16:07:00.070325784Z,2025-07-17T16:07:00.070325784Z,10,2,1108,C,A,1,14.26,100,130,165051,276614087,13.11,100,1,13.85,2,1,12.98,200,2,14.28,100,1,12.9,2,1,14.46,100,1,12.86,100,1,14.48,700,1,12.73,100,1,14.52,200,2,12.71,100,1,14.55,100,1,12.5,700,1,14.56,800,2,12.46,100,1,14.6,700,1,12.43,700,1,14.63,100,1,12.42,700,1,14.88,100,1,ARL,331928009
,2025-07-17T16:07:00.070373975Z,2025-07-17T16:07:00.070373975Z,10,2,1108,A,A,1,14.14,100,130,165247,276614089,13.11,100,1,13.85,2,1,12.98,200,2,14.14,100,1,12.9,2,1,14.28,100,1,12.86,100,1,14.46,100,1,12.73,100,1,14.48,700,1,12.71,100,1,14.52,200,2,12.5,700,1,14.55,100,1,12.46,100,1,14.56,800,2,12.43,700,1,14.6,700,1,12.42,700,1,14.63,100,1,ARL,331929033
,2025-07-17T16:07:00.071194493Z,2025-07-17T16:07:00.071194493Z,10,2,1108,C,A,1,14.14,100,130,164857,276614094,13.11,100,1,13.85,2,1,12.98,200,2,14.28,100,1,12.9,2,1,14.46,100,1,12.86,100,1,14.48,700,1,12.73,100,1,14.52,200,2,12.71,100,1,14.55,100,1,12.5,700,1,14.56,800,2,12.46,100,1,14.6,700,1,12.43,700,1,14.63,100,1,12.42,700,1,14.88,100,1,ARL,331929033
,2025-07-17T16:07:00.071239867Z,2025-07-17T16:07:00.071239867Z,10,2,1108,A,A,1,14.26,100,130,165238,276614095,13.11,100,1,13.85,2,1,12.98,200,2,14.26,100,1,12.9,2,1,14.28,100,1,12.86,100,1,14.46,100,1,12.73,100,1,14.48,700,1,12.71,100,1,14.52,200,2,12.5,700,1,14.55,100,1,12.46,100,1,14.56,800,2,12.43,700,1,14.6,700,1,12.42,700,1,14.63,100,1,ARL,331929041
,2025-07-17T16:07:00.074415631Z,2025-07-17T16:07:00.074415631Z,10,2,1108,C,A,10,14.88,100,0,165315,276614119,13.11,100,1,13.85,2,1,12.98,200,2,14.26,100,1,12.9,2,1,14.28,100,1,12.86,100,1,14.46,100,1,12.73,100,1,14.48,700,1,12.71,100,1,14.52,200,2,12.5,700,1,14.55,100,1,12.46,100,1,14.56,800,2,12.43,700,1,14.6,700,1,12.42,700,1,14.63,100,1,ARL,331927017
,2025-07-17T16:07:00.090194106Z,2025-07-17T16:07:00.090194106Z,10,2,1108,C,A,6,14.55,100,0,165651,276614378,13.11,100,1,13.85,2,1,12.98,200,2,14.26,100,1,12.9,2,1,14.28,100,1,12.86,100,1,14.46,100,1,12.73,100,1,14.48,700,1,12.71,100,1,14.52,200,2,12.5,700,1,14.56,800,2,12.46,100,1,14.6,700,1,12.43,700,1,14.63,100,1,12.42,700,1,14.96,100,1,ARL,331051173
,2025-07-17T16:07:00.090194106Z,2025-07-17T16:07:00.090194106Z,10,2,1108,A,A,9,14.96,100,130,165651,276614378,13.11,100,1,13.85,2,1,12.98,200,2,14.26,100,1,12.9,2,1,14.28,100,1,12.86,100,1,14.46,100,1,12.73,100,1,14.48,700,1,12.71,100,1,14.52,200,2,12.5,700,1,14.56,800,2,12.46,100,1,14.6,700,1,12.43,700,1,14.63,100,1,12.42,700,1,14.96,200,2,ARL,331929633
,2025-07-17T16:07:00.101927028Z,2025-07-17T16:07:00.101927028Z,10,2,1108,A,A,9,14.68,700,130,165119,276614699,13.11,100,1,13.85,2,1,12.98,200,2,14.26,100,1,12.9,2,1,14.28,100,1,12.86,100,1,14.46,100,1,12.73,100,1,14.48,700,1,12.71,100,1,14.52,200,2,12.5,700,1,14.56,800,2,12.46,100,1,14.6,700,1,12.43,700,1,14.63,100,1,12.42,700,1,14.68,700,1,ARL,331929977
,2025-07-17T16:07:00.494492099Z,2025-07-17T16:07:00.494492099Z,10,2,1108,A,A,1,13.86,100,130,165396,276622423,13.11,100,1,13.85,2,1,12.98,200,2,13.86,100,1,12.9,2,1,14.26,100,1,12.86,100,1,14.28,100,1,12.73,100,1,14.46,100,1,12.71,100,1,14.48,700,1,12.5,700,1,14.52,200,2,12.46,100,1,14.56,800,2,12.43,700,1,14.6,700,1,12.42,700,1,14.63,100,1,ARL,331942821
,2025-07-17T16:07:00.495152219Z,2025-07-17T16:07:00.495152219Z,10,2,1108,A,B,7,12.49,100,130,166026,276622452,13.11,100,1,13.85,2,1,12.98,200,2,13.86,100,1,12.9,2,1,14.26,100,1,12.86,100,1,14.28,100,1,12.73,100,1,14.46,100,1,12.71,100,1,14.48,700,1,12.5,700,1,14.52,200,2,12.49,100,1,14.56,800,2,12.46,100,1,14.6,700,1,12.43,700,1,14.63,100,1,ARL,331942901
,2025-07-17T16:07:00.495823953Z,2025-07-17T16:07:00.495823953Z,10,2,1108,A,B,7,12.49,100,130,165645,276622469,13.11,100,1,13.85,2,1,12.98,200,2,13.86,100,1,12.9,2,1,14.26,100,1,12.86,100,1,14.28,100,1,12.73,100,1,14.46,100,1,12.71,100,1,14.48,700,1,12.5,700,1,14.52,200,2,12.49,200,2,14.56,800,2,12.46,100,1,14.6,700,1,12.43,700,1,14.63,100,1,ARL,331942945
,2025-07-17T16:07:00.499501052Z,2025-07-17T16:07:00.499501052Z,10,2,1108,C,A,2,14.26,100,130,165097,276622569,13.11,100,1,13.85,2,1,12.98,200,2,13.86,100,1,12.9,2,1,14.28,100,1,12.86,100,1,14.46,100,1,12.73,100,1,14.48,700,1,12.71,100,1,14.52,200,2,12.5,700,1,14.56,800,2,12.49,200,2,14.6,700,1,12.46,100,1,14.63,100,1,12.43,700,1,14.68,700,1,ARL,331929041
,2025-07-17T16:07:00.499549738Z,2025-07-17T16:07:00.499549738Z,10,2,1108,A,A,2,14.14,100,130,165180,276622571,13.11,100,1,13.85,2,1,12.98,200,2,13.86,100,1,12.9,2,1,14.14,100,1,12.86,100,1,14.28,100,1,12.73,100,1,14.46,100,1,12.71,100,1,14.48,700,1,12.5,700,1,14.52,200,2,12.49,200,2,14.56,800,2,12.46,100,1,14.6,700,1,12.43,700,1,14.63,100,1,ARL,331943133
,2025-07-17T16:07:22.814776694Z,2025-07-17T16:07:22.814776694Z,10,2,1108,A,A,0,13.69,15,130,165115,276946179,13.11,100,1,13.69,15,1,12.98,200,2,13.85,2,1,12.9,2,1,13.86,100,1,12.86,100,1,14.14,100,1,12.73,100,1,14.28,100,1,12.71,100,1,14.46,100,1,12.5,700,1,14.48,700,1,12.49,200,2,14.52,200,2,12.46,100,1,14.56,800,2,12.43,700,1,14.6,700,1,ARL,332385317
,2025-07-17T16:07:22.814891345Z,2025-07-17T16:07:22.814891345Z,10,2,1108,C,A,2,13.86,100,0,166162,276946183,13.11,100,1,13.69,15,1,12.98,200,2,13.85,2,1,12.9,2,1,14.14,100,1,12.86,100,1,14.28,100,1,12.73,100,1,14.46,100,1,12.71,100,1,14.48,700,1,12.5,700,1,14.52,200,2,12.49,200,2,14.56,800,2,12.46,100,1,14.6,700,1,12.43,700,1,14.63,100,1,ARL,331942821
,2025-07-17T16:07:22.814891345Z,2025-07-17T16:07:22.814891345Z,10,2,1108,A,A,1,13.7,100,130,166162,276946183,13.11,100,1,13.69,15,1,12.98,200,2,13.7,100,1,12.9,2,1,13.85,2,1,12.86,100,1,14.14,100,1,12.73,100,1,14.28,100,1,12.71,100,1,14.46,100,1,12.5,700,1,14.48,700,1,12.49,200,2,14.52,200,2,12.46,100,1,14.56,800,2,12.43,700,1,14.6,700,1,ARL,332385325
,2025-07-17T16:07:22.819606945Z,2025-07-17T16:07:22.819606945Z,10,2,1108,C,A,10,14.63,100,0,165463,276946337,13.11,100,1,13.69,15,1,12.98,200,2,13.7,100,1,12.9,2,1,13.85,2,1,12.86,100,1,14.14,100,1,12.73,100,1,14.28,100,1,12.71,100,1,14.46,100,1,12.5,700,1,14.48,700,1,12.49,200,2,14.52,200,2,12.46,100,1,14.56,800,2,12.43,700,1,14.6,700,1,ARL,331927477
,2025-07-17T16:07:22.819606945Z,2025-07-17T16:07:22.819606945Z,10,2,1108,A,A,7,14.49,100,130,165463,276946337,13.11,100,1,13.69,15,1,12.98,200,2,13.7,100,1,12.9,2,1,13.85,2,1,12.86,100,1,14.14,100,1,12.73,100,1,14.28,100,1,12.71,100,1,14.46,100,1,12.5,700,1,14.48,700,1,12.49,200,2,14.49,100,1,12.46,100,1,14.52,200,2,12.43,700,1,14.56,800,2,ARL,332385597
,2025-07-17T16:07:22.821000003Z,2025-07-17T16:07:22.821000003Z,10,2,1108,C,A,3,14.14,100,130,165448,276946343,13.11,100,1,13.69,15,1,12.98,200,2,13.7,100,1,12.9,2,1,13.85,2,1,12.86,100,1,14.28,100,1,12.73,100,1,14.46,100,1,12.71,100,1,14.48,700,1,12.5,700,1,14.49,100,1,12.49,200,2,14.52,200,2,12.46,100,1,14.56,800,2,12.43,700,1,14.6,700,1,ARL,331943133
,2025-07-17T16:07:22.821052982Z,2025-07-17T16:07:22.821052982Z,10,2,1108,A,A,3,13.97,100,130,165225,276946344,13.11,100,1,13.69,15,1,12.98,200,2,13.7,100,1,12.9,2,1,13.85,2,1,12.86,100,1,13.97,100,1,12.73,100,1,14.28,100,1,12.71,100,1,14.46,100,1,12.5,700,1,14.48,700,1,12.49,200,2,14.49,100,1,12.46,100,1,14.52,200,2,12.43,700,1,14.56,800,2,ARL,332385613
,2025-07-17T16:07:28.273658191Z,2025-07-17T16:07:28.273658191Z,10,2,1108,C,A,0,13.69,15,130,165417,277012951,13.11,100,1,13.7,100,1,12.98,200,2,13.85,2,1,12.9,2,1,13.97,100,1,12.86,100,1,14.28,100,1,12.73,100,1,14.46,100,1,12.71,100,1,14.48,700,1,12.5,700,1,14.49,100,1,12.49,200,2,14.52,200,2,12.46,100,1,14.56,800,2,12.43,700,1,14.6,700,1,ARL,332385317
,2025-07-17T16:07:28.700815737Z,2025-07-17T16:07:28.700815737Z,10,2,1108,C,A,0,13.7,100,130,165412,277019711,13.11,100,1,13.85,2,1,12.98,200,2,13.97,100,1,12.9,2,1,14.28,100,1,12.86,100,1,14.46,100,1,12.73,100,1,14.48,700,1,12.71,100,1,14.49,100,1,12.5,700,1,14.52,200,2,12.49,200,2,14.56,800,2,12.46,100,1,14.6,700,1,12.43,700,1,14.66,200,2,ARL,332385325
,2025-07-17T16:07:28.701230409Z,2025-07-17T16:07:28.701230409Z,10,2,1108,C,B,2,12.9,2,0,166260,277019718,13.11,100,1,13.85,2,1,12.98,200,2,13.97,100,1,12.86,100,1,14.28,100,1,12.73,100,1,14.46,100,1,12.71,100,1,14.48,700,1,12.5,700,1,14.49,100,1,12.49,200,2,14.52,200,2,12.46,100,1,14.56,800,2,12.43,700,1,14.6,700,1,12.42,700,1,14.66,200,2,ARL,331694297
,2025-07-17T16:07:28.701230409Z,2025-07-17T16:07:28.701230409Z,10,2,1108,A,B,1,13.01,2,130,166260,277019718,13.11,100,1,13.85,2,1,13.01,2,1,13.97,100,1,12.98,200,2,14.28,100,1,12.86,100,1,14.46,100,1,12.73,100,1,14.48,700,1,12.71,100,1,14.49,100,1,12.5,700,1,14.52,200,2,12.49,200,2,14.56,800,2,12.46,100,1,14.6,700,1,12.43,700,1,14.66,200,2,ARL,332494213
,2025-07-17T16:07:28.702476699Z,2025-07-17T16:07:28.702476699Z,10,2,1108,C,A,9,14.66,100,0,165321,277019729,13.11,100,1,13.85,2,1,13.01,2,1,13.97,100,1,12.98,200,2,14.28,100,1,12.86,100,1,14.46,100,1,12.73,100,1,14.48,700,1,12.71,100,1,14.49,100,1,12.5,700,1,14.52,200,2,12.49,200,2,14.56,800,2,12.46,100,1,14.6,700,1,12.43,700,1,14.66,100,1,ARL,332386121
,2025-07-17T16:07:28.703357714Z,2025-07-17T16:07:28.703357714Z,10,2,1108,C,A,9,14.66,100,0,165378,277019733,13.11,100,1,13.85,2,1,13.01,2,1,13.97,100,1,12.98,200,2,14.28,100,1,12.86,100,1,14.46,100,1,12.73,100,1,14.48,700,1,12.71,100,1,14.49,100,1,12.5,700,1,14.52,200,2,12.49,200,2,14.56,800,2,12.46,100,1,14.6,700,1,12.43,700,1,14.68,700,1,ARL,332385565
,2025-07-17T16:07:28.724036175Z,2025-07-17T16:07:28.724036175Z,10,2,1108,C,A,1,13.97,100,130,165665,277019926,13.11,100,1,13.85,2,1,13.01,2,1,14.28,100,1,12.98,200,2,14.46,100,1,12.86,100,1,14.48,700,1,12.73,100,1,14.49,100,1,12.71,100,1,14.52,200,2,12.5,700,1,14.56,800,2,12.49,200,2,14.6,700,1,12.46,100,1,14.68,700,1,12.43,700,1,14.82,100,1,ARL,332385613
,2025-07-17T16:07:28.724085453Z,2025-07-17T16:07:28.724085453Z,10,2,1108,A,A,1,14.2,100,130,165382,277019929,13.11,100,1,13.85,2,1,13.01,2,1,14.2,100,1,12.98,200,2,14.28,100,1,12.86,100,1,14.46,100,1,12.73,100,1,14.48,700,1,12.71,100,1,14.49,100,1,12.5,700,1,14.52,200,2,12.49,200,2,14.56,800,2,12.46,100,1,14.6,700,1,12.43,700,1,14.68,700,1,ARL,332494893
,2025-07-17T16:07:28.751662660Z,2025-07-17T16:07:28.751662660Z,10,2,1108,C,A,10,14.82,100,0,165460,277020284,13.11,100,1,13.85,2,1,13.01,2,1,14.2,100,1,12.98,200,2,14.28,100,1,12.86,100,1,14.46,100,1,12.73,100,1,14.48,700,1,12.71,100,1,14.49,100,1,12.5,700,1,14.52,200,2,12.49,200,2,14.56,800,2,12.46,100,1,14.6,700,1,12.43,700,1,14.68,700,1,ARL,332494229
,2025-07-17T16:07:28.830995364Z,2025-07-17T16:07:28.830995364Z,10,2,1108,C,A,5,14.49,100,130,165623,277021007,13.11,100,1,13.85,2,1,13.01,2,1,14.2,100,1,12.98,200,2,14.28,100,1,12.86,100,1,14.46,100,1,12.73,100,1,14.48,700,1,12.71,100,1,14.52,200,2,12.5,700,1,14.56,800,2,12.49,200,2,14.6,700,1,12.46,100,1,14.68,700,1,12.43,700,1,14.95,200,2,ARL,332385597
,2025-07-17T16:07:28.831125667Z,2025-07-17T16:07:28.831125667Z,10,2,1108,A,A,9,14.77,100,130,165710,277021012,13.11,100,1,13.85,2,1,13.01,2,1,14.2,100,1,12.98,200,2,14.28,100,1,12.86,100,1,14.46,100,1,12.73,100,1,14.48,700,1,12.71,100,1,14.52,200,2,12.5,700,1,14.56,800,2,12.49,200,2,14.6,700,1,12.46,100,1,14.68,700,1,12.43,700,1,14.77,100,1,ARL,332497653
,2025-07-17T16:07:29.214500816Z,2025-07-17T16:07:29.214500816Z,10,2,1108,A,A,1,13.86,100,128,166454,277029015,13.11,100,1,13.85,2,1,13.01,2,1,13.86,100,1,12.98,200,2,14.2,100,1,12.86,100,1,14.28,100,1,12.73,100,1,14.46,100,1,12.71,100,1,14.48,700,1,12.5,700,1,14.52,200,2,12.49,200,2,14.56,800,2,12.46,100,1,14.6,700,1,12.43,700,1,14.68,700,1,ARL,332508813
,2025-07-17T16:08:20.816087447Z,2025-07-17T16:08:20.816087447Z,10,2,1108,A,A,0,13.68,15,130,165403,277732167,13.11,100,1,13.68,15,1,13.01,2,1,13.85,2,1,12.98,200,2,13.86,100,1,12.86,100,1,14.2,100,1,12.73,100,1,14.28,100,1,12.71,100,1,14.46,100,1,12.5,700,1,14.48,700,1,12.49,200,2,14.52,200,2,12.46,100,1,14.56,800,2,12.43,700,1,14.6,700,1,ARL,333436357
,2025-07-17T16:08:20.816200644Z,2025-07-17T16:08:20.816200644Z,10,2,1108,C,A,2,13.86,100,0,165561,277732170,13.11,100,1,13.68,15,1,13.01,2,1,13.85,2,1,12.98,200,2,14.2,100,1,12.86,100,1,14.28,100,1,12.73,100,1,14.46,100,1,12.71,100,1,14.48,700,1,12.5,700,1,14.52,200,2,12.49,200,2,14.56,800,2,12.46,100,1,14.6,700,1,12.43,700,1,14.68,700,1,ARL,332508813
,2025-07-17T16:08:20.816200644Z,2025-07-17T16:08:20.816200644Z,10,2,1108,A,A,1,13.69,100,130,165561,277732170,13.11,100,1,13.68,15,1,13.01,2,1,13.69,100,1,12.98,200,2,13.85,2,1,12.86,100,1,14.2,100,1,12.73,100,1,14.28,100,1,12.71,100,1,14.46,100,1,12.5,700,1,14.48,700,1,12.49,200,2,14.52,200,2,12.46,100,1,14.56,800,2,12.43,700,1,14.6,700,1,ARL,333436361
,2025-07-17T16:08:20.818965359Z,2025-07-17T16:08:20.818965359Z,10,2,1108,A,A,10,14.65,100,130,165461,277732216,13.11,100,1,13.68,15,1,13.01,2,1,13.69,100,1,12.98,200,2,13.85,2,1,12.86,100,1,14.2,100,1,12.73,100,1,14.28,100,1,12.71,100,1,14.46,100,1,12.5,700,1,14.48,700,1,12.49,200,2,14.52,200,2,12.46,100,1,14.56,800,2,12.43,700,1,14.6,700,1,ARL,333436425
,2025-07-17T16:08:20.821924168Z,2025-07-17T16:08:20.821924168Z,10,2,1108,C,A,3,14.2,100,130,165376,277732239,13.11,100,1,13.68,15,1,13.01,2,1,13.69,100,1,12.98,200,2,13.85,2,1,12.86,100,1,14.28,100,1,12.73,100,1,14.46,100,1,12.71,100,1,14.48,700,1,12.5,700,1,14.52,200,2,12.49,200,2,14.56,800,2,12.46,100,1,14.6,700,1,12.43,700,1,14.65,100,1,ARL,332494893
,2025-07-17T16:08:20.821974299Z,2025-07-17T16:08:20.821974299Z,10,2,1108,A,A,3,13.96,100,130,165242,277732240,13.11,100,1,13.68,15,1,13.01,2,1,13.69,100,1,12.98,200,2,13.85,2,1,12.86,100,1,13.96,100,1,12.73,100,1,14.28,100,1,12.71,100,1,14.46,100,1,12.5,700,1,14.48,700,1,12.49,200,2,14.52,200,2,12.46,100,1,14.56,800,2,12.43,700,1,14.6,700,1,ARL,333436473
,2025-07-17T16:08:20.829945074Z,2025-07-17T16:08:20.829945074Z,10,2,1108,A,A,10,14.65,100,130,165425,277732299,13.11,100,1,13.68,15,1,13.01,2,1,13.69,100,1,12.98,200,2,13.85,2,1,12.86,100,1,13.96,100,1,12.73,100,1,14.28,100,1,12.71,100,1,14.46,100,1,12.5,700,1,14.48,700,1,12.49,200,2,14.52,200,2,12.46,100,1,14.56,800,2,12.43,700,1,14.6,700,1,ARL,333436589
,2025-07-17T16:08:20.966063681Z,2025-07-17T16:08:20.966063681Z,10,2,1108,A,A,6,14.48,100,130,165585,277733304,13.11,100,1,13.68,15,1,13.01,2,1,13.69,100,1,12.98,200,2,13.85,2,1,12.86,100,1,13.96,100,1,12.73,100,1,14.28,100,1,12.71,100,1,14.46,100,1,12.5,700,1,14.48,800,2,12.49,200,2,14.52,200,2,12.46,100,1,14.56,800,2,12.43,700,1,14.6,700,1,ARL,333438545
,2025-07-17T16:08:22.998002821Z,2025-07-17T16:08:22.998002821Z,10,2,1108,C,A,0,13.68,15,130,165365,277766492,13.11,100,1,13.69,100,1,13.01,2,1,13.85,2,1,12.98,200,2,13.96,100,1,12.86,100,1,14.28,100,1,12.73,100,1,14.46,100,1,12.71,100,1,14.48,800,2,12.5,700,1,14.52,200,2,12.49,200,2,14.56,800,2,12.46,100,1,14.6,700,1,12.43,700,1,14.65,200,2,ARL,333436357
,2025-07-17T16:08:27.482344236Z,2025-07-17T16:08:27.482344236Z,10,2,1108,C,A,0,13.69,100,130,165448,277841171,13.11,100,1,13.85,2,1,13.01,2,1,13.96,100,1,12.98,200,2,14.28,100,1,12.86,100,1,14.46,100,1,12.73,100,1,14.48,800,2,12.71,100,1,14.52,200,2,12.5,700,1,14.56,800,2,12.49,200,2,14.6,700,1,12.46,100,1,14.65,200,2,12.43,700,1,14.68,700,1,ARL,333436361
,2025-07-17T16:08:27.483075481Z,2025-07-17T16:08:27.483075481Z,10,2,1108,C,A,10,14.75,100,0,165526,277841175,13.11,100,1,13.85,2,1,13.01,2,1,13.96,100,1,12.98,200,2,14.28,100,1,12.86,100,1,14.46,100,1,12.73,100,1,14.48,800,2,12.71,100,1,14.52,200,2,12.5,700,1,14.56,800,2,12.49,200,2,14.6,700,1,12.46,100,1,14.65,200,2,12.43,700,1,14.68,700,1,ARL,333436397
,2025-07-17T16:08:27.483075481Z,2025-07-17T16:08:27.483075481Z,10,2,1108,A,A,10,14.99,100,130,165526,277841175,13.11,100,1,13.85,2,1,13.01,2,1,13.96,100,1,12.98,200,2,14.28,100,1,12.86,100,1,14.46,100,1,12.73,100,1,14.48,800,2,12.71,100,1,14.52,200,2,12.5,700,1,14.56,800,2,12.49,200,2,14.6,700,1,12.46,100,1,14.65,200,2,12.43,700,1,14.68,700,1,ARL,333581389
,2025-07-17T16:08:27.483420069Z,2025-07-17T16:08:27.483420069Z,10,2,1108,C,A,5,14.52,100,0,165823,277841178,13.11,100,1,13.85,2,1,13.01,2,1,13.96,100,1,12.98,200,2,14.28,100,1,12.86,100,1,14.46,100,1,12.73,100,1,14.48,800,2,12.71,100,1,14.52,100,1,12.5,700,1,14.56,800,2,12.49,200,2,14.6,700,1,12.46,100,1,14.65,200,2,12.43,700,1,14.68,700,1,ARL,328780577
,2025-07-17T16:08:27.483420069Z,2025-07-17T16:08:27.483420069Z,10,2,1108,A,A,10,14.74,100,130,165823,277841178,13.11,100,1,13.85,2,1,13.01,2,1,13.96,100,1,12.98,200,2,14.28,100,1,12.86,100,1,14.46,100,1,12.73,100,1,14.48,800,2,12.71,100,1,14.52,100,1,12.5,700,1,14.56,800,2,12.49,200,2,14.6,700,1,12.46,100,1,14.65,200,2,12.43,700,1,14.68,700,1,ARL,333581393
,2025-07-17T16:08:27.483913735Z,2025-07-17T16:08:27.483913735Z,10,2,1108,C,A,8,14.65,100,0,165489,277841218,13.11,100,1,13.85,2,1,13.01,2,1,13.96,100,1,12.98,200,2,14.28,100,1,12.86,100,1,14.46,100,1,12.73,100,1,14.48,800,2,12.71,100,1,14.52,100,1,12.5,700,1,14.56,800,2,12.49,200,2,14.6,700,1,12.46,100,1,14.65,100,1,12.43,700,1,14.68,700,1,ARL,333436589
,2025-07-17T16:08:27.484800296Z,2025-07-17T16:08:27.484800296Z,10,2,1108,C,A,8,14.65,100,0,165661,277841228,13.11,100,1,13.85,2,1,13.01,2,1,13.96,100,1,12.98,200,2,14.28,100,1,12.86,100,1,14.46,100,1,12.73,100,1,14.48,800,2,12.71,100,1,14.52,100,1,12.5,700,1,14.56,800,2,12.49,200,2,14.6,700,1,12.46,100,1,14.68,700,1,12.43,700,1,14.74,100,1,ARL,333436425
,2025-07-17T16:08:27.484800296Z,2025-07-17T16:08:27.484800296Z,10,2,1108,A,A,10,14.94,100,130,165661,277841228,13.11,100,1,13.85,2,1,13.01,2,1,13.96,100,1,12.98,200,2,14.28,100,1,12.86,100,1,14.46,100,1,12.73,100,1,14.48,800,2,12.71,100,1,14.52,100,1,12.5,700,1,14.56,800,2,12.49,200,2,14.6,700,1,12.46,100,1,14.68,700,1,12.43,700,1,14.74,100,1,ARL,333581429
,2025-07-17T16:08:27.487097702Z,2025-07-17T16:08:27.487097702Z,10,2,1108,C,A,5,14.52,100,0,165574,277841319,13.11,100,1,13.85,2,1,13.01,2,1,13.96,100,1,12.98,200,2,14.28,100,1,12.86,100,1,14.46,100,1,12.73,100,1,14.48,800,2,12.71,100,1,14.56,800,2,12.5,700,1,14.6,700,1,12.49,200,2,14.68,700,1,12.46,100,1,14.74,100,1,12.43,700,1,14.94,200,2,ARL,328780597
,2025-07-17T16:08:27.487097702Z,2025-07-17T16:08:27.487097702Z,10,2,1108,A,A,8,14.74,100,130,165574,277841319,13.11,100,1,13.85,2,1,13.01,2,1,13.96,100,1,12.98,200,2,14.28,100,1,12.86,100,1,14.46,100,1,12.73,100,1,14.48,800,2,12.71,100,1,14.56,800,2,12.5,700,1,14.6,700,1,12.49,200,2,14.68,700,1,12.46,100,1,14.74,200,2,12.43,700,1,14.94,200,2,ARL,333581481
,2025-07-17T16:08:27.492093401Z,2025-07-17T16:08:27.492093401Z,10,2,1108,C,A,4,14.48,100,130,165505,277841396,13.11,100,1,13.85,2,1,13.01,2,1,13.96,100,1,12.98,200,2,14.28,100,1,12.86,100,1,14.46,100,1,12.73,100,1,14.48,700,1,12.71,100,1,14.56,800,2,12.5,700,1,14.6,700,1,12.49,200,2,14.68,700,1,12.46,100,1,14.74,200,2,12.43,700,1,14.94,200,2,ARL,333438545
,2025-07-17T16:08:27.492220454Z,2025-07-17T16:08:27.492220454Z,10,2,1108,A,A,9,14.75,100,130,165296,277841397,13.11,100,1,13.85,2,1,13.01,2,1,13.96,100,1,12.98,200,2,14.28,100,1,12.86,100,1,14.46,100,1,12.73,100,1,14.48,700,1,12.71,100,1,14.56,800,2,12.5,700,1,14.6,700,1,12.49,200,2,14.68,700,1,12.46,100,1,14.74,200,2,12.43,700,1,14.75,100,1,ARL,333581569
,2025-07-17T16:08:27.496770678Z,2025-07-17T16:08:27.496770678Z,10,2,1108,C,A,1,13.96,100,130,165444,277841427,13.11,100,1,13.85,2,1,13.01,2,1,14.28,100,1,12.98,200,2,14.46,100,1,12.86,100,1,14.48,700,1,12.73,100,1,14.56,800,2,12.71,100,1,14.6,700,1,12.5,700,1,14.68,700,1,12.49,200,2,14.74,200,2,12.46,100,1,14.75,100,1,12.43,700,1,14.94,200,2,ARL,333436473
,2025-07-17T16:08:27.496822540Z,2025-07-17T16:08:27.496822540Z,10,2,1108,A,A,1,14.19,100,130,165292,277841428,13.11,100,1,13.85,2,1,13.01,2,1,14.19,100,1,12.98,200,2,14.28,100,1,12.86,100,1,14.46,100,1,12.73,100,1,14.48,700,1,12.71,100,1,14.56,800,2,12.5,700,1,14.6,700,1,12.49,200,2,14.68,700,1,12.46,100,1,14.74,200,2,12.43,700,1,14.75,100,1,ARL,333581625
,2025-07-17T16:08:27.500928061Z,2025-07-17T16:08:27.500928061Z,10,2,1108,C,A,0,13.85,2,0,165557,277841469,13.11,100,1,14.19,100,1,13.01,2,1,14.28,100,1,12.98,200,2,14.46,100,1,12.86,100,1,14.48,700,1,12.73,100,1,14.56,800,2,12.71,100,1,14.6,700,1,12.5,700,1,14.68,700,1,12.49,200,2,14.74,200,2,12.46,100,1,14.75,100,1,12.43,700,1,14.94,200,2,ARL,331155889
,2025-07-17T16:08:27.500928061Z,2025-07-17T16:08:27.500928061Z,10,2,1108,A,A,0,13.98,2,130,165557,277841469,13.11,100,1,13.98,2,1,13.01,2,1,14.19,100,1,12.98,200,2,14.28,100,1,12.86,100,1,14.46,100,1,12.73,100,1,14.48,700,1,12.71,100,1,14.56,800,2,12.5,700,1,14.6,700,1,12.49,200,2,14.68,700,1,12.46,100,1,14.74,200,2,12.43,700,1,14.75,100,1,ARL,333581677
,2025-07-17T16:08:27.516449334Z,2025-07-17T16:08:27.516449334Z,10,2,1108,C,A,1,14.19,100,130,165039,277841551,13.11,100,1,13.98,2,1,13.01,2,1,14.28,100,1,12.98,200,2,14.46,100,1,12.86,100,1,14.48,700,1,12.73,100,1,14.56,800,2,12.71,100,1,14.6,700,1,12.5,700,1,14.68,700,1,12.49,200,2,14.74,200,2,12.46,100,1,14.75,100,1,12.43,700,1,14.94,200,2,ARL,333581625
,2025-07-17T16:08:27.516496962Z,2025-07-17T16:08:27.516496962Z,10,2,1108,A,A,1,14.26,100,130,165137,277841552,13.11,100,1,13.98,2,1,13.01,2,1,14.26,100,1,12.98,200,2,14.28,100,1,12.86,100,1,14.46,100,1,12.73,100,1,14.48,700,1,12.71,100,1,14.56,800,2,12.5,700,1,14.6,700,1,12.49,200,2,14.68,700,1,12.46,100,1,14.74,200,2,12.43,700,1,14.75,100,1,ARL,333581765
,2025-07-17T16:08:27.987513451Z,2025-07-17T16:08:27.987513451Z,10,2,1108,A,A,1,13.99,100,130,165288,277846288,13.11,100,1,13.98,2,1,13.01,2,1,13.99,100,1,12.98,200,2,14.26,100,1,12.86,100,1,14.28,100,1,12.73,100,1,14.46,100,1,12.71,100,1,14.48,700,1,12.5,700,1,14.56,800,2,12.49,200,2,14.6,700,1,12.46,100,1,14.68,700,1,12.43,700,1,14.74,200,2,ARL,333590057
,2025-07-17T16:08:58.024814068Z,2025-07-17T16:08:58.024814068Z,10,2,1108,A,A,0,13.81,15,130,165314,278261182,13.11,100,1,13.81,15,1,13.01,2,1,13.98,2,1,12.98,200,2,13.99,100,1,12.86,100,1,14.26,100,1,12.73,100,1,14.28,100,1,12.71,100,1,14.46,100,1,12.5,700,1,14.48,700,1,12.49,200,2,14.56,800,2,12.46,100,1,14.6,700,1,12.43,700,1,14.68,700,1,ARL,334141429
,2025-07-17T16:09:00.222509491Z,2025-07-17T16:09:00.222509491Z,10,2,1108,C,A,2,13.99,100,0,165743,278295684,13.11,100,1,13.81,15,1,13.01,2,1,13.98,2,1,12.98,200,2,14.26,100,1,12.86,100,1,14.28,100,1,12.73,100,1,14.46,100,1,12.71,100,1,14.48,700,1,12.5,700,1,14.56,800,2,12.49,200,2,14.6,700,1,12.46,100,1,14.68,700,1,12.43,700,1,14.74,200,2,ARL,333590057
,2025-07-17T16:09:00.222509491Z,2025-07-17T16:09:00.222509491Z,10,2,1108,A,A,1,13.82,100,130,165743,278295684,13.11,100,1,13.81,15,1,13.01,2,1,13.82,100,1,12.98,200,2,13.98,2,1,12.86,100,1,14.26,100,1,12.73,100,1,14.28,100,1,12.71,100,1,14.46,100,1,12.5,700,1,14.48,700,1,12.49,200,2,14.56,800,2,12.46,100,1,14.6,700,1,12.43,700,1,14.68,700,1,ARL,334189729
,2025-07-17T16:09:00.226338384Z,2025-07-17T16:09:00.226338384Z,10,2,1108,A,A,9,14.61,100,130,165962,278296281,13.11,100,1,13.81,15,1,13.01,2,1,13.82,100,1,12.98,200,2,13.98,2,1,12.86,100,1,14.26,100,1,12.73,100,1,14.28,100,1,12.71,100,1,14.46,100,1,12.5,700,1,14.48,700,1,12.49,200,2,14.56,800,2,12.46,100,1,14.6,700,1,12.43,700,1,14.61,100,1,ARL,334190189
,2025-07-17T16:09:00.227763275Z,2025-07-17T16:09:00.227763275Z,10,2,1108,C,A,3,14.26,100,130,165786,278296402,13.11,100,1,13.81,15,1,13.01,2,1,13.82,100,1,12.98,200,2,13.98,2,1,12.86,100,1,14.28,100,1,12.73,100,1,14.46,100,1,12.71,100,1,14.48,700,1,12.5,700,1,14.56,800,2,12.49,200,2,14.6,700,1,12.46,100,1,14.61,100,1,12.43,700,1,14.68,700,1,ARL,333581765
,2025-07-17T16:09:00.227818153Z,2025-07-17T16:09:00.227818153Z,10,2,1108,A,A,3,14.1,100,130,165330,278296411,13.11,100,1,13.81,15,1,13.01,2,1,13.82,100,1,12.98,200,2,13.98,2,1,12.86,100,1,14.1,100,1,12.73,100,1,14.28,100,1,12.71,100,1,14.46,100,1,12.5,700,1,14.48,700,1,12.49,200,2,14.56,800,2,12.46,100,1,14.6,700,1,12.43,700,1,14.61,100,1,ARL,334190225
,2025-07-17T16:09:08.719524374Z,2025-07-17T16:09:08.719524374Z,10,2,1108,A,A,0,13.75,15,130,166319,278436950,13.11,100,1,13.75,15,1,13.01,2,1,13.81,15,1,12.98,200,2,13.82,100,1,12.86,100,1,13.98,2,1,12.73,100,1,14.1,100,1,12.71,100,1,14.28,100,1,12.5,700,1,14.46,100,1,12.49,200,2,14.48,700,1,12.46,100,1,14.56,800,2,12.43,700,1,14.6,700,1,ARL,334366613
,2025-07-17T16:09:08.719706070Z,2025-07-17T16:09:08.719706070Z,10,2,1108,C,A,2,13.82,100,0,165340,278436967,13.11,100,1,13.75,15,1,13.01,2,1,13.81,15,1,12.98,200,2,13.98,2,1,12.86,100,1,14.1,100,1,12.73,100,1,14.28,100,1,12.71,100,1,14.46,100,1,12.5,700,1,14.48,700,1,12.49,200,2,14.56,800,2,12.46,100,1,14.6,700,1,12.43,700,1,14.61,100,1,ARL,334189729
,2025-07-17T16:09:08.719706070Z,2025-07-17T16:09:08.719706070Z,10,2,1108,A,A,1,13.76,100,130,165340,278436967,13.11,100,1,13.75,15,1,13.01,2,1,13.76,100,1,12.98,200,2,13.81,15,1,12.86,100,1,13.98,2,1,12.73,100,1,14.1,100,1,12.71,100,1,14.28,100,1,12.5,700,1,14.46,100,1,12.49,200,2,14.48,700,1,12.46,100,1,14.56,800,2,12.43,700,1,14.6,700,1,ARL,334366617
,2025-07-17T16:09:18.819135505Z,2025-07-17T16:09:18.819135505Z,10,2,1108,C,A,2,13.81,15,130,165230,278596985,13.11,100,1,13.75,15,1,13.01,2,1,13.76,100,1,12.98,200,2,13.98,2,1,12.86,100,1,14.1,100,1,12.73,100,1,14.28,100,1,12.71,100,1,14.46,100,1,12.5,700,1,14.48,700,1,12.49,200,2,14.56,800,2,12.46,100,1,14.6,700,1,12.43,700,1,14.61,100,1,ARL,334141429
,2025-07-17T16:09:19.927039122Z,2025-07-17T16:09:19.927039122Z,10,2,1108,A,A,0,13.73,15,130,165901,278621672,13.11,100,1,13.73,15,1,13.01,2,1,13.75,15,1,12.98,200,2,13.76,100,1,12.86,100,1,13.98,2,1,12.73,100,1,14.1,100,1,12.71,100,1,14.28,100,1,12.5,700,1,14.46,100,1,12.49,200,2,14.48,700,1,12.46,100,1,14.56,800,2,12.43,700,1,14.6,700,1,ARL,334583329
,2025-07-17T16:09:20.284695585Z,2025-07-17T16:09:20.284695585Z,10,2,1108,C,A,2,13.76,100,0,165490,278629057,13.11,100,1,13.73,15,1,13.01,2,1,13.75,15,1,12.98,200,2,13.98,2,1,12.86,100,1,14.1,100,1,12.73,100,1,14.28,100,1,12.71,100,1,14.46,100,1,12.5,700,1,14.48,700,1,12.49,200,2,14.56,800,2,12.46,100,1,14.6,700,1,12.43,700,1,14.61,100,1,ARL,334366617
,2025-07-17T16:09:20.284695585Z,2025-07-17T16:09:20.284695585Z,10,2,1108,A,A,1,13.74,100,130,165490,278629057,13.11,100,1,13.73,15,1,13.01,2,1,13.74,100,1,12.98,200,2,13.75,15,1,12.86,100,1,13.98,2,1,12.73,100,1,14.1,100,1,12.71,100,1,14.28,100,1,12.5,700,1,14.46,100,1,12.49,200,2,14.48,700,1,12.46,100,1,14.56,800,2,12.43,700,1,14.6,700,1,ARL,334593569
,2025-07-17T16:09:20.293106270Z,2025-07-17T16:09:20.293106270Z,10,2,1108,C,A,4,14.1,100,130,165350,278629219,13.11,100,1,13.73,15,1,13.01,2,1,13.74,100,1,12.98,200,2,13.75,15,1,12.86,100,1,13.98,2,1,12.73,100,1,14.28,100,1,12.71,100,1,14.46,100,1,12.5,700,1,14.48,700,1,12.49,200,2,14.56,800,2,12.46,100,1,14.6,700,1,12.43,700,1,14.61,100,1,ARL,334190225
,2025-07-17T16:09:20.293161454Z,2025-07-17T16:09:20.293161454Z,10,2,1108,A,A,4,14.01,100,130,165187,278629220,13.11,100,1,13.73,15,1,13.01,2,1,13.74,100,1,12.98,200,2,13.75,15,1,12.86,100,1,13.98,2,1,12.73,100,1,14.01,100,1,12.71,100,1,14.28,100,1,12.5,700,1,14.46,100,1,12.49,200,2,14.48,700,1,12.46,100,1,14.56,800,2,12.43,700,1,14.6,700,1,ARL,334593753
,2025-07-17T16:09:20.818648795Z,2025-07-17T16:09:20.818648795Z,10,2,1108,C,A,0,13.73,15,130,165140,278640667,13.11,100,1,13.74,100,1,13.01,2,1,13.75,15,1,12.98,200,2,13.98,2,1,12.86,100,1,14.01,100,1,12.73,100,1,14.28,100,1,12.71,100,1,14.46,100,1,12.5,700,1,14.48,700,1,12.49,200,2,14.56,800,2,12.46,100,1,14.6,700,1,12.43,700,1,14.61,100,1,ARL,334583329
,2025-07-17T16:09:20.818761228Z,2025-07-17T16:09:20.818761228Z,10,2,1108,C,A,1,13.75,15,130,165128,278640670,13.11,100,1,13.74,100,1,13.01,2,1,13.98,2,1,12.98,200,2,14.01,100,1,12.86,100,1,14.28,100,1,12.73,100,1,14.46,100,1,12.71,100,1,14.48,700,1,12.5,700,1,14.56,800,2,12.49,200,2,14.6,700,1,12.46,100,1,14.61,100,1,12.43,700,1,14.62,200,2,ARL,334366613
,2025-07-17T16:09:28.985956629Z,2025-07-17T16:09:28.985956629Z,10,2,1108,C,A,1,13.98,2,0,165803,278784943,13.11,100,1,13.74,100,1,13.01,2,1,14.01,100,1,12.98,200,2,14.28,100,1,12.86,100,1,14.46,100,1,12.73,100,1,14.48,700,1,12.71,100,1,14.56,800,2,12.5,700,1,14.6,700,1,12.49,200,2,14.61,100,1,12.46,100,1,14.62,200,2,12.43,700,1,14.68,700,1,ARL,333581677
,2025-07-17T16:09:28.985956629Z,2025-07-17T16:09:28.985956629Z,10,2,1108,A,A,1,13.9,2,130,165803,278784943,13.11,100,1,13.74,100,1,13.01,2,1,13.9,2,1,12.98,200,2,14.01,100,1,12.86,100,1,14.28,100,1,12.73,100,1,14.46,100,1,12.71,100,1,14.48,700,1,12.5,700,1,14.56,800,2,12.49,200,2,14.6,700,1,12.46,100,1,14.61,100,1,12.43,700,1,14.62,200,2,ARL,334804177
,2025-07-17T16:09:40.821522565Z,2025-07-17T16:09:40.821522565Z,10,2,1108,A,A,0,13.7,15,130,165340,278938091,13.11,100,1,13.7,15,1,13.01,2,1,13.74,100,1,12.98,200,2,13.9,2,1,12.86,100,1,14.01,100,1,12.73,100,1,14.28,100,1,12.71,100,1,14.46,100,1,12.5,700,1,14.48,700,1,12.49,200,2,14.56,800,2,12.46,100,1,14.6,700,1,12.43,700,1,14.61,100,1,ARL,335003269
,2025-07-17T16:09:40.853439053Z,2025-07-17T16:09:40.853439053Z,10,2,1108,C,A,1,13.74,100,0,165524,278938747,13.11,100,1,13.7,15,1,13.01,2,1,13.9,2,1,12.98,200,2,14.01,100,1,12.86,100,1,14.28,100,1,12.73,100,1,14.46,100,1,12.71,100,1,14.48,700,1,12.5,700,1,14.56,800,2,12.49,200,2,14.6,700,1,12.46,100,1,14.61,100,1,12.43,700,1,14.62,200,2,ARL,334593569
,2025-07-17T16:09:40.853439053Z,2025-07-17T16:09:40.853439053Z,10,2,1108,A,A,1,13.71,100,130,165524,278938747,13.11,100,1,13.7,15,1,13.01,2,1,13.71,100,1,12.98,200,2,13.9,2,1,12.86,100,1,14.01,100,1,12.73,100,1,14.28,100,1,12.71,100,1,14.46,100,1,12.5,700,1,14.48,700,1,12.49,200,2,14.56,800,2,12.46,100,1,14.6,700,1,12.43,700,1,14.61,100,1,ARL,335003813
,2025-07-17T16:09:50.820783486Z,2025-07-17T16:09:50.820783486Z,10,2,1108,A,A,0,13.67,15,130,165645,279081140,13.11,100,1,13.67,15,1,13.01,2,1,13.7,15,1,12.98,200,2,13.71,100,1,12.86,100,1,13.9,2,1,12.73,100,1,14.01,100,1,12.71,100,1,14.28,100,1,12.5,700,1,14.46,100,1,12.49,200,2,14.48,700,1,12.46,100,1,14.56,800,2,12.43,700,1,14.6,700,1,ARL,335178437
,2025-07-17T16:09:52.678611805Z,2025-07-17T16:09:52.678611805Z,10,2,1108,C,A,2,13.71,100,0,165553,279109959,13.11,100,1,13.67,15,1,13.01,2,1,13.7,15,1,12.98,200,2,13.9,2,1,12.86,100,1,14.01,100,1,12.73,100,1,14.28,100,1,12.71,100,1,14.46,100,1,12.5,700,1,14.48,700,1,12.49,200,2,14.56,800,2,12.46,100,1,14.6,700,1,12.43,700,1,14.61,100,1,ARL,335003813
,2025-07-17T16:09:52.678611805Z,2025-07-17T16:09:52.678611805Z,10,2,1108,A,A,1,13.68,100,130,165553,279109959,13.11,100,1,13.67,15,1,13.01,2,1,13.68,100,1,12.98,200,2,13.7,15,1,12.86,100,1,13.9,2,1,12.73,100,1,14.01,100,1,12.71,100,1,14.28,100,1,12.5,700,1,14.46,100,1,12.49,200,2,14.48,700,1,12.46,100,1,14.56,800,2,12.43,700,1,14.6,700,1,ARL,335220349
,2025-07-17T16:09:52.681844377Z,2025-07-17T16:09:52.681844377Z,10,2,1108,C,A,10,14.61,100,130,165561,279110066,13.11,100,1,13.67,15,1,13.01,2,1,13.68,100,1,12.98,200,2,13.7,15,1,12.86,100,1,13.9,2,1,12.73,100,1,14.01,100,1,12.71,100,1,14.28,100,1,12.5,700,1,14.46,100,1,12.49,200,2,14.48,700,1,12.46,100,1,14.56,800,2,12.43,700,1,14.6,700,1,ARL,334190189
,2025-07-17T16:09:52.681961200Z,2025-07-17T16:09:52.681961200Z,10,2,1108,A,A,7,14.47,100,130,166330,279110068,13.11,100,1,13.67,15,1,13.01,2,1,13.68,100,1,12.98,200,2,13.7,15,1,12.86,100,1,13.9,2,1,12.73,100,1,14.01,100,1,12.71,100,1,14.28,100,1,12.5,700,1,14.46,100,1,12.49,200,2,14.47,100,1,12.46,100,1,14.48,700,1,12.43,700,1,14.56,800,2,ARL,335220561
,2025-07-17T16:10:04.521306513Z,2025-07-17T16:10:04.521306513Z,10,2,1108,C,A,0,13.67,15,130,165291,279306715,13.11,100,1,13.68,100,1,13.01,2,1,13.7,15,1,12.98,200,2,13.9,2,1,12.86,100,1,14.01,100,1,12.73,100,1,14.28,100,1,12.71,100,1,14.46,100,1,12.5,700,1,14.47,100,1,12.49,200,2,14.48,700,1,12.46,100,1,14.56,800,2,12.43,700,1,14.6,700,1,ARL,335178437
,2025-07-17T16:10:04.561688313Z,2025-07-17T16:10:04.561688313Z,10,2,1108,C,A,1,13.7,15,128,166543,279312083,13.11,100,1,13.68,100,1,13.01,2,1,13.9,2,1,12.98,200,2,14.01,100,1,12.86,100,1,14.28,100,1,12.73,100,1,14.46,100,1,12.71,100,1,14.47,100,1,12.5,700,1,14.48,700,1,12.49,200,2,14.56,800,2,12.46,100,1,14.6,700,1,12.43,700,1,14.62,200,2,ARL,335003269
,2025-07-17T16:10:32.822495087Z,2025-07-17T16:10:32.822495087Z,10,2,1108,A,A,0,13.65,15,130,165411,279705339,13.11,100,1,13.65,15,1,13.01,2,1,13.68,100,1,12.98,200,2,13.9,2,1,12.86,100,1,14.01,100,1,12.73,100,1,14.28,100,1,12.71,100,1,14.46,100,1,12.5,700,1,14.47,100,1,12.49,200,2,14.48,700,1,12.46,100,1,14.56,800,2,12.43,700,1,14.6,700,1,ARL,335996705
,2025-07-17T16:10:32.822757517Z,2025-07-17T16:10:32.822757517Z,10,2,1108,C,A,1,13.68,100,0,165621,279705347,13.11,100,1,13.65,15,1,13.01,2,1,13.9,2,1,12.98,200,2,14.01,100,1,12.86,100,1,14.28,100,1,12.73,100,1,14.46,100,1,12.71,100,1,14.47,100,1,12.5,700,1,14.48,700,1,12.49,200,2,14.56,800,2,12.46,100,1,14.6,700,1,12.43,700,1,14.62,200,2,ARL,335220349
,2025-07-17T16:10:32.822757517Z,2025-07-17T16:10:32.822757517Z,10,2,1108,A,A,1,13.66,100,130,165621,279705347,13.11,100,1,13.65,15,1,13.01,2,1,13.66,100,1,12.98,200,2,13.9,2,1,12.86,100,1,14.01,100,1,12.73,100,1,14.28,100,1,12.71,100,1,14.46,100,1,12.5,700,1,14.47,100,1,12.49,200,2,14.48,700,1,12.46,100,1,14.56,800,2,12.43,700,1,14.6,700,1,ARL,335996709
,2025-07-17T16:10:32.830032662Z,2025-07-17T16:10:32.830032662Z,10,2,1108,C,A,3,14.01,100,130,168182,279705485,13.11,100,1,13.65,15,1,13.01,2,1,13.66,100,1,12.98,200,2,13.9,2,1,12.86,100,1,14.28,100,1,12.73,100,1,14.46,100,1,12.71,100,1,14.47,100,1,12.5,700,1,14.48,700,1,12.49,200,2,14.56,800,2,12.46,100,1,14.6,700,1,12.43,700,1,14.62,200,2,ARL,334593753
,2025-07-17T16:10:32.830085472Z,2025-07-17T16:10:32.830085472Z,10,2,1108,A,A,3,13.93,100,130,165248,279705486,13.11,100,1,13.65,15,1,13.01,2,1,13.66,100,1,12.98,200,2,13.9,2,1,12.86,100,1,13.93,100,1,12.73,100,1,14.28,100,1,12.71,100,1,14.46,100,1,12.5,700,1,14.47,100,1,12.49,200,2,14.48,700,1,12.46,100,1,14.56,800,2,12.43,700,1,14.6,700,1,ARL,335996777
,2025-07-17T16:10:42.822189504Z,2025-07-17T16:10:42.822189504Z,10,2,1108,A,A,0,13.63,15,130,165365,279834760,13.11,100,1,13.63,15,1,13.01,2,1,13.65,15,1,12.98,200,2,13.66,100,1,12.86,100,1,13.9,2,1,12.73,100,1,13.93,100,1,12.71,100,1,14.28,100,1,12.5,700,1,14.46,100,1,12.49,200,2,14.47,100,1,12.46,100,1,14.48,700,1,12.43,700,1,14.56,800,2,ARL,336161333
,2025-07-17T16:10:42.822258887Z,2025-07-17T16:10:42.822258887Z,10,2,1108,C,A,2,13.66,100,0,165776,279834761,13.11,100,1,13.63,15,1,13.01,2,1,13.65,15,1,12.98,200,2,13.9,2,1,12.86,100,1,13.93,100,1,12.73,100,1,14.28,100,1,12.71,100,1,14.46,100,1,12.5,700,1,14.47,100,1,12.49,200,2,14.48,700,1,12.46,100,1,14.56,800,2,12.43,700,1,14.6,700,1,ARL,335996709
,2025-07-17T16:10:42.822258887Z,2025-07-17T16:10:42.822258887Z,10,2,1108,A,A,1,13.64,100,130,165776,279834761,13.11,100,1,13.63,15,1,13.01,2,1,13.64,100,1,12.98,200,2,13.65,15,1,12.86,100,1,13.9,2,1,12.73,100,1,13.93,100,1,12.71,100,1,14.28,100,1,12.5,700,1,14.46,100,1,12.49,200,2,14.47,100,1,12.46,100,1,14.48,700,1,12.43,700,1,14.56,800,2,ARL,336161337
,2025-07-17T16:10:42.822998664Z,2025-07-17T16:10:42.822998664Z,10,2,1108,C,A,6,14.46,100,130,165265,279834765,13.11,100,1,13.63,15,1,13.01,2,1,13.64,100,1,12.98,200,2,13.65,15,1,12.86,100,1,13.9,2,1,12.73,100,1,13.93,100,1,12.71,100,1,14.28,100,1,12.5,700,1,14.47,100,1,12.49,200,2,14.48,700,1,12.46,100,1,14.56,800,2,12.43,700,1,14.6,700,1,ARL,331927161
,2025-07-17T16:10:42.823352130Z,2025-07-17T16:10:42.823352130Z,10,2,1108,A,A,5,14.25,100,130,165314,279834767,13.11,100,1,13.63,15,1,13.01,2,1,13.64,100,1,12.98,200,2,13.65,15,1,12.86,100,1,13.9,2,1,12.73,100,1,13.93,100,1,12.71,100,1,14.25,100,1,12.5,700,1,14.28,100,1,12.49,200,2,14.47,100,1,12.46,100,1,14.48,700,1,12.43,700,1,14.56,800,2,ARL,336161365
,2025-07-17T16:10:46.533890361Z,2025-07-17T16:10:46.533890361Z,10,2,1108,A,A,9,14.51,100,130,165581,279921726,13.11,100,1,13.63,15,1,13.01,2,1,13.64,100,1,12.98,200,2,13.65,15,1,12.86,100,1,13.9,2,1,12.73,100,1,13.93,100,1,12.71,100,1,14.25,100,1,12.5,700,1,14.28,100,1,12.49,200,2,14.47,100,1,12.46,100,1,14.48,700,1,12.43,700,1,14.51,100,1,ARL,336259225
,2025-07-17T16:10:46.537992315Z,2025-07-17T16:10:46.537992315Z,10,2,1108,C,A,2,13.65,15,128,166559,279921911,13.11,100,1,13.63,15,1,13.01,2,1,13.64,100,1,12.98,200,2,13.9,2,1,12.86,100,1,13.93,100,1,12.73,100,1,14.25,100,1,12.71,100,1,14.28,100,1,12.5,700,1,14.47,100,1,12.49,200,2,14.48,700,1,12.46,100,1,14.51,100,1,12.43,700,1,14.56,800,2,ARL,335996705
,2025-07-17T16:10:46.561080616Z,2025-07-17T16:10:46.561080616Z,10,2,1108,A,A,8,14.51,100,130,165414,279924883,13.11,100,1,13.63,15,1,13.01,2,1,13.64,100,1,12.98,200,2,13.9,2,1,12.86,100,1,13.93,100,1,12.73,100,1,14.25,100,1,12.71,100,1,14.28,100,1,12.5,700,1,14.47,100,1,12.49,200,2,14.48,700,1,12.46,100,1,14.51,200,2,12.43,700,1,14.56,800,2,ARL,336261905
,2025-07-17T16:10:47.543238729Z,2025-07-17T16:10:47.543238729Z,10,2,1108,A,A,0,13.61,15,130,165272,279938097,13.11,100,1,13.61,15,1,13.01,2,1,13.63,15,1,12.98,200,2,13.64,100,1,12.86,100,1,13.9,2,1,12.73,100,1,13.93,100,1,12.71,100,1,14.25,100,1,12.5,700,1,14.28,100,1,12.49,200,2,14.47,100,1,12.46,100,1,14.48,700,1,12.43,700,1,14.51,200,2,ARL,336278197
,2025-07-17T16:10:48.657290980Z,2025-07-17T16:10:48.657290980Z,10,2,1108,C,A,2,13.64,100,0,165415,279952266,13.11,100,1,13.61,15,1,13.01,2,1,13.63,15,1,12.98,200,2,13.9,2,1,12.86,100,1,13.93,100,1,12.73,100,1,14.25,100,1,12.71,100,1,14.28,100,1,12.5,700,1,14.47,100,1,12.49,200,2,14.48,700,1,12.46,100,1,14.51,200,2,12.43,700,1,14.56,800,2,ARL,336161337
,2025-07-17T16:10:48.657290980Z,2025-07-17T16:10:48.657290980Z,10,2,1108,A,A,1,13.62,100,130,165415,279952266,13.11,100,1,13.61,15,1,13.01,2,1,13.62,100,1,12.98,200,2,13.63,15,1,12.86,100,1,13.9,2,1,12.73,100,1,13.93,100,1,12.71,100,1,14.25,100,1,12.5,700,1,14.28,100,1,12.49,200,2,14.47,100,1,12.46,100,1,14.48,700,1,12.43,700,1,14.51,200,2,ARL,336295769
,2025-07-17T16:10:51.058878264Z,2025-07-17T16:10:51.058878264Z,10,2,1108,C,A,0,13.61,15,128,166028,280001840,13.11,100,1,13.62,100,1,13.01,2,1,13.63,15,1,12.98,200,2,13.9,2,1,12.86,100,1,13.93,100,1,12.73,100,1,14.25,100,1,12.71,100,1,14.28,100,1,12.5,700,1,14.47,100,1,12.49,200,2,14.48,700,1,12.46,100,1,14.51,200,2,12.43,700,1,14.56,800,2,ARL,336278197
,2025-07-17T16:10:51.059016199Z,2025-07-17T16:10:51.059016199Z,10,2,1108,C,A,1,13.63,15,128,167724,280001873,13.11,100,1,13.62,100,1,13.01,2,1,13.9,2,1,12.98,200,2,13.93,100,1,12.86,100,1,14.25,100,1,12.73,100,1,14.28,100,1,12.71,100,1,14.47,100,1,12.5,700,1,14.48,700,1,12.49,200,2,14.51,200,2,12.46,100,1,14.56,800,2,12.43,700,1,14.6,700,1,ARL,336161333
,2025-07-17T16:10:51.059443298Z,2025-07-17T16:10:51.059443298Z,10,2,1108,C,A,0,13.62,100,130,165455,280001952,13.11,100,1,13.9,2,1,13.01,2,1,13.93,100,1,12.98,200,2,14.25,100,1,12.86,100,1,14.28,100,1,12.73,100,1,14.47,100,1,12.71,100,1,14.48,700,1,12.5,700,1,14.51,200,2,12.49,200,2,14.56,800,2,12.46,100,1,14.6,700,1,12.43,700,1,14.64,200,2,ARL,336295769
,2025-07-17T16:10:51.170545251Z,2025-07-17T16:10:51.170545251Z,10,2,1108,A,A,1,13.91,100,130,165358,280003702,13.11,100,1,13.9,2,1,13.01,2,1,13.91,100,1,12.98,200,2,13.93,100,1,12.86,100,1,14.25,100,1,12.73,100,1,14.28,100,1,12.71,100,1,14.47,100,1,12.5,700,1,14.48,700,1,12.49,200,2,14.51,200,2,12.46,100,1,14.56,800,2,12.43,700,1,14.6,700,1,ARL,336351081
,2025-07-17T16:10:52.958288317Z,2025-07-17T16:10:52.958288317Z,10,2,1108,A,A,0,13.6,15,130,165324,280050139,13.11,100,1,13.6,15,1,13.01,2,1,13.9,2,1,12.98,200,2,13.91,100,1,12.86,100,1,13.93,100,1,12.73,100,1,14.25,100,1,12.71,100,1,14.28,100,1,12.5,700,1,14.47,100,1,12.49,200,2,14.48,700,1,12.46,100,1,14.51,200,2,12.43,700,1,14.56,800,2,ARL,336402845
,2025-07-17T16:10:53.101871639Z,2025-07-17T16:10:53.101871639Z,10,2,1108,C,A,2,13.91,100,0,165534,280057228,13.11,100,1,13.6,15,1,13.01,2,1,13.9,2,1,12.98,200,2,13.93,100,1,12.86,100,1,14.25,100,1,12.73,100,1,14.28,100,1,12.71,100,1,14.47,100,1,12.5,700,1,14.48,700,1,12.49,200,2,14.51,200,2,12.46,100,1,14.56,800,2,12.43,700,1,14.6,700,1,ARL,336351081
,2025-07-17T16:10:53.101871639Z,2025-07-17T16:10:53.101871639Z,10,2,1108,A,A,1,13.61,100,130,165534,280057228,13.11,100,1,13.6,15,1,13.01,2,1,13.61,100,1,12.98,200,2,13.9,2,1,12.86,100,1,13.93,100,1,12.73,100,1,14.25,100,1,12.71,100,1,14.28,100,1,12.5,700,1,14.47,100,1,12.49,200,2,14.48,700,1,12.46,100,1,14.51,200,2,12.43,700,1,14.56,800,2,ARL,336410125
,2025-07-17T16:10:54.959141873Z,2025-07-17T16:10:54.959141873Z,10,2,1108,C,A,2,13.9,2,0,165719,280084546,13.11,100,1,13.6,15,1,13.01,2,1,13.61,100,1,12.98,200,2,13.93,100,1,12.86,100,1,14.25,100,1,12.73,100,1,14.28,100,1,12.71,100,1,14.47,100,1,12.5,700,1,14.48,700,1,12.49,200,2,14.51,200,2,12.46,100,1,14.56,800,2,12.43,700,1,14.6,700,1,ARL,334804177
,2025-07-17T16:10:54.959141873Z,2025-07-17T16:10:54.959141873Z,10,2,1108,A,A,2,13.82,2,130,165719,280084546,13.11,100,1,13.6,15,1,13.01,2,1,13.61,100,1,12.98,200,2,13.82,2,1,12.86,100,1,13.93,100,1,12.73,100,1,14.25,100,1,12.71,100,1,14.28,100,1,12.5,700,1,14.47,100,1,12.49,200,2,14.48,700,1,12.46,100,1,14.51,200,2,12.43,700,1,14.56,800,2,ARL,336447325
,2025-07-17T16:10:59.517870358Z,2025-07-17T16:10:59.517870358Z,10,2,1108,A,A,0,13.58,15,130,165447,280173685,13.11,100,1,13.58,15,1,13.01,2,1,13.6,15,1,12.98,200,2,13.61,100,1,12.86,100,1,13.82,2,1,12.73,100,1,13.93,100,1,12.71,100,1,14.25,100,1,12.5,700,1,14.28,100,1,12.49,200,2,14.47,100,1,12.46,100,1,14.48,700,1,12.43,700,1,14.51,200,2,ARL,336555153
,2025-07-17T16:11:00.215719725Z,2025-07-17T16:11:00.215719725Z,10,2,1108,C,A,2,13.61,100,0,165569,280184406,13.11,100,1,13.58,15,1,13.01,2,1,13.6,15,1,12.98,200,2,13.82,2,1,12.86,100,1,13.93,100,1,12.73,100,1,14.25,100,1,12.71,100,1,14.28,100,1,12.5,700,1,14.47,100,1,12.49,200,2,14.48,700,1,12.46,100,1,14.51,200,2,12.43,700,1,14.56,800,2,ARL,336410125
,2025-07-17T16:11:00.215719725Z,2025-07-17T16:11:00.215719725Z,10,2,1108,A,A,1,13.59,100,130,165569,280184406,13.11,100,1,13.58,15,1,13.01,2,1,13.59,100,1,12.98,200,2,13.6,15,1,12.86,100,1,13.82,2,1,12.73,100,1,13.93,100,1,12.71,100,1,14.25,100,1,12.5,700,1,14.28,100,1,12.49,200,2,14.47,100,1,12.46,100,1,14.48,700,1,12.43,700,1,14.51,200,2,ARL,336567189
,2025-07-17T16:11:00.228833925Z,2025-07-17T16:11:00.228833925Z,10,2,1108,C,A,4,13.93,100,130,165452,280184613,13.11,100,1,13.58,15,1,13.01,2,1,13.59,100,1,12.98,200,2,13.6,15,1,12.86,100,1,13.82,2,1,12.73,100,1,14.25,100,1,12.71,100,1,14.28,100,1,12.5,700,1,14.47,100,1,12.49,200,2,14.48,700,1,12.46,100,1,14.51,200,2,12.43,700,1,14.56,800,2,ARL,335996777
,2025-07-17T16:11:00.228885790Z,2025-07-17T16:11:00.228885790Z,10,2,1108,A,A,4,13.86,100,130,165334,280184614,13.11,100,1,13.58,15,1,13.01,2,1,13.59,100,1,12.98,200,2,13.6,15,1,12.86,100,1,13.82,2,1,12.73,100,1,13.86,100,1,12.71,100,1,14.25,100,1,12.5,700,1,14.28,100,1,12.49,200,2,14.47,100,1,12.46,100,1,14.48,700,1,12.43,700,1,14.51,200,2,ARL,336567333
,2025-07-17T16:11:00.366645846Z,2025-07-17T16:11:00.366645846Z,10,2,1108,A,A,3,13.62,1,130,165695,280189435,13.11,100,1,13.58,15,1,13.01,2,1,13.59,100,1,12.98,200,2,13.6,15,1,12.86,100,1,13.62,1,1,12.73,100,1,13.82,2,1,12.71,100,1,13.86,100,1,12.5,700,1,14.25,100,1,12.49,200,2,14.28,100,1,12.46,100,1,14.47,100,1,12.43,700,1,14.48,700,1,ARL,336572049
,2025-07-17T16:11:00.367209243Z,2025-07-17T16:11:00.367209243Z,10,2,1108,C,B,7,12.49,100,0,165530,280189439,13.11,100,1,13.58,15,1,13.01,2,1,13.59,100,1,12.98,200,2,13.6,15,1,12.86,100,1,13.62,1,1,12.73,100,1,13.82,2,1,12.71,100,1,13.86,100,1,12.5,700,1,14.25,100,1,12.49,100,1,14.28,100,1,12.46,100,1,14.47,100,1,12.43,700,1,14.48,700,1,ARL,331942945
,2025-07-17T16:11:00.367319059Z,2025-07-17T16:11:00.367319059Z,10,2,1108,C,B,7,12.49,100,0,166035,280189441,13.11,100,1,13.58,15,1,13.01,2,1,13.59,100,1,12.98,200,2,13.6,15,1,12.86,100,1,13.62,1,1,12.73,100,1,13.82,2,1,12.71,100,1,13.86,100,1,12.5,700,1,14.25,100,1,12.46,100,1,14.28,100,1,12.43,700,1,14.47,100,1,12.42,700,1,14.48,700,1,ARL,331942901
,2025-07-17T16:11:00.466703632Z,2025-07-17T16:11:00.466703632Z,10,2,1108,C,A,3,13.62,1,130,164992,280191783,13.11,100,1,13.58,15,1,13.01,2,1,13.59,100,1,12.98,200,2,13.6,15,1,12.86,100,1,13.82,2,1,12.73,100,1,13.86,100,1,12.71,100,1,14.25,100,1,12.5,700,1,14.28,100,1,12.46,100,1,14.47,100,1,12.43,700,1,14.48,700,1,12.42,700,1,14.51,200,2,ARL,336572049
,2025-07-17T16:11:06.626666474Z,2025-07-17T16:11:06.626666474Z,10,2,1108,A,A,6,14.27,700,130,165325,280342316,13.11,100,1,13.58,15,1,13.01,2,1,13.59,100,1,12.98,200,2,13.6,15,1,12.86,100,1,13.82,2,1,12.73,100,1,13.86,100,1,12.71,100,1,14.25,100,1,12.5,700,1,14.27,700,1,12.46,100,1,14.28,100,1,12.43,700,1,14.47,100,1,12.42,700,1,14.48,700,1,ARL,336747457
,2025-07-17T16:11:08.307868957Z,2025-07-17T16:11:08.307868957Z,10,2,1108,C,A,2,13.6,15,130,165581,280374785,13.11,100,1,13.58,15,1,13.01,2,1,13.59,100,1,12.98,200,2,13.82,2,1,12.86,100,1,13.86,100,1,12.73,100,1,14.25,100,1,12.71,100,1,14.27,700,1,12.5,700,1,14.28,100,1,12.46,100,1,14.47,100,1,12.43,700,1,14.48,700,1,12.42,700,1,14.51,200,2,ARL,336402845
,2025-07-17T16:11:09.568370995Z,2025-07-17T16:11:09.568370995Z,10,2,1108,A,A,0,13.56,15,130,165297,280401189,13.11,100,1,13.56,15,1,13.01,2,1,13.58,15,1,12.98,200,2,13.59,100,1,12.86,100,1,13.82,2,1,12.73,100,1,13.86,100,1,12.71,100,1,14.25,100,1,12.5,700,1,14.27,700,1,12.46,100,1,14.28,100,1,12.43,700,1,14.47,100,1,12.42,700,1,14.48,700,1,ARL,336816813
,2025-07-17T16:11:10.341788521Z,2025-07-17T16:11:10.341788521Z,10,2,1108,C,A,2,13.59,100,0,165450,280411396,13.11,100,1,13.56,15,1,13.01,2,1,13.58,15,1,12.98,200,2,13.82,2,1,12.86,100,1,13.86,100,1,12.73,100,1,14.25,100,1,12.71,100,1,14.27,700,1,12.5,700,1,14.28,100,1,12.46,100,1,14.47,100,1,12.43,700,1,14.48,700,1,12.42,700,1,14.51,200,2,ARL,336567189
,2025-07-17T16:11:10.341788521Z,2025-07-17T16:11:10.341788521Z,10,2,1108,A,A,1,13.57,100,130,165450,280411396,13.11,100,1,13.56,15,1,13.01,2,1,13.57,100,1,12.98,200,2,13.58,15,1,12.86,100,1,13.82,2,1,12.73,100,1,13.86,100,1,12.71,100,1,14.25,100,1,12.5,700,1,14.27,700,1,12.46,100,1,14.28,100,1,12.43,700,1,14.47,100,1,12.42,700,1,14.48,700,1,ARL,336828765
,2025-07-17T16:11:14.610535763Z,2025-07-17T16:11:14.610535763Z,10,2,1108,C,A,2,13.58,15,130,165687,280482371,13.11,100,1,13.56,15,1,13.01,2,1,13.57,100,1,12.98,200,2,13.82,2,1,12.86,100,1,13.86,100,1,12.73,100,1,14.25,100,1,12.71,100,1,14.27,700,1,12.5,700,1,14.28,100,1,12.46,100,1,14.47,100,1,12.43,700,1,14.48,700,1,12.42,700,1,14.51,200,2,ARL,336555153
,2025-07-17T16:11:16.025292936Z,2025-07-17T16:11:16.025292936Z,10,2,1108,C,A,0,13.56,15,130,165295,280514282,13.11,100,1,13.57,100,1,13.01,2,1,13.82,2,1,12.98,200,2,13.86,100,1,12.86,100,1,14.25,100,1,12.73,100,1,14.27,700,1,12.71,100,1,14.28,100,1,12.5,700,1,14.47,100,1,12.46,100,1,14.48,700,1,12.43,700,1,14.51,200,2,12.42,700,1,14.56,800,2,ARL,336816813
,2025-07-17T16:11:50.026672014Z,2025-07-17T16:11:50.026672014Z,10,2,1108,A,A,0,13.55,15,130,165344,281078802,13.11,100,1,13.55,15,1,13.01,2,1,13.57,100,1,12.98,200,2,13.82,2,1,12.86,100,1,13.86,100,1,12.73,100,1,14.25,100,1,12.71,100,1,14.27,700,1,12.5,700,1,14.28,100,1,12.46,100,1,14.47,100,1,12.43,700,1,14.48,700,1,12.42,700,1,14.51,200,2,ARL,337690189
,2025-07-17T16:11:50.026839463Z,2025-07-17T16:11:50.026839463Z,10,2,1108,C,A,1,13.57,100,0,165514,281078803,13.11,100,1,13.55,15,1,13.01,2,1,13.82,2,1,12.98,200,2,13.86,100,1,12.86,100,1,14.25,100,1,12.73,100,1,14.27,700,1,12.71,100,1,14.28,100,1,12.5,700,1,14.47,100,1,12.46,100,1,14.48,700,1,12.43,700,1,14.51,200,2,12.42,700,1,14.56,800,2,ARL,336828765
,2025-07-17T16:11:50.026839463Z,2025-07-17T16:11:50.026839463Z,10,2,1108,A,A,1,13.56,100,130,165514,281078803,13.11,100,1,13.55,15,1,13.01,2,1,13.56,100,1,12.98,200,2,13.82,2,1,12.86,100,1,13.86,100,1,12.73,100,1,14.25,100,1,12.71,100,1,14.27,700,1,12.5,700,1,14.28,100,1,12.46,100,1,14.47,100,1,12.43,700,1,14.48,700,1,12.42,700,1,14.51,200,2,ARL,337690193
,2025-07-17T16:11:53.859743991Z,2025-07-17T16:11:53.859743991Z,10,2,1108,A,A,0,13.53,15,130,165471,281142794,13.11,100,1,13.53,15,1,13.01,2,1,13.55,15,1,12.98,200,2,13.56,100,1,12.86,100,1,13.82,2,1,12.73,100,1,13.86,100,1,12.71,100,1,14.25,100,1,12.5,700,1,14.27,700,1,12.46,100,1,14.28,100,1,12.43,700,1,14.47,100,1,12.42,700,1,14.48,700,1,ARL,337772837
,2025-07-17T16:11:54.662361841Z,2025-07-17T16:11:54.662361841Z,10,2,1108,C,A,2,13.56,100,0,165491,281156215,13.11,100,1,13.53,15,1,13.01,2,1,13.55,15,1,12.98,200,2,13.82,2,1,12.86,100,1,13.86,100,1,12.73,100,1,14.25,100,1,12.71,100,1,14.27,700,1,12.5,700,1,14.28,100,1,12.46,100,1,14.47,100,1,12.43,700,1,14.48,700,1,12.42,700,1,14.51,200,2,ARL,337690193
,2025-07-17T16:11:54.662361841Z,2025-07-17T16:11:54.662361841Z,10,2,1108,A,A,1,13.54,100,130,165491,281156215,13.11,100,1,13.53,15,1,13.01,2,1,13.54,100,1,12.98,200,2,13.55,15,1,12.86,100,1,13.82,2,1,12.73,100,1,13.86,100,1,12.71,100,1,14.25,100,1,12.5,700,1,14.27,700,1,12.46,100,1,14.28,100,1,12.43,700,1,14.47,100,1,12.42,700,1,14.48,700,1,ARL,337790717
,2025-07-17T16:11:54.663968656Z,2025-07-17T16:11:54.663968656Z,10,2,1108,A,A,10,14.49,100,130,165370,281156223,13.11,100,1,13.53,15,1,13.01,2,1,13.54,100,1,12.98,200,2,13.55,15,1,12.86,100,1,13.82,2,1,12.73,100,1,13.86,100,1,12.71,100,1,14.25,100,1,12.5,700,1,14.27,700,1,12.46,100,1,14.28,100,1,12.43,700,1,14.47,100,1,12.42,700,1,14.48,700,1,ARL,337790745
,2025-07-17T16:11:54.666160990Z,2025-07-17T16:11:54.666160990Z,10,2,1108,C,A,8,14.47,100,0,165610,281156243,13.11,100,1,13.53,15,1,13.01,2,1,13.54,100,1,12.98,200,2,13.55,15,1,12.86,100,1,13.82,2,1,12.73,100,1,13.86,100,1,12.71,100,1,14.25,100,1,12.5,700,1,14.27,700,1,12.46,100,1,14.28,100,1,12.43,700,1,14.48,700,1,12.42,700,1,14.49,100,1,ARL,335220561
,2025-07-17T16:11:54.666160990Z,2025-07-17T16:11:54.666160990Z,10,2,1108,A,A,8,14.33,100,130,165610,281156243,13.11,100,1,13.53,15,1,13.01,2,1,13.54,100,1,12.98,200,2,13.55,15,1,12.86,100,1,13.82,2,1,12.73,100,1,13.86,100,1,12.71,100,1,14.25,100,1,12.5,700,1,14.27,700,1,12.46,100,1,14.28,100,1,12.43,700,1,14.33,100,1,12.42,700,1,14.48,700,1,ARL,337790761
,2025-07-17T16:11:54.667339002Z,2025-07-17T16:11:54.667339002Z,10,2,1108,A,A,10,14.49,100,130,165544,281156250,13.11,100,1,13.53,15,1,13.01,2,1,13.54,100,1,12.98,200,2,13.55,15,1,12.86,100,1,13.82,2,1,12.73,100,1,13.86,100,1,12.71,100,1,14.25,100,1,12.5,700,1,14.27,700,1,12.46,100,1,14.28,100,1,12.43,700,1,14.33,100,1,12.42,700,1,14.48,700,1,ARL,337790777
,2025-07-17T16:11:59.382350338Z,2025-07-17T16:11:59.382350338Z,10,2,1108,C,A,2,13.55,15,130,165340,281270010,13.11,100,1,13.53,15,1,13.01,2,1,13.54,100,1,12.98,200,2,13.82,2,1,12.86,100,1,13.86,100,1,12.73,100,1,14.25,100,1,12.71,100,1,14.27,700,1,12.5,700,1,14.28,100,1,12.46,100,1,14.33,100,1,12.43,700,1,14.48,700,1,12.42,700,1,14.49,200,2,ARL,337690189
,2025-07-17T16:12:02.981913204Z,2025-07-17T16:12:02.981913204Z,10,2,1108,A,A,0,13.51,15,130,165515,281348152,13.11,100,1,13.51,15,1,13.01,2,1,13.53,15,1,12.98,200,2,13.54,100,1,12.86,100,1,13.82,2,1,12.73,100,1,13.86,100,1,12.71,100,1,14.25,100,1,12.5,700,1,14.27,700,1,12.46,100,1,14.28,100,1,12.43,700,1,14.33,100,1,12.42,700,1,14.48,700,1,ARL,338041605
,2025-07-17T16:12:03.063997054Z,2025-07-17T16:12:03.063997054Z,10,2,1108,C,A,2,13.54,100,0,165551,281351122,13.11,100,1,13.51,15,1,13.01,2,1,13.53,15,1,12.98,200,2,13.82,2,1,12.86,100,1,13.86,100,1,12.73,100,1,14.25,100,1,12.71,100,1,14.27,700,1,12.5,700,1,14.28,100,1,12.46,100,1,14.33,100,1,12.43,700,1,14.48,700,1,12.42,700,1,14.49,200,2,ARL,337790717
,2025-07-17T16:12:03.063997054Z,2025-07-17T16:12:03.063997054Z,10,2,1108,A,A,1,13.52,100,130,165551,281351122,13.11,100,1,13.51,15,1,13.01,2,1,13.52,100,1,12.98,200,2,13.53,15,1,12.86,100,1,13.82,2,1,12.73,100,1,13.86,100,1,12.71,100,1,14.25,100,1,12.5,700,1,14.27,700,1,12.46,100,1,14.28,100,1,12.43,700,1,14.33,100,1,12.42,700,1,14.48,700,1,ARL,338044041
,2025-07-17T16:12:03.068301745Z,2025-07-17T16:12:03.068301745Z,10,2,1108,C,B,1,13.01,2,0,165401,281351235,13.11,100,1,13.51,15,1,12.98,200,2,13.52,100,1,12.86,100,1,13.53,15,1,12.73,100,1,13.82,2,1,12.71,100,1,13.86,100,1,12.5,700,1,14.25,100,1,12.46,100,1,14.27,700,1,12.43,700,1,14.28,100,1,12.42,700,1,14.33,100,1,12.37,700,1,14.48,700,1,ARL,332494213
,2025-07-17T16:12:03.068301745Z,2025-07-17T16:12:03.068301745Z,10,2,1108,A,B,2,12.92,2,130,165401,281351235,13.11,100,1,13.51,15,1,12.98,200,2,13.52,100,1,12.92,2,1,13.53,15,1,12.86,100,1,13.82,2,1,12.73,100,1,13.86,100,1,12.71,100,1,14.25,100,1,12.5,700,1,14.27,700,1,12.46,100,1,14.28,100,1,12.43,700,1,14.33,100,1,12.42,700,1,14.48,700,1,ARL,338044113
,2025-07-17T16:12:03.075034550Z,2025-07-17T16:12:03.075034550Z,10,2,1108,C,A,4,13.86,100,130,165488,281351372,13.11,100,1,13.51,15,1,12.98,200,2,13.52,100,1,12.92,2,1,13.53,15,1,12.86,100,1,13.82,2,1,12.73,100,1,14.25,100,1,12.71,100,1,14.27,700,1,12.5,700,1,14.28,100,1,12.46,100,1,14.33,100,1,12.43,700,1,14.48,700,1,12.42,700,1,14.49,200,2,ARL,336567333
,2025-07-17T16:12:03.075095341Z,2025-07-17T16:12:03.075095341Z,10,2,1108,A,A,3,13.79,100,130,165188,281351373,13.11,100,1,13.51,15,1,12.98,200,2,13.52,100,1,12.92,2,1,13.53,15,1,12.86,100,1,13.79,100,1,12.73,100,1,13.82,2,1,12.71,100,1,14.25,100,1,12.5,700,1,14.27,700,1,12.46,100,1,14.28,100,1,12.43,700,1,14.33,100,1,12.42,700,1,14.48,700,1,ARL,338044233
,2025-07-17T16:12:06.775011783Z,2025-07-17T16:12:06.775011783Z,10,2,1108,A,A,9,14.4,100,130,165854,281422697,13.11,100,1,13.51,15,1,12.98,200,2,13.52,100,1,12.92,2,1,13.53,15,1,12.86,100,1,13.79,100,1,12.73,100,1,13.82,2,1,12.71,100,1,14.25,100,1,12.5,700,1,14.27,700,1,12.46,100,1,14.28,100,1,12.43,700,1,14.33,100,1,12.42,700,1,14.4,100,1,ARL,338139585
,2025-07-17T16:12:06.775449017Z,2025-07-17T16:12:06.775449017Z,10,2,1108,A,A,9,14.4,100,130,165519,281422702,13.11,100,1,13.51,15,1,12.98,200,2,13.52,100,1,12.92,2,1,13.53,15,1,12.86,100,1,13.79,100,1,12.73,100,1,13.82,2,1,12.71,100,1,14.25,100,1,12.5,700,1,14.27,700,1,12.46,100,1,14.28,100,1,12.43,700,1,14.33,100,1,12.42,700,1,14.4,200,2,ARL,338139601
,2025-07-17T16:12:06.779540143Z,2025-07-17T16:12:06.779540143Z,10,2,1108,C,A,2,13.53,15,130,165574,281422782,13.11,100,1,13.51,15,1,12.98,200,2,13.52,100,1,12.92,2,1,13.79,100,1,12.86,100,1,13.82,2,1,12.73,100,1,14.25,100,1,12.71,100,1,14.27,700,1,12.5,700,1,14.28,100,1,12.46,100,1,14.33,100,1,12.43,700,1,14.4,200,2,12.42,700,1,14.48,700,1,ARL,337772837
,2025-07-17T16:12:07.784533539Z,2025-07-17T16:12:07.784533539Z,10,2,1108,A,A,0,13.49,15,130,165354,281443568,13.11,100,1,13.49,15,1,12.98,200,2,13.51,15,1,12.92,2,1,13.52,100,1,12.86,100,1,13.79,100,1,12.73,100,1,13.82,2,1,12.71,100,1,14.25,100,1,12.5,700,1,14.27,700,1,12.46,100,1,14.28,100,1,12.43,700,1,14.33,100,1,12.42,700,1,14.4,200,2,ARL,338167057
,2025-07-17T16:12:08.585029039Z,2025-07-17T16:12:08.585029039Z,10,2,1108,C,A,2,13.52,100,0,165546,281451898,13.11,100,1,13.49,15,1,12.98,200,2,13.51,15,1,12.92,2,1,13.79,100,1,12.86,100,1,13.82,2,1,12.73,100,1,14.25,100,1,12.71,100,1,14.27,700,1,12.5,700,1,14.28,100,1,12.46,100,1,14.33,100,1,12.43,700,1,14.4,200,2,12.42,700,1,14.48,700,1,ARL,338044041
,2025-07-17T16:12:08.585029039Z,2025-07-17T16:12:08.585029039Z,10,2,1108,A,A,1,13.5,100,130,165546,281451898,13.11,100,1,13.49,15,1,12.98,200,2,13.5,100,1,12.92,2,1,13.51,15,1,12.86,100,1,13.79,100,1,12.73,100,1,13.82,2,1,12.71,100,1,14.25,100,1,12.5,700,1,14.27,700,1,12.46,100,1,14.28,100,1,12.43,700,1,14.33,100,1,12.42,700,1,14.4,200,2,ARL,338180793
,2025-07-17T16:12:18.789756367Z,2025-07-17T16:12:18.789756367Z,10,2,1108,C,A,4,13.82,2,0,165655,281613266,13.11,100,1,13.49,15,1,12.98,200,2,13.5,100,1,12.92,2,1,13.51,15,1,12.86,100,1,13.79,100,1,12.73,100,1,14.25,100,1,12.71,100,1,14.27,700,1,12.5,700,1,14.28,100,1,12.46,100,1,14.33,100,1,12.43,700,1,14.4,200,2,12.42,700,1,14.48,700,1,ARL,336447325
,2025-07-17T16:12:18.789756367Z,2025-07-17T16:12:18.789756367Z,10,2,1108,A,A,3,13.74,2,130,165655,281613266,13.11,100,1,13.49,15,1,12.98,200,2,13.5,100,1,12.92,2,1,13.51,15,1,12.86,100,1,13.74,2,1,12.73,100,1,13.79,100,1,12.71,100,1,14.25,100,1,12.5,700,1,14.27,700,1,12.46,100,1,14.28,100,1,12.43,700,1,14.33,100,1,12.42,700,1,14.4,200,2,ARL,338371797
,2025-07-17T16:12:19.370820933Z,2025-07-17T16:12:19.370820933Z,10,2,1108,A,A,6,14.27,700,130,165471,281622545,13.11,100,1,13.49,15,1,12.98,200,2,13.5,100,1,12.92,2,1,13.51,15,1,12.86,100,1,13.74,2,1,12.73,100,1,13.79,100,1,12.71,100,1,14.25,100,1,12.5,700,1,14.27,1400,2,12.46,100,1,14.28,100,1,12.43,700,1,14.33,100,1,12.42,700,1,14.4,200,2,ARL,338382329
,2025-07-17T16:12:19.696521343Z,2025-07-17T16:12:19.696521343Z,10,2,1108,C,A,0,13.49,15,128,168375,281630053,13.11,100,1,13.5,100,1,12.98,200,2,13.51,15,1,12.92,2,1,13.74,2,1,12.86,100,1,13.79,100,1,12.73,100,1,14.25,100,1,12.71,100,1,14.27,1400,2,12.5,700,1,14.28,100,1,12.46,100,1,14.33,100,1,12.43,700,1,14.4,200,2,12.42,700,1,14.48,700,1,ARL,338167057
,2025-07-17T16:12:19.711591494Z,2025-07-17T16:12:19.711591494Z,10,2,1108,C,A,1,13.51,15,128,181870,281634812,13.11,100,1,13.5,100,1,12.98,200,2,13.74,2,1,12.92,2,1,13.79,100,1,12.86,100,1,14.25,100,1,12.73,100,1,14.27,1400,2,12.71,100,1,14.28,100,1,12.5,700,1,14.33,100,1,12.46,100,1,14.4,200,2,12.43,700,1,14.48,700,1,12.42,700,1,14.49,200,2,ARL,338041605
,2025-07-17T16:12:32.761112078Z,2025-07-17T16:12:32.761112078Z,10,2,1108,A,A,0,13.48,15,130,165346,281880398,13.11,100,1,13.48,15,1,12.98,200,2,13.5,100,1,12.92,2,1,13.74,2,1,12.86,100,1,13.79,100,1,12.73,100,1,14.25,100,1,12.71,100,1,14.27,1400,2,12.5,700,1,14.28,100,1,12.46,100,1,14.33,100,1,12.43,700,1,14.4,200,2,12.42,700,1,14.48,700,1,ARL,338707945
,2025-07-17T16:12:32.761246859Z,2025-07-17T16:12:32.761246859Z,10,2,1108,C,A,1,13.5,100,0,166343,281880409,13.11,100,1,13.48,15,1,12.98,200,2,13.74,2,1,12.92,2,1,13.79,100,1,12.86,100,1,14.25,100,1,12.73,100,1,14.27,1400,2,12.71,100,1,14.28,100,1,12.5,700,1,14.33,100,1,12.46,100,1,14.4,200,2,12.43,700,1,14.48,700,1,12.42,700,1,14.49,200,2,ARL,338180793
,2025-07-17T16:12:32.761246859Z,2025-07-17T16:12:32.761246859Z,10,2,1108,A,A,1,13.49,100,130,166343,281880409,13.11,100,1,13.48,15,1,12.98,200,2,13.49,100,1,12.92,2,1,13.74,2,1,12.86,100,1,13.79,100,1,12.73,100,1,14.25,100,1,12.71,100,1,14.27,1400,2,12.5,700,1,14.28,100,1,12.46,100,1,14.33,100,1,12.43,700,1,14.4,200,2,12.42,700,1,14.48,700,1,ARL,338707949
,2025-07-17T16:12:40.992898990Z,2025-07-17T16:12:40.992898990Z,10,2,1108,C,A,1,13.49,100,130,165306,282007871,13.11,100,1,13.48,15,1,12.98,200,2,13.74,2,1,12.92,2,1,13.79,100,1,12.86,100,1,14.25,100,1,12.73,100,1,14.27,1400,2,12.71,100,1,14.28,100,1,12.5,700,1,14.33,100,1,12.46,100,1,14.4,200,2,12.43,700,1,14.48,700,1,12.42,700,1,14.49,200,2,ARL,338707949
,2025-07-17T16:12:40.993167418Z,2025-07-17T16:12:40.993167418Z,10,2,1108,C,A,4,14.27,700,130,165246,282007875,13.11,100,1,13.48,15,1,12.98,200,2,13.74,2,1,12.92,2,1,13.79,100,1,12.86,100,1,14.25,100,1,12.73,100,1,14.27,700,1,12.71,100,1,14.28,100,1,12.5,700,1,14.33,100,1,12.46,100,1,14.4,200,2,12.43,700,1,14.48,700,1,12.42,700,1,14.49,200,2,ARL,338382329
,2025-07-17T16:12:40.993168470Z,2025-07-17T16:12:40.993168470Z,10,2,1108,C,A,4,14.27,700,130,165320,282007876,13.11,100,1,13.48,15,1,12.98,200,2,13.74,2,1,12.92,2,1,13.79,100,1,12.86,100,1,14.25,100,1,12.73,100,1,14.28,100,1,12.71,100,1,14.33,100,1,12.5,700,1,14.4,200,2,12.46,100,1,14.48,700,1,12.43,700,1,14.49,200,2,12.42,700,1,14.55,100,1,ARL,336747457
,2025-07-17T16:12:40.993214193Z,2025-07-17T16:12:40.993214193Z,10,2,1108,A,A,9,14.54,700,130,165433,282007877,13.11,100,1,13.48,15,1,12.98,200,2,13.74,2,1,12.92,2,1,13.79,100,1,12.86,100,1,14.25,100,1,12.73,100,1,14.28,100,1,12.71,100,1,14.33,100,1,12.5,700,1,14.4,200,2,12.46,100,1,14.48,700,1,12.43,700,1,14.49,200,2,12.42,700,1,14.54,700,1,ARL,338864169
,2025-07-17T16:12:40.993227993Z,2025-07-17T16:12:40.993227993Z,10,2,1108,A,A,7,14.47,700,130,165447,282007878,13.11,100,1,13.48,15,1,12.98,200,2,13.74,2,1,12.92,2,1,13.79,100,1,12.86,100,1,14.25,100,1,12.73,100,1,14.28,100,1,12.71,100,1,14.33,100,1,12.5,700,1,14.4,200,2,12.46,100,1,14.47,700,1,12.43,700,1,14.48,700,1,12.42,700,1,14.49,200,2,ARL,338864173
,2025-07-17T16:12:40.994617858Z,2025-07-17T16:12:40.994617858Z,10,2,1108,C,A,9,14.49,100,0,165439,282007892,13.11,100,1,13.48,15,1,12.98,200,2,13.74,2,1,12.92,2,1,13.79,100,1,12.86,100,1,14.25,100,1,12.73,100,1,14.28,100,1,12.71,100,1,14.33,100,1,12.5,700,1,14.4,200,2,12.46,100,1,14.47,700,1,12.43,700,1,14.48,700,1,12.42,700,1,14.49,100,1,ARL,337790745
,2025-07-17T16:12:40.997135307Z,2025-07-17T16:12:40.997135307Z,10,2,1108,C,A,5,14.33,100,130,165393,282007914,13.11,100,1,13.48,15,1,12.98,200,2,13.74,2,1,12.92,2,1,13.79,100,1,12.86,100,1,14.25,100,1,12.73,100,1,14.28,100,1,12.71,100,1,14.4,200,2,12.5,700,1,14.47,700,1,12.46,100,1,14.48,700,1,12.43,700,1,14.49,100,1,12.42,700,1,14.54,700,1,ARL,337790761
,2025-07-17T16:12:41.004063876Z,2025-07-17T16:12:41.004063876Z,10,2,1108,C,A,8,14.49,100,0,165746,282007959,13.11,100,1,13.48,15,1,12.98,200,2,13.74,2,1,12.92,2,1,13.79,100,1,12.86,100,1,14.25,100,1,12.73,100,1,14.28,100,1,12.71,100,1,14.4,200,2,12.5,700,1,14.47,700,1,12.46,100,1,14.48,700,1,12.43,700,1,14.54,700,1,12.42,700,1,14.56,800,2,ARL,337790777
,2025-07-17T16:12:41.005406614Z,2025-07-17T16:12:41.005406614Z,10,2,1108,A,A,1,13.49,100,128,169439,282008256,13.11,100,1,13.48,15,1,12.98,200,2,13.49,100,1,12.92,2,1,13.74,2,1,12.86,100,1,13.79,100,1,12.73,100,1,14.25,100,1,12.71,100,1,14.28,100,1,12.5,700,1,14.4,200,2,12.46,100,1,14.47,700,1,12.43,700,1,14.48,700,1,12.42,700,1,14.54,700,1,ARL,338864581
,2025-07-17T16:12:41.010473041Z,2025-07-17T16:12:41.010473041Z,10,2,1108,A,A,7,14.44,100,130,165310,282008884,13.11,100,1,13.48,15,1,12.98,200,2,13.49,100,1,12.92,2,1,13.74,2,1,12.86,100,1,13.79,100,1,12.73,100,1,14.25,100,1,12.71,100,1,14.28,100,1,12.5,700,1,14.4,200,2,12.46,100,1,14.44,100,1,12.43,700,1,14.47,700,1,12.42,700,1,14.48,700,1,ARL,338865133
,2025-07-17T16:12:41.010994859Z,2025-07-17T16:12:41.010994859Z,10,2,1108,C,A,3,13.79,100,130,165482,282008914,13.11,100,1,13.48,15,1,12.98,200,2,13.49,100,1,12.92,2,1,13.74,2,1,12.86,100,1,14.25,100,1,12.73,100,1,14.28,100,1,12.71,100,1,14.4,200,2,12.5,700,1,14.44,100,1,12.46,100,1,14.47,700,1,12.43,700,1,14.48,700,1,12.42,700,1,14.54,700,1,ARL,338044233
,2025-07-17T16:12:41.011046717Z,2025-07-17T16:12:41.011046717Z,10,2,1108,A,A,3,14.06,100,130,165269,282008916,13.11,100,1,13.48,15,1,12.98,200,2,13.49,100,1,12.92,2,1,13.74,2,1,12.86,100,1,14.06,100,1,12.73,100,1,14.25,100,1,12.71,100,1,14.28,100,1,12.5,700,1,14.4,200,2,12.46,100,1,14.44,100,1,12.43,700,1,14.47,700,1,12.42,700,1,14.48,700,1,ARL,338865141
,2025-07-17T16:12:41.011390077Z,2025-07-17T16:12:41.011390077Z,10,2,1108,A,A,7,14.44,100,130,165265,282008942,13.11,100,1,13.48,15,1,12.98,200,2,13.49,100,1,12.92,2,1,13.74,2,1,12.86,100,1,14.06,100,1,12.73,100,1,14.25,100,1,12.71,100,1,14.28,100,1,12.5,700,1,14.4,200,2,12.46,100,1,14.44,200,2,12.43,700,1,14.47,700,1,12.42,700,1,14.48,700,1,ARL,338865165
,2025-07-17T16:12:41.011879795Z,2025-07-17T16:12:41.011879795Z,10,2,1108,C,A,3,14.06,100,130,165124,282008953,13.11,100,1,13.48,15,1,12.98,200,2,13.49,100,1,12.92,2,1,13.74,2,1,12.86,100,1,14.25,100,1,12.73,100,1,14.28,100,1,12.71,100,1,14.4,200,2,12.5,700,1,14.44,200,2,12.46,100,1,14.47,700,1,12.43,700,1,14.48,700,1,12.42,700,1,14.54,700,1,ARL,338865141
,2025-07-17T16:12:41.011929033Z,2025-07-17T16:12:41.011929033Z,10,2,1108,A,A,3,13.76,100,130,165461,282008954,13.11,100,1,13.48,15,1,12.98,200,2,13.49,100,1,12.92,2,1,13.74,2,1,12.86,100,1,13.76,100,1,12.73,100,1,14.25,100,1,12.71,100,1,14.28,100,1,12.5,700,1,14.4,200,2,12.46,100,1,14.44,200,2,12.43,700,1,14.47,700,1,12.42,700,1,14.48,700,1,ARL,338865177
,2025-07-17T16:12:41.043241012Z,2025-07-17T16:12:41.043241012Z,10,2,1108,A,A,10,14.54,100,130,165371,282009482,13.11,100,1,13.48,15,1,12.98,200,2,13.49,100,1,12.92,2,1,13.74,2,1,12.86,100,1,13.76,100,1,12.73,100,1,14.25,100,1,12.71,100,1,14.28,100,1,12.5,700,1,14.4,200,2,12.46,100,1,14.44,200,2,12.43,700,1,14.47,700,1,12.42,700,1,14.48,700,1,ARL,338866245
,2025-07-17T16:12:42.001182016Z,2025-07-17T16:12:42.001182016Z,10,2,1108,A,A,5,14.28,100,130,165828,282033913,13.11,100,1,13.48,15,1,12.98,200,2,13.49,100,1,12.92,2,1,13.74,2,1,12.86,100,1,13.76,100,1,12.73,100,1,14.25,100,1,12.71,100,1,14.28,200,2,12.5,700,1,14.4,200,2,12.46,100,1,14.44,200,2,12.43,700,1,14.47,700,1,12.42,700,1,14.48,700,1,ARL,338894329
,2025-07-17T16:12:42.761989222Z,2025-07-17T16:12:42.761989222Z,10,2,1108,A,A,0,13.46,15,130,165247,282042242,13.11,100,1,13.46,15,1,12.98,200,2,13.48,15,1,12.92,2,1,13.49,100,1,12.86,100,1,13.74,2,1,12.73,100,1,13.76,100,1,12.71,100,1,14.25,100,1,12.5,700,1,14.28,200,2,12.46,100,1,14.4,200,2,12.43,700,1,14.44,200,2,12.42,700,1,14.47,700,1,ARL,338904977
,2025-07-17T16:12:43.021951997Z,2025-07-17T16:12:43.021951997Z,10,2,1108,C,A,2,13.49,100,0,175905,282057719,13.11,100,1,13.46,15,1,12.98,200,2,13.48,15,1,12.92,2,1,13.74,2,1,12.86,100,1,13.76,100,1,12.73,100,1,14.25,100,1,12.71,100,1,14.28,200,2,12.5,700,1,14.4,200,2,12.46,100,1,14.44,200,2,12.43,700,1,14.47,700,1,12.42,700,1,14.48,700,1,ARL,338864581
,2025-07-17T16:12:43.021951997Z,2025-07-17T16:12:43.021951997Z,10,2,1108,A,A,1,13.47,100,128,175905,282057719,13.11,100,1,13.46,15,1,12.98,200,2,13.47,100,1,12.92,2,1,13.48,15,1,12.86,100,1,13.74,2,1,12.73,100,1,13.76,100,1,12.71,100,1,14.25,100,1,12.5,700,1,14.28,200,2,12.46,100,1,14.4,200,2,12.43,700,1,14.44,200,2,12.42,700,1,14.47,700,1,ARL,338918217
,2025-07-17T16:12:43.154787212Z,2025-07-17T16:12:43.154787212Z,10,2,1108,A,A,6,14.27,100,130,165163,282073056,13.11,100,1,13.46,15,1,12.98,200,2,13.47,100,1,12.92,2,1,13.48,15,1,12.86,100,1,13.74,2,1,12.73,100,1,13.76,100,1,12.71,100,1,14.25,100,1,12.5,700,1,14.27,100,1,12.46,100,1,14.28,200,2,12.43,700,1,14.4,200,2,12.42,700,1,14.44,200,2,ARL,338932853
,2025-07-17T16:12:43.915387059Z,2025-07-17T16:12:43.915387059Z,10,2,1108,C,A,7,14.28,100,130,165467,282085822,13.11,100,1,13.46,15,1,12.98,200,2,13.47,100,1,12.92,2,1,13.48,15,1,12.86,100,1,13.74,2,1,12.73,100,1,13.76,100,1,12.71,100,1,14.25,100,1,12.5,700,1,14.27,100,1,12.46,100,1,14.28,100,1,12.43,700,1,14.4,200,2,12.42,700,1,14.44,200,2,ARL,302681357
,2025-07-17T16:12:43.915389642Z,2025-07-17T16:12:43.915389642Z,10,2,1108,A,A,5,14.0,100,130,165698,282085823,13.11,100,1,13.46,15,1,12.98,200,2,13.47,100,1,12.92,2,1,13.48,15,1,12.86,100,1,13.74,2,1,12.73,100,1,13.76,100,1,12.71,100,1,14.0,100,1,12.5,700,1,14.25,100,1,12.46,100,1,14.27,100,1,12.43,700,1,14.28,100,1,12.42,700,1,14.4,200,2,ARL,338945933
,2025-07-17T16:12:50.729079105Z,2025-07-17T16:12:50.729079105Z,10,2,1108,C,A,0,13.46,15,130,165344,282168721,13.11,100,1,13.47,100,1,12.98,200,2,13.48,15,1,12.92,2,1,13.74,2,1,12.86,100,1,13.76,100,1,12.73,100,1,14.0,100,1,12.71,100,1,14.25,100,1,12.5,700,1,14.27,100,1,12.46,100,1,14.28,100,1,12.43,700,1,14.4,200,2,12.42,700,1,14.44,200,2,ARL,338904977
,2025-07-17T16:12:50.729252907Z,2025-07-17T16:12:50.729252907Z,10,2,1108,C,A,1,13.48,15,130,165330,282168744,13.11,100,1,13.47,100,1,12.98,200,2,13.74,2,1,12.92,2,1,13.76,100,1,12.86,100,1,14.0,100,1,12.73,100,1,14.25,100,1,12.71,100,1,14.27,100,1,12.5,700,1,14.28,100,1,12.46,100,1,14.4,200,2,12.43,700,1,14.44,200,2,12.42,700,1,14.47,700,1,ARL,338707945
,2025-07-17T16:12:50.729409745Z,2025-07-17T16:12:50.729409745Z,10,2,1108,A,A,0,13.47,96,130,165996,282168754,13.11,100,1,13.47,196,2,12.98,200,2,13.74,2,1,12.92,2,1,13.76,100,1,12.86,100,1,14.0,100,1,12.73,100,1,14.25,100,1,12.71,100,1,14.27,100,1,12.5,700,1,14.28,100,1,12.46,100,1,14.4,200,2,12.43,700,1,14.44,200,2,12.42,700,1,14.47,700,1,ARL,339054149
,2025-07-17T16:12:53.021749348Z,2025-07-17T16:12:53.021749348Z,10,2,1108,A,A,0,13.46,15,130,165304,282194154,13.11,100,1,13.46,15,1,12.98,200,2,13.47,196,2,12.92,2,1,13.74,2,1,12.86,100,1,13.76,100,1,12.73,100,1,14.0,100,1,12.71,100,1,14.25,100,1,12.5,700,1,14.27,100,1,12.46,100,1,14.28,100,1,12.43,700,1,14.4,200,2,12.42,700,1,14.44,200,2,ARL,339096733
,2025-07-17T16:12:53.021793735Z,2025-07-17T16:12:53.021793735Z,10,2,1108,C,A,1,13.47,100,130,165406,282194157,13.11,100,1,13.46,15,1,12.98,200,2,13.47,96,1,12.92,2,1,13.74,2,1,12.86,100,1,13.76,100,1,12.73,100,1,14.0,100,1,12.71,100,1,14.25,100,1,12.5,700,1,14.27,100,1,12.46,100,1,14.28,100,1,12.43,700,1,14.4,200,2,12.42,700,1,14.44,200,2,ARL,338918217
,2025-07-17T16:12:53.022064745Z,2025-07-17T16:12:53.022064745Z,10,2,1108,C,A,1,13.47,96,130,165377,282194159,13.11,100,1,13.46,15,1,12.98,200,2,13.74,2,1,12.92,2,1,13.76,100,1,12.86,100,1,14.0,100,1,12.73,100,1,14.25,100,1,12.71,100,1,14.27,100,1,12.5,700,1,14.28,100,1,12.46,100,1,14.4,200,2,12.43,700,1,14.44,200,2,12.42,700,1,14.47,700,1,ARL,339054149
,2025-07-17T16:12:53.023423468Z,2025-07-17T16:12:53.023423468Z,10,2,1108,C,A,8,14.44,100,0,166062,282194181,13.11,100,1,13.46,15,1,12.98,200,2,13.74,2,1,12.92,2,1,13.76,100,1,12.86,100,1,14.0,100,1,12.73,100,1,14.25,100,1,12.71,100,1,14.27,100,1,12.5,700,1,14.28,100,1,12.46,100,1,14.4,200,2,12.43,700,1,14.44,100,1,12.42,700,1,14.47,700,1,ARL,338865165
,2025-07-17T16:12:53.025486466Z,2025-07-17T16:12:53.025486466Z,10,2,1108,C,A,8,14.44,100,0,165517,282194189,13.11,100,1,13.46,15,1,12.98,200,2,13.74,2,1,12.92,2,1,13.76,100,1,12.86,100,1,14.0,100,1,12.73,100,1,14.25,100,1,12.71,100,1,14.27,100,1,12.5,700,1,14.28,100,1,12.46,100,1,14.4,200,2,12.43,700,1,14.47,700,1,12.42,700,1,14.48,700,1,ARL,338865133
,2025-07-17T16:12:53.027549524Z,2025-07-17T16:12:53.027549524Z,10,2,1108,C,A,6,14.28,100,130,165502,282194224,13.11,100,1,13.46,15,1,12.98,200,2,13.74,2,1,12.92,2,1,13.76,100,1,12.86,100,1,14.0,100,1,12.73,100,1,14.25,100,1,12.71,100,1,14.27,100,1,12.5,700,1,14.4,200,2,12.46,100,1,14.47,700,1,12.43,700,1,14.48,700,1,12.42,700,1,14.54,700,1,ARL,338894329
,2025-07-17T16:12:53.027701439Z,2025-07-17T16:12:53.027701439Z,10,2,1108,A,A,10,14.55,100,130,165338,282194226,13.11,100,1,13.46,15,1,12.98,200,2,13.74,2,1,12.92,2,1,13.76,100,1,12.86,100,1,14.0,100,1,12.73,100,1,14.25,100,1,12.71,100,1,14.27,100,1,12.5,700,1,14.4,200,2,12.46,100,1,14.47,700,1,12.43,700,1,14.48,700,1,12.42,700,1,14.54,700,1,ARL,339096833
,2025-07-17T16:12:53.033101265Z,2025-07-17T16:12:53.033101265Z,10,2,1108,C,A,2,13.76,100,130,165272,282194348,13.11,100,1,13.46,15,1,12.98,200,2,13.74,2,1,12.92,2,1,14.0,100,1,12.86,100,1,14.25,100,1,12.73,100,1,14.27,100,1,12.71,100,1,14.4,200,2,12.5,700,1,14.47,700,1,12.46,100,1,14.48,700,1,12.43,700,1,14.54,700,1,12.42,700,1,14.55,100,1,ARL,338865177
,2025-07-17T16:12:53.033137644Z,2025-07-17T16:12:53.033137644Z,10,2,1108,C,A,6,14.47,700,130,165204,282194349,13.11,100,1,13.46,15,1,12.98,200,2,13.74,2,1,12.92,2,1,14.0,100,1,12.86,100,1,14.25,100,1,12.73,100,1,14.27,100,1,12.71,100,1,14.4,200,2,12.5,700,1,14.48,700,1,12.46,100,1,14.54,700,1,12.43,700,1,14.55,100,1,12.42,700,1,14.56,700,1,ARL,338864173
,2025-07-17T16:12:53.033153612Z,2025-07-17T16:12:53.033153612Z,10,2,1108,A,A,3,14.04,100,130,165206,282194350,13.11,100,1,13.46,15,1,12.98,200,2,13.74,2,1,12.92,2,1,14.0,100,1,12.86,100,1,14.04,100,1,12.73,100,1,14.25,100,1,12.71,100,1,14.27,100,1,12.5,700,1,14.4,200,2,12.46,100,1,14.48,700,1,12.43,700,1,14.54,700,1,12.42,700,1,14.55,100,1,ARL,339096893
,2025-07-17T16:12:53.033596046Z,2025-07-17T16:12:53.033596046Z,10,2,1108,C,A,1,13.74,2,0,166026,282194354,13.11,100,1,13.46,15,1,12.98,200,2,14.0,100,1,12.92,2,1,14.04,100,1,12.86,100,1,14.25,100,1,12.73,100,1,14.27,100,1,12.71,100,1,14.4,200,2,12.5,700,1,14.48,700,1,12.46,100,1,14.54,700,1,12.43,700,1,14.55,100,1,12.42,700,1,14.56,700,1,ARL,338371797
,2025-07-17T16:12:53.033596046Z,2025-07-17T16:12:53.033596046Z,10,2,1108,A,A,1,13.98,2,130,166026,282194354,13.11,100,1,13.46,15,1,12.98,200,2,13.98,2,1,12.92,2,1,14.0,100,1,12.86,100,1,14.04,100,1,12.73,100,1,14.25,100,1,12.71,100,1,14.27,100,1,12.5,700,1,14.4,200,2,12.46,100,1,14.48,700,1,12.43,700,1,14.54,700,1,12.42,700,1,14.55,100,1,ARL,339096909
,2025-07-17T16:12:53.033835120Z,2025-07-17T16:12:53.033835120Z,10,2,1108,C,A,4,14.25,100,130,165526,282194360,13.11,100,1,13.46,15,1,12.98,200,2,13.98,2,1,12.92,2,1,14.0,100,1,12.86,100,1,14.04,100,1,12.73,100,1,14.27,100,1,12.71,100,1,14.4,200,2,12.5,700,1,14.48,700,1,12.46,100,1,14.54,700,1,12.43,700,1,14.55,100,1,12.42,700,1,14.56,700,1,ARL,336161365
,2025-07-17T16:12:53.034187864Z,2025-07-17T16:12:53.034187864Z,10,2,1108,A,A,10,14.6,100,130,165276,282194365,13.11,100,1,13.46,15,1,12.98,200,2,13.98,2,1,12.92,2,1,14.0,100,1,12.86,100,1,14.04,100,1,12.73,100,1,14.27,100,1,12.71,100,1,14.4,200,2,12.5,700,1,14.48,700,1,12.46,100,1,14.54,700,1,12.43,700,1,14.55,100,1,12.42,700,1,14.56,700,1,ARL,339096925
,2025-07-17T16:12:53.043562198Z,2025-07-17T16:12:53.043562198Z,10,2,1108,C,A,3,14.04,100,130,165027,282194436,13.11,100,1,13.46,15,1,12.98,200,2,13.98,2,1,12.92,2,1,14.0,100,1,12.86,100,1,14.27,100,1,12.73,100,1,14.4,200,2,12.71,100,1,14.48,700,1,12.5,700,1,14.54,700,1,12.46,100,1,14.55,100,1,12.43,700,1,14.56,700,1,12.42,700,1,14.6,100,1,ARL,339096893
,2025-07-17T16:12:53.043610101Z,2025-07-17T16:12:53.043610101Z,10,2,1108,A,A,3,14.26,100,130,165198,282194438,13.11,100,1,13.46,15,1,12.98,200,2,13.98,2,1,12.92,2,1,14.0,100,1,12.86,100,1,14.26,100,1,12.73,100,1,14.27,100,1,12.71,100,1,14.4,200,2,12.5,700,1,14.48,700,1,12.46,100,1,14.54,700,1,12.43,700,1,14.55,100,1,12.42,700,1,14.56,700,1,ARL,339097005
,2025-07-17T16:12:53.332564148Z,2025-07-17T16:12:53.332564148Z,10,2,1108,C,A,2,14.0,100,130,165339,282196976,13.11,100,1,13.46,15,1,12.98,200,2,13.98,2,1,12.92,2,1,14.26,100,1,12.86,100,1,14.27,100,1,12.73,100,1,14.4,200,2,12.71,100,1,14.48,700,1,12.5,700,1,14.54,700,1,12.46,100,1,14.55,100,1,12.43,700,1,14.56,700,1,12.42,700,1,14.6,100,1,ARL,338945933
,2025-07-17T16:12:53.332565150Z,2025-07-17T16:12:53.332565150Z,10,2,1108,A,A,6,14.53,100,130,165358,282196977,13.11,100,1,13.46,15,1,12.98,200,2,13.98,2,1,12.92,2,1,14.26,100,1,12.86,100,1,14.27,100,1,12.73,100,1,14.4,200,2,12.71,100,1,14.48,700,1,12.5,700,1,14.53,100,1,12.46,100,1,14.54,700,1,12.43,700,1,14.55,100,1,12.42,700,1,14.56,700,1,ARL,339100477
,2025-07-17T16:12:53.587644886Z,2025-07-17T16:12:53.587644886Z,10,2,1108,C,A,3,14.27,100,130,165356,282200200,13.11,100,1,13.46,15,1,12.98,200,2,13.98,2,1,12.92,2,1,14.26,100,1,12.86,100,1,14.4,200,2,12.73,100,1,14.48,700,1,12.71,100,1,14.53,100,1,12.5,700,1,14.54,700,1,12.46,100,1,14.55,100,1,12.43,700,1,14.56,700,1,12.42,700,1,14.6,100,1,ARL,338932853
,2025-07-17T16:12:54.015051915Z,2025-07-17T16:12:54.015051915Z,10,2,1108,A,A,1,13.47,100,130,165364,282207405,13.11,100,1,13.46,15,1,12.98,200,2,13.47,100,1,12.92,2,1,13.98,2,1,12.86,100,1,14.26,100,1,12.73,100,1,14.4,200,2,12.71,100,1,14.48,700,1,12.5,700,1,14.53,100,1,12.46,100,1,14.54,700,1,12.43,700,1,14.55,100,1,12.42,700,1,14.56,700,1,ARL,339110853
,2025-07-17T16:12:54.015785325Z,2025-07-17T16:12:54.015785325Z,10,2,1108,C,A,10,14.6,100,130,165994,282207428,13.11,100,1,13.46,15,1,12.98,200,2,13.47,100,1,12.92,2,1,13.98,2,1,12.86,100,1,14.26,100,1,12.73,100,1,14.4,200,2,12.71,100,1,14.48,700,1,12.5,700,1,14.53,100,1,12.46,100,1,14.54,700,1,12.43,700,1,14.55,100,1,12.42,700,1,14.56,700,1,ARL,339096925
,2025-07-17T16:12:54.015788678Z,2025-07-17T16:12:54.015788678Z,10,2,1108,A,A,6,14.52,100,130,165381,282207429,13.11,100,1,13.46,15,1,12.98,200,2,13.47,100,1,12.92,2,1,13.98,2,1,12.86,100,1,14.26,100,1,12.73,100,1,14.4,200,2,12.71,100,1,14.48,700,1,12.5,700,1,14.52,100,1,12.46,100,1,14.53,100,1,12.43,700,1,14.54,700,1,12.42,700,1,14.55,100,1,ARL,339110897
,2025-07-17T16:12:54.016139684Z,2025-07-17T16:12:54.016139684Z,10,2,1108,A,A,3,14.07,100,130,165352,282207437,13.11,100,1,13.46,15,1,12.98,200,2,13.47,100,1,12.92,2,1,13.98,2,1,12.86,100,1,14.07,100,1,12.73,100,1,14.26,100,1,12.71,100,1,14.4,200,2,12.5,700,1,14.48,700,1,12.46,100,1,14.52,100,1,12.43,700,1,14.53,100,1,12.42,700,1,14.54,700,1,ARL,339110909
,2025-07-17T16:12:54.016988897Z,2025-07-17T16:12:54.016988897Z,10,2,1108,A,A,6,14.42,100,130,165596,282207488,13.11,100,1,13.46,15,1,12.98,200,2,13.47,100,1,12.92,2,1,13.98,2,1,12.86,100,1,14.07,100,1,12.73,100,1,14.26,100,1,12.71,100,1,14.4,200,2,12.5,700,1,14.42,100,1,12.46,100,1,14.48,700,1,12.43,700,1,14.52,100,1,12.42,700,1,14.53,100,1,ARL,339110981
,2025-07-17T16:12:54.017215883Z,2025-07-17T16:12:54.017215883Z,10,2,1108,C,A,2,13.98,2,0,165243,282207495,13.11,100,1,13.46,15,1,12.98,200,2,13.47,100,1,12.92,2,1,14.07,100,1,12.86,100,1,14.26,100,1,12.73,100,1,14.4,200,2,12.71,100,1,14.42,100,1,12.5,700,1,14.48,700,1,12.46,100,1,14.52,100,1,12.43,700,1,14.53,100,1,12.42,700,1,14.54,700,1,ARL,339096909
,2025-07-17T16:12:54.017215883Z,2025-07-17T16:12:54.017215883Z,10,2,1108,A,A,2,13.73,2,130,165243,282207495,13.11,100,1,13.46,15,1,12.98,200,2,13.47,100,1,12.92,2,1,13.73,2,1,12.86,100,1,14.07,100,1,12.73,100,1,14.26,100,1,12.71,100,1,14.4,200,2,12.5,700,1,14.42,100,1,12.46,100,1,14.48,700,1,12.43,700,1,14.52,100,1,12.42,700,1,14.53,100,1,ARL,339110993
,2025-07-17T16:12:54.020013940Z,2025-07-17T16:12:54.020013940Z,10,2,1108,C,A,4,14.26,100,130,165238,282207539,13.11,100,1,13.46,15,1,12.98,200,2,13.47,100,1,12.92,2,1,13.73,2,1,12.86,100,1,14.07,100,1,12.73,100,1,14.4,200,2,12.71,100,1,14.42,100,1,12.5,700,1,14.48,700,1,12.46,100,1,14.52,100,1,12.43,700,1,14.53,100,1,12.42,700,1,14.54,700,1,ARL,339097005
,2025-07-17T16:12:54.020067630Z,2025-07-17T16:12:54.020067630Z,10,2,1108,A,A,3,13.74,100,130,165389,282207540,13.11,100,1,13.46,15,1,12.98,200,2,13.47,100,1,12.92,2,1,13.73,2,1,12.86,100,1,13.74,100,1,12.73,100,1,14.07,100,1,12.71,100,1,14.4,200,2,12.5,700,1,14.42,100,1,12.46,100,1,14.48,700,1,12.43,700,1,14.52,100,1,12.42,700,1,14.53,100,1,ARL,339111029
,2025-07-17T16:12:54.029066847Z,2025-07-17T16:12:54.029066847Z,10,2,1108,A,A,5,14.26,100,130,165532,282207737,13.11,100,1,13.46,15,1,12.98,200,2,13.47,100,1,12.92,2,1,13.73,2,1,12.86,100,1,13.74,100,1,12.73,100,1,14.07,100,1,12.71,100,1,14.26,100,1,12.5,700,1,14.4,200,2,12.46,100,1,14.42,100,1,12.43,700,1,14.48,700,1,12.42,700,1,14.52,100,1,ARL,339111189
,2025-07-17T16:12:54.069614114Z,2025-07-17T16:12:54.069614114Z,10,2,1108,A,A,7,14.42,100,130,165696,282210148,13.11,100,1,13.46,15,1,12.98,200,2,13.47,100,1,12.92,2,1,13.73,2,1,12.86,100,1,13.74,100,1,12.73,100,1,14.07,100,1,12.71,100,1,14.26,100,1,12.5,700,1,14.4,200,2,12.46,100,1,14.42,200,2,12.43,700,1,14.48,700,1,12.42,700,1,14.52,100,1,ARL,339112945
,2025-07-17T16:12:54.694630780Z,2025-07-17T16:12:54.694630780Z,10,2,1108,A,A,6,14.27,100,130,165283,282224916,13.11,100,1,13.46,15,1,12.98,200,2,13.47,100,1,12.92,2,1,13.73,2,1,12.86,100,1,13.74,100,1,12.73,100,1,14.07,100,1,12.71,100,1,14.26,100,1,12.5,700,1,14.27,100,1,12.46,100,1,14.4,200,2,12.43,700,1,14.42,200,2,12.42,700,1,14.48,700,1,ARL,339126221
,2025-07-17T16:12:55.255162003Z,2025-07-17T16:12:55.255162003Z,10,2,1108,A,A,4,14.0,100,130,165583,282231441,13.11,100,1,13.46,15,1,12.98,200,2,13.47,100,1,12.92,2,1,13.73,2,1,12.86,100,1,13.74,100,1,12.73,100,1,14.0,100,1,12.71,100,1,14.07,100,1,12.5,700,1,14.26,100,1,12.46,100,1,14.27,100,1,12.43,700,1,14.4,200,2,12.42,700,1,14.42,200,2,ARL,339133353
,2025-07-17T16:12:58.302017238Z,2025-07-17T16:12:58.302017238Z,10,2,1108,C,A,0,13.46,15,128,166209,282279351,13.11,100,1,13.47,100,1,12.98,200,2,13.73,2,1,12.92,2,1,13.74,100,1,12.86,100,1,14.0,100,1,12.73,100,1,14.07,100,1,12.71,100,1,14.26,100,1,12.5,700,1,14.27,100,1,12.46,100,1,14.4,200,2,12.43,700,1,14.42,200,2,12.42,700,1,14.48,700,1,ARL,339096733
,2025-07-17T16:12:58.420710579Z,2025-07-17T16:12:58.420710579Z,10,2,1108,C,A,0,13.47,100,128,177167,282288716,13.11,100,1,13.73,2,1,12.98,200,2,13.74,100,1,12.92,2,1,14.0,100,1,12.86,100,1,14.07,100,1,12.73,100,1,14.26,100,1,12.71,100,1,14.27,100,1,12.5,700,1,14.4,200,2,12.46,100,1,14.42,200,2,12.43,700,1,14.48,700,1,12.42,700,1,14.52,100,1,ARL,339110853
,2025-07-17T16:12:58.420776003Z,2025-07-17T16:12:58.420776003Z,10,2,1108,A,A,0,13.47,96,128,174584,282288757,13.11,100,1,13.47,96,1,12.98,200,2,13.73,2,1,12.92,2,1,13.74,100,1,12.86,100,1,14.0,100,1,12.73,100,1,14.07,100,1,12.71,100,1,14.26,100,1,12.5,700,1,14.27,100,1,12.46,100,1,14.4,200,2,12.43,700,1,14.42,200,2,12.42,700,1,14.48,700,1,ARL,339201549
,2025-07-17T16:12:58.421165414Z,2025-07-17T16:12:58.421165414Z,10,2,1108,C,A,0,13.47,96,130,173139,282289082,13.11,100,1,13.73,2,1,12.98,200,2,13.74,100,1,12.92,2,1,14.0,100,1,12.86,100,1,14.07,100,1,12.73,100,1,14.26,100,1,12.71,100,1,14.27,100,1,12.5,700,1,14.4,200,2,12.46,100,1,14.42,200,2,12.43,700,1,14.48,700,1,12.42,700,1,14.52,100,1,ARL,339201549
,2025-07-17T16:12:58.421581692Z,2025-07-17T16:12:58.421581692Z,10,2,1108,C,A,3,14.07,100,130,175034,282289338,13.11,100,1,13.73,2,1,12.98,200,2,13.74,100,1,12.92,2,1,14.0,100,1,12.86,100,1,14.26,100,1,12.73,100,1,14.27,100,1,12.71,100,1,14.4,200,2,12.5,700,1,14.42,200,2,12.46,100,1,14.48,700,1,12.43,700,1,14.52,100,1,12.42,700,1,14.54,700,1,ARL,339110909
,2025-07-17T16:12:58.421969675Z,2025-07-17T16:12:58.421969675Z,10,2,1108,A,A,5,14.35,100,128,176110,282289650,13.11,100,1,13.73,2,1,12.98,200,2,13.74,100,1,12.92,2,1,14.0,100,1,12.86,100,1,14.26,100,1,12.73,100,1,14.27,100,1,12.71,100,1,14.35,100,1,12.5,700,1,14.4,200,2,12.46,100,1,14.42,200,2,12.43,700,1,14.48,700,1,12.42,700,1,14.52,100,1,ARL,339202733
,2025-07-17T16:12:58.422073305Z,2025-07-17T16:12:58.422073305Z,10,2,1108,C,A,9,14.52,100,0,174572,282289747,13.11,100,1,13.73,2,1,12.98,200,2,13.74,100,1,12.92,2,1,14.0,100,1,12.86,100,1,14.26,100,1,12.73,100,1,14.27,100,1,12.71,100,1,14.35,100,1,12.5,700,1,14.4,200,2,12.46,100,1,14.42,200,2,12.43,700,1,14.48,700,1,12.42,700,1,14.54,700,1,ARL,339110897
,2025-07-17T16:12:58.424789366Z,2025-07-17T16:12:58.424789366Z,10,2,1108,C,A,6,14.4,100,0,169004,282290622,13.11,100,1,13.73,2,1,12.98,200,2,13.74,100,1,12.92,2,1,14.0,100,1,12.86,100,1,14.26,100,1,12.73,100,1,14.27,100,1,12.71,100,1,14.35,100,1,12.5,700,1,14.4,100,1,12.46,100,1,14.42,200,2,12.43,700,1,14.48,700,1,12.42,700,1,14.54,700,1,ARL,338139585
,2025-07-17T16:12:58.425283932Z,2025-07-17T16:12:58.425283932Z,10,2,1108,C,A,6,14.4,100,0,166244,282290769,13.11,100,1,13.73,2,1,12.98,200,2,13.74,100,1,12.92,2,1,14.0,100,1,12.86,100,1,14.26,100,1,12.73,100,1,14.27,100,1,12.71,100,1,14.35,100,1,12.5,700,1,14.42,200,2,12.46,100,1,14.48,700,1,12.43,700,1,14.54,700,1,12.42,700,1,14.56,700,1,ARL,338139601
,2025-07-17T16:12:58.425283932Z,2025-07-17T16:12:58.425283932Z,10,2,1108,A,A,10,14.57,100,128,166244,282290769,13.11,100,1,13.73,2,1,12.98,200,2,13.74,100,1,12.92,2,1,14.0,100,1,12.86,100,1,14.26,100,1,12.73,100,1,14.27,100,1,12.71,100,1,14.35,100,1,12.5,700,1,14.42,200,2,12.46,100,1,14.48,700,1,12.43,700,1,14.54,700,1,12.42,700,1,14.56,700,1,ARL,339203897
,2025-07-17T16:12:58.426258092Z,2025-07-17T16:12:58.426258092Z,10,2,1108,C,A,3,14.26,100,130,165530,282290946,13.11,100,1,13.73,2,1,12.98,200,2,13.74,100,1,12.92,2,1,14.0,100,1,12.86,100,1,14.27,100,1,12.73,100,1,14.35,100,1,12.71,100,1,14.42,200,2,12.5,700,1,14.48,700,1,12.46,100,1,14.54,700,1,12.43,700,1,14.56,700,1,12.42,700,1,14.57,200,2,ARL,339111189
,2025-07-17T16:12:58.426378483Z,2025-07-17T16:12:58.426378483Z,10,2,1108,A,A,7,14.53,100,130,165994,282290959,13.11,100,1,13.73,2,1,12.98,200,2,13.74,100,1,12.92,2,1,14.0,100,1,12.86,100,1,14.27,100,1,12.73,100,1,14.35,100,1,12.71,100,1,14.42,200,2,12.5,700,1,14.48,700,1,12.46,100,1,14.53,100,1,12.43,700,1,14.54,700,1,12.42,700,1,14.56,700,1,ARL,339204077
,2025-07-17T16:12:58.430665639Z,2025-07-17T16:12:58.430665639Z,10,2,1108,C,A,1,13.74,100,130,165055,282291933,13.11,100,1,13.73,2,1,12.98,200,2,14.0,100,1,12.92,2,1,14.27,100,1,12.86,100,1,14.35,100,1,12.73,100,1,14.42,200,2,12.71,100,1,14.48,700,1,12.5,700,1,14.53,100,1,12.46,100,1,14.54,700,1,12.43,700,1,14.56,700,1,12.42,700,1,14.57,200,2,ARL,339111029
,2025-07-17T16:12:58.430720526Z,2025-07-17T16:12:58.430720526Z,10,2,1108,A,A,2,14.01,100,128,168000,282291946,13.11,100,1,13.73,2,1,12.98,200,2,14.0,100,1,12.92,2,1,14.01,100,1,12.86,100,1,14.27,100,1,12.73,100,1,14.35,100,1,12.71,100,1,14.42,200,2,12.5,700,1,14.48,700,1,12.46,100,1,14.53,100,1,12.43,700,1,14.54,700,1,12.42,700,1,14.56,700,1,ARL,339205213
,2025-07-17T16:12:58.437907652Z,2025-07-17T16:12:58.437907652Z,10,2,1108,C,B,2,12.92,2,0,165687,282292938,13.11,100,1,13.73,2,1,12.98,200,2,14.0,100,1,12.86,100,1,14.01,100,1,12.73,100,1,14.27,100,1,12.71,100,1,14.35,100,1,12.5,700,1,14.42,200,2,12.46,100,1,14.48,700,1,12.43,700,1,14.53,100,1,12.42,700,1,14.54,700,1,12.37,700,1,14.56,700,1,ARL,338044113
,2025-07-17T16:12:58.437907652Z,2025-07-17T16:12:58.437907652Z,10,2,1108,A,B,1,13.02,2,130,165687,282292938,13.11,100,1,13.73,2,1,13.02,2,1,14.0,100,1,12.98,200,2,14.01,100,1,12.86,100,1,14.27,100,1,12.73,100,1,14.35,100,1,12.71,100,1,14.42,200,2,12.5,700,1,14.48,700,1,12.46,100,1,14.53,100,1,12.43,700,1,14.54,700,1,12.42,700,1,14.56,700,1,ARL,339207125
,2025-07-17T16:12:58.437911392Z,2025-07-17T16:12:58.437911392Z,10,2,1108,C,A,0,13.73,2,0,165370,282292939,13.11,100,1,14.0,100,1,13.02,2,1,14.01,100,1,12.98,200,2,14.27,100,1,12.86,100,1,14.35,100,1,12.73,100,1,14.42,200,2,12.71,100,1,14.48,700,1,12.5,700,1,14.53,100,1,12.46,100,1,14.54,700,1,12.43,700,1,14.56,700,1,12.42,700,1,14.57,200,2,ARL,339110993
,2025-07-17T16:12:58.437911392Z,2025-07-17T16:12:58.437911392Z,10,2,1108,A,A,0,13.98,2,130,165370,282292939,13.11,100,1,13.98,2,1,13.02,2,1,14.0,100,1,12.98,200,2,14.01,100,1,12.86,100,1,14.27,100,1,12.73,100,1,14.35,100,1,12.71,100,1,14.42,200,2,12.5,700,1,14.48,700,1,12.46,100,1,14.53,100,1,12.43,700,1,14.54,700,1,12.42,700,1,14.56,700,1,ARL,339207129
,2025-07-17T16:12:58.438678961Z,2025-07-17T16:12:58.438678961Z,10,2,1108,C,A,2,14.01,100,130,164983,282293023,13.11,100,1,13.98,2,1,13.02,2,1,14.0,100,1,12.98,200,2,14.27,100,1,12.86,100,1,14.35,100,1,12.73,100,1,14.42,200,2,12.71,100,1,14.48,700,1,12.5,700,1,14.53,100,1,12.46,100,1,14.54,700,1,12.43,700,1,14.56,700,1,12.42,700,1,14.57,200,2,ARL,339205213
,2025-07-17T16:12:58.438728994Z,2025-07-17T16:12:58.438728994Z,10,2,1108,A,A,2,14.24,100,130,165342,282293026,13.11,100,1,13.98,2,1,13.02,2,1,14.0,100,1,12.98,200,2,14.24,100,1,12.86,100,1,14.27,100,1,12.73,100,1,14.35,100,1,12.71,100,1,14.42,200,2,12.5,700,1,14.48,700,1,12.46,100,1,14.53,100,1,12.43,700,1,14.54,700,1,12.42,700,1,14.56,700,1,ARL,339207197
,2025-07-17T16:12:58.441669159Z,2025-07-17T16:12:58.441669159Z,10,2,1108,C,A,5,14.42,100,0,165338,282293191,13.11,100,1,13.98,2,1,13.02,2,1,14.0,100,1,12.98,200,2,14.24,100,1,12.86,100,1,14.27,100,1,12.73,100,1,14.35,100,1,12.71,100,1,14.42,100,1,12.5,700,1,14.48,700,1,12.46,100,1,14.53,100,1,12.43,700,1,14.54,700,1,12.42,700,1,14.56,700,1,ARL,339110981
,2025-07-17T16:12:58.619238614Z,2025-07-17T16:12:58.619238614Z,10,2,1108,C,A,5,14.42,100,0,165488,282299781,13.11,100,1,13.98,2,1,13.02,2,1,14.0,100,1,12.98,200,2,14.24,100,1,12.86,100,1,14.27,100,1,12.73,100,1,14.35,100,1,12.71,100,1,14.48,700,1,12.5,700,1,14.53,100,1,12.46,100,1,14.54,700,1,12.43,700,1,14.56,700,1,12.42,700,1,14.57,200,2,ARL,339112945
,2025-07-17T16:12:58.985928594Z,2025-07-17T16:12:58.985928594Z,10,2,1108,C,B,1,13.02,2,0,165354,282305386,13.11,100,1,13.98,2,1,12.98,200,2,14.0,100,1,12.86,100,1,14.24,100,1,12.73,100,1,14.27,100,1,12.71,100,1,14.35,100,1,12.5,700,1,14.48,700,1,12.46,100,1,14.53,100,1,12.43,700,1,14.54,700,1,12.42,700,1,14.56,700,1,12.37,700,1,14.57,200,2,ARL,339207125
,2025-07-17T16:12:58.985928594Z,2025-07-17T16:12:58.985928594Z,10,2,1108,A,B,2,12.86,2,130,165354,282305386,13.11,100,1,13.98,2,1,12.98,200,2,14.0,100,1,12.86,102,2,14.24,100,1,12.73,100,1,14.27,100,1,12.71,100,1,14.35,100,1,12.5,700,1,14.48,700,1,12.46,100,1,14.53,100,1,12.43,700,1,14.54,700,1,12.42,700,1,14.56,700,1,12.37,700,1,14.57,200,2,ARL,339222617
,2025-07-17T16:12:59.062943193Z,2025-07-17T16:12:59.062943193Z,10,2,1108,A,A,1,13.99,100,130,165219,282306400,13.11,100,1,13.98,2,1,12.98,200,2,13.99,100,1,12.86,102,2,14.0,100,1,12.73,100,1,14.24,100,1,12.71,100,1,14.27,100,1,12.5,700,1,14.35,100,1,12.46,100,1,14.48,700,1,12.43,700,1,14.53,100,1,12.42,700,1,14.54,700,1,12.37,700,1,14.56,700,1,ARL,339224109
,2025-07-17T16:12:59.082690430Z,2025-07-17T16:12:59.082690430Z,10,2,1108,C,A,2,14.0,100,130,165140,282307908,13.11,100,1,13.98,2,1,12.98,200,2,13.99,100,1,12.86,102,2,14.24,100,1,12.73,100,1,14.27,100,1,12.71,100,1,14.35,100,1,12.5,700,1,14.48,700,1,12.46,100,1,14.53,100,1,12.43,700,1,14.54,700,1,12.42,700,1,14.56,700,1,12.37,700,1,14.57,200,2,ARL,339133353
,2025-07-17T16:12:59.082691385Z,2025-07-17T16:12:59.082691385Z,10,2,1108,A,A,6,14.53,100,130,165255,282307909,13.11,100,1,13.98,2,1,12.98,200,2,13.99,100,1,12.86,102,2,14.24,100,1,12.73,100,1,14.27,100,1,12.71,100,1,14.35,100,1,12.5,700,1,14.48,700,1,12.46,100,1,14.53,200,2,12.43,700,1,14.54,700,1,12.42,700,1,14.56,700,1,12.37,700,1,14.57,200,2,ARL,339225769
,2025-07-17T16:12:59.088642718Z,2025-07-17T16:12:59.088642718Z,10,2,1108,C,A,3,14.27,100,130,165399,282308094,13.11,100,1,13.98,2,1,12.98,200,2,13.99,100,1,12.86,102,2,14.24,100,1,12.73,100,1,14.35,100,1,12.71,100,1,14.48,700,1,12.5,700,1,14.53,200,2,12.46,100,1,14.54,700,1,12.43,700,1,14.56,700,1,12.42,700,1,14.57,200,2,12.37,700,1,14.68,700,1,ARL,339126221
,2025-07-17T16:12:59.092762564Z,2025-07-17T16:12:59.092762564Z,10,2,1108,C,A,3,14.35,100,130,165278,282308154,13.11,100,1,13.98,2,1,12.98,200,2,13.99,100,1,12.86,102,2,14.24,100,1,12.73,100,1,14.48,700,1,12.71,100,1,14.53,200,2,12.5,700,1,14.54,700,1,12.46,100,1,14.56,700,1,12.43,700,1,14.57,200,2,12.42,700,1,14.68,700,1,12.37,700,1,14.81,100,1,ARL,339202733
,2025-07-17T16:12:59.093113488Z,2025-07-17T16:12:59.093113488Z,10,2,1108,A,A,8,14.6,100,130,165427,282308163,13.11,100,1,13.98,2,1,12.98,200,2,13.99,100,1,12.86,102,2,14.24,100,1,12.73,100,1,14.48,700,1,12.71,100,1,14.53,200,2,12.5,700,1,14.54,700,1,12.46,100,1,14.56,700,1,12.43,700,1,14.57,200,2,12.42,700,1,14.6,100,1,12.37,700,1,14.68,700,1,ARL,339226021
,2025-07-17T16:12:59.430320610Z,2025-07-17T16:12:59.430320610Z,10,2,1108,C,A,4,14.53,100,0,165402,282313368,13.11,100,1,13.98,2,1,12.98,200,2,13.99,100,1,12.86,102,2,14.24,100,1,12.73,100,1,14.48,700,1,12.71,100,1,14.53,100,1,12.5,700,1,14.54,700,1,12.46,100,1,14.56,700,1,12.43,700,1,14.57,200,2,12.42,700,1,14.6,100,1,12.37,700,1,14.68,700,1,ARL,339204077
,2025-07-17T16:12:59.430320610Z,2025-07-17T16:12:59.430320610Z,10,2,1108,A,A,10,14.77,100,130,165402,282313368,13.11,100,1,13.98,2,1,12.98,200,2,13.99,100,1,12.86,102,2,14.24,100,1,12.73,100,1,14.48,700,1,12.71,100,1,14.53,100,1,12.5,700,1,14.54,700,1,12.46,100,1,14.56,700,1,12.43,700,1,14.57,200,2,12.42,700,1,14.6,100,1,12.37,700,1,14.68,700,1,ARL,339232213
,2025-07-17T16:13:04.825736034Z,2025-07-17T16:13:04.825736034Z,10,2,1108,A,A,0,13.66,15,128,166132,282392593,13.11,100,1,13.66,15,1,12.98,200,2,13.98,2,1,12.86,102,2,13.99,100,1,12.73,100,1,14.24,100,1,12.71,100,1,14.48,700,1,12.5,700,1,14.53,100,1,12.46,100,1,14.54,700,1,12.43,700,1,14.56,700,1,12.42,700,1,14.57,200,2,12.37,700,1,14.6,100,1,ARL,339332865
,2025-07-17T16:13:06.189110140Z,2025-07-17T16:13:06.189110140Z,10,2,1108,C,B,2,12.86,2,0,165672,282411935,13.11,100,1,13.66,15,1,12.98,200,2,13.98,2,1,12.86,100,1,13.99,100,1,12.73,100,1,14.24,100,1,12.71,100,1,14.48,700,1,12.5,700,1,14.53,100,1,12.46,100,1,14.54,700,1,12.43,700,1,14.56,700,1,12.42,700,1,14.57,200,2,12.37,700,1,14.6,100,1,ARL,339222617
,2025-07-17T16:13:06.189110140Z,2025-07-17T16:13:06.189110140Z,10,2,1108,A,B,2,12.96,2,130,165672,282411935,13.11,100,1,13.66,15,1,12.98,200,2,13.98,2,1,12.96,2,1,13.99,100,1,12.86,100,1,14.24,100,1,12.73,100,1,14.48,700,1,12.71,100,1,14.53,100,1,12.5,700,1,14.54,700,1,12.46,100,1,14.56,700,1,12.43,700,1,14.57,200,2,12.42,700,1,14.6,100,1,ARL,339356397
,2025-07-17T16:13:06.224732787Z,2025-07-17T16:13:06.224732787Z,10,2,1108,C,A,2,13.99,100,0,165602,282413599,13.11,100,1,13.66,15,1,12.98,200,2,13.98,2,1,12.96,2,1,14.24,100,1,12.86,100,1,14.48,700,1,12.73,100,1,14.53,100,1,12.71,100,1,14.54,700,1,12.5,700,1,14.56,700,1,12.46,100,1,14.57,200,2,12.43,700,1,14.6,100,1,12.42,700,1,14.68,700,1,ARL,339224109
,2025-07-17T16:13:06.224732787Z,2025-07-17T16:13:06.224732787Z,10,2,1108,A,A,1,13.67,100,130,165602,282413599,13.11,100,1,13.66,15,1,12.98,200,2,13.67,100,1,12.96,2,1,13.98,2,1,12.86,100,1,14.24,100,1,12.73,100,1,14.48,700,1,12.71,100,1,14.53,100,1,12.5,700,1,14.54,700,1,12.46,100,1,14.56,700,1,12.43,700,1,14.57,200,2,12.42,700,1,14.6,100,1,ARL,339358233
,2025-07-17T16:13:06.225475906Z,2025-07-17T16:13:06.225475906Z,10,2,1108,C,A,9,14.6,100,128,166875,282413678,13.11,100,1,13.66,15,1,12.98,200,2,13.67,100,1,12.96,2,1,13.98,2,1,12.86,100,1,14.24,100,1,12.73,100,1,14.48,700,1,12.71,100,1,14.53,100,1,12.5,700,1,14.54,700,1,12.46,100,1,14.56,700,1,12.43,700,1,14.57,200,2,12.42,700,1,14.68,700,1,ARL,339226021
,2025-07-17T16:13:06.225829921Z,2025-07-17T16:13:06.225829921Z,10,2,1108,A,A,4,14.28,100,130,165376,282413699,13.11,100,1,13.66,15,1,12.98,200,2,13.67,100,1,12.96,2,1,13.98,2,1,12.86,100,1,14.24,100,1,12.73,100,1,14.28,100,1,12.71,100,1,14.48,700,1,12.5,700,1,14.53,100,1,12.46,100,1,14.54,700,1,12.43,700,1,14.56,700,1,12.42,700,1,14.57,200,2,ARL,339358333
,2025-07-17T16:13:06.226716697Z,2025-07-17T16:13:06.226716697Z,10,2,1108,A,A,10,14.63,100,130,165605,282413745,13.11,100,1,13.66,15,1,12.98,200,2,13.67,100,1,12.96,2,1,13.98,2,1,12.86,100,1,14.24,100,1,12.73,100,1,14.28,100,1,12.71,100,1,14.48,700,1,12.5,700,1,14.53,100,1,12.46,100,1,14.54,700,1,12.43,700,1,14.56,700,1,12.42,700,1,14.57,200,2,ARL,339358353
,2025-07-17T16:13:06.229693020Z,2025-07-17T16:13:06.229693020Z,10,2,1108,C,A,2,13.98,2,0,165518,282413801,13.11,100,1,13.66,15,1,12.98,200,2,13.67,100,1,12.96,2,1,14.24,100,1,12.86,100,1,14.28,100,1,12.73,100,1,14.48,700,1,12.71,100,1,14.53,100,1,12.5,700,1,14.54,700,1,12.46,100,1,14.56,700,1,12.43,700,1,14.57,200,2,12.42,700,1,14.63,100,1,ARL,339207129
,2025-07-17T16:13:06.229693020Z,2025-07-17T16:13:06.229693020Z,10,2,1108,A,A,2,13.81,2,130,165518,282413801,13.11,100,1,13.66,15,1,12.98,200,2,13.67,100,1,12.96,2,1,13.81,2,1,12.86,100,1,14.24,100,1,12.73,100,1,14.28,100,1,12.71,100,1,14.48,700,1,12.5,700,1,14.53,100,1,12.46,100,1,14.54,700,1,12.43,700,1,14.56,700,1,12.42,700,1,14.57,200,2,ARL,339358409
,2025-07-17T16:13:06.236401579Z,2025-07-17T16:13:06.236401579Z,10,2,1108,C,A,3,14.24,100,130,166211,282414131,13.11,100,1,13.66,15,1,12.98,200,2,13.67,100,1,12.96,2,1,13.81,2,1,12.86,100,1,14.28,100,1,12.73,100,1,14.48,700,1,12.71,100,1,14.53,100,1,12.5,700,1,14.54,700,1,12.46,100,1,14.56,700,1,12.43,700,1,14.57,200,2,12.42,700,1,14.63,100,1,ARL,339207197
,2025-07-17T16:13:06.236456489Z,2025-07-17T16:13:06.236456489Z,10,2,1108,A,A,3,13.94,100,130,165046,282414141,13.11,100,1,13.66,15,1,12.98,200,2,13.67,100,1,12.96,2,1,13.81,2,1,12.86,100,1,13.94,100,1,12.73,100,1,14.28,100,1,12.71,100,1,14.48,700,1,12.5,700,1,14.53,100,1,12.46,100,1,14.54,700,1,12.43,700,1,14.56,700,1,12.42,700,1,14.57,200,2,ARL,339358741
,2025-07-17T16:13:06.275720866Z,2025-07-17T16:13:06.275720866Z,10,2,1108,A,A,10,14.63,100,130,165595,282414642,13.11,100,1,13.66,15,1,12.98,200,2,13.67,100,1,12.96,2,1,13.81,2,1,12.86,100,1,13.94,100,1,12.73,100,1,14.28,100,1,12.71,100,1,14.48,700,1,12.5,700,1,14.53,100,1,12.46,100,1,14.54,700,1,12.43,700,1,14.56,700,1,12.42,700,1,14.57,200,2,ARL,339359401
,2025-07-17T16:13:06.277013512Z,2025-07-17T16:13:06.277013512Z,10,2,1108,A,A,5,14.46,100,130,165402,282414660,13.11,100,1,13.66,15,1,12.98,200,2,13.67,100,1,12.96,2,1,13.81,2,1,12.86,100,1,13.94,100,1,12.73,100,1,14.28,100,1,12.71,100,1,14.46,100,1,12.5,700,1,14.48,700,1,12.46,100,1,14.53,100,1,12.43,700,1,14.54,700,1,12.42,700,1,14.56,700,1,ARL,339359421
,2025-07-17T16:13:06.622493734Z,2025-07-17T16:13:06.622493734Z,10,2,1108,A,A,4,14.22,100,130,165368,282418746,13.11,100,1,13.66,15,1,12.98,200,2,13.67,100,1,12.96,2,1,13.81,2,1,12.86,100,1,13.94,100,1,12.73,100,1,14.22,100,1,12.71,100,1,14.28,100,1,12.5,700,1,14.46,100,1,12.46,100,1,14.48,700,1,12.43,700,1,14.53,100,1,12.42,700,1,14.54,700,1,ARL,339365193
,2025-07-17T16:13:06.663671305Z,2025-07-17T16:13:06.663671305Z,10,2,1108,C,A,8,14.53,100,130,165439,282418921,13.11,100,1,13.66,15,1,12.98,200,2,13.67,100,1,12.96,2,1,13.81,2,1,12.86,100,1,13.94,100,1,12.73,100,1,14.22,100,1,12.71,100,1,14.28,100,1,12.5,700,1,14.46,100,1,12.46,100,1,14.48,700,1,12.43,700,1,14.54,700,1,12.42,700,1,14.56,700,1,ARL,339225769
,2025-07-17T16:13:06.759625628Z,2025-07-17T16:13:06.759625628Z,10,2,1108,A,A,8,14.49,100,130,165475,282419471,13.11,100,1,13.66,15,1,12.98,200,2,13.67,100,1,12.96,2,1,13.81,2,1,12.86,100,1,13.94,100,1,12.73,100,1,14.22,100,1,12.71,100,1,14.28,100,1,12.5,700,1,14.46,100,1,12.46,100,1,14.48,700,1,12.43,700,1,14.49,100,1,12.42,700,1,14.54,700,1,ARL,339366385
,2025-07-17T16:13:09.353883614Z,2025-07-17T16:13:09.353883614Z,10,2,1108,A,A,0,13.64,15,130,165126,282469242,13.11,100,1,13.64,15,1,12.98,200,2,13.66,15,1,12.96,2,1,13.67,100,1,12.86,100,1,13.81,2,1,12.73,100,1,13.94,100,1,12.71,100,1,14.22,100,1,12.5,700,1,14.28,100,1,12.46,100,1,14.46,100,1,12.43,700,1,14.48,700,1,12.42,700,1,14.49,100,1,ARL,339425837
,2025-07-17T16:13:09.368030843Z,2025-07-17T16:13:09.368030843Z,10,2,1108,C,A,2,13.67,100,0,166816,282470466,13.11,100,1,13.64,15,1,12.98,200,2,13.66,15,1,12.96,2,1,13.81,2,1,12.86,100,1,13.94,100,1,12.73,100,1,14.22,100,1,12.71,100,1,14.28,100,1,12.5,700,1,14.46,100,1,12.46,100,1,14.48,700,1,12.43,700,1,14.49,100,1,12.42,700,1,14.54,700,1,ARL,339358233
,2025-07-17T16:13:09.368030843Z,2025-07-17T16:13:09.368030843Z,10,2,1108,A,A,1,13.65,100,128,166816,282470466,13.11,100,1,13.64,15,1,12.98,200,2,13.65,100,1,12.96,2,1,13.66,15,1,12.86,100,1,13.81,2,1,12.73,100,1,13.94,100,1,12.71,100,1,14.22,100,1,12.5,700,1,14.28,100,1,12.46,100,1,14.46,100,1,12.43,700,1,14.48,700,1,12.42,700,1,14.49,100,1,ARL,339427217
,2025-07-17T16:13:14.046102556Z,2025-07-17T16:13:14.046102556Z,10,2,1108,C,A,2,13.66,15,130,165319,282563502,13.11,100,1,13.64,15,1,12.98,200,2,13.65,100,1,12.96,2,1,13.81,2,1,12.86,100,1,13.94,100,1,12.73,100,1,14.22,100,1,12.71,100,1,14.28,100,1,12.5,700,1,14.46,100,1,12.46,100,1,14.48,700,1,12.43,700,1,14.49,100,1,12.42,700,1,14.54,700,1,ARL,339332865
,2025-07-17T16:13:17.775045316Z,2025-07-17T16:13:17.775045316Z,10,2,1108,A,A,0,13.57,15,130,165600,282616566,13.11,100,1,13.57,15,1,12.98,200,2,13.64,15,1,12.96,2,1,13.65,100,1,12.86,100,1,13.81,2,1,12.73,100,1,13.94,100,1,12.71,100,1,14.22,100,1,12.5,700,1,14.28,100,1,12.46,100,1,14.46,100,1,12.43,700,1,14.48,700,1,12.42,700,1,14.49,100,1,ARL,339610637
,2025-07-17T16:13:19.780978185Z,2025-07-17T16:13:19.780978185Z,10,2,1108,C,A,2,13.65,100,0,165506,282644181,13.11,100,1,13.57,15,1,12.98,200,2,13.64,15,1,12.96,2,1,13.81,2,1,12.86,100,1,13.94,100,1,12.73,100,1,14.22,100,1,12.71,100,1,14.28,100,1,12.5,700,1,14.46,100,1,12.46,100,1,14.48,700,1,12.43,700,1,14.49,100,1,12.42,700,1,14.54,700,1,ARL,339427217
,2025-07-17T16:13:19.780978185Z,2025-07-17T16:13:19.780978185Z,10,2,1108,A,A,1,13.58,100,130,165506,282644181,13.11,100,1,13.57,15,1,12.98,200,2,13.58,100,1,12.96,2,1,13.64,15,1,12.86,100,1,13.81,2,1,12.73,100,1,13.94,100,1,12.71,100,1,14.22,100,1,12.5,700,1,14.28,100,1,12.46,100,1,14.46,100,1,12.43,700,1,14.48,700,1,12.42,700,1,14.49,100,1,ARL,339641813
,2025-07-17T16:13:19.789606057Z,2025-07-17T16:13:19.789606057Z,10,2,1108,C,A,4,13.94,100,130,165401,282644321,13.11,100,1,13.57,15,1,12.98,200,2,13.58,100,1,12.96,2,1,13.64,15,1,12.86,100,1,13.81,2,1,12.73,100,1,14.22,100,1,12.71,100,1,14.28,100,1,12.5,700,1,14.46,100,1,12.46,100,1,14.48,700,1,12.43,700,1,14.49,100,1,12.42,700,1,14.54,700,1,ARL,339358741
,2025-07-17T16:13:19.789656689Z,2025-07-17T16:13:19.789656689Z,10,2,1108,A,A,4,13.85,100,130,165321,282644322,13.11,100,1,13.57,15,1,12.98,200,2,13.58,100,1,12.96,2,1,13.64,15,1,12.86,100,1,13.81,2,1,12.73,100,1,13.85,100,1,12.71,100,1,14.22,100,1,12.5,700,1,14.28,100,1,12.46,100,1,14.46,100,1,12.43,700,1,14.48,700,1,12.42,700,1,14.49,100,1,ARL,339642033
,2025-07-17T16:13:19.863452537Z,2025-07-17T16:13:19.863452537Z,10,2,1108,C,A,0,13.57,15,130,166169,282645966,13.11,100,1,13.58,100,1,12.98,200,2,13.64,15,1,12.96,2,1,13.81,2,1,12.86,100,1,13.85,100,1,12.73,100,1,14.22,100,1,12.71,100,1,14.28,100,1,12.5,700,1,14.46,100,1,12.46,100,1,14.48,700,1,12.43,700,1,14.49,100,1,12.42,700,1,14.54,700,1,ARL,339610637
,2025-07-17T16:13:19.863624798Z,2025-07-17T16:13:19.863624798Z,10,2,1108,C,A,1,13.64,15,130,165285,282646001,13.11,100,1,13.58,100,1,12.98,200,2,13.81,2,1,12.96,2,1,13.85,100,1,12.86,100,1,14.22,100,1,12.73,100,1,14.28,100,1,12.71,100,1,14.46,100,1,12.5,700,1,14.48,700,1,12.46,100,1,14.49,100,1,12.43,700,1,14.54,700,1,12.42,700,1,14.56,700,1,ARL,339425837
,2025-07-17T16:13:19.863803503Z,2025-07-17T16:13:19.863803503Z,10,2,1108,A,A,0,13.58,96,130,165289,282646014,13.11,100,1,13.58,196,2,12.98,200,2,13.81,2,1,12.96,2,1,13.85,100,1,12.86,100,1,14.22,100,1,12.73,100,1,14.28,100,1,12.71,100,1,14.46,100,1,12.5,700,1,14.48,700,1,12.46,100,1,14.49,100,1,12.43,700,1,14.54,700,1,12.42,700,1,14.56,700,1,ARL,339643285
,2025-07-17T16:13:24.182459676Z,2025-07-17T16:13:24.182459676Z,10,2,1108,A,A,0,13.57,15,130,165335,282694909,13.11,100,1,13.57,15,1,12.98,200,2,13.58,196,2,12.96,2,1,13.81,2,1,12.86,100,1,13.85,100,1,12.73,100,1,14.22,100,1,12.71,100,1,14.28,100,1,12.5,700,1,14.46,100,1,12.46,100,1,14.48,700,1,12.43,700,1,14.49,100,1,12.42,700,1,14.54,700,1,ARL,339710089
,2025-07-17T16:13:24.182753004Z,2025-07-17T16:13:24.182753004Z,10,2,1108,C,A,1,13.58,96,130,165198,282694924,13.11,100,1,13.57,15,1,12.98,200,2,13.58,100,1,12.96,2,1,13.81,2,1,12.86,100,1,13.85,100,1,12.73,100,1,14.22,100,1,12.71,100,1,14.28,100,1,12.5,700,1,14.46,100,1,12.46,100,1,14.48,700,1,12.43,700,1,14.49,100,1,12.42,700,1,14.54,700,1,ARL,339643285
,2025-07-17T16:13:24.627209125Z,2025-07-17T16:13:24.627209125Z,10,2,1108,A,A,5,14.26,700,130,165389,282700118,13.11,100,1,13.57,15,1,12.98,200,2,13.58,100,1,12.96,2,1,13.81,2,1,12.86,100,1,13.85,100,1,12.73,100,1,14.22,100,1,12.71,100,1,14.26,700,1,12.5,700,1,14.28,100,1,12.46,100,1,14.46,100,1,12.43,700,1,14.48,700,1,12.42,700,1,14.49,100,1,ARL,339716321
,2025-07-17T16:13:25.962552288Z,2025-07-17T16:13:25.962552288Z,10,2,1108,A,A,7,14.46,100,130,165656,282719507,13.11,100,1,13.57,15,1,12.98,200,2,13.58,100,1,12.96,2,1,13.81,2,1,12.86,100,1,13.85,100,1,12.73,100,1,14.22,100,1,12.71,100,1,14.26,700,1,12.5,700,1,14.28,100,1,12.46,100,1,14.46,200,2,12.43,700,1,14.48,700,1,12.42,700,1,14.49,100,1,ARL,339739285
,2025-07-17T16:13:25.963043858Z,2025-07-17T16:13:25.963043858Z,10,2,1108,A,A,7,14.46,100,130,165470,282719515,13.11,100,1,13.57,15,1,12.98,200,2,13.58,100,1,12.96,2,1,13.81,2,1,12.86,100,1,13.85,100,1,12.73,100,1,14.22,100,1,12.71,100,1,14.26,700,1,12.5,700,1,14.28,100,1,12.46,100,1,14.46,300,3,12.43,700,1,14.48,700,1,12.42,700,1,14.49,100,1,ARL,339739297
,2025-07-17T16:13:34.825063658Z,2025-07-17T16:13:34.825063658Z,10,2,1108,A,A,0,13.55,15,130,165379,282849136,13.11,100,1,13.55,15,1,12.98,200,2,13.57,15,1,12.96,2,1,13.58,100,1,12.86,100,1,13.81,2,1,12.73,100,1,13.85,100,1,12.71,100,1,14.22,100,1,12.5,700,1,14.26,700,1,12.46,100,1,14.28,100,1,12.43,700,1,14.46,300,3,12.42,700,1,14.48,700,1,ARL,339897885
,2025-07-17T16:13:36.525285006Z,2025-07-17T16:13:36.525285006Z,10,2,1108,C,A,2,13.58,100,0,165539,282880671,13.11,100,1,13.55,15,1,12.98,200,2,13.57,15,1,12.96,2,1,13.81,2,1,12.86,100,1,13.85,100,1,12.73,100,1,14.22,100,1,12.71,100,1,14.26,700,1,12.5,700,1,14.28,100,1,12.46,100,1,14.46,300,3,12.43,700,1,14.48,700,1,12.42,700,1,14.49,100,1,ARL,339641813
,2025-07-17T16:13:36.525285006Z,2025-07-17T16:13:36.525285006Z,10,2,1108,A,A,1,13.56,100,130,165539,282880671,13.11,100,1,13.55,15,1,12.98,200,2,13.56,100,1,12.96,2,1,13.57,15,1,12.86,100,1,13.81,2,1,12.73,100,1,13.85,100,1,12.71,100,1,14.22,100,1,12.5,700,1,14.26,700,1,12.46,100,1,14.28,100,1,12.43,700,1,14.46,300,3,12.42,700,1,14.48,700,1,ARL,339937253
,2025-07-17T16:13:40.166532673Z,2025-07-17T16:13:40.166532673Z,10,2,1108,C,A,2,13.57,15,130,165525,282934517,13.11,100,1,13.55,15,1,12.98,200,2,13.56,100,1,12.96,2,1,13.81,2,1,12.86,100,1,13.85,100,1,12.73,100,1,14.22,100,1,12.71,100,1,14.26,700,1,12.5,700,1,14.28,100,1,12.46,100,1,14.46,300,3,12.43,700,1,14.48,700,1,12.42,700,1,14.49,100,1,ARL,339710089
,2025-07-17T16:13:41.168516592Z,2025-07-17T16:13:41.168516592Z,10,2,1108,A,A,0,13.53,15,130,165385,282947373,13.11,100,1,13.53,15,1,12.98,200,2,13.55,15,1,12.96,2,1,13.56,100,1,12.86,100,1,13.81,2,1,12.73,100,1,13.85,100,1,12.71,100,1,14.22,100,1,12.5,700,1,14.26,700,1,12.46,100,1,14.28,100,1,12.43,700,1,14.46,300,3,12.42,700,1,14.48,700,1,ARL,340027925
,2025-07-17T16:13:41.810482971Z,2025-07-17T16:13:41.810482971Z,10,2,1108,C,A,2,13.56,100,0,165804,282959674,13.11,100,1,13.53,15,1,12.98,200,2,13.55,15,1,12.96,2,1,13.81,2,1,12.86,100,1,13.85,100,1,12.73,100,1,14.22,100,1,12.71,100,1,14.26,700,1,12.5,700,1,14.28,100,1,12.46,100,1,14.46,300,3,12.43,700,1,14.48,700,1,12.42,700,1,14.49,100,1,ARL,339937253
,2025-07-17T16:13:41.810482971Z,2025-07-17T16:13:41.810482971Z,10,2,1108,A,A,1,13.54,100,130,165804,282959674,13.11,100,1,13.53,15,1,12.98,200,2,13.54,100,1,12.96,2,1,13.55,15,1,12.86,100,1,13.81,2,1,12.73,100,1,13.85,100,1,12.71,100,1,14.22,100,1,12.5,700,1,14.26,700,1,12.46,100,1,14.28,100,1,12.43,700,1,14.46,300,3,12.42,700,1,14.48,700,1,ARL,340046965
,2025-07-17T16:13:53.138226660Z,2025-07-17T16:13:53.138226660Z,10,2,1108,C,A,0,13.53,15,130,165270,283090735,13.11,100,1,13.54,100,1,12.98,200,2,13.55,15,1,12.96,2,1,13.81,2,1,12.86,100,1,13.85,100,1,12.73,100,1,14.22,100,1,12.71,100,1,14.26,700,1,12.5,700,1,14.28,100,1,12.46,100,1,14.46,300,3,12.43,700,1,14.48,700,1,12.42,700,1,14.49,100,1,ARL,340027925
,2025-07-17T16:13:53.784124590Z,2025-07-17T16:13:53.784124590Z,10,2,1108,C,A,1,13.55,15,128,177637,283098338,13.11,100,1,13.54,100,1,12.98,200,2,13.81,2,1,12.96,2,1,13.85,100,1,12.86,100,1,14.22,100,1,12.73,100,1,14.26,700,1,12.71,100,1,14.28,100,1,12.5,700,1,14.46,300,3,12.46,100,1,14.48,700,1,12.43,700,1,14.49,100,1,12.42,700,1,14.54,700,1,ARL,339897885
,2025-07-17T16:14:06.190701389Z,2025-07-17T16:14:06.190701389Z,10,2,1108,C,A,1,13.81,2,0,165593,283262191,13.11,100,1,13.54,100,1,12.98,200,2,13.85,100,1,12.96,2,1,14.22,100,1,12.86,100,1,14.26,700,1,12.73,100,1,14.28,100,1,12.71,100,1,14.46,300,3,12.5,700,1,14.48,700,1,12.46,100,1,14.49,100,1,12.43,700,1,14.54,700,1,12.42,700,1,14.56,700,1,ARL,339358409
,2025-07-17T16:14:06.190701389Z,2025-07-17T16:14:06.190701389Z,10,2,1108,A,A,1,13.74,2,130,165593,283262191,13.11,100,1,13.54,100,1,12.98,200,2,13.74,2,1,12.96,2,1,13.85,100,1,12.86,100,1,14.22,100,1,12.73,100,1,14.26,700,1,12.71,100,1,14.28,100,1,12.5,700,1,14.46,300,3,12.46,100,1,14.48,700,1,12.43,700,1,14.49,100,1,12.42,700,1,14.54,700,1,ARL,340449865
,2025-07-17T16:14:10.827253317Z,2025-07-17T16:14:10.827253317Z,10,2,1108,A,A,0,13.51,15,130,165890,283315922,13.11,100,1,13.51,15,1,12.98,200,2,13.54,100,1,12.96,2,1,13.74,2,1,12.86,100,1,13.85,100,1,12.73,100,1,14.22,100,1,12.71,100,1,14.26,700,1,12.5,700,1,14.28,100,1,12.46,100,1,14.46,300,3,12.43,700,1,14.48,700,1,12.42,700,1,14.49,100,1,ARL,340526285
,2025-07-17T16:14:10.876729278Z,2025-07-17T16:14:10.876729278Z,10,2,1108,C,A,1,13.54,100,0,165576,283317356,13.11,100,1,13.51,15,1,12.98,200,2,13.74,2,1,12.96,2,1,13.85,100,1,12.86,100,1,14.22,100,1,12.73,100,1,14.26,700,1,12.71,100,1,14.28,100,1,12.5,700,1,14.46,300,3,12.46,100,1,14.48,700,1,12.43,700,1,14.49,100,1,12.42,700,1,14.54,700,1,ARL,340046965
,2025-07-17T16:14:10.876729278Z,2025-07-17T16:14:10.876729278Z,10,2,1108,A,A,1,13.52,100,130,165576,283317356,13.11,100,1,13.51,15,1,12.98,200,2,13.52,100,1,12.96,2,1,13.74,2,1,12.86,100,1,13.85,100,1,12.73,100,1,14.22,100,1,12.71,100,1,14.26,700,1,12.5,700,1,14.28,100,1,12.46,100,1,14.46,300,3,12.43,700,1,14.48,700,1,12.42,700,1,14.49,100,1,ARL,340527921
,2025-07-17T16:14:10.878435316Z,2025-07-17T16:14:10.878435316Z,10,2,1108,A,A,8,14.47,100,130,165883,283317367,13.11,100,1,13.51,15,1,12.98,200,2,13.52,100,1,12.96,2,1,13.74,2,1,12.86,100,1,13.85,100,1,12.73,100,1,14.22,100,1,12.71,100,1,14.26,700,1,12.5,700,1,14.28,100,1,12.46,100,1,14.46,300,3,12.43,700,1,14.47,100,1,12.42,700,1,14.48,700,1,ARL,340527969
,2025-07-17T16:14:10.892513823Z,2025-07-17T16:14:10.892513823Z,10,2,1108,A,A,8,14.47,100,130,165691,283317451,13.11,100,1,13.51,15,1,12.98,200,2,13.52,100,1,12.96,2,1,13.74,2,1,12.86,100,1,13.85,100,1,12.73,100,1,14.22,100,1,12.71,100,1,14.26,700,1,12.5,700,1,14.28,100,1,12.46,100,1,14.46,300,3,12.43,700,1,14.47,200,2,12.42,700,1,14.48,700,1,ARL,340528121
,2025-07-17T16:14:10.985342000Z,2025-07-17T16:14:10.985342000Z,10,2,1108,C,A,7,14.46,100,0,165716,283318181,13.11,100,1,13.51,15,1,12.98,200,2,13.52,100,1,12.96,2,1,13.74,2,1,12.86,100,1,13.85,100,1,12.73,100,1,14.22,100,1,12.71,100,1,14.26,700,1,12.5,700,1,14.28,100,1,12.46,100,1,14.46,200,2,12.43,700,1,14.47,200,2,12.42,700,1,14.48,700,1,ARL,339359421
,2025-07-17T16:14:10.985342000Z,2025-07-17T16:14:10.985342000Z,10,2,1108,A,A,7,14.31,100,130,165716,283318181,13.11,100,1,13.51,15,1,12.98,200,2,13.52,100,1,12.96,2,1,13.74,2,1,12.86,100,1,13.85,100,1,12.73,100,1,14.22,100,1,12.71,100,1,14.26,700,1,12.5,700,1,14.28,100,1,12.46,100,1,14.31,100,1,12.43,700,1,14.46,200,2,12.42,700,1,14.47,200,2,ARL,340529021
,2025-07-17T16:14:19.528322793Z,2025-07-17T16:14:19.528322793Z,10,2,1108,A,A,0,13.49,15,130,165440,283419160,13.11,100,1,13.49,15,1,12.98,200,2,13.51,15,1,12.96,2,1,13.52,100,1,12.86,100,1,13.74,2,1,12.73,100,1,13.85,100,1,12.71,100,1,14.22,100,1,12.5,700,1,14.26,700,1,12.46,100,1,14.28,100,1,12.43,700,1,14.31,100,1,12.42,700,1,14.46,200,2,ARL,340664453
,2025-07-17T16:14:21.306599291Z,2025-07-17T16:14:21.306599291Z,10,2,1108,C,A,2,13.52,100,0,165679,283454179,13.11,100,1,13.49,15,1,12.98,200,2,13.51,15,1,12.96,2,1,13.74,2,1,12.86,100,1,13.85,100,1,12.73,100,1,14.22,100,1,12.71,100,1,14.26,700,1,12.5,700,1,14.28,100,1,12.46,100,1,14.31,100,1,12.43,700,1,14.46,200,2,12.42,700,1,14.47,200,2,ARL,340527921
,2025-07-17T16:14:21.306599291Z,2025-07-17T16:14:21.306599291Z,10,2,1108,A,A,1,13.5,100,130,165679,283454179,13.11,100,1,13.49,15,1,12.98,200,2,13.5,100,1,12.96,2,1,13.51,15,1,12.86,100,1,13.74,2,1,12.73,100,1,13.85,100,1,12.71,100,1,14.22,100,1,12.5,700,1,14.26,700,1,12.46,100,1,14.28,100,1,12.43,700,1,14.31,100,1,12.42,700,1,14.46,200,2,ARL,340704401
,2025-07-17T16:14:21.317096752Z,2025-07-17T16:14:21.317096752Z,10,2,1108,C,A,4,13.85,100,130,165239,283454878,13.11,100,1,13.49,15,1,12.98,200,2,13.5,100,1,12.96,2,1,13.51,15,1,12.86,100,1,13.74,2,1,12.73,100,1,14.22,100,1,12.71,100,1,14.26,700,1,12.5,700,1,14.28,100,1,12.46,100,1,14.31,100,1,12.43,700,1,14.46,200,2,12.42,700,1,14.47,200,2,ARL,339642033
,2025-07-17T16:14:21.317148983Z,2025-07-17T16:14:21.317148983Z,10,2,1108,A,A,4,13.77,100,130,165153,283454882,13.11,100,1,13.49,15,1,12.98,200,2,13.5,100,1,12.96,2,1,13.51,15,1,12.86,100,1,13.74,2,1,12.73,100,1,13.77,100,1,12.71,100,1,14.22,100,1,12.5,700,1,14.26,700,1,12.46,100,1,14.28,100,1,12.43,700,1,14.31,100,1,12.42,700,1,14.46,200,2,ARL,340705133
,2025-07-17T16:14:36.523382949Z,2025-07-17T16:14:36.523382949Z,10,2,1108,C,A,0,13.49,15,128,170400,283655411,13.11,100,1,13.5,100,1,12.98,200,2,13.51,15,1,12.96,2,1,13.74,2,1,12.86,100,1,13.77,100,1,12.73,100,1,14.22,100,1,12.71,100,1,14.26,700,1,12.5,700,1,14.28,100,1,12.46,100,1,14.31,100,1,12.43,700,1,14.46,200,2,12.42,700,1,14.47,200,2,ARL,340664453
,2025-07-17T16:14:36.523564373Z,2025-07-17T16:14:36.523564373Z,10,2,1108,C,A,1,13.51,15,128,166127,283655455,13.11,100,1,13.5,100,1,12.98,200,2,13.74,2,1,12.96,2,1,13.77,100,1,12.86,100,1,14.22,100,1,12.73,100,1,14.26,700,1,12.71,100,1,14.28,100,1,12.5,700,1,14.31,100,1,12.46,100,1,14.46,200,2,12.43,700,1,14.47,200,2,12.42,700,1,14.48,700,1,ARL,340526285
,2025-07-17T16:14:36.523696080Z,2025-07-17T16:14:36.523696080Z,10,2,1108,A,A,0,13.5,99,128,166260,283655477,13.11,100,1,13.5,199,2,12.98,200,2,13.74,2,1,12.96,2,1,13.77,100,1,12.86,100,1,14.22,100,1,12.73,100,1,14.26,700,1,12.71,100,1,14.28,100,1,12.5,700,1,14.31,100,1,12.46,100,1,14.46,200,2,12.43,700,1,14.47,200,2,12.42,700,1,14.48,700,1,ARL,340971661
,2025-07-17T16:14:52.280428336Z,2025-07-17T16:14:52.280428336Z,10,2,1108,C,A,0,13.5,99,130,165342,283870929,13.11,100,1,13.5,100,1,12.98,200,2,13.74,2,1,12.96,2,1,13.77,100,1,12.86,100,1,14.22,100,1,12.73,100,1,14.26,700,1,12.71,100,1,14.28,100,1,12.5,700,1,14.31,100,1,12.46,100,1,14.46,200,2,12.43,700,1,14.47,200,2,12.42,700,1,14.48,700,1,ARL,340971661
,2025-07-17T16:14:52.296871817Z,2025-07-17T16:14:52.296871817Z,10,2,1108,A,A,0,13.48,15,130,165308,283871393,13.11,100,1,13.48,15,1,12.98,200,2,13.5,100,1,12.96,2,1,13.74,2,1,12.86,100,1,13.77,100,1,12.73,100,1,14.22,100,1,12.71,100,1,14.26,700,1,12.5,700,1,14.28,100,1,12.46,100,1,14.31,100,1,12.43,700,1,14.46,200,2,12.42,700,1,14.47,200,2,ARL,341248825
,2025-07-17T16:14:52.828556785Z,2025-07-17T16:14:52.828556785Z,10,2,1108,C,A,0,13.48,15,130,165082,283875146,13.11,100,1,13.5,100,1,12.98,200,2,13.74,2,1,12.96,2,1,13.77,100,1,12.86,100,1,14.22,100,1,12.73,100,1,14.26,700,1,12.71,100,1,14.28,100,1,12.5,700,1,14.31,100,1,12.46,100,1,14.46,200,2,12.43,700,1,14.47,200,2,12.42,700,1,14.48,700,1,ARL,341248825
,2025-07-17T16:14:52.828868258Z,2025-07-17T16:14:52.828868258Z,10,2,1108,A,A,0,13.5,99,130,165455,283875150,13.11,100,1,13.5,199,2,12.98,200,2,13.74,2,1,12.96,2,1,13.77,100,1,12.86,100,1,14.22,100,1,12.73,100,1,14.26,700,1,12.71,100,1,14.28,100,1,12.5,700,1,14.31,100,1,12.46,100,1,14.46,200,2,12.43,700,1,14.47,200,2,12.42,700,1,14.48,700,1,ARL,341253573
,2025-07-17T16:15:16.987204735Z,2025-07-17T16:15:16.987204735Z,10,2,1108,C,A,0,13.5,99,130,165236,284194889,13.11,100,1,13.5,100,1,12.98,200,2,13.74,2,1,12.96,2,1,13.77,100,1,12.86,100,1,14.22,100,1,12.73,100,1,14.26,700,1,12.71,100,1,14.28,100,1,12.5,700,1,14.31,100,1,12.46,100,1,14.46,200,2,12.43,700,1,14.47,200,2,12.42,700,1,14.48,700,1,ARL,341253573
,2025-07-17T16:15:16.987249289Z,2025-07-17T16:15:16.987249289Z,10,2,1108,C,A,0,13.5,100,130,165386,284194891,13.11,100,1,13.74,2,1,12.98,200,2,13.77,100,1,12.96,2,1,14.22,100,1,12.86,100,1,14.26,700,1,12.73,100,1,14.28,100,1,12.71,100,1,14.31,100,1,12.5,700,1,14.46,200,2,12.46,100,1,14.47,200,2,12.43,700,1,14.48,700,1,12.42,700,1,14.49,100,1,ARL,340704401
,2025-07-17T16:15:16.987524101Z,2025-07-17T16:15:16.987524101Z,10,2,1108,C,A,3,14.26,700,130,165392,284194901,13.11,100,1,13.74,2,1,12.98,200,2,13.77,100,1,12.96,2,1,14.22,100,1,12.86,100,1,14.28,100,1,12.73,100,1,14.31,100,1,12.71,100,1,14.46,200,2,12.5,700,1,14.47,200,2,12.46,100,1,14.48,700,1,12.43,700,1,14.49,100,1,12.42,700,1,14.54,700,1,ARL,339716321
,2025-07-17T16:15:16.987579177Z,2025-07-17T16:15:16.987579177Z,10,2,1108,A,A,5,14.46,700,130,165291,284194908,13.11,100,1,13.74,2,1,12.98,200,2,13.77,100,1,12.96,2,1,14.22,100,1,12.86,100,1,14.28,100,1,12.73,100,1,14.31,100,1,12.71,100,1,14.46,900,3,12.5,700,1,14.47,200,2,12.46,100,1,14.48,700,1,12.43,700,1,14.49,100,1,12.42,700,1,14.54,700,1,ARL,341661841
,2025-07-17T16:15:16.987980299Z,2025-07-17T16:15:16.987980299Z,10,2,1108,C,A,10,14.55,100,0,165471,284194935,13.11,100,1,13.74,2,1,12.98,200,2,13.77,100,1,12.96,2,1,14.22,100,1,12.86,100,1,14.28,100,1,12.73,100,1,14.31,100,1,12.71,100,1,14.46,900,3,12.5,700,1,14.47,200,2,12.46,100,1,14.48,700,1,12.43,700,1,14.49,100,1,12.42,700,1,14.54,700,1,ARL,340704465
,2025-07-17T16:15:16.988244795Z,2025-07-17T16:15:16.988244795Z,10,2,1108,C,A,6,14.47,100,0,165474,284194952,13.11,100,1,13.74,2,1,12.98,200,2,13.77,100,1,12.96,2,1,14.22,100,1,12.86,100,1,14.28,100,1,12.73,100,1,14.31,100,1,12.71,100,1,14.46,900,3,12.5,700,1,14.47,100,1,12.46,100,1,14.48,700,1,12.43,700,1,14.49,100,1,12.42,700,1,14.54,700,1,ARL,340527969
,2025-07-17T16:15:16.989720957Z,2025-07-17T16:15:16.989720957Z,10,2,1108,C,A,6,14.47,100,0,165740,284195185,13.11,100,1,13.74,2,1,12.98,200,2,13.77,100,1,12.96,2,1,14.22,100,1,12.86,100,1,14.28,100,1,12.73,100,1,14.31,100,1,12.71,100,1,14.46,900,3,12.5,700,1,14.48,700,1,12.46,100,1,14.49,100,1,12.43,700,1,14.54,700,1,12.42,700,1,14.56,700,1,ARL,340528121
,2025-07-17T16:15:16.992638952Z,2025-07-17T16:15:16.992638952Z,10,2,1108,C,A,4,14.31,100,130,165395,284195309,13.11,100,1,13.74,2,1,12.98,200,2,13.77,100,1,12.96,2,1,14.22,100,1,12.86,100,1,14.28,100,1,12.73,100,1,14.46,900,3,12.71,100,1,14.48,700,1,12.5,700,1,14.49,100,1,12.46,100,1,14.54,700,1,12.43,700,1,14.56,700,1,12.42,700,1,14.6,100,1,ARL,340529021
,2025-07-17T16:15:16.992776612Z,2025-07-17T16:15:16.992776612Z,10,2,1108,A,A,8,14.56,100,130,165355,284195310,13.11,100,1,13.74,2,1,12.98,200,2,13.77,100,1,12.96,2,1,14.22,100,1,12.86,100,1,14.28,100,1,12.73,100,1,14.46,900,3,12.71,100,1,14.48,700,1,12.5,700,1,14.49,100,1,12.46,100,1,14.54,700,1,12.43,700,1,14.56,800,2,12.42,700,1,14.6,100,1,ARL,341661985
,2025-07-17T16:15:17.000422944Z,2025-07-17T16:15:17.000422944Z,10,2,1108,C,A,1,13.77,100,130,165230,284195454,13.11,100,1,13.74,2,1,12.98,200,2,14.22,100,1,12.96,2,1,14.28,100,1,12.86,100,1,14.46,900,3,12.73,100,1,14.48,700,1,12.71,100,1,14.49,100,1,12.5,700,1,14.54,700,1,12.46,100,1,14.56,800,2,12.43,700,1,14.6,100,1,12.42,700,1,14.74,200,2,ARL,340705133
,2025-07-17T16:15:17.000456046Z,2025-07-17T16:15:17.000456046Z,10,2,1108,C,A,3,14.46,700,130,165010,284195456,13.11,100,1,13.74,2,1,12.98,200,2,14.22,100,1,12.96,2,1,14.28,100,1,12.86,100,1,14.46,200,2,12.73,100,1,14.48,700,1,12.71,100,1,14.49,100,1,12.5,700,1,14.54,700,1,12.46,100,1,14.56,800,2,12.43,700,1,14.6,100,1,12.42,700,1,14.74,200,2,ARL,341661841
,2025-07-17T16:15:17.000474862Z,2025-07-17T16:15:17.000474862Z,10,2,1108,A,A,1,14.05,100,130,165171,284195458,13.11,100,1,13.74,2,1,12.98,200,2,14.05,100,1,12.96,2,1,14.22,100,1,12.86,100,1,14.28,100,1,12.73,100,1,14.46,200,2,12.71,100,1,14.48,700,1,12.5,700,1,14.49,100,1,12.46,100,1,14.54,700,1,12.43,700,1,14.56,800,2,12.42,700,1,14.6,100,1,ARL,341662085
,2025-07-17T16:15:17.001158038Z,2025-07-17T16:15:17.001158038Z,10,2,1108,C,A,3,14.28,100,130,165368,284195476,13.11,100,1,13.74,2,1,12.98,200,2,14.05,100,1,12.96,2,1,14.22,100,1,12.86,100,1,14.46,200,2,12.73,100,1,14.48,700,1,12.71,100,1,14.49,100,1,12.5,700,1,14.54,700,1,12.46,100,1,14.56,800,2,12.43,700,1,14.6,100,1,12.42,700,1,14.74,200,2,ARL,339358333
,2025-07-17T16:15:17.001522171Z,2025-07-17T16:15:17.001522171Z,10,2,1108,A,A,8,14.6,100,130,165141,284195477,13.11,100,1,13.74,2,1,12.98,200,2,14.05,100,1,12.96,2,1,14.22,100,1,12.86,100,1,14.46,200,2,12.73,100,1,14.48,700,1,12.71,100,1,14.49,100,1,12.5,700,1,14.54,700,1,12.46,100,1,14.56,800,2,12.43,700,1,14.6,200,2,12.42,700,1,14.74,200,2,ARL,341662113
,2025-07-17T16:15:17.002064284Z,2025-07-17T16:15:17.002064284Z,10,2,1108,C,A,9,14.74,100,0,165679,284195479,13.11,100,1,13.74,2,1,12.98,200,2,14.05,100,1,12.96,2,1,14.22,100,1,12.86,100,1,14.46,200,2,12.73,100,1,14.48,700,1,12.71,100,1,14.49,100,1,12.5,700,1,14.54,700,1,12.46,100,1,14.56,800,2,12.43,700,1,14.6,200,2,12.42,700,1,14.74,100,1,ARL,341661905
,2025-07-17T16:15:17.002064284Z,2025-07-17T16:15:17.002064284Z,10,2,1108,A,A,10,14.96,100,130,165679,284195479,13.11,100,1,13.74,2,1,12.98,200,2,14.05,100,1,12.96,2,1,14.22,100,1,12.86,100,1,14.46,200,2,12.73,100,1,14.48,700,1,12.71,100,1,14.49,100,1,12.5,700,1,14.54,700,1,12.46,100,1,14.56,800,2,12.43,700,1,14.6,200,2,12.42,700,1,14.74,100,1,ARL,341662117
,2025-07-17T16:15:17.003081581Z,2025-07-17T16:15:17.003081581Z,10,2,1108,C,A,9,14.74,100,0,165221,284195486,13.11,100,1,13.74,2,1,12.98,200,2,14.05,100,1,12.96,2,1,14.22,100,1,12.86,100,1,14.46,200,2,12.73,100,1,14.48,700,1,12.71,100,1,14.49,100,1,12.5,700,1,14.54,700,1,12.46,100,1,14.56,800,2,12.43,700,1,14.6,200,2,12.42,700,1,14.96,100,1,ARL,341661877
