,ts_recv,ts_event,rtype,publisher_id,instrument_id,action,side,depth,price,size,flags,ts_in_delta,sequence,bid_px_00,bid_sz_00,bid_ct_00,ask_px_00,ask_sz_00,ask_ct_00,bid_px_01,bid_sz_01,bid_ct_01,ask_px_01,ask_sz_01,ask_ct_01,bid_px_02,bid_sz_02,bid_ct_02,ask_px_02,ask_sz_02,ask_ct_02,bid_px_03,bid_sz_03,bid_ct_03,ask_px_03,ask_sz_03,ask_ct_03,bid_px_04,bid_sz_04,bid_ct_04,ask_px_04,ask_sz_04,ask_ct_04,bid_px_05,bid_sz_05,bid_ct_05,ask_px_05,ask_sz_05,ask_ct_05,bid_px_06,bid_sz_06,bid_ct_06,ask_px_06,ask_sz_06,ask_ct_06,bid_px_07,bid_sz_07,bid_ct_07,ask_px_07,ask_sz_07,ask_ct_07,bid_px_08,bid_sz_08,bid_ct_08,ask_px_08,ask_sz_08,ask_ct_08,bid_px_09,bid_sz_09,bid_ct_09,ask_px_09,ask_sz_09,ask_ct_09,symbol,order_id
,2025-07-17T15:34:28.170575785Z,2025-07-17T15:34:28.170575785Z,10,2,1108,A,A,0,13.81,50,130,165079,242513651,13.26,100,1,13.81,50,1,13.23,2,1,13.83,100,1,13.03,100,1,13.85,100,1,12.73,100,1,13.95,2,1,12.71,100,1,14.12,100,1,12.5,700,1,14.2,50,1,12.46,200,2,14.56,800,2,12.43,700,1,14.6,700,1,12.42,700,1,14.61,100,1,12.37,700,1,14.65,100,1,ARL,288724173
,2025-07-17T15:34:28.170626756Z,2025-07-17T15:34:28.170626756Z,10,2,1108,C,B,0,13.26,100,130,165455,242513653,13.23,2,1,13.81,50,1,13.03,100,1,13.83,100,1,12.73,100,1,13.85,100,1,12.71,100,1,13.95,2,1,12.5,700,1,14.12,100,1,12.46,200,2,14.2,50,1,12.43,700,1,14.56,800,2,12.42,700,1,14.6,700,1,12.37,700,1,14.61,100,1,12.36,200,2,14.65,100,1,ARL,285586221
,2025-07-17T15:34:28.171272157Z,2025-07-17T15:34:28.171272157Z,10,2,1108,A,A,0,13.78,2,130,165285,242513665,13.23,2,1,13.78,2,1,13.03,100,1,13.81,50,1,12.73,100,1,13.83,100,1,12.71,100,1,13.85,100,1,12.5,700,1,13.95,2,1,12.46,200,2,14.12,100,1,12.43,700,1,14.2,50,1,12.42,700,1,14.56,800,2,12.37,700,1,14.6,700,1,12.36,200,2,14.61,100,1,ARL,288724201
,2025-07-17T15:34:28.171439252Z,2025-07-17T15:34:28.171439252Z,10,2,1108,T,N,0,13.41,13,130,165741,242513674,13.23,2,1,13.78,2,1,13.03,100,1,13.81,50,1,12.73,100,1,13.83,100,1,12.71,100,1,13.85,100,1,12.5,700,1,13.95,2,1,12.46,200,2,14.12,100,1,12.43,700,1,14.2,50,1,12.42,700,1,14.56,800,2,12.37,700,1,14.6,700,1,12.36,200,2,14.61,100,1,ARL,0
,2025-07-17T15:34:28.171892519Z,2025-07-17T15:34:28.171892519Z,10,2,1108,A,B,0,13.31,10,130,165407,242513691,13.31,10,1,13.78,2,1,13.23,2,1,13.81,50,1,13.03,100,1,13.83,100,1,12.73,100,1,13.85,100,1,12.71,100,1,13.95,2,1,12.5,700,1,14.12,100,1,12.46,200,2,14.2,50,1,12.43,700,1,14.56,800,2,12.42,700,1,14.6,700,1,12.37,700,1,14.61,100,1,ARL,288724225
,2025-07-17T15:34:28.171893498Z,2025-07-17T15:34:28.171893498Z,10,2,1108,A,A,2,13.82,10,130,165210,242513692,13.31,10,1,13.78,2,1,13.23,2,1,13.81,50,1,13.03,100,1,13.82,10,1,12.73,100,1,13.83,100,1,12.71,100,1,13.85,100,1,12.5,700,1,13.95,2,1,12.46,200,2,14.12,100,1,12.43,700,1,14.2,50,1,12.42,700,1,14.56,800,2,12.37,700,1,14.6,700,1,ARL,288724229
,2025-07-17T15:34:28.174846475Z,2025-07-17T15:34:28.174846475Z,10,2,1108,A,B,1,13.3,100,130,165237,242513742,13.31,10,1,13.78,2,1,13.3,100,1,13.81,50,1,13.23,2,1,13.82,10,1,13.03,100,1,13.83,100,1,12.73,100,1,13.85,100,1,12.71,100,1,13.95,2,1,12.5,700,1,14.12,100,1,12.46,200,2,14.2,50,1,12.43,700,1,14.56,800,2,12.42,700,1,14.6,700,1,ARL,288724429
,2025-07-17T15:34:28.174864618Z,2025-07-17T15:34:28.174864618Z,10,2,1108,C,A,3,13.83,100,0,165507,242513743,13.31,10,1,13.78,2,1,13.3,100,1,13.81,50,1,13.23,2,1,13.82,10,1,13.03,100,1,13.85,100,1,12.73,100,1,13.95,2,1,12.71,100,1,14.12,100,1,12.5,700,1,14.2,50,1,12.46,200,2,14.56,800,2,12.43,700,1,14.6,700,1,12.42,700,1,14.61,100,1,ARL,287560121
,2025-07-17T15:34:28.174864618Z,2025-07-17T15:34:28.174864618Z,10,2,1108,A,A,1,13.79,100,130,165507,242513743,13.31,10,1,13.78,2,1,13.3,100,1,13.79,100,1,13.23,2,1,13.81,50,1,13.03,100,1,13.82,10,1,12.73,100,1,13.85,100,1,12.71,100,1,13.95,2,1,12.5,700,1,14.12,100,1,12.46,200,2,14.2,50,1,12.43,700,1,14.56,800,2,12.42,700,1,14.6,700,1,ARL,288724433
,2025-07-17T15:34:28.175164464Z,2025-07-17T15:34:28.175164464Z,10,2,1108,C,A,0,13.78,2,130,165105,242513747,13.31,10,1,13.79,100,1,13.3,100,1,13.81,50,1,13.23,2,1,13.82,10,1,13.03,100,1,13.85,100,1,12.73,100,1,13.95,2,1,12.71,100,1,14.12,100,1,12.5,700,1,14.2,50,1,12.46,200,2,14.56,800,2,12.43,700,1,14.6,700,1,12.42,700,1,14.61,100,1,ARL,288724201
,2025-07-17T15:34:28.180191067Z,2025-07-17T15:34:28.180191067Z,10,2,1108,A,A,1,13.8,100,130,165469,242513781,13.31,10,1,13.79,100,1,13.3,100,1,13.8,100,1,13.23,2,1,13.81,50,1,13.03,100,1,13.82,10,1,12.73,100,1,13.85,100,1,12.71,100,1,13.95,2,1,12.5,700,1,14.12,100,1,12.46,200,2,14.2,50,1,12.43,700,1,14.56,800,2,12.42,700,1,14.6,700,1,ARL,288724565
,2025-07-17T15:34:28.187072050Z,2025-07-17T15:34:28.187072050Z,10,2,1108,C,A,4,13.85,100,130,165334,242513907,13.31,10,1,13.79,100,1,13.3,100,1,13.8,100,1,13.23,2,1,13.81,50,1,13.03,100,1,13.82,10,1,12.73,100,1,13.95,2,1,12.71,100,1,14.12,100,1,12.5,700,1,14.2,50,1,12.46,200,2,14.56,800,2,12.43,700,1,14.6,700,1,12.42,700,1,14.61,100,1,ARL,287560333
,2025-07-17T15:34:28.192104387Z,2025-07-17T15:34:28.192104387Z,10,2,1108,C,A,0,13.79,100,130,165034,242513974,13.31,10,1,13.8,100,1,13.3,100,1,13.81,50,1,13.23,2,1,13.82,10,1,13.03,100,1,13.95,2,1,12.73,100,1,14.12,100,1,12.71,100,1,14.2,50,1,12.5,700,1,14.56,800,2,12.46,200,2,14.6,700,1,12.43,700,1,14.61,100,1,12.42,700,1,14.65,100,1,ARL,288724433
,2025-07-17T15:34:28.231436134Z,2025-07-17T15:34:28.231436134Z,10,2,1108,A,A,3,13.83,100,130,165186,242514372,13.31,10,1,13.8,100,1,13.3,100,1,13.81,50,1,13.23,2,1,13.82,10,1,13.03,100,1,13.83,100,1,12.73,100,1,13.95,2,1,12.71,100,1,14.12,100,1,12.5,700,1,14.2,50,1,12.46,200,2,14.56,800,2,12.43,700,1,14.6,700,1,12.42,700,1,14.61,100,1,ARL,288725173
,2025-07-17T15:34:28.255958718Z,2025-07-17T15:34:28.255958718Z,10,2,1108,C,A,6,14.2,50,130,165091,242514761,13.31,10,1,13.8,100,1,13.3,100,1,13.81,50,1,13.23,2,1,13.82,10,1,13.03,100,1,13.83,100,1,12.73,100,1,13.95,2,1,12.71,100,1,14.12,100,1,12.5,700,1,14.56,800,2,12.46,200,2,14.6,700,1,12.43,700,1,14.61,100,1,12.42,700,1,14.65,100,1,ARL,288723725
,2025-07-17T15:34:28.271110273Z,2025-07-17T15:34:28.271110273Z,10,2,1108,C,A,1,13.81,50,130,165176,242515164,13.31,10,1,13.8,100,1,13.3,100,1,13.82,10,1,13.23,2,1,13.83,100,1,13.03,100,1,13.95,2,1,12.73,100,1,14.12,100,1,12.71,100,1,14.56,800,2,12.5,700,1,14.6,700,1,12.46,200,2,14.61,100,1,12.43,700,1,14.65,100,1,12.42,700,1,14.68,700,1,ARL,288724173
,2025-07-17T15:34:28.281052249Z,2025-07-17T15:34:28.281052249Z,10,2,1108,C,A,0,13.8,100,130,165121,242515254,13.31,10,1,13.82,10,1,13.3,100,1,13.83,100,1,13.23,2,1,13.95,2,1,13.03,100,1,14.12,100,1,12.73,100,1,14.56,800,2,12.71,100,1,14.6,700,1,12.5,700,1,14.61,100,1,12.46,200,2,14.65,100,1,12.43,700,1,14.68,700,1,12.42,700,1,14.72,200,2,ARL,288724565
,2025-07-17T15:34:32.289244370Z,2025-07-17T15:34:32.289244370Z,10,2,1108,A,A,2,13.84,100,130,165242,242598225,13.31,10,1,13.82,10,1,13.3,100,1,13.83,100,1,13.23,2,1,13.84,100,1,13.03,100,1,13.95,2,1,12.73,100,1,14.12,100,1,12.71,100,1,14.56,800,2,12.5,700,1,14.6,700,1,12.46,200,2,14.61,100,1,12.43,700,1,14.65,100,1,12.42,700,1,14.68,700,1,ARL,288845417
,2025-07-17T15:34:39.864526516Z,2025-07-17T15:34:39.864526516Z,10,2,1108,A,A,0,13.8,15,130,165511,242774235,13.31,10,1,13.8,15,1,13.3,100,1,13.82,10,1,13.23,2,1,13.83,100,1,13.03,100,1,13.84,100,1,12.73,100,1,13.95,2,1,12.71,100,1,14.12,100,1,12.5,700,1,14.56,800,2,12.46,200,2,14.6,700,1,12.43,700,1,14.61,100,1,12.42,700,1,14.65,100,1,ARL,289055901
,2025-07-17T15:34:39.865171719Z,2025-07-17T15:34:39.865171719Z,10,2,1108,C,A,2,13.83,100,0,166213,242774299,13.31,10,1,13.8,15,1,13.3,100,1,13.82,10,1,13.23,2,1,13.84,100,1,13.03,100,1,13.95,2,1,12.73,100,1,14.12,100,1,12.71,100,1,14.56,800,2,12.5,700,1,14.6,700,1,12.46,200,2,14.61,100,1,12.43,700,1,14.65,100,1,12.42,700,1,14.68,700,1,ARL,288725173
,2025-07-17T15:34:39.865171719Z,2025-07-17T15:34:39.865171719Z,10,2,1108,A,A,1,13.81,100,130,166213,242774299,13.31,10,1,13.8,15,1,13.3,100,1,13.81,100,1,13.23,2,1,13.82,10,1,13.03,100,1,13.84,100,1,12.73,100,1,13.95,2,1,12.71,100,1,14.12,100,1,12.5,700,1,14.56,800,2,12.46,200,2,14.6,700,1,12.43,700,1,14.61,100,1,12.42,700,1,14.65,100,1,ARL,289056097
,2025-07-17T15:34:39.869009668Z,2025-07-17T15:34:39.869009668Z,10,2,1108,T,N,0,13.41,1,130,166304,242774413,13.31,10,1,13.8,15,1,13.3,100,1,13.81,100,1,13.23,2,1,13.82,10,1,13.03,100,1,13.84,100,1,12.73,100,1,13.95,2,1,12.71,100,1,14.12,100,1,12.5,700,1,14.56,800,2,12.46,200,2,14.6,700,1,12.43,700,1,14.61,100,1,12.42,700,1,14.65,100,1,ARL,0
,2025-07-17T15:34:39.871441822Z,2025-07-17T15:34:39.871441822Z,10,2,1108,A,A,1,13.81,100,130,165164,242774468,13.31,10,1,13.8,15,1,13.3,100,1,13.81,200,2,13.23,2,1,13.82,10,1,13.03,100,1,13.84,100,1,12.73,100,1,13.95,2,1,12.71,100,1,14.12,100,1,12.5,700,1,14.56,800,2,12.46,200,2,14.6,700,1,12.43,700,1,14.61,100,1,12.42,700,1,14.65,100,1,ARL,289056353
,2025-07-17T15:34:39.878479562Z,2025-07-17T15:34:39.878479562Z,10,2,1108,C,A,3,13.84,100,130,165450,242774619,13.31,10,1,13.8,15,1,13.3,100,1,13.81,200,2,13.23,2,1,13.82,10,1,13.03,100,1,13.95,2,1,12.73,100,1,14.12,100,1,12.71,100,1,14.56,800,2,12.5,700,1,14.6,700,1,12.46,200,2,14.61,100,1,12.43,700,1,14.65,100,1,12.42,700,1,14.68,700,1,ARL,288845417
,2025-07-17T15:34:42.774024574Z,2025-07-17T15:34:42.774024574Z,10,2,1108,C,B,0,13.31,10,130,165467,242816556,13.3,100,1,13.8,15,1,13.23,2,1,13.81,200,2,13.03,100,1,13.82,10,1,12.73,100,1,13.95,2,1,12.71,100,1,14.12,100,1,12.5,700,1,14.56,800,2,12.46,200,2,14.6,700,1,12.43,700,1,14.61,100,1,12.42,700,1,14.65,100,1,12.37,700,1,14.68,700,1,ARL,288724225
,2025-07-17T15:34:42.775139521Z,2025-07-17T15:34:42.775139521Z,10,2,1108,C,A,1,13.81,100,130,165220,242816563,13.3,100,1,13.8,15,1,13.23,2,1,13.81,100,1,13.03,100,1,13.82,10,1,12.73,100,1,13.95,2,1,12.71,100,1,14.12,100,1,12.5,700,1,14.56,800,2,12.46,200,2,14.6,700,1,12.43,700,1,14.61,100,1,12.42,700,1,14.65,100,1,12.37,700,1,14.68,700,1,ARL,289056353
,2025-07-17T15:34:46.773922586Z,2025-07-17T15:34:46.773922586Z,10,2,1108,C,A,0,13.8,15,130,165359,242893860,13.3,100,1,13.81,100,1,13.23,2,1,13.82,10,1,13.03,100,1,13.95,2,1,12.73,100,1,14.12,100,1,12.71,100,1,14.56,800,2,12.5,700,1,14.6,700,1,12.46,200,2,14.61,100,1,12.43,700,1,14.65,100,1,12.42,700,1,14.68,700,1,12.37,700,1,14.72,200,2,ARL,289055901
,2025-07-17T15:34:46.800789632Z,2025-07-17T15:34:46.800789632Z,10,2,1108,A,A,2,13.83,100,130,165425,242894153,13.3,100,1,13.81,100,1,13.23,2,1,13.82,10,1,13.03,100,1,13.83,100,1,12.73,100,1,13.95,2,1,12.71,100,1,14.12,100,1,12.5,700,1,14.56,800,2,12.46,200,2,14.6,700,1,12.43,700,1,14.61,100,1,12.42,700,1,14.65,100,1,12.37,700,1,14.68,700,1,ARL,289199221
,2025-07-17T15:34:53.545665068Z,2025-07-17T15:34:53.545665068Z,10,2,1108,C,A,1,13.82,10,130,165636,243011340,13.3,100,1,13.81,100,1,13.23,2,1,13.83,100,1,13.03,100,1,13.95,2,1,12.73,100,1,14.12,100,1,12.71,100,1,14.56,800,2,12.5,700,1,14.6,700,1,12.46,200,2,14.61,100,1,12.43,700,1,14.65,100,1,12.42,700,1,14.68,700,1,12.37,700,1,14.72,200,2,ARL,288724229
,2025-07-17T15:35:05.620598378Z,2025-07-17T15:35:05.620598378Z,10,2,1108,A,A,0,13.77,15,130,165550,243344672,13.3,100,1,13.77,15,1,13.23,2,1,13.81,100,1,13.03,100,1,13.83,100,1,12.73,100,1,13.95,2,1,12.71,100,1,14.12,100,1,12.5,700,1,14.56,800,2,12.46,200,2,14.6,700,1,12.43,700,1,14.61,100,1,12.42,700,1,14.65,100,1,12.37,700,1,14.68,700,1,ARL,289722397
,2025-07-17T15:35:05.712409728Z,2025-07-17T15:35:05.712409728Z,10,2,1108,C,A,1,13.81,100,0,165515,243347940,13.3,100,1,13.77,15,1,13.23,2,1,13.83,100,1,13.03,100,1,13.95,2,1,12.73,100,1,14.12,100,1,12.71,100,1,14.56,800,2,12.5,700,1,14.6,700,1,12.46,200,2,14.61,100,1,12.43,700,1,14.65,100,1,12.42,700,1,14.68,700,1,12.37,700,1,14.72,200,2,ARL,289056097
,2025-07-17T15:35:05.712409728Z,2025-07-17T15:35:05.712409728Z,10,2,1108,A,A,1,13.78,100,130,165515,243347940,13.3,100,1,13.77,15,1,13.23,2,1,13.78,100,1,13.03,100,1,13.83,100,1,12.73,100,1,13.95,2,1,12.71,100,1,14.12,100,1,12.5,700,1,14.56,800,2,12.46,200,2,14.6,700,1,12.43,700,1,14.61,100,1,12.42,700,1,14.65,100,1,12.37,700,1,14.68,700,1,ARL,289726281
,2025-07-17T15:35:05.713150123Z,2025-07-17T15:35:05.713150123Z,10,2,1108,C,A,7,14.61,100,130,165327,243347987,13.3,100,1,13.77,15,1,13.23,2,1,13.78,100,1,13.03,100,1,13.83,100,1,12.73,100,1,13.95,2,1,12.71,100,1,14.12,100,1,12.5,700,1,14.56,800,2,12.46,200,2,14.6,700,1,12.43,700,1,14.65,100,1,12.42,700,1,14.68,700,1,12.37,700,1,14.72,200,2,ARL,237978629
,2025-07-17T15:35:05.713508657Z,2025-07-17T15:35:05.713508657Z,10,2,1108,A,A,5,14.4,100,128,168434,243348032,13.3,100,1,13.77,15,1,13.23,2,1,13.78,100,1,13.03,100,1,13.83,100,1,12.73,100,1,13.95,2,1,12.71,100,1,14.12,100,1,12.5,700,1,14.4,100,1,12.46,200,2,14.56,800,2,12.43,700,1,14.6,700,1,12.42,700,1,14.65,100,1,12.37,700,1,14.68,700,1,ARL,289726421
,2025-07-17T15:35:05.729398505Z,2025-07-17T15:35:05.729398505Z,10,2,1108,A,A,2,13.8,100,128,170372,243351264,13.3,100,1,13.77,15,1,13.23,2,1,13.78,100,1,13.03,100,1,13.8,100,1,12.73,100,1,13.83,100,1,12.71,100,1,13.95,2,1,12.5,700,1,14.12,100,1,12.46,200,2,14.4,100,1,12.43,700,1,14.56,800,2,12.42,700,1,14.6,700,1,12.37,700,1,14.65,100,1,ARL,289730309
,2025-07-17T15:35:05.737802616Z,2025-07-17T15:35:05.737802616Z,10,2,1108,C,A,3,13.83,100,130,165340,243352644,13.3,100,1,13.77,15,1,13.23,2,1,13.78,100,1,13.03,100,1,13.8,100,1,12.73,100,1,13.95,2,1,12.71,100,1,14.12,100,1,12.5,700,1,14.4,100,1,12.46,200,2,14.56,800,2,12.43,700,1,14.6,700,1,12.42,700,1,14.65,100,1,12.37,700,1,14.68,700,1,ARL,289199221
,2025-07-17T15:35:06.286407017Z,2025-07-17T15:35:06.286407017Z,10,2,1108,C,A,0,13.77,15,130,165318,243362628,13.3,100,1,13.78,100,1,13.23,2,1,13.8,100,1,13.03,100,1,13.95,2,1,12.73,100,1,14.12,100,1,12.71,100,1,14.4,100,1,12.5,700,1,14.56,800,2,12.46,200,2,14.6,700,1,12.43,700,1,14.65,100,1,12.42,700,1,14.68,700,1,12.37,700,1,14.72,200,2,ARL,289722397
,2025-07-17T15:35:09.788115219Z,2025-07-17T15:35:09.788115219Z,10,2,1108,C,B,1,13.23,2,0,165712,243432828,13.3,100,1,13.78,100,1,13.03,100,1,13.8,100,1,12.73,100,1,13.95,2,1,12.71,100,1,14.12,100,1,12.5,700,1,14.4,100,1,12.46,200,2,14.56,800,2,12.43,700,1,14.6,700,1,12.42,700,1,14.65,100,1,12.37,700,1,14.68,700,1,12.36,200,2,14.72,200,2,ARL,272263853
,2025-07-17T15:35:09.788115219Z,2025-07-17T15:35:09.788115219Z,10,2,1108,A,B,1,13.14,2,130,165712,243432828,13.3,100,1,13.78,100,1,13.14,2,1,13.8,100,1,13.03,100,1,13.95,2,1,12.73,100,1,14.12,100,1,12.71,100,1,14.4,100,1,12.5,700,1,14.56,800,2,12.46,200,2,14.6,700,1,12.43,700,1,14.65,100,1,12.42,700,1,14.68,700,1,12.37,700,1,14.72,200,2,ARL,289828293
,2025-07-17T15:35:11.891701845Z,2025-07-17T15:35:11.891701845Z,10,2,1108,C,A,1,13.8,100,130,165164,243482295,13.3,100,1,13.78,100,1,13.14,2,1,13.95,2,1,13.03,100,1,14.12,100,1,12.73,100,1,14.4,100,1,12.71,100,1,14.56,800,2,12.5,700,1,14.6,700,1,12.46,200,2,14.65,100,1,12.43,700,1,14.68,700,1,12.42,700,1,14.72,200,2,12.37,700,1,14.81,200,2,ARL,289730309
,2025-07-17T15:35:14.301481698Z,2025-07-17T15:35:14.301481698Z,10,2,1108,A,A,7,14.68,700,130,165315,243521615,13.3,100,1,13.78,100,1,13.14,2,1,13.95,2,1,13.03,100,1,14.12,100,1,12.73,100,1,14.4,100,1,12.71,100,1,14.56,800,2,12.5,700,1,14.6,700,1,12.46,200,2,14.65,100,1,12.43,700,1,14.68,1400,2,12.42,700,1,14.72,200,2,12.37,700,1,14.81,200,2,ARL,289932801
,2025-07-17T15:35:15.940479233Z,2025-07-17T15:35:15.940479233Z,10,2,1108,A,A,1,13.82,100,130,165183,243557058,13.3,100,1,13.78,100,1,13.14,2,1,13.82,100,1,13.03,100,1,13.95,2,1,12.73,100,1,14.12,100,1,12.71,100,1,14.4,100,1,12.5,700,1,14.56,800,2,12.46,200,2,14.6,700,1,12.43,700,1,14.65,100,1,12.42,700,1,14.68,1400,2,12.37,700,1,14.72,200,2,ARL,289976125
,2025-07-17T15:35:23.746509184Z,2025-07-17T15:35:23.746509184Z,10,2,1108,A,A,1,13.8,100,130,165130,243692012,13.3,100,1,13.78,100,1,13.14,2,1,13.8,100,1,13.03,100,1,13.82,100,1,12.73,100,1,13.95,2,1,12.71,100,1,14.12,100,1,12.5,700,1,14.4,100,1,12.46,200,2,14.56,800,2,12.43,700,1,14.6,700,1,12.42,700,1,14.65,100,1,12.37,700,1,14.68,1400,2,ARL,290159301
,2025-07-17T15:35:23.754453294Z,2025-07-17T15:35:23.754453294Z,10,2,1108,C,A,2,13.82,100,130,165252,243692501,13.3,100,1,13.78,100,1,13.14,2,1,13.8,100,1,13.03,100,1,13.95,2,1,12.73,100,1,14.12,100,1,12.71,100,1,14.4,100,1,12.5,700,1,14.56,800,2,12.46,200,2,14.6,700,1,12.43,700,1,14.65,100,1,12.42,700,1,14.68,1400,2,12.37,700,1,14.72,200,2,ARL,289976125
,2025-07-17T15:35:39.056513985Z,2025-07-17T15:35:39.056513985Z,10,2,1108,C,A,1,13.8,100,130,165615,243992725,13.3,100,1,13.78,100,1,13.14,2,1,13.95,2,1,13.03,100,1,14.12,100,1,12.73,100,1,14.4,100,1,12.71,100,1,14.56,800,2,12.5,700,1,14.6,700,1,12.46,200,2,14.65,100,1,12.43,700,1,14.68,1400,2,12.42,700,1,14.72,200,2,12.37,700,1,14.81,200,2,ARL,290159301
,2025-07-17T15:35:43.128644252Z,2025-07-17T15:35:43.128644252Z,10,2,1108,A,A,1,13.82,100,130,165465,244078096,13.3,100,1,13.78,100,1,13.14,2,1,13.82,100,1,13.03,100,1,13.95,2,1,12.73,100,1,14.12,100,1,12.71,100,1,14.4,100,1,12.5,700,1,14.56,800,2,12.46,200,2,14.6,700,1,12.43,700,1,14.65,100,1,12.42,700,1,14.68,1400,2,12.37,700,1,14.72,200,2,ARL,290630573
,2025-07-17T15:36:30.043928872Z,2025-07-17T15:36:30.043928872Z,10,2,1108,A,A,1,13.8,100,130,165637,245013624,13.3,100,1,13.78,100,1,13.14,2,1,13.8,100,1,13.03,100,1,13.82,100,1,12.73,100,1,13.95,2,1,12.71,100,1,14.12,100,1,12.5,700,1,14.4,100,1,12.46,200,2,14.56,800,2,12.43,700,1,14.6,700,1,12.42,700,1,14.65,100,1,12.37,700,1,14.68,1400,2,ARL,291778909
,2025-07-17T15:36:30.050880126Z,2025-07-17T15:36:30.050880126Z,10,2,1108,C,A,2,13.82,100,130,165327,245013914,13.3,100,1,13.78,100,1,13.14,2,1,13.8,100,1,13.03,100,1,13.95,2,1,12.73,100,1,14.12,100,1,12.71,100,1,14.4,100,1,12.5,700,1,14.56,800,2,12.46,200,2,14.6,700,1,12.43,700,1,14.65,100,1,12.42,700,1,14.68,1400,2,12.37,700,1,14.72,200,2,ARL,290630573
,2025-07-17T15:36:34.297844579Z,2025-07-17T15:36:34.297844579Z,10,2,1108,C,B,0,13.3,100,130,165426,245144122,13.14,2,1,13.78,100,1,13.03,100,1,13.8,100,1,12.73,100,1,13.95,2,1,12.71,100,1,14.12,100,1,12.5,700,1,14.4,100,1,12.46,200,2,14.56,800,2,12.43,700,1,14.6,700,1,12.42,700,1,14.65,100,1,12.37,700,1,14.68,1400,2,12.36,200,2,14.72,200,2,ARL,288724429
,2025-07-17T15:36:35.381165559Z,2025-07-17T15:36:35.381165559Z,10,2,1108,A,B,1,13.13,100,130,165250,245161447,13.14,2,1,13.78,100,1,13.13,100,1,13.8,100,1,13.03,100,1,13.95,2,1,12.73,100,1,14.12,100,1,12.71,100,1,14.4,100,1,12.5,700,1,14.56,800,2,12.46,200,2,14.6,700,1,12.43,700,1,14.65,100,1,12.42,700,1,14.68,1400,2,12.37,700,1,14.72,200,2,ARL,291951937
,2025-07-17T15:36:35.532685683Z,2025-07-17T15:36:35.532685683Z,10,2,1108,A,B,0,13.27,10,130,165349,245174454,13.27,10,1,13.78,100,1,13.14,2,1,13.8,100,1,13.13,100,1,13.95,2,1,13.03,100,1,14.12,100,1,12.73,100,1,14.4,100,1,12.71,100,1,14.56,800,2,12.5,700,1,14.6,700,1,12.46,200,2,14.65,100,1,12.43,700,1,14.68,1400,2,12.42,700,1,14.72,200,2,ARL,291964737
,2025-07-17T15:36:36.151966883Z,2025-07-17T15:36:36.151966883Z,10,2,1108,C,B,2,13.13,100,0,165644,245183955,13.27,10,1,13.78,100,1,13.14,2,1,13.8,100,1,13.03,100,1,13.95,2,1,12.73,100,1,14.12,100,1,12.71,100,1,14.4,100,1,12.5,700,1,14.56,800,2,12.46,200,2,14.6,700,1,12.43,700,1,14.65,100,1,12.42,700,1,14.68,1400,2,12.37,700,1,14.72,200,2,ARL,291951937
,2025-07-17T15:36:36.151966883Z,2025-07-17T15:36:36.151966883Z,10,2,1108,A,B,1,13.26,100,130,165644,245183955,13.27,10,1,13.78,100,1,13.26,100,1,13.8,100,1,13.14,2,1,13.95,2,1,13.03,100,1,14.12,100,1,12.73,100,1,14.4,100,1,12.71,100,1,14.56,800,2,12.5,700,1,14.6,700,1,12.46,200,2,14.65,100,1,12.43,700,1,14.68,1400,2,12.42,700,1,14.72,200,2,ARL,291975017
,2025-07-17T15:36:46.889749756Z,2025-07-17T15:36:46.889749756Z,10,2,1108,C,B,0,13.27,10,128,167522,245499598,13.26,100,1,13.78,100,1,13.14,2,1,13.8,100,1,13.03,100,1,13.95,2,1,12.73,100,1,14.12,100,1,12.71,100,1,14.4,100,1,12.5,700,1,14.56,800,2,12.46,200,2,14.6,700,1,12.43,700,1,14.65,100,1,12.42,700,1,14.68,1400,2,12.37,700,1,14.72,200,2,ARL,291964737
,2025-07-17T15:36:46.986655137Z,2025-07-17T15:36:46.986655137Z,10,2,1108,C,A,1,13.8,100,130,165254,245503745,13.26,100,1,13.78,100,1,13.14,2,1,13.95,2,1,13.03,100,1,14.12,100,1,12.73,100,1,14.4,100,1,12.71,100,1,14.56,800,2,12.5,700,1,14.6,700,1,12.46,200,2,14.65,100,1,12.43,700,1,14.68,1400,2,12.42,700,1,14.72,200,2,12.37,700,1,14.81,200,2,ARL,291778909
,2025-07-17T15:36:50.997269299Z,2025-07-17T15:36:50.997269299Z,10,2,1108,A,A,1,13.82,100,130,165390,245564901,13.26,100,1,13.78,100,1,13.14,2,1,13.82,100,1,13.03,100,1,13.95,2,1,12.73,100,1,14.12,100,1,12.71,100,1,14.4,100,1,12.5,700,1,14.56,800,2,12.46,200,2,14.6,700,1,12.43,700,1,14.65,100,1,12.42,700,1,14.68,1400,2,12.37,700,1,14.72,200,2,ARL,292434813
,2025-07-17T15:37:40.389572053Z,2025-07-17T15:37:40.389572053Z,10,2,1108,C,B,1,13.14,2,0,165520,246491394,13.26,100,1,13.78,100,1,13.03,100,1,13.82,100,1,12.73,100,1,13.95,2,1,12.71,100,1,14.12,100,1,12.5,700,1,14.4,100,1,12.46,200,2,14.56,800,2,12.43,700,1,14.6,700,1,12.42,700,1,14.65,100,1,12.37,700,1,14.68,1400,2,12.36,200,2,14.72,200,2,ARL,289828293
,2025-07-17T15:37:40.389572053Z,2025-07-17T15:37:40.389572053Z,10,2,1108,A,B,1,13.04,2,130,165520,246491394,13.26,100,1,13.78,100,1,13.04,2,1,13.82,100,1,13.03,100,1,13.95,2,1,12.73,100,1,14.12,100,1,12.71,100,1,14.4,100,1,12.5,700,1,14.56,800,2,12.46,200,2,14.6,700,1,12.43,700,1,14.65,100,1,12.42,700,1,14.68,1400,2,12.37,700,1,14.72,200,2,ARL,293594281
,2025-07-17T15:39:27.069942913Z,2025-07-17T15:39:27.069942913Z,10,2,1108,A,A,1,13.8,100,128,166756,248436908,13.26,100,1,13.78,100,1,13.04,2,1,13.8,100,1,13.03,100,1,13.82,100,1,12.73,100,1,13.95,2,1,12.71,100,1,14.12,100,1,12.5,700,1,14.4,100,1,12.46,200,2,14.56,800,2,12.43,700,1,14.6,700,1,12.42,700,1,14.65,100,1,12.37,700,1,14.68,1400,2,ARL,296059685
,2025-07-17T15:39:27.077400388Z,2025-07-17T15:39:27.077400388Z,10,2,1108,C,A,2,13.82,100,130,165514,248437548,13.26,100,1,13.78,100,1,13.04,2,1,13.8,100,1,13.03,100,1,13.95,2,1,12.73,100,1,14.12,100,1,12.71,100,1,14.4,100,1,12.5,700,1,14.56,800,2,12.46,200,2,14.6,700,1,12.43,700,1,14.65,100,1,12.42,700,1,14.68,1400,2,12.37,700,1,14.72,200,2,ARL,292434813
,2025-07-17T15:39:30.509687817Z,2025-07-17T15:39:30.509687817Z,10,2,1108,A,A,0,13.76,15,130,165266,248491930,13.26,100,1,13.76,15,1,13.04,2,1,13.78,100,1,13.03,100,1,13.8,100,1,12.73,100,1,13.95,2,1,12.71,100,1,14.12,100,1,12.5,700,1,14.4,100,1,12.46,200,2,14.56,800,2,12.43,700,1,14.6,700,1,12.42,700,1,14.65,100,1,12.37,700,1,14.68,1400,2,ARL,296136617
,2025-07-17T15:39:30.573052284Z,2025-07-17T15:39:30.573052284Z,10,2,1108,C,A,1,13.78,100,0,165559,248492793,13.26,100,1,13.76,15,1,13.04,2,1,13.8,100,1,13.03,100,1,13.95,2,1,12.73,100,1,14.12,100,1,12.71,100,1,14.4,100,1,12.5,700,1,14.56,800,2,12.46,200,2,14.6,700,1,12.43,700,1,14.65,100,1,12.42,700,1,14.68,1400,2,12.37,700,1,14.72,200,2,ARL,289726281
,2025-07-17T15:39:30.573052284Z,2025-07-17T15:39:30.573052284Z,10,2,1108,A,A,1,13.77,100,130,165559,248492793,13.26,100,1,13.76,15,1,13.04,2,1,13.77,100,1,13.03,100,1,13.8,100,1,12.73,100,1,13.95,2,1,12.71,100,1,14.12,100,1,12.5,700,1,14.4,100,1,12.46,200,2,14.56,800,2,12.43,700,1,14.6,700,1,12.42,700,1,14.65,100,1,12.37,700,1,14.68,1400,2,ARL,296137537
,2025-07-17T15:39:30.589004378Z,2025-07-17T15:39:30.589004378Z,10,2,1108,C,A,4,14.12,100,130,165442,248493012,13.26,100,1,13.76,15,1,13.04,2,1,13.77,100,1,13.03,100,1,13.8,100,1,12.73,100,1,13.95,2,1,12.71,100,1,14.4,100,1,12.5,700,1,14.56,800,2,12.46,200,2,14.6,700,1,12.43,700,1,14.65,100,1,12.42,700,1,14.68,1400,2,12.37,700,1,14.72,200,2,ARL,286680917
,2025-07-17T15:39:30.589059301Z,2025-07-17T15:39:30.589059301Z,10,2,1108,A,A,4,14.05,100,130,165295,248493014,13.26,100,1,13.76,15,1,13.04,2,1,13.77,100,1,13.03,100,1,13.8,100,1,12.73,100,1,13.95,2,1,12.71,100,1,14.05,100,1,12.5,700,1,14.4,100,1,12.46,200,2,14.56,800,2,12.43,700,1,14.6,700,1,12.42,700,1,14.65,100,1,12.37,700,1,14.68,1400,2,ARL,296137769
,2025-07-17T15:39:31.091844988Z,2025-07-17T15:39:31.091844988Z,10,2,1108,A,A,2,13.78,100,130,165381,248502203,13.26,100,1,13.76,15,1,13.04,2,1,13.77,100,1,13.03,100,1,13.78,100,1,12.73,100,1,13.8,100,1,12.71,100,1,13.95,2,1,12.5,700,1,14.05,100,1,12.46,200,2,14.4,100,1,12.43,700,1,14.56,800,2,12.42,700,1,14.6,700,1,12.37,700,1,14.65,100,1,ARL,296149845
,2025-07-17T15:39:31.098691429Z,2025-07-17T15:39:31.098691429Z,10,2,1108,C,A,3,13.8,100,130,165212,248502510,13.26,100,1,13.76,15,1,13.04,2,1,13.77,100,1,13.03,100,1,13.78,100,1,12.73,100,1,13.95,2,1,12.71,100,1,14.05,100,1,12.5,700,1,14.4,100,1,12.46,200,2,14.56,800,2,12.43,700,1,14.6,700,1,12.42,700,1,14.65,100,1,12.37,700,1,14.68,1400,2,ARL,296059685
,2025-07-17T15:39:40.690971606Z,2025-07-17T15:39:40.690971606Z,10,2,1108,A,A,0,13.73,15,128,179829,248666930,13.26,100,1,13.73,15,1,13.04,2,1,13.76,15,1,13.03,100,1,13.77,100,1,12.73,100,1,13.78,100,1,12.71,100,1,13.95,2,1,12.5,700,1,14.05,100,1,12.46,200,2,14.4,100,1,12.43,700,1,14.56,800,2,12.42,700,1,14.6,700,1,12.37,700,1,14.65,100,1,ARL,296365029
,2025-07-17T15:39:40.696182148Z,2025-07-17T15:39:40.696182148Z,10,2,1108,C,A,2,13.77,100,0,167281,248669978,13.26,100,1,13.73,15,1,13.04,2,1,13.76,15,1,13.03,100,1,13.78,100,1,12.73,100,1,13.95,2,1,12.71,100,1,14.05,100,1,12.5,700,1,14.4,100,1,12.46,200,2,14.56,800,2,12.43,700,1,14.6,700,1,12.42,700,1,14.65,100,1,12.37,700,1,14.68,1400,2,ARL,296137537
,2025-07-17T15:39:40.696182148Z,2025-07-17T15:39:40.696182148Z,10,2,1108,A,A,1,13.74,100,130,167281,248669978,13.26,100,1,13.73,15,1,13.04,2,1,13.74,100,1,13.03,100,1,13.76,15,1,12.73,100,1,13.78,100,1,12.71,100,1,13.95,2,1,12.5,700,1,14.05,100,1,12.46,200,2,14.4,100,1,12.43,700,1,14.56,800,2,12.42,700,1,14.6,700,1,12.37,700,1,14.65,100,1,ARL,296368281
,2025-07-17T15:39:40.708645114Z,2025-07-17T15:39:40.708645114Z,10,2,1108,A,A,2,13.76,100,130,165263,248674504,13.26,100,1,13.73,15,1,13.04,2,1,13.74,100,1,13.03,100,1,13.76,115,2,12.73,100,1,13.78,100,1,12.71,100,1,13.95,2,1,12.5,700,1,14.05,100,1,12.46,200,2,14.4,100,1,12.43,700,1,14.56,800,2,12.42,700,1,14.6,700,1,12.37,700,1,14.65,100,1,ARL,296372577
,2025-07-17T15:39:40.731266408Z,2025-07-17T15:39:40.731266408Z,10,2,1108,C,A,3,13.78,100,130,165139,248676672,13.26,100,1,13.73,15,1,13.04,2,1,13.74,100,1,13.03,100,1,13.76,115,2,12.73,100,1,13.95,2,1,12.71,100,1,14.05,100,1,12.5,700,1,14.4,100,1,12.46,200,2,14.56,800,2,12.43,700,1,14.6,700,1,12.42,700,1,14.65,100,1,12.37,700,1,14.68,1400,2,ARL,296149845
,2025-07-17T15:39:41.085699437Z,2025-07-17T15:39:41.085699437Z,10,2,1108,A,A,6,14.56,100,130,165291,248688410,13.26,100,1,13.73,15,1,13.04,2,1,13.74,100,1,13.03,100,1,13.76,115,2,12.73,100,1,13.95,2,1,12.71,100,1,14.05,100,1,12.5,700,1,14.4,100,1,12.46,200,2,14.56,900,3,12.43,700,1,14.6,700,1,12.42,700,1,14.65,100,1,12.37,700,1,14.68,1400,2,ARL,296391881
,2025-07-17T15:39:43.773645905Z,2025-07-17T15:39:43.773645905Z,10,2,1108,C,A,10,14.72,100,0,165869,248737506,13.26,100,1,13.73,15,1,13.04,2,1,13.74,100,1,13.03,100,1,13.76,115,2,12.73,100,1,13.95,2,1,12.71,100,1,14.05,100,1,12.5,700,1,14.4,100,1,12.46,200,2,14.56,900,3,12.43,700,1,14.6,700,1,12.42,700,1,14.65,100,1,12.37,700,1,14.68,1400,2,ARL,286680577
,2025-07-17T15:39:43.773645905Z,2025-07-17T15:39:43.773645905Z,10,2,1108,A,A,8,14.61,100,130,165869,248737506,13.26,100,1,13.73,15,1,13.04,2,1,13.74,100,1,13.03,100,1,13.76,115,2,12.73,100,1,13.95,2,1,12.71,100,1,14.05,100,1,12.5,700,1,14.4,100,1,12.46,200,2,14.56,900,3,12.43,700,1,14.6,700,1,12.42,700,1,14.61,100,1,12.37,700,1,14.65,100,1,ARL,296455037
,2025-07-17T15:39:43.773738855Z,2025-07-17T15:39:43.773738855Z,10,2,1108,A,A,8,14.61,100,130,165618,248737508,13.26,100,1,13.73,15,1,13.04,2,1,13.74,100,1,13.03,100,1,13.76,115,2,12.73,100,1,13.95,2,1,12.71,100,1,14.05,100,1,12.5,700,1,14.4,100,1,12.46,200,2,14.56,900,3,12.43,700,1,14.6,700,1,12.42,700,1,14.61,200,2,12.37,700,1,14.65,100,1,ARL,296455041
,2025-07-17T15:39:44.428505546Z,2025-07-17T15:39:44.428505546Z,10,2,1108,C,A,2,13.76,15,130,165354,248751670,13.26,100,1,13.73,15,1,13.04,2,1,13.74,100,1,13.03,100,1,13.76,100,1,12.73,100,1,13.95,2,1,12.71,100,1,14.05,100,1,12.5,700,1,14.4,100,1,12.46,200,2,14.56,900,3,12.43,700,1,14.6,700,1,12.42,700,1,14.61,200,2,12.37,700,1,14.65,100,1,ARL,296136617
,2025-07-17T15:39:44.433372235Z,2025-07-17T15:39:44.433372235Z,10,2,1108,C,A,0,13.73,15,128,167057,248752483,13.26,100,1,13.74,100,1,13.04,2,1,13.76,100,1,13.03,100,1,13.95,2,1,12.73,100,1,14.05,100,1,12.71,100,1,14.4,100,1,12.5,700,1,14.56,900,3,12.46,200,2,14.6,700,1,12.43,700,1,14.61,200,2,12.42,700,1,14.65,100,1,12.37,700,1,14.68,1400,2,ARL,296365029
,2025-07-17T15:39:44.435889060Z,2025-07-17T15:39:44.435889060Z,10,2,1108,C,A,0,13.74,100,130,165825,248752938,13.26,100,1,13.76,100,1,13.04,2,1,13.95,2,1,13.03,100,1,14.05,100,1,12.73,100,1,14.4,100,1,12.71,100,1,14.56,900,3,12.5,700,1,14.6,700,1,12.46,200,2,14.61,200,2,12.43,700,1,14.65,100,1,12.42,700,1,14.68,1400,2,12.37,700,1,14.81,300,3,ARL,296368281
,2025-07-17T15:39:44.450073949Z,2025-07-17T15:39:44.450073949Z,10,2,1108,C,A,0,13.76,100,130,165141,248753643,13.26,100,1,13.95,2,1,13.04,2,1,14.05,100,1,13.03,100,1,14.4,100,1,12.73,100,1,14.56,900,3,12.71,100,1,14.6,700,1,12.5,700,1,14.61,200,2,12.46,200,2,14.65,100,1,12.43,700,1,14.68,1400,2,12.42,700,1,14.81,300,3,12.37,700,1,15.12,100,1,ARL,296372577
,2025-07-17T15:39:44.450806746Z,2025-07-17T15:39:44.450806746Z,10,2,1108,C,A,8,14.81,100,0,165584,248753673,13.26,100,1,13.95,2,1,13.04,2,1,14.05,100,1,13.03,100,1,14.4,100,1,12.73,100,1,14.56,900,3,12.71,100,1,14.6,700,1,12.5,700,1,14.61,200,2,12.46,200,2,14.65,100,1,12.43,700,1,14.68,1400,2,12.42,700,1,14.81,200,2,12.37,700,1,15.12,100,1,ARL,296368709
,2025-07-17T15:39:44.450806746Z,2025-07-17T15:39:44.450806746Z,10,2,1108,A,A,9,15.06,100,130,165584,248753673,13.26,100,1,13.95,2,1,13.04,2,1,14.05,100,1,13.03,100,1,14.4,100,1,12.73,100,1,14.56,900,3,12.71,100,1,14.6,700,1,12.5,700,1,14.61,200,2,12.46,200,2,14.65,100,1,12.43,700,1,14.68,1400,2,12.42,700,1,14.81,200,2,12.37,700,1,15.06,100,1,ARL,296478965
,2025-07-17T15:39:44.450910591Z,2025-07-17T15:39:44.450910591Z,10,2,1108,C,A,0,13.95,2,0,165401,248753678,13.26,100,1,14.05,100,1,13.04,2,1,14.4,100,1,13.03,100,1,14.56,900,3,12.73,100,1,14.6,700,1,12.71,100,1,14.61,200,2,12.5,700,1,14.65,100,1,12.46,200,2,14.68,1400,2,12.43,700,1,14.81,200,2,12.42,700,1,15.06,100,1,12.37,700,1,15.12,100,1,ARL,287540393
,2025-07-17T15:39:44.450910591Z,2025-07-17T15:39:44.450910591Z,10,2,1108,A,A,1,14.07,2,130,165401,248753678,13.26,100,1,14.05,100,1,13.04,2,1,14.07,2,1,13.03,100,1,14.4,100,1,12.73,100,1,14.56,900,3,12.71,100,1,14.6,700,1,12.5,700,1,14.61,200,2,12.46,200,2,14.65,100,1,12.43,700,1,14.68,1400,2,12.42,700,1,14.81,200,2,12.37,700,1,15.06,100,1,ARL,296478973
,2025-07-17T15:39:44.454964327Z,2025-07-17T15:39:44.454964327Z,10,2,1108,C,A,8,14.81,100,0,165970,248753748,13.26,100,1,14.05,100,1,13.04,2,1,14.07,2,1,13.03,100,1,14.4,100,1,12.73,100,1,14.56,900,3,12.71,100,1,14.6,700,1,12.5,700,1,14.61,200,2,12.46,200,2,14.65,100,1,12.43,700,1,14.68,1400,2,12.42,700,1,14.81,100,1,12.37,700,1,15.06,100,1,ARL,286680741
,2025-07-17T15:39:44.454964327Z,2025-07-17T15:39:44.454964327Z,10,2,1108,A,A,9,14.96,100,130,165970,248753748,13.26,100,1,14.05,100,1,13.04,2,1,14.07,2,1,13.03,100,1,14.4,100,1,12.73,100,1,14.56,900,3,12.71,100,1,14.6,700,1,12.5,700,1,14.61,200,2,12.46,200,2,14.65,100,1,12.43,700,1,14.68,1400,2,12.42,700,1,14.81,100,1,12.37,700,1,14.96,100,1,ARL,296479053
,2025-07-17T15:39:44.456122660Z,2025-07-17T15:39:44.456122660Z,10,2,1108,C,A,6,14.65,100,130,165402,248753812,13.26,100,1,14.05,100,1,13.04,2,1,14.07,2,1,13.03,100,1,14.4,100,1,12.73,100,1,14.56,900,3,12.71,100,1,14.6,700,1,12.5,700,1,14.61,200,2,12.46,200,2,14.68,1400,2,12.43,700,1,14.81,100,1,12.42,700,1,14.96,100,1,12.37,700,1,15.06,100,1,ARL,286680905
,2025-07-17T15:39:44.456211953Z,2025-07-17T15:39:44.456211953Z,10,2,1108,A,A,7,14.78,100,130,165547,248753815,13.26,100,1,14.05,100,1,13.04,2,1,14.07,2,1,13.03,100,1,14.4,100,1,12.73,100,1,14.56,900,3,12.71,100,1,14.6,700,1,12.5,700,1,14.61,200,2,12.46,200,2,14.68,1400,2,12.43,700,1,14.78,100,1,12.42,700,1,14.81,100,1,12.37,700,1,14.96,100,1,ARL,296479285
,2025-07-17T15:39:44.461889886Z,2025-07-17T15:39:44.461889886Z,10,2,1108,C,A,0,14.05,100,130,165208,248753947,13.26,100,1,14.07,2,1,13.04,2,1,14.4,100,1,13.03,100,1,14.56,900,3,12.73,100,1,14.6,700,1,12.71,100,1,14.61,200,2,12.5,700,1,14.68,1400,2,12.46,200,2,14.78,100,1,12.43,700,1,14.81,100,1,12.42,700,1,14.96,100,1,12.37,700,1,15.06,100,1,ARL,296137769
,2025-07-17T15:39:44.461943584Z,2025-07-17T15:39:44.461943584Z,10,2,1108,A,A,1,14.26,100,130,165225,248753952,13.26,100,1,14.07,2,1,13.04,2,1,14.26,100,1,13.03,100,1,14.4,100,1,12.73,100,1,14.56,900,3,12.71,100,1,14.6,700,1,12.5,700,1,14.61,200,2,12.46,200,2,14.68,1400,2,12.43,700,1,14.78,100,1,12.42,700,1,14.81,100,1,12.37,700,1,14.96,100,1,ARL,296479425
,2025-07-17T15:39:44.593607433Z,2025-07-17T15:39:44.593607433Z,10,2,1108,C,A,8,14.81,100,0,165780,248756227,13.26,100,1,14.07,2,1,13.04,2,1,14.26,100,1,13.03,100,1,14.4,100,1,12.73,100,1,14.56,900,3,12.71,100,1,14.6,700,1,12.5,700,1,14.61,200,2,12.46,200,2,14.68,1400,2,12.43,700,1,14.78,100,1,12.42,700,1,14.96,100,1,12.37,700,1,15.06,100,1,ARL,286684005
,2025-07-17T15:39:44.593607433Z,2025-07-17T15:39:44.593607433Z,10,2,1108,A,A,8,14.96,100,130,165780,248756227,13.26,100,1,14.07,2,1,13.04,2,1,14.26,100,1,13.03,100,1,14.4,100,1,12.73,100,1,14.56,900,3,12.71,100,1,14.6,700,1,12.5,700,1,14.61,200,2,12.46,200,2,14.68,1400,2,12.43,700,1,14.78,100,1,12.42,700,1,14.96,200,2,12.37,700,1,15.06,100,1,ARL,296482509
,2025-07-17T15:39:44.859720946Z,2025-07-17T15:39:44.859720946Z,10,2,1108,C,A,5,14.61,100,0,165616,248760319,13.26,100,1,14.07,2,1,13.04,2,1,14.26,100,1,13.03,100,1,14.4,100,1,12.73,100,1,14.56,900,3,12.71,100,1,14.6,700,1,12.5,700,1,14.61,100,1,12.46,200,2,14.68,1400,2,12.43,700,1,14.78,100,1,12.42,700,1,14.96,200,2,12.37,700,1,15.06,100,1,ARL,296455041
,2025-07-17T15:39:44.859720946Z,2025-07-17T15:39:44.859720946Z,10,2,1108,A,A,10,15.1,100,130,165616,248760319,13.26,100,1,14.07,2,1,13.04,2,1,14.26,100,1,13.03,100,1,14.4,100,1,12.73,100,1,14.56,900,3,12.71,100,1,14.6,700,1,12.5,700,1,14.61,100,1,12.46,200,2,14.68,1400,2,12.43,700,1,14.78,100,1,12.42,700,1,14.96,200,2,12.37,700,1,15.06,100,1,ARL,296485621
,2025-07-17T15:39:44.859994671Z,2025-07-17T15:39:44.859994671Z,10,2,1108,A,A,1,14.08,100,130,165425,248760324,13.26,100,1,14.07,2,1,13.04,2,1,14.08,100,1,13.03,100,1,14.26,100,1,12.73,100,1,14.4,100,1,12.71,100,1,14.56,900,3,12.5,700,1,14.6,700,1,12.46,200,2,14.61,100,1,12.43,700,1,14.68,1400,2,12.42,700,1,14.78,100,1,12.37,700,1,14.96,200,2,ARL,296485629
,2025-07-17T15:39:44.863513587Z,2025-07-17T15:39:44.863513587Z,10,2,1108,C,A,6,14.61,100,0,165208,248760417,13.26,100,1,14.07,2,1,13.04,2,1,14.08,100,1,13.03,100,1,14.26,100,1,12.73,100,1,14.4,100,1,12.71,100,1,14.56,900,3,12.5,700,1,14.6,700,1,12.46,200,2,14.68,1400,2,12.43,700,1,14.78,100,1,12.42,700,1,14.96,200,2,12.37,700,1,15.06,100,1,ARL,296455037
,2025-07-17T15:39:44.863513587Z,2025-07-17T15:39:44.863513587Z,10,2,1108,A,A,10,15.1,100,130,165208,248760417,13.26,100,1,14.07,2,1,13.04,2,1,14.08,100,1,13.03,100,1,14.26,100,1,12.73,100,1,14.4,100,1,12.71,100,1,14.56,900,3,12.5,700,1,14.6,700,1,12.46,200,2,14.68,1400,2,12.43,700,1,14.78,100,1,12.42,700,1,14.96,200,2,12.37,700,1,15.06,100,1,ARL,296485649
,2025-07-17T15:39:54.186842327Z,2025-07-17T15:39:54.186842327Z,10,2,1108,C,A,10,15.1,100,0,165897,248915116,13.26,100,1,14.07,2,1,13.04,2,1,14.08,100,1,13.03,100,1,14.26,100,1,12.73,100,1,14.4,100,1,12.71,100,1,14.56,900,3,12.5,700,1,14.6,700,1,12.46,200,2,14.68,1400,2,12.43,700,1,14.78,100,1,12.42,700,1,14.96,200,2,12.37,700,1,15.06,100,1,ARL,296485649
,2025-07-17T15:39:54.186842327Z,2025-07-17T15:39:54.186842327Z,10,2,1108,A,A,8,14.88,100,130,165897,248915116,13.26,100,1,14.07,2,1,13.04,2,1,14.08,100,1,13.03,100,1,14.26,100,1,12.73,100,1,14.4,100,1,12.71,100,1,14.56,900,3,12.5,700,1,14.6,700,1,12.46,200,2,14.68,1400,2,12.43,700,1,14.78,100,1,12.42,700,1,14.88,100,1,12.37,700,1,14.96,200,2,ARL,296679277
,2025-07-17T15:39:54.187391707Z,2025-07-17T15:39:54.187391707Z,10,2,1108,A,A,8,14.88,100,130,165705,248915126,13.26,100,1,14.07,2,1,13.04,2,1,14.08,100,1,13.03,100,1,14.26,100,1,12.73,100,1,14.4,100,1,12.71,100,1,14.56,900,3,12.5,700,1,14.6,700,1,12.46,200,2,14.68,1400,2,12.43,700,1,14.78,100,1,12.42,700,1,14.88,200,2,12.37,700,1,14.96,200,2,ARL,296679285
,2025-07-17T15:42:06.780337543Z,2025-07-17T15:42:06.780337543Z,10,2,1108,A,A,0,13.9,15,130,165511,251407709,13.26,100,1,13.9,15,1,13.04,2,1,14.07,2,1,13.03,100,1,14.08,100,1,12.73,100,1,14.26,100,1,12.71,100,1,14.4,100,1,12.5,700,1,14.56,900,3,12.46,200,2,14.6,700,1,12.43,700,1,14.68,1400,2,12.42,700,1,14.78,100,1,12.37,700,1,14.88,200,2,ARL,299689753
,2025-07-17T15:42:06.780602350Z,2025-07-17T15:42:06.780602350Z,10,2,1108,C,A,2,14.08,100,0,165411,251407713,13.26,100,1,13.9,15,1,13.04,2,1,14.07,2,1,13.03,100,1,14.26,100,1,12.73,100,1,14.4,100,1,12.71,100,1,14.56,900,3,12.5,700,1,14.6,700,1,12.46,200,2,14.68,1400,2,12.43,700,1,14.78,100,1,12.42,700,1,14.88,200,2,12.37,700,1,14.96,200,2,ARL,296485629
,2025-07-17T15:42:06.780602350Z,2025-07-17T15:42:06.780602350Z,10,2,1108,A,A,1,13.91,100,130,165411,251407713,13.26,100,1,13.9,15,1,13.04,2,1,13.91,100,1,13.03,100,1,14.07,2,1,12.73,100,1,14.26,100,1,12.71,100,1,14.4,100,1,12.5,700,1,14.56,900,3,12.46,200,2,14.6,700,1,12.43,700,1,14.68,1400,2,12.42,700,1,14.78,100,1,12.37,700,1,14.88,200,2,ARL,299689769
,2025-07-17T15:42:06.795355762Z,2025-07-17T15:42:06.795355762Z,10,2,1108,C,A,3,14.26,100,130,165545,251408268,13.26,100,1,13.9,15,1,13.04,2,1,13.91,100,1,13.03,100,1,14.07,2,1,12.73,100,1,14.4,100,1,12.71,100,1,14.56,900,3,12.5,700,1,14.6,700,1,12.46,200,2,14.68,1400,2,12.43,700,1,14.78,100,1,12.42,700,1,14.88,200,2,12.37,700,1,14.96,200,2,ARL,296479425
,2025-07-17T15:42:06.795408057Z,2025-07-17T15:42:06.795408057Z,10,2,1108,A,A,3,14.19,100,130,165335,251408269,13.26,100,1,13.9,15,1,13.04,2,1,13.91,100,1,13.03,100,1,14.07,2,1,12.73,100,1,14.19,100,1,12.71,100,1,14.4,100,1,12.5,700,1,14.56,900,3,12.46,200,2,14.6,700,1,12.43,700,1,14.68,1400,2,12.42,700,1,14.78,100,1,12.37,700,1,14.88,200,2,ARL,299690593
,2025-07-17T15:42:16.263966448Z,2025-07-17T15:42:16.263966448Z,10,2,1108,C,A,9,14.88,100,0,165711,251574391,13.26,100,1,13.9,15,1,13.04,2,1,13.91,100,1,13.03,100,1,14.07,2,1,12.73,100,1,14.19,100,1,12.71,100,1,14.4,100,1,12.5,700,1,14.56,900,3,12.46,200,2,14.6,700,1,12.43,700,1,14.68,1400,2,12.42,700,1,14.78,100,1,12.37,700,1,14.88,100,1,ARL,296679285
,2025-07-17T15:42:16.263966448Z,2025-07-17T15:42:16.263966448Z,10,2,1108,A,A,8,14.76,100,130,165711,251574391,13.26,100,1,13.9,15,1,13.04,2,1,13.91,100,1,13.03,100,1,14.07,2,1,12.73,100,1,14.19,100,1,12.71,100,1,14.4,100,1,12.5,700,1,14.56,900,3,12.46,200,2,14.6,700,1,12.43,700,1,14.68,1400,2,12.42,700,1,14.76,100,1,12.37,700,1,14.78,100,1,ARL,299903169
,2025-07-17T15:42:17.356601231Z,2025-07-17T15:42:17.356601231Z,10,2,1108,A,A,0,13.83,15,130,165484,251593608,13.26,100,1,13.83,15,1,13.04,2,1,13.9,15,1,13.03,100,1,13.91,100,1,12.73,100,1,14.07,2,1,12.71,100,1,14.19,100,1,12.5,700,1,14.4,100,1,12.46,200,2,14.56,900,3,12.43,700,1,14.6,700,1,12.42,700,1,14.68,1400,2,12.37,700,1,14.76,100,1,ARL,299923773
,2025-07-17T15:42:17.577308779Z,2025-07-17T15:42:17.577308779Z,10,2,1108,C,A,2,13.91,100,0,165467,251595553,13.26,100,1,13.83,15,1,13.04,2,1,13.9,15,1,13.03,100,1,14.07,2,1,12.73,100,1,14.19,100,1,12.71,100,1,14.4,100,1,12.5,700,1,14.56,900,3,12.46,200,2,14.6,700,1,12.43,700,1,14.68,1400,2,12.42,700,1,14.76,100,1,12.37,700,1,14.78,100,1,ARL,299689769
,2025-07-17T15:42:17.577308779Z,2025-07-17T15:42:17.577308779Z,10,2,1108,A,A,1,13.84,100,130,165467,251595553,13.26,100,1,13.83,15,1,13.04,2,1,13.84,100,1,13.03,100,1,13.9,15,1,12.73,100,1,14.07,2,1,12.71,100,1,14.19,100,1,12.5,700,1,14.4,100,1,12.46,200,2,14.56,900,3,12.43,700,1,14.6,700,1,12.42,700,1,14.68,1400,2,12.37,700,1,14.76,100,1,ARL,299926781
,2025-07-17T15:42:17.579177582Z,2025-07-17T15:42:17.579177582Z,10,2,1108,C,A,10,14.78,100,0,165607,251595571,13.26,100,1,13.83,15,1,13.04,2,1,13.84,100,1,13.03,100,1,13.9,15,1,12.73,100,1,14.07,2,1,12.71,100,1,14.19,100,1,12.5,700,1,14.4,100,1,12.46,200,2,14.56,900,3,12.43,700,1,14.6,700,1,12.42,700,1,14.68,1400,2,12.37,700,1,14.76,100,1,ARL,296479285
,2025-07-17T15:42:17.579177582Z,2025-07-17T15:42:17.579177582Z,10,2,1108,A,A,8,14.64,100,130,165607,251595571,13.26,100,1,13.83,15,1,13.04,2,1,13.84,100,1,13.03,100,1,13.9,15,1,12.73,100,1,14.07,2,1,12.71,100,1,14.19,100,1,12.5,700,1,14.4,100,1,12.46,200,2,14.56,900,3,12.43,700,1,14.6,700,1,12.42,700,1,14.64,100,1,12.37,700,1,14.68,1400,2,ARL,299926813
,2025-07-17T15:42:17.589098227Z,2025-07-17T15:42:17.589098227Z,10,2,1108,C,A,4,14.19,100,130,165323,251595691,13.26,100,1,13.83,15,1,13.04,2,1,13.84,100,1,13.03,100,1,13.9,15,1,12.73,100,1,14.07,2,1,12.71,100,1,14.4,100,1,12.5,700,1,14.56,900,3,12.46,200,2,14.6,700,1,12.43,700,1,14.64,100,1,12.42,700,1,14.68,1400,2,12.37,700,1,14.76,100,1,ARL,299690593
,2025-07-17T15:42:17.589151325Z,2025-07-17T15:42:17.589151325Z,10,2,1108,A,A,4,14.12,100,130,165586,251595692,13.26,100,1,13.83,15,1,13.04,2,1,13.84,100,1,13.03,100,1,13.9,15,1,12.73,100,1,14.07,2,1,12.71,100,1,14.12,100,1,12.5,700,1,14.4,100,1,12.46,200,2,14.56,900,3,12.43,700,1,14.6,700,1,12.42,700,1,14.64,100,1,12.37,700,1,14.68,1400,2,ARL,299926965
,2025-07-17T15:42:18.398054465Z,2025-07-17T15:42:18.398054465Z,10,2,1108,A,A,10,14.73,100,130,165535,251612478,13.26,100,1,13.83,15,1,13.04,2,1,13.84,100,1,13.03,100,1,13.9,15,1,12.73,100,1,14.07,2,1,12.71,100,1,14.12,100,1,12.5,700,1,14.4,100,1,12.46,200,2,14.56,900,3,12.43,700,1,14.6,700,1,12.42,700,1,14.64,100,1,12.37,700,1,14.68,1400,2,ARL,299945073
,2025-07-17T15:42:21.517706139Z,2025-07-17T15:42:21.517706139Z,10,2,1108,C,A,2,13.9,15,130,165575,251668179,13.26,100,1,13.83,15,1,13.04,2,1,13.84,100,1,13.03,100,1,14.07,2,1,12.73,100,1,14.12,100,1,12.71,100,1,14.4,100,1,12.5,700,1,14.56,900,3,12.46,200,2,14.6,700,1,12.43,700,1,14.64,100,1,12.42,700,1,14.68,1400,2,12.37,700,1,14.73,100,1,ARL,299689753
,2025-07-17T15:42:22.522578675Z,2025-07-17T15:42:22.522578675Z,10,2,1108,A,A,0,13.79,15,130,165567,251690950,13.26,100,1,13.79,15,1,13.04,2,1,13.83,15,1,13.03,100,1,13.84,100,1,12.73,100,1,14.07,2,1,12.71,100,1,14.12,100,1,12.5,700,1,14.4,100,1,12.46,200,2,14.56,900,3,12.43,700,1,14.6,700,1,12.42,700,1,14.64,100,1,12.37,700,1,14.68,1400,2,ARL,300042293
,2025-07-17T15:42:22.533515955Z,2025-07-17T15:42:22.533515955Z,10,2,1108,A,A,1,13.82,100,130,165524,251691033,13.26,100,1,13.79,15,1,13.04,2,1,13.82,100,1,13.03,100,1,13.83,15,1,12.73,100,1,13.84,100,1,12.71,100,1,14.07,2,1,12.5,700,1,14.12,100,1,12.46,200,2,14.4,100,1,12.43,700,1,14.56,900,3,12.42,700,1,14.6,700,1,12.37,700,1,14.64,100,1,ARL,300042385
,2025-07-17T15:42:23.490079821Z,2025-07-17T15:42:23.490079821Z,10,2,1108,C,A,3,13.84,100,0,167300,251710173,13.26,100,1,13.79,15,1,13.04,2,1,13.82,100,1,13.03,100,1,13.83,15,1,12.73,100,1,14.07,2,1,12.71,100,1,14.12,100,1,12.5,700,1,14.4,100,1,12.46,200,2,14.56,900,3,12.43,700,1,14.6,700,1,12.42,700,1,14.64,100,1,12.37,700,1,14.68,1400,2,ARL,299926781
,2025-07-17T15:42:23.490079821Z,2025-07-17T15:42:23.490079821Z,10,2,1108,A,A,1,13.8,100,128,167300,251710173,13.26,100,1,13.79,15,1,13.04,2,1,13.8,100,1,13.03,100,1,13.82,100,1,12.73,100,1,13.83,15,1,12.71,100,1,14.07,2,1,12.5,700,1,14.12,100,1,12.46,200,2,14.4,100,1,12.43,700,1,14.56,900,3,12.42,700,1,14.6,700,1,12.37,700,1,14.64,100,1,ARL,300061581
,2025-07-17T15:42:23.588899941Z,2025-07-17T15:42:23.588899941Z,10,2,1108,C,A,0,13.79,15,130,165213,251718746,13.26,100,1,13.8,100,1,13.04,2,1,13.82,100,1,13.03,100,1,13.83,15,1,12.73,100,1,14.07,2,1,12.71,100,1,14.12,100,1,12.5,700,1,14.4,100,1,12.46,200,2,14.56,900,3,12.43,700,1,14.6,700,1,12.42,700,1,14.64,100,1,12.37,700,1,14.68,1400,2,ARL,300042293
,2025-07-17T15:42:23.589055082Z,2025-07-17T15:42:23.589055082Z,10,2,1108,C,A,2,13.83,15,130,165696,251718767,13.26,100,1,13.8,100,1,13.04,2,1,13.82,100,1,13.03,100,1,14.07,2,1,12.73,100,1,14.12,100,1,12.71,100,1,14.4,100,1,12.5,700,1,14.56,900,3,12.46,200,2,14.6,700,1,12.43,700,1,14.64,100,1,12.42,700,1,14.68,1400,2,12.37,700,1,14.73,100,1,ARL,299923773
,2025-07-17T15:42:34.003544527Z,2025-07-17T15:42:34.003544527Z,10,2,1108,C,A,0,13.8,100,130,165554,251901273,13.26,100,1,13.82,100,1,13.04,2,1,14.07,2,1,13.03,100,1,14.12,100,1,12.73,100,1,14.4,100,1,12.71,100,1,14.56,900,3,12.5,700,1,14.6,700,1,12.46,200,2,14.64,100,1,12.43,700,1,14.68,1400,2,12.42,700,1,14.73,100,1,12.37,700,1,14.76,100,1,ARL,300061581
,2025-07-17T15:42:34.003783950Z,2025-07-17T15:42:34.003783950Z,10,2,1108,C,A,0,13.82,100,130,165390,251901275,13.26,100,1,14.07,2,1,13.04,2,1,14.12,100,1,13.03,100,1,14.4,100,1,12.73,100,1,14.56,900,3,12.71,100,1,14.6,700,1,12.5,700,1,14.64,100,1,12.46,200,2,14.68,1400,2,12.43,700,1,14.73,100,1,12.42,700,1,14.76,100,1,12.37,700,1,14.81,200,2,ARL,300042385
,2025-07-17T15:42:34.004059450Z,2025-07-17T15:42:34.004059450Z,10,2,1108,C,A,7,14.73,100,0,165730,251901280,13.26,100,1,14.07,2,1,13.04,2,1,14.12,100,1,13.03,100,1,14.4,100,1,12.73,100,1,14.56,900,3,12.71,100,1,14.6,700,1,12.5,700,1,14.64,100,1,12.46,200,2,14.68,1400,2,12.43,700,1,14.76,100,1,12.42,700,1,14.81,200,2,12.37,700,1,14.87,100,1,ARL,299945073
,2025-07-17T15:42:34.004059450Z,2025-07-17T15:42:34.004059450Z,10,2,1108,A,A,10,14.88,100,130,165730,251901280,13.26,100,1,14.07,2,1,13.04,2,1,14.12,100,1,13.03,100,1,14.4,100,1,12.73,100,1,14.56,900,3,12.71,100,1,14.6,700,1,12.5,700,1,14.64,100,1,12.46,200,2,14.68,1400,2,12.43,700,1,14.76,100,1,12.42,700,1,14.81,200,2,12.37,700,1,14.87,100,1,ARL,300280745
,2025-07-17T15:42:34.004506043Z,2025-07-17T15:42:34.004506043Z,10,2,1108,C,A,9,14.87,100,0,165609,251901285,13.26,100,1,14.07,2,1,13.04,2,1,14.12,100,1,13.03,100,1,14.4,100,1,12.73,100,1,14.56,900,3,12.71,100,1,14.6,700,1,12.5,700,1,14.64,100,1,12.46,200,2,14.68,1400,2,12.43,700,1,14.76,100,1,12.42,700,1,14.81,200,2,12.37,700,1,14.88,100,1,ARL,300061989
,2025-07-17T15:42:34.004506043Z,2025-07-17T15:42:34.004506043Z,10,2,1108,A,A,10,15.06,100,130,165609,251901285,13.26,100,1,14.07,2,1,13.04,2,1,14.12,100,1,13.03,100,1,14.4,100,1,12.73,100,1,14.56,900,3,12.71,100,1,14.6,700,1,12.5,700,1,14.64,100,1,12.46,200,2,14.68,1400,2,12.43,700,1,14.76,100,1,12.42,700,1,14.81,200,2,12.37,700,1,14.88,100,1,ARL,300280757
,2025-07-17T15:42:34.004512153Z,2025-07-17T15:42:34.004512153Z,10,2,1108,C,A,7,14.76,100,0,165633,251901286,13.26,100,1,14.07,2,1,13.04,2,1,14.12,100,1,13.03,100,1,14.4,100,1,12.73,100,1,14.56,900,3,12.71,100,1,14.6,700,1,12.5,700,1,14.64,100,1,12.46,200,2,14.68,1400,2,12.43,700,1,14.81,200,2,12.42,700,1,14.88,100,1,12.37,700,1,15.06,100,1,ARL,299903169
,2025-07-17T15:42:34.004512153Z,2025-07-17T15:42:34.004512153Z,10,2,1108,A,A,8,14.88,100,130,165633,251901286,13.26,100,1,14.07,2,1,13.04,2,1,14.12,100,1,13.03,100,1,14.4,100,1,12.73,100,1,14.56,900,3,12.71,100,1,14.6,700,1,12.5,700,1,14.64,100,1,12.46,200,2,14.68,1400,2,12.43,700,1,14.81,200,2,12.42,700,1,14.88,200,2,12.37,700,1,15.06,100,1,ARL,300280761
,2025-07-17T15:42:34.005667449Z,2025-07-17T15:42:34.005667449Z,10,2,1108,C,A,7,14.81,100,0,165477,251901305,13.26,100,1,14.07,2,1,13.04,2,1,14.12,100,1,13.03,100,1,14.4,100,1,12.73,100,1,14.56,900,3,12.71,100,1,14.6,700,1,12.5,700,1,14.64,100,1,12.46,200,2,14.68,1400,2,12.43,700,1,14.81,100,1,12.42,700,1,14.88,200,2,12.37,700,1,15.06,100,1,ARL,299926849
,2025-07-17T15:42:34.005667449Z,2025-07-17T15:42:34.005667449Z,10,2,1108,A,A,9,14.96,100,130,165477,251901305,13.26,100,1,14.07,2,1,13.04,2,1,14.12,100,1,13.03,100,1,14.4,100,1,12.73,100,1,14.56,900,3,12.71,100,1,14.6,700,1,12.5,700,1,14.64,100,1,12.46,200,2,14.68,1400,2,12.43,700,1,14.81,100,1,12.42,700,1,14.88,200,2,12.37,700,1,14.96,100,1,ARL,300280777
,2025-07-17T15:42:34.007743383Z,2025-07-17T15:42:34.007743383Z,10,2,1108,C,A,5,14.64,100,130,165295,251901330,13.26,100,1,14.07,2,1,13.04,2,1,14.12,100,1,13.03,100,1,14.4,100,1,12.73,100,1,14.56,900,3,12.71,100,1,14.6,700,1,12.5,700,1,14.68,1400,2,12.46,200,2,14.81,100,1,12.43,700,1,14.88,200,2,12.42,700,1,14.96,100,1,12.37,700,1,15.06,100,1,ARL,299926813
,2025-07-17T15:42:34.007907269Z,2025-07-17T15:42:34.007907269Z,10,2,1108,A,A,6,14.78,100,130,165394,251901331,13.26,100,1,14.07,2,1,13.04,2,1,14.12,100,1,13.03,100,1,14.4,100,1,12.73,100,1,14.56,900,3,12.71,100,1,14.6,700,1,12.5,700,1,14.68,1400,2,12.46,200,2,14.78,100,1,12.43,700,1,14.81,100,1,12.42,700,1,14.88,200,2,12.37,700,1,14.96,100,1,ARL,300280825
,2025-07-17T15:42:34.010031518Z,2025-07-17T15:42:34.010031518Z,10,2,1108,C,A,1,14.12,100,130,165313,251901352,13.26,100,1,14.07,2,1,13.04,2,1,14.4,100,1,13.03,100,1,14.56,900,3,12.73,100,1,14.6,700,1,12.71,100,1,14.68,1400,2,12.5,700,1,14.78,100,1,12.46,200,2,14.81,100,1,12.43,700,1,14.88,200,2,12.42,700,1,14.96,100,1,12.37,700,1,15.06,100,1,ARL,299926965
,2025-07-17T15:42:34.010083409Z,2025-07-17T15:42:34.010083409Z,10,2,1108,A,A,1,14.26,100,130,165433,251901353,13.26,100,1,14.07,2,1,13.04,2,1,14.26,100,1,13.03,100,1,14.4,100,1,12.73,100,1,14.56,900,3,12.71,100,1,14.6,700,1,12.5,700,1,14.68,1400,2,12.46,200,2,14.78,100,1,12.43,700,1,14.81,100,1,12.42,700,1,14.88,200,2,12.37,700,1,14.96,100,1,ARL,300280857
,2025-07-17T15:42:34.010406771Z,2025-07-17T15:42:34.010406771Z,10,2,1108,C,A,7,14.81,100,0,165599,251901355,13.26,100,1,14.07,2,1,13.04,2,1,14.26,100,1,13.03,100,1,14.4,100,1,12.73,100,1,14.56,900,3,12.71,100,1,14.6,700,1,12.5,700,1,14.68,1400,2,12.46,200,2,14.78,100,1,12.43,700,1,14.88,200,2,12.42,700,1,14.96,100,1,12.37,700,1,15.06,100,1,ARL,299926857
,2025-07-17T15:42:34.010406771Z,2025-07-17T15:42:34.010406771Z,10,2,1108,A,A,8,14.96,100,130,165599,251901355,13.26,100,1,14.07,2,1,13.04,2,1,14.26,100,1,13.03,100,1,14.4,100,1,12.73,100,1,14.56,900,3,12.71,100,1,14.6,700,1,12.5,700,1,14.68,1400,2,12.46,200,2,14.78,100,1,12.43,700,1,14.88,200,2,12.42,700,1,14.96,200,2,12.37,700,1,15.06,100,1,ARL,300280873
,2025-07-17T15:42:34.951932909Z,2025-07-17T15:42:34.951932909Z,10,2,1108,A,A,1,14.08,100,130,165118,251912292,13.26,100,1,14.07,2,1,13.04,2,1,14.08,100,1,13.03,100,1,14.26,100,1,12.73,100,1,14.4,100,1,12.71,100,1,14.56,900,3,12.5,700,1,14.6,700,1,12.46,200,2,14.68,1400,2,12.43,700,1,14.78,100,1,12.42,700,1,14.88,200,2,12.37,700,1,14.96,200,2,ARL,300294885
,2025-07-17T15:43:21.513673603Z,2025-07-17T15:43:21.513673603Z,10,2,1108,A,A,0,13.92,15,130,165346,252622568,13.26,100,1,13.92,15,1,13.04,2,1,14.07,2,1,13.03,100,1,14.08,100,1,12.73,100,1,14.26,100,1,12.71,100,1,14.4,100,1,12.5,700,1,14.56,900,3,12.46,200,2,14.6,700,1,12.43,700,1,14.68,1400,2,12.42,700,1,14.78,100,1,12.37,700,1,14.88,200,2,ARL,301218889
,2025-07-17T15:43:24.878071152Z,2025-07-17T15:43:24.878071152Z,10,2,1108,C,A,2,14.08,100,0,165608,252681819,13.26,100,1,13.92,15,1,13.04,2,1,14.07,2,1,13.03,100,1,14.26,100,1,12.73,100,1,14.4,100,1,12.71,100,1,14.56,900,3,12.5,700,1,14.6,700,1,12.46,200,2,14.68,1400,2,12.43,700,1,14.78,100,1,12.42,700,1,14.88,200,2,12.37,700,1,14.96,200,2,ARL,300294885
,2025-07-17T15:43:24.878071152Z,2025-07-17T15:43:24.878071152Z,10,2,1108,A,A,1,13.93,100,130,165608,252681819,13.26,100,1,13.92,15,1,13.04,2,1,13.93,100,1,13.03,100,1,14.07,2,1,12.73,100,1,14.26,100,1,12.71,100,1,14.4,100,1,12.5,700,1,14.56,900,3,12.46,200,2,14.6,700,1,12.43,700,1,14.68,1400,2,12.42,700,1,14.78,100,1,12.37,700,1,14.88,200,2,ARL,301295841
,2025-07-17T15:43:32.780206927Z,2025-07-17T15:43:32.780206927Z,10,2,1108,A,A,0,13.88,15,130,165485,252800884,13.26,100,1,13.88,15,1,13.04,2,1,13.92,15,1,13.03,100,1,13.93,100,1,12.73,100,1,14.07,2,1,12.71,100,1,14.26,100,1,12.5,700,1,14.4,100,1,12.46,200,2,14.56,900,3,12.43,700,1,14.6,700,1,12.42,700,1,14.68,1400,2,12.37,700,1,14.78,100,1,ARL,301451057
,2025-07-17T15:43:32.780474141Z,2025-07-17T15:43:32.780474141Z,10,2,1108,C,A,2,13.93,100,0,165478,252800887,13.26,100,1,13.88,15,1,13.04,2,1,13.92,15,1,13.03,100,1,14.07,2,1,12.73,100,1,14.26,100,1,12.71,100,1,14.4,100,1,12.5,700,1,14.56,900,3,12.46,200,2,14.6,700,1,12.43,700,1,14.68,1400,2,12.42,700,1,14.78,100,1,12.37,700,1,14.88,200,2,ARL,301295841
,2025-07-17T15:43:32.780474141Z,2025-07-17T15:43:32.780474141Z,10,2,1108,A,A,1,13.89,100,130,165478,252800887,13.26,100,1,13.88,15,1,13.04,2,1,13.89,100,1,13.03,100,1,13.92,15,1,12.73,100,1,14.07,2,1,12.71,100,1,14.26,100,1,12.5,700,1,14.4,100,1,12.46,200,2,14.56,900,3,12.43,700,1,14.6,700,1,12.42,700,1,14.68,1400,2,12.37,700,1,14.78,100,1,ARL,301451061
,2025-07-17T15:43:32.791954053Z,2025-07-17T15:43:32.791954053Z,10,2,1108,C,A,4,14.26,100,130,165645,252801681,13.26,100,1,13.88,15,1,13.04,2,1,13.89,100,1,13.03,100,1,13.92,15,1,12.73,100,1,14.07,2,1,12.71,100,1,14.4,100,1,12.5,700,1,14.56,900,3,12.46,200,2,14.6,700,1,12.43,700,1,14.68,1400,2,12.42,700,1,14.78,100,1,12.37,700,1,14.88,200,2,ARL,300280857
,2025-07-17T15:43:32.792008881Z,2025-07-17T15:43:32.792008881Z,10,2,1108,A,A,4,14.17,100,130,165736,252801689,13.26,100,1,13.88,15,1,13.04,2,1,13.89,100,1,13.03,100,1,13.92,15,1,12.73,100,1,14.07,2,1,12.71,100,1,14.17,100,1,12.5,700,1,14.4,100,1,12.46,200,2,14.56,900,3,12.43,700,1,14.6,700,1,12.42,700,1,14.68,1400,2,12.37,700,1,14.78,100,1,ARL,301452785
,2025-07-17T15:43:44.004667259Z,2025-07-17T15:43:44.004667259Z,10,2,1108,C,A,2,13.92,15,130,165382,252977583,13.26,100,1,13.88,15,1,13.04,2,1,13.89,100,1,13.03,100,1,14.07,2,1,12.73,100,1,14.17,100,1,12.71,100,1,14.4,100,1,12.5,700,1,14.56,900,3,12.46,200,2,14.6,700,1,12.43,700,1,14.68,1400,2,12.42,700,1,14.78,100,1,12.37,700,1,14.88,200,2,ARL,301218889
,2025-07-17T15:43:44.005025587Z,2025-07-17T15:43:44.005025587Z,10,2,1108,C,A,9,14.88,100,0,165524,252977592,13.26,100,1,13.88,15,1,13.04,2,1,13.89,100,1,13.03,100,1,14.07,2,1,12.73,100,1,14.17,100,1,12.71,100,1,14.4,100,1,12.5,700,1,14.56,900,3,12.46,200,2,14.6,700,1,12.43,700,1,14.68,1400,2,12.42,700,1,14.78,100,1,12.37,700,1,14.88,100,1,ARL,300280761
,2025-07-17T15:43:44.005025587Z,2025-07-17T15:43:44.005025587Z,10,2,1108,A,A,8,14.77,100,130,165524,252977592,13.26,100,1,13.88,15,1,13.04,2,1,13.89,100,1,13.03,100,1,14.07,2,1,12.73,100,1,14.17,100,1,12.71,100,1,14.4,100,1,12.5,700,1,14.56,900,3,12.46,200,2,14.6,700,1,12.43,700,1,14.68,1400,2,12.42,700,1,14.77,100,1,12.37,700,1,14.78,100,1,ARL,301671709
,2025-07-17T15:43:44.005147707Z,2025-07-17T15:43:44.005147707Z,10,2,1108,C,A,10,14.88,100,0,165364,252977595,13.26,100,1,13.88,15,1,13.04,2,1,13.89,100,1,13.03,100,1,14.07,2,1,12.73,100,1,14.17,100,1,12.71,100,1,14.4,100,1,12.5,700,1,14.56,900,3,12.46,200,2,14.6,700,1,12.43,700,1,14.68,1400,2,12.42,700,1,14.77,100,1,12.37,700,1,14.78,100,1,ARL,300280745
,2025-07-17T15:43:44.005147707Z,2025-07-17T15:43:44.005147707Z,10,2,1108,A,A,8,14.77,100,130,165364,252977595,13.26,100,1,13.88,15,1,13.04,2,1,13.89,100,1,13.03,100,1,14.07,2,1,12.73,100,1,14.17,100,1,12.71,100,1,14.4,100,1,12.5,700,1,14.56,900,3,12.46,200,2,14.6,700,1,12.43,700,1,14.68,1400,2,12.42,700,1,14.77,200,2,12.37,700,1,14.78,100,1,ARL,301671713
,2025-07-17T15:43:48.787332399Z,2025-07-17T15:43:48.787332399Z,10,2,1108,A,A,0,13.83,15,130,165265,253027890,13.26,100,1,13.83,15,1,13.04,2,1,13.88,15,1,13.03,100,1,13.89,100,1,12.73,100,1,14.07,2,1,12.71,100,1,14.17,100,1,12.5,700,1,14.4,100,1,12.46,200,2,14.56,900,3,12.43,700,1,14.6,700,1,12.42,700,1,14.68,1400,2,12.37,700,1,14.77,200,2,ARL,301746941
,2025-07-17T15:43:48.787601640Z,2025-07-17T15:43:48.787601640Z,10,2,1108,C,A,2,13.89,100,0,165267,253027924,13.26,100,1,13.83,15,1,13.04,2,1,13.88,15,1,13.03,100,1,14.07,2,1,12.73,100,1,14.17,100,1,12.71,100,1,14.4,100,1,12.5,700,1,14.56,900,3,12.46,200,2,14.6,700,1,12.43,700,1,14.68,1400,2,12.42,700,1,14.77,200,2,12.37,700,1,14.78,100,1,ARL,301451061
,2025-07-17T15:43:48.787601640Z,2025-07-17T15:43:48.787601640Z,10,2,1108,A,A,1,13.84,100,130,165267,253027924,13.26,100,1,13.83,15,1,13.04,2,1,13.84,100,1,13.03,100,1,13.88,15,1,12.73,100,1,14.07,2,1,12.71,100,1,14.17,100,1,12.5,700,1,14.4,100,1,12.46,200,2,14.56,900,3,12.43,700,1,14.6,700,1,12.42,700,1,14.68,1400,2,12.37,700,1,14.77,200,2,ARL,301746949
,2025-07-17T15:43:48.790434947Z,2025-07-17T15:43:48.790434947Z,10,2,1108,C,A,10,14.78,100,0,165599,253028027,13.26,100,1,13.83,15,1,13.04,2,1,13.84,100,1,13.03,100,1,13.88,15,1,12.73,100,1,14.07,2,1,12.71,100,1,14.17,100,1,12.5,700,1,14.4,100,1,12.46,200,2,14.56,900,3,12.43,700,1,14.6,700,1,12.42,700,1,14.68,1400,2,12.37,700,1,14.77,200,2,ARL,300280825
,2025-07-17T15:43:48.790434947Z,2025-07-17T15:43:48.790434947Z,10,2,1108,A,A,8,14.64,100,130,165599,253028027,13.26,100,1,13.83,15,1,13.04,2,1,13.84,100,1,13.03,100,1,13.88,15,1,12.73,100,1,14.07,2,1,12.71,100,1,14.17,100,1,12.5,700,1,14.4,100,1,12.46,200,2,14.56,900,3,12.43,700,1,14.6,700,1,12.42,700,1,14.64,100,1,12.37,700,1,14.68,1400,2,ARL,301747005
,2025-07-17T15:43:53.123652480Z,2025-07-17T15:43:53.123652480Z,10,2,1108,C,A,2,13.88,15,130,165279,253100941,13.26,100,1,13.83,15,1,13.04,2,1,13.84,100,1,13.03,100,1,14.07,2,1,12.73,100,1,14.17,100,1,12.71,100,1,14.4,100,1,12.5,700,1,14.56,900,3,12.46,200,2,14.6,700,1,12.43,700,1,14.64,100,1,12.42,700,1,14.68,1400,2,12.37,700,1,14.77,200,2,ARL,301451057
,2025-07-17T15:43:54.126111293Z,2025-07-17T15:43:54.126111293Z,10,2,1108,A,A,0,13.81,15,130,165683,253121467,13.26,100,1,13.81,15,1,13.04,2,1,13.83,15,1,13.03,100,1,13.84,100,1,12.73,100,1,14.07,2,1,12.71,100,1,14.17,100,1,12.5,700,1,14.4,100,1,12.46,200,2,14.56,900,3,12.43,700,1,14.6,700,1,12.42,700,1,14.64,100,1,12.37,700,1,14.68,1400,2,ARL,301867541
,2025-07-17T15:43:54.998073317Z,2025-07-17T15:43:54.998073317Z,10,2,1108,C,A,2,13.84,100,0,165616,253137948,13.26,100,1,13.81,15,1,13.04,2,1,13.83,15,1,13.03,100,1,14.07,2,1,12.73,100,1,14.17,100,1,12.71,100,1,14.4,100,1,12.5,700,1,14.56,900,3,12.46,200,2,14.6,700,1,12.43,700,1,14.64,100,1,12.42,700,1,14.68,1400,2,12.37,700,1,14.77,200,2,ARL,301746949
,2025-07-17T15:43:54.998073317Z,2025-07-17T15:43:54.998073317Z,10,2,1108,A,A,1,13.82,100,130,165616,253137948,13.26,100,1,13.81,15,1,13.04,2,1,13.82,100,1,13.03,100,1,13.83,15,1,12.73,100,1,14.07,2,1,12.71,100,1,14.17,100,1,12.5,700,1,14.4,100,1,12.46,200,2,14.56,900,3,12.43,700,1,14.6,700,1,12.42,700,1,14.64,100,1,12.37,700,1,14.68,1400,2,ARL,301885353
,2025-07-17T15:43:55.019007300Z,2025-07-17T15:43:55.019007300Z,10,2,1108,C,A,4,14.17,100,130,165441,253138492,13.26,100,1,13.81,15,1,13.04,2,1,13.82,100,1,13.03,100,1,13.83,15,1,12.73,100,1,14.07,2,1,12.71,100,1,14.4,100,1,12.5,700,1,14.56,900,3,12.46,200,2,14.6,700,1,12.43,700,1,14.64,100,1,12.42,700,1,14.68,1400,2,12.37,700,1,14.77,200,2,ARL,301452785
,2025-07-17T15:43:55.019060515Z,2025-07-17T15:43:55.019060515Z,10,2,1108,A,A,4,14.1,100,130,165420,253138493,13.26,100,1,13.81,15,1,13.04,2,1,13.82,100,1,13.03,100,1,13.83,15,1,12.73,100,1,14.07,2,1,12.71,100,1,14.1,100,1,12.5,700,1,14.4,100,1,12.46,200,2,14.56,900,3,12.43,700,1,14.6,700,1,12.42,700,1,14.64,100,1,12.37,700,1,14.68,1400,2,ARL,301886057
,2025-07-17T15:44:01.698626200Z,2025-07-17T15:44:01.698626200Z,10,2,1108,C,A,2,13.83,15,130,165267,253246317,13.26,100,1,13.81,15,1,13.04,2,1,13.82,100,1,13.03,100,1,14.07,2,1,12.73,100,1,14.1,100,1,12.71,100,1,14.4,100,1,12.5,700,1,14.56,900,3,12.46,200,2,14.6,700,1,12.43,700,1,14.64,100,1,12.42,700,1,14.68,1400,2,12.37,700,1,14.77,200,2,ARL,301746941
,2025-07-17T15:44:04.014712730Z,2025-07-17T15:44:04.014712730Z,10,2,1108,A,A,2,13.83,100,130,165426,253292355,13.26,100,1,13.81,15,1,13.04,2,1,13.82,100,1,13.03,100,1,13.83,100,1,12.73,100,1,14.07,2,1,12.71,100,1,14.1,100,1,12.5,700,1,14.4,100,1,12.46,200,2,14.56,900,3,12.43,700,1,14.6,700,1,12.42,700,1,14.64,100,1,12.37,700,1,14.68,1400,2,ARL,302078553
,2025-07-17T15:44:05.055461574Z,2025-07-17T15:44:05.055461574Z,10,2,1108,A,A,0,13.81,100,130,165374,253307083,13.26,100,1,13.81,115,2,13.04,2,1,13.82,100,1,13.03,100,1,13.83,100,1,12.73,100,1,14.07,2,1,12.71,100,1,14.1,100,1,12.5,700,1,14.4,100,1,12.46,200,2,14.56,900,3,12.43,700,1,14.6,700,1,12.42,700,1,14.64,100,1,12.37,700,1,14.68,1400,2,ARL,302100649
,2025-07-17T15:44:05.062266845Z,2025-07-17T15:44:05.062266845Z,10,2,1108,C,A,2,13.83,100,130,165104,253307147,13.26,100,1,13.81,115,2,13.04,2,1,13.82,100,1,13.03,100,1,14.07,2,1,12.73,100,1,14.1,100,1,12.71,100,1,14.4,100,1,12.5,700,1,14.56,900,3,12.46,200,2,14.6,700,1,12.43,700,1,14.64,100,1,12.42,700,1,14.68,1400,2,12.37,700,1,14.77,200,2,ARL,302078553
,2025-07-17T15:44:09.389548394Z,2025-07-17T15:44:09.389548394Z,10,2,1108,A,A,0,13.76,15,130,165336,253384422,13.26,100,1,13.76,15,1,13.04,2,1,13.81,115,2,13.03,100,1,13.82,100,1,12.73,100,1,14.07,2,1,12.71,100,1,14.1,100,1,12.5,700,1,14.4,100,1,12.46,200,2,14.56,900,3,12.43,700,1,14.6,700,1,12.42,700,1,14.64,100,1,12.37,700,1,14.68,1400,2,ARL,302205249
,2025-07-17T15:44:09.390329935Z,2025-07-17T15:44:09.390329935Z,10,2,1108,C,A,10,14.77,100,0,166205,253384438,13.26,100,1,13.76,15,1,13.04,2,1,13.81,115,2,13.03,100,1,13.82,100,1,12.73,100,1,14.07,2,1,12.71,100,1,14.1,100,1,12.5,700,1,14.4,100,1,12.46,200,2,14.56,900,3,12.43,700,1,14.6,700,1,12.42,700,1,14.64,100,1,12.37,700,1,14.68,1400,2,ARL,301671709
,2025-07-17T15:44:09.390329935Z,2025-07-17T15:44:09.390329935Z,10,2,1108,A,A,9,14.66,100,128,166205,253384438,13.26,100,1,13.76,15,1,13.04,2,1,13.81,115,2,13.03,100,1,13.82,100,1,12.73,100,1,14.07,2,1,12.71,100,1,14.1,100,1,12.5,700,1,14.4,100,1,12.46,200,2,14.56,900,3,12.43,700,1,14.6,700,1,12.42,700,1,14.64,100,1,12.37,700,1,14.66,100,1,ARL,302205289
,2025-07-17T15:44:09.390893172Z,2025-07-17T15:44:09.390893172Z,10,2,1108,A,A,9,14.66,100,130,165314,253384456,13.26,100,1,13.76,15,1,13.04,2,1,13.81,115,2,13.03,100,1,13.82,100,1,12.73,100,1,14.07,2,1,12.71,100,1,14.1,100,1,12.5,700,1,14.4,100,1,12.46,200,2,14.56,900,3,12.43,700,1,14.6,700,1,12.42,700,1,14.64,100,1,12.37,700,1,14.66,200,2,ARL,302205309
,2025-07-17T15:44:09.395281780Z,2025-07-17T15:44:09.395281780Z,10,2,1108,C,A,2,13.82,100,0,165832,253384698,13.26,100,1,13.76,15,1,13.04,2,1,13.81,115,2,13.03,100,1,14.07,2,1,12.73,100,1,14.1,100,1,12.71,100,1,14.4,100,1,12.5,700,1,14.56,900,3,12.46,200,2,14.6,700,1,12.43,700,1,14.64,100,1,12.42,700,1,14.66,200,2,12.37,700,1,14.68,1400,2,ARL,301885353
,2025-07-17T15:44:09.395281780Z,2025-07-17T15:44:09.395281780Z,10,2,1108,A,A,1,13.77,100,130,165832,253384698,13.26,100,1,13.76,15,1,13.04,2,1,13.77,100,1,13.03,100,1,13.81,115,2,12.73,100,1,14.07,2,1,12.71,100,1,14.1,100,1,12.5,700,1,14.4,100,1,12.46,200,2,14.56,900,3,12.43,700,1,14.6,700,1,12.42,700,1,14.64,100,1,12.37,700,1,14.66,200,2,ARL,302205493
,2025-07-17T15:44:09.397845986Z,2025-07-17T15:44:09.397845986Z,10,2,1108,A,A,2,13.79,100,130,165200,253384788,13.26,100,1,13.76,15,1,13.04,2,1,13.77,100,1,13.03,100,1,13.79,100,1,12.73,100,1,13.81,115,2,12.71,100,1,14.07,2,1,12.5,700,1,14.1,100,1,12.46,200,2,14.4,100,1,12.43,700,1,14.56,900,3,12.42,700,1,14.6,700,1,12.37,700,1,14.64,100,1,ARL,302205561
,2025-07-17T15:44:09.404663816Z,2025-07-17T15:44:09.404663816Z,10,2,1108,C,A,3,13.81,100,130,165140,253385013,13.26,100,1,13.76,15,1,13.04,2,1,13.77,100,1,13.03,100,1,13.79,100,1,12.73,100,1,13.81,15,1,12.71,100,1,14.07,2,1,12.5,700,1,14.1,100,1,12.46,200,2,14.4,100,1,12.43,700,1,14.56,900,3,12.42,700,1,14.6,700,1,12.37,700,1,14.64,100,1,ARL,302100649
,2025-07-17T15:44:20.402370565Z,2025-07-17T15:44:20.402370565Z,10,2,1108,C,A,3,13.81,15,130,165266,253562230,13.26,100,1,13.76,15,1,13.04,2,1,13.77,100,1,13.03,100,1,13.79,100,1,12.73,100,1,14.07,2,1,12.71,100,1,14.1,100,1,12.5,700,1,14.4,100,1,12.46,200,2,14.56,900,3,12.43,700,1,14.6,700,1,12.42,700,1,14.64,100,1,12.37,700,1,14.66,200,2,ARL,301867541
,2025-07-17T15:44:21.405320730Z,2025-07-17T15:44:21.405320730Z,10,2,1108,A,A,0,13.74,15,130,165392,253582427,13.26,100,1,13.74,15,1,13.04,2,1,13.76,15,1,13.03,100,1,13.77,100,1,12.73,100,1,13.79,100,1,12.71,100,1,14.07,2,1,12.5,700,1,14.1,100,1,12.46,200,2,14.4,100,1,12.43,700,1,14.56,900,3,12.42,700,1,14.6,700,1,12.37,700,1,14.64,100,1,ARL,302458113
,2025-07-17T15:44:21.843070079Z,2025-07-17T15:44:21.843070079Z,10,2,1108,C,A,2,13.77,100,0,165832,253590641,13.26,100,1,13.74,15,1,13.04,2,1,13.76,15,1,13.03,100,1,13.79,100,1,12.73,100,1,14.07,2,1,12.71,100,1,14.1,100,1,12.5,700,1,14.4,100,1,12.46,200,2,14.56,900,3,12.43,700,1,14.6,700,1,12.42,700,1,14.64,100,1,12.37,700,1,14.66,200,2,ARL,302205493
,2025-07-17T15:44:21.843070079Z,2025-07-17T15:44:21.843070079Z,10,2,1108,A,A,1,13.75,100,130,165832,253590641,13.26,100,1,13.74,15,1,13.04,2,1,13.75,100,1,13.03,100,1,13.76,15,1,12.73,100,1,13.79,100,1,12.71,100,1,14.07,2,1,12.5,700,1,14.1,100,1,12.46,200,2,14.4,100,1,12.43,700,1,14.56,900,3,12.42,700,1,14.6,700,1,12.37,700,1,14.64,100,1,ARL,302466045
,2025-07-17T15:44:21.855250804Z,2025-07-17T15:44:21.855250804Z,10,2,1108,C,A,5,14.1,100,130,165289,253590837,13.26,100,1,13.74,15,1,13.04,2,1,13.75,100,1,13.03,100,1,13.76,15,1,12.73,100,1,13.79,100,1,12.71,100,1,14.07,2,1,12.5,700,1,14.4,100,1,12.46,200,2,14.56,900,3,12.43,700,1,14.6,700,1,12.42,700,1,14.64,100,1,12.37,700,1,14.66,200,2,ARL,301886057
,2025-07-17T15:44:21.855305995Z,2025-07-17T15:44:21.855305995Z,10,2,1108,A,A,4,14.03,100,130,165163,253590838,13.26,100,1,13.74,15,1,13.04,2,1,13.75,100,1,13.03,100,1,13.76,15,1,12.73,100,1,13.79,100,1,12.71,100,1,14.03,100,1,12.5,700,1,14.07,2,1,12.46,200,2,14.4,100,1,12.43,700,1,14.56,900,3,12.42,700,1,14.6,700,1,12.37,700,1,14.64,100,1,ARL,302466157
,2025-07-17T15:44:24.446910206Z,2025-07-17T15:44:24.446910206Z,10,2,1108,A,A,3,13.77,100,130,165326,253614407,13.26,100,1,13.74,15,1,13.04,2,1,13.75,100,1,13.03,100,1,13.76,15,1,12.73,100,1,13.77,100,1,12.71,100,1,13.79,100,1,12.5,700,1,14.03,100,1,12.46,200,2,14.07,2,1,12.43,700,1,14.4,100,1,12.42,700,1,14.56,900,3,12.37,700,1,14.6,700,1,ARL,302500469
,2025-07-17T15:44:24.465390625Z,2025-07-17T15:44:24.465390625Z,10,2,1108,C,A,4,13.79,100,130,165193,253614591,13.26,100,1,13.74,15,1,13.04,2,1,13.75,100,1,13.03,100,1,13.76,15,1,12.73,100,1,13.77,100,1,12.71,100,1,14.03,100,1,12.5,700,1,14.07,2,1,12.46,200,2,14.4,100,1,12.43,700,1,14.56,900,3,12.42,700,1,14.6,700,1,12.37,700,1,14.64,100,1,ARL,302205561
,2025-07-17T15:44:30.846657613Z,2025-07-17T15:44:30.846657613Z,10,2,1108,C,A,2,13.76,15,130,165370,253704439,13.26,100,1,13.74,15,1,13.04,2,1,13.75,100,1,13.03,100,1,13.77,100,1,12.73,100,1,14.03,100,1,12.71,100,1,14.07,2,1,12.5,700,1,14.4,100,1,12.46,200,2,14.56,900,3,12.43,700,1,14.6,700,1,12.42,700,1,14.64,100,1,12.37,700,1,14.66,200,2,ARL,302205249
,2025-07-17T15:44:31.849618640Z,2025-07-17T15:44:31.849618640Z,10,2,1108,A,A,0,13.72,15,130,166053,253721156,13.26,100,1,13.72,15,1,13.04,2,1,13.74,15,1,13.03,100,1,13.75,100,1,12.73,100,1,13.77,100,1,12.71,100,1,14.03,100,1,12.5,700,1,14.07,2,1,12.46,200,2,14.4,100,1,12.43,700,1,14.56,900,3,12.42,700,1,14.6,700,1,12.37,700,1,14.64,100,1,ARL,302649021
,2025-07-17T15:44:31.849756452Z,2025-07-17T15:44:31.849756452Z,10,2,1108,A,A,2,13.75,100,130,165405,253721157,13.26,100,1,13.72,15,1,13.04,2,1,13.74,15,1,13.03,100,1,13.75,200,2,12.73,100,1,13.77,100,1,12.71,100,1,14.03,100,1,12.5,700,1,14.07,2,1,12.46,200,2,14.4,100,1,12.43,700,1,14.56,900,3,12.42,700,1,14.6,700,1,12.37,700,1,14.64,100,1,ARL,302649029
,2025-07-17T15:44:31.909959614Z,2025-07-17T15:44:31.909959614Z,10,2,1108,C,A,3,13.77,100,130,165364,253722140,13.26,100,1,13.72,15,1,13.04,2,1,13.74,15,1,13.03,100,1,13.75,200,2,12.73,100,1,14.03,100,1,12.71,100,1,14.07,2,1,12.5,700,1,14.4,100,1,12.46,200,2,14.56,900,3,12.43,700,1,14.6,700,1,12.42,700,1,14.64,100,1,12.37,700,1,14.66,200,2,ARL,302500469
,2025-07-17T15:44:32.484331764Z,2025-07-17T15:44:32.484331764Z,10,2,1108,C,A,2,13.75,100,0,165466,253730877,13.26,100,1,13.72,15,1,13.04,2,1,13.74,15,1,13.03,100,1,13.75,100,1,12.73,100,1,14.03,100,1,12.71,100,1,14.07,2,1,12.5,700,1,14.4,100,1,12.46,200,2,14.56,900,3,12.43,700,1,14.6,700,1,12.42,700,1,14.64,100,1,12.37,700,1,14.66,200,2,ARL,302466045
,2025-07-17T15:44:32.484331764Z,2025-07-17T15:44:32.484331764Z,10,2,1108,A,A,1,13.73,100,130,165466,253730877,13.26,100,1,13.72,15,1,13.04,2,1,13.73,100,1,13.03,100,1,13.74,15,1,12.73,100,1,13.75,100,1,12.71,100,1,14.03,100,1,12.5,700,1,14.07,2,1,12.46,200,2,14.4,100,1,12.43,700,1,14.56,900,3,12.42,700,1,14.6,700,1,12.37,700,1,14.64,100,1,ARL,302662769
,2025-07-17T15:44:33.389222513Z,2025-07-17T15:44:33.389222513Z,10,2,1108,A,A,6,14.28,100,130,165301,253745665,13.26,100,1,13.72,15,1,13.04,2,1,13.73,100,1,13.03,100,1,13.74,15,1,12.73,100,1,13.75,100,1,12.71,100,1,14.03,100,1,12.5,700,1,14.07,2,1,12.46,200,2,14.28,100,1,12.43,700,1,14.4,100,1,12.42,700,1,14.56,900,3,12.37,700,1,14.6,700,1,ARL,302681357
,2025-07-17T15:44:33.389223581Z,2025-07-17T15:44:33.389223581Z,10,2,1108,C,A,8,14.56,100,130,165449,253745666,13.26,100,1,13.72,15,1,13.04,2,1,13.73,100,1,13.03,100,1,13.74,15,1,12.73,100,1,13.75,100,1,12.71,100,1,14.03,100,1,12.5,700,1,14.07,2,1,12.46,200,2,14.28,100,1,12.43,700,1,14.4,100,1,12.42,700,1,14.56,800,2,12.37,700,1,14.6,700,1,ARL,146960005
,2025-07-17T15:44:36.362022168Z,2025-07-17T15:44:36.362022168Z,10,2,1108,C,A,2,13.74,15,130,165505,253783635,13.26,100,1,13.72,15,1,13.04,2,1,13.73,100,1,13.03,100,1,13.75,100,1,12.73,100,1,14.03,100,1,12.71,100,1,14.07,2,1,12.5,700,1,14.28,100,1,12.46,200,2,14.4,100,1,12.43,700,1,14.56,800,2,12.42,700,1,14.6,700,1,12.37,700,1,14.64,100,1,ARL,302458113
,2025-07-17T15:44:37.364212109Z,2025-07-17T15:44:37.364212109Z,10,2,1108,A,A,0,13.7,15,130,165310,253797506,13.26,100,1,13.7,15,1,13.04,2,1,13.72,15,1,13.03,100,1,13.73,100,1,12.73,100,1,13.75,100,1,12.71,100,1,14.03,100,1,12.5,700,1,14.07,2,1,12.46,200,2,14.28,100,1,12.43,700,1,14.4,100,1,12.42,700,1,14.56,800,2,12.37,700,1,14.6,700,1,ARL,302750929
,2025-07-17T15:44:37.364353897Z,2025-07-17T15:44:37.364353897Z,10,2,1108,A,A,2,13.73,100,130,165170,253797510,13.26,100,1,13.7,15,1,13.04,2,1,13.72,15,1,13.03,100,1,13.73,200,2,12.73,100,1,13.75,100,1,12.71,100,1,14.03,100,1,12.5,700,1,14.07,2,1,12.46,200,2,14.28,100,1,12.43,700,1,14.4,100,1,12.42,700,1,14.56,800,2,12.37,700,1,14.6,700,1,ARL,302750937
,2025-07-17T15:44:37.457954350Z,2025-07-17T15:44:37.457954350Z,10,2,1108,C,A,3,13.75,100,130,165144,253798432,13.26,100,1,13.7,15,1,13.04,2,1,13.72,15,1,13.03,100,1,13.73,200,2,12.73,100,1,14.03,100,1,12.71,100,1,14.07,2,1,12.5,700,1,14.28,100,1,12.46,200,2,14.4,100,1,12.43,700,1,14.56,800,2,12.42,700,1,14.6,700,1,12.37,700,1,14.64,100,1,ARL,302649029
,2025-07-17T15:44:38.432294362Z,2025-07-17T15:44:38.432294362Z,10,2,1108,C,A,2,13.73,100,0,166147,253807786,13.26,100,1,13.7,15,1,13.04,2,1,13.72,15,1,13.03,100,1,13.73,100,1,12.73,100,1,14.03,100,1,12.71,100,1,14.07,2,1,12.5,700,1,14.28,100,1,12.46,200,2,14.4,100,1,12.43,700,1,14.56,800,2,12.42,700,1,14.6,700,1,12.37,700,1,14.64,100,1,ARL,302662769
,2025-07-17T15:44:38.432294362Z,2025-07-17T15:44:38.432294362Z,10,2,1108,A,A,1,13.71,100,130,166147,253807786,13.26,100,1,13.7,15,1,13.04,2,1,13.71,100,1,13.03,100,1,13.72,15,1,12.73,100,1,13.73,100,1,12.71,100,1,14.03,100,1,12.5,700,1,14.07,2,1,12.46,200,2,14.28,100,1,12.43,700,1,14.4,100,1,12.42,700,1,14.56,800,2,12.37,700,1,14.6,700,1,ARL,302763889
,2025-07-17T15:44:43.019083502Z,2025-07-17T15:44:43.019083502Z,10,2,1108,C,A,0,13.7,15,128,178715,253875920,13.26,100,1,13.71,100,1,13.04,2,1,13.72,15,1,13.03,100,1,13.73,100,1,12.73,100,1,14.03,100,1,12.71,100,1,14.07,2,1,12.5,700,1,14.28,100,1,12.46,200,2,14.4,100,1,12.43,700,1,14.56,800,2,12.42,700,1,14.6,700,1,12.37,700,1,14.64,100,1,ARL,302750929
,2025-07-17T15:44:43.019184132Z,2025-07-17T15:44:43.019184132Z,10,2,1108,C,A,1,13.72,15,128,168526,253876010,13.26,100,1,13.71,100,1,13.04,2,1,13.73,100,1,13.03,100,1,14.03,100,1,12.73,100,1,14.07,2,1,12.71,100,1,14.28,100,1,12.5,700,1,14.4,100,1,12.46,200,2,14.56,800,2,12.43,700,1,14.6,700,1,12.42,700,1,14.64,100,1,12.37,700,1,14.66,200,2,ARL,302649021
,2025-07-17T15:44:44.075843113Z,2025-07-17T15:44:44.075843113Z,10,2,1108,A,A,0,13.7,15,128,166886,253892869,13.26,100,1,13.7,15,1,13.04,2,1,13.71,100,1,13.03,100,1,13.73,100,1,12.73,100,1,14.03,100,1,12.71,100,1,14.07,2,1,12.5,700,1,14.28,100,1,12.46,200,2,14.4,100,1,12.43,700,1,14.56,800,2,12.42,700,1,14.6,700,1,12.37,700,1,14.64,100,1,ARL,302867209
,2025-07-17T15:44:44.781464821Z,2025-07-17T15:44:44.781464821Z,10,2,1108,C,A,0,13.7,15,130,165911,253901222,13.26,100,1,13.71,100,1,13.04,2,1,13.73,100,1,13.03,100,1,14.03,100,1,12.73,100,1,14.07,2,1,12.71,100,1,14.28,100,1,12.5,700,1,14.4,100,1,12.46,200,2,14.56,800,2,12.43,700,1,14.6,700,1,12.42,700,1,14.64,100,1,12.37,700,1,14.66,200,2,ARL,302867209
,2025-07-17T15:44:53.143083969Z,2025-07-17T15:44:53.143083969Z,10,2,1108,C,A,1,13.73,100,130,165301,254011871,13.26,100,1,13.71,100,1,13.04,2,1,14.03,100,1,13.03,100,1,14.07,2,1,12.73,100,1,14.28,100,1,12.71,100,1,14.4,100,1,12.5,700,1,14.56,800,2,12.46,200,2,14.6,700,1,12.43,700,1,14.64,100,1,12.42,700,1,14.66,200,2,12.37,700,1,14.68,1400,2,ARL,302750937
,2025-07-17T15:44:57.191023026Z,2025-07-17T15:44:57.191023026Z,10,2,1108,A,A,1,13.75,100,130,165444,254079162,13.26,100,1,13.71,100,1,13.04,2,1,13.75,100,1,13.03,100,1,14.03,100,1,12.73,100,1,14.07,2,1,12.71,100,1,14.28,100,1,12.5,700,1,14.4,100,1,12.46,200,2,14.56,800,2,12.43,700,1,14.6,700,1,12.42,700,1,14.64,100,1,12.37,700,1,14.66,200,2,ARL,303118785
,2025-07-17T15:45:07.065587919Z,2025-07-17T15:45:07.065587919Z,10,2,1108,C,A,0,13.71,100,128,168655,254244597,13.26,100,1,13.75,100,1,13.04,2,1,14.03,100,1,13.03,100,1,14.07,2,1,12.73,100,1,14.28,100,1,12.71,100,1,14.4,100,1,12.5,700,1,14.56,800,2,12.46,200,2,14.6,700,1,12.43,700,1,14.64,100,1,12.42,700,1,14.66,200,2,12.37,700,1,14.68,1400,2,ARL,302763889
,2025-07-17T15:45:07.079966224Z,2025-07-17T15:45:07.079966224Z,10,2,1108,C,A,0,13.75,100,130,165281,254245492,13.26,100,1,14.03,100,1,13.04,2,1,14.07,2,1,13.03,100,1,14.28,100,1,12.73,100,1,14.4,100,1,12.71,100,1,14.56,800,2,12.5,700,1,14.6,700,1,12.46,200,2,14.64,100,1,12.43,700,1,14.66,200,2,12.42,700,1,14.68,1400,2,12.37,700,1,14.79,100,1,ARL,303118785
,2025-07-17T15:45:07.080521807Z,2025-07-17T15:45:07.080521807Z,10,2,1108,C,A,7,14.66,100,0,165408,254245505,13.26,100,1,14.03,100,1,13.04,2,1,14.07,2,1,13.03,100,1,14.28,100,1,12.73,100,1,14.4,100,1,12.71,100,1,14.56,800,2,12.5,700,1,14.6,700,1,12.46,200,2,14.64,100,1,12.43,700,1,14.66,100,1,12.42,700,1,14.68,1400,2,12.37,700,1,14.79,100,1,ARL,302205289
,2025-07-17T15:45:07.080706110Z,2025-07-17T15:45:07.080706110Z,10,2,1108,C,A,9,14.79,100,0,166135,254245511,13.26,100,1,14.03,100,1,13.04,2,1,14.07,2,1,13.03,100,1,14.28,100,1,12.73,100,1,14.4,100,1,12.71,100,1,14.56,800,2,12.5,700,1,14.6,700,1,12.46,200,2,14.64,100,1,12.43,700,1,14.66,100,1,12.42,700,1,14.68,1400,2,12.37,700,1,14.81,200,2,ARL,302662821
,2025-07-17T15:45:07.081407507Z,2025-07-17T15:45:07.081407507Z,10,2,1108,C,A,9,14.81,100,0,170557,254245568,13.26,100,1,14.03,100,1,13.04,2,1,14.07,2,1,13.03,100,1,14.28,100,1,12.73,100,1,14.4,100,1,12.71,100,1,14.56,800,2,12.5,700,1,14.6,700,1,12.46,200,2,14.64,100,1,12.43,700,1,14.66,100,1,12.42,700,1,14.68,1400,2,12.37,700,1,14.81,100,1,ARL,301747001
,2025-07-17T15:45:07.081441134Z,2025-07-17T15:45:07.081441134Z,10,2,1108,C,A,7,14.66,100,0,166836,254245576,13.26,100,1,14.03,100,1,13.04,2,1,14.07,2,1,13.03,100,1,14.28,100,1,12.73,100,1,14.4,100,1,12.71,100,1,14.56,800,2,12.5,700,1,14.6,700,1,12.46,200,2,14.64,100,1,12.43,700,1,14.68,1400,2,12.42,700,1,14.81,100,1,12.37,700,1,14.89,100,1,ARL,302205309
,2025-07-17T15:45:07.081441134Z,2025-07-17T15:45:07.081441134Z,10,2,1108,A,A,9,14.89,100,130,166836,254245576,13.26,100,1,14.03,100,1,13.04,2,1,14.07,2,1,13.03,100,1,14.28,100,1,12.73,100,1,14.4,100,1,12.71,100,1,14.56,800,2,12.5,700,1,14.6,700,1,12.46,200,2,14.64,100,1,12.43,700,1,14.68,1400,2,12.42,700,1,14.81,100,1,12.37,700,1,14.89,200,2,ARL,303330521
,2025-07-17T15:45:07.085057258Z,2025-07-17T15:45:07.085057258Z,10,2,1108,C,A,0,14.03,100,130,165267,254246434,13.26,100,1,14.07,2,1,13.04,2,1,14.28,100,1,13.03,100,1,14.4,100,1,12.73,100,1,14.56,800,2,12.71,100,1,14.6,700,1,12.5,700,1,14.64,100,1,12.46,200,2,14.68,1400,2,12.43,700,1,14.81,100,1,12.42,700,1,14.89,200,2,12.37,700,1,14.96,100,1,ARL,302466157
,2025-07-17T15:45:07.085109545Z,2025-07-17T15:45:07.085109545Z,10,2,1108,A,A,1,14.26,100,130,165307,254246437,13.26,100,1,14.07,2,1,13.04,2,1,14.26,100,1,13.03,100,1,14.28,100,1,12.73,100,1,14.4,100,1,12.71,100,1,14.56,800,2,12.5,700,1,14.6,700,1,12.46,200,2,14.64,100,1,12.43,700,1,14.68,1400,2,12.42,700,1,14.81,100,1,12.37,700,1,14.89,200,2,ARL,303331401
,2025-07-17T15:45:07.086368957Z,2025-07-17T15:45:07.086368957Z,10,2,1108,C,A,6,14.64,100,130,165743,254246501,13.26,100,1,14.07,2,1,13.04,2,1,14.26,100,1,13.03,100,1,14.28,100,1,12.73,100,1,14.4,100,1,12.71,100,1,14.56,800,2,12.5,700,1,14.6,700,1,12.46,200,2,14.68,1400,2,12.43,700,1,14.81,100,1,12.42,700,1,14.89,200,2,12.37,700,1,14.96,100,1,ARL,301747005
,2025-07-17T15:45:07.086494745Z,2025-07-17T15:45:07.086494745Z,10,2,1108,A,A,7,14.78,100,130,165580,254246502,13.26,100,1,14.07,2,1,13.04,2,1,14.26,100,1,13.03,100,1,14.28,100,1,12.73,100,1,14.4,100,1,12.71,100,1,14.56,800,2,12.5,700,1,14.6,700,1,12.46,200,2,14.68,1400,2,12.43,700,1,14.78,100,1,12.42,700,1,14.81,100,1,12.37,700,1,14.89,200,2,ARL,303331425
,2025-07-17T15:45:07.133812895Z,2025-07-17T15:45:07.133812895Z,10,2,1108,C,A,8,14.81,100,0,165593,254250625,13.26,100,1,14.07,2,1,13.04,2,1,14.26,100,1,13.03,100,1,14.28,100,1,12.73,100,1,14.4,100,1,12.71,100,1,14.56,800,2,12.5,700,1,14.6,700,1,12.46,200,2,14.68,1400,2,12.43,700,1,14.78,100,1,12.42,700,1,14.89,200,2,12.37,700,1,14.96,100,1,ARL,301747957
,2025-07-17T15:45:07.133812895Z,2025-07-17T15:45:07.133812895Z,10,2,1108,A,A,9,14.96,100,130,165593,254250625,13.26,100,1,14.07,2,1,13.04,2,1,14.26,100,1,13.03,100,1,14.28,100,1,12.73,100,1,14.4,100,1,12.71,100,1,14.56,800,2,12.5,700,1,14.6,700,1,12.46,200,2,14.68,1400,2,12.43,700,1,14.78,100,1,12.42,700,1,14.89,200,2,12.37,700,1,14.96,200,2,ARL,303334253
,2025-07-17T15:45:07.469796155Z,2025-07-17T15:45:07.469796155Z,10,2,1108,A,A,1,14.08,100,130,165147,254258029,13.26,100,1,14.07,2,1,13.04,2,1,14.08,100,1,13.03,100,1,14.26,100,1,12.73,100,1,14.28,100,1,12.71,100,1,14.4,100,1,12.5,700,1,14.56,800,2,12.46,200,2,14.6,700,1,12.43,700,1,14.68,1400,2,12.42,700,1,14.78,100,1,12.37,700,1,14.89,200,2,ARL,303340405
,2025-07-17T15:45:08.094603115Z,2025-07-17T15:45:08.094603115Z,10,2,1108,C,A,9,14.89,100,0,165437,254266885,13.26,100,1,14.07,2,1,13.04,2,1,14.08,100,1,13.03,100,1,14.26,100,1,12.73,100,1,14.28,100,1,12.71,100,1,14.4,100,1,12.5,700,1,14.56,800,2,12.46,200,2,14.6,700,1,12.43,700,1,14.68,1400,2,12.42,700,1,14.78,100,1,12.37,700,1,14.89,100,1,ARL,303330521
,2025-07-17T15:45:08.103141155Z,2025-07-17T15:45:08.103141155Z,10,2,1108,C,A,9,14.89,100,0,165489,254266971,13.26,100,1,14.07,2,1,13.04,2,1,14.08,100,1,13.03,100,1,14.26,100,1,12.73,100,1,14.28,100,1,12.71,100,1,14.4,100,1,12.5,700,1,14.56,800,2,12.46,200,2,14.6,700,1,12.43,700,1,14.68,1400,2,12.42,700,1,14.78,100,1,12.37,700,1,14.96,200,2,ARL,303330477
,2025-07-17T15:45:24.186842413Z,2025-07-17T15:45:24.186842413Z,10,2,1108,A,A,9,14.88,100,130,165865,254547413,13.26,100,1,14.07,2,1,13.04,2,1,14.08,100,1,13.03,100,1,14.26,100,1,12.73,100,1,14.28,100,1,12.71,100,1,14.4,100,1,12.5,700,1,14.56,800,2,12.46,200,2,14.6,700,1,12.43,700,1,14.68,1400,2,12.42,700,1,14.78,100,1,12.37,700,1,14.88,100,1,ARL,303682385
,2025-07-17T15:45:24.187276389Z,2025-07-17T15:45:24.187276389Z,10,2,1108,A,A,9,14.88,100,130,165503,254547415,13.26,100,1,14.07,2,1,13.04,2,1,14.08,100,1,13.03,100,1,14.26,100,1,12.73,100,1,14.28,100,1,12.71,100,1,14.4,100,1,12.5,700,1,14.56,800,2,12.46,200,2,14.6,700,1,12.43,700,1,14.68,1400,2,12.42,700,1,14.78,100,1,12.37,700,1,14.88,200,2,ARL,303682389
,2025-07-17T15:45:37.509289536Z,2025-07-17T15:45:37.509289536Z,10,2,1108,A,A,0,13.94,15,130,165352,254851462,13.26,100,1,13.94,15,1,13.04,2,1,14.07,2,1,13.03,100,1,14.08,100,1,12.73,100,1,14.26,100,1,12.71,100,1,14.28,100,1,12.5,700,1,14.4,100,1,12.46,200,2,14.56,800,2,12.43,700,1,14.6,700,1,12.42,700,1,14.68,1400,2,12.37,700,1,14.78,100,1,ARL,304056997
,2025-07-17T15:45:37.997967775Z,2025-07-17T15:45:37.997967775Z,10,2,1108,C,A,2,14.08,100,0,165722,254864588,13.26,100,1,13.94,15,1,13.04,2,1,14.07,2,1,13.03,100,1,14.26,100,1,12.73,100,1,14.28,100,1,12.71,100,1,14.4,100,1,12.5,700,1,14.56,800,2,12.46,200,2,14.6,700,1,12.43,700,1,14.68,1400,2,12.42,700,1,14.78,100,1,12.37,700,1,14.88,200,2,ARL,303340405
,2025-07-17T15:45:37.997967775Z,2025-07-17T15:45:37.997967775Z,10,2,1108,A,A,1,13.95,100,130,165722,254864588,13.26,100,1,13.94,15,1,13.04,2,1,13.95,100,1,13.03,100,1,14.07,2,1,12.73,100,1,14.26,100,1,12.71,100,1,14.28,100,1,12.5,700,1,14.4,100,1,12.46,200,2,14.56,800,2,12.43,700,1,14.6,700,1,12.42,700,1,14.68,1400,2,12.37,700,1,14.78,100,1,ARL,304072245
,2025-07-17T15:45:44.700428155Z,2025-07-17T15:45:44.700428155Z,10,2,1108,A,A,0,13.89,15,130,165253,254999429,13.26,100,1,13.89,15,1,13.04,2,1,13.94,15,1,13.03,100,1,13.95,100,1,12.73,100,1,14.07,2,1,12.71,100,1,14.26,100,1,12.5,700,1,14.28,100,1,12.46,200,2,14.4,100,1,12.43,700,1,14.56,800,2,12.42,700,1,14.6,700,1,12.37,700,1,14.68,1400,2,ARL,304238913
,2025-07-17T15:45:45.262371701Z,2025-07-17T15:45:45.262371701Z,10,2,1108,C,A,2,13.95,100,0,165421,255010979,13.26,100,1,13.89,15,1,13.04,2,1,13.94,15,1,13.03,100,1,14.07,2,1,12.73,100,1,14.26,100,1,12.71,100,1,14.28,100,1,12.5,700,1,14.4,100,1,12.46,200,2,14.56,800,2,12.43,700,1,14.6,700,1,12.42,700,1,14.68,1400,2,12.37,700,1,14.78,100,1,ARL,304072245
,2025-07-17T15:45:45.262371701Z,2025-07-17T15:45:45.262371701Z,10,2,1108,A,A,1,13.9,100,130,165421,255010979,13.26,100,1,13.89,15,1,13.04,2,1,13.9,100,1,13.03,100,1,13.94,15,1,12.73,100,1,14.07,2,1,12.71,100,1,14.26,100,1,12.5,700,1,14.28,100,1,12.46,200,2,14.4,100,1,12.43,700,1,14.56,800,2,12.42,700,1,14.6,700,1,12.37,700,1,14.68,1400,2,ARL,304252313
,2025-07-17T15:45:45.274194870Z,2025-07-17T15:45:45.274194870Z,10,2,1108,C,A,4,14.26,100,130,165512,255011158,13.26,100,1,13.89,15,1,13.04,2,1,13.9,100,1,13.03,100,1,13.94,15,1,12.73,100,1,14.07,2,1,12.71,100,1,14.28,100,1,12.5,700,1,14.4,100,1,12.46,200,2,14.56,800,2,12.43,700,1,14.6,700,1,12.42,700,1,14.68,1400,2,12.37,700,1,14.78,100,1,ARL,303331401
,2025-07-17T15:45:45.274245387Z,2025-07-17T15:45:45.274245387Z,10,2,1108,A,A,4,14.18,100,130,165334,255011161,13.26,100,1,13.89,15,1,13.04,2,1,13.9,100,1,13.03,100,1,13.94,15,1,12.73,100,1,14.07,2,1,12.71,100,1,14.18,100,1,12.5,700,1,14.28,100,1,12.46,200,2,14.4,100,1,12.43,700,1,14.56,800,2,12.42,700,1,14.6,700,1,12.37,700,1,14.68,1400,2,ARL,304252469
,2025-07-17T15:45:58.419617935Z,2025-07-17T15:45:58.419617935Z,10,2,1108,C,A,2,13.94,15,130,165398,255183198,13.26,100,1,13.89,15,1,13.04,2,1,13.9,100,1,13.03,100,1,14.07,2,1,12.73,100,1,14.18,100,1,12.71,100,1,14.28,100,1,12.5,700,1,14.4,100,1,12.46,200,2,14.56,800,2,12.43,700,1,14.6,700,1,12.42,700,1,14.68,1400,2,12.37,700,1,14.78,100,1,ARL,304056997
,2025-07-17T15:45:58.420113307Z,2025-07-17T15:45:58.420113307Z,10,2,1108,C,A,10,14.88,100,0,165384,255183203,13.26,100,1,13.89,15,1,13.04,2,1,13.9,100,1,13.03,100,1,14.07,2,1,12.73,100,1,14.18,100,1,12.71,100,1,14.28,100,1,12.5,700,1,14.4,100,1,12.46,200,2,14.56,800,2,12.43,700,1,14.6,700,1,12.42,700,1,14.68,1400,2,12.37,700,1,14.78,100,1,ARL,303682389
,2025-07-17T15:45:58.420113307Z,2025-07-17T15:45:58.420113307Z,10,2,1108,A,A,9,14.77,100,130,165384,255183203,13.26,100,1,13.89,15,1,13.04,2,1,13.9,100,1,13.03,100,1,14.07,2,1,12.73,100,1,14.18,100,1,12.71,100,1,14.28,100,1,12.5,700,1,14.4,100,1,12.46,200,2,14.56,800,2,12.43,700,1,14.6,700,1,12.42,700,1,14.68,1400,2,12.37,700,1,14.77,100,1,ARL,304503585
,2025-07-17T15:45:58.420590199Z,2025-07-17T15:45:58.420590199Z,10,2,1108,A,A,9,14.77,100,130,165690,255183204,13.26,100,1,13.89,15,1,13.04,2,1,13.9,100,1,13.03,100,1,14.07,2,1,12.73,100,1,14.18,100,1,12.71,100,1,14.28,100,1,12.5,700,1,14.4,100,1,12.46,200,2,14.56,800,2,12.43,700,1,14.6,700,1,12.42,700,1,14.68,1400,2,12.37,700,1,14.77,200,2,ARL,304503593
,2025-07-17T15:45:58.782726994Z,2025-07-17T15:45:58.782726994Z,10,2,1108,C,A,0,13.89,15,130,165115,255189425,13.26,100,1,13.9,100,1,13.04,2,1,14.07,2,1,13.03,100,1,14.18,100,1,12.73,100,1,14.28,100,1,12.71,100,1,14.4,100,1,12.5,700,1,14.56,800,2,12.46,200,2,14.6,700,1,12.43,700,1,14.68,1400,2,12.42,700,1,14.77,200,2,12.37,700,1,14.78,100,1,ARL,304238913
,2025-07-17T15:46:16.782892334Z,2025-07-17T15:46:16.782892334Z,10,2,1108,A,A,0,13.88,15,130,165282,255552962,13.26,100,1,13.88,15,1,13.04,2,1,13.9,100,1,13.03,100,1,14.07,2,1,12.73,100,1,14.18,100,1,12.71,100,1,14.28,100,1,12.5,700,1,14.4,100,1,12.46,200,2,14.56,800,2,12.43,700,1,14.6,700,1,12.42,700,1,14.68,1400,2,12.37,700,1,14.77,200,2,ARL,304949689
,2025-07-17T15:46:16.783160795Z,2025-07-17T15:46:16.783160795Z,10,2,1108,C,A,1,13.9,100,0,165446,255552970,13.26,100,1,13.88,15,1,13.04,2,1,14.07,2,1,13.03,100,1,14.18,100,1,12.73,100,1,14.28,100,1,12.71,100,1,14.4,100,1,12.5,700,1,14.56,800,2,12.46,200,2,14.6,700,1,12.43,700,1,14.68,1400,2,12.42,700,1,14.77,200,2,12.37,700,1,14.78,100,1,ARL,304252313
,2025-07-17T15:46:16.783160795Z,2025-07-17T15:46:16.783160795Z,10,2,1108,A,A,1,13.89,100,130,165446,255552970,13.26,100,1,13.88,15,1,13.04,2,1,13.89,100,1,13.03,100,1,14.07,2,1,12.73,100,1,14.18,100,1,12.71,100,1,14.28,100,1,12.5,700,1,14.4,100,1,12.46,200,2,14.56,800,2,12.43,700,1,14.6,700,1,12.42,700,1,14.68,1400,2,12.37,700,1,14.77,200,2,ARL,304949697
,2025-07-17T15:46:18.782732218Z,2025-07-17T15:46:18.782732218Z,10,2,1108,C,A,0,13.88,15,130,165352,255587336,13.26,100,1,13.89,100,1,13.04,2,1,14.07,2,1,13.03,100,1,14.18,100,1,12.73,100,1,14.28,100,1,12.71,100,1,14.4,100,1,12.5,700,1,14.56,800,2,12.46,200,2,14.6,700,1,12.43,700,1,14.68,1400,2,12.42,700,1,14.77,200,2,12.37,700,1,14.78,100,1,ARL,304949689
,2025-07-17T15:46:28.474001551Z,2025-07-17T15:46:28.474001551Z,10,2,1108,C,A,0,13.89,100,130,165346,255746167,13.26,100,1,14.07,2,1,13.04,2,1,14.18,100,1,13.03,100,1,14.28,100,1,12.73,100,1,14.4,100,1,12.71,100,1,14.56,800,2,12.5,700,1,14.6,700,1,12.46,200,2,14.68,1400,2,12.43,700,1,14.77,200,2,12.42,700,1,14.78,100,1,12.37,700,1,14.96,200,2,ARL,304949697
,2025-07-17T15:46:28.474561156Z,2025-07-17T15:46:28.474561156Z,10,2,1108,C,A,7,14.77,100,0,165438,255746173,13.26,100,1,14.07,2,1,13.04,2,1,14.18,100,1,13.03,100,1,14.28,100,1,12.73,100,1,14.4,100,1,12.71,100,1,14.56,800,2,12.5,700,1,14.6,700,1,12.46,200,2,14.68,1400,2,12.43,700,1,14.77,100,1,12.42,700,1,14.78,100,1,12.37,700,1,14.96,200,2,ARL,304503593
,2025-07-17T15:46:28.474561156Z,2025-07-17T15:46:28.474561156Z,10,2,1108,A,A,9,14.88,100,130,165438,255746173,13.26,100,1,14.07,2,1,13.04,2,1,14.18,100,1,13.03,100,1,14.28,100,1,12.73,100,1,14.4,100,1,12.71,100,1,14.56,800,2,12.5,700,1,14.6,700,1,12.46,200,2,14.68,1400,2,12.43,700,1,14.77,100,1,12.42,700,1,14.78,100,1,12.37,700,1,14.88,100,1,ARL,305184937
,2025-07-17T15:46:28.474730225Z,2025-07-17T15:46:28.474730225Z,10,2,1108,C,A,7,14.77,100,0,166235,255746176,13.26,100,1,14.07,2,1,13.04,2,1,14.18,100,1,13.03,100,1,14.28,100,1,12.73,100,1,14.4,100,1,12.71,100,1,14.56,800,2,12.5,700,1,14.6,700,1,12.46,200,2,14.68,1400,2,12.43,700,1,14.78,100,1,12.42,700,1,14.88,100,1,12.37,700,1,14.96,200,2,ARL,304503585
,2025-07-17T15:46:28.474730225Z,2025-07-17T15:46:28.474730225Z,10,2,1108,A,A,8,14.88,100,130,166235,255746176,13.26,100,1,14.07,2,1,13.04,2,1,14.18,100,1,13.03,100,1,14.28,100,1,12.73,100,1,14.4,100,1,12.71,100,1,14.56,800,2,12.5,700,1,14.6,700,1,12.46,200,2,14.68,1400,2,12.43,700,1,14.78,100,1,12.42,700,1,14.88,200,2,12.37,700,1,14.96,200,2,ARL,305184953
,2025-07-17T15:46:28.474736101Z,2025-07-17T15:46:28.474736101Z,10,2,1108,C,A,10,14.98,100,0,166053,255746178,13.26,100,1,14.07,2,1,13.04,2,1,14.18,100,1,13.03,100,1,14.28,100,1,12.73,100,1,14.4,100,1,12.71,100,1,14.56,800,2,12.5,700,1,14.6,700,1,12.46,200,2,14.68,1400,2,12.43,700,1,14.78,100,1,12.42,700,1,14.88,200,2,12.37,700,1,14.96,200,2,ARL,304252333
,2025-07-17T15:46:28.474736101Z,2025-07-17T15:46:28.474736101Z,10,2,1108,A,A,10,15.03,100,128,166053,255746178,13.26,100,1,14.07,2,1,13.04,2,1,14.18,100,1,13.03,100,1,14.28,100,1,12.73,100,1,14.4,100,1,12.71,100,1,14.56,800,2,12.5,700,1,14.6,700,1,12.46,200,2,14.68,1400,2,12.43,700,1,14.78,100,1,12.42,700,1,14.88,200,2,12.37,700,1,14.96,200,2,ARL,305184957
,2025-07-17T15:46:28.492716775Z,2025-07-17T15:46:28.492716775Z,10,2,1108,C,A,1,14.18,100,130,165205,255746619,13.26,100,1,14.07,2,1,13.04,2,1,14.28,100,1,13.03,100,1,14.4,100,1,12.73,100,1,14.56,800,2,12.71,100,1,14.6,700,1,12.5,700,1,14.68,1400,2,12.46,200,2,14.78,100,1,12.43,700,1,14.88,200,2,12.42,700,1,14.96,200,2,12.37,700,1,15.03,100,1,ARL,304252469
,2025-07-17T15:46:28.492765859Z,2025-07-17T15:46:28.492765859Z,10,2,1108,A,A,1,14.26,100,130,165420,255746621,13.26,100,1,14.07,2,1,13.04,2,1,14.26,100,1,13.03,100,1,14.28,100,1,12.73,100,1,14.4,100,1,12.71,100,1,14.56,800,2,12.5,700,1,14.6,700,1,12.46,200,2,14.68,1400,2,12.43,700,1,14.78,100,1,12.42,700,1,14.88,200,2,12.37,700,1,14.96,200,2,ARL,305185529
,2025-07-17T15:46:28.646108242Z,2025-07-17T15:46:28.646108242Z,10,2,1108,A,A,1,14.08,100,130,165225,255748568,13.26,100,1,14.07,2,1,13.04,2,1,14.08,100,1,13.03,100,1,14.26,100,1,12.73,100,1,14.28,100,1,12.71,100,1,14.4,100,1,12.5,700,1,14.56,800,2,12.46,200,2,14.6,700,1,12.43,700,1,14.68,1400,2,12.42,700,1,14.78,100,1,12.37,700,1,14.88,200,2,ARL,305187077
,2025-07-17T15:46:57.523859388Z,2025-07-17T15:46:57.523859388Z,10,2,1108,A,A,0,13.92,15,130,165270,256268482,13.26,100,1,13.92,15,1,13.04,2,1,14.07,2,1,13.03,100,1,14.08,100,1,12.73,100,1,14.26,100,1,12.71,100,1,14.28,100,1,12.5,700,1,14.4,100,1,12.46,200,2,14.56,800,2,12.43,700,1,14.6,700,1,12.42,700,1,14.68,1400,2,12.37,700,1,14.78,100,1,ARL,305862145
,2025-07-17T15:46:57.932677299Z,2025-07-17T15:46:57.932677299Z,10,2,1108,C,A,2,14.08,100,0,165695,256280751,13.26,100,1,13.92,15,1,13.04,2,1,14.07,2,1,13.03,100,1,14.26,100,1,12.73,100,1,14.28,100,1,12.71,100,1,14.4,100,1,12.5,700,1,14.56,800,2,12.46,200,2,14.6,700,1,12.43,700,1,14.68,1400,2,12.42,700,1,14.78,100,1,12.37,700,1,14.88,200,2,ARL,305187077
,2025-07-17T15:46:57.932677299Z,2025-07-17T15:46:57.932677299Z,10,2,1108,A,A,1,13.93,100,130,165695,256280751,13.26,100,1,13.92,15,1,13.04,2,1,13.93,100,1,13.03,100,1,14.07,2,1,12.73,100,1,14.26,100,1,12.71,100,1,14.28,100,1,12.5,700,1,14.4,100,1,12.46,200,2,14.56,800,2,12.43,700,1,14.6,700,1,12.42,700,1,14.68,1400,2,12.37,700,1,14.78,100,1,ARL,305878881
,2025-07-17T15:47:06.609290857Z,2025-07-17T15:47:06.609290857Z,10,2,1108,A,A,0,13.88,15,130,165394,256488374,13.26,100,1,13.88,15,1,13.04,2,1,13.92,15,1,13.03,100,1,13.93,100,1,12.73,100,1,14.07,2,1,12.71,100,1,14.26,100,1,12.5,700,1,14.28,100,1,12.46,200,2,14.4,100,1,12.43,700,1,14.56,800,2,12.42,700,1,14.6,700,1,12.37,700,1,14.68,1400,2,ARL,306121113
,2025-07-17T15:47:08.787529505Z,2025-07-17T15:47:08.787529505Z,10,2,1108,C,A,2,13.93,100,0,165639,256532991,13.26,100,1,13.88,15,1,13.04,2,1,13.92,15,1,13.03,100,1,14.07,2,1,12.73,100,1,14.26,100,1,12.71,100,1,14.28,100,1,12.5,700,1,14.4,100,1,12.46,200,2,14.56,800,2,12.43,700,1,14.6,700,1,12.42,700,1,14.68,1400,2,12.37,700,1,14.78,100,1,ARL,305878881
,2025-07-17T15:47:08.787529505Z,2025-07-17T15:47:08.787529505Z,10,2,1108,A,A,1,13.89,100,130,165639,256532991,13.26,100,1,13.88,15,1,13.04,2,1,13.89,100,1,13.03,100,1,13.92,15,1,12.73,100,1,14.07,2,1,12.71,100,1,14.26,100,1,12.5,700,1,14.28,100,1,12.46,200,2,14.4,100,1,12.43,700,1,14.56,800,2,12.42,700,1,14.6,700,1,12.37,700,1,14.68,1400,2,ARL,306170837
,2025-07-17T15:47:08.805818249Z,2025-07-17T15:47:08.805818249Z,10,2,1108,C,A,4,14.26,100,130,165157,256533442,13.26,100,1,13.88,15,1,13.04,2,1,13.89,100,1,13.03,100,1,13.92,15,1,12.73,100,1,14.07,2,1,12.71,100,1,14.28,100,1,12.5,700,1,14.4,100,1,12.46,200,2,14.56,800,2,12.43,700,1,14.6,700,1,12.42,700,1,14.68,1400,2,12.37,700,1,14.78,100,1,ARL,305185529
,2025-07-17T15:47:08.805868059Z,2025-07-17T15:47:08.805868059Z,10,2,1108,A,A,4,14.17,100,130,165714,256533443,13.26,100,1,13.88,15,1,13.04,2,1,13.89,100,1,13.03,100,1,13.92,15,1,12.73,100,1,14.07,2,1,12.71,100,1,14.17,100,1,12.5,700,1,14.28,100,1,12.46,200,2,14.4,100,1,12.43,700,1,14.56,800,2,12.42,700,1,14.6,700,1,12.37,700,1,14.68,1400,2,ARL,306171457
,2025-07-17T15:47:13.121288953Z,2025-07-17T15:47:13.121288953Z,10,2,1108,C,A,0,13.88,15,130,165402,256612694,13.26,100,1,13.89,100,1,13.04,2,1,13.92,15,1,13.03,100,1,14.07,2,1,12.73,100,1,14.17,100,1,12.71,100,1,14.28,100,1,12.5,700,1,14.4,100,1,12.46,200,2,14.56,800,2,12.43,700,1,14.6,700,1,12.42,700,1,14.68,1400,2,12.37,700,1,14.78,100,1,ARL,306121113
,2025-07-17T15:47:13.122396816Z,2025-07-17T15:47:13.122396816Z,10,2,1108,C,A,1,13.92,15,130,165717,256612757,13.26,100,1,13.89,100,1,13.04,2,1,14.07,2,1,13.03,100,1,14.17,100,1,12.73,100,1,14.28,100,1,12.71,100,1,14.4,100,1,12.5,700,1,14.56,800,2,12.46,200,2,14.6,700,1,12.43,700,1,14.68,1400,2,12.42,700,1,14.78,100,1,12.37,700,1,14.88,200,2,ARL,305862145
,2025-07-17T15:47:24.786310694Z,2025-07-17T15:47:24.786310694Z,10,2,1108,A,A,0,13.87,15,130,165572,256812416,13.26,100,1,13.87,15,1,13.04,2,1,13.89,100,1,13.03,100,1,14.07,2,1,12.73,100,1,14.17,100,1,12.71,100,1,14.28,100,1,12.5,700,1,14.4,100,1,12.46,200,2,14.56,800,2,12.43,700,1,14.6,700,1,12.42,700,1,14.68,1400,2,12.37,700,1,14.78,100,1,ARL,306519385
,2025-07-17T15:47:24.786580061Z,2025-07-17T15:47:24.786580061Z,10,2,1108,C,A,1,13.89,100,0,165596,256812420,13.26,100,1,13.87,15,1,13.04,2,1,14.07,2,1,13.03,100,1,14.17,100,1,12.73,100,1,14.28,100,1,12.71,100,1,14.4,100,1,12.5,700,1,14.56,800,2,12.46,200,2,14.6,700,1,12.43,700,1,14.68,1400,2,12.42,700,1,14.78,100,1,12.37,700,1,14.88,200,2,ARL,306170837
,2025-07-17T15:47:24.786580061Z,2025-07-17T15:47:24.786580061Z,10,2,1108,A,A,1,13.88,100,130,165596,256812420,13.26,100,1,13.87,15,1,13.04,2,1,13.88,100,1,13.03,100,1,14.07,2,1,12.73,100,1,14.17,100,1,12.71,100,1,14.28,100,1,12.5,700,1,14.4,100,1,12.46,200,2,14.56,800,2,12.43,700,1,14.6,700,1,12.42,700,1,14.68,1400,2,12.37,700,1,14.78,100,1,ARL,306519397
,2025-07-17T15:47:24.786759805Z,2025-07-17T15:47:24.786759805Z,10,2,1108,C,A,10,14.88,100,0,165924,256812422,13.26,100,1,13.87,15,1,13.04,2,1,13.88,100,1,13.03,100,1,14.07,2,1,12.73,100,1,14.17,100,1,12.71,100,1,14.28,100,1,12.5,700,1,14.4,100,1,12.46,200,2,14.56,800,2,12.43,700,1,14.6,700,1,12.42,700,1,14.68,1400,2,12.37,700,1,14.78,100,1,ARL,305184937
,2025-07-17T15:47:24.786759805Z,2025-07-17T15:47:24.786759805Z,10,2,1108,A,A,9,14.77,100,130,165924,256812422,13.26,100,1,13.87,15,1,13.04,2,1,13.88,100,1,13.03,100,1,14.07,2,1,12.73,100,1,14.17,100,1,12.71,100,1,14.28,100,1,12.5,700,1,14.4,100,1,12.46,200,2,14.56,800,2,12.43,700,1,14.6,700,1,12.42,700,1,14.68,1400,2,12.37,700,1,14.77,100,1,ARL,306519409
,2025-07-17T15:47:24.800449950Z,2025-07-17T15:47:24.800449950Z,10,2,1108,A,A,9,14.75,100,130,166054,256812578,13.26,100,1,13.87,15,1,13.04,2,1,13.88,100,1,13.03,100,1,14.07,2,1,12.73,100,1,14.17,100,1,12.71,100,1,14.28,100,1,12.5,700,1,14.4,100,1,12.46,200,2,14.56,800,2,12.43,700,1,14.6,700,1,12.42,700,1,14.68,1400,2,12.37,700,1,14.75,100,1,ARL,306519741
,2025-07-17T15:47:27.860107552Z,2025-07-17T15:47:27.860107552Z,10,2,1108,A,A,0,13.83,15,130,165340,256866835,13.26,100,1,13.83,15,1,13.04,2,1,13.87,15,1,13.03,100,1,13.88,100,1,12.73,100,1,14.07,2,1,12.71,100,1,14.17,100,1,12.5,700,1,14.28,100,1,12.46,200,2,14.4,100,1,12.43,700,1,14.56,800,2,12.42,700,1,14.6,700,1,12.37,700,1,14.68,1400,2,ARL,306587393
,2025-07-17T15:47:31.406863918Z,2025-07-17T15:47:31.406863918Z,10,2,1108,C,A,2,13.88,100,0,165394,256910124,13.26,100,1,13.83,15,1,13.04,2,1,13.87,15,1,13.03,100,1,14.07,2,1,12.73,100,1,14.17,100,1,12.71,100,1,14.28,100,1,12.5,700,1,14.4,100,1,12.46,200,2,14.56,800,2,12.43,700,1,14.6,700,1,12.42,700,1,14.68,1400,2,12.37,700,1,14.75,100,1,ARL,306519397
,2025-07-17T15:47:31.406863918Z,2025-07-17T15:47:31.406863918Z,10,2,1108,A,A,1,13.84,100,130,165394,256910124,13.26,100,1,13.83,15,1,13.04,2,1,13.84,100,1,13.03,100,1,13.87,15,1,12.73,100,1,14.07,2,1,12.71,100,1,14.17,100,1,12.5,700,1,14.28,100,1,12.46,200,2,14.4,100,1,12.43,700,1,14.56,800,2,12.42,700,1,14.6,700,1,12.37,700,1,14.68,1400,2,ARL,306647425
,2025-07-17T15:47:31.413325908Z,2025-07-17T15:47:31.413325908Z,10,2,1108,A,A,9,14.64,100,130,165569,256910184,13.26,100,1,13.83,15,1,13.04,2,1,13.84,100,1,13.03,100,1,13.87,15,1,12.73,100,1,14.07,2,1,12.71,100,1,14.17,100,1,12.5,700,1,14.28,100,1,12.46,200,2,14.4,100,1,12.43,700,1,14.56,800,2,12.42,700,1,14.6,700,1,12.37,700,1,14.64,100,1,ARL,306647521
,2025-07-17T15:47:37.159424166Z,2025-07-17T15:47:37.159424166Z,10,2,1108,C,A,2,13.87,15,130,165638,256983942,13.26,100,1,13.83,15,1,13.04,2,1,13.84,100,1,13.03,100,1,14.07,2,1,12.73,100,1,14.17,100,1,12.71,100,1,14.28,100,1,12.5,700,1,14.4,100,1,12.46,200,2,14.56,800,2,12.43,700,1,14.6,700,1,12.42,700,1,14.64,100,1,12.37,700,1,14.68,1400,2,ARL,306519385
,2025-07-17T15:47:37.171834941Z,2025-07-17T15:47:37.171834941Z,10,2,1108,A,A,2,13.85,100,130,165499,256984053,13.26,100,1,13.83,15,1,13.04,2,1,13.84,100,1,13.03,100,1,13.85,100,1,12.73,100,1,14.07,2,1,12.71,100,1,14.17,100,1,12.5,700,1,14.28,100,1,12.46,200,2,14.4,100,1,12.43,700,1,14.56,800,2,12.42,700,1,14.6,700,1,12.37,700,1,14.64,100,1,ARL,306749753
,2025-07-17T15:47:38.161015969Z,2025-07-17T15:47:38.161015969Z,10,2,1108,A,A,0,13.79,15,130,165314,256998606,13.26,100,1,13.79,15,1,13.04,2,1,13.83,15,1,13.03,100,1,13.84,100,1,12.73,100,1,13.85,100,1,12.71,100,1,14.07,2,1,12.5,700,1,14.17,100,1,12.46,200,2,14.28,100,1,12.43,700,1,14.4,100,1,12.42,700,1,14.56,800,2,12.37,700,1,14.6,700,1,ARL,306770041
,2025-07-17T15:47:38.794795887Z,2025-07-17T15:47:38.794795887Z,10,2,1108,C,A,2,13.84,100,0,166358,257010989,13.26,100,1,13.79,15,1,13.04,2,1,13.83,15,1,13.03,100,1,13.85,100,1,12.73,100,1,14.07,2,1,12.71,100,1,14.17,100,1,12.5,700,1,14.28,100,1,12.46,200,2,14.4,100,1,12.43,700,1,14.56,800,2,12.42,700,1,14.6,700,1,12.37,700,1,14.64,100,1,ARL,306647425
,2025-07-17T15:47:38.794795887Z,2025-07-17T15:47:38.794795887Z,10,2,1108,A,A,1,13.8,100,128,166358,257010989,13.26,100,1,13.79,15,1,13.04,2,1,13.8,100,1,13.03,100,1,13.83,15,1,12.73,100,1,13.85,100,1,12.71,100,1,14.07,2,1,12.5,700,1,14.17,100,1,12.46,200,2,14.28,100,1,12.43,700,1,14.4,100,1,12.42,700,1,14.56,800,2,12.37,700,1,14.6,700,1,ARL,306784133
,2025-07-17T15:47:38.804458744Z,2025-07-17T15:47:38.804458744Z,10,2,1108,C,A,5,14.17,100,130,165514,257011716,13.26,100,1,13.79,15,1,13.04,2,1,13.8,100,1,13.03,100,1,13.83,15,1,12.73,100,1,13.85,100,1,12.71,100,1,14.07,2,1,12.5,700,1,14.28,100,1,12.46,200,2,14.4,100,1,12.43,700,1,14.56,800,2,12.42,700,1,14.6,700,1,12.37,700,1,14.64,100,1,ARL,306171457
,2025-07-17T15:47:38.804513793Z,2025-07-17T15:47:38.804513793Z,10,2,1108,A,A,5,14.08,100,130,165799,257011717,13.26,100,1,13.79,15,1,13.04,2,1,13.8,100,1,13.03,100,1,13.83,15,1,12.73,100,1,13.85,100,1,12.71,100,1,14.07,2,1,12.5,700,1,14.08,100,1,12.46,200,2,14.28,100,1,12.43,700,1,14.4,100,1,12.42,700,1,14.56,800,2,12.37,700,1,14.6,700,1,ARL,306784853
,2025-07-17T15:47:39.092305947Z,2025-07-17T15:47:39.092305947Z,10,2,1108,C,A,0,13.79,15,130,166112,257018687,13.26,100,1,13.8,100,1,13.04,2,1,13.83,15,1,13.03,100,1,13.85,100,1,12.73,100,1,14.07,2,1,12.71,100,1,14.08,100,1,12.5,700,1,14.28,100,1,12.46,200,2,14.4,100,1,12.43,700,1,14.56,800,2,12.42,700,1,14.6,700,1,12.37,700,1,14.64,100,1,ARL,306770041
,2025-07-17T15:47:39.095755335Z,2025-07-17T15:47:39.095755335Z,10,2,1108,C,A,1,13.83,15,130,165524,257018796,13.26,100,1,13.8,100,1,13.04,2,1,13.85,100,1,13.03,100,1,14.07,2,1,12.73,100,1,14.08,100,1,12.71,100,1,14.28,100,1,12.5,700,1,14.4,100,1,12.46,200,2,14.56,800,2,12.43,700,1,14.6,700,1,12.42,700,1,14.64,100,1,12.37,700,1,14.68,1400,2,ARL,306587393
,2025-07-17T15:48:08.909201576Z,2025-07-17T15:48:08.909201576Z,10,2,1108,A,A,1,13.83,100,130,165329,257603755,13.26,100,1,13.8,100,1,13.04,2,1,13.83,100,1,13.03,100,1,13.85,100,1,12.73,100,1,14.07,2,1,12.71,100,1,14.08,100,1,12.5,700,1,14.28,100,1,12.46,200,2,14.4,100,1,12.43,700,1,14.56,800,2,12.42,700,1,14.6,700,1,12.37,700,1,14.64,100,1,ARL,307567929
,2025-07-17T15:48:08.916555821Z,2025-07-17T15:48:08.916555821Z,10,2,1108,C,A,2,13.85,100,130,165277,257604057,13.26,100,1,13.8,100,1,13.04,2,1,13.83,100,1,13.03,100,1,14.07,2,1,12.73,100,1,14.08,100,1,12.71,100,1,14.28,100,1,12.5,700,1,14.4,100,1,12.46,200,2,14.56,800,2,12.43,700,1,14.6,700,1,12.42,700,1,14.64,100,1,12.37,700,1,14.68,1400,2,ARL,306749753
,2025-07-17T15:48:09.653308042Z,2025-07-17T15:48:09.653308042Z,10,2,1108,A,A,0,13.78,15,130,165423,257621095,13.26,100,1,13.78,15,1,13.04,2,1,13.8,100,1,13.03,100,1,13.83,100,1,12.73,100,1,14.07,2,1,12.71,100,1,14.08,100,1,12.5,700,1,14.28,100,1,12.46,200,2,14.4,100,1,12.43,700,1,14.56,800,2,12.42,700,1,14.6,700,1,12.37,700,1,14.64,100,1,ARL,307587873
,2025-07-17T15:48:11.166517494Z,2025-07-17T15:48:11.166517494Z,10,2,1108,C,A,0,13.78,15,128,171760,257644020,13.26,100,1,13.8,100,1,13.04,2,1,13.83,100,1,13.03,100,1,14.07,2,1,12.73,100,1,14.08,100,1,12.71,100,1,14.28,100,1,12.5,700,1,14.4,100,1,12.46,200,2,14.56,800,2,12.43,700,1,14.6,700,1,12.42,700,1,14.64,100,1,12.37,700,1,14.68,1400,2,ARL,307587873
,2025-07-17T15:48:13.508913083Z,2025-07-17T15:48:13.508913083Z,10,2,1108,A,A,0,13.78,15,130,165470,257727039,13.26,100,1,13.78,15,1,13.04,2,1,13.8,100,1,13.03,100,1,13.83,100,1,12.73,100,1,14.07,2,1,12.71,100,1,14.08,100,1,12.5,700,1,14.28,100,1,12.46,200,2,14.4,100,1,12.43,700,1,14.56,800,2,12.42,700,1,14.6,700,1,12.37,700,1,14.64,100,1,ARL,307714769
,2025-07-17T15:48:13.525788139Z,2025-07-17T15:48:13.525788139Z,10,2,1108,A,A,2,13.81,100,130,165406,257727301,13.26,100,1,13.78,15,1,13.04,2,1,13.8,100,1,13.03,100,1,13.81,100,1,12.73,100,1,13.83,100,1,12.71,100,1,14.07,2,1,12.5,700,1,14.08,100,1,12.46,200,2,14.28,100,1,12.43,700,1,14.4,100,1,12.42,700,1,14.56,800,2,12.37,700,1,14.6,700,1,ARL,307715101
,2025-07-17T15:48:13.532443045Z,2025-07-17T15:48:13.532443045Z,10,2,1108,C,A,3,13.83,100,130,165829,257727457,13.26,100,1,13.78,15,1,13.04,2,1,13.8,100,1,13.03,100,1,13.81,100,1,12.73,100,1,14.07,2,1,12.71,100,1,14.08,100,1,12.5,700,1,14.28,100,1,12.46,200,2,14.4,100,1,12.43,700,1,14.56,800,2,12.42,700,1,14.6,700,1,12.37,700,1,14.64,100,1,ARL,307567929
,2025-07-17T15:48:15.568378275Z,2025-07-17T15:48:15.568378275Z,10,2,1108,C,A,1,13.8,100,0,165879,257757458,13.26,100,1,13.78,15,1,13.04,2,1,13.81,100,1,13.03,100,1,14.07,2,1,12.73,100,1,14.08,100,1,12.71,100,1,14.28,100,1,12.5,700,1,14.4,100,1,12.46,200,2,14.56,800,2,12.43,700,1,14.6,700,1,12.42,700,1,14.64,100,1,12.37,700,1,14.68,1400,2,ARL,306784133
,2025-07-17T15:48:15.568378275Z,2025-07-17T15:48:15.568378275Z,10,2,1108,A,A,1,13.79,100,130,165879,257757458,13.26,100,1,13.78,15,1,13.04,2,1,13.79,100,1,13.03,100,1,13.81,100,1,12.73,100,1,14.07,2,1,12.71,100,1,14.08,100,1,12.5,700,1,14.28,100,1,12.46,200,2,14.4,100,1,12.43,700,1,14.56,800,2,12.42,700,1,14.6,700,1,12.37,700,1,14.64,100,1,ARL,307753241
,2025-07-17T15:48:24.009190157Z,2025-07-17T15:48:24.009190157Z,10,2,1108,A,A,0,13.75,15,130,165189,257928318,13.26,100,1,13.75,15,1,13.04,2,1,13.78,15,1,13.03,100,1,13.79,100,1,12.73,100,1,13.81,100,1,12.71,100,1,14.07,2,1,12.5,700,1,14.08,100,1,12.46,200,2,14.28,100,1,12.43,700,1,14.4,100,1,12.42,700,1,14.56,800,2,12.37,700,1,14.6,700,1,ARL,307964605
,2025-07-17T15:48:24.009357442Z,2025-07-17T15:48:24.009357442Z,10,2,1108,A,A,2,13.79,100,130,165191,257928319,13.26,100,1,13.75,15,1,13.04,2,1,13.78,15,1,13.03,100,1,13.79,200,2,12.73,100,1,13.81,100,1,12.71,100,1,14.07,2,1,12.5,700,1,14.08,100,1,12.46,200,2,14.28,100,1,12.43,700,1,14.4,100,1,12.42,700,1,14.56,800,2,12.37,700,1,14.6,700,1,ARL,307964609
,2025-07-17T15:48:24.009778967Z,2025-07-17T15:48:24.009778967Z,10,2,1108,C,A,2,13.79,100,0,165414,257928325,13.26,100,1,13.75,15,1,13.04,2,1,13.78,15,1,13.03,100,1,13.79,100,1,12.73,100,1,13.81,100,1,12.71,100,1,14.07,2,1,12.5,700,1,14.08,100,1,12.46,200,2,14.28,100,1,12.43,700,1,14.4,100,1,12.42,700,1,14.56,800,2,12.37,700,1,14.6,700,1,ARL,307753241
,2025-07-17T15:48:24.009778967Z,2025-07-17T15:48:24.009778967Z,10,2,1108,A,A,1,13.76,100,130,165414,257928325,13.26,100,1,13.75,15,1,13.04,2,1,13.76,100,1,13.03,100,1,13.78,15,1,12.73,100,1,13.79,100,1,12.71,100,1,13.81,100,1,12.5,700,1,14.07,2,1,12.46,200,2,14.08,100,1,12.43,700,1,14.28,100,1,12.42,700,1,14.4,100,1,12.37,700,1,14.56,800,2,ARL,307964621
,2025-07-17T15:48:24.009808793Z,2025-07-17T15:48:24.009808793Z,10,2,1108,C,A,4,13.81,100,130,165373,257928326,13.26,100,1,13.75,15,1,13.04,2,1,13.76,100,1,13.03,100,1,13.78,15,1,12.73,100,1,13.79,100,1,12.71,100,1,14.07,2,1,12.5,700,1,14.08,100,1,12.46,200,2,14.28,100,1,12.43,700,1,14.4,100,1,12.42,700,1,14.56,800,2,12.37,700,1,14.6,700,1,ARL,307715101
,2025-07-17T15:48:42.009788565Z,2025-07-17T15:48:42.009788565Z,10,2,1108,C,A,2,13.78,15,130,165481,258199397,13.26,100,1,13.75,15,1,13.04,2,1,13.76,100,1,13.03,100,1,13.79,100,1,12.73,100,1,14.07,2,1,12.71,100,1,14.08,100,1,12.5,700,1,14.28,100,1,12.46,200,2,14.4,100,1,12.43,700,1,14.56,800,2,12.42,700,1,14.6,700,1,12.37,700,1,14.64,100,1,ARL,307714769
,2025-07-17T15:48:42.011680742Z,2025-07-17T15:48:42.011680742Z,10,2,1108,A,A,9,14.64,100,130,165650,258199535,13.26,100,1,13.75,15,1,13.04,2,1,13.76,100,1,13.03,100,1,13.79,100,1,12.73,100,1,14.07,2,1,12.71,100,1,14.08,100,1,12.5,700,1,14.28,100,1,12.46,200,2,14.4,100,1,12.43,700,1,14.56,800,2,12.42,700,1,14.6,700,1,12.37,700,1,14.64,200,2,ARL,308296381
,2025-07-17T15:48:42.016595806Z,2025-07-17T15:48:42.016595806Z,10,2,1108,A,A,2,13.77,100,130,165568,258199787,13.26,100,1,13.75,15,1,13.04,2,1,13.76,100,1,13.03,100,1,13.77,100,1,12.73,100,1,13.79,100,1,12.71,100,1,14.07,2,1,12.5,700,1,14.08,100,1,12.46,200,2,14.28,100,1,12.43,700,1,14.4,100,1,12.42,700,1,14.56,800,2,12.37,700,1,14.6,700,1,ARL,308296741
,2025-07-17T15:48:42.023266760Z,2025-07-17T15:48:42.023266760Z,10,2,1108,C,A,3,13.79,100,130,165647,258199990,13.26,100,1,13.75,15,1,13.04,2,1,13.76,100,1,13.03,100,1,13.77,100,1,12.73,100,1,14.07,2,1,12.71,100,1,14.08,100,1,12.5,700,1,14.28,100,1,12.46,200,2,14.4,100,1,12.43,700,1,14.56,800,2,12.42,700,1,14.6,700,1,12.37,700,1,14.64,200,2,ARL,307964609
,2025-07-17T15:48:46.749922127Z,2025-07-17T15:48:46.749922127Z,10,2,1108,A,A,0,13.73,15,128,166363,258260871,13.26,100,1,13.73,15,1,13.04,2,1,13.75,15,1,13.03,100,1,13.76,100,1,12.73,100,1,13.77,100,1,12.71,100,1,14.07,2,1,12.5,700,1,14.08,100,1,12.46,200,2,14.28,100,1,12.43,700,1,14.4,100,1,12.42,700,1,14.56,800,2,12.37,700,1,14.6,700,1,ARL,308374537
,2025-07-17T15:48:46.758385367Z,2025-07-17T15:48:46.758385367Z,10,2,1108,C,A,2,13.76,100,0,165666,258261154,13.26,100,1,13.73,15,1,13.04,2,1,13.75,15,1,13.03,100,1,13.77,100,1,12.73,100,1,14.07,2,1,12.71,100,1,14.08,100,1,12.5,700,1,14.28,100,1,12.46,200,2,14.4,100,1,12.43,700,1,14.56,800,2,12.42,700,1,14.6,700,1,12.37,700,1,14.64,200,2,ARL,307964621
,2025-07-17T15:48:46.758385367Z,2025-07-17T15:48:46.758385367Z,10,2,1108,A,A,1,13.74,100,130,165666,258261154,13.26,100,1,13.73,15,1,13.04,2,1,13.74,100,1,13.03,100,1,13.75,15,1,12.73,100,1,13.77,100,1,12.71,100,1,14.07,2,1,12.5,700,1,14.08,100,1,12.46,200,2,14.28,100,1,12.43,700,1,14.4,100,1,12.42,700,1,14.56,800,2,12.37,700,1,14.6,700,1,ARL,308374881
,2025-07-17T15:48:46.773503306Z,2025-07-17T15:48:46.773503306Z,10,2,1108,C,A,5,14.08,100,130,165682,258261538,13.26,100,1,13.73,15,1,13.04,2,1,13.74,100,1,13.03,100,1,13.75,15,1,12.73,100,1,13.77,100,1,12.71,100,1,14.07,2,1,12.5,700,1,14.28,100,1,12.46,200,2,14.4,100,1,12.43,700,1,14.56,800,2,12.42,700,1,14.6,700,1,12.37,700,1,14.64,200,2,ARL,306784853
,2025-07-17T15:48:46.773555566Z,2025-07-17T15:48:46.773555566Z,10,2,1108,A,A,4,14.01,100,130,165160,258261539,13.26,100,1,13.73,15,1,13.04,2,1,13.74,100,1,13.03,100,1,13.75,15,1,12.73,100,1,13.77,100,1,12.71,100,1,14.01,100,1,12.5,700,1,14.07,2,1,12.46,200,2,14.28,100,1,12.43,700,1,14.4,100,1,12.42,700,1,14.56,800,2,12.37,700,1,14.6,700,1,ARL,308375185
,2025-07-17T15:49:02.010329052Z,2025-07-17T15:49:02.010329052Z,10,2,1108,A,A,2,13.75,100,130,165428,258502869,13.26,100,1,13.73,15,1,13.04,2,1,13.74,100,1,13.03,100,1,13.75,115,2,12.73,100,1,13.77,100,1,12.71,100,1,14.01,100,1,12.5,700,1,14.07,2,1,12.46,200,2,14.28,100,1,12.43,700,1,14.4,100,1,12.42,700,1,14.56,800,2,12.37,700,1,14.6,700,1,ARL,308705489
,2025-07-17T15:49:02.019824230Z,2025-07-17T15:49:02.019824230Z,10,2,1108,C,A,3,13.77,100,130,165337,258502929,13.26,100,1,13.73,15,1,13.04,2,1,13.74,100,1,13.03,100,1,13.75,115,2,12.73,100,1,14.01,100,1,12.71,100,1,14.07,2,1,12.5,700,1,14.28,100,1,12.46,200,2,14.4,100,1,12.43,700,1,14.56,800,2,12.42,700,1,14.6,700,1,12.37,700,1,14.64,200,2,ARL,308296741
,2025-07-17T15:49:03.405840358Z,2025-07-17T15:49:03.405840358Z,10,2,1108,C,A,2,13.75,15,130,165232,258527308,13.26,100,1,13.73,15,1,13.04,2,1,13.74,100,1,13.03,100,1,13.75,100,1,12.73,100,1,14.01,100,1,12.71,100,1,14.07,2,1,12.5,700,1,14.28,100,1,12.46,200,2,14.4,100,1,12.43,700,1,14.56,800,2,12.42,700,1,14.6,700,1,12.37,700,1,14.64,200,2,ARL,307964605
,2025-07-17T15:49:04.713831675Z,2025-07-17T15:49:04.713831675Z,10,2,1108,A,A,0,13.71,15,128,166250,258547335,13.26,100,1,13.71,15,1,13.04,2,1,13.73,15,1,13.03,100,1,13.74,100,1,12.73,100,1,13.75,100,1,12.71,100,1,14.01,100,1,12.5,700,1,14.07,2,1,12.46,200,2,14.28,100,1,12.43,700,1,14.4,100,1,12.42,700,1,14.56,800,2,12.37,700,1,14.6,700,1,ARL,308763065
,2025-07-17T15:49:06.012946379Z,2025-07-17T15:49:06.012946379Z,10,2,1108,A,A,1,13.73,100,130,165562,258567259,13.26,100,1,13.71,15,1,13.04,2,1,13.73,115,2,13.03,100,1,13.74,100,1,12.73,100,1,13.75,100,1,12.71,100,1,14.01,100,1,12.5,700,1,14.07,2,1,12.46,200,2,14.28,100,1,12.43,700,1,14.4,100,1,12.42,700,1,14.56,800,2,12.37,700,1,14.6,700,1,ARL,308786185
,2025-07-17T15:49:06.023126600Z,2025-07-17T15:49:06.023126600Z,10,2,1108,C,A,3,13.75,100,130,165547,258567405,13.26,100,1,13.71,15,1,13.04,2,1,13.73,115,2,13.03,100,1,13.74,100,1,12.73,100,1,14.01,100,1,12.71,100,1,14.07,2,1,12.5,700,1,14.28,100,1,12.46,200,2,14.4,100,1,12.43,700,1,14.56,800,2,12.42,700,1,14.6,700,1,12.37,700,1,14.64,200,2,ARL,308705489
,2025-07-17T15:49:06.344191321Z,2025-07-17T15:49:06.344191321Z,10,2,1108,C,A,2,13.74,100,0,165569,258574949,13.26,100,1,13.71,15,1,13.04,2,1,13.73,115,2,13.03,100,1,14.01,100,1,12.73,100,1,14.07,2,1,12.71,100,1,14.28,100,1,12.5,700,1,14.4,100,1,12.46,200,2,14.56,800,2,12.43,700,1,14.6,700,1,12.42,700,1,14.64,200,2,12.37,700,1,14.65,100,1,ARL,308374881
,2025-07-17T15:49:06.344191321Z,2025-07-17T15:49:06.344191321Z,10,2,1108,A,A,1,13.72,100,130,165569,258574949,13.26,100,1,13.71,15,1,13.04,2,1,13.72,100,1,13.03,100,1,13.73,115,2,12.73,100,1,14.01,100,1,12.71,100,1,14.07,2,1,12.5,700,1,14.28,100,1,12.46,200,2,14.4,100,1,12.43,700,1,14.56,800,2,12.42,700,1,14.6,700,1,12.37,700,1,14.64,200,2,ARL,308797069
,2025-07-17T15:49:10.459152457Z,2025-07-17T15:49:10.459152457Z,10,2,1108,C,A,2,13.73,15,130,165428,258636400,13.26,100,1,13.71,15,1,13.04,2,1,13.72,100,1,13.03,100,1,13.73,100,1,12.73,100,1,14.01,100,1,12.71,100,1,14.07,2,1,12.5,700,1,14.28,100,1,12.46,200,2,14.4,100,1,12.43,700,1,14.56,800,2,12.42,700,1,14.6,700,1,12.37,700,1,14.64,200,2,ARL,308374537
,2025-07-17T15:49:11.460432218Z,2025-07-17T15:49:11.460432218Z,10,2,1108,A,A,0,13.69,15,130,165382,258650544,13.26,100,1,13.69,15,1,13.04,2,1,13.71,15,1,13.03,100,1,13.72,100,1,12.73,100,1,13.73,100,1,12.71,100,1,14.01,100,1,12.5,700,1,14.07,2,1,12.46,200,2,14.28,100,1,12.43,700,1,14.4,100,1,12.42,700,1,14.56,800,2,12.37,700,1,14.6,700,1,ARL,308893737
,2025-07-17T15:49:11.891477604Z,2025-07-17T15:49:11.891477604Z,10,2,1108,C,A,2,13.72,100,0,165495,258658721,13.26,100,1,13.69,15,1,13.04,2,1,13.71,15,1,13.03,100,1,13.73,100,1,12.73,100,1,14.01,100,1,12.71,100,1,14.07,2,1,12.5,700,1,14.28,100,1,12.46,200,2,14.4,100,1,12.43,700,1,14.56,800,2,12.42,700,1,14.6,700,1,12.37,700,1,14.64,200,2,ARL,308797069
,2025-07-17T15:49:11.891477604Z,2025-07-17T15:49:11.891477604Z,10,2,1108,A,A,1,13.7,100,130,165495,258658721,13.26,100,1,13.69,15,1,13.04,2,1,13.7,100,1,13.03,100,1,13.71,15,1,12.73,100,1,13.73,100,1,12.71,100,1,14.01,100,1,12.5,700,1,14.07,2,1,12.46,200,2,14.28,100,1,12.43,700,1,14.4,100,1,12.42,700,1,14.56,800,2,12.37,700,1,14.6,700,1,ARL,308901793
,2025-07-17T15:49:11.948535655Z,2025-07-17T15:49:11.948535655Z,10,2,1108,C,A,10,14.64,100,130,165394,258659496,13.26,100,1,13.69,15,1,13.04,2,1,13.7,100,1,13.03,100,1,13.71,15,1,12.73,100,1,13.73,100,1,12.71,100,1,14.01,100,1,12.5,700,1,14.07,2,1,12.46,200,2,14.28,100,1,12.43,700,1,14.4,100,1,12.42,700,1,14.56,800,2,12.37,700,1,14.6,700,1,ARL,306647521
,2025-07-17T15:49:11.948663655Z,2025-07-17T15:49:11.948663655Z,10,2,1108,A,A,8,14.5,100,130,165457,258659499,13.26,100,1,13.69,15,1,13.04,2,1,13.7,100,1,13.03,100,1,13.71,15,1,12.73,100,1,13.73,100,1,12.71,100,1,14.01,100,1,12.5,700,1,14.07,2,1,12.46,200,2,14.28,100,1,12.43,700,1,14.4,100,1,12.42,700,1,14.5,100,1,12.37,700,1,14.56,800,2,ARL,308903349
,2025-07-17T15:49:12.221056085Z,2025-07-17T15:49:12.221056085Z,10,2,1108,A,A,2,13.71,100,130,165282,258663292,13.26,100,1,13.69,15,1,13.04,2,1,13.7,100,1,13.03,100,1,13.71,115,2,12.73,100,1,13.73,100,1,12.71,100,1,14.01,100,1,12.5,700,1,14.07,2,1,12.46,200,2,14.28,100,1,12.43,700,1,14.4,100,1,12.42,700,1,14.5,100,1,12.37,700,1,14.56,800,2,ARL,308909249
,2025-07-17T15:49:12.227821500Z,2025-07-17T15:49:12.227821500Z,10,2,1108,C,A,3,13.73,100,130,165405,258663378,13.26,100,1,13.69,15,1,13.04,2,1,13.7,100,1,13.03,100,1,13.71,115,2,12.73,100,1,14.01,100,1,12.71,100,1,14.07,2,1,12.5,700,1,14.28,100,1,12.46,200,2,14.4,100,1,12.43,700,1,14.5,100,1,12.42,700,1,14.56,800,2,12.37,700,1,14.6,700,1,ARL,308786185
,2025-07-17T15:49:14.463063539Z,2025-07-17T15:49:14.463063539Z,10,2,1108,C,A,2,13.71,15,130,165582,258702625,13.26,100,1,13.69,15,1,13.04,2,1,13.7,100,1,13.03,100,1,13.71,100,1,12.73,100,1,14.01,100,1,12.71,100,1,14.07,2,1,12.5,700,1,14.28,100,1,12.46,200,2,14.4,100,1,12.43,700,1,14.5,100,1,12.42,700,1,14.56,800,2,12.37,700,1,14.6,700,1,ARL,308763065
,2025-07-17T15:49:15.466199239Z,2025-07-17T15:49:15.466199239Z,10,2,1108,A,A,0,13.67,15,130,165883,258716863,13.26,100,1,13.67,15,1,13.04,2,1,13.69,15,1,13.03,100,1,13.7,100,1,12.73,100,1,13.71,100,1,12.71,100,1,14.01,100,1,12.5,700,1,14.07,2,1,12.46,200,2,14.28,100,1,12.43,700,1,14.4,100,1,12.42,700,1,14.5,100,1,12.37,700,1,14.56,800,2,ARL,308980305
,2025-07-17T15:49:16.350859152Z,2025-07-17T15:49:16.350859152Z,10,2,1108,C,A,2,13.7,100,0,165436,258727929,13.26,100,1,13.67,15,1,13.04,2,1,13.69,15,1,13.03,100,1,13.71,100,1,12.73,100,1,14.01,100,1,12.71,100,1,14.07,2,1,12.5,700,1,14.28,100,1,12.46,200,2,14.4,100,1,12.43,700,1,14.5,100,1,12.42,700,1,14.56,800,2,12.37,700,1,14.6,700,1,ARL,308901793
,2025-07-17T15:49:16.350859152Z,2025-07-17T15:49:16.350859152Z,10,2,1108,A,A,1,13.68,100,130,165436,258727929,13.26,100,1,13.67,15,1,13.04,2,1,13.68,100,1,13.03,100,1,13.69,15,1,12.73,100,1,13.71,100,1,12.71,100,1,14.01,100,1,12.5,700,1,14.07,2,1,12.46,200,2,14.28,100,1,12.43,700,1,14.4,100,1,12.42,700,1,14.5,100,1,12.37,700,1,14.56,800,2,ARL,308998225
,2025-07-17T15:49:16.493946243Z,2025-07-17T15:49:16.493946243Z,10,2,1108,A,A,2,13.69,100,130,165247,258729266,13.26,100,1,13.67,15,1,13.04,2,1,13.68,100,1,13.03,100,1,13.69,115,2,12.73,100,1,13.71,100,1,12.71,100,1,14.01,100,1,12.5,700,1,14.07,2,1,12.46,200,2,14.28,100,1,12.43,700,1,14.4,100,1,12.42,700,1,14.5,100,1,12.37,700,1,14.56,800,2,ARL,309001525
,2025-07-17T15:49:16.557759633Z,2025-07-17T15:49:16.557759633Z,10,2,1108,C,A,3,13.71,100,130,165230,258730034,13.26,100,1,13.67,15,1,13.04,2,1,13.68,100,1,13.03,100,1,13.69,115,2,12.73,100,1,14.01,100,1,12.71,100,1,14.07,2,1,12.5,700,1,14.28,100,1,12.46,200,2,14.4,100,1,12.43,700,1,14.5,100,1,12.42,700,1,14.56,800,2,12.37,700,1,14.6,700,1,ARL,308909249
,2025-07-17T15:49:21.185984774Z,2025-07-17T15:49:21.185984774Z,10,2,1108,C,A,4,14.07,2,0,165713,258786552,13.26,100,1,13.67,15,1,13.04,2,1,13.68,100,1,13.03,100,1,13.69,115,2,12.73,100,1,14.01,100,1,12.71,100,1,14.28,100,1,12.5,700,1,14.4,100,1,12.46,200,2,14.5,100,1,12.43,700,1,14.56,800,2,12.42,700,1,14.6,700,1,12.37,700,1,14.64,100,1,ARL,296478973
,2025-07-17T15:49:21.185984774Z,2025-07-17T15:49:21.185984774Z,10,2,1108,A,A,3,13.98,2,130,165713,258786552,13.26,100,1,13.67,15,1,13.04,2,1,13.68,100,1,13.03,100,1,13.69,115,2,12.73,100,1,13.98,2,1,12.71,100,1,14.01,100,1,12.5,700,1,14.28,100,1,12.46,200,2,14.4,100,1,12.43,700,1,14.5,100,1,12.42,700,1,14.56,800,2,12.37,700,1,14.6,700,1,ARL,309091513
,2025-07-17T15:49:24.282985894Z,2025-07-17T15:49:24.282985894Z,10,2,1108,C,A,2,13.69,15,130,166218,258838460,13.26,100,1,13.67,15,1,13.04,2,1,13.68,100,1,13.03,100,1,13.69,100,1,12.73,100,1,13.98,2,1,12.71,100,1,14.01,100,1,12.5,700,1,14.28,100,1,12.46,200,2,14.4,100,1,12.43,700,1,14.5,100,1,12.42,700,1,14.56,800,2,12.37,700,1,14.6,700,1,ARL,308893737
,2025-07-17T15:49:34.570031718Z,2025-07-17T15:49:34.570031718Z,10,2,1108,C,A,0,13.67,15,130,165416,258980876,13.26,100,1,13.68,100,1,13.04,2,1,13.69,100,1,13.03,100,1,13.98,2,1,12.73,100,1,14.01,100,1,12.71,100,1,14.28,100,1,12.5,700,1,14.4,100,1,12.46,200,2,14.5,100,1,12.43,700,1,14.56,800,2,12.42,700,1,14.6,700,1,12.37,700,1,14.64,100,1,ARL,308980305
,2025-07-17T15:49:34.591347169Z,2025-07-17T15:49:34.591347169Z,10,2,1108,C,A,1,13.69,100,130,165746,258983321,13.26,100,1,13.68,100,1,13.04,2,1,13.98,2,1,13.03,100,1,14.01,100,1,12.73,100,1,14.28,100,1,12.71,100,1,14.4,100,1,12.5,700,1,14.5,100,1,12.46,200,2,14.56,800,2,12.43,700,1,14.6,700,1,12.42,700,1,14.64,100,1,12.37,700,1,14.65,100,1,ARL,309001525
,2025-07-17T15:49:38.609851985Z,2025-07-17T15:49:38.609851985Z,10,2,1108,A,A,1,13.72,100,130,165409,259031220,13.26,100,1,13.68,100,1,13.04,2,1,13.72,100,1,13.03,100,1,13.98,2,1,12.73,100,1,14.01,100,1,12.71,100,1,14.28,100,1,12.5,700,1,14.4,100,1,12.46,200,2,14.5,100,1,12.43,700,1,14.56,800,2,12.42,700,1,14.6,700,1,12.37,700,1,14.64,100,1,ARL,309410565
,2025-07-17T15:49:38.609907720Z,2025-07-17T15:49:38.609907720Z,10,2,1108,C,B,0,13.26,100,130,165614,259031221,13.04,2,1,13.68,100,1,13.03,100,1,13.72,100,1,12.73,100,1,13.98,2,1,12.71,100,1,14.01,100,1,12.5,700,1,14.28,100,1,12.46,200,2,14.4,100,1,12.43,700,1,14.5,100,1,12.42,700,1,14.56,800,2,12.37,700,1,14.6,700,1,12.36,200,2,14.64,100,1,ARL,291975017
,2025-07-17T15:49:39.068349660Z,2025-07-17T15:49:39.068349660Z,10,2,1108,A,B,2,13.02,100,130,165345,259035032,13.04,2,1,13.68,100,1,13.03,100,1,13.72,100,1,13.02,100,1,13.98,2,1,12.73,100,1,14.01,100,1,12.71,100,1,14.28,100,1,12.5,700,1,14.4,100,1,12.46,200,2,14.5,100,1,12.43,700,1,14.56,800,2,12.42,700,1,14.6,700,1,12.37,700,1,14.64,100,1,ARL,309415429
,2025-07-17T15:49:44.788249210Z,2025-07-17T15:49:44.788249210Z,10,2,1108,A,A,0,13.67,15,130,165191,259105347,13.04,2,1,13.67,15,1,13.03,100,1,13.68,100,1,13.02,100,1,13.72,100,1,12.73,100,1,13.98,2,1,12.71,100,1,14.01,100,1,12.5,700,1,14.28,100,1,12.46,200,2,14.4,100,1,12.43,700,1,14.5,100,1,12.42,700,1,14.56,800,2,12.37,700,1,14.6,700,1,ARL,309524921
,2025-07-17T15:49:44.788855587Z,2025-07-17T15:49:44.788855587Z,10,2,1108,A,A,2,13.7,100,130,165170,259105361,13.04,2,1,13.67,15,1,13.03,100,1,13.68,100,1,13.02,100,1,13.7,100,1,12.73,100,1,13.72,100,1,12.71,100,1,13.98,2,1,12.5,700,1,14.01,100,1,12.46,200,2,14.28,100,1,12.43,700,1,14.4,100,1,12.42,700,1,14.5,100,1,12.37,700,1,14.56,800,2,ARL,309524933
,2025-07-17T15:49:44.789537536Z,2025-07-17T15:49:44.789537536Z,10,2,1108,C,A,3,13.72,100,130,165380,259105380,13.04,2,1,13.67,15,1,13.03,100,1,13.68,100,1,13.02,100,1,13.7,100,1,12.73,100,1,13.98,2,1,12.71,100,1,14.01,100,1,12.5,700,1,14.28,100,1,12.46,200,2,14.4,100,1,12.43,700,1,14.5,100,1,12.42,700,1,14.56,800,2,12.37,700,1,14.6,700,1,ARL,309410565
,2025-07-17T15:49:54.788493605Z,2025-07-17T15:49:54.788493605Z,10,2,1108,A,A,0,13.65,15,130,165236,259253294,13.04,2,1,13.65,15,1,13.03,100,1,13.67,15,1,13.02,100,1,13.68,100,1,12.73,100,1,13.7,100,1,12.71,100,1,13.98,2,1,12.5,700,1,14.01,100,1,12.46,200,2,14.28,100,1,12.43,700,1,14.4,100,1,12.42,700,1,14.5,100,1,12.37,700,1,14.56,800,2,ARL,309707269
,2025-07-17T15:49:54.799370442Z,2025-07-17T15:49:54.799370442Z,10,2,1108,A,A,2,13.68,100,130,165302,259253527,13.04,2,1,13.65,15,1,13.03,100,1,13.67,15,1,13.02,100,1,13.68,200,2,12.73,100,1,13.7,100,1,12.71,100,1,13.98,2,1,12.5,700,1,14.01,100,1,12.46,200,2,14.28,100,1,12.43,700,1,14.4,100,1,12.42,700,1,14.5,100,1,12.37,700,1,14.56,800,2,ARL,309707413
,2025-07-17T15:49:54.820469390Z,2025-07-17T15:49:54.820469390Z,10,2,1108,C,A,3,13.7,100,130,165527,259253732,13.04,2,1,13.65,15,1,13.03,100,1,13.67,15,1,13.02,100,1,13.68,200,2,12.73,100,1,13.98,2,1,12.71,100,1,14.01,100,1,12.5,700,1,14.28,100,1,12.46,200,2,14.4,100,1,12.43,700,1,14.5,100,1,12.42,700,1,14.56,800,2,12.37,700,1,14.6,700,1,ARL,309524933
,2025-07-17T15:49:59.511938438Z,2025-07-17T15:49:59.511938438Z,10,2,1108,C,A,2,13.68,100,0,165626,259313537,13.04,2,1,13.65,15,1,13.03,100,1,13.67,15,1,13.02,100,1,13.68,100,1,12.73,100,1,13.98,2,1,12.71,100,1,14.01,100,1,12.5,700,1,14.28,100,1,12.46,200,2,14.4,100,1,12.43,700,1,14.5,100,1,12.42,700,1,14.56,800,2,12.37,700,1,14.6,700,1,ARL,308998225
,2025-07-17T15:49:59.511938438Z,2025-07-17T15:49:59.511938438Z,10,2,1108,A,A,1,13.66,100,130,165626,259313537,13.04,2,1,13.65,15,1,13.03,100,1,13.66,100,1,13.02,100,1,13.67,15,1,12.73,100,1,13.68,100,1,12.71,100,1,13.98,2,1,12.5,700,1,14.01,100,1,12.46,200,2,14.28,100,1,12.43,700,1,14.4,100,1,12.42,700,1,14.5,100,1,12.37,700,1,14.56,800,2,ARL,309782481
,2025-07-17T15:49:59.533897369Z,2025-07-17T15:49:59.533897369Z,10,2,1108,C,A,5,14.01,100,130,165265,259314032,13.04,2,1,13.65,15,1,13.03,100,1,13.66,100,1,13.02,100,1,13.67,15,1,12.73,100,1,13.68,100,1,12.71,100,1,13.98,2,1,12.5,700,1,14.28,100,1,12.46,200,2,14.4,100,1,12.43,700,1,14.5,100,1,12.42,700,1,14.56,800,2,12.37,700,1,14.6,700,1,ARL,308375185
,2025-07-17T15:49:59.533948952Z,2025-07-17T15:49:59.533948952Z,10,2,1108,A,A,4,13.93,100,130,166323,259314033,13.04,2,1,13.65,15,1,13.03,100,1,13.66,100,1,13.02,100,1,13.67,15,1,12.73,100,1,13.68,100,1,12.71,100,1,13.93,100,1,12.5,700,1,13.98,2,1,12.46,200,2,14.28,100,1,12.43,700,1,14.4,100,1,12.42,700,1,14.5,100,1,12.37,700,1,14.56,800,2,ARL,309782973
,2025-07-17T15:50:00.547239401Z,2025-07-17T15:50:00.547239401Z,10,2,1108,C,A,2,13.67,15,130,165571,259349868,13.04,2,1,13.65,15,1,13.03,100,1,13.66,100,1,13.02,100,1,13.68,100,1,12.73,100,1,13.93,100,1,12.71,100,1,13.98,2,1,12.5,700,1,14.28,100,1,12.46,200,2,14.4,100,1,12.43,700,1,14.5,100,1,12.42,700,1,14.56,800,2,12.37,700,1,14.6,700,1,ARL,309524921
,2025-07-17T15:50:00.555363249Z,2025-07-17T15:50:00.555363249Z,10,2,1108,A,A,8,14.54,100,128,173439,259353226,13.04,2,1,13.65,15,1,13.03,100,1,13.66,100,1,13.02,100,1,13.68,100,1,12.73,100,1,13.93,100,1,12.71,100,1,13.98,2,1,12.5,700,1,14.28,100,1,12.46,200,2,14.4,100,1,12.43,700,1,14.5,100,1,12.42,700,1,14.54,100,1,12.37,700,1,14.56,800,2,ARL,309823025
,2025-07-17T15:50:03.412257475Z,2025-07-17T15:50:03.412257475Z,10,2,1108,A,A,0,13.63,15,130,165405,259413272,13.04,2,1,13.63,15,1,13.03,100,1,13.65,15,1,13.02,100,1,13.66,100,1,12.73,100,1,13.68,100,1,12.71,100,1,13.93,100,1,12.5,700,1,13.98,2,1,12.46,200,2,14.28,100,1,12.43,700,1,14.4,100,1,12.42,700,1,14.5,100,1,12.37,700,1,14.54,100,1,ARL,309899025
,2025-07-17T15:50:03.415361851Z,2025-07-17T15:50:03.415361851Z,10,2,1108,A,A,9,14.53,100,130,165521,259413427,13.04,2,1,13.63,15,1,13.03,100,1,13.65,15,1,13.02,100,1,13.66,100,1,12.73,100,1,13.68,100,1,12.71,100,1,13.93,100,1,12.5,700,1,13.98,2,1,12.46,200,2,14.28,100,1,12.43,700,1,14.4,100,1,12.42,700,1,14.5,100,1,12.37,700,1,14.53,100,1,ARL,309899141
,2025-07-17T15:50:03.824126753Z,2025-07-17T15:50:03.824126753Z,10,2,1108,C,A,2,13.66,100,0,165399,259418661,13.04,2,1,13.63,15,1,13.03,100,1,13.65,15,1,13.02,100,1,13.68,100,1,12.73,100,1,13.93,100,1,12.71,100,1,13.98,2,1,12.5,700,1,14.28,100,1,12.46,200,2,14.4,100,1,12.43,700,1,14.5,100,1,12.42,700,1,14.53,100,1,12.37,700,1,14.54,100,1,ARL,309782481
,2025-07-17T15:50:03.824126753Z,2025-07-17T15:50:03.824126753Z,10,2,1108,A,A,1,13.64,100,130,165399,259418661,13.04,2,1,13.63,15,1,13.03,100,1,13.64,100,1,13.02,100,1,13.65,15,1,12.73,100,1,13.68,100,1,12.71,100,1,13.93,100,1,12.5,700,1,13.98,2,1,12.46,200,2,14.28,100,1,12.43,700,1,14.4,100,1,12.42,700,1,14.5,100,1,12.37,700,1,14.53,100,1,ARL,309903973
,2025-07-17T15:50:04.484733438Z,2025-07-17T15:50:04.484733438Z,10,2,1108,A,A,3,13.66,100,130,165321,259433904,13.04,2,1,13.63,15,1,13.03,100,1,13.64,100,1,13.02,100,1,13.65,15,1,12.73,100,1,13.66,100,1,12.71,100,1,13.68,100,1,12.5,700,1,13.93,100,1,12.46,200,2,13.98,2,1,12.43,700,1,14.28,100,1,12.42,700,1,14.4,100,1,12.37,700,1,14.5,100,1,ARL,309922345
,2025-07-17T15:50:04.524563568Z,2025-07-17T15:50:04.524563568Z,10,2,1108,C,A,4,13.68,100,130,165471,259434652,13.04,2,1,13.63,15,1,13.03,100,1,13.64,100,1,13.02,100,1,13.65,15,1,12.73,100,1,13.66,100,1,12.71,100,1,13.93,100,1,12.5,700,1,13.98,2,1,12.46,200,2,14.28,100,1,12.43,700,1,14.4,100,1,12.42,700,1,14.5,100,1,12.37,700,1,14.53,100,1,ARL,309707413
,2025-07-17T15:50:06.787661846Z,2025-07-17T15:50:06.787661846Z,10,2,1108,C,A,0,13.63,15,130,165129,259472951,13.04,2,1,13.64,100,1,13.03,100,1,13.65,15,1,13.02,100,1,13.66,100,1,12.73,100,1,13.93,100,1,12.71,100,1,13.98,2,1,12.5,700,1,14.28,100,1,12.46,200,2,14.4,100,1,12.43,700,1,14.5,100,1,12.42,700,1,14.53,100,1,12.37,700,1,14.54,100,1,ARL,309899025
,2025-07-17T15:50:09.185334126Z,2025-07-17T15:50:09.185334126Z,10,2,1108,A,A,0,13.61,15,130,165241,259516855,13.04,2,1,13.61,15,1,13.03,100,1,13.64,100,1,13.02,100,1,13.65,15,1,12.73,100,1,13.66,100,1,12.71,100,1,13.93,100,1,12.5,700,1,13.98,2,1,12.46,200,2,14.28,100,1,12.43,700,1,14.4,100,1,12.42,700,1,14.5,100,1,12.37,700,1,14.53,100,1,ARL,310030465
,2025-07-17T15:50:09.198311198Z,2025-07-17T15:50:09.198311198Z,10,2,1108,A,A,1,13.64,100,130,165239,259517754,13.04,2,1,13.61,15,1,13.03,100,1,13.64,200,2,13.02,100,1,13.65,15,1,12.73,100,1,13.66,100,1,12.71,100,1,13.93,100,1,12.5,700,1,13.98,2,1,12.46,200,2,14.28,100,1,12.43,700,1,14.4,100,1,12.42,700,1,14.5,100,1,12.37,700,1,14.53,100,1,ARL,310031625
,2025-07-17T15:50:09.205322092Z,2025-07-17T15:50:09.205322092Z,10,2,1108,C,A,3,13.66,100,130,165324,259517973,13.04,2,1,13.61,15,1,13.03,100,1,13.64,200,2,13.02,100,1,13.65,15,1,12.73,100,1,13.93,100,1,12.71,100,1,13.98,2,1,12.5,700,1,14.28,100,1,12.46,200,2,14.4,100,1,12.43,700,1,14.5,100,1,12.42,700,1,14.53,100,1,12.37,700,1,14.54,100,1,ARL,309922345
,2025-07-17T15:50:09.330572653Z,2025-07-17T15:50:09.330572653Z,10,2,1108,C,A,1,13.64,100,0,165500,259522708,13.04,2,1,13.61,15,1,13.03,100,1,13.64,100,1,13.02,100,1,13.65,15,1,12.73,100,1,13.93,100,1,12.71,100,1,13.98,2,1,12.5,700,1,14.28,100,1,12.46,200,2,14.4,100,1,12.43,700,1,14.5,100,1,12.42,700,1,14.53,100,1,12.37,700,1,14.54,100,1,ARL,309903973
,2025-07-17T15:50:09.330572653Z,2025-07-17T15:50:09.330572653Z,10,2,1108,A,A,1,13.62,100,130,165500,259522708,13.04,2,1,13.61,15,1,13.03,100,1,13.62,100,1,13.02,100,1,13.64,100,1,12.73,100,1,13.65,15,1,12.71,100,1,13.93,100,1,12.5,700,1,13.98,2,1,12.46,200,2,14.28,100,1,12.43,700,1,14.4,100,1,12.42,700,1,14.5,100,1,12.37,700,1,14.53,100,1,ARL,310037965
,2025-07-17T15:50:20.204373858Z,2025-07-17T15:50:20.204373858Z,10,2,1108,C,A,3,13.65,15,130,165327,259737768,13.04,2,1,13.61,15,1,13.03,100,1,13.62,100,1,13.02,100,1,13.64,100,1,12.73,100,1,13.93,100,1,12.71,100,1,13.98,2,1,12.5,700,1,14.28,100,1,12.46,200,2,14.4,100,1,12.43,700,1,14.5,100,1,12.42,700,1,14.53,100,1,12.37,700,1,14.54,100,1,ARL,309707269
,2025-07-17T15:50:25.935412900Z,2025-07-17T15:50:25.935412900Z,10,2,1108,A,A,0,13.59,15,128,166134,259828644,13.04,2,1,13.59,15,1,13.03,100,1,13.61,15,1,13.02,100,1,13.62,100,1,12.73,100,1,13.64,100,1,12.71,100,1,13.93,100,1,12.5,700,1,13.98,2,1,12.46,200,2,14.28,100,1,12.43,700,1,14.4,100,1,12.42,700,1,14.5,100,1,12.37,700,1,14.53,100,1,ARL,310424077
,2025-07-17T15:50:26.954662143Z,2025-07-17T15:50:26.954662143Z,10,2,1108,C,A,2,13.62,100,0,166007,259847181,13.04,2,1,13.59,15,1,13.03,100,1,13.61,15,1,13.02,100,1,13.64,100,1,12.73,100,1,13.93,100,1,12.71,100,1,13.98,2,1,12.5,700,1,14.28,100,1,12.46,200,2,14.4,100,1,12.43,700,1,14.5,100,1,12.42,700,1,14.53,100,1,12.37,700,1,14.54,100,1,ARL,310037965
,2025-07-17T15:50:26.954662143Z,2025-07-17T15:50:26.954662143Z,10,2,1108,A,A,1,13.6,100,130,166007,259847181,13.04,2,1,13.59,15,1,13.03,100,1,13.6,100,1,13.02,100,1,13.61,15,1,12.73,100,1,13.64,100,1,12.71,100,1,13.93,100,1,12.5,700,1,13.98,2,1,12.46,200,2,14.28,100,1,12.43,700,1,14.4,100,1,12.42,700,1,14.5,100,1,12.37,700,1,14.53,100,1,ARL,310446249
,2025-07-17T15:50:30.046714265Z,2025-07-17T15:50:30.046714265Z,10,2,1108,C,A,0,13.59,15,130,165304,259916670,13.04,2,1,13.6,100,1,13.03,100,1,13.61,15,1,13.02,100,1,13.64,100,1,12.73,100,1,13.93,100,1,12.71,100,1,13.98,2,1,12.5,700,1,14.28,100,1,12.46,200,2,14.4,100,1,12.43,700,1,14.5,100,1,12.42,700,1,14.53,100,1,12.37,700,1,14.54,100,1,ARL,310424077
,2025-07-17T15:50:30.046849726Z,2025-07-17T15:50:30.046849726Z,10,2,1108,C,A,1,13.61,15,130,165388,259916674,13.04,2,1,13.6,100,1,13.03,100,1,13.64,100,1,13.02,100,1,13.93,100,1,12.73,100,1,13.98,2,1,12.71,100,1,14.28,100,1,12.5,700,1,14.4,100,1,12.46,200,2,14.5,100,1,12.43,700,1,14.53,100,1,12.42,700,1,14.54,100,1,12.37,700,1,14.56,800,2,ARL,310030465
,2025-07-17T15:51:37.985992174Z,2025-07-17T15:51:37.985992174Z,10,2,1108,C,A,3,13.98,2,0,166156,261130345,13.04,2,1,13.6,100,1,13.03,100,1,13.64,100,1,13.02,100,1,13.93,100,1,12.73,100,1,14.28,100,1,12.71,100,1,14.4,100,1,12.5,700,1,14.5,100,1,12.46,200,2,14.53,100,1,12.43,700,1,14.54,100,1,12.42,700,1,14.56,800,2,12.37,700,1,14.6,700,1,ARL,309091513
,2025-07-17T15:51:37.985992174Z,2025-07-17T15:51:37.985992174Z,10,2,1108,A,A,2,13.89,2,130,166156,261130345,13.04,2,1,13.6,100,1,13.03,100,1,13.64,100,1,13.02,100,1,13.89,2,1,12.73,100,1,13.93,100,1,12.71,100,1,14.28,100,1,12.5,700,1,14.4,100,1,12.46,200,2,14.5,100,1,12.43,700,1,14.53,100,1,12.42,700,1,14.54,100,1,12.37,700,1,14.56,800,2,ARL,311979125
,2025-07-17T15:52:16.371351021Z,2025-07-17T15:52:16.371351021Z,10,2,1108,T,N,0,13.41,58,0,166818,261713745,13.04,2,1,13.6,100,1,13.03,100,1,13.64,100,1,13.02,100,1,13.89,2,1,12.73,100,1,13.93,100,1,12.71,100,1,14.28,100,1,12.5,700,1,14.4,100,1,12.46,200,2,14.5,100,1,12.43,700,1,14.53,100,1,12.42,700,1,14.54,100,1,12.37,700,1,14.56,800,2,ARL,0
,2025-07-17T15:52:16.371351021Z,2025-07-17T15:52:16.371351021Z,10,2,1108,T,N,0,13.28,12,130,166818,261713746,13.04,2,1,13.6,100,1,13.03,100,1,13.64,100,1,13.02,100,1,13.89,2,1,12.73,100,1,13.93,100,1,12.71,100,1,14.28,100,1,12.5,700,1,14.4,100,1,12.46,200,2,14.5,100,1,12.43,700,1,14.53,100,1,12.42,700,1,14.54,100,1,12.37,700,1,14.56,800,2,ARL,0
,2025-07-17T15:52:16.372269170Z,2025-07-17T15:52:16.372269170Z,10,2,1108,C,A,0,13.6,100,130,165455,261713790,13.04,2,1,13.64,100,1,13.03,100,1,13.89,2,1,13.02,100,1,13.93,100,1,12.73,100,1,14.28,100,1,12.71,100,1,14.4,100,1,12.5,700,1,14.5,100,1,12.46,200,2,14.53,100,1,12.43,700,1,14.54,100,1,12.42,700,1,14.56,800,2,12.37,700,1,14.6,700,1,ARL,310446249
,2025-07-17T15:52:16.373023186Z,2025-07-17T15:52:16.373023186Z,10,2,1108,C,A,10,14.65,100,0,165605,261713830,13.04,2,1,13.64,100,1,13.03,100,1,13.89,2,1,13.02,100,1,13.93,100,1,12.73,100,1,14.28,100,1,12.71,100,1,14.4,100,1,12.5,700,1,14.5,100,1,12.46,200,2,14.53,100,1,12.43,700,1,14.54,100,1,12.42,700,1,14.56,800,2,12.37,700,1,14.6,700,1,ARL,310446269
,2025-07-17T15:52:16.374186508Z,2025-07-17T15:52:16.374186508Z,10,2,1108,C,A,0,13.64,100,130,166651,261713870,13.04,2,1,13.89,2,1,13.03,100,1,13.93,100,1,13.02,100,1,14.28,100,1,12.73,100,1,14.4,100,1,12.71,100,1,14.5,100,1,12.5,700,1,14.53,100,1,12.46,200,2,14.54,100,1,12.43,700,1,14.56,800,2,12.42,700,1,14.6,700,1,12.37,700,1,14.66,200,2,ARL,310031625
,2025-07-17T15:52:16.375222836Z,2025-07-17T15:52:16.375222836Z,10,2,1108,C,A,6,14.54,100,0,165449,261713944,13.04,2,1,13.89,2,1,13.03,100,1,13.93,100,1,13.02,100,1,14.28,100,1,12.73,100,1,14.4,100,1,12.71,100,1,14.5,100,1,12.5,700,1,14.53,100,1,12.46,200,2,14.56,800,2,12.43,700,1,14.6,700,1,12.42,700,1,14.66,200,2,12.37,700,1,14.68,1400,2,ARL,309823025
,2025-07-17T15:52:16.375248654Z,2025-07-17T15:52:16.375248654Z,10,2,1108,C,A,8,14.66,100,0,165593,261713945,13.04,2,1,13.89,2,1,13.03,100,1,13.93,100,1,13.02,100,1,14.28,100,1,12.73,100,1,14.4,100,1,12.71,100,1,14.5,100,1,12.5,700,1,14.53,100,1,12.46,200,2,14.56,800,2,12.43,700,1,14.6,700,1,12.42,700,1,14.66,100,1,12.37,700,1,14.68,1400,2,ARL,308901981
,2025-07-17T15:52:16.375662552Z,2025-07-17T15:52:16.375662552Z,10,2,1108,C,A,5,14.53,100,0,165602,261713959,13.04,2,1,13.89,2,1,13.03,100,1,13.93,100,1,13.02,100,1,14.28,100,1,12.73,100,1,14.4,100,1,12.71,100,1,14.5,100,1,12.5,700,1,14.56,800,2,12.46,200,2,14.6,700,1,12.43,700,1,14.66,100,1,12.42,700,1,14.68,1400,2,12.37,700,1,14.7,100,1,ARL,309899141
,2025-07-17T15:52:16.375662552Z,2025-07-17T15:52:16.375662552Z,10,2,1108,A,A,10,14.76,100,130,165602,261713959,13.04,2,1,13.89,2,1,13.03,100,1,13.93,100,1,13.02,100,1,14.28,100,1,12.73,100,1,14.4,100,1,12.71,100,1,14.5,100,1,12.5,700,1,14.56,800,2,12.46,200,2,14.6,700,1,12.43,700,1,14.66,100,1,12.42,700,1,14.68,1400,2,12.37,700,1,14.7,100,1,ARL,312771829
,2025-07-17T15:52:16.378220434Z,2025-07-17T15:52:16.378220434Z,10,2,1108,C,A,4,14.5,100,0,165509,261714145,13.04,2,1,13.89,2,1,13.03,100,1,13.93,100,1,13.02,100,1,14.28,100,1,12.73,100,1,14.4,100,1,12.71,100,1,14.56,800,2,12.5,700,1,14.6,700,1,12.46,200,2,14.66,100,1,12.43,700,1,14.68,1400,2,12.42,700,1,14.7,100,1,12.37,700,1,14.76,100,1,ARL,308903349
,2025-07-17T15:52:16.378220434Z,2025-07-17T15:52:16.378220434Z,10,2,1108,A,A,9,14.72,100,130,165509,261714145,13.04,2,1,13.89,2,1,13.03,100,1,13.93,100,1,13.02,100,1,14.28,100,1,12.73,100,1,14.4,100,1,12.71,100,1,14.56,800,2,12.5,700,1,14.6,700,1,12.46,200,2,14.66,100,1,12.43,700,1,14.68,1400,2,12.42,700,1,14.7,100,1,12.37,700,1,14.72,100,1,ARL,312772061
,2025-07-17T15:52:16.378705201Z,2025-07-17T15:52:16.378705201Z,10,2,1108,A,B,0,13.27,10,130,165437,261714171,13.27,10,1,13.89,2,1,13.04,2,1,13.93,100,1,13.03,100,1,14.28,100,1,13.02,100,1,14.4,100,1,12.73,100,1,14.56,800,2,12.71,100,1,14.6,700,1,12.5,700,1,14.66,100,1,12.46,200,2,14.68,1400,2,12.43,700,1,14.7,100,1,12.42,700,1,14.72,100,1,ARL,312772069
,2025-07-17T15:52:16.378707041Z,2025-07-17T15:52:16.378707041Z,10,2,1108,A,A,0,13.86,15,130,165344,261714172,13.27,10,1,13.86,15,1,13.04,2,1,13.89,2,1,13.03,100,1,13.93,100,1,13.02,100,1,14.28,100,1,12.73,100,1,14.4,100,1,12.71,100,1,14.56,800,2,12.5,700,1,14.6,700,1,12.46,200,2,14.66,100,1,12.43,700,1,14.68,1400,2,12.42,700,1,14.7,100,1,ARL,312772073
,2025-07-17T15:52:16.378962330Z,2025-07-17T15:52:16.378962330Z,10,2,1108,C,B,3,13.02,100,0,165452,261714185,13.27,10,1,13.86,15,1,13.04,2,1,13.89,2,1,13.03,100,1,13.93,100,1,12.73,100,1,14.28,100,1,12.71,100,1,14.4,100,1,12.5,700,1,14.56,800,2,12.46,200,2,14.6,700,1,12.43,700,1,14.66,100,1,12.42,700,1,14.68,1400,2,12.37,700,1,14.7,100,1,ARL,309415429
,2025-07-17T15:52:16.378962330Z,2025-07-17T15:52:16.378962330Z,10,2,1108,A,B,1,13.26,100,130,165452,261714185,13.27,10,1,13.86,15,1,13.26,100,1,13.89,2,1,13.04,2,1,13.93,100,1,13.03,100,1,14.28,100,1,12.73,100,1,14.4,100,1,12.71,100,1,14.56,800,2,12.5,700,1,14.6,700,1,12.46,200,2,14.66,100,1,12.43,700,1,14.68,1400,2,12.42,700,1,14.7,100,1,ARL,312772077
,2025-07-17T15:52:16.388859982Z,2025-07-17T15:52:16.388859982Z,10,2,1108,C,A,2,13.93,100,130,165487,261714477,13.27,10,1,13.86,15,1,13.26,100,1,13.89,2,1,13.04,2,1,14.28,100,1,13.03,100,1,14.4,100,1,12.73,100,1,14.56,800,2,12.71,100,1,14.6,700,1,12.5,700,1,14.66,100,1,12.46,200,2,14.68,1400,2,12.43,700,1,14.7,100,1,12.42,700,1,14.72,100,1,ARL,309782973
,2025-07-17T15:52:16.388917108Z,2025-07-17T15:52:16.388917108Z,10,2,1108,A,A,2,14.19,100,130,165343,261714481,13.27,10,1,13.86,15,1,13.26,100,1,13.89,2,1,13.04,2,1,14.19,100,1,13.03,100,1,14.28,100,1,12.73,100,1,14.4,100,1,12.71,100,1,14.56,800,2,12.5,700,1,14.6,700,1,12.46,200,2,14.66,100,1,12.43,700,1,14.68,1400,2,12.42,700,1,14.7,100,1,ARL,312772501
,2025-07-17T15:52:16.396008715Z,2025-07-17T15:52:16.396008715Z,10,2,1108,C,A,7,14.66,100,0,165787,261714603,13.27,10,1,13.86,15,1,13.26,100,1,13.89,2,1,13.04,2,1,14.19,100,1,13.03,100,1,14.28,100,1,12.73,100,1,14.4,100,1,12.71,100,1,14.56,800,2,12.5,700,1,14.6,700,1,12.46,200,2,14.68,1400,2,12.43,700,1,14.7,100,1,12.42,700,1,14.72,100,1,ARL,308903001
,2025-07-17T15:52:16.397512710Z,2025-07-17T15:52:16.397512710Z,10,2,1108,C,A,2,14.19,100,130,164971,261714619,13.27,10,1,13.86,15,1,13.26,100,1,13.89,2,1,13.04,2,1,14.28,100,1,13.03,100,1,14.4,100,1,12.73,100,1,14.56,800,2,12.71,100,1,14.6,700,1,12.5,700,1,14.68,1400,2,12.46,200,2,14.7,100,1,12.43,700,1,14.72,100,1,12.42,700,1,14.76,100,1,ARL,312772501
,2025-07-17T15:52:16.397561691Z,2025-07-17T15:52:16.397561691Z,10,2,1108,A,A,2,14.26,100,130,165351,261714620,13.27,10,1,13.86,15,1,13.26,100,1,13.89,2,1,13.04,2,1,14.26,100,1,13.03,100,1,14.28,100,1,12.73,100,1,14.4,100,1,12.71,100,1,14.56,800,2,12.5,700,1,14.6,700,1,12.46,200,2,14.68,1400,2,12.43,700,1,14.7,100,1,12.42,700,1,14.72,100,1,ARL,312772901
,2025-07-17T15:52:16.423972000Z,2025-07-17T15:52:16.423972000Z,10,2,1108,C,A,8,14.7,100,0,165423,261714976,13.27,10,1,13.86,15,1,13.26,100,1,13.89,2,1,13.04,2,1,14.26,100,1,13.03,100,1,14.28,100,1,12.73,100,1,14.4,100,1,12.71,100,1,14.56,800,2,12.5,700,1,14.6,700,1,12.46,200,2,14.68,1400,2,12.43,700,1,14.72,100,1,12.42,700,1,14.76,100,1,ARL,312771573
,2025-07-17T15:52:16.464616142Z,2025-07-17T15:52:16.464616142Z,10,2,1108,A,A,1,13.87,100,130,165201,261715303,13.27,10,1,13.86,15,1,13.26,100,1,13.87,100,1,13.04,2,1,13.89,2,1,13.03,100,1,14.26,100,1,12.73,100,1,14.28,100,1,12.71,100,1,14.4,100,1,12.5,700,1,14.56,800,2,12.46,200,2,14.6,700,1,12.43,700,1,14.68,1400,2,12.42,700,1,14.72,100,1,ARL,312773881
,2025-07-17T15:52:16.479925781Z,2025-07-17T15:52:16.479925781Z,10,2,1108,C,A,3,14.26,100,130,165113,261715467,13.27,10,1,13.86,15,1,13.26,100,1,13.87,100,1,13.04,2,1,13.89,2,1,13.03,100,1,14.28,100,1,12.73,100,1,14.4,100,1,12.71,100,1,14.56,800,2,12.5,700,1,14.6,700,1,12.46,200,2,14.68,1400,2,12.43,700,1,14.72,100,1,12.42,700,1,14.76,100,1,ARL,312772901
,2025-07-17T15:52:16.479974840Z,2025-07-17T15:52:16.479974840Z,10,2,1108,A,A,3,14.15,100,130,165291,261715468,13.27,10,1,13.86,15,1,13.26,100,1,13.87,100,1,13.04,2,1,13.89,2,1,13.03,100,1,14.15,100,1,12.73,100,1,14.28,100,1,12.71,100,1,14.4,100,1,12.5,700,1,14.56,800,2,12.46,200,2,14.6,700,1,12.43,700,1,14.68,1400,2,12.42,700,1,14.72,100,1,ARL,312774033
,2025-07-17T15:52:28.787151494Z,2025-07-17T15:52:28.787151494Z,10,2,1108,C,B,0,13.27,10,130,165371,261883294,13.26,100,1,13.86,15,1,13.04,2,1,13.87,100,1,13.03,100,1,13.89,2,1,12.73,100,1,14.15,100,1,12.71,100,1,14.28,100,1,12.5,700,1,14.4,100,1,12.46,200,2,14.56,800,2,12.43,700,1,14.6,700,1,12.42,700,1,14.68,1400,2,12.37,700,1,14.72,100,1,ARL,312772069
,2025-07-17T15:52:28.787152437Z,2025-07-17T15:52:28.787152437Z,10,2,1108,C,A,0,13.86,15,130,165390,261883295,13.26,100,1,13.87,100,1,13.04,2,1,13.89,2,1,13.03,100,1,14.15,100,1,12.73,100,1,14.28,100,1,12.71,100,1,14.4,100,1,12.5,700,1,14.56,800,2,12.46,200,2,14.6,700,1,12.43,700,1,14.68,1400,2,12.42,700,1,14.72,100,1,12.37,700,1,14.76,100,1,ARL,312772073
,2025-07-17T15:52:43.128203357Z,2025-07-17T15:52:43.128203357Z,10,2,1108,C,A,1,13.89,2,0,167676,262115170,13.26,100,1,13.87,100,1,13.04,2,1,14.15,100,1,13.03,100,1,14.28,100,1,12.73,100,1,14.4,100,1,12.71,100,1,14.56,800,2,12.5,700,1,14.6,700,1,12.46,200,2,14.68,1400,2,12.43,700,1,14.72,100,1,12.42,700,1,14.76,100,1,12.37,700,1,14.81,100,1,ARL,311979125
,2025-07-17T15:52:43.128203357Z,2025-07-17T15:52:43.128203357Z,10,2,1108,A,A,1,13.99,2,128,167676,262115170,13.26,100,1,13.87,100,1,13.04,2,1,13.99,2,1,13.03,100,1,14.15,100,1,12.73,100,1,14.28,100,1,12.71,100,1,14.4,100,1,12.5,700,1,14.56,800,2,12.46,200,2,14.6,700,1,12.43,700,1,14.68,1400,2,12.42,700,1,14.72,100,1,12.37,700,1,14.76,100,1,ARL,313336713
,2025-07-17T15:54:24.908318259Z,2025-07-17T15:54:24.908318259Z,10,2,1108,A,B,0,13.29,10,130,165523,263863872,13.29,10,1,13.87,100,1,13.26,100,1,13.99,2,1,13.04,2,1,14.15,100,1,13.03,100,1,14.28,100,1,12.73,100,1,14.4,100,1,12.71,100,1,14.56,800,2,12.5,700,1,14.6,700,1,12.46,200,2,14.68,1400,2,12.43,700,1,14.72,100,1,12.42,700,1,14.76,100,1,ARL,315581981
,2025-07-17T15:54:26.792313320Z,2025-07-17T15:54:26.792313320Z,10,2,1108,C,B,0,13.29,10,130,165136,263895481,13.26,100,1,13.87,100,1,13.04,2,1,13.99,2,1,13.03,100,1,14.15,100,1,12.73,100,1,14.28,100,1,12.71,100,1,14.4,100,1,12.5,700,1,14.56,800,2,12.46,200,2,14.6,700,1,12.43,700,1,14.68,1400,2,12.42,700,1,14.72,100,1,12.37,700,1,14.76,100,1,ARL,315581981
,2025-07-17T15:54:52.985950259Z,2025-07-17T15:54:52.985950259Z,10,2,1108,C,A,1,13.99,2,0,165824,264262615,13.26,100,1,13.87,100,1,13.04,2,1,14.15,100,1,13.03,100,1,14.28,100,1,12.73,100,1,14.4,100,1,12.71,100,1,14.56,800,2,12.5,700,1,14.6,700,1,12.46,200,2,14.68,1400,2,12.43,700,1,14.72,100,1,12.42,700,1,14.76,100,1,12.37,700,1,14.81,100,1,ARL,313336713
,2025-07-17T15:54:52.985950259Z,2025-07-17T15:54:52.985950259Z,10,2,1108,A,A,1,14.1,2,130,165824,264262615,13.26,100,1,13.87,100,1,13.04,2,1,14.1,2,1,13.03,100,1,14.15,100,1,12.73,100,1,14.28,100,1,12.71,100,1,14.4,100,1,12.5,700,1,14.56,800,2,12.46,200,2,14.6,700,1,12.43,700,1,14.68,1400,2,12.42,700,1,14.72,100,1,12.37,700,1,14.76,100,1,ARL,316098525
,2025-07-17T15:55:33.673432762Z,2025-07-17T15:55:33.673432762Z,10,2,1108,A,B,0,13.29,10,130,165490,264905534,13.29,10,1,13.87,100,1,13.26,100,1,14.1,2,1,13.04,2,1,14.15,100,1,13.03,100,1,14.28,100,1,12.73,100,1,14.4,100,1,12.71,100,1,14.56,800,2,12.5,700,1,14.6,700,1,12.46,200,2,14.68,1400,2,12.43,700,1,14.72,100,1,12.42,700,1,14.76,100,1,ARL,316911465
,2025-07-17T15:55:34.257251787Z,2025-07-17T15:55:34.257251787Z,10,2,1108,C,B,1,13.26,100,0,165417,264919835,13.29,10,1,13.87,100,1,13.04,2,1,14.1,2,1,13.03,100,1,14.15,100,1,12.73,100,1,14.28,100,1,12.71,100,1,14.4,100,1,12.5,700,1,14.56,800,2,12.46,200,2,14.6,700,1,12.43,700,1,14.68,1400,2,12.42,700,1,14.72,100,1,12.37,700,1,14.76,100,1,ARL,312772077
,2025-07-17T15:55:34.257251787Z,2025-07-17T15:55:34.257251787Z,10,2,1108,A,B,1,13.28,100,130,165417,264919835,13.29,10,1,13.87,100,1,13.28,100,1,14.1,2,1,13.04,2,1,14.15,100,1,13.03,100,1,14.28,100,1,12.73,100,1,14.4,100,1,12.71,100,1,14.56,800,2,12.5,700,1,14.6,700,1,12.46,200,2,14.68,1400,2,12.43,700,1,14.72,100,1,12.42,700,1,14.76,100,1,ARL,316924721
,2025-07-17T15:55:40.197584524Z,2025-07-17T15:55:40.197584524Z,10,2,1108,C,B,0,13.29,10,130,165876,265015966,13.28,100,1,13.87,100,1,13.04,2,1,14.1,2,1,13.03,100,1,14.15,100,1,12.73,100,1,14.28,100,1,12.71,100,1,14.4,100,1,12.5,700,1,14.56,800,2,12.46,200,2,14.6,700,1,12.43,700,1,14.68,1400,2,12.42,700,1,14.72,100,1,12.37,700,1,14.76,100,1,ARL,316911465
,2025-07-17T15:57:51.111121910Z,2025-07-17T15:57:51.111121910Z,10,2,1108,T,N,0,13.6,1,0,167045,267268162,13.28,100,1,13.87,100,1,13.04,2,1,14.1,2,1,13.03,100,1,14.15,100,1,12.73,100,1,14.28,100,1,12.71,100,1,14.4,100,1,12.5,700,1,14.56,800,2,12.46,200,2,14.6,700,1,12.43,700,1,14.68,1400,2,12.42,700,1,14.72,100,1,12.37,700,1,14.76,100,1,ARL,0
,2025-07-17T15:57:51.111121910Z,2025-07-17T15:57:51.111121910Z,10,2,1108,T,N,0,13.575,99,130,167045,267268163,13.28,100,1,13.87,100,1,13.04,2,1,14.1,2,1,13.03,100,1,14.15,100,1,12.73,100,1,14.28,100,1,12.71,100,1,14.4,100,1,12.5,700,1,14.56,800,2,12.46,200,2,14.6,700,1,12.43,700,1,14.68,1400,2,12.42,700,1,14.72,100,1,12.37,700,1,14.76,100,1,ARL,0
,2025-07-17T15:57:51.111527963Z,2025-07-17T15:57:51.111527963Z,10,2,1108,T,N,0,13.575,100,130,165792,267268168,13.28,100,1,13.87,100,1,13.04,2,1,14.1,2,1,13.03,100,1,14.15,100,1,12.73,100,1,14.28,100,1,12.71,100,1,14.4,100,1,12.5,700,1,14.56,800,2,12.46,200,2,14.6,700,1,12.43,700,1,14.68,1400,2,12.42,700,1,14.72,100,1,12.37,700,1,14.76,100,1,ARL,0
,2025-07-17T15:57:51.111911476Z,2025-07-17T15:57:51.111911476Z,10,2,1108,T,N,0,13.575,1,130,166056,267268183,13.28,100,1,13.87,100,1,13.04,2,1,14.1,2,1,13.03,100,1,14.15,100,1,12.73,100,1,14.28,100,1,12.71,100,1,14.4,100,1,12.5,700,1,14.56,800,2,12.46,200,2,14.6,700,1,12.43,700,1,14.68,1400,2,12.42,700,1,14.72,100,1,12.37,700,1,14.76,100,1,ARL,0
,2025-07-17T15:57:51.328698198Z,2025-07-17T15:57:51.328698198Z,10,2,1108,C,A,0,13.87,100,130,165362,267272430,13.28,100,1,14.1,2,1,13.04,2,1,14.15,100,1,13.03,100,1,14.28,100,1,12.73,100,1,14.4,100,1,12.71,100,1,14.56,800,2,12.5,700,1,14.6,700,1,12.46,200,2,14.68,1400,2,12.43,700,1,14.72,100,1,12.42,700,1,14.76,100,1,12.37,700,1,14.81,100,1,ARL,312773881
,2025-07-17T15:57:51.329692071Z,2025-07-17T15:57:51.329692071Z,10,2,1108,C,A,8,14.76,100,0,165601,267272442,13.28,100,1,14.1,2,1,13.04,2,1,14.15,100,1,13.03,100,1,14.28,100,1,12.73,100,1,14.4,100,1,12.71,100,1,14.56,800,2,12.5,700,1,14.6,700,1,12.46,200,2,14.68,1400,2,12.43,700,1,14.72,100,1,12.42,700,1,14.81,100,1,12.37,700,1,14.89,100,1,ARL,312771829
,2025-07-17T15:57:51.329692071Z,2025-07-17T15:57:51.329692071Z,10,2,1108,A,A,9,14.89,100,130,165601,267272442,13.28,100,1,14.1,2,1,13.04,2,1,14.15,100,1,13.03,100,1,14.28,100,1,12.73,100,1,14.4,100,1,12.71,100,1,14.56,800,2,12.5,700,1,14.6,700,1,12.46,200,2,14.68,1400,2,12.43,700,1,14.72,100,1,12.42,700,1,14.81,100,1,12.37,700,1,14.89,200,2,ARL,319985025
,2025-07-17T15:57:51.339162512Z,2025-07-17T15:57:51.339162512Z,10,2,1108,C,A,1,14.15,100,130,165707,267272660,13.28,100,1,14.1,2,1,13.04,2,1,14.28,100,1,13.03,100,1,14.4,100,1,12.73,100,1,14.56,800,2,12.71,100,1,14.6,700,1,12.5,700,1,14.68,1400,2,12.46,200,2,14.72,100,1,12.43,700,1,14.81,100,1,12.42,700,1,14.89,200,2,12.37,700,1,14.96,100,1,ARL,312774033
,2025-07-17T15:57:51.339216923Z,2025-07-17T15:57:51.339216923Z,10,2,1108,A,A,1,14.26,100,130,165175,267272665,13.28,100,1,14.1,2,1,13.04,2,1,14.26,100,1,13.03,100,1,14.28,100,1,12.73,100,1,14.4,100,1,12.71,100,1,14.56,800,2,12.5,700,1,14.6,700,1,12.46,200,2,14.68,1400,2,12.43,700,1,14.72,100,1,12.42,700,1,14.81,100,1,12.37,700,1,14.89,200,2,ARL,319985165
,2025-07-17T15:57:52.378204338Z,2025-07-17T15:57:52.378204338Z,10,2,1108,A,A,1,14.11,100,130,165186,267283873,13.28,100,1,14.1,2,1,13.04,2,1,14.11,100,1,13.03,100,1,14.26,100,1,12.73,100,1,14.28,100,1,12.71,100,1,14.4,100,1,12.5,700,1,14.56,800,2,12.46,200,2,14.6,700,1,12.43,700,1,14.68,1400,2,12.42,700,1,14.72,100,1,12.37,700,1,14.81,100,1,ARL,320000233
,2025-07-17T15:58:14.483712278Z,2025-07-17T15:58:14.483712278Z,10,2,1108,T,N,0,13.41,44,130,166801,267657010,13.28,100,1,14.1,2,1,13.04,2,1,14.11,100,1,13.03,100,1,14.26,100,1,12.73,100,1,14.28,100,1,12.71,100,1,14.4,100,1,12.5,700,1,14.56,800,2,12.46,200,2,14.6,700,1,12.43,700,1,14.68,1400,2,12.42,700,1,14.72,100,1,12.37,700,1,14.81,100,1,ARL,0
,2025-07-17T15:58:14.483743947Z,2025-07-17T15:58:14.483743947Z,10,2,1108,A,A,0,13.76,4,130,165407,267657011,13.28,100,1,13.76,4,1,13.04,2,1,14.1,2,1,13.03,100,1,14.11,100,1,12.73,100,1,14.26,100,1,12.71,100,1,14.28,100,1,12.5,700,1,14.4,100,1,12.46,200,2,14.56,800,2,12.43,700,1,14.6,700,1,12.42,700,1,14.68,1400,2,12.37,700,1,14.72,100,1,ARL,320484625
,2025-07-17T15:58:14.483999049Z,2025-07-17T15:58:14.483999049Z,10,2,1108,C,A,2,14.11,100,0,165502,267657013,13.28,100,1,13.76,4,1,13.04,2,1,14.1,2,1,13.03,100,1,14.26,100,1,12.73,100,1,14.28,100,1,12.71,100,1,14.4,100,1,12.5,700,1,14.56,800,2,12.46,200,2,14.6,700,1,12.43,700,1,14.68,1400,2,12.42,700,1,14.72,100,1,12.37,700,1,14.81,100,1,ARL,320000233
,2025-07-17T15:58:14.483999049Z,2025-07-17T15:58:14.483999049Z,10,2,1108,A,A,1,13.77,100,130,165502,267657013,13.28,100,1,13.76,4,1,13.04,2,1,13.77,100,1,13.03,100,1,14.1,2,1,12.73,100,1,14.26,100,1,12.71,100,1,14.28,100,1,12.5,700,1,14.4,100,1,12.46,200,2,14.56,800,2,12.43,700,1,14.6,700,1,12.42,700,1,14.68,1400,2,12.37,700,1,14.72,100,1,ARL,320484637
,2025-07-17T15:58:14.484017806Z,2025-07-17T15:58:14.484017806Z,10,2,1108,C,B,0,13.28,100,130,165607,267657014,13.04,2,1,13.76,4,1,13.03,100,1,13.77,100,1,12.73,100,1,14.1,2,1,12.71,100,1,14.26,100,1,12.5,700,1,14.28,100,1,12.46,200,2,14.4,100,1,12.43,700,1,14.56,800,2,12.42,700,1,14.6,700,1,12.37,700,1,14.68,1400,2,12.36,200,2,14.72,100,1,ARL,316924721
,2025-07-17T15:58:14.484133730Z,2025-07-17T15:58:14.484133730Z,10,2,1108,T,N,0,13.41,8,130,165720,267657017,13.04,2,1,13.76,4,1,13.03,100,1,13.77,100,1,12.73,100,1,14.1,2,1,12.71,100,1,14.26,100,1,12.5,700,1,14.28,100,1,12.46,200,2,14.4,100,1,12.43,700,1,14.56,800,2,12.42,700,1,14.6,700,1,12.37,700,1,14.68,1400,2,12.36,200,2,14.72,100,1,ARL,0
,2025-07-17T15:58:14.484147359Z,2025-07-17T15:58:14.484147359Z,10,2,1108,A,A,2,13.79,100,130,165173,267657020,13.04,2,1,13.76,4,1,13.03,100,1,13.77,100,1,12.73,100,1,13.79,100,1,12.71,100,1,14.1,2,1,12.5,700,1,14.26,100,1,12.46,200,2,14.28,100,1,12.43,700,1,14.4,100,1,12.42,700,1,14.56,800,2,12.37,700,1,14.6,700,1,12.36,200,2,14.68,1400,2,ARL,320484661
,2025-07-17T15:58:14.484761664Z,2025-07-17T15:58:14.484761664Z,10,2,1108,C,A,0,13.76,4,128,166184,267657070,13.04,2,1,13.77,100,1,13.03,100,1,13.79,100,1,12.73,100,1,14.1,2,1,12.71,100,1,14.26,100,1,12.5,700,1,14.28,100,1,12.46,200,2,14.4,100,1,12.43,700,1,14.56,800,2,12.42,700,1,14.6,700,1,12.37,700,1,14.68,1400,2,12.36,200,2,14.72,100,1,ARL,320484625
,2025-07-17T15:58:14.484798779Z,2025-07-17T15:58:14.484798779Z,10,2,1108,C,A,0,13.77,100,130,165091,267657073,13.04,2,1,13.79,100,1,13.03,100,1,14.1,2,1,12.73,100,1,14.26,100,1,12.71,100,1,14.28,100,1,12.5,700,1,14.4,100,1,12.46,200,2,14.56,800,2,12.43,700,1,14.6,700,1,12.42,700,1,14.68,1400,2,12.37,700,1,14.72,100,1,12.36,200,2,14.81,100,1,ARL,320484637
,2025-07-17T15:58:14.485227487Z,2025-07-17T15:58:14.485227487Z,10,2,1108,C,A,9,14.81,100,0,165416,267657092,13.04,2,1,13.79,100,1,13.03,100,1,14.1,2,1,12.73,100,1,14.26,100,1,12.71,100,1,14.28,100,1,12.5,700,1,14.4,100,1,12.46,200,2,14.56,800,2,12.43,700,1,14.6,700,1,12.42,700,1,14.68,1400,2,12.37,700,1,14.72,100,1,12.36,200,2,14.84,100,1,ARL,312771781
,2025-07-17T15:58:14.485227487Z,2025-07-17T15:58:14.485227487Z,10,2,1108,A,A,7,14.68,100,130,165416,267657092,13.04,2,1,13.79,100,1,13.03,100,1,14.1,2,1,12.73,100,1,14.26,100,1,12.71,100,1,14.28,100,1,12.5,700,1,14.4,100,1,12.46,200,2,14.56,800,2,12.43,700,1,14.6,700,1,12.42,700,1,14.68,1500,3,12.37,700,1,14.72,100,1,12.36,200,2,14.84,100,1,ARL,320484781
,2025-07-17T15:58:14.485685308Z,2025-07-17T15:58:14.485685308Z,10,2,1108,A,A,9,14.76,100,130,165566,267657098,13.04,2,1,13.79,100,1,13.03,100,1,14.1,2,1,12.73,100,1,14.26,100,1,12.71,100,1,14.28,100,1,12.5,700,1,14.4,100,1,12.46,200,2,14.56,800,2,12.43,700,1,14.6,700,1,12.42,700,1,14.68,1500,3,12.37,700,1,14.72,100,1,12.36,200,2,14.76,100,1,ARL,320484821
,2025-07-17T15:58:14.485824228Z,2025-07-17T15:58:14.485824228Z,10,2,1108,A,A,8,14.69,100,130,165415,267657101,13.04,2,1,13.79,100,1,13.03,100,1,14.1,2,1,12.73,100,1,14.26,100,1,12.71,100,1,14.28,100,1,12.5,700,1,14.4,100,1,12.46,200,2,14.56,800,2,12.43,700,1,14.6,700,1,12.42,700,1,14.68,1500,3,12.37,700,1,14.69,100,1,12.36,200,2,14.72,100,1,ARL,320484825
,2025-07-17T15:58:14.508012098Z,2025-07-17T15:58:14.508012098Z,10,2,1108,C,A,2,14.26,100,130,165158,267657330,13.04,2,1,13.79,100,1,13.03,100,1,14.1,2,1,12.73,100,1,14.28,100,1,12.71,100,1,14.4,100,1,12.5,700,1,14.56,800,2,12.46,200,2,14.6,700,1,12.43,700,1,14.68,1500,3,12.42,700,1,14.69,100,1,12.37,700,1,14.72,100,1,12.36,200,2,14.76,100,1,ARL,319985165
,2025-07-17T15:58:14.508062605Z,2025-07-17T15:58:14.508062605Z,10,2,1108,A,A,1,14.05,100,130,165285,267657333,13.04,2,1,13.79,100,1,13.03,100,1,14.05,100,1,12.73,100,1,14.1,2,1,12.71,100,1,14.28,100,1,12.5,700,1,14.4,100,1,12.46,200,2,14.56,800,2,12.43,700,1,14.6,700,1,12.42,700,1,14.68,1500,3,12.37,700,1,14.69,100,1,12.36,200,2,14.72,100,1,ARL,320484985
,2025-07-17T15:58:14.529391743Z,2025-07-17T15:58:14.529391743Z,10,2,1108,A,B,2,13.02,100,130,165365,267657561,13.04,2,1,13.79,100,1,13.03,100,1,14.05,100,1,13.02,100,1,14.1,2,1,12.73,100,1,14.28,100,1,12.71,100,1,14.4,100,1,12.5,700,1,14.56,800,2,12.46,200,2,14.6,700,1,12.43,700,1,14.68,1500,3,12.42,700,1,14.69,100,1,12.37,700,1,14.72,100,1,ARL,320485385
,2025-07-17T15:58:14.529413184Z,2025-07-17T15:58:14.529413184Z,10,2,1108,A,A,1,13.8,100,130,165107,267657562,13.04,2,1,13.79,100,1,13.03,100,1,13.8,100,1,13.02,100,1,14.05,100,1,12.73,100,1,14.1,2,1,12.71,100,1,14.28,100,1,12.5,700,1,14.4,100,1,12.46,200,2,14.56,800,2,12.43,700,1,14.6,700,1,12.42,700,1,14.68,1500,3,12.37,700,1,14.69,100,1,ARL,320485389
,2025-07-17T15:58:14.659734381Z,2025-07-17T15:58:14.659734381Z,10,2,1108,C,A,0,13.79,100,130,165045,267658873,13.04,2,1,13.8,100,1,13.03,100,1,14.05,100,1,13.02,100,1,14.1,2,1,12.73,100,1,14.28,100,1,12.71,100,1,14.4,100,1,12.5,700,1,14.56,800,2,12.46,200,2,14.6,700,1,12.43,700,1,14.68,1500,3,12.42,700,1,14.69,100,1,12.37,700,1,14.72,100,1,ARL,320484661
,2025-07-17T15:58:14.659773896Z,2025-07-17T15:58:14.659773896Z,10,2,1108,C,A,0,13.8,100,130,165334,267658879,13.04,2,1,14.05,100,1,13.03,100,1,14.1,2,1,13.02,100,1,14.28,100,1,12.73,100,1,14.4,100,1,12.71,100,1,14.56,800,2,12.5,700,1,14.6,700,1,12.46,200,2,14.68,1500,3,12.43,700,1,14.69,100,1,12.42,700,1,14.72,100,1,12.37,700,1,14.76,100,1,ARL,320485389
,2025-07-17T15:58:14.660502341Z,2025-07-17T15:58:14.660502341Z,10,2,1108,C,A,10,14.84,100,0,165295,267658892,13.04,2,1,14.05,100,1,13.03,100,1,14.1,2,1,13.02,100,1,14.28,100,1,12.73,100,1,14.4,100,1,12.71,100,1,14.56,800,2,12.5,700,1,14.6,700,1,12.46,200,2,14.68,1500,3,12.43,700,1,14.69,100,1,12.42,700,1,14.72,100,1,12.37,700,1,14.76,100,1,ARL,320484709
,2025-07-17T15:58:14.672150755Z,2025-07-17T15:58:14.672150755Z,10,2,1108,C,A,0,14.05,100,130,165051,267658982,13.04,2,1,14.1,2,1,13.03,100,1,14.28,100,1,13.02,100,1,14.4,100,1,12.73,100,1,14.56,800,2,12.71,100,1,14.6,700,1,12.5,700,1,14.68,1500,3,12.46,200,2,14.69,100,1,12.43,700,1,14.72,100,1,12.42,700,1,14.76,100,1,12.37,700,1,14.89,100,1,ARL,320484985
,2025-07-17T15:58:14.672200872Z,2025-07-17T15:58:14.672200872Z,10,2,1108,A,A,1,14.12,100,130,165102,267658983,13.04,2,1,14.1,2,1,13.03,100,1,14.12,100,1,13.02,100,1,14.28,100,1,12.73,100,1,14.4,100,1,12.71,100,1,14.56,800,2,12.5,700,1,14.6,700,1,12.46,200,2,14.68,1500,3,12.43,700,1,14.69,100,1,12.42,700,1,14.72,100,1,12.37,700,1,14.76,100,1,ARL,320487017
,2025-07-17T15:58:14.673019194Z,2025-07-17T15:58:14.673019194Z,10,2,1108,C,A,1,14.12,100,130,164922,267658989,13.04,2,1,14.1,2,1,13.03,100,1,14.28,100,1,13.02,100,1,14.4,100,1,12.73,100,1,14.56,800,2,12.71,100,1,14.6,700,1,12.5,700,1,14.68,1500,3,12.46,200,2,14.69,100,1,12.43,700,1,14.72,100,1,12.42,700,1,14.76,100,1,12.37,700,1,14.89,100,1,ARL,320487017
,2025-07-17T15:58:14.673065320Z,2025-07-17T15:58:14.673065320Z,10,2,1108,A,A,1,14.26,100,130,165160,267658990,13.04,2,1,14.1,2,1,13.03,100,1,14.26,100,1,13.02,100,1,14.28,100,1,12.73,100,1,14.4,100,1,12.71,100,1,14.56,800,2,12.5,700,1,14.6,700,1,12.46,200,2,14.68,1500,3,12.43,700,1,14.69,100,1,12.42,700,1,14.72,100,1,12.37,700,1,14.76,100,1,ARL,320487025
,2025-07-17T15:58:14.682780396Z,2025-07-17T15:58:14.682780396Z,10,2,1108,C,A,9,14.76,100,0,165145,267659018,13.04,2,1,14.1,2,1,13.03,100,1,14.26,100,1,13.02,100,1,14.28,100,1,12.73,100,1,14.4,100,1,12.71,100,1,14.56,800,2,12.5,700,1,14.6,700,1,12.46,200,2,14.68,1500,3,12.43,700,1,14.69,100,1,12.42,700,1,14.72,100,1,12.37,700,1,14.89,100,1,ARL,320484821
,2025-07-17T15:58:14.710622495Z,2025-07-17T15:58:14.710622495Z,10,2,1108,C,A,10,14.91,100,0,165396,267659178,13.04,2,1,14.1,2,1,13.03,100,1,14.26,100,1,13.02,100,1,14.28,100,1,12.73,100,1,14.4,100,1,12.71,100,1,14.56,800,2,12.5,700,1,14.6,700,1,12.46,200,2,14.68,1500,3,12.43,700,1,14.69,100,1,12.42,700,1,14.72,100,1,12.37,700,1,14.89,100,1,ARL,320486925
,2025-07-17T15:58:15.563904700Z,2025-07-17T15:58:15.563904700Z,10,2,1108,C,A,6,14.68,100,0,165556,267672469,13.04,2,1,14.1,2,1,13.03,100,1,14.26,100,1,13.02,100,1,14.28,100,1,12.73,100,1,14.4,100,1,12.71,100,1,14.56,800,2,12.5,700,1,14.6,700,1,12.46,200,2,14.68,1400,2,12.43,700,1,14.69,100,1,12.42,700,1,14.72,100,1,12.37,700,1,14.89,100,1,ARL,320484781
,2025-07-17T15:58:15.563904700Z,2025-07-17T15:58:15.563904700Z,10,2,1108,A,A,9,14.87,100,130,165556,267672469,13.04,2,1,14.1,2,1,13.03,100,1,14.26,100,1,13.02,100,1,14.28,100,1,12.73,100,1,14.4,100,1,12.71,100,1,14.56,800,2,12.5,700,1,14.6,700,1,12.46,200,2,14.68,1400,2,12.43,700,1,14.69,100,1,12.42,700,1,14.72,100,1,12.37,700,1,14.87,100,1,ARL,320504473
,2025-07-17T15:58:15.577554368Z,2025-07-17T15:58:15.577554368Z,10,2,1108,C,A,7,14.69,100,0,165428,267672549,13.04,2,1,14.1,2,1,13.03,100,1,14.26,100,1,13.02,100,1,14.28,100,1,12.73,100,1,14.4,100,1,12.71,100,1,14.56,800,2,12.5,700,1,14.6,700,1,12.46,200,2,14.68,1400,2,12.43,700,1,14.72,100,1,12.42,700,1,14.87,100,1,12.37,700,1,14.89,100,1,ARL,320484825
,2025-07-17T15:58:15.577554368Z,2025-07-17T15:58:15.577554368Z,10,2,1108,A,A,9,14.88,100,130,165428,267672549,13.04,2,1,14.1,2,1,13.03,100,1,14.26,100,1,13.02,100,1,14.28,100,1,12.73,100,1,14.4,100,1,12.71,100,1,14.56,800,2,12.5,700,1,14.6,700,1,12.46,200,2,14.68,1400,2,12.43,700,1,14.72,100,1,12.42,700,1,14.87,100,1,12.37,700,1,14.88,100,1,ARL,320504609
,2025-07-17T15:58:16.501915292Z,2025-07-17T15:58:16.501915292Z,10,2,1108,A,A,1,14.11,100,130,165223,267685252,13.04,2,1,14.1,2,1,13.03,100,1,14.11,100,1,13.02,100,1,14.26,100,1,12.73,100,1,14.28,100,1,12.71,100,1,14.4,100,1,12.5,700,1,14.56,800,2,12.46,200,2,14.6,700,1,12.43,700,1,14.68,1400,2,12.42,700,1,14.72,100,1,12.37,700,1,14.87,100,1,ARL,320519893
,2025-07-17T15:58:19.965034325Z,2025-07-17T15:58:19.965034325Z,10,2,1108,A,A,0,13.94,15,130,166655,267738403,13.04,2,1,13.94,15,1,13.03,100,1,14.1,2,1,13.02,100,1,14.11,100,1,12.73,100,1,14.26,100,1,12.71,100,1,14.28,100,1,12.5,700,1,14.4,100,1,12.46,200,2,14.56,800,2,12.43,700,1,14.6,700,1,12.42,700,1,14.68,1400,2,12.37,700,1,14.72,100,1,ARL,320588689
,2025-07-17T15:58:20.237668047Z,2025-07-17T15:58:20.237668047Z,10,2,1108,C,A,2,14.11,100,0,165355,267745213,13.04,2,1,13.94,15,1,13.03,100,1,14.1,2,1,13.02,100,1,14.26,100,1,12.73,100,1,14.28,100,1,12.71,100,1,14.4,100,1,12.5,700,1,14.56,800,2,12.46,200,2,14.6,700,1,12.43,700,1,14.68,1400,2,12.42,700,1,14.72,100,1,12.37,700,1,14.87,100,1,ARL,320519893
,2025-07-17T15:58:20.237668047Z,2025-07-17T15:58:20.237668047Z,10,2,1108,A,A,1,13.95,100,130,165355,267745213,13.04,2,1,13.94,15,1,13.03,100,1,13.95,100,1,13.02,100,1,14.1,2,1,12.73,100,1,14.26,100,1,12.71,100,1,14.28,100,1,12.5,700,1,14.4,100,1,12.46,200,2,14.56,800,2,12.43,700,1,14.6,700,1,12.42,700,1,14.68,1400,2,12.37,700,1,14.72,100,1,ARL,320595817
,2025-07-17T15:58:20.705344578Z,2025-07-17T15:58:20.705344578Z,10,2,1108,C,A,0,13.94,15,128,167593,267754327,13.04,2,1,13.95,100,1,13.03,100,1,14.1,2,1,13.02,100,1,14.26,100,1,12.73,100,1,14.28,100,1,12.71,100,1,14.4,100,1,12.5,700,1,14.56,800,2,12.46,200,2,14.6,700,1,12.43,700,1,14.68,1400,2,12.42,700,1,14.72,100,1,12.37,700,1,14.87,100,1,ARL,320588689
,2025-07-17T15:58:30.799887713Z,2025-07-17T15:58:30.799887713Z,10,2,1108,A,A,0,13.89,15,130,165349,267913947,13.04,2,1,13.89,15,1,13.03,100,1,13.95,100,1,13.02,100,1,14.1,2,1,12.73,100,1,14.26,100,1,12.71,100,1,14.28,100,1,12.5,700,1,14.4,100,1,12.46,200,2,14.56,800,2,12.43,700,1,14.6,700,1,12.42,700,1,14.68,1400,2,12.37,700,1,14.72,100,1,ARL,320833897
,2025-07-17T15:58:30.905491759Z,2025-07-17T15:58:30.905491759Z,10,2,1108,C,A,1,13.95,100,0,165560,267919515,13.04,2,1,13.89,15,1,13.03,100,1,14.1,2,1,13.02,100,1,14.26,100,1,12.73,100,1,14.28,100,1,12.71,100,1,14.4,100,1,12.5,700,1,14.56,800,2,12.46,200,2,14.6,700,1,12.43,700,1,14.68,1400,2,12.42,700,1,14.72,100,1,12.37,700,1,14.87,100,1,ARL,320595817
,2025-07-17T15:58:30.905491759Z,2025-07-17T15:58:30.905491759Z,10,2,1108,A,A,1,13.9,100,130,165560,267919515,13.04,2,1,13.89,15,1,13.03,100,1,13.9,100,1,13.02,100,1,14.1,2,1,12.73,100,1,14.26,100,1,12.71,100,1,14.28,100,1,12.5,700,1,14.4,100,1,12.46,200,2,14.56,800,2,12.43,700,1,14.6,700,1,12.42,700,1,14.68,1400,2,12.37,700,1,14.72,100,1,ARL,320839125
,2025-07-17T15:58:30.916561264Z,2025-07-17T15:58:30.916561264Z,10,2,1108,C,A,3,14.26,100,130,165089,267919917,13.04,2,1,13.89,15,1,13.03,100,1,13.9,100,1,13.02,100,1,14.1,2,1,12.73,100,1,14.28,100,1,12.71,100,1,14.4,100,1,12.5,700,1,14.56,800,2,12.46,200,2,14.6,700,1,12.43,700,1,14.68,1400,2,12.42,700,1,14.72,100,1,12.37,700,1,14.87,100,1,ARL,320487025
,2025-07-17T15:58:30.916619122Z,2025-07-17T15:58:30.916619122Z,10,2,1108,A,A,3,14.18,100,130,165156,267919919,13.04,2,1,13.89,15,1,13.03,100,1,13.9,100,1,13.02,100,1,14.1,2,1,12.73,100,1,14.18,100,1,12.71,100,1,14.28,100,1,12.5,700,1,14.4,100,1,12.46,200,2,14.56,800,2,12.43,700,1,14.6,700,1,12.42,700,1,14.68,1400,2,12.37,700,1,14.72,100,1,ARL,320839577
,2025-07-17T15:58:31.124222733Z,2025-07-17T15:58:31.124222733Z,10,2,1108,C,A,10,14.87,100,0,165984,267925564,13.04,2,1,13.89,15,1,13.03,100,1,13.9,100,1,13.02,100,1,14.1,2,1,12.73,100,1,14.18,100,1,12.71,100,1,14.28,100,1,12.5,700,1,14.4,100,1,12.46,200,2,14.56,800,2,12.43,700,1,14.6,700,1,12.42,700,1,14.68,1400,2,12.37,700,1,14.72,100,1,ARL,320504473
,2025-07-17T15:58:31.124222733Z,2025-07-17T15:58:31.124222733Z,10,2,1108,A,A,10,14.76,100,130,165984,267925564,13.04,2,1,13.89,15,1,13.03,100,1,13.9,100,1,13.02,100,1,14.1,2,1,12.73,100,1,14.18,100,1,12.71,100,1,14.28,100,1,12.5,700,1,14.4,100,1,12.46,200,2,14.56,800,2,12.43,700,1,14.6,700,1,12.42,700,1,14.68,1400,2,12.37,700,1,14.72,100,1,ARL,320845893
,2025-07-17T15:58:40.799787018Z,2025-07-17T15:58:40.799787018Z,10,2,1108,A,A,0,13.83,15,130,165225,268074431,13.04,2,1,13.83,15,1,13.03,100,1,13.89,15,1,13.02,100,1,13.9,100,1,12.73,100,1,14.1,2,1,12.71,100,1,14.18,100,1,12.5,700,1,14.28,100,1,12.46,200,2,14.4,100,1,12.43,700,1,14.56,800,2,12.42,700,1,14.6,700,1,12.37,700,1,14.68,1400,2,ARL,321038033
,2025-07-17T15:58:43.690078924Z,2025-07-17T15:58:43.690078924Z,10,2,1108,C,A,2,13.9,100,0,165549,268115228,13.04,2,1,13.83,15,1,13.03,100,1,13.89,15,1,13.02,100,1,14.1,2,1,12.73,100,1,14.18,100,1,12.71,100,1,14.28,100,1,12.5,700,1,14.4,100,1,12.46,200,2,14.56,800,2,12.43,700,1,14.6,700,1,12.42,700,1,14.68,1400,2,12.37,700,1,14.72,100,1,ARL,320839125
,2025-07-17T15:58:43.690078924Z,2025-07-17T15:58:43.690078924Z,10,2,1108,A,A,1,13.84,100,130,165549,268115228,13.04,2,1,13.83,15,1,13.03,100,1,13.84,100,1,13.02,100,1,13.89,15,1,12.73,100,1,14.1,2,1,12.71,100,1,14.18,100,1,12.5,700,1,14.28,100,1,12.46,200,2,14.4,100,1,12.43,700,1,14.56,800,2,12.42,700,1,14.6,700,1,12.37,700,1,14.68,1400,2,ARL,321096769
,2025-07-17T15:58:44.903574654Z,2025-07-17T15:58:44.903574654Z,10,2,1108,A,A,0,13.83,100,130,165455,268129040,13.04,2,1,13.83,115,2,13.03,100,1,13.84,100,1,13.02,100,1,13.89,15,1,12.73,100,1,14.1,2,1,12.71,100,1,14.18,100,1,12.5,700,1,14.28,100,1,12.46,200,2,14.4,100,1,12.43,700,1,14.56,800,2,12.42,700,1,14.6,700,1,12.37,700,1,14.68,1400,2,ARL,321114473
,2025-07-17T15:58:44.923948853Z,2025-07-17T15:58:44.923948853Z,10,2,1108,C,A,4,14.18,100,130,165415,268129217,13.04,2,1,13.83,115,2,13.03,100,1,13.84,100,1,13.02,100,1,13.89,15,1,12.73,100,1,14.1,2,1,12.71,100,1,14.28,100,1,12.5,700,1,14.4,100,1,12.46,200,2,14.56,800,2,12.43,700,1,14.6,700,1,12.42,700,1,14.68,1400,2,12.37,700,1,14.72,100,1,ARL,320839577
,2025-07-17T15:58:44.924000519Z,2025-07-17T15:58:44.924000519Z,10,2,1108,A,A,4,14.11,100,130,165356,268129218,13.04,2,1,13.83,115,2,13.03,100,1,13.84,100,1,13.02,100,1,13.89,15,1,12.73,100,1,14.1,2,1,12.71,100,1,14.11,100,1,12.5,700,1,14.28,100,1,12.46,200,2,14.4,100,1,12.43,700,1,14.56,800,2,12.42,700,1,14.6,700,1,12.37,700,1,14.68,1400,2,ARL,321114729
,2025-07-17T15:58:51.241176997Z,2025-07-17T15:58:51.241176997Z,10,2,1108,C,A,2,13.89,15,130,165268,268212338,13.04,2,1,13.83,115,2,13.03,100,1,13.84,100,1,13.02,100,1,14.1,2,1,12.73,100,1,14.11,100,1,12.71,100,1,14.28,100,1,12.5,700,1,14.4,100,1,12.46,200,2,14.56,800,2,12.43,700,1,14.6,700,1,12.42,700,1,14.68,1400,2,12.37,700,1,14.72,100,1,ARL,320833897
,2025-07-17T15:58:51.253961905Z,2025-07-17T15:58:51.253961905Z,10,2,1108,A,A,0,13.8,100,130,165434,268212497,13.04,2,1,13.8,100,1,13.03,100,1,13.83,115,2,13.02,100,1,13.84,100,1,12.73,100,1,14.1,2,1,12.71,100,1,14.11,100,1,12.5,700,1,14.28,100,1,12.46,200,2,14.4,100,1,12.43,700,1,14.56,800,2,12.42,700,1,14.6,700,1,12.37,700,1,14.68,1400,2,ARL,321225725
,2025-07-17T15:58:51.260587778Z,2025-07-17T15:58:51.260587778Z,10,2,1108,C,A,1,13.83,100,130,165401,268212534,13.04,2,1,13.8,100,1,13.03,100,1,13.83,15,1,13.02,100,1,13.84,100,1,12.73,100,1,14.1,2,1,12.71,100,1,14.11,100,1,12.5,700,1,14.28,100,1,12.46,200,2,14.4,100,1,12.43,700,1,14.56,800,2,12.42,700,1,14.6,700,1,12.37,700,1,14.68,1400,2,ARL,321114473
,2025-07-17T15:58:53.579462029Z,2025-07-17T15:58:53.579462029Z,10,2,1108,C,A,1,13.83,15,130,166259,268250290,13.04,2,1,13.8,100,1,13.03,100,1,13.84,100,1,13.02,100,1,14.1,2,1,12.73,100,1,14.11,100,1,12.71,100,1,14.28,100,1,12.5,700,1,14.4,100,1,12.46,200,2,14.56,800,2,12.43,700,1,14.6,700,1,12.42,700,1,14.68,1400,2,12.37,700,1,14.72,100,1,ARL,321038033
,2025-07-17T15:58:53.580052014Z,2025-07-17T15:58:53.580052014Z,10,2,1108,C,A,1,13.84,100,0,165431,268250346,13.04,2,1,13.8,100,1,13.03,100,1,14.1,2,1,13.02,100,1,14.11,100,1,12.73,100,1,14.28,100,1,12.71,100,1,14.4,100,1,12.5,700,1,14.56,800,2,12.46,200,2,14.6,700,1,12.43,700,1,14.68,1400,2,12.42,700,1,14.72,100,1,12.37,700,1,14.76,100,1,ARL,321096769
,2025-07-17T15:58:53.580052014Z,2025-07-17T15:58:53.580052014Z,10,2,1108,A,A,1,13.81,100,130,165431,268250346,13.04,2,1,13.8,100,1,13.03,100,1,13.81,100,1,13.02,100,1,14.1,2,1,12.73,100,1,14.11,100,1,12.71,100,1,14.28,100,1,12.5,700,1,14.4,100,1,12.46,200,2,14.56,800,2,12.43,700,1,14.6,700,1,12.42,700,1,14.68,1400,2,12.37,700,1,14.72,100,1,ARL,321272581
,2025-07-17T15:58:54.583958582Z,2025-07-17T15:58:54.583958582Z,10,2,1108,A,A,8,14.65,100,130,165633,268265585,13.04,2,1,13.8,100,1,13.03,100,1,13.81,100,1,13.02,100,1,14.1,2,1,12.73,100,1,14.11,100,1,12.71,100,1,14.28,100,1,12.5,700,1,14.4,100,1,12.46,200,2,14.56,800,2,12.43,700,1,14.6,700,1,12.42,700,1,14.65,100,1,12.37,700,1,14.68,1400,2,ARL,321293737
,2025-07-17T15:58:54.584094980Z,2025-07-17T15:58:54.584094980Z,10,2,1108,A,A,8,14.64,100,130,165732,268265586,13.04,2,1,13.8,100,1,13.03,100,1,13.81,100,1,13.02,100,1,14.1,2,1,12.73,100,1,14.11,100,1,12.71,100,1,14.28,100,1,12.5,700,1,14.4,100,1,12.46,200,2,14.56,800,2,12.43,700,1,14.6,700,1,12.42,700,1,14.64,100,1,12.37,700,1,14.65,100,1,ARL,321293741
,2025-07-17T15:58:55.304938318Z,2025-07-17T15:58:55.304938318Z,10,2,1108,A,A,0,13.78,100,130,165711,268277940,13.04,2,1,13.78,100,1,13.03,100,1,13.8,100,1,13.02,100,1,13.81,100,1,12.73,100,1,14.1,2,1,12.71,100,1,14.11,100,1,12.5,700,1,14.28,100,1,12.46,200,2,14.4,100,1,12.43,700,1,14.56,800,2,12.42,700,1,14.6,700,1,12.37,700,1,14.64,100,1,ARL,321309865
,2025-07-17T15:58:55.307472032Z,2025-07-17T15:58:55.307472032Z,10,2,1108,A,A,8,14.58,100,130,165177,268278004,13.04,2,1,13.78,100,1,13.03,100,1,13.8,100,1,13.02,100,1,13.81,100,1,12.73,100,1,14.1,2,1,12.71,100,1,14.11,100,1,12.5,700,1,14.28,100,1,12.46,200,2,14.4,100,1,12.43,700,1,14.56,800,2,12.42,700,1,14.58,100,1,12.37,700,1,14.6,700,1,ARL,321309941
,2025-07-17T15:58:55.311734700Z,2025-07-17T15:58:55.311734700Z,10,2,1108,C,A,1,13.8,100,130,165265,268278030,13.04,2,1,13.78,100,1,13.03,100,1,13.81,100,1,13.02,100,1,14.1,2,1,12.73,100,1,14.11,100,1,12.71,100,1,14.28,100,1,12.5,700,1,14.4,100,1,12.46,200,2,14.56,800,2,12.43,700,1,14.58,100,1,12.42,700,1,14.6,700,1,12.37,700,1,14.64,100,1,ARL,321225725
,2025-07-17T15:58:58.668086788Z,2025-07-17T15:58:58.668086788Z,10,2,1108,C,A,1,13.81,100,0,165518,268321684,13.04,2,1,13.78,100,1,13.03,100,1,14.1,2,1,13.02,100,1,14.11,100,1,12.73,100,1,14.28,100,1,12.71,100,1,14.4,100,1,12.5,700,1,14.56,800,2,12.46,200,2,14.58,100,1,12.43,700,1,14.6,700,1,12.42,700,1,14.64,100,1,12.37,700,1,14.65,100,1,ARL,321272581
,2025-07-17T15:58:58.668086788Z,2025-07-17T15:58:58.668086788Z,10,2,1108,A,A,1,13.79,100,130,165518,268321684,13.04,2,1,13.78,100,1,13.03,100,1,13.79,100,1,13.02,100,1,14.1,2,1,12.73,100,1,14.11,100,1,12.71,100,1,14.28,100,1,12.5,700,1,14.4,100,1,12.46,200,2,14.56,800,2,12.43,700,1,14.58,100,1,12.42,700,1,14.6,700,1,12.37,700,1,14.64,100,1,ARL,321364281
,2025-07-17T15:59:03.613527621Z,2025-07-17T15:59:03.613527621Z,10,2,1108,A,A,0,13.72,15,130,165292,268437919,13.04,2,1,13.72,15,1,13.03,100,1,13.78,100,1,13.02,100,1,13.79,100,1,12.73,100,1,14.1,2,1,12.71,100,1,14.11,100,1,12.5,700,1,14.28,100,1,12.46,200,2,14.4,100,1,12.43,700,1,14.56,800,2,12.42,700,1,14.58,100,1,12.37,700,1,14.6,700,1,ARL,321500117
,2025-07-17T15:59:03.626181384Z,2025-07-17T15:59:03.626181384Z,10,2,1108,A,A,1,13.76,100,130,165232,268438110,13.04,2,1,13.72,15,1,13.03,100,1,13.76,100,1,13.02,100,1,13.78,100,1,12.73,100,1,13.79,100,1,12.71,100,1,14.1,2,1,12.5,700,1,14.11,100,1,12.46,200,2,14.28,100,1,12.43,700,1,14.4,100,1,12.42,700,1,14.56,800,2,12.37,700,1,14.58,100,1,ARL,321500317
,2025-07-17T15:59:03.632928023Z,2025-07-17T15:59:03.632928023Z,10,2,1108,C,A,2,13.78,100,130,165235,268438149,13.04,2,1,13.72,15,1,13.03,100,1,13.76,100,1,13.02,100,1,13.79,100,1,12.73,100,1,14.1,2,1,12.71,100,1,14.11,100,1,12.5,700,1,14.28,100,1,12.46,200,2,14.4,100,1,12.43,700,1,14.56,800,2,12.42,700,1,14.58,100,1,12.37,700,1,14.6,700,1,ARL,321309865
,2025-07-17T15:59:03.649116452Z,2025-07-17T15:59:03.649116452Z,10,2,1108,C,A,4,14.11,100,130,165611,268438330,13.04,2,1,13.72,15,1,13.03,100,1,13.76,100,1,13.02,100,1,13.79,100,1,12.73,100,1,14.1,2,1,12.71,100,1,14.28,100,1,12.5,700,1,14.4,100,1,12.46,200,2,14.56,800,2,12.43,700,1,14.58,100,1,12.42,700,1,14.6,700,1,12.37,700,1,14.64,100,1,ARL,321114729
,2025-07-17T15:59:03.649167617Z,2025-07-17T15:59:03.649167617Z,10,2,1108,A,A,3,14.04,100,130,165256,268438331,13.04,2,1,13.72,15,1,13.03,100,1,13.76,100,1,13.02,100,1,13.79,100,1,12.73,100,1,14.04,100,1,12.71,100,1,14.1,2,1,12.5,700,1,14.28,100,1,12.46,200,2,14.4,100,1,12.43,700,1,14.56,800,2,12.42,700,1,14.58,100,1,12.37,700,1,14.6,700,1,ARL,321500957
,2025-07-17T15:59:04.223835151Z,2025-07-17T15:59:04.223835151Z,10,2,1108,C,A,2,13.79,100,0,165654,268447989,13.04,2,1,13.72,15,1,13.03,100,1,13.76,100,1,13.02,100,1,14.04,100,1,12.73,100,1,14.1,2,1,12.71,100,1,14.28,100,1,12.5,700,1,14.4,100,1,12.46,200,2,14.56,800,2,12.43,700,1,14.58,100,1,12.42,700,1,14.6,700,1,12.37,700,1,14.64,100,1,ARL,321364281
,2025-07-17T15:59:04.223835151Z,2025-07-17T15:59:04.223835151Z,10,2,1108,A,A,1,13.73,100,130,165654,268447989,13.04,2,1,13.72,15,1,13.03,100,1,13.73,100,1,13.02,100,1,13.76,100,1,12.73,100,1,14.04,100,1,12.71,100,1,14.1,2,1,12.5,700,1,14.28,100,1,12.46,200,2,14.4,100,1,12.43,700,1,14.56,800,2,12.42,700,1,14.58,100,1,12.37,700,1,14.6,700,1,ARL,321511377
,2025-07-17T15:59:04.799833206Z,2025-07-17T15:59:04.799833206Z,10,2,1108,C,A,0,13.72,15,130,165436,268457531,13.04,2,1,13.73,100,1,13.03,100,1,13.76,100,1,13.02,100,1,14.04,100,1,12.73,100,1,14.1,2,1,12.71,100,1,14.28,100,1,12.5,700,1,14.4,100,1,12.46,200,2,14.56,800,2,12.43,700,1,14.58,100,1,12.42,700,1,14.6,700,1,12.37,700,1,14.64,100,1,ARL,321500117
,2025-07-17T16:00:13.989771852Z,2025-07-17T16:00:13.989771852Z,10,2,1108,C,A,3,14.1,2,0,165562,269514876,13.04,2,1,13.73,100,1,13.03,100,1,13.76,100,1,13.02,100,1,14.04,100,1,12.73,100,1,14.28,100,1,12.71,100,1,14.4,100,1,12.5,700,1,14.56,800,2,12.46,200,2,14.58,100,1,12.43,700,1,14.6,700,1,12.42,700,1,14.64,100,1,12.37,700,1,14.65,100,1,ARL,316098525
,2025-07-17T16:00:13.989771852Z,2025-07-17T16:00:13.989771852Z,10,2,1108,A,A,2,14.01,2,130,165562,269514876,13.04,2,1,13.73,100,1,13.03,100,1,13.76,100,1,13.02,100,1,14.01,2,1,12.73,100,1,14.04,100,1,12.71,100,1,14.28,100,1,12.5,700,1,14.4,100,1,12.46,200,2,14.56,800,2,12.43,700,1,14.58,100,1,12.42,700,1,14.6,700,1,12.37,700,1,14.64,100,1,ARL,322898193
,2025-07-17T16:00:28.802849928Z,2025-07-17T16:00:28.802849928Z,10,2,1108,A,A,0,13.72,15,130,166002,269765653,13.04,2,1,13.72,15,1,13.03,100,1,13.73,100,1,13.02,100,1,13.76,100,1,12.73,100,1,14.01,2,1,12.71,100,1,14.04,100,1,12.5,700,1,14.28,100,1,12.46,200,2,14.4,100,1,12.43,700,1,14.56,800,2,12.42,700,1,14.58,100,1,12.37,700,1,14.6,700,1,ARL,323238809
,2025-07-17T16:00:32.549247168Z,2025-07-17T16:00:32.549247168Z,10,2,1108,A,A,2,13.74,100,130,165448,269878282,13.04,2,1,13.72,15,1,13.03,100,1,13.73,100,1,13.02,100,1,13.74,100,1,12.73,100,1,13.76,100,1,12.71,100,1,14.01,2,1,12.5,700,1,14.04,100,1,12.46,200,2,14.28,100,1,12.43,700,1,14.4,100,1,12.42,700,1,14.56,800,2,12.37,700,1,14.58,100,1,ARL,323370569
,2025-07-17T16:00:32.560823786Z,2025-07-17T16:00:32.560823786Z,10,2,1108,C,A,3,13.76,100,130,165307,269878639,13.04,2,1,13.72,15,1,13.03,100,1,13.73,100,1,13.02,100,1,13.74,100,1,12.73,100,1,14.01,2,1,12.71,100,1,14.04,100,1,12.5,700,1,14.28,100,1,12.46,200,2,14.4,100,1,12.43,700,1,14.56,800,2,12.42,700,1,14.58,100,1,12.37,700,1,14.6,700,1,ARL,321500317
,2025-07-17T16:00:35.512999155Z,2025-07-17T16:00:35.512999155Z,10,2,1108,A,A,0,13.69,15,130,165303,269940539,13.04,2,1,13.69,15,1,13.03,100,1,13.72,15,1,13.02,100,1,13.73,100,1,12.73,100,1,13.74,100,1,12.71,100,1,14.01,2,1,12.5,700,1,14.04,100,1,12.46,200,2,14.28,100,1,12.43,700,1,14.4,100,1,12.42,700,1,14.56,800,2,12.37,700,1,14.58,100,1,ARL,323455221
,2025-07-17T16:00:42.614063415Z,2025-07-17T16:00:42.614063415Z,10,2,1108,C,A,2,13.73,100,0,165769,270051089,13.04,2,1,13.69,15,1,13.03,100,1,13.72,15,1,13.02,100,1,13.74,100,1,12.73,100,1,14.01,2,1,12.71,100,1,14.04,100,1,12.5,700,1,14.28,100,1,12.46,200,2,14.4,100,1,12.43,700,1,14.56,800,2,12.42,700,1,14.58,100,1,12.37,700,1,14.6,700,1,ARL,321511377
,2025-07-17T16:00:42.614063415Z,2025-07-17T16:00:42.614063415Z,10,2,1108,A,A,1,13.7,100,130,165769,270051089,13.04,2,1,13.69,15,1,13.03,100,1,13.7,100,1,13.02,100,1,13.72,15,1,12.73,100,1,13.74,100,1,12.71,100,1,14.01,2,1,12.5,700,1,14.04,100,1,12.46,200,2,14.28,100,1,12.43,700,1,14.4,100,1,12.42,700,1,14.56,800,2,12.37,700,1,14.58,100,1,ARL,323599605
,2025-07-17T16:00:42.614088947Z,2025-07-17T16:00:42.614088947Z,10,2,1108,A,A,2,13.72,100,130,165252,270051090,13.04,2,1,13.69,15,1,13.03,100,1,13.7,100,1,13.02,100,1,13.72,115,2,12.73,100,1,13.74,100,1,12.71,100,1,14.01,2,1,12.5,700,1,14.04,100,1,12.46,200,2,14.28,100,1,12.43,700,1,14.4,100,1,12.42,700,1,14.56,800,2,12.37,700,1,14.58,100,1,ARL,323599609
,2025-07-17T16:00:42.614231125Z,2025-07-17T16:00:42.614231125Z,10,2,1108,C,A,3,13.74,100,130,165089,270051092,13.04,2,1,13.69,15,1,13.03,100,1,13.7,100,1,13.02,100,1,13.72,115,2,12.73,100,1,14.01,2,1,12.71,100,1,14.04,100,1,12.5,700,1,14.28,100,1,12.46,200,2,14.4,100,1,12.43,700,1,14.56,800,2,12.42,700,1,14.58,100,1,12.37,700,1,14.6,700,1,ARL,323370569
,2025-07-17T16:00:42.636595817Z,2025-07-17T16:00:42.636595817Z,10,2,1108,C,A,4,14.04,100,130,165359,270051179,13.04,2,1,13.69,15,1,13.03,100,1,13.7,100,1,13.02,100,1,13.72,115,2,12.73,100,1,14.01,2,1,12.71,100,1,14.28,100,1,12.5,700,1,14.4,100,1,12.46,200,2,14.56,800,2,12.43,700,1,14.58,100,1,12.42,700,1,14.6,700,1,12.37,700,1,14.64,100,1,ARL,321500957
,2025-07-17T16:00:42.636649389Z,2025-07-17T16:00:42.636649389Z,10,2,1108,A,A,3,13.97,100,130,165315,270051181,13.04,2,1,13.69,15,1,13.03,100,1,13.7,100,1,13.02,100,1,13.72,115,2,12.73,100,1,13.97,100,1,12.71,100,1,14.01,2,1,12.5,700,1,14.28,100,1,12.46,200,2,14.4,100,1,12.43,700,1,14.56,800,2,12.42,700,1,14.58,100,1,12.37,700,1,14.6,700,1,ARL,323599765
,2025-07-17T16:00:46.803097192Z,2025-07-17T16:00:46.803097192Z,10,2,1108,C,A,2,13.72,15,130,165268,270102799,13.04,2,1,13.69,15,1,13.03,100,1,13.7,100,1,13.02,100,1,13.72,100,1,12.73,100,1,13.97,100,1,12.71,100,1,14.01,2,1,12.5,700,1,14.28,100,1,12.46,200,2,14.4,100,1,12.43,700,1,14.56,800,2,12.42,700,1,14.58,100,1,12.37,700,1,14.6,700,1,ARL,323238809
,2025-07-17T16:00:49.255465939Z,2025-07-17T16:00:49.255465939Z,10,2,1108,A,A,0,13.66,15,130,165325,270140405,13.04,2,1,13.66,15,1,13.03,100,1,13.69,15,1,13.02,100,1,13.7,100,1,12.73,100,1,13.72,100,1,12.71,100,1,13.97,100,1,12.5,700,1,14.01,2,1,12.46,200,2,14.28,100,1,12.43,700,1,14.4,100,1,12.42,700,1,14.56,800,2,12.37,700,1,14.58,100,1,ARL,323720189
,2025-07-17T16:00:49.739479408Z,2025-07-17T16:00:49.739479408Z,10,2,1108,A,A,2,13.7,100,130,165196,270146528,13.04,2,1,13.66,15,1,13.03,100,1,13.69,15,1,13.02,100,1,13.7,200,2,12.73,100,1,13.72,100,1,12.71,100,1,13.97,100,1,12.5,700,1,14.01,2,1,12.46,200,2,14.28,100,1,12.43,700,1,14.4,100,1,12.42,700,1,14.56,800,2,12.37,700,1,14.58,100,1,ARL,323730309
,2025-07-17T16:00:49.744872763Z,2025-07-17T16:00:49.744872763Z,10,2,1108,C,A,2,13.7,100,0,165498,270146577,13.04,2,1,13.66,15,1,13.03,100,1,13.69,15,1,13.02,100,1,13.7,100,1,12.73,100,1,13.72,100,1,12.71,100,1,13.97,100,1,12.5,700,1,14.01,2,1,12.46,200,2,14.28,100,1,12.43,700,1,14.4,100,1,12.42,700,1,14.56,800,2,12.37,700,1,14.58,100,1,ARL,323599605
,2025-07-17T16:00:49.744872763Z,2025-07-17T16:00:49.744872763Z,10,2,1108,A,A,1,13.67,100,130,165498,270146577,13.04,2,1,13.66,15,1,13.03,100,1,13.67,100,1,13.02,100,1,13.69,15,1,12.73,100,1,13.7,100,1,12.71,100,1,13.72,100,1,12.5,700,1,13.97,100,1,12.46,200,2,14.01,2,1,12.43,700,1,14.28,100,1,12.42,700,1,14.4,100,1,12.37,700,1,14.56,800,2,ARL,323730353
,2025-07-17T16:00:49.746256906Z,2025-07-17T16:00:49.746256906Z,10,2,1108,C,A,4,13.72,100,130,165236,270146586,13.04,2,1,13.66,15,1,13.03,100,1,13.67,100,1,13.02,100,1,13.69,15,1,12.73,100,1,13.7,100,1,12.71,100,1,13.97,100,1,12.5,700,1,14.01,2,1,12.46,200,2,14.28,100,1,12.43,700,1,14.4,100,1,12.42,700,1,14.56,800,2,12.37,700,1,14.58,100,1,ARL,323599609
,2025-07-17T16:00:51.624646272Z,2025-07-17T16:00:51.624646272Z,10,2,1108,A,A,8,14.54,100,130,165617,270181394,13.04,2,1,13.66,15,1,13.03,100,1,13.67,100,1,13.02,100,1,13.69,15,1,12.73,100,1,13.7,100,1,12.71,100,1,13.97,100,1,12.5,700,1,14.01,2,1,12.46,200,2,14.28,100,1,12.43,700,1,14.4,100,1,12.42,700,1,14.54,100,1,12.37,700,1,14.56,800,2,ARL,323775433
,2025-07-17T16:00:51.625206675Z,2025-07-17T16:00:51.625206675Z,10,2,1108,A,A,8,14.53,100,130,165841,270181399,13.04,2,1,13.66,15,1,13.03,100,1,13.67,100,1,13.02,100,1,13.69,15,1,12.73,100,1,13.7,100,1,12.71,100,1,13.97,100,1,12.5,700,1,14.01,2,1,12.46,200,2,14.28,100,1,12.43,700,1,14.4,100,1,12.42,700,1,14.53,100,1,12.37,700,1,14.54,100,1,ARL,323775457
,2025-07-17T16:00:53.749169565Z,2025-07-17T16:00:53.749169565Z,10,2,1108,A,A,1,13.67,100,130,165445,270204567,13.04,2,1,13.66,15,1,13.03,100,1,13.67,200,2,13.02,100,1,13.69,15,1,12.73,100,1,13.7,100,1,12.71,100,1,13.97,100,1,12.5,700,1,14.01,2,1,12.46,200,2,14.28,100,1,12.43,700,1,14.4,100,1,12.42,700,1,14.53,100,1,12.37,700,1,14.54,100,1,ARL,323803301
,2025-07-17T16:00:53.755801462Z,2025-07-17T16:00:53.755801462Z,10,2,1108,C,A,3,13.7,100,130,165218,270204616,13.04,2,1,13.66,15,1,13.03,100,1,13.67,200,2,13.02,100,1,13.69,15,1,12.73,100,1,13.97,100,1,12.71,100,1,14.01,2,1,12.5,700,1,14.28,100,1,12.46,200,2,14.4,100,1,12.43,700,1,14.53,100,1,12.42,700,1,14.54,100,1,12.37,700,1,14.56,800,2,ARL,323730309
,2025-07-17T16:01:00.801177403Z,2025-07-17T16:01:00.801177403Z,10,2,1108,C,A,2,13.69,15,130,165336,270319932,13.04,2,1,13.66,15,1,13.03,100,1,13.67,200,2,13.02,100,1,13.97,100,1,12.73,100,1,14.01,2,1,12.71,100,1,14.28,100,1,12.5,700,1,14.4,100,1,12.46,200,2,14.53,100,1,12.43,700,1,14.54,100,1,12.42,700,1,14.56,800,2,12.37,700,1,14.58,100,1,ARL,323455221
,2025-07-17T16:01:10.802712247Z,2025-07-17T16:01:10.802712247Z,10,2,1108,A,A,0,13.62,15,130,165323,270493149,13.04,2,1,13.62,15,1,13.03,100,1,13.66,15,1,13.02,100,1,13.67,200,2,12.73,100,1,13.97,100,1,12.71,100,1,14.01,2,1,12.5,700,1,14.28,100,1,12.46,200,2,14.4,100,1,12.43,700,1,14.53,100,1,12.42,700,1,14.54,100,1,12.37,700,1,14.56,800,2,ARL,324161541
,2025-07-17T16:01:11.418671671Z,2025-07-17T16:01:11.418671671Z,10,2,1108,A,A,1,13.65,100,130,165801,270503944,13.04,2,1,13.62,15,1,13.03,100,1,13.65,100,1,13.02,100,1,13.66,15,1,12.73,100,1,13.67,200,2,12.71,100,1,13.97,100,1,12.5,700,1,14.01,2,1,12.46,200,2,14.28,100,1,12.43,700,1,14.4,100,1,12.42,700,1,14.53,100,1,12.37,700,1,14.54,100,1,ARL,324175569
,2025-07-17T16:01:11.425757014Z,2025-07-17T16:01:11.425757014Z,10,2,1108,C,A,3,13.67,100,130,165170,270504009,13.04,2,1,13.62,15,1,13.03,100,1,13.65,100,1,13.02,100,1,13.66,15,1,12.73,100,1,13.67,100,1,12.71,100,1,13.97,100,1,12.5,700,1,14.01,2,1,12.46,200,2,14.28,100,1,12.43,700,1,14.4,100,1,12.42,700,1,14.53,100,1,12.37,700,1,14.54,100,1,ARL,323803301
,2025-07-17T16:01:11.820588141Z,2025-07-17T16:01:11.820588141Z,10,2,1108,C,A,3,13.67,100,0,165475,270509970,13.04,2,1,13.62,15,1,13.03,100,1,13.65,100,1,13.02,100,1,13.66,15,1,12.73,100,1,13.97,100,1,12.71,100,1,14.01,2,1,12.5,700,1,14.28,100,1,12.46,200,2,14.4,100,1,12.43,700,1,14.53,100,1,12.42,700,1,14.54,100,1,12.37,700,1,14.56,800,2,ARL,323730353
,2025-07-17T16:01:11.820588141Z,2025-07-17T16:01:11.820588141Z,10,2,1108,A,A,1,13.63,100,130,165475,270509970,13.04,2,1,13.62,15,1,13.03,100,1,13.63,100,1,13.02,100,1,13.65,100,1,12.73,100,1,13.66,15,1,12.71,100,1,13.97,100,1,12.5,700,1,14.01,2,1,12.46,200,2,14.28,100,1,12.43,700,1,14.4,100,1,12.42,700,1,14.53,100,1,12.37,700,1,14.54,100,1,ARL,324186213
,2025-07-17T16:01:11.826234488Z,2025-07-17T16:01:11.826234488Z,10,2,1108,C,A,4,13.97,100,130,165383,270510142,13.04,2,1,13.62,15,1,13.03,100,1,13.63,100,1,13.02,100,1,13.65,100,1,12.73,100,1,13.66,15,1,12.71,100,1,14.01,2,1,12.5,700,1,14.28,100,1,12.46,200,2,14.4,100,1,12.43,700,1,14.53,100,1,12.42,700,1,14.54,100,1,12.37,700,1,14.56,800,2,ARL,323599765
,2025-07-17T16:01:11.826286284Z,2025-07-17T16:01:11.826286284Z,10,2,1108,A,A,4,13.9,100,130,165163,270510143,13.04,2,1,13.62,15,1,13.03,100,1,13.63,100,1,13.02,100,1,13.65,100,1,12.73,100,1,13.66,15,1,12.71,100,1,13.9,100,1,12.5,700,1,14.01,2,1,12.46,200,2,14.28,100,1,12.43,700,1,14.4,100,1,12.42,700,1,14.53,100,1,12.37,700,1,14.54,100,1,ARL,324186721
,2025-07-17T16:01:11.828464891Z,2025-07-17T16:01:11.828464891Z,10,2,1108,A,A,8,14.43,100,130,165523,270510182,13.04,2,1,13.62,15,1,13.03,100,1,13.63,100,1,13.02,100,1,13.65,100,1,12.73,100,1,13.66,15,1,12.71,100,1,13.9,100,1,12.5,700,1,14.01,2,1,12.46,200,2,14.28,100,1,12.43,700,1,14.4,100,1,12.42,700,1,14.43,100,1,12.37,700,1,14.53,100,1,ARL,324186781
,2025-07-17T16:01:22.802353061Z,2025-07-17T16:01:22.802353061Z,10,2,1108,C,A,3,13.66,15,130,165475,270674903,13.04,2,1,13.62,15,1,13.03,100,1,13.63,100,1,13.02,100,1,13.65,100,1,12.73,100,1,13.9,100,1,12.71,100,1,14.01,2,1,12.5,700,1,14.28,100,1,12.46,200,2,14.4,100,1,12.43,700,1,14.43,100,1,12.42,700,1,14.53,100,1,12.37,700,1,14.54,100,1,ARL,323720189
,2025-07-17T16:01:32.803839043Z,2025-07-17T16:01:32.803839043Z,10,2,1108,A,A,0,13.6,15,130,165596,270824320,13.04,2,1,13.6,15,1,13.03,100,1,13.62,15,1,13.02,100,1,13.63,100,1,12.73,100,1,13.65,100,1,12.71,100,1,13.9,100,1,12.5,700,1,14.01,2,1,12.46,200,2,14.28,100,1,12.43,700,1,14.4,100,1,12.42,700,1,14.43,100,1,12.37,700,1,14.53,100,1,ARL,324619361
,2025-07-17T16:01:32.804108576Z,2025-07-17T16:01:32.804108576Z,10,2,1108,C,A,2,13.63,100,0,165592,270824323,13.04,2,1,13.6,15,1,13.03,100,1,13.62,15,1,13.02,100,1,13.65,100,1,12.73,100,1,13.9,100,1,12.71,100,1,14.01,2,1,12.5,700,1,14.28,100,1,12.46,200,2,14.4,100,1,12.43,700,1,14.43,100,1,12.42,700,1,14.53,100,1,12.37,700,1,14.54,100,1,ARL,324186213
,2025-07-17T16:01:32.804108576Z,2025-07-17T16:01:32.804108576Z,10,2,1108,A,A,1,13.61,100,130,165592,270824323,13.04,2,1,13.6,15,1,13.03,100,1,13.61,100,1,13.02,100,1,13.62,15,1,12.73,100,1,13.65,100,1,12.71,100,1,13.9,100,1,12.5,700,1,14.01,2,1,12.46,200,2,14.28,100,1,12.43,700,1,14.4,100,1,12.42,700,1,14.43,100,1,12.37,700,1,14.53,100,1,ARL,324619369
,2025-07-17T16:01:32.815748258Z,2025-07-17T16:01:32.815748258Z,10,2,1108,A,A,3,13.63,100,130,165262,270824657,13.04,2,1,13.6,15,1,13.03,100,1,13.61,100,1,13.02,100,1,13.62,15,1,12.73,100,1,13.63,100,1,12.71,100,1,13.65,100,1,12.5,700,1,13.9,100,1,12.46,200,2,14.01,2,1,12.43,700,1,14.28,100,1,12.42,700,1,14.4,100,1,12.37,700,1,14.43,100,1,ARL,324619837
,2025-07-17T16:01:32.822443626Z,2025-07-17T16:01:32.822443626Z,10,2,1108,C,A,4,13.65,100,130,165340,270824747,13.04,2,1,13.6,15,1,13.03,100,1,13.61,100,1,13.02,100,1,13.62,15,1,12.73,100,1,13.63,100,1,12.71,100,1,13.9,100,1,12.5,700,1,14.01,2,1,12.46,200,2,14.28,100,1,12.43,700,1,14.4,100,1,12.42,700,1,14.43,100,1,12.37,700,1,14.53,100,1,ARL,324175569
,2025-07-17T16:01:37.242525208Z,2025-07-17T16:01:37.242525208Z,10,2,1108,C,A,2,13.62,15,130,165212,270889017,13.04,2,1,13.6,15,1,13.03,100,1,13.61,100,1,13.02,100,1,13.63,100,1,12.73,100,1,13.9,100,1,12.71,100,1,14.01,2,1,12.5,700,1,14.28,100,1,12.46,200,2,14.4,100,1,12.43,700,1,14.43,100,1,12.42,700,1,14.53,100,1,12.37,700,1,14.54,100,1,ARL,324161541
,2025-07-17T16:01:40.605632399Z,2025-07-17T16:01:40.605632399Z,10,2,1108,A,A,1,13.61,100,130,165366,270946497,13.04,2,1,13.6,15,1,13.03,100,1,13.61,200,2,13.02,100,1,13.63,100,1,12.73,100,1,13.9,100,1,12.71,100,1,14.01,2,1,12.5,700,1,14.28,100,1,12.46,200,2,14.4,100,1,12.43,700,1,14.43,100,1,12.42,700,1,14.53,100,1,12.37,700,1,14.54,100,1,ARL,324782841
,2025-07-17T16:01:40.653572805Z,2025-07-17T16:01:40.653572805Z,10,2,1108,C,A,2,13.63,100,130,165371,270946779,13.04,2,1,13.6,15,1,13.03,100,1,13.61,200,2,13.02,100,1,13.9,100,1,12.73,100,1,14.01,2,1,12.71,100,1,14.28,100,1,12.5,700,1,14.4,100,1,12.46,200,2,14.43,100,1,12.43,700,1,14.53,100,1,12.42,700,1,14.54,100,1,12.37,700,1,14.56,800,2,ARL,324619837
,2025-07-17T16:01:47.565825466Z,2025-07-17T16:01:47.565825466Z,10,2,1108,A,A,0,13.57,15,128,166218,271062350,13.04,2,1,13.57,15,1,13.03,100,1,13.6,15,1,13.02,100,1,13.61,200,2,12.73,100,1,13.9,100,1,12.71,100,1,14.01,2,1,12.5,700,1,14.28,100,1,12.46,200,2,14.4,100,1,12.43,700,1,14.43,100,1,12.42,700,1,14.53,100,1,12.37,700,1,14.54,100,1,ARL,324934601
,2025-07-17T16:01:47.902804446Z,2025-07-17T16:01:47.902804446Z,10,2,1108,C,A,2,13.61,100,0,165327,271068098,13.04,2,1,13.57,15,1,13.03,100,1,13.6,15,1,13.02,100,1,13.61,100,1,12.73,100,1,13.9,100,1,12.71,100,1,14.01,2,1,12.5,700,1,14.28,100,1,12.46,200,2,14.4,100,1,12.43,700,1,14.43,100,1,12.42,700,1,14.53,100,1,12.37,700,1,14.54,100,1,ARL,324619369
,2025-07-17T16:01:47.902804446Z,2025-07-17T16:01:47.902804446Z,10,2,1108,A,A,1,13.58,100,130,165327,271068098,13.04,2,1,13.57,15,1,13.03,100,1,13.58,100,1,13.02,100,1,13.6,15,1,12.73,100,1,13.61,100,1,12.71,100,1,13.9,100,1,12.5,700,1,14.01,2,1,12.46,200,2,14.28,100,1,12.43,700,1,14.4,100,1,12.42,700,1,14.43,100,1,12.37,700,1,14.53,100,1,ARL,324942229
,2025-07-17T16:01:47.903546622Z,2025-07-17T16:01:47.903546622Z,10,2,1108,C,A,7,14.4,100,130,165135,271068105,13.04,2,1,13.57,15,1,13.03,100,1,13.58,100,1,13.02,100,1,13.6,15,1,12.73,100,1,13.61,100,1,12.71,100,1,13.9,100,1,12.5,700,1,14.01,2,1,12.46,200,2,14.28,100,1,12.43,700,1,14.43,100,1,12.42,700,1,14.53,100,1,12.37,700,1,14.54,100,1,ARL,289726421
,2025-07-17T16:01:47.903902473Z,2025-07-17T16:01:47.903902473Z,10,2,1108,A,A,6,14.19,100,130,165213,271068115,13.04,2,1,13.57,15,1,13.03,100,1,13.58,100,1,13.02,100,1,13.6,15,1,12.73,100,1,13.61,100,1,12.71,100,1,13.9,100,1,12.5,700,1,14.01,2,1,12.46,200,2,14.19,100,1,12.43,700,1,14.28,100,1,12.42,700,1,14.43,100,1,12.37,700,1,14.53,100,1,ARL,324942273
,2025-07-17T16:01:50.798934838Z,2025-07-17T16:01:50.798934838Z,10,2,1108,A,A,2,13.59,100,130,165666,271131418,13.04,2,1,13.57,15,1,13.03,100,1,13.58,100,1,13.02,100,1,13.59,100,1,12.73,100,1,13.6,15,1,12.71,100,1,13.61,100,1,12.5,700,1,13.9,100,1,12.46,200,2,14.01,2,1,12.43,700,1,14.19,100,1,12.42,700,1,14.28,100,1,12.37,700,1,14.43,100,1,ARL,325022101
,2025-07-17T16:01:50.805488726Z,2025-07-17T16:01:50.805488726Z,10,2,1108,C,A,4,13.61,100,130,165235,271131583,13.04,2,1,13.57,15,1,13.03,100,1,13.58,100,1,13.02,100,1,13.59,100,1,12.73,100,1,13.6,15,1,12.71,100,1,13.9,100,1,12.5,700,1,14.01,2,1,12.46,200,2,14.19,100,1,12.43,700,1,14.28,100,1,12.42,700,1,14.43,100,1,12.37,700,1,14.53,100,1,ARL,324782841
,2025-07-17T16:01:52.132898568Z,2025-07-17T16:01:52.132898568Z,10,2,1108,C,A,3,13.6,15,130,165193,271153294,13.04,2,1,13.57,15,1,13.03,100,1,13.58,100,1,13.02,100,1,13.59,100,1,12.73,100,1,13.9,100,1,12.71,100,1,14.01,2,1,12.5,700,1,14.19,100,1,12.46,200,2,14.28,100,1,12.43,700,1,14.43,100,1,12.42,700,1,14.53,100,1,12.37,700,1,14.54,100,1,ARL,324619361
,2025-07-17T16:01:53.137336077Z,2025-07-17T16:01:53.137336077Z,10,2,1108,A,A,0,13.55,15,130,165885,271200452,13.04,2,1,13.55,15,1,13.03,100,1,13.57,15,1,13.02,100,1,13.58,100,1,12.73,100,1,13.59,100,1,12.71,100,1,13.9,100,1,12.5,700,1,14.01,2,1,12.46,200,2,14.19,100,1,12.43,700,1,14.28,100,1,12.42,700,1,14.43,100,1,12.37,700,1,14.53,100,1,ARL,325109165
,2025-07-17T16:01:56.263988198Z,2025-07-17T16:01:56.263988198Z,10,2,1108,C,A,2,13.58,100,0,165897,271251019,13.04,2,1,13.55,15,1,13.03,100,1,13.57,15,1,13.02,100,1,13.59,100,1,12.73,100,1,13.9,100,1,12.71,100,1,14.01,2,1,12.5,700,1,14.19,100,1,12.46,200,2,14.28,100,1,12.43,700,1,14.43,100,1,12.42,700,1,14.53,100,1,12.37,700,1,14.54,100,1,ARL,324942229
,2025-07-17T16:01:56.263988198Z,2025-07-17T16:01:56.263988198Z,10,2,1108,A,A,1,13.56,100,130,165897,271251019,13.04,2,1,13.55,15,1,13.03,100,1,13.56,100,1,13.02,100,1,13.57,15,1,12.73,100,1,13.59,100,1,12.71,100,1,13.9,100,1,12.5,700,1,14.01,2,1,12.46,200,2,14.19,100,1,12.43,700,1,14.28,100,1,12.42,700,1,14.43,100,1,12.37,700,1,14.53,100,1,ARL,325176181
,2025-07-17T16:01:56.269458197Z,2025-07-17T16:01:56.269458197Z,10,2,1108,C,A,4,13.9,100,130,165591,271251357,13.04,2,1,13.55,15,1,13.03,100,1,13.56,100,1,13.02,100,1,13.57,15,1,12.73,100,1,13.59,100,1,12.71,100,1,14.01,2,1,12.5,700,1,14.19,100,1,12.46,200,2,14.28,100,1,12.43,700,1,14.43,100,1,12.42,700,1,14.53,100,1,12.37,700,1,14.54,100,1,ARL,324186721
,2025-07-17T16:01:56.269508928Z,2025-07-17T16:01:56.269508928Z,10,2,1108,A,A,4,13.83,100,130,165304,271251358,13.04,2,1,13.55,15,1,13.03,100,1,13.56,100,1,13.02,100,1,13.57,15,1,12.73,100,1,13.59,100,1,12.71,100,1,13.83,100,1,12.5,700,1,14.01,2,1,12.46,200,2,14.19,100,1,12.43,700,1,14.28,100,1,12.42,700,1,14.43,100,1,12.37,700,1,14.53,100,1,ARL,325176373
,2025-07-17T16:01:56.300723805Z,2025-07-17T16:01:56.300723805Z,10,2,1108,A,A,9,14.51,100,130,165573,271252044,13.04,2,1,13.55,15,1,13.03,100,1,13.56,100,1,13.02,100,1,13.57,15,1,12.73,100,1,13.59,100,1,12.71,100,1,13.83,100,1,12.5,700,1,14.01,2,1,12.46,200,2,14.19,100,1,12.43,700,1,14.28,100,1,12.42,700,1,14.43,100,1,12.37,700,1,14.51,100,1,ARL,325177757
,2025-07-17T16:01:56.776814001Z,2025-07-17T16:01:56.776814001Z,10,2,1108,T,N,0,13.41,16,130,166243,271255700,13.04,2,1,13.55,15,1,13.03,100,1,13.56,100,1,13.02,100,1,13.57,15,1,12.73,100,1,13.59,100,1,12.71,100,1,13.83,100,1,12.5,700,1,14.01,2,1,12.46,200,2,14.19,100,1,12.43,700,1,14.28,100,1,12.42,700,1,14.43,100,1,12.37,700,1,14.51,100,1,ARL,0
,2025-07-17T16:01:56.777248616Z,2025-07-17T16:01:56.777248616Z,10,2,1108,T,N,0,13.41,16,130,165716,271255708,13.04,2,1,13.55,15,1,13.03,100,1,13.56,100,1,13.02,100,1,13.57,15,1,12.73,100,1,13.59,100,1,12.71,100,1,13.83,100,1,12.5,700,1,14.01,2,1,12.46,200,2,14.19,100,1,12.43,700,1,14.28,100,1,12.42,700,1,14.43,100,1,12.37,700,1,14.51,100,1,ARL,0
,2025-07-17T16:01:56.777739254Z,2025-07-17T16:01:56.777739254Z,10,2,1108,T,N,0,13.41,4,130,166815,271255712,13.04,2,1,13.55,15,1,13.03,100,1,13.56,100,1,13.02,100,1,13.57,15,1,12.73,100,1,13.59,100,1,12.71,100,1,13.83,100,1,12.5,700,1,14.01,2,1,12.46,200,2,14.19,100,1,12.43,700,1,14.28,100,1,12.42,700,1,14.43,100,1,12.37,700,1,14.51,100,1,ARL,0
,2025-07-17T16:02:01.992379223Z,2025-07-17T16:02:01.992379223Z,10,2,1108,C,A,5,14.01,2,0,165384,271343251,13.04,2,1,13.55,15,1,13.03,100,1,13.56,100,1,13.02,100,1,13.57,15,1,12.73,100,1,13.59,100,1,12.71,100,1,13.83,100,1,12.5,700,1,14.19,100,1,12.46,200,2,14.28,100,1,12.43,700,1,14.43,100,1,12.42,700,1,14.51,100,1,12.37,700,1,14.53,100,1,ARL,322898193
,2025-07-17T16:02:01.992379223Z,2025-07-17T16:02:01.992379223Z,10,2,1108,A,A,5,13.92,2,130,165384,271343251,13.04,2,1,13.55,15,1,13.03,100,1,13.56,100,1,13.02,100,1,13.57,15,1,12.73,100,1,13.59,100,1,12.71,100,1,13.83,100,1,12.5,700,1,13.92,2,1,12.46,200,2,14.19,100,1,12.43,700,1,14.28,100,1,12.42,700,1,14.43,100,1,12.37,700,1,14.51,100,1,ARL,325297093
,2025-07-17T16:02:03.207555626Z,2025-07-17T16:02:03.207555626Z,10,2,1108,C,A,2,13.57,15,130,165200,271367066,13.04,2,1,13.55,15,1,13.03,100,1,13.56,100,1,13.02,100,1,13.59,100,1,12.73,100,1,13.83,100,1,12.71,100,1,13.92,2,1,12.5,700,1,14.19,100,1,12.46,200,2,14.28,100,1,12.43,700,1,14.43,100,1,12.42,700,1,14.51,100,1,12.37,700,1,14.53,100,1,ARL,324934601
,2025-07-17T16:02:04.212791108Z,2025-07-17T16:02:04.212791108Z,10,2,1108,A,A,0,13.53,15,130,165231,271415821,13.04,2,1,13.53,15,1,13.03,100,1,13.55,15,1,13.02,100,1,13.56,100,1,12.73,100,1,13.59,100,1,12.71,100,1,13.83,100,1,12.5,700,1,13.92,2,1,12.46,200,2,14.19,100,1,12.43,700,1,14.28,100,1,12.42,700,1,14.43,100,1,12.37,700,1,14.51,100,1,ARL,325382429
,2025-07-17T16:02:04.214183279Z,2025-07-17T16:02:04.214183279Z,10,2,1108,A,A,8,14.43,100,130,165535,271415834,13.04,2,1,13.53,15,1,13.03,100,1,13.55,15,1,13.02,100,1,13.56,100,1,12.73,100,1,13.59,100,1,12.71,100,1,13.83,100,1,12.5,700,1,13.92,2,1,12.46,200,2,14.19,100,1,12.43,700,1,14.28,100,1,12.42,700,1,14.43,200,2,12.37,700,1,14.51,100,1,ARL,325382437
,2025-07-17T16:02:04.839967173Z,2025-07-17T16:02:04.839967173Z,10,2,1108,C,A,2,13.56,100,0,165495,271432190,13.04,2,1,13.53,15,1,13.03,100,1,13.55,15,1,13.02,100,1,13.59,100,1,12.73,100,1,13.83,100,1,12.71,100,1,13.92,2,1,12.5,700,1,14.19,100,1,12.46,200,2,14.28,100,1,12.43,700,1,14.43,200,2,12.42,700,1,14.51,100,1,12.37,700,1,14.53,100,1,ARL,325176181
,2025-07-17T16:02:04.839967173Z,2025-07-17T16:02:04.839967173Z,10,2,1108,A,A,1,13.54,100,130,165495,271432190,13.04,2,1,13.53,15,1,13.03,100,1,13.54,100,1,13.02,100,1,13.55,15,1,12.73,100,1,13.59,100,1,12.71,100,1,13.83,100,1,12.5,700,1,13.92,2,1,12.46,200,2,14.19,100,1,12.43,700,1,14.28,100,1,12.42,700,1,14.43,200,2,12.37,700,1,14.51,100,1,ARL,325400045
,2025-07-17T16:02:04.840006082Z,2025-07-17T16:02:04.840006082Z,10,2,1108,A,A,7,14.27,700,130,165158,271432192,13.04,2,1,13.53,15,1,13.03,100,1,13.54,100,1,13.02,100,1,13.55,15,1,12.73,100,1,13.59,100,1,12.71,100,1,13.83,100,1,12.5,700,1,13.92,2,1,12.46,200,2,14.19,100,1,12.43,700,1,14.27,700,1,12.42,700,1,14.28,100,1,12.37,700,1,14.43,200,2,ARL,325400053
,2025-07-17T16:02:11.249125653Z,2025-07-17T16:02:11.249125653Z,10,2,1108,A,A,9,14.42,100,130,165489,271526467,13.04,2,1,13.53,15,1,13.03,100,1,13.54,100,1,13.02,100,1,13.55,15,1,12.73,100,1,13.59,100,1,12.71,100,1,13.83,100,1,12.5,700,1,13.92,2,1,12.46,200,2,14.19,100,1,12.43,700,1,14.27,700,1,12.42,700,1,14.28,100,1,12.37,700,1,14.42,100,1,ARL,325520705
,2025-07-17T16:02:15.062605521Z,2025-07-17T16:02:15.062605521Z,10,2,1108,C,A,0,13.53,15,128,169140,271576282,13.04,2,1,13.54,100,1,13.03,100,1,13.55,15,1,13.02,100,1,13.59,100,1,12.73,100,1,13.83,100,1,12.71,100,1,13.92,2,1,12.5,700,1,14.19,100,1,12.46,200,2,14.27,700,1,12.43,700,1,14.28,100,1,12.42,700,1,14.42,100,1,12.37,700,1,14.43,200,2,ARL,325382429
,2025-07-17T16:02:15.068283706Z,2025-07-17T16:02:15.068283706Z,10,2,1108,C,A,1,13.55,15,130,165342,271577104,13.04,2,1,13.54,100,1,13.03,100,1,13.59,100,1,13.02,100,1,13.83,100,1,12.73,100,1,13.92,2,1,12.71,100,1,14.19,100,1,12.5,700,1,14.27,700,1,12.46,200,2,14.28,100,1,12.43,700,1,14.42,100,1,12.42,700,1,14.43,200,2,12.37,700,1,14.51,100,1,ARL,325109165
,2025-07-17T16:02:20.634863301Z,2025-07-17T16:02:20.634863301Z,10,2,1108,C,A,0,13.54,100,130,165188,271675842,13.04,2,1,13.59,100,1,13.03,100,1,13.83,100,1,13.02,100,1,13.92,2,1,12.73,100,1,14.19,100,1,12.71,100,1,14.27,700,1,12.5,700,1,14.28,100,1,12.46,200,2,14.42,100,1,12.43,700,1,14.43,200,2,12.42,700,1,14.51,100,1,12.37,700,1,14.56,800,2,ARL,325400045
,2025-07-17T16:02:20.650301212Z,2025-07-17T16:02:20.650301212Z,10,2,1108,C,A,0,13.59,100,130,165539,271676032,13.04,2,1,13.83,100,1,13.03,100,1,13.92,2,1,13.02,100,1,14.19,100,1,12.73,100,1,14.27,700,1,12.71,100,1,14.28,100,1,12.5,700,1,14.42,100,1,12.46,200,2,14.43,200,2,12.43,700,1,14.51,100,1,12.42,700,1,14.56,800,2,12.37,700,1,14.57,100,1,ARL,325022101
,2025-07-17T16:02:20.650335946Z,2025-07-17T16:02:20.650335946Z,10,2,1108,C,A,3,14.27,700,130,165502,271676033,13.04,2,1,13.83,100,1,13.03,100,1,13.92,2,1,13.02,100,1,14.19,100,1,12.73,100,1,14.28,100,1,12.71,100,1,14.42,100,1,12.5,700,1,14.43,200,2,12.46,200,2,14.51,100,1,12.43,700,1,14.56,800,2,12.42,700,1,14.57,100,1,12.37,700,1,14.6,700,1,ARL,325400053
,2025-07-17T16:02:20.650381040Z,2025-07-17T16:02:20.650381040Z,10,2,1108,A,A,7,14.53,700,130,165443,271676035,13.04,2,1,13.83,100,1,13.03,100,1,13.92,2,1,13.02,100,1,14.19,100,1,12.73,100,1,14.28,100,1,12.71,100,1,14.42,100,1,12.5,700,1,14.43,200,2,12.46,200,2,14.51,100,1,12.43,700,1,14.53,700,1,12.42,700,1,14.56,800,2,12.37,700,1,14.57,100,1,ARL,325714545
,2025-07-17T16:02:20.651020858Z,2025-07-17T16:02:20.651020858Z,10,2,1108,C,A,4,14.42,100,0,165679,271676048,13.04,2,1,13.83,100,1,13.03,100,1,13.92,2,1,13.02,100,1,14.19,100,1,12.73,100,1,14.28,100,1,12.71,100,1,14.43,200,2,12.5,700,1,14.51,100,1,12.46,200,2,14.53,700,1,12.43,700,1,14.56,800,2,12.42,700,1,14.57,100,1,12.37,700,1,14.6,700,1,ARL,325520705
,2025-07-17T16:02:20.651035000Z,2025-07-17T16:02:20.651035000Z,10,2,1108,C,A,2,14.19,100,130,166182,271676049,13.04,2,1,13.83,100,1,13.03,100,1,13.92,2,1,13.02,100,1,14.28,100,1,12.73,100,1,14.43,200,2,12.71,100,1,14.51,100,1,12.5,700,1,14.53,700,1,12.46,200,2,14.56,800,2,12.43,700,1,14.57,100,1,12.42,700,1,14.6,700,1,12.37,700,1,14.64,100,1,ARL,324942273
,2025-07-17T16:02:20.651393708Z,2025-07-17T16:02:20.651393708Z,10,2,1108,A,A,4,14.45,100,130,165240,271676057,13.04,2,1,13.83,100,1,13.03,100,1,13.92,2,1,13.02,100,1,14.28,100,1,12.73,100,1,14.43,200,2,12.71,100,1,14.45,100,1,12.5,700,1,14.51,100,1,12.46,200,2,14.53,700,1,12.43,700,1,14.56,800,2,12.42,700,1,14.57,100,1,12.37,700,1,14.6,700,1,ARL,325714601
,2025-07-17T16:02:20.651618897Z,2025-07-17T16:02:20.651618897Z,10,2,1108,C,A,3,14.43,100,0,168916,271676089,13.04,2,1,13.83,100,1,13.03,100,1,13.92,2,1,13.02,100,1,14.28,100,1,12.73,100,1,14.43,100,1,12.71,100,1,14.45,100,1,12.5,700,1,14.51,100,1,12.46,200,2,14.53,700,1,12.43,700,1,14.56,800,2,12.42,700,1,14.57,100,1,12.37,700,1,14.6,700,1,ARL,325382437
,2025-07-17T16:02:20.651854531Z,2025-07-17T16:02:20.651854531Z,10,2,1108,C,A,8,14.57,100,0,167087,271676104,13.04,2,1,13.83,100,1,13.03,100,1,13.92,2,1,13.02,100,1,14.28,100,1,12.73,100,1,14.43,100,1,12.71,100,1,14.45,100,1,12.5,700,1,14.51,100,1,12.46,200,2,14.53,700,1,12.43,700,1,14.56,800,2,12.42,700,1,14.6,700,1,12.37,700,1,14.64,100,1,ARL,324619409
,2025-07-17T16:02:20.651932129Z,2025-07-17T16:02:20.651932129Z,10,2,1108,C,A,3,14.43,100,130,165159,271676110,13.04,2,1,13.83,100,1,13.03,100,1,13.92,2,1,13.02,100,1,14.28,100,1,12.73,100,1,14.45,100,1,12.71,100,1,14.51,100,1,12.5,700,1,14.53,700,1,12.46,200,2,14.56,800,2,12.43,700,1,14.6,700,1,12.42,700,1,14.64,100,1,12.37,700,1,14.68,700,1,ARL,324186781
,2025-07-17T16:02:20.652094426Z,2025-07-17T16:02:20.652094426Z,10,2,1108,A,A,8,14.63,100,130,165505,271676118,13.04,2,1,13.83,100,1,13.03,100,1,13.92,2,1,13.02,100,1,14.28,100,1,12.73,100,1,14.45,100,1,12.71,100,1,14.51,100,1,12.5,700,1,14.53,700,1,12.46,200,2,14.56,800,2,12.43,700,1,14.6,700,1,12.42,700,1,14.63,100,1,12.37,700,1,14.64,100,1,ARL,325714653
,2025-07-17T16:02:20.653460814Z,2025-07-17T16:02:20.653460814Z,10,2,1108,A,B,0,13.27,10,130,165577,271676147,13.27,10,1,13.83,100,1,13.04,2,1,13.92,2,1,13.03,100,1,14.28,100,1,13.02,100,1,14.45,100,1,12.73,100,1,14.51,100,1,12.71,100,1,14.53,700,1,12.5,700,1,14.56,800,2,12.46,200,2,14.6,700,1,12.43,700,1,14.63,100,1,12.42,700,1,14.64,100,1,ARL,325714717
,2025-07-17T16:02:20.653461966Z,2025-07-17T16:02:20.653461966Z,10,2,1108,A,A,0,13.83,15,130,165266,271676148,13.27,10,1,13.83,115,2,13.04,2,1,13.92,2,1,13.03,100,1,14.28,100,1,13.02,100,1,14.45,100,1,12.73,100,1,14.51,100,1,12.71,100,1,14.53,700,1,12.5,700,1,14.56,800,2,12.46,200,2,14.6,700,1,12.43,700,1,14.63,100,1,12.42,700,1,14.64,100,1,ARL,325714721
,2025-07-17T16:02:20.653721185Z,2025-07-17T16:02:20.653721185Z,10,2,1108,C,B,3,13.02,100,0,165711,271676153,13.27,10,1,13.83,115,2,13.04,2,1,13.92,2,1,13.03,100,1,14.28,100,1,12.73,100,1,14.45,100,1,12.71,100,1,14.51,100,1,12.5,700,1,14.53,700,1,12.46,200,2,14.56,800,2,12.43,700,1,14.6,700,1,12.42,700,1,14.63,100,1,12.37,700,1,14.64,100,1,ARL,320485385
,2025-07-17T16:02:20.653721185Z,2025-07-17T16:02:20.653721185Z,10,2,1108,A,B,1,13.26,100,130,165711,271676153,13.27,10,1,13.83,115,2,13.26,100,1,13.92,2,1,13.04,2,1,14.28,100,1,13.03,100,1,14.45,100,1,12.73,100,1,14.51,100,1,12.71,100,1,14.53,700,1,12.5,700,1,14.56,800,2,12.46,200,2,14.6,700,1,12.43,700,1,14.63,100,1,12.42,700,1,14.64,100,1,ARL,325714729
,2025-07-17T16:02:20.655111649Z,2025-07-17T16:02:20.655111649Z,10,2,1108,C,B,2,13.04,2,0,165417,271676165,13.27,10,1,13.83,115,2,13.26,100,1,13.92,2,1,13.03,100,1,14.28,100,1,12.73,100,1,14.45,100,1,12.71,100,1,14.51,100,1,12.5,700,1,14.53,700,1,12.46,200,2,14.56,800,2,12.43,700,1,14.6,700,1,12.42,700,1,14.63,100,1,12.37,700,1,14.64,100,1,ARL,293594281
,2025-07-17T16:02:20.655111649Z,2025-07-17T16:02:20.655111649Z,10,2,1108,A,B,3,12.91,2,130,165417,271676165,13.27,10,1,13.83,115,2,13.26,100,1,13.92,2,1,13.03,100,1,14.28,100,1,12.91,2,1,14.45,100,1,12.73,100,1,14.51,100,1,12.71,100,1,14.53,700,1,12.5,700,1,14.56,800,2,12.46,200,2,14.6,700,1,12.43,700,1,14.63,100,1,12.42,700,1,14.64,100,1,ARL,325714741
,2025-07-17T16:02:20.663209235Z,2025-07-17T16:02:20.663209235Z,10,2,1108,C,A,0,13.83,100,130,165341,271676274,13.27,10,1,13.83,15,1,13.26,100,1,13.92,2,1,13.03,100,1,14.28,100,1,12.91,2,1,14.45,100,1,12.73,100,1,14.51,100,1,12.71,100,1,14.53,700,1,12.5,700,1,14.56,800,2,12.46,200,2,14.6,700,1,12.43,700,1,14.63,100,1,12.42,700,1,14.64,100,1,ARL,325176373
