,ts_recv,ts_event,rtype,publisher_id,instrument_id,action,side,depth,price,size,flags,ts_in_delta,sequence,bid_px_00,bid_sz_00,bid_ct_00,ask_px_00,ask_sz_00,ask_ct_00,bid_px_01,bid_sz_01,bid_ct_01,ask_px_01,ask_sz_01,ask_ct_01,bid_px_02,bid_sz_02,bid_ct_02,ask_px_02,ask_sz_02,ask_ct_02,bid_px_03,bid_sz_03,bid_ct_03,ask_px_03,ask_sz_03,ask_ct_03,bid_px_04,bid_sz_04,bid_ct_04,ask_px_04,ask_sz_04,ask_ct_04,bid_px_05,bid_sz_05,bid_ct_05,ask_px_05,ask_sz_05,ask_ct_05,bid_px_06,bid_sz_06,bid_ct_06,ask_px_06,ask_sz_06,ask_ct_06,bid_px_07,bid_sz_07,bid_ct_07,ask_px_07,ask_sz_07,ask_ct_07,bid_px_08,bid_sz_08,bid_ct_08,ask_px_08,ask_sz_08,ask_ct_08,bid_px_09,bid_sz_09,bid_ct_09,ask_px_09,ask_sz_09,ask_ct_09,symbol,order_id
0,2025-07-17T07:05:09.035627674Z,2025-07-17T07:05:09.035627674Z,10,2,1108,R,N,0,,0,8,0,0,,0,0,,0,0,,0,0,,0,0,,0,0,,0,0,,0,0,,0,0,,0,0,,0,0,,0,0,,0,0,,0,0,,0,0,,0,0,,0,0,,0,0,,0,0,,0,0,,0,0,ARL,0
1,2025-07-17T08:05:03.360677248Z,2025-07-17T08:05:03.360677248Z,10,2,1108,A,B,0,5.51,100,130,165200,851012,5.51,100,1,,0,0,,0,0,,0,0,,0,0,,0,0,,0,0,,0,0,,0,0,,0,0,,0,0,,0,0,,0,0,,0,0,,0,0,,0,0,,0,0,,0,0,,0,0,,0,0,ARL,817593
2,2025-07-17T08:05:03.360683462Z,2025-07-17T08:05:03.360683462Z,10,2,1108,A,A,0,21.33,100,130,165331,851013,5.51,100,1,21.33,100,1,,0,0,,0,0,,0,0,,0,0,,0,0,,0,0,,0,0,,0,0,,0,0,,0,0,,0,0,,0,0,,0,0,,0,0,,0,0,,0,0,,0,0,,0,0,ARL,817597
3,2025-07-17T08:05:03.361327319Z,2025-07-17T08:05:03.361327319Z,10,2,1108,A,B,0,5.9,100,130,165198,851022,5.9,100,1,21.33,100,1,5.51,100,1,,0,0,,0,0,,0,0,,0,0,,0,0,,0,0,,0,0,,0,0,,0,0,,0,0,,0,0,,0,0,,0,0,,0,0,,0,0,,0,0,,0,0,ARL,817633
4,2025-07-17T08:05:03.361332576Z,2025-07-17T08:05:03.361332576Z,10,2,1108,A,A,0,20.94,100,130,165247,851023,5.9,100,1,20.94,100,1,5.51,100,1,21.33,100,1,,0,0,,0,0,,0,0,,0,0,,0,0,,0,0,,0,0,,0,0,,0,0,,0,0,,0,0,,0,0,,0,0,,0,0,,0,0,,0,0,ARL,817637
5,2025-07-17T08:09:48.860696464Z,2025-07-17T08:09:48.860696464Z,10,2,1108,C,B,1,5.51,100,130,165631,1289631,5.9,100,1,20.94,100,1,,0,0,21.33,100,1,,0,0,,0,0,,0,0,,0,0,,0,0,,0,0,,0,0,,0,0,,0,0,,0,0,,0,0,,0,0,,0,0,,0,0,,0,0,,0,0,ARL,817593
6,2025-07-17T08:09:48.860705588Z,2025-07-17T08:09:48.860705588Z,10,2,1108,A,B,1,5.37,100,130,165297,1289632,5.9,100,1,20.94,100,1,5.37,100,1,21.33,100,1,,0,0,,0,0,,0,0,,0,0,,0,0,,0,0,,0,0,,0,0,,0,0,,0,0,,0,0,,0,0,,0,0,,0,0,,0,0,,0,0,ARL,1263973
7,2025-07-17T08:09:49.157896784Z,2025-07-17T08:09:49.157896784Z,10,2,1108,C,B,0,5.9,100,130,165115,1290626,5.37,100,1,20.94,100,1,,0,0,21.33,100,1,,0,0,,0,0,,0,0,,0,0,,0,0,,0,0,,0,0,,0,0,,0,0,,0,0,,0,0,,0,0,,0,0,,0,0,,0,0,,0,0,ARL,817633
8,2025-07-17T08:09:49.157903443Z,2025-07-17T08:09:49.157903443Z,10,2,1108,A,B,0,5.4,100,0,166009,1290627,5.4,100,1,20.94,100,1,5.37,100,1,21.33,100,1,,0,0,,0,0,,0,0,,0,0,,0,0,,0,0,,0,0,,0,0,,0,0,,0,0,,0,0,,0,0,,0,0,,0,0,,0,0,,0,0,ARL,1264721
9,2025-07-17T08:09:49.157903798Z,2025-07-17T08:09:49.157903798Z,10,2,1108,C,A,0,20.94,100,130,165654,1290628,5.4,100,1,21.33,100,1,5.37,100,1,,0,0,,0,0,,0,0,,0,0,,0,0,,0,0,,0,0,,0,0,,0,0,,0,0,,0,0,,0,0,,0,0,,0,0,,0,0,,0,0,,0,0,ARL,817637
10,2025-07-17T08:09:49.157909054Z,2025-07-17T08:09:49.157909054Z,10,2,1108,A,A,1,21.47,100,130,165545,1290629,5.4,100,1,21.33,100,1,5.37,100,1,21.47,100,1,,0,0,,0,0,,0,0,,0,0,,0,0,,0,0,,0,0,,0,0,,0,0,,0,0,,0,0,,0,0,,0,0,,0,0,,0,0,,0,0,ARL,1264725
11,2025-07-17T11:00:00.125174985Z,2025-07-17T11:00:00.125174985Z,10,2,1108,C,B,1,5.37,100,130,165929,10583317,5.4,100,1,21.33,100,1,,0,0,21.47,100,1,,0,0,,0,0,,0,0,,0,0,,0,0,,0,0,,0,0,,0,0,,0,0,,0,0,,0,0,,0,0,,0,0,,0,0,,0,0,,0,0,ARL,1263973
12,2025-07-17T11:00:00.125182048Z,2025-07-17T11:00:00.125182048Z,10,2,1108,A,B,0,9.79,100,130,165199,10583320,9.79,100,1,21.33,100,1,5.4,100,1,21.47,100,1,,0,0,,0,0,,0,0,,0,0,,0,0,,0,0,,0,0,,0,0,,0,0,,0,0,,0,0,,0,0,,0,0,,0,0,,0,0,,0,0,ARL,12852457
13,2025-07-17T11:00:00.125454029Z,2025-07-17T11:00:00.125454029Z,10,2,1108,C,B,1,5.4,100,130,165713,10583363,9.79,100,1,21.33,100,1,,0,0,21.47,100,1,,0,0,,0,0,,0,0,,0,0,,0,0,,0,0,,0,0,,0,0,,0,0,,0,0,,0,0,,0,0,,0,0,,0,0,,0,0,,0,0,ARL,1264721
14,2025-07-17T11:00:00.125460962Z,2025-07-17T11:00:00.125460962Z,10,2,1108,A,B,0,9.84,100,130,165088,10583364,9.84,100,1,21.33,100,1,9.79,100,1,21.47,100,1,,0,0,,0,0,,0,0,,0,0,,0,0,,0,0,,0,0,,0,0,,0,0,,0,0,,0,0,,0,0,,0,0,,0,0,,0,0,,0,0,ARL,12852537
15,2025-07-17T11:00:07.975824831Z,2025-07-17T11:00:07.975824831Z,10,2,1108,C,A,0,21.33,100,130,165390,10674471,9.84,100,1,21.47,100,1,9.79,100,1,,0,0,,0,0,,0,0,,0,0,,0,0,,0,0,,0,0,,0,0,,0,0,,0,0,,0,0,,0,0,,0,0,,0,0,,0,0,,0,0,,0,0,ARL,817597
16,2025-07-17T11:00:07.975837956Z,2025-07-17T11:00:07.975837956Z,10,2,1108,A,A,0,17.44,100,130,165427,10674472,9.84,100,1,17.44,100,1,9.79,100,1,21.47,100,1,,0,0,,0,0,,0,0,,0,0,,0,0,,0,0,,0,0,,0,0,,0,0,,0,0,,0,0,,0,0,,0,0,,0,0,,0,0,,0,0,ARL,12983425
17,2025-07-17T11:00:07.975972618Z,2025-07-17T11:00:07.975972618Z,10,2,1108,C,A,1,21.47,100,130,165484,10674473,9.84,100,1,17.44,100,1,9.79,100,1,,0,0,,0,0,,0,0,,0,0,,0,0,,0,0,,0,0,,0,0,,0,0,,0,0,,0,0,,0,0,,0,0,,0,0,,0,0,,0,0,,0,0,ARL,1264725
18,2025-07-17T11:00:07.975979367Z,2025-07-17T11:00:07.975979367Z,10,2,1108,A,A,0,17.36,100,130,165357,10674474,9.84,100,1,17.36,100,1,9.79,100,1,17.44,100,1,,0,0,,0,0,,0,0,,0,0,,0,0,,0,0,,0,0,,0,0,,0,0,,0,0,,0,0,,0,0,,0,0,,0,0,,0,0,,0,0,ARL,12983429
19,2025-07-17T11:00:08.254975294Z,2025-07-17T11:00:08.254975294Z,10,2,1108,C,A,1,17.44,100,130,165204,10676310,9.84,100,1,17.36,100,1,9.79,100,1,,0,0,,0,0,,0,0,,0,0,,0,0,,0,0,,0,0,,0,0,,0,0,,0,0,,0,0,,0,0,,0,0,,0,0,,0,0,,0,0,,0,0,ARL,12983425
20,2025-07-17T11:00:08.254985173Z,2025-07-17T11:00:08.254985173Z,10,2,1108,A,A,1,18.92,100,130,165286,10676311,9.84,100,1,17.36,100,1,9.79,100,1,18.92,100,1,,0,0,,0,0,,0,0,,0,0,,0,0,,0,0,,0,0,,0,0,,0,0,,0,0,,0,0,,0,0,,0,0,,0,0,,0,0,,0,0,ARL,12985397
21,2025-07-17T11:00:08.255147130Z,2025-07-17T11:00:08.255147130Z,10,2,1108,C,A,0,17.36,100,130,165096,10676314,9.84,100,1,18.92,100,1,9.79,100,1,,0,0,,0,0,,0,0,,0,0,,0,0,,0,0,,0,0,,0,0,,0,0,,0,0,,0,0,,0,0,,0,0,,0,0,,0,0,,0,0,,0,0,ARL,12983429
22,2025-07-17T11:00:08.255155317Z,2025-07-17T11:00:08.255155317Z,10,2,1108,A,A,0,18.84,100,130,165097,10676315,9.84,100,1,18.84,100,1,9.79,100,1,18.92,100,1,,0,0,,0,0,,0,0,,0,0,,0,0,,0,0,,0,0,,0,0,,0,0,,0,0,,0,0,,0,0,,0,0,,0,0,,0,0,,0,0,ARL,12985401
23,2025-07-17T11:00:08.255862656Z,2025-07-17T11:00:08.255862656Z,10,2,1108,C,A,1,18.92,100,130,165036,10676320,9.84,100,1,18.84,100,1,9.79,100,1,,0,0,,0,0,,0,0,,0,0,,0,0,,0,0,,0,0,,0,0,,0,0,,0,0,,0,0,,0,0,,0,0,,0,0,,0,0,,0,0,,0,0,ARL,12985397
24,2025-07-17T11:00:08.255871843Z,2025-07-17T11:00:08.255871843Z,10,2,1108,A,A,1,20.62,100,130,165232,10676321,9.84,100,1,18.84,100,1,9.79,100,1,20.62,100,1,,0,0,,0,0,,0,0,,0,0,,0,0,,0,0,,0,0,,0,0,,0,0,,0,0,,0,0,,0,0,,0,0,,0,0,,0,0,,0,0,ARL,12985405
25,2025-07-17T11:00:08.256168895Z,2025-07-17T11:00:08.256168895Z,10,2,1108,C,A,0,18.84,100,130,165011,10676324,9.84,100,1,20.62,100,1,9.79,100,1,,0,0,,0,0,,0,0,,0,0,,0,0,,0,0,,0,0,,0,0,,0,0,,0,0,,0,0,,0,0,,0,0,,0,0,,0,0,,0,0,,0,0,ARL,12985401
26,2025-07-17T11:00:08.256175346Z,2025-07-17T11:00:08.256175346Z,10,2,1108,A,A,0,20.53,100,130,165269,10676325,9.84,100,1,20.53,100,1,9.79,100,1,20.62,100,1,,0,0,,0,0,,0,0,,0,0,,0,0,,0,0,,0,0,,0,0,,0,0,,0,0,,0,0,,0,0,,0,0,,0,0,,0,0,,0,0,ARL,12985413
27,2025-07-17T11:00:08.256885010Z,2025-07-17T11:00:08.256885010Z,10,2,1108,C,A,1,20.62,100,130,165272,10676333,9.84,100,1,20.53,100,1,9.79,100,1,,0,0,,0,0,,0,0,,0,0,,0,0,,0,0,,0,0,,0,0,,0,0,,0,0,,0,0,,0,0,,0,0,,0,0,,0,0,,0,0,,0,0,ARL,12985405
28,2025-07-17T11:00:08.256892686Z,2025-07-17T11:00:08.256892686Z,10,2,1108,A,A,1,21.47,100,130,165384,10676334,9.84,100,1,20.53,100,1,9.79,100,1,21.47,100,1,,0,0,,0,0,,0,0,,0,0,,0,0,,0,0,,0,0,,0,0,,0,0,,0,0,,0,0,,0,0,,0,0,,0,0,,0,0,,0,0,ARL,12985417
29,2025-07-17T11:00:08.257069458Z,2025-07-17T11:00:08.257069458Z,10,2,1108,C,A,0,20.53,100,130,165354,10676335,9.84,100,1,21.47,100,1,9.79,100,1,,0,0,,0,0,,0,0,,0,0,,0,0,,0,0,,0,0,,0,0,,0,0,,0,0,,0,0,,0,0,,0,0,,0,0,,0,0,,0,0,,0,0,ARL,12985413
30,2025-07-17T11:00:08.257076085Z,2025-07-17T11:00:08.257076085Z,10,2,1108,A,A,0,21.47,100,130,165249,10676336,9.84,100,1,21.47,200,2,9.79,100,1,,0,0,,0,0,,0,0,,0,0,,0,0,,0,0,,0,0,,0,0,,0,0,,0,0,,0,0,,0,0,,0,0,,0,0,,0,0,,0,0,,0,0,ARL,12985421
31,2025-07-17T11:01:05.260421351Z,2025-07-17T11:01:05.260421351Z,10,2,1108,C,A,0,21.47,100,130,165317,10824633,9.84,100,1,21.47,100,1,9.79,100,1,,0,0,,0,0,,0,0,,0,0,,0,0,,0,0,,0,0,,0,0,,0,0,,0,0,,0,0,,0,0,,0,0,,0,0,,0,0,,0,0,,0,0,ARL,12985417
32,2025-07-17T11:01:05.260445703Z,2025-07-17T11:01:05.260445703Z,10,2,1108,A,A,0,17.44,100,130,165434,10824634,9.84,100,1,17.44,100,1,9.79,100,1,21.47,100,1,,0,0,,0,0,,0,0,,0,0,,0,0,,0,0,,0,0,,0,0,,0,0,,0,0,,0,0,,0,0,,0,0,,0,0,,0,0,,0,0,ARL,13174157
33,2025-07-17T11:01:05.260693130Z,2025-07-17T11:01:05.260693130Z,10,2,1108,C,A,1,21.47,100,130,165306,10824635,9.84,100,1,17.44,100,1,9.79,100,1,,0,0,,0,0,,0,0,,0,0,,0,0,,0,0,,0,0,,0,0,,0,0,,0,0,,0,0,,0,0,,0,0,,0,0,,0,0,,0,0,,0,0,ARL,12985421
34,2025-07-17T11:01:05.260709480Z,2025-07-17T11:01:05.260709480Z,10,2,1108,A,A,0,17.36,100,130,165150,10824636,9.84,100,1,17.36,100,1,9.79,100,1,17.44,100,1,,0,0,,0,0,,0,0,,0,0,,0,0,,0,0,,0,0,,0,0,,0,0,,0,0,,0,0,,0,0,,0,0,,0,0,,0,0,,0,0,ARL,13174161
35,2025-07-17T11:56:26.691461161Z,2025-07-17T11:56:26.691461161Z,10,2,1108,C,B,1,9.79,100,130,165682,14213017,9.84,100,1,17.36,100,1,,0,0,17.44,100,1,,0,0,,0,0,,0,0,,0,0,,0,0,,0,0,,0,0,,0,0,,0,0,,0,0,,0,0,,0,0,,0,0,,0,0,,0,0,,0,0,ARL,12852457
36,2025-07-17T11:56:26.691465204Z,2025-07-17T11:56:26.691465204Z,10,2,1108,C,A,1,17.44,100,130,165335,14213018,9.84,100,1,17.36,100,1,,0,0,,0,0,,0,0,,0,0,,0,0,,0,0,,0,0,,0,0,,0,0,,0,0,,0,0,,0,0,,0,0,,0,0,,0,0,,0,0,,0,0,,0,0,ARL,13174157
37,2025-07-17T11:56:26.694767820Z,2025-07-17T11:56:26.694767820Z,10,2,1108,A,B,1,9.79,100,130,165430,14213075,9.84,100,1,17.36,100,1,9.79,100,1,,0,0,,0,0,,0,0,,0,0,,0,0,,0,0,,0,0,,0,0,,0,0,,0,0,,0,0,,0,0,,0,0,,0,0,,0,0,,0,0,,0,0,ARL,19202569
38,2025-07-17T11:56:26.694772016Z,2025-07-17T11:56:26.694772016Z,10,2,1108,A,A,1,17.44,100,130,165345,14213076,9.84,100,1,17.36,100,1,9.79,100,1,17.44,100,1,,0,0,,0,0,,0,0,,0,0,,0,0,,0,0,,0,0,,0,0,,0,0,,0,0,,0,0,,0,0,,0,0,,0,0,,0,0,,0,0,ARL,19202573
39,2025-07-17T11:56:30.445937099Z,2025-07-17T11:56:30.445937099Z,10,2,1108,C,A,1,17.44,100,130,165310,14219824,9.84,100,1,17.36,100,1,9.79,100,1,,0,0,,0,0,,0,0,,0,0,,0,0,,0,0,,0,0,,0,0,,0,0,,0,0,,0,0,,0,0,,0,0,,0,0,,0,0,,0,0,,0,0,ARL,19202573
40,2025-07-17T11:56:30.445951937Z,2025-07-17T11:56:30.445951937Z,10,2,1108,A,A,1,17.93,100,130,165512,14219825,9.84,100,1,17.36,100,1,9.79,100,1,17.93,100,1,,0,0,,0,0,,0,0,,0,0,,0,0,,0,0,,0,0,,0,0,,0,0,,0,0,,0,0,,0,0,,0,0,,0,0,,0,0,,0,0,ARL,19218909
41,2025-07-17T11:56:30.446066952Z,2025-07-17T11:56:30.446066952Z,10,2,1108,C,A,1,17.93,100,130,165013,14219826,9.84,100,1,17.36,100,1,9.79,100,1,,0,0,,0,0,,0,0,,0,0,,0,0,,0,0,,0,0,,0,0,,0,0,,0,0,,0,0,,0,0,,0,0,,0,0,,0,0,,0,0,,0,0,ARL,19218909
42,2025-07-17T11:56:30.446084801Z,2025-07-17T11:56:30.446084801Z,10,2,1108,A,A,1,17.44,100,130,165347,14219827,9.84,100,1,17.36,100,1,9.79,100,1,17.44,100,1,,0,0,,0,0,,0,0,,0,0,,0,0,,0,0,,0,0,,0,0,,0,0,,0,0,,0,0,,0,0,,0,0,,0,0,,0,0,,0,0,ARL,19218913
43,2025-07-17T11:56:30.446191769Z,2025-07-17T11:56:30.446191769Z,10,2,1108,C,A,0,17.36,100,130,165423,14219828,9.84,100,1,17.44,100,1,9.79,100,1,,0,0,,0,0,,0,0,,0,0,,0,0,,0,0,,0,0,,0,0,,0,0,,0,0,,0,0,,0,0,,0,0,,0,0,,0,0,,0,0,,0,0,ARL,13174161
44,2025-07-17T11:56:30.446213519Z,2025-07-17T11:56:30.446213519Z,10,2,1108,A,A,1,17.85,100,130,165517,14219829,9.84,100,1,17.44,100,1,9.79,100,1,17.85,100,1,,0,0,,0,0,,0,0,,0,0,,0,0,,0,0,,0,0,,0,0,,0,0,,0,0,,0,0,,0,0,,0,0,,0,0,,0,0,,0,0,ARL,19218917
45,2025-07-17T11:56:30.446378732Z,2025-07-17T11:56:30.446378732Z,10,2,1108,C,A,1,17.85,100,130,164905,14219830,9.84,100,1,17.44,100,1,9.79,100,1,,0,0,,0,0,,0,0,,0,0,,0,0,,0,0,,0,0,,0,0,,0,0,,0,0,,0,0,,0,0,,0,0,,0,0,,0,0,,0,0,,0,0,ARL,19218917
46,2025-07-17T11:56:30.446558412Z,2025-07-17T11:56:30.446558412Z,10,2,1108,A,A,0,17.36,100,130,165234,14219831,9.84,100,1,17.36,100,1,9.79,100,1,17.44,100,1,,0,0,,0,0,,0,0,,0,0,,0,0,,0,0,,0,0,,0,0,,0,0,,0,0,,0,0,,0,0,,0,0,,0,0,,0,0,,0,0,ARL,19218921
47,2025-07-17T11:57:30.222822537Z,2025-07-17T11:57:30.222822537Z,10,2,1108,C,B,0,9.84,100,130,165260,14325877,9.79,100,1,17.36,100,1,,0,0,17.44,100,1,,0,0,,0,0,,0,0,,0,0,,0,0,,0,0,,0,0,,0,0,,0,0,,0,0,,0,0,,0,0,,0,0,,0,0,,0,0,,0,0,ARL,12852537
48,2025-07-17T11:57:30.222823580Z,2025-07-17T11:57:30.222823580Z,10,2,1108,C,A,0,17.36,100,130,165198,14325878,9.79,100,1,17.44,100,1,,0,0,,0,0,,0,0,,0,0,,0,0,,0,0,,0,0,,0,0,,0,0,,0,0,,0,0,,0,0,,0,0,,0,0,,0,0,,0,0,,0,0,,0,0,ARL,19218921
49,2025-07-17T11:57:30.223986626Z,2025-07-17T11:57:30.223986626Z,10,2,1108,A,B,0,9.84,100,130,165341,14325937,9.84,100,1,17.44,100,1,9.79,100,1,,0,0,,0,0,,0,0,,0,0,,0,0,,0,0,,0,0,,0,0,,0,0,,0,0,,0,0,,0,0,,0,0,,0,0,,0,0,,0,0,,0,0,ARL,19346173
50,2025-07-17T11:57:30.223991040Z,2025-07-17T11:57:30.223991040Z,10,2,1108,A,A,0,17.36,100,130,165106,14325938,9.84,100,1,17.36,100,1,9.79,100,1,17.44,100,1,,0,0,,0,0,,0,0,,0,0,,0,0,,0,0,,0,0,,0,0,,0,0,,0,0,,0,0,,0,0,,0,0,,0,0,,0,0,,0,0,ARL,19346177
51,2025-07-17T12:30:01.317842911Z,2025-07-17T12:30:01.317842911Z,10,2,1108,A,A,2,20.48,100,130,165874,16864046,9.84,100,1,17.36,100,1,9.79,100,1,17.44,100,1,,0,0,20.48,100,1,,0,0,,0,0,,0,0,,0,0,,0,0,,0,0,,0,0,,0,0,,0,0,,0,0,,0,0,,0,0,,0,0,,0,0,ARL,23570297
52,2025-07-17T12:30:03.426300621Z,2025-07-17T12:30:03.426300621Z,10,2,1108,A,B,2,7.74,100,130,165236,16882670,9.84,100,1,17.36,100,1,9.79,100,1,17.44,100,1,7.74,100,1,20.48,100,1,,0,0,,0,0,,0,0,,0,0,,0,0,,0,0,,0,0,,0,0,,0,0,,0,0,,0,0,,0,0,,0,0,,0,0,ARL,23616197
53,2025-07-17T12:30:03.426301523Z,2025-07-17T12:30:03.426301523Z,10,2,1108,A,A,2,20.48,100,130,165339,16882671,9.84,100,1,17.36,100,1,9.79,100,1,17.44,100,1,7.74,100,1,20.48,200,2,,0,0,,0,0,,0,0,,0,0,,0,0,,0,0,,0,0,,0,0,,0,0,,0,0,,0,0,,0,0,,0,0,,0,0,ARL,23616201
54,2025-07-17T12:30:03.604533925Z,2025-07-17T12:30:03.604533925Z,10,2,1108,A,B,2,7.74,100,130,165243,16886020,9.84,100,1,17.36,100,1,9.79,100,1,17.44,100,1,7.74,200,2,20.48,200,2,,0,0,,0,0,,0,0,,0,0,,0,0,,0,0,,0,0,,0,0,,0,0,,0,0,,0,0,,0,0,,0,0,,0,0,ARL,23622101
55,2025-07-17T12:30:51.178228608Z,2025-07-17T12:30:51.178228608Z,10,2,1108,A,A,2,20.48,100,130,165625,17120703,9.84,100,1,17.36,100,1,9.79,100,1,17.44,100,1,7.74,200,2,20.48,300,3,,0,0,,0,0,,0,0,,0,0,,0,0,,0,0,,0,0,,0,0,,0,0,,0,0,,0,0,,0,0,,0,0,,0,0,ARL,24099409
56,2025-07-17T12:30:51.642959794Z,2025-07-17T12:30:51.642959794Z,10,2,1108,A,B,2,7.74,100,130,165373,17122998,9.84,100,1,17.36,100,1,9.79,100,1,17.44,100,1,7.74,300,3,20.48,300,3,,0,0,,0,0,,0,0,,0,0,,0,0,,0,0,,0,0,,0,0,,0,0,,0,0,,0,0,,0,0,,0,0,,0,0,ARL,24102329
57,2025-07-17T13:15:00.032446132Z,2025-07-17T13:15:00.032446132Z,10,2,1108,C,A,1,17.44,100,130,165604,23080007,9.84,100,1,17.36,100,1,9.79,100,1,20.48,300,3,7.74,300,3,,0,0,,0,0,,0,0,,0,0,,0,0,,0,0,,0,0,,0,0,,0,0,,0,0,,0,0,,0,0,,0,0,,0,0,,0,0,ARL,19218913
58,2025-07-17T13:15:00.032483824Z,2025-07-17T13:15:00.032483824Z,10,2,1108,C,B,1,9.79,100,128,167387,23080041,9.84,100,1,17.36,100,1,7.74,300,3,20.48,300,3,,0,0,,0,0,,0,0,,0,0,,0,0,,0,0,,0,0,,0,0,,0,0,,0,0,,0,0,,0,0,,0,0,,0,0,,0,0,,0,0,ARL,19202569
59,2025-07-17T13:15:00.058314138Z,2025-07-17T13:15:00.058314138Z,10,2,1108,C,A,0,17.36,100,128,166100,23101369,9.84,100,1,20.48,300,3,7.74,300,3,,0,0,,0,0,,0,0,,0,0,,0,0,,0,0,,0,0,,0,0,,0,0,,0,0,,0,0,,0,0,,0,0,,0,0,,0,0,,0,0,,0,0,ARL,19346177
60,2025-07-17T13:15:00.058371545Z,2025-07-17T13:15:00.058371545Z,10,2,1108,C,B,0,9.84,100,130,165839,23101396,7.74,300,3,20.48,300,3,,0,0,,0,0,,0,0,,0,0,,0,0,,0,0,,0,0,,0,0,,0,0,,0,0,,0,0,,0,0,,0,0,,0,0,,0,0,,0,0,,0,0,,0,0,ARL,19346173
61,2025-07-17T13:15:01.925073727Z,2025-07-17T13:15:01.925073727Z,10,2,1108,A,B,0,7.74,100,130,165317,23123943,7.74,400,4,20.48,300,3,,0,0,,0,0,,0,0,,0,0,,0,0,,0,0,,0,0,,0,0,,0,0,,0,0,,0,0,,0,0,,0,0,,0,0,,0,0,,0,0,,0,0,,0,0,ARL,31960841
62,2025-07-17T13:15:02.042741730Z,2025-07-17T13:15:02.042741730Z,10,2,1108,A,A,0,20.48,100,130,165217,23124563,7.74,400,4,20.48,400,4,,0,0,,0,0,,0,0,,0,0,,0,0,,0,0,,0,0,,0,0,,0,0,,0,0,,0,0,,0,0,,0,0,,0,0,,0,0,,0,0,,0,0,,0,0,ARL,31962113
63,2025-07-17T13:17:49.831164624Z,2025-07-17T13:17:49.831164624Z,10,2,1108,A,B,0,7.74,100,130,165264,23465434,7.74,500,5,20.48,400,4,,0,0,,0,0,,0,0,,0,0,,0,0,,0,0,,0,0,,0,0,,0,0,,0,0,,0,0,,0,0,,0,0,,0,0,,0,0,,0,0,,0,0,,0,0,ARL,33574717
64,2025-07-17T13:17:49.831544051Z,2025-07-17T13:17:49.831544051Z,10,2,1108,A,A,0,20.48,100,130,165314,23465435,7.74,500,5,20.48,500,5,,0,0,,0,0,,0,0,,0,0,,0,0,,0,0,,0,0,,0,0,,0,0,,0,0,,0,0,,0,0,,0,0,,0,0,,0,0,,0,0,,0,0,,0,0,ARL,33574725
65,2025-07-17T13:19:57.597203040Z,2025-07-17T13:19:57.597203040Z,10,2,1108,A,B,0,8.74,100,130,165281,23710201,8.74,100,1,20.48,500,5,7.74,500,5,,0,0,,0,0,,0,0,,0,0,,0,0,,0,0,,0,0,,0,0,,0,0,,0,0,,0,0,,0,0,,0,0,,0,0,,0,0,,0,0,,0,0,ARL,34790041
66,2025-07-17T13:19:57.597291053Z,2025-07-17T13:19:57.597291053Z,10,2,1108,A,A,0,18.35,100,130,165217,23710202,8.74,100,1,18.35,100,1,7.74,500,5,20.48,500,5,,0,0,,0,0,,0,0,,0,0,,0,0,,0,0,,0,0,,0,0,,0,0,,0,0,,0,0,,0,0,,0,0,,0,0,,0,0,,0,0,ARL,34790045
67,2025-07-17T13:19:58.492619751Z,2025-07-17T13:19:58.492619751Z,10,2,1108,A,A,0,18.24,100,130,165309,23728432,8.74,100,1,18.24,100,1,7.74,500,5,18.35,100,1,,0,0,20.48,500,5,,0,0,,0,0,,0,0,,0,0,,0,0,,0,0,,0,0,,0,0,,0,0,,0,0,,0,0,,0,0,,0,0,,0,0,ARL,34810233
68,2025-07-17T13:19:58.492634480Z,2025-07-17T13:19:58.492634480Z,10,2,1108,A,B,0,9.24,100,130,165346,23728435,9.24,100,1,18.24,100,1,8.74,100,1,18.35,100,1,7.74,500,5,20.48,500,5,,0,0,,0,0,,0,0,,0,0,,0,0,,0,0,,0,0,,0,0,,0,0,,0,0,,0,0,,0,0,,0,0,,0,0,ARL,34810241
69,2025-07-17T13:20:00.525263842Z,2025-07-17T13:20:00.525263842Z,10,2,1108,C,A,0,18.24,100,0,166519,23765825,9.24,100,1,18.35,100,1,8.74,100,1,20.48,500,5,7.74,500,5,,0,0,,0,0,,0,0,,0,0,,0,0,,0,0,,0,0,,0,0,,0,0,,0,0,,0,0,,0,0,,0,0,,0,0,,0,0,ARL,34810233
70,2025-07-17T13:20:00.525264700Z,2025-07-17T13:20:00.525264700Z,10,2,1108,C,B,0,9.24,100,130,165661,23765826,8.74,100,1,18.35,100,1,7.74,500,5,20.48,500,5,,0,0,,0,0,,0,0,,0,0,,0,0,,0,0,,0,0,,0,0,,0,0,,0,0,,0,0,,0,0,,0,0,,0,0,,0,0,,0,0,ARL,34810241
71,2025-07-17T13:25:00.157467184Z,2025-07-17T13:25:00.157467184Z,10,2,1108,C,B,0,8.74,100,130,165039,24448205,7.74,500,5,18.35,100,1,,0,0,20.48,500,5,,0,0,,0,0,,0,0,,0,0,,0,0,,0,0,,0,0,,0,0,,0,0,,0,0,,0,0,,0,0,,0,0,,0,0,,0,0,,0,0,ARL,34790041
72,2025-07-17T13:25:00.157473422Z,2025-07-17T13:25:00.157473422Z,10,2,1108,C,A,0,18.35,100,130,165090,24448207,7.74,500,5,20.48,500,5,,0,0,,0,0,,0,0,,0,0,,0,0,,0,0,,0,0,,0,0,,0,0,,0,0,,0,0,,0,0,,0,0,,0,0,,0,0,,0,0,,0,0,,0,0,ARL,34790045
73,2025-07-17T13:25:01.732320109Z,2025-07-17T13:25:01.732320109Z,10,2,1108,A,B,0,7.74,100,130,165277,24478872,7.74,600,6,20.48,500,5,,0,0,,0,0,,0,0,,0,0,,0,0,,0,0,,0,0,,0,0,,0,0,,0,0,,0,0,,0,0,,0,0,,0,0,,0,0,,0,0,,0,0,,0,0,ARL,38041417
74,2025-07-17T13:25:01.819282823Z,2025-07-17T13:25:01.819282823Z,10,2,1108,A,A,0,20.48,100,130,165137,24480276,7.74,600,6,20.48,600,6,,0,0,,0,0,,0,0,,0,0,,0,0,,0,0,,0,0,,0,0,,0,0,,0,0,,0,0,,0,0,,0,0,,0,0,,0,0,,0,0,,0,0,,0,0,ARL,38043741
75,2025-07-17T13:28:08.191915168Z,2025-07-17T13:28:08.191915168Z,10,2,1108,A,B,0,7.74,100,130,165295,25597187,7.74,700,7,20.48,600,6,,0,0,,0,0,,0,0,,0,0,,0,0,,0,0,,0,0,,0,0,,0,0,,0,0,,0,0,,0,0,,0,0,,0,0,,0,0,,0,0,,0,0,,0,0,ARL,40617777
76,2025-07-17T13:28:08.191982270Z,2025-07-17T13:28:08.191982270Z,10,2,1108,A,A,0,20.48,100,130,165331,25597189,7.74,700,7,20.48,700,7,,0,0,,0,0,,0,0,,0,0,,0,0,,0,0,,0,0,,0,0,,0,0,,0,0,,0,0,,0,0,,0,0,,0,0,,0,0,,0,0,,0,0,,0,0,ARL,40617785
77,2025-07-17T13:28:21.011249114Z,2025-07-17T13:28:21.011249114Z,10,2,1108,A,A,0,18.32,700,130,165478,25907820,7.74,700,7,18.32,700,1,,0,0,20.48,700,7,,0,0,,0,0,,0,0,,0,0,,0,0,,0,0,,0,0,,0,0,,0,0,,0,0,,0,0,,0,0,,0,0,,0,0,,0,0,,0,0,ARL,40846101
78,2025-07-17T13:28:21.028865155Z,2025-07-17T13:28:21.028865155Z,10,2,1108,A,B,0,9.29,700,130,165210,25917006,9.29,700,1,18.32,700,1,7.74,700,7,20.48,700,7,,0,0,,0,0,,0,0,,0,0,,0,0,,0,0,,0,0,,0,0,,0,0,,0,0,,0,0,,0,0,,0,0,,0,0,,0,0,,0,0,ARL,40851989
79,2025-07-17T13:28:30.048730211Z,2025-07-17T13:28:30.048730211Z,10,2,1108,A,B,0,9.67,100,130,165257,26140646,9.67,100,1,18.32,700,1,9.29,700,1,20.48,700,7,7.74,700,7,,0,0,,0,0,,0,0,,0,0,,0,0,,0,0,,0,0,,0,0,,0,0,,0,0,,0,0,,0,0,,0,0,,0,0,,0,0,ARL,40999441
80,2025-07-17T13:28:30.048741690Z,2025-07-17T13:28:30.048741690Z,10,2,1108,A,A,0,17.6,100,130,165762,26140658,9.67,100,1,17.6,100,1,9.29,700,1,18.32,700,1,7.74,700,7,20.48,700,7,,0,0,,0,0,,0,0,,0,0,,0,0,,0,0,,0,0,,0,0,,0,0,,0,0,,0,0,,0,0,,0,0,,0,0,ARL,40999449
81,2025-07-17T13:28:30.051894007Z,2025-07-17T13:28:30.051894007Z,10,2,1108,A,B,0,9.99,100,130,167791,26142104,9.99,100,1,17.6,100,1,9.67,100,1,18.32,700,1,9.29,700,1,20.48,700,7,7.74,700,7,,0,0,,0,0,,0,0,,0,0,,0,0,,0,0,,0,0,,0,0,,0,0,,0,0,,0,0,,0,0,,0,0,ARL,41000165
82,2025-07-17T13:28:30.051907073Z,2025-07-17T13:28:30.051907073Z,10,2,1108,A,A,0,17.12,100,130,165495,26142118,9.99,100,1,17.12,100,1,9.67,100,1,17.6,100,1,9.29,700,1,18.32,700,1,7.74,700,7,20.48,700,7,,0,0,,0,0,,0,0,,0,0,,0,0,,0,0,,0,0,,0,0,,0,0,,0,0,,0,0,,0,0,ARL,41000173
83,2025-07-17T13:28:30.256853564Z,2025-07-17T13:28:30.256853564Z,10,2,1108,A,B,1,9.67,100,130,165280,26170917,9.99,100,1,17.12,100,1,9.67,200,2,17.6,100,1,9.29,700,1,18.32,700,1,7.74,700,7,20.48,700,7,,0,0,,0,0,,0,0,,0,0,,0,0,,0,0,,0,0,,0,0,,0,0,,0,0,,0,0,,0,0,ARL,41021369
84,2025-07-17T13:28:30.256865858Z,2025-07-17T13:28:30.256865858Z,10,2,1108,A,A,1,17.6,100,130,165298,26170918,9.99,100,1,17.12,100,1,9.67,200,2,17.6,200,2,9.29,700,1,18.32,700,1,7.74,700,7,20.48,700,7,,0,0,,0,0,,0,0,,0,0,,0,0,,0,0,,0,0,,0,0,,0,0,,0,0,,0,0,,0,0,ARL,41021373
85,2025-07-17T13:28:30.277457031Z,2025-07-17T13:28:30.277457031Z,10,2,1108,A,B,0,9.99,100,130,165315,26171531,9.99,200,2,17.12,100,1,9.67,200,2,17.6,200,2,9.29,700,1,18.32,700,1,7.74,700,7,20.48,700,7,,0,0,,0,0,,0,0,,0,0,,0,0,,0,0,,0,0,,0,0,,0,0,,0,0,,0,0,,0,0,ARL,41021837
86,2025-07-17T13:28:30.277470320Z,2025-07-17T13:28:30.277470320Z,10,2,1108,A,A,0,17.12,100,130,165325,26171533,9.99,200,2,17.12,200,2,9.67,200,2,17.6,200,2,9.29,700,1,18.32,700,1,7.74,700,7,20.48,700,7,,0,0,,0,0,,0,0,,0,0,,0,0,,0,0,,0,0,,0,0,,0,0,,0,0,,0,0,,0,0,ARL,41021841
87,2025-07-17T13:28:30.613317490Z,2025-07-17T13:28:30.613317490Z,10,2,1108,A,B,3,9.13,100,130,165177,26182390,9.99,200,2,17.12,200,2,9.67,200,2,17.6,200,2,9.29,700,1,18.32,700,1,9.13,100,1,20.48,700,7,7.74,700,7,,0,0,,0,0,,0,0,,0,0,,0,0,,0,0,,0,0,,0,0,,0,0,,0,0,,0,0,ARL,41032049
88,2025-07-17T13:28:30.613329849Z,2025-07-17T13:28:30.613329849Z,10,2,1108,A,A,3,18.4,100,130,165208,26182393,9.99,200,2,17.12,200,2,9.67,200,2,17.6,200,2,9.29,700,1,18.32,700,1,9.13,100,1,18.4,100,1,7.74,700,7,20.48,700,7,,0,0,,0,0,,0,0,,0,0,,0,0,,0,0,,0,0,,0,0,,0,0,,0,0,ARL,41032057
89,2025-07-17T13:28:41.476711173Z,2025-07-17T13:28:41.476711173Z,10,2,1108,A,B,4,7.84,100,130,165374,26518296,9.99,200,2,17.12,200,2,9.67,200,2,17.6,200,2,9.29,700,1,18.32,700,1,9.13,100,1,18.4,100,1,7.84,100,1,20.48,700,7,7.74,700,7,,0,0,,0,0,,0,0,,0,0,,0,0,,0,0,,0,0,,0,0,,0,0,ARL,41306441
90,2025-07-17T13:28:41.476722715Z,2025-07-17T13:28:41.476722715Z,10,2,1108,A,A,4,20.32,100,130,165260,26518297,9.99,200,2,17.12,200,2,9.67,200,2,17.6,200,2,9.29,700,1,18.32,700,1,9.13,100,1,18.4,100,1,7.84,100,1,20.32,100,1,7.74,700,7,20.48,700,7,,0,0,,0,0,,0,0,,0,0,,0,0,,0,0,,0,0,,0,0,ARL,41306445
91,2025-07-17T13:28:46.014739305Z,2025-07-17T13:28:46.014739305Z,10,2,1108,A,A,0,15.3,100,130,165569,26613800,9.99,200,2,15.3,100,1,9.67,200,2,17.12,200,2,9.29,700,1,17.6,200,2,9.13,100,1,18.32,700,1,7.84,100,1,18.4,100,1,7.74,700,7,20.32,100,1,,0,0,20.48,700,7,,0,0,,0,0,,0,0,,0,0,,0,0,,0,0,ARL,41370837
92,2025-07-17T13:28:46.014802018Z,2025-07-17T13:28:46.014802018Z,10,2,1108,C,A,6,20.48,100,0,165982,26613836,9.99,200,2,15.3,100,1,9.67,200,2,17.12,200,2,9.29,700,1,17.6,200,2,9.13,100,1,18.32,700,1,7.84,100,1,18.4,100,1,7.74,700,7,20.32,100,1,,0,0,20.48,600,6,,0,0,,0,0,,0,0,,0,0,,0,0,,0,0,ARL,23570297
93,2025-07-17T13:28:46.014802018Z,2025-07-17T13:28:46.014802018Z,10,2,1108,A,A,5,19.58,100,130,165982,26613836,9.99,200,2,15.3,100,1,9.67,200,2,17.12,200,2,9.29,700,1,17.6,200,2,9.13,100,1,18.32,700,1,7.84,100,1,18.4,100,1,7.74,700,7,19.58,100,1,,0,0,20.32,100,1,,0,0,20.48,600,6,,0,0,,0,0,,0,0,,0,0,ARL,41370945
94,2025-07-17T13:28:46.014803011Z,2025-07-17T13:28:46.014803011Z,10,2,1108,C,A,7,20.48,100,0,166124,26613837,9.99,200,2,15.3,100,1,9.67,200,2,17.12,200,2,9.29,700,1,17.6,200,2,9.13,100,1,18.32,700,1,7.84,100,1,18.4,100,1,7.74,700,7,19.58,100,1,,0,0,20.32,100,1,,0,0,20.48,500,5,,0,0,,0,0,,0,0,,0,0,ARL,23616201
95,2025-07-17T13:28:46.014803011Z,2025-07-17T13:28:46.014803011Z,10,2,1108,A,A,5,19.58,100,130,166124,26613837,9.99,200,2,15.3,100,1,9.67,200,2,17.12,200,2,9.29,700,1,17.6,200,2,9.13,100,1,18.32,700,1,7.84,100,1,18.4,100,1,7.74,700,7,19.58,200,2,,0,0,20.32,100,1,,0,0,20.48,500,5,,0,0,,0,0,,0,0,,0,0,ARL,41370949
96,2025-07-17T13:28:46.014804158Z,2025-07-17T13:28:46.014804158Z,10,2,1108,C,A,7,20.48,100,0,166541,26613838,9.99,200,2,15.3,100,1,9.67,200,2,17.12,200,2,9.29,700,1,17.6,200,2,9.13,100,1,18.32,700,1,7.84,100,1,18.4,100,1,7.74,700,7,19.58,200,2,,0,0,20.32,100,1,,0,0,20.48,400,4,,0,0,,0,0,,0,0,,0,0,ARL,24099409
97,2025-07-17T13:28:46.014804158Z,2025-07-17T13:28:46.014804158Z,10,2,1108,A,A,5,19.58,100,0,166541,26613838,9.99,200,2,15.3,100,1,9.67,200,2,17.12,200,2,9.29,700,1,17.6,200,2,9.13,100,1,18.32,700,1,7.84,100,1,18.4,100,1,7.74,700,7,19.58,300,3,,0,0,20.32,100,1,,0,0,20.48,400,4,,0,0,,0,0,,0,0,,0,0,ARL,41370953
98,2025-07-17T13:28:46.014804564Z,2025-07-17T13:28:46.014804564Z,10,2,1108,C,A,7,20.48,100,0,166135,26613839,9.99,200,2,15.3,100,1,9.67,200,2,17.12,200,2,9.29,700,1,17.6,200,2,9.13,100,1,18.32,700,1,7.84,100,1,18.4,100,1,7.74,700,7,19.58,300,3,,0,0,20.32,100,1,,0,0,20.48,300,3,,0,0,,0,0,,0,0,,0,0,ARL,31962113
99,2025-07-17T13:28:46.014804564Z,2025-07-17T13:28:46.014804564Z,10,2,1108,A,A,5,19.58,100,130,166135,26613839,9.99,200,2,15.3,100,1,9.67,200,2,17.12,200,2,9.29,700,1,17.6,200,2,9.13,100,1,18.32,700,1,7.84,100,1,18.4,100,1,7.74,700,7,19.58,400,4,,0,0,20.32,100,1,,0,0,20.48,300,3,,0,0,,0,0,,0,0,,0,0,ARL,41370957
100,2025-07-17T13:28:46.014805680Z,2025-07-17T13:28:46.014805680Z,10,2,1108,C,A,7,20.48,100,0,166471,26613840,9.99,200,2,15.3,100,1,9.67,200,2,17.12,200,2,9.29,700,1,17.6,200,2,9.13,100,1,18.32,700,1,7.84,100,1,18.4,100,1,7.74,700,7,19.58,400,4,,0,0,20.32,100,1,,0,0,20.48,200,2,,0,0,,0,0,,0,0,,0,0,ARL,33574725
101,2025-07-17T13:28:46.014805680Z,2025-07-17T13:28:46.014805680Z,10,2,1108,A,A,5,19.58,100,0,166471,26613840,9.99,200,2,15.3,100,1,9.67,200,2,17.12,200,2,9.29,700,1,17.6,200,2,9.13,100,1,18.32,700,1,7.84,100,1,18.4,100,1,7.74,700,7,19.58,500,5,,0,0,20.32,100,1,,0,0,20.48,200,2,,0,0,,0,0,,0,0,,0,0,ARL,41370961
102,2025-07-17T13:28:46.014805841Z,2025-07-17T13:28:46.014805841Z,10,2,1108,C,A,7,20.48,100,0,166310,26613841,9.99,200,2,15.3,100,1,9.67,200,2,17.12,200,2,9.29,700,1,17.6,200,2,9.13,100,1,18.32,700,1,7.84,100,1,18.4,100,1,7.74,700,7,19.58,500,5,,0,0,20.32,100,1,,0,0,20.48,100,1,,0,0,,0,0,,0,0,,0,0,ARL,38043741
103,2025-07-17T13:28:46.014805841Z,2025-07-17T13:28:46.014805841Z,10,2,1108,A,A,5,19.58,100,130,166310,26613841,9.99,200,2,15.3,100,1,9.67,200,2,17.12,200,2,9.29,700,1,17.6,200,2,9.13,100,1,18.32,700,1,7.84,100,1,18.4,100,1,7.74,700,7,19.58,600,6,,0,0,20.32,100,1,,0,0,20.48,100,1,,0,0,,0,0,,0,0,,0,0,ARL,41370965
104,2025-07-17T13:28:46.014807086Z,2025-07-17T13:28:46.014807086Z,10,2,1108,C,A,7,20.48,100,0,166257,26613842,9.99,200,2,15.3,100,1,9.67,200,2,17.12,200,2,9.29,700,1,17.6,200,2,9.13,100,1,18.32,700,1,7.84,100,1,18.4,100,1,7.74,700,7,19.58,600,6,,0,0,20.32,100,1,,0,0,,0,0,,0,0,,0,0,,0,0,,0,0,ARL,40617785
105,2025-07-17T13:28:46.014807086Z,2025-07-17T13:28:46.014807086Z,10,2,1108,A,A,5,19.58,100,130,166257,26613842,9.99,200,2,15.3,100,1,9.67,200,2,17.12,200,2,9.29,700,1,17.6,200,2,9.13,100,1,18.32,700,1,7.84,100,1,18.4,100,1,7.74,700,7,19.58,700,7,,0,0,20.32,100,1,,0,0,,0,0,,0,0,,0,0,,0,0,,0,0,ARL,41370969
106,2025-07-17T13:28:46.015523291Z,2025-07-17T13:28:46.015523291Z,10,2,1108,A,B,0,10.18,700,130,167070,26614152,10.18,700,1,15.3,100,1,9.99,200,2,17.12,200,2,9.67,200,2,17.6,200,2,9.29,700,1,18.32,700,1,9.13,100,1,18.4,100,1,7.84,100,1,19.58,700,7,7.74,700,7,20.32,100,1,,0,0,,0,0,,0,0,,0,0,,0,0,,0,0,ARL,41371221
107,2025-07-17T13:28:46.015525315Z,2025-07-17T13:28:46.015525315Z,10,2,1108,A,A,1,16.11,700,130,166302,26614155,10.18,700,1,15.3,100,1,9.99,200,2,16.11,700,1,9.67,200,2,17.12,200,2,9.29,700,1,17.6,200,2,9.13,100,1,18.32,700,1,7.84,100,1,18.4,100,1,7.74,700,7,19.58,700,7,,0,0,20.32,100,1,,0,0,,0,0,,0,0,,0,0,ARL,41371225
108,2025-07-17T13:28:46.017209641Z,2025-07-17T13:28:46.017209641Z,10,2,1108,C,A,2,17.12,100,0,165527,26614961,10.18,700,1,15.3,100,1,9.99,200,2,16.11,700,1,9.67,200,2,17.12,100,1,9.29,700,1,17.6,200,2,9.13,100,1,18.32,700,1,7.84,100,1,18.4,100,1,7.74,700,7,19.58,700,7,,0,0,20.32,100,1,,0,0,,0,0,,0,0,,0,0,ARL,41000173
109,2025-07-17T13:28:46.017209641Z,2025-07-17T13:28:46.017209641Z,10,2,1108,A,A,2,16.38,100,130,165527,26614961,10.18,700,1,15.3,100,1,9.99,200,2,16.11,700,1,9.67,200,2,16.38,100,1,9.29,700,1,17.12,100,1,9.13,100,1,17.6,200,2,7.84,100,1,18.32,700,1,7.74,700,7,18.4,100,1,,0,0,19.58,700,7,,0,0,20.32,100,1,,0,0,,0,0,ARL,41372085
110,2025-07-17T13:28:46.017260228Z,2025-07-17T13:28:46.017260228Z,10,2,1108,C,A,4,17.6,100,0,165399,26614991,10.18,700,1,15.3,100,1,9.99,200,2,16.11,700,1,9.67,200,2,16.38,100,1,9.29,700,1,17.12,100,1,9.13,100,1,17.6,100,1,7.84,100,1,18.32,700,1,7.74,700,7,18.4,100,1,,0,0,19.58,700,7,,0,0,20.32,100,1,,0,0,,0,0,ARL,40999449
111,2025-07-17T13:28:46.017260228Z,2025-07-17T13:28:46.017260228Z,10,2,1108,A,A,3,16.83,100,130,165399,26614991,10.18,700,1,15.3,100,1,9.99,200,2,16.11,700,1,9.67,200,2,16.38,100,1,9.29,700,1,16.83,100,1,9.13,100,1,17.12,100,1,7.84,100,1,17.6,100,1,7.74,700,7,18.32,700,1,,0,0,18.4,100,1,,0,0,19.58,700,7,,0,0,20.32,100,1,ARL,41372125
112,2025-07-17T13:28:46.017531156Z,2025-07-17T13:28:46.017531156Z,10,2,1108,C,A,4,17.12,100,0,165417,26615138,10.18,700,1,15.3,100,1,9.99,200,2,16.11,700,1,9.67,200,2,16.38,100,1,9.29,700,1,16.83,100,1,9.13,100,1,17.6,100,1,7.84,100,1,18.32,700,1,7.74,700,7,18.4,100,1,,0,0,19.58,700,7,,0,0,20.32,100,1,,0,0,,0,0,ARL,41021841
113,2025-07-17T13:28:46.017531156Z,2025-07-17T13:28:46.017531156Z,10,2,1108,A,A,2,16.38,100,130,165417,26615138,10.18,700,1,15.3,100,1,9.99,200,2,16.11,700,1,9.67,200,2,16.38,200,2,9.29,700,1,16.83,100,1,9.13,100,1,17.6,100,1,7.84,100,1,18.32,700,1,7.74,700,7,18.4,100,1,,0,0,19.58,700,7,,0,0,20.32,100,1,,0,0,,0,0,ARL,41372369
114,2025-07-17T13:28:46.017657609Z,2025-07-17T13:28:46.017657609Z,10,2,1108,C,A,4,17.6,100,0,165464,26615203,10.18,700,1,15.3,100,1,9.99,200,2,16.11,700,1,9.67,200,2,16.38,200,2,9.29,700,1,16.83,100,1,9.13,100,1,18.32,700,1,7.84,100,1,18.4,100,1,7.74,700,7,19.58,700,7,,0,0,20.32,100,1,,0,0,,0,0,,0,0,,0,0,ARL,41021373
115,2025-07-17T13:28:46.017657609Z,2025-07-17T13:28:46.017657609Z,10,2,1108,A,A,3,16.83,100,130,165464,26615203,10.18,700,1,15.3,100,1,9.99,200,2,16.11,700,1,9.67,200,2,16.38,200,2,9.29,700,1,16.83,200,2,9.13,100,1,18.32,700,1,7.84,100,1,18.4,100,1,7.74,700,7,19.58,700,7,,0,0,20.32,100,1,,0,0,,0,0,,0,0,,0,0,ARL,41372469
116,2025-07-17T13:28:46.017721028Z,2025-07-17T13:28:46.017721028Z,10,2,1108,C,A,5,18.4,100,0,165400,26615230,10.18,700,1,15.3,100,1,9.99,200,2,16.11,700,1,9.67,200,2,16.38,200,2,9.29,700,1,16.83,200,2,9.13,100,1,18.32,700,1,7.84,100,1,19.58,700,7,7.74,700,7,20.32,100,1,,0,0,,0,0,,0,0,,0,0,,0,0,,0,0,ARL,41032057
117,2025-07-17T13:28:46.017721028Z,2025-07-17T13:28:46.017721028Z,10,2,1108,A,A,4,17.6,100,130,165400,26615230,10.18,700,1,15.3,100,1,9.99,200,2,16.11,700,1,9.67,200,2,16.38,200,2,9.29,700,1,16.83,200,2,9.13,100,1,17.6,100,1,7.84,100,1,18.32,700,1,7.74,700,7,19.58,700,7,,0,0,20.32,100,1,,0,0,,0,0,,0,0,,0,0,ARL,41372493
118,2025-07-17T13:28:46.017837874Z,2025-07-17T13:28:46.017837874Z,10,2,1108,C,A,7,20.32,100,0,165245,26615283,10.18,700,1,15.3,100,1,9.99,200,2,16.11,700,1,9.67,200,2,16.38,200,2,9.29,700,1,16.83,200,2,9.13,100,1,17.6,100,1,7.84,100,1,18.32,700,1,7.74,700,7,19.58,700,7,,0,0,,0,0,,0,0,,0,0,,0,0,,0,0,ARL,41306445
119,2025-07-17T13:28:46.017837874Z,2025-07-17T13:28:46.017837874Z,10,2,1108,A,A,6,19.44,100,130,165245,26615283,10.18,700,1,15.3,100,1,9.99,200,2,16.11,700,1,9.67,200,2,16.38,200,2,9.29,700,1,16.83,200,2,9.13,100,1,17.6,100,1,7.84,100,1,18.32,700,1,7.74,700,7,19.44,100,1,,0,0,19.58,700,7,,0,0,,0,0,,0,0,,0,0,ARL,41372549
120,2025-07-17T13:28:46.022095254Z,2025-07-17T13:28:46.022095254Z,10,2,1108,A,B,1,10.05,700,128,167174,26616844,10.18,700,1,15.3,100,1,10.05,700,1,16.11,700,1,9.99,200,2,16.38,200,2,9.67,200,2,16.83,200,2,9.29,700,1,17.6,100,1,9.13,100,1,18.32,700,1,7.84,100,1,19.44,100,1,7.74,700,7,19.58,700,7,,0,0,,0,0,,0,0,,0,0,ARL,41375793
121,2025-07-17T13:28:46.022822832Z,2025-07-17T13:28:46.022822832Z,10,2,1108,A,A,2,16.3,700,130,165231,26617168,10.18,700,1,15.3,100,1,10.05,700,1,16.11,700,1,9.99,200,2,16.3,700,1,9.67,200,2,16.38,200,2,9.29,700,1,16.83,200,2,9.13,100,1,17.6,100,1,7.84,100,1,18.32,700,1,7.74,700,7,19.44,100,1,,0,0,19.58,700,7,,0,0,,0,0,ARL,41375973
122,2025-07-17T13:28:46.025816567Z,2025-07-17T13:28:46.025816567Z,10,2,1108,A,B,0,11.76,100,130,165012,26618403,11.76,100,1,15.3,100,1,10.18,700,1,16.11,700,1,10.05,700,1,16.3,700,1,9.99,200,2,16.38,200,2,9.67,200,2,16.83,200,2,9.29,700,1,17.6,100,1,9.13,100,1,18.32,700,1,7.84,100,1,19.44,100,1,7.74,700,7,19.58,700,7,,0,0,,0,0,ARL,41376297
123,2025-07-17T13:28:46.025870563Z,2025-07-17T13:28:46.025870563Z,10,2,1108,C,B,8,7.74,100,0,166599,26618436,11.76,100,1,15.3,100,1,10.18,700,1,16.11,700,1,10.05,700,1,16.3,700,1,9.99,200,2,16.38,200,2,9.67,200,2,16.83,200,2,9.29,700,1,17.6,100,1,9.13,100,1,18.32,700,1,7.84,100,1,19.44,100,1,7.74,600,6,19.58,700,7,,0,0,,0,0,ARL,23616197
124,2025-07-17T13:28:46.025870563Z,2025-07-17T13:28:46.025870563Z,10,2,1108,A,B,7,8.47,100,130,166599,26618436,11.76,100,1,15.3,100,1,10.18,700,1,16.11,700,1,10.05,700,1,16.3,700,1,9.99,200,2,16.38,200,2,9.67,200,2,16.83,200,2,9.29,700,1,17.6,100,1,9.13,100,1,18.32,700,1,8.47,100,1,19.44,100,1,7.84,100,1,19.58,700,7,7.74,600,6,,0,0,ARL,41376333
125,2025-07-17T13:28:46.025872146Z,2025-07-17T13:28:46.025872146Z,10,2,1108,C,B,9,7.74,100,0,165912,26618438,11.76,100,1,15.3,100,1,10.18,700,1,16.11,700,1,10.05,700,1,16.3,700,1,9.99,200,2,16.38,200,2,9.67,200,2,16.83,200,2,9.29,700,1,17.6,100,1,9.13,100,1,18.32,700,1,8.47,100,1,19.44,100,1,7.84,100,1,19.58,700,7,7.74,500,5,,0,0,ARL,23622101
126,2025-07-17T13:28:46.025872146Z,2025-07-17T13:28:46.025872146Z,10,2,1108,A,B,7,8.47,100,130,165912,26618438,11.76,100,1,15.3,100,1,10.18,700,1,16.11,700,1,10.05,700,1,16.3,700,1,9.99,200,2,16.38,200,2,9.67,200,2,16.83,200,2,9.29,700,1,17.6,100,1,9.13,100,1,18.32,700,1,8.47,200,2,19.44,100,1,7.84,100,1,19.58,700,7,7.74,500,5,,0,0,ARL,41376337
127,2025-07-17T13:28:46.025873388Z,2025-07-17T13:28:46.025873388Z,10,2,1108,C,B,9,7.74,100,0,166299,26618439,11.76,100,1,15.3,100,1,10.18,700,1,16.11,700,1,10.05,700,1,16.3,700,1,9.99,200,2,16.38,200,2,9.67,200,2,16.83,200,2,9.29,700,1,17.6,100,1,9.13,100,1,18.32,700,1,8.47,200,2,19.44,100,1,7.84,100,1,19.58,700,7,7.74,400,4,,0,0,ARL,24102329
128,2025-07-17T13:28:46.025873388Z,2025-07-17T13:28:46.025873388Z,10,2,1108,A,B,7,8.47,100,128,166299,26618439,11.76,100,1,15.3,100,1,10.18,700,1,16.11,700,1,10.05,700,1,16.3,700,1,9.99,200,2,16.38,200,2,9.67,200,2,16.83,200,2,9.29,700,1,17.6,100,1,9.13,100,1,18.32,700,1,8.47,300,3,19.44,100,1,7.84,100,1,19.58,700,7,7.74,400,4,,0,0,ARL,41376341
129,2025-07-17T13:28:46.025874774Z,2025-07-17T13:28:46.025874774Z,10,2,1108,C,B,9,7.74,100,0,170905,26618441,11.76,100,1,15.3,100,1,10.18,700,1,16.11,700,1,10.05,700,1,16.3,700,1,9.99,200,2,16.38,200,2,9.67,200,2,16.83,200,2,9.29,700,1,17.6,100,1,9.13,100,1,18.32,700,1,8.47,300,3,19.44,100,1,7.84,100,1,19.58,700,7,7.74,300,3,,0,0,ARL,31960841
130,2025-07-17T13:28:46.025874774Z,2025-07-17T13:28:46.025874774Z,10,2,1108,A,B,7,8.47,100,0,170905,26618441,11.76,100,1,15.3,100,1,10.18,700,1,16.11,700,1,10.05,700,1,16.3,700,1,9.99,200,2,16.38,200,2,9.67,200,2,16.83,200,2,9.29,700,1,17.6,100,1,9.13,100,1,18.32,700,1,8.47,400,4,19.44,100,1,7.84,100,1,19.58,700,7,7.74,300,3,,0,0,ARL,41376345
131,2025-07-17T13:28:46.025875041Z,2025-07-17T13:28:46.025875041Z,10,2,1108,C,B,9,7.74,100,0,170638,26618442,11.76,100,1,15.3,100,1,10.18,700,1,16.11,700,1,10.05,700,1,16.3,700,1,9.99,200,2,16.38,200,2,9.67,200,2,16.83,200,2,9.29,700,1,17.6,100,1,9.13,100,1,18.32,700,1,8.47,400,4,19.44,100,1,7.84,100,1,19.58,700,7,7.74,200,2,,0,0,ARL,33574717
132,2025-07-17T13:28:46.025875041Z,2025-07-17T13:28:46.025875041Z,10,2,1108,A,B,7,8.47,100,0,170638,26618442,11.76,100,1,15.3,100,1,10.18,700,1,16.11,700,1,10.05,700,1,16.3,700,1,9.99,200,2,16.38,200,2,9.67,200,2,16.83,200,2,9.29,700,1,17.6,100,1,9.13,100,1,18.32,700,1,8.47,500,5,19.44,100,1,7.84,100,1,19.58,700,7,7.74,200,2,,0,0,ARL,41376349
133,2025-07-17T13:28:46.025875401Z,2025-07-17T13:28:46.025875401Z,10,2,1108,C,B,9,7.74,100,0,170278,26618443,11.76,100,1,15.3,100,1,10.18,700,1,16.11,700,1,10.05,700,1,16.3,700,1,9.99,200,2,16.38,200,2,9.67,200,2,16.83,200,2,9.29,700,1,17.6,100,1,9.13,100,1,18.32,700,1,8.47,500,5,19.44,100,1,7.84,100,1,19.58,700,7,7.74,100,1,,0,0,ARL,38041417
134,2025-07-17T13:28:46.025875401Z,2025-07-17T13:28:46.025875401Z,10,2,1108,A,B,7,8.47,100,0,170278,26618443,11.76,100,1,15.3,100,1,10.18,700,1,16.11,700,1,10.05,700,1,16.3,700,1,9.99,200,2,16.38,200,2,9.67,200,2,16.83,200,2,9.29,700,1,17.6,100,1,9.13,100,1,18.32,700,1,8.47,600,6,19.44,100,1,7.84,100,1,19.58,700,7,7.74,100,1,,0,0,ARL,41376353
135,2025-07-17T13:28:46.025877502Z,2025-07-17T13:28:46.025877502Z,10,2,1108,C,B,9,7.74,100,0,168177,26618447,11.76,100,1,15.3,100,1,10.18,700,1,16.11,700,1,10.05,700,1,16.3,700,1,9.99,200,2,16.38,200,2,9.67,200,2,16.83,200,2,9.29,700,1,17.6,100,1,9.13,100,1,18.32,700,1,8.47,600,6,19.44,100,1,7.84,100,1,19.58,700,7,,0,0,,0,0,ARL,40617777
136,2025-07-17T13:28:46.025877502Z,2025-07-17T13:28:46.025877502Z,10,2,1108,A,B,7,8.47,100,130,168177,26618447,11.76,100,1,15.3,100,1,10.18,700,1,16.11,700,1,10.05,700,1,16.3,700,1,9.99,200,2,16.38,200,2,9.67,200,2,16.83,200,2,9.29,700,1,17.6,100,1,9.13,100,1,18.32,700,1,8.47,700,7,19.44,100,1,7.84,100,1,19.58,700,7,,0,0,,0,0,ARL,41376357
137,2025-07-17T13:28:46.027560174Z,2025-07-17T13:28:46.027560174Z,10,2,1108,C,B,3,9.99,100,0,165509,26619144,11.76,100,1,15.3,100,1,10.18,700,1,16.11,700,1,10.05,700,1,16.3,700,1,9.99,100,1,16.38,200,2,9.67,200,2,16.83,200,2,9.29,700,1,17.6,100,1,9.13,100,1,18.32,700,1,8.47,700,7,19.44,100,1,7.84,100,1,19.58,700,7,,0,0,,0,0,ARL,41000165
138,2025-07-17T13:28:46.027560174Z,2025-07-17T13:28:46.027560174Z,10,2,1108,A,B,1,10.93,100,130,165509,26619144,11.76,100,1,15.3,100,1,10.93,100,1,16.11,700,1,10.18,700,1,16.3,700,1,10.05,700,1,16.38,200,2,9.99,100,1,16.83,200,2,9.67,200,2,17.6,100,1,9.29,700,1,18.32,700,1,9.13,100,1,19.44,100,1,8.47,700,7,19.58,700,7,7.84,100,1,,0,0,ARL,41376501
139,2025-07-17T13:28:46.029556957Z,2025-07-17T13:28:46.029556957Z,10,2,1108,C,B,5,9.67,100,0,169828,26619966,11.76,100,1,15.3,100,1,10.93,100,1,16.11,700,1,10.18,700,1,16.3,700,1,10.05,700,1,16.38,200,2,9.99,100,1,16.83,200,2,9.67,100,1,17.6,100,1,9.29,700,1,18.32,700,1,9.13,100,1,19.44,100,1,8.47,700,7,19.58,700,7,7.84,100,1,,0,0,ARL,40999441
140,2025-07-17T13:28:46.029556957Z,2025-07-17T13:28:46.029556957Z,10,2,1108,A,B,2,10.58,100,128,169828,26619966,11.76,100,1,15.3,100,1,10.93,100,1,16.11,700,1,10.58,100,1,16.3,700,1,10.18,700,1,16.38,200,2,10.05,700,1,16.83,200,2,9.99,100,1,17.6,100,1,9.67,100,1,18.32,700,1,9.29,700,1,19.44,100,1,9.13,100,1,19.58,700,7,8.47,700,7,,0,0,ARL,41376725
141,2025-07-17T13:28:46.029609064Z,2025-07-17T13:28:46.029609064Z,10,2,1108,C,B,10,7.84,100,0,166186,26619999,11.76,100,1,15.3,100,1,10.93,100,1,16.11,700,1,10.58,100,1,16.3,700,1,10.18,700,1,16.38,200,2,10.05,700,1,16.83,200,2,9.99,100,1,17.6,100,1,9.67,100,1,18.32,700,1,9.29,700,1,19.44,100,1,9.13,100,1,19.58,700,7,8.47,700,7,,0,0,ARL,41306441
142,2025-07-17T13:28:46.029609064Z,2025-07-17T13:28:46.029609064Z,10,2,1108,A,B,9,8.58,100,130,166186,26619999,11.76,100,1,15.3,100,1,10.93,100,1,16.11,700,1,10.58,100,1,16.3,700,1,10.18,700,1,16.38,200,2,10.05,700,1,16.83,200,2,9.99,100,1,17.6,100,1,9.67,100,1,18.32,700,1,9.29,700,1,19.44,100,1,9.13,100,1,19.58,700,7,8.58,100,1,,0,0,ARL,41376733
143,2025-07-17T13:28:46.031073916Z,2025-07-17T13:28:46.031073916Z,10,2,1108,C,B,8,9.13,100,0,165536,26620530,11.76,100,1,15.3,100,1,10.93,100,1,16.11,700,1,10.58,100,1,16.3,700,1,10.18,700,1,16.38,200,2,10.05,700,1,16.83,200,2,9.99,100,1,17.6,100,1,9.67,100,1,18.32,700,1,9.29,700,1,19.44,100,1,8.58,100,1,19.58,700,7,8.47,700,7,,0,0,ARL,41032049
144,2025-07-17T13:28:46.031073916Z,2025-07-17T13:28:46.031073916Z,10,2,1108,A,B,5,9.99,100,130,165536,26620530,11.76,100,1,15.3,100,1,10.93,100,1,16.11,700,1,10.58,100,1,16.3,700,1,10.18,700,1,16.38,200,2,10.05,700,1,16.83,200,2,9.99,200,2,17.6,100,1,9.67,100,1,18.32,700,1,9.29,700,1,19.44,100,1,8.58,100,1,19.58,700,7,8.47,700,7,,0,0,ARL,41376769
145,2025-07-17T13:28:46.037954661Z,2025-07-17T13:28:46.037954661Z,10,2,1108,C,B,6,9.67,100,0,166331,26623213,11.76,100,1,15.3,100,1,10.93,100,1,16.11,700,1,10.58,100,1,16.3,700,1,10.18,700,1,16.38,200,2,10.05,700,1,16.83,200,2,9.99,200,2,17.6,100,1,9.29,700,1,18.32,700,1,8.58,100,1,19.44,100,1,8.47,700,7,19.58,700,7,,0,0,,0,0,ARL,41021369
146,2025-07-17T13:28:46.037954661Z,2025-07-17T13:28:46.037954661Z,10,2,1108,A,B,2,10.58,100,128,166331,26623213,11.76,100,1,15.3,100,1,10.93,100,1,16.11,700,1,10.58,200,2,16.3,700,1,10.18,700,1,16.38,200,2,10.05,700,1,16.83,200,2,9.99,200,2,17.6,100,1,9.29,700,1,18.32,700,1,8.58,100,1,19.44,100,1,8.47,700,7,19.58,700,7,,0,0,,0,0,ARL,41377117
147,2025-07-17T13:28:46.042858782Z,2025-07-17T13:28:46.042858782Z,10,2,1108,C,B,5,9.99,100,0,165640,26625366,11.76,100,1,15.3,100,1,10.93,100,1,16.11,700,1,10.58,200,2,16.3,700,1,10.18,700,1,16.38,200,2,10.05,700,1,16.83,200,2,9.99,100,1,17.6,100,1,9.29,700,1,18.32,700,1,8.58,100,1,19.44,100,1,8.47,700,7,19.58,700,7,,0,0,,0,0,ARL,41021837
148,2025-07-17T13:28:46.042858782Z,2025-07-17T13:28:46.042858782Z,10,2,1108,A,B,1,10.93,100,130,165640,26625366,11.76,100,1,15.3,100,1,10.93,200,2,16.11,700,1,10.58,200,2,16.3,700,1,10.18,700,1,16.38,200,2,10.05,700,1,16.83,200,2,9.99,100,1,17.6,100,1,9.29,700,1,18.32,700,1,8.58,100,1,19.44,100,1,8.47,700,7,19.58,700,7,,0,0,,0,0,ARL,41379985
149,2025-07-17T13:28:52.312295020Z,2025-07-17T13:28:52.312295020Z,10,2,1108,A,B,2,10.75,700,130,165354,26806665,11.76,100,1,15.3,100,1,10.93,200,2,16.11,700,1,10.75,700,1,16.3,700,1,10.58,200,2,16.38,200,2,10.18,700,1,16.83,200,2,10.05,700,1,17.6,100,1,9.99,100,1,18.32,700,1,9.29,700,1,19.44,100,1,8.58,100,1,19.58,700,7,8.47,700,7,,0,0,ARL,41507073
150,2025-07-17T13:28:52.312330796Z,2025-07-17T13:28:52.312330796Z,10,2,1108,C,B,5,10.05,700,130,165236,26806666,11.76,100,1,15.3,100,1,10.93,200,2,16.11,700,1,10.75,700,1,16.3,700,1,10.58,200,2,16.38,200,2,10.18,700,1,16.83,200,2,9.99,100,1,17.6,100,1,9.29,700,1,18.32,700,1,8.58,100,1,19.44,100,1,8.47,700,7,19.58,700,7,,0,0,,0,0,ARL,41375793
151,2025-07-17T13:28:52.512292648Z,2025-07-17T13:28:52.512292648Z,10,2,1108,A,B,1,10.99,700,130,165261,26808221,11.76,100,1,15.3,100,1,10.99,700,1,16.11,700,1,10.93,200,2,16.3,700,1,10.75,700,1,16.38,200,2,10.58,200,2,16.83,200,2,10.18,700,1,17.6,100,1,9.99,100,1,18.32,700,1,9.29,700,1,19.44,100,1,8.58,100,1,19.58,700,7,8.47,700,7,,0,0,ARL,41509393
152,2025-07-17T13:28:52.513090520Z,2025-07-17T13:28:52.513090520Z,10,2,1108,C,B,3,10.75,700,130,165032,26808222,11.76,100,1,15.3,100,1,10.99,700,1,16.11,700,1,10.93,200,2,16.3,700,1,10.58,200,2,16.38,200,2,10.18,700,1,16.83,200,2,9.99,100,1,17.6,100,1,9.29,700,1,18.32,700,1,8.58,100,1,19.44,100,1,8.47,700,7,19.58,700,7,,0,0,,0,0,ARL,41507073
153,2025-07-17T13:28:53.957067631Z,2025-07-17T13:28:53.957067631Z,10,2,1108,A,A,2,16.15,700,130,165517,26835971,11.76,100,1,15.3,100,1,10.99,700,1,16.11,700,1,10.93,200,2,16.15,700,1,10.58,200,2,16.3,700,1,10.18,700,1,16.38,200,2,9.99,100,1,16.83,200,2,9.29,700,1,17.6,100,1,8.58,100,1,18.32,700,1,8.47,700,7,19.44,100,1,,0,0,19.58,700,7,ARL,41528029
154,2025-07-17T13:28:53.957116061Z,2025-07-17T13:28:53.957116061Z,10,2,1108,C,A,7,18.32,700,130,165456,26835974,11.76,100,1,15.3,100,1,10.99,700,1,16.11,700,1,10.93,200,2,16.15,700,1,10.58,200,2,16.3,700,1,10.18,700,1,16.38,200,2,9.99,100,1,16.83,200,2,9.29,700,1,17.6,100,1,8.58,100,1,19.44,100,1,8.47,700,7,19.58,700,7,,0,0,,0,0,ARL,40846101
155,2025-07-17T13:28:54.128310778Z,2025-07-17T13:28:54.128310778Z,10,2,1108,A,B,5,9.99,700,130,165441,26850111,11.76,100,1,15.3,100,1,10.99,700,1,16.11,700,1,10.93,200,2,16.15,700,1,10.58,200,2,16.3,700,1,10.18,700,1,16.38,200,2,9.99,800,2,16.83,200,2,9.29,700,1,17.6,100,1,8.58,100,1,19.44,100,1,8.47,700,7,19.58,700,7,,0,0,,0,0,ARL,41530665
156,2025-07-17T13:28:54.128338727Z,2025-07-17T13:28:54.128338727Z,10,2,1108,C,B,6,9.29,700,130,165207,26850112,11.76,100,1,15.3,100,1,10.99,700,1,16.11,700,1,10.93,200,2,16.15,700,1,10.58,200,2,16.3,700,1,10.18,700,1,16.38,200,2,9.99,800,2,16.83,200,2,8.58,100,1,17.6,100,1,8.47,700,7,19.44,100,1,,0,0,19.58,700,7,,0,0,,0,0,ARL,40851989
157,2025-07-17T13:28:54.328487063Z,2025-07-17T13:28:54.328487063Z,10,2,1108,A,B,4,10.26,700,130,165274,26851888,11.76,100,1,15.3,100,1,10.99,700,1,16.11,700,1,10.93,200,2,16.15,700,1,10.58,200,2,16.3,700,1,10.26,700,1,16.38,200,2,10.18,700,1,16.83,200,2,9.99,800,2,17.6,100,1,8.58,100,1,19.44,100,1,8.47,700,7,19.58,700,7,,0,0,,0,0,ARL,41533513
158,2025-07-17T13:28:54.328519057Z,2025-07-17T13:28:54.328519057Z,10,2,1108,C,B,6,9.99,700,130,165029,26851889,11.76,100,1,15.3,100,1,10.99,700,1,16.11,700,1,10.93,200,2,16.15,700,1,10.58,200,2,16.3,700,1,10.26,700,1,16.38,200,2,10.18,700,1,16.83,200,2,9.99,100,1,17.6,100,1,8.58,100,1,19.44,100,1,8.47,700,7,19.58,700,7,,0,0,,0,0,ARL,41530665
159,2025-07-17T13:28:54.477455479Z,2025-07-17T13:28:54.477455479Z,10,2,1108,A,B,1,11.14,700,130,165275,26853475,11.76,100,1,15.3,100,1,11.14,700,1,16.11,700,1,10.99,700,1,16.15,700,1,10.93,200,2,16.3,700,1,10.58,200,2,16.38,200,2,10.26,700,1,16.83,200,2,10.18,700,1,17.6,100,1,9.99,100,1,19.44,100,1,8.58,100,1,19.58,700,7,8.47,700,7,,0,0,ARL,41534785
160,2025-07-17T13:28:54.477852651Z,2025-07-17T13:28:54.477852651Z,10,2,1108,C,B,6,10.18,700,130,165350,26853478,11.76,100,1,15.3,100,1,11.14,700,1,16.11,700,1,10.99,700,1,16.15,700,1,10.93,200,2,16.3,700,1,10.58,200,2,16.38,200,2,10.26,700,1,16.83,200,2,9.99,100,1,17.6,100,1,8.58,100,1,19.44,100,1,8.47,700,7,19.58,700,7,,0,0,,0,0,ARL,41371221
161,2025-07-17T13:28:54.528542919Z,2025-07-17T13:28:54.528542919Z,10,2,1108,A,B,5,10.53,700,130,165324,26853925,11.76,100,1,15.3,100,1,11.14,700,1,16.11,700,1,10.99,700,1,16.15,700,1,10.93,200,2,16.3,700,1,10.58,200,2,16.38,200,2,10.53,700,1,16.83,200,2,10.26,700,1,17.6,100,1,9.99,100,1,19.44,100,1,8.58,100,1,19.58,700,7,8.47,700,7,,0,0,ARL,41535173
162,2025-07-17T13:28:54.528571375Z,2025-07-17T13:28:54.528571375Z,10,2,1108,C,B,6,10.26,700,130,165179,26853926,11.76,100,1,15.3,100,1,11.14,700,1,16.11,700,1,10.99,700,1,16.15,700,1,10.93,200,2,16.3,700,1,10.58,200,2,16.38,200,2,10.53,700,1,16.83,200,2,9.99,100,1,17.6,100,1,8.58,100,1,19.44,100,1,8.47,700,7,19.58,700,7,,0,0,,0,0,ARL,41533513
163,2025-07-17T13:28:54.728575124Z,2025-07-17T13:28:54.728575124Z,10,2,1108,A,B,4,10.8,700,130,165189,26856081,11.76,100,1,15.3,100,1,11.14,700,1,16.11,700,1,10.99,700,1,16.15,700,1,10.93,200,2,16.3,700,1,10.8,700,1,16.38,200,2,10.58,200,2,16.83,200,2,10.53,700,1,17.6,100,1,9.99,100,1,19.44,100,1,8.58,100,1,19.58,700,7,8.47,700,7,,0,0,ARL,41537525
164,2025-07-17T13:28:54.728651317Z,2025-07-17T13:28:54.728651317Z,10,2,1108,C,B,6,10.53,700,130,164958,26856082,11.76,100,1,15.3,100,1,11.14,700,1,16.11,700,1,10.99,700,1,16.15,700,1,10.93,200,2,16.3,700,1,10.8,700,1,16.38,200,2,10.58,200,2,16.83,200,2,9.99,100,1,17.6,100,1,8.58,100,1,19.44,100,1,8.47,700,7,19.58,700,7,,0,0,,0,0,ARL,41535173
165,2025-07-17T13:28:54.928412211Z,2025-07-17T13:28:54.928412211Z,10,2,1108,A,B,2,11.07,700,130,165195,26858349,11.76,100,1,15.3,100,1,11.14,700,1,16.11,700,1,11.07,700,1,16.15,700,1,10.99,700,1,16.3,700,1,10.93,200,2,16.38,200,2,10.8,700,1,16.83,200,2,10.58,200,2,17.6,100,1,9.99,100,1,19.44,100,1,8.58,100,1,19.58,700,7,8.47,700,7,,0,0,ARL,41539477
166,2025-07-17T13:28:54.928488170Z,2025-07-17T13:28:54.928488170Z,10,2,1108,C,B,5,10.8,700,130,165133,26858351,11.76,100,1,15.3,100,1,11.14,700,1,16.11,700,1,11.07,700,1,16.15,700,1,10.99,700,1,16.3,700,1,10.93,200,2,16.38,200,2,10.58,200,2,16.83,200,2,9.99,100,1,17.6,100,1,8.58,100,1,19.44,100,1,8.47,700,7,19.58,700,7,,0,0,,0,0,ARL,41537525
167,2025-07-17T13:29:00.583110843Z,2025-07-17T13:29:00.583110843Z,10,2,1108,A,B,5,10.84,100,130,165620,27000961,11.76,100,1,15.3,100,1,11.14,700,1,16.11,700,1,11.07,700,1,16.15,700,1,10.99,700,1,16.3,700,1,10.93,200,2,16.38,200,2,10.84,100,1,16.83,200,2,10.58,200,2,17.6,100,1,9.99,100,1,19.44,100,1,8.58,100,1,19.58,700,7,8.47,700,7,,0,0,ARL,41635065
168,2025-07-17T13:29:00.583124331Z,2025-07-17T13:29:00.583124331Z,10,2,1108,A,A,5,16.49,100,130,165469,27000962,11.76,100,1,15.3,100,1,11.14,700,1,16.11,700,1,11.07,700,1,16.15,700,1,10.99,700,1,16.3,700,1,10.93,200,2,16.38,200,2,10.84,100,1,16.49,100,1,10.58,200,2,16.83,200,2,9.99,100,1,17.6,100,1,8.58,100,1,19.44,100,1,8.47,700,7,19.58,700,7,ARL,41635069
169,2025-07-17T13:29:31.666485583Z,2025-07-17T13:29:31.666485583Z,10,2,1108,A,B,3,11.05,100,130,165401,27592251,11.76,100,1,15.3,100,1,11.14,700,1,16.11,700,1,11.07,700,1,16.15,700,1,11.05,100,1,16.3,700,1,10.99,700,1,16.38,200,2,10.93,200,2,16.49,100,1,10.84,100,1,16.83,200,2,10.58,200,2,17.6,100,1,9.99,100,1,19.44,100,1,8.58,100,1,19.58,700,7,ARL,42089321
170,2025-07-17T13:29:31.666510533Z,2025-07-17T13:29:31.666510533Z,10,2,1108,A,A,3,16.22,100,130,165507,27592252,11.76,100,1,15.3,100,1,11.14,700,1,16.11,700,1,11.07,700,1,16.15,700,1,11.05,100,1,16.22,100,1,10.99,700,1,16.3,700,1,10.93,200,2,16.38,200,2,10.84,100,1,16.49,100,1,10.58,200,2,16.83,200,2,9.99,100,1,17.6,100,1,8.58,100,1,19.44,100,1,ARL,42089325
171,2025-07-17T13:29:32.011088073Z,2025-07-17T13:29:32.011088073Z,10,2,1108,A,B,1,11.29,100,130,165263,27599196,11.76,100,1,15.3,100,1,11.29,100,1,16.11,700,1,11.14,700,1,16.15,700,1,11.07,700,1,16.22,100,1,11.05,100,1,16.3,700,1,10.99,700,1,16.38,200,2,10.93,200,2,16.49,100,1,10.84,100,1,16.83,200,2,10.58,200,2,17.6,100,1,9.99,100,1,19.44,100,1,ARL,42099317
172,2025-07-17T13:29:32.011092154Z,2025-07-17T13:29:32.011092154Z,10,2,1108,A,A,1,15.91,100,130,165147,27599197,11.76,100,1,15.3,100,1,11.29,100,1,15.91,100,1,11.14,700,1,16.11,700,1,11.07,700,1,16.15,700,1,11.05,100,1,16.22,100,1,10.99,700,1,16.3,700,1,10.93,200,2,16.38,200,2,10.84,100,1,16.49,100,1,10.58,200,2,16.83,200,2,9.99,100,1,17.6,100,1,ARL,42099321
173,2025-07-17T13:29:55.529183618Z,2025-07-17T13:29:55.529183618Z,10,2,1108,A,B,1,11.52,100,130,165379,28123971,11.76,100,1,15.3,100,1,11.52,100,1,15.91,100,1,11.29,100,1,16.11,700,1,11.14,700,1,16.15,700,1,11.07,700,1,16.22,100,1,11.05,100,1,16.3,700,1,10.99,700,1,16.38,200,2,10.93,200,2,16.49,100,1,10.84,100,1,16.83,200,2,10.58,200,2,17.6,100,1,ARL,42446497
174,2025-07-17T13:29:55.529200619Z,2025-07-17T13:29:55.529200619Z,10,2,1108,A,A,1,15.61,100,130,165283,28123973,11.76,100,1,15.3,100,1,11.52,100,1,15.61,100,1,11.29,100,1,15.91,100,1,11.14,700,1,16.11,700,1,11.07,700,1,16.15,700,1,11.05,100,1,16.22,100,1,10.99,700,1,16.3,700,1,10.93,200,2,16.38,200,2,10.84,100,1,16.49,100,1,10.58,200,2,16.83,200,2,ARL,42446501
175,2025-07-17T13:29:59.677285294Z,2025-07-17T13:29:59.677285294Z,10,2,1108,A,B,10,10.11,100,130,165389,28321241,11.76,100,1,15.3,100,1,11.52,100,1,15.61,100,1,11.29,100,1,15.91,100,1,11.14,700,1,16.11,700,1,11.07,700,1,16.15,700,1,11.05,100,1,16.22,100,1,10.99,700,1,16.3,700,1,10.93,200,2,16.38,200,2,10.84,100,1,16.49,100,1,10.58,200,2,16.83,200,2,ARL,42583289
176,2025-07-17T13:29:59.677290064Z,2025-07-17T13:29:59.677290064Z,10,2,1108,A,A,10,17.45,100,128,167123,28321242,11.76,100,1,15.3,100,1,11.52,100,1,15.61,100,1,11.29,100,1,15.91,100,1,11.14,700,1,16.11,700,1,11.07,700,1,16.15,700,1,11.05,100,1,16.22,100,1,10.99,700,1,16.3,700,1,10.93,200,2,16.38,200,2,10.84,100,1,16.49,100,1,10.58,200,2,16.83,200,2,ARL,42583293
177,2025-07-17T13:30:00.092900330Z,2025-07-17T13:30:00.092900330Z,10,2,1108,A,B,6,11.01,100,128,185149,28409476,11.76,100,1,15.3,100,1,11.52,100,1,15.61,100,1,11.29,100,1,15.91,100,1,11.14,700,1,16.11,700,1,11.07,700,1,16.15,700,1,11.05,100,1,16.22,100,1,11.01,100,1,16.3,700,1,10.99,700,1,16.38,200,2,10.93,200,2,16.49,100,1,10.84,100,1,16.83,200,2,ARL,42674817
178,2025-07-17T13:30:00.092988904Z,2025-07-17T13:30:00.092988904Z,10,2,1108,A,A,3,16.1,100,128,175662,28409593,11.76,100,1,15.3,100,1,11.52,100,1,15.61,100,1,11.29,100,1,15.91,100,1,11.14,700,1,16.1,100,1,11.07,700,1,16.11,700,1,11.05,100,1,16.15,700,1,11.01,100,1,16.22,100,1,10.99,700,1,16.3,700,1,10.93,200,2,16.38,200,2,10.84,100,1,16.49,100,1,ARL,42674989
179,2025-07-17T13:30:00.675553569Z,2025-07-17T13:30:00.675553569Z,10,2,1108,A,B,9,10.92,100,128,171792,28833560,11.76,100,1,15.3,100,1,11.52,100,1,15.61,100,1,11.29,100,1,15.91,100,1,11.14,700,1,16.1,100,1,11.07,700,1,16.11,700,1,11.05,100,1,16.15,700,1,11.01,100,1,16.22,100,1,10.99,700,1,16.3,700,1,10.93,200,2,16.38,200,2,10.92,100,1,16.49,100,1,ARL,43143317
180,2025-07-17T13:30:00.675570319Z,2025-07-17T13:30:00.675570319Z,10,2,1108,A,A,6,16.2,100,128,178220,28833574,11.76,100,1,15.3,100,1,11.52,100,1,15.61,100,1,11.29,100,1,15.91,100,1,11.14,700,1,16.1,100,1,11.07,700,1,16.11,700,1,11.05,100,1,16.15,700,1,11.01,100,1,16.2,100,1,10.99,700,1,16.22,100,1,10.93,200,2,16.3,700,1,10.92,100,1,16.38,200,2,ARL,43143333
181,2025-07-17T13:30:00.730688348Z,2025-07-17T13:30:00.730688348Z,10,2,1108,A,B,9,10.92,100,130,170880,28858298,11.76,100,1,15.3,100,1,11.52,100,1,15.61,100,1,11.29,100,1,15.91,100,1,11.14,700,1,16.1,100,1,11.07,700,1,16.11,700,1,11.05,100,1,16.15,700,1,11.01,100,1,16.2,100,1,10.99,700,1,16.22,100,1,10.93,200,2,16.3,700,1,10.92,200,2,16.38,200,2,ARL,43191333
182,2025-07-17T13:30:00.730693126Z,2025-07-17T13:30:00.730693126Z,10,2,1108,A,A,6,16.2,100,128,174279,28858300,11.76,100,1,15.3,100,1,11.52,100,1,15.61,100,1,11.29,100,1,15.91,100,1,11.14,700,1,16.1,100,1,11.07,700,1,16.11,700,1,11.05,100,1,16.15,700,1,11.01,100,1,16.2,200,2,10.99,700,1,16.22,100,1,10.93,200,2,16.3,700,1,10.92,200,2,16.38,200,2,ARL,43191369
183,2025-07-17T13:30:00.869883482Z,2025-07-17T13:30:00.869883482Z,10,2,1108,A,B,3,11.24,100,128,173434,28963823,11.76,100,1,15.3,100,1,11.52,100,1,15.61,100,1,11.29,100,1,15.91,100,1,11.24,100,1,16.1,100,1,11.14,700,1,16.11,700,1,11.07,700,1,16.15,700,1,11.05,100,1,16.2,200,2,11.01,100,1,16.22,100,1,10.99,700,1,16.3,700,1,10.93,200,2,16.38,200,2,ARL,43313941
184,2025-07-17T13:30:00.869917271Z,2025-07-17T13:30:00.869917271Z,10,2,1108,A,A,3,15.98,100,130,169036,28963843,11.76,100,1,15.3,100,1,11.52,100,1,15.61,100,1,11.29,100,1,15.91,100,1,11.24,100,1,15.98,100,1,11.14,700,1,16.1,100,1,11.07,700,1,16.11,700,1,11.05,100,1,16.15,700,1,11.01,100,1,16.2,200,2,10.99,700,1,16.22,100,1,10.93,200,2,16.3,700,1,ARL,43314009
185,2025-07-17T13:30:00.870273955Z,2025-07-17T13:30:00.870273955Z,10,2,1108,C,B,3,11.24,100,0,178095,28964259,11.76,100,1,15.3,100,1,11.52,100,1,15.61,100,1,11.29,100,1,15.91,100,1,11.14,700,1,15.98,100,1,11.07,700,1,16.1,100,1,11.05,100,1,16.11,700,1,11.01,100,1,16.15,700,1,10.99,700,1,16.2,200,2,10.93,200,2,16.22,100,1,10.92,200,2,16.3,700,1,ARL,43313941
186,2025-07-17T13:30:00.870278857Z,2025-07-17T13:30:00.870278857Z,10,2,1108,C,A,3,15.98,100,128,173193,28964260,11.76,100,1,15.3,100,1,11.52,100,1,15.61,100,1,11.29,100,1,15.91,100,1,11.14,700,1,16.1,100,1,11.07,700,1,16.11,700,1,11.05,100,1,16.15,700,1,11.01,100,1,16.2,200,2,10.99,700,1,16.22,100,1,10.93,200,2,16.3,700,1,10.92,200,2,16.38,200,2,ARL,43314009
187,2025-07-17T13:30:00.870848973Z,2025-07-17T13:30:00.870848973Z,10,2,1108,A,B,2,11.4,100,128,175937,28964903,11.76,100,1,15.3,100,1,11.52,100,1,15.61,100,1,11.4,100,1,15.91,100,1,11.29,100,1,16.1,100,1,11.14,700,1,16.11,700,1,11.07,700,1,16.15,700,1,11.05,100,1,16.2,200,2,11.01,100,1,16.22,100,1,10.99,700,1,16.3,700,1,10.93,200,2,16.38,200,2,ARL,43315905
188,2025-07-17T13:30:00.871359085Z,2025-07-17T13:30:00.871359085Z,10,2,1108,A,A,9,16.38,100,128,176400,28965402,11.76,100,1,15.3,100,1,11.52,100,1,15.61,100,1,11.4,100,1,15.91,100,1,11.29,100,1,16.1,100,1,11.14,700,1,16.11,700,1,11.07,700,1,16.15,700,1,11.05,100,1,16.2,200,2,11.01,100,1,16.22,100,1,10.99,700,1,16.3,700,1,10.93,200,2,16.38,300,3,ARL,43317137
189,2025-07-17T13:30:00.871520352Z,2025-07-17T13:30:00.871520352Z,10,2,1108,A,B,0,12.23,100,128,180652,28965571,12.23,100,1,15.3,100,1,11.76,100,1,15.61,100,1,11.52,100,1,15.91,100,1,11.4,100,1,16.1,100,1,11.29,100,1,16.11,700,1,11.14,700,1,16.15,700,1,11.07,700,1,16.2,200,2,11.05,100,1,16.22,100,1,11.01,100,1,16.3,700,1,10.99,700,1,16.38,300,3,ARL,43317473
190,2025-07-17T13:30:00.871548318Z,2025-07-17T13:30:00.871548318Z,10,2,1108,C,A,10,16.49,100,0,174965,28965592,12.23,100,1,15.3,100,1,11.76,100,1,15.61,100,1,11.52,100,1,15.91,100,1,11.4,100,1,16.1,100,1,11.29,100,1,16.11,700,1,11.14,700,1,16.15,700,1,11.07,700,1,16.2,200,2,11.05,100,1,16.22,100,1,11.01,100,1,16.3,700,1,10.99,700,1,16.38,300,3,ARL,41635069
191,2025-07-17T13:30:00.871548318Z,2025-07-17T13:30:00.871548318Z,10,2,1108,A,A,1,15.47,100,128,174965,28965592,12.23,100,1,15.3,100,1,11.76,100,1,15.47,100,1,11.52,100,1,15.61,100,1,11.4,100,1,15.91,100,1,11.29,100,1,16.1,100,1,11.14,700,1,16.11,700,1,11.07,700,1,16.15,700,1,11.05,100,1,16.2,200,2,11.01,100,1,16.22,100,1,10.99,700,1,16.3,700,1,ARL,43317561
192,2025-07-17T13:30:00.911486897Z,2025-07-17T13:30:00.911486897Z,10,2,1108,A,B,2,11.69,2,128,224530,28973032,12.23,100,1,15.3,100,1,11.76,100,1,15.47,100,1,11.69,2,1,15.61,100,1,11.52,100,1,15.91,100,1,11.4,100,1,16.1,100,1,11.29,100,1,16.11,700,1,11.14,700,1,16.15,700,1,11.07,700,1,16.2,200,2,11.05,100,1,16.22,100,1,11.01,100,1,16.3,700,1,ARL,43324133
193,2025-07-17T13:30:00.914351054Z,2025-07-17T13:30:00.914351054Z,10,2,1108,A,A,1,15.31,2,128,177681,28975648,12.23,100,1,15.3,100,1,11.76,100,1,15.31,2,1,11.69,2,1,15.47,100,1,11.52,100,1,15.61,100,1,11.4,100,1,15.91,100,1,11.29,100,1,16.1,100,1,11.14,700,1,16.11,700,1,11.07,700,1,16.15,700,1,11.05,100,1,16.2,200,2,11.01,100,1,16.22,100,1,ARL,43328313
194,2025-07-17T13:30:00.915197739Z,2025-07-17T13:30:00.915197739Z,10,2,1108,A,B,1,11.93,100,130,174269,28976307,12.23,100,1,15.3,100,1,11.93,100,1,15.31,2,1,11.76,100,1,15.47,100,1,11.69,2,1,15.61,100,1,11.52,100,1,15.91,100,1,11.4,100,1,16.1,100,1,11.29,100,1,16.11,700,1,11.14,700,1,16.15,700,1,11.07,700,1,16.2,200,2,11.05,100,1,16.22,100,1,ARL,43329953
195,2025-07-17T13:30:00.916332252Z,2025-07-17T13:30:00.916332252Z,10,2,1108,A,A,4,15.8,100,128,175728,28977103,12.23,100,1,15.3,100,1,11.93,100,1,15.31,2,1,11.76,100,1,15.47,100,1,11.69,2,1,15.61,100,1,11.52,100,1,15.8,100,1,11.4,100,1,15.91,100,1,11.29,100,1,16.1,100,1,11.14,700,1,16.11,700,1,11.07,700,1,16.15,700,1,11.05,100,1,16.2,200,2,ARL,43331877
196,2025-07-17T13:30:00.931432717Z,2025-07-17T13:30:00.931432717Z,10,2,1108,C,A,4,15.8,100,0,172973,28991138,12.23,100,1,15.3,100,1,11.93,100,1,15.31,2,1,11.76,100,1,15.47,100,1,11.69,2,1,15.61,100,1,11.52,100,1,15.91,100,1,11.4,100,1,16.1,100,1,11.29,100,1,16.11,700,1,11.14,700,1,16.15,700,1,11.07,700,1,16.2,200,2,11.05,100,1,16.22,100,1,ARL,43331877
197,2025-07-17T13:30:00.931432717Z,2025-07-17T13:30:00.931432717Z,10,2,1108,A,A,0,14.74,100,128,172973,28991138,12.23,100,1,14.74,100,1,11.93,100,1,15.3,100,1,11.76,100,1,15.31,2,1,11.69,2,1,15.47,100,1,11.52,100,1,15.61,100,1,11.4,100,1,15.91,100,1,11.29,100,1,16.1,100,1,11.14,700,1,16.11,700,1,11.07,700,1,16.15,700,1,11.05,100,1,16.2,200,2,ARL,43357029
198,2025-07-17T13:30:00.940916945Z,2025-07-17T13:30:00.940916945Z,10,2,1108,C,A,3,15.47,100,0,165656,29000554,12.23,100,1,14.74,100,1,11.93,100,1,15.3,100,1,11.76,100,1,15.31,2,1,11.69,2,1,15.61,100,1,11.52,100,1,15.91,100,1,11.4,100,1,16.1,100,1,11.29,100,1,16.11,700,1,11.14,700,1,16.15,700,1,11.07,700,1,16.2,200,2,11.05,100,1,16.22,100,1,ARL,43317561
199,2025-07-17T13:30:00.940916945Z,2025-07-17T13:30:00.940916945Z,10,2,1108,A,A,0,14.44,100,130,165656,29000554,12.23,100,1,14.44,100,1,11.93,100,1,14.74,100,1,11.76,100,1,15.3,100,1,11.69,2,1,15.31,2,1,11.52,100,1,15.61,100,1,11.4,100,1,15.91,100,1,11.29,100,1,16.1,100,1,11.14,700,1,16.11,700,1,11.07,700,1,16.15,700,1,11.05,100,1,16.2,200,2,ARL,43373009
200,2025-07-17T13:30:00.941071231Z,2025-07-17T13:30:00.941071231Z,10,2,1108,A,A,2,15.28,100,130,165631,29000677,12.23,100,1,14.44,100,1,11.93,100,1,14.74,100,1,11.76,100,1,15.28,100,1,11.69,2,1,15.3,100,1,11.52,100,1,15.31,2,1,11.4,100,1,15.61,100,1,11.29,100,1,15.91,100,1,11.14,700,1,16.1,100,1,11.07,700,1,16.11,700,1,11.05,100,1,16.15,700,1,ARL,43373085
201,2025-07-17T13:30:01.086438727Z,2025-07-17T13:30:01.086438727Z,10,2,1108,C,B,10,11.01,100,0,167223,29116818,12.23,100,1,14.44,100,1,11.93,100,1,14.74,100,1,11.76,100,1,15.28,100,1,11.69,2,1,15.3,100,1,11.52,100,1,15.31,2,1,11.4,100,1,15.61,100,1,11.29,100,1,15.91,100,1,11.14,700,1,16.1,100,1,11.07,700,1,16.11,700,1,11.05,100,1,16.15,700,1,ARL,42674817
202,2025-07-17T13:30:01.086438727Z,2025-07-17T13:30:01.086438727Z,10,2,1108,A,B,0,12.47,100,130,167223,29116818,12.47,100,1,14.44,100,1,12.23,100,1,14.74,100,1,11.93,100,1,15.28,100,1,11.76,100,1,15.3,100,1,11.69,2,1,15.31,2,1,11.52,100,1,15.61,100,1,11.4,100,1,15.91,100,1,11.29,100,1,16.1,100,1,11.14,700,1,16.11,700,1,11.07,700,1,16.15,700,1,ARL,43554133
203,2025-07-17T13:30:01.086456460Z,2025-07-17T13:30:01.086456460Z,10,2,1108,C,A,7,16.1,100,0,168766,29116862,12.47,100,1,14.44,100,1,12.23,100,1,14.74,100,1,11.93,100,1,15.28,100,1,11.76,100,1,15.3,100,1,11.69,2,1,15.31,2,1,11.52,100,1,15.61,100,1,11.4,100,1,15.91,100,1,11.29,100,1,16.11,700,1,11.14,700,1,16.15,700,1,11.07,700,1,16.2,200,2,ARL,42674989
204,2025-07-17T13:30:01.086456460Z,2025-07-17T13:30:01.086456460Z,10,2,1108,A,A,0,14.2,100,128,168766,29116862,12.47,100,1,14.2,100,1,12.23,100,1,14.44,100,1,11.93,100,1,14.74,100,1,11.76,100,1,15.28,100,1,11.69,2,1,15.3,100,1,11.52,100,1,15.31,2,1,11.4,100,1,15.61,100,1,11.29,100,1,15.91,100,1,11.14,700,1,16.11,700,1,11.07,700,1,16.15,700,1,ARL,43554141
205,2025-07-17T13:30:01.214703183Z,2025-07-17T13:30:01.214703183Z,10,2,1108,A,B,0,12.67,100,0,179739,29196804,12.67,100,1,14.2,100,1,12.47,100,1,14.44,100,1,12.23,100,1,14.74,100,1,11.93,100,1,15.28,100,1,11.76,100,1,15.3,100,1,11.69,2,1,15.31,2,1,11.52,100,1,15.61,100,1,11.4,100,1,15.91,100,1,11.29,100,1,16.11,700,1,11.14,700,1,16.15,700,1,ARL,43663229
206,2025-07-17T13:30:01.214704496Z,2025-07-17T13:30:01.214704496Z,10,2,1108,A,A,0,14,100,128,178426,29196805,12.67,100,1,14,100,1,12.47,100,1,14.2,100,1,12.23,100,1,14.44,100,1,11.93,100,1,14.74,100,1,11.76,100,1,15.28,100,1,11.69,2,1,15.3,100,1,11.52,100,1,15.31,2,1,11.4,100,1,15.61,100,1,11.29,100,1,15.91,100,1,11.14,700,1,16.11,700,1,ARL,43663233
207,2025-07-17T13:30:01.254829854Z,2025-07-17T13:30:01.254829854Z,10,2,1108,C,B,5,11.69,2,0,177685,29223480,12.67,100,1,14,100,1,12.47,100,1,14.2,100,1,12.23,100,1,14.44,100,1,11.93,100,1,14.74,100,1,11.76,100,1,15.28,100,1,11.52,100,1,15.3,100,1,11.4,100,1,15.31,2,1,11.29,100,1,15.61,100,1,11.14,700,1,15.91,100,1,11.07,700,1,16.11,700,1,ARL,43324133
208,2025-07-17T13:30:01.254829854Z,2025-07-17T13:30:01.254829854Z,10,2,1108,A,B,2,12.33,2,128,177685,29223480,12.67,100,1,14,100,1,12.47,100,1,14.2,100,1,12.33,2,1,14.44,100,1,12.23,100,1,14.74,100,1,11.93,100,1,15.28,100,1,11.76,100,1,15.3,100,1,11.52,100,1,15.31,2,1,11.4,100,1,15.61,100,1,11.29,100,1,15.91,100,1,11.14,700,1,16.11,700,1,ARL,43692153
209,2025-07-17T13:30:01.254836082Z,2025-07-17T13:30:01.254836082Z,10,2,1108,C,A,6,15.31,2,0,180884,29223485,12.67,100,1,14,100,1,12.47,100,1,14.2,100,1,12.33,2,1,14.44,100,1,12.23,100,1,14.74,100,1,11.93,100,1,15.28,100,1,11.76,100,1,15.3,100,1,11.52,100,1,15.61,100,1,11.4,100,1,15.91,100,1,11.29,100,1,16.11,700,1,11.14,700,1,16.15,700,1,ARL,43328313
210,2025-07-17T13:30:01.254836082Z,2025-07-17T13:30:01.254836082Z,10,2,1108,A,A,3,14.65,2,128,180884,29223485,12.67,100,1,14,100,1,12.47,100,1,14.2,100,1,12.33,2,1,14.44,100,1,12.23,100,1,14.65,2,1,11.93,100,1,14.74,100,1,11.76,100,1,15.28,100,1,11.52,100,1,15.3,100,1,11.4,100,1,15.61,100,1,11.29,100,1,15.91,100,1,11.14,700,1,16.11,700,1,ARL,43692157
211,2025-07-17T13:30:01.326934077Z,2025-07-17T13:30:01.326934077Z,10,2,1108,C,B,6,11.52,100,130,175400,29250087,12.67,100,1,14,100,1,12.47,100,1,14.2,100,1,12.33,2,1,14.44,100,1,12.23,100,1,14.65,2,1,11.93,100,1,14.74,100,1,11.76,100,1,15.28,100,1,11.4,100,1,15.3,100,1,11.29,100,1,15.61,100,1,11.14,700,1,15.91,100,1,11.07,700,1,16.11,700,1,ARL,42446497
212,2025-07-17T13:30:01.327714478Z,2025-07-17T13:30:01.327714478Z,10,2,1108,C,A,7,15.61,100,128,180420,29250293,12.67,100,1,14,100,1,12.47,100,1,14.2,100,1,12.33,2,1,14.44,100,1,12.23,100,1,14.65,2,1,11.93,100,1,14.74,100,1,11.76,100,1,15.28,100,1,11.4,100,1,15.3,100,1,11.29,100,1,15.91,100,1,11.14,700,1,16.11,700,1,11.07,700,1,16.15,700,1,ARL,42446501
213,2025-07-17T13:30:01.367244122Z,2025-07-17T13:30:01.367244122Z,10,2,1108,A,B,2,12.33,100,130,166111,29262273,12.67,100,1,14,100,1,12.47,100,1,14.2,100,1,12.33,102,2,14.44,100,1,12.23,100,1,14.65,2,1,11.93,100,1,14.74,100,1,11.76,100,1,15.28,100,1,11.4,100,1,15.3,100,1,11.29,100,1,15.91,100,1,11.14,700,1,16.11,700,1,11.07,700,1,16.15,700,1,ARL,43755813
214,2025-07-17T13:30:01.367256226Z,2025-07-17T13:30:01.367256226Z,10,2,1108,A,A,2,14.34,100,130,165618,29262274,12.67,100,1,14,100,1,12.47,100,1,14.2,100,1,12.33,102,2,14.34,100,1,12.23,100,1,14.44,100,1,11.93,100,1,14.65,2,1,11.76,100,1,14.74,100,1,11.4,100,1,15.28,100,1,11.29,100,1,15.3,100,1,11.14,700,1,15.91,100,1,11.07,700,1,16.11,700,1,ARL,43755821
215,2025-07-17T13:30:01.456460560Z,2025-07-17T13:30:01.456460560Z,10,2,1108,A,B,2,12.36,100,130,171287,29285993,12.67,100,1,14,100,1,12.47,100,1,14.2,100,1,12.36,100,1,14.34,100,1,12.33,102,2,14.44,100,1,12.23,100,1,14.65,2,1,11.93,100,1,14.74,100,1,11.76,100,1,15.28,100,1,11.4,100,1,15.3,100,1,11.29,100,1,15.91,100,1,11.14,700,1,16.11,700,1,ARL,43781537
216,2025-07-17T13:30:01.456476348Z,2025-07-17T13:30:01.456476348Z,10,2,1108,A,A,6,14.9,100,130,166602,29285996,12.67,100,1,14,100,1,12.47,100,1,14.2,100,1,12.36,100,1,14.34,100,1,12.33,102,2,14.44,100,1,12.23,100,1,14.65,2,1,11.93,100,1,14.74,100,1,11.76,100,1,14.9,100,1,11.4,100,1,15.28,100,1,11.29,100,1,15.3,100,1,11.14,700,1,15.91,100,1,ARL,43781545
217,2025-07-17T13:30:01.487884350Z,2025-07-17T13:30:01.487884350Z,10,2,1108,A,B,2,12.36,100,130,165832,29297612,12.67,100,1,14,100,1,12.47,100,1,14.2,100,1,12.36,200,2,14.34,100,1,12.33,102,2,14.44,100,1,12.23,100,1,14.65,2,1,11.93,100,1,14.74,100,1,11.76,100,1,14.9,100,1,11.4,100,1,15.28,100,1,11.29,100,1,15.3,100,1,11.14,700,1,15.91,100,1,ARL,43787977
218,2025-07-17T13:30:01.487905785Z,2025-07-17T13:30:01.487905785Z,10,2,1108,A,A,6,14.9,100,128,177067,29297619,12.67,100,1,14,100,1,12.47,100,1,14.2,100,1,12.36,200,2,14.34,100,1,12.33,102,2,14.44,100,1,12.23,100,1,14.65,2,1,11.93,100,1,14.74,100,1,11.76,100,1,14.9,200,2,11.4,100,1,15.28,100,1,11.29,100,1,15.3,100,1,11.14,700,1,15.91,100,1,ARL,43787985
219,2025-07-17T13:30:01.488866053Z,2025-07-17T13:30:01.488866053Z,10,2,1108,A,A,10,16.08,100,128,172059,29298118,12.67,100,1,14,100,1,12.47,100,1,14.2,100,1,12.36,200,2,14.34,100,1,12.33,102,2,14.44,100,1,12.23,100,1,14.65,2,1,11.93,100,1,14.74,100,1,11.76,100,1,14.9,200,2,11.4,100,1,15.28,100,1,11.29,100,1,15.3,100,1,11.14,700,1,15.91,100,1,ARL,43788313
220,2025-07-17T13:30:01.532274368Z,2025-07-17T13:30:01.532274368Z,10,2,1108,A,B,2,12.46,100,128,170630,29318499,12.67,100,1,14,100,1,12.47,100,1,14.2,100,1,12.46,100,1,14.34,100,1,12.36,200,2,14.44,100,1,12.33,102,2,14.65,2,1,12.23,100,1,14.74,100,1,11.93,100,1,14.9,200,2,11.76,100,1,15.28,100,1,11.4,100,1,15.3,100,1,11.29,100,1,15.91,100,1,ARL,43804025
221,2025-07-17T13:30:01.532324961Z,2025-07-17T13:30:01.532324961Z,10,2,1108,A,A,1,14.2,100,128,173333,29318528,12.67,100,1,14,100,1,12.47,100,1,14.2,200,2,12.46,100,1,14.34,100,1,12.36,200,2,14.44,100,1,12.33,102,2,14.65,2,1,12.23,100,1,14.74,100,1,11.93,100,1,14.9,200,2,11.76,100,1,15.28,100,1,11.4,100,1,15.3,100,1,11.29,100,1,15.91,100,1,ARL,43804081
222,2025-07-17T13:30:01.537195873Z,2025-07-17T13:30:01.537195873Z,10,2,1108,A,B,0,12.99,100,128,177786,29320724,12.99,100,1,14,100,1,12.67,100,1,14.2,200,2,12.47,100,1,14.34,100,1,12.46,100,1,14.44,100,1,12.36,200,2,14.65,2,1,12.33,102,2,14.74,100,1,12.23,100,1,14.9,200,2,11.93,100,1,15.28,100,1,11.76,100,1,15.3,100,1,11.4,100,1,15.91,100,1,ARL,43805737
223,2025-07-17T13:30:01.537219414Z,2025-07-17T13:30:01.537219414Z,10,2,1108,A,A,4,14.65,100,128,167618,29320743,12.99,100,1,14,100,1,12.67,100,1,14.2,200,2,12.47,100,1,14.34,100,1,12.46,100,1,14.44,100,1,12.36,200,2,14.65,102,2,12.33,102,2,14.74,100,1,12.23,100,1,14.9,200,2,11.93,100,1,15.28,100,1,11.76,100,1,15.3,100,1,11.4,100,1,15.91,100,1,ARL,43805773
224,2025-07-17T13:30:01.571375465Z,2025-07-17T13:30:01.571375465Z,10,2,1108,A,B,0,13.2,28,130,183336,29336931,13.2,28,1,14,100,1,12.99,100,1,14.2,200,2,12.67,100,1,14.34,100,1,12.47,100,1,14.44,100,1,12.46,100,1,14.65,102,2,12.36,200,2,14.74,100,1,12.33,102,2,14.9,200,2,12.23,100,1,15.28,100,1,11.93,100,1,15.3,100,1,11.76,100,1,15.91,100,1,ARL,43820541
225,2025-07-17T13:30:01.590381387Z,2025-07-17T13:30:01.590381387Z,10,2,1108,A,A,10,16.08,100,128,183147,29346224,13.2,28,1,14,100,1,12.99,100,1,14.2,200,2,12.67,100,1,14.34,100,1,12.47,100,1,14.44,100,1,12.46,100,1,14.65,102,2,12.36,200,2,14.74,100,1,12.33,102,2,14.9,200,2,12.23,100,1,15.28,100,1,11.93,100,1,15.3,100,1,11.76,100,1,15.91,100,1,ARL,43826261
226,2025-07-17T13:30:01.592539240Z,2025-07-17T13:30:01.592539240Z,10,2,1108,A,A,9,15.41,100,128,172822,29347463,13.2,28,1,14,100,1,12.99,100,1,14.2,200,2,12.67,100,1,14.34,100,1,12.47,100,1,14.44,100,1,12.46,100,1,14.65,102,2,12.36,200,2,14.74,100,1,12.33,102,2,14.9,200,2,12.23,100,1,15.28,100,1,11.93,100,1,15.3,100,1,11.76,100,1,15.41,100,1,ARL,43826805
227,2025-07-17T13:30:01.661958252Z,2025-07-17T13:30:01.661958252Z,10,2,1108,A,B,8,11.93,100,130,165451,29378719,13.2,28,1,14,100,1,12.99,100,1,14.2,200,2,12.67,100,1,14.34,100,1,12.47,100,1,14.44,100,1,12.46,100,1,14.65,102,2,12.36,200,2,14.74,100,1,12.33,102,2,14.9,200,2,12.23,100,1,15.28,100,1,11.93,200,2,15.3,100,1,11.76,100,1,15.41,100,1,ARL,43852121
228,2025-07-17T13:30:01.661989524Z,2025-07-17T13:30:01.661989524Z,10,2,1108,A,A,5,14.74,100,128,170086,29378727,13.2,28,1,14,100,1,12.99,100,1,14.2,200,2,12.67,100,1,14.34,100,1,12.47,100,1,14.44,100,1,12.46,100,1,14.65,102,2,12.36,200,2,14.74,200,2,12.33,102,2,14.9,200,2,12.23,100,1,15.28,100,1,11.93,200,2,15.3,100,1,11.76,100,1,15.41,100,1,ARL,43852129
229,2025-07-17T13:30:01.929395142Z,2025-07-17T13:30:01.929395142Z,10,2,1108,C,A,4,14.65,100,130,165367,29480243,13.2,28,1,14,100,1,12.99,100,1,14.2,200,2,12.67,100,1,14.34,100,1,12.47,100,1,14.44,100,1,12.46,100,1,14.65,2,1,12.36,200,2,14.74,200,2,12.33,102,2,14.9,200,2,12.23,100,1,15.28,100,1,11.93,200,2,15.3,100,1,11.76,100,1,15.41,100,1,ARL,43805773
230,2025-07-17T13:30:01.930800767Z,2025-07-17T13:30:01.930800767Z,10,2,1108,A,A,0,13.67,100,130,165610,29480698,13.2,28,1,13.67,100,1,12.99,100,1,14,100,1,12.67,100,1,14.2,200,2,12.47,100,1,14.34,100,1,12.46,100,1,14.44,100,1,12.36,200,2,14.65,2,1,12.33,102,2,14.74,200,2,12.23,100,1,14.9,200,2,11.93,200,2,15.28,100,1,11.76,100,1,15.3,100,1,ARL,43953649
231,2025-07-17T13:30:02.378274380Z,2025-07-17T13:30:02.378274380Z,10,2,1108,A,B,2,12.73,100,130,165674,29585499,13.2,28,1,13.67,100,1,12.99,100,1,14,100,1,12.73,100,1,14.2,200,2,12.67,100,1,14.34,100,1,12.47,100,1,14.44,100,1,12.46,100,1,14.65,2,1,12.36,200,2,14.74,200,2,12.33,102,2,14.9,200,2,12.23,100,1,15.28,100,1,11.93,200,2,15.3,100,1,ARL,44066409
232,2025-07-17T13:30:02.378280610Z,2025-07-17T13:30:02.378280610Z,10,2,1108,A,A,1,13.93,100,130,165619,29585501,13.2,28,1,13.67,100,1,12.99,100,1,13.93,100,1,12.73,100,1,14,100,1,12.67,100,1,14.2,200,2,12.47,100,1,14.34,100,1,12.46,100,1,14.44,100,1,12.36,200,2,14.65,2,1,12.33,102,2,14.74,200,2,12.23,100,1,14.9,200,2,11.93,200,2,15.28,100,1,ARL,44066417
233,2025-07-17T13:30:02.476818222Z,2025-07-17T13:30:02.476818222Z,10,2,1108,C,A,8,14.9,100,0,165584,29601178,13.2,28,1,13.67,100,1,12.99,100,1,13.93,100,1,12.73,100,1,14,100,1,12.67,100,1,14.2,200,2,12.47,100,1,14.34,100,1,12.46,100,1,14.44,100,1,12.36,200,2,14.65,2,1,12.33,102,2,14.74,200,2,12.23,100,1,14.9,100,1,11.93,200,2,15.28,100,1,ARL,43781545
234,2025-07-17T13:30:02.476818222Z,2025-07-17T13:30:02.476818222Z,10,2,1108,A,A,6,14.57,100,130,165584,29601178,13.2,28,1,13.67,100,1,12.99,100,1,13.93,100,1,12.73,100,1,14,100,1,12.67,100,1,14.2,200,2,12.47,100,1,14.34,100,1,12.46,100,1,14.44,100,1,12.36,200,2,14.57,100,1,12.33,102,2,14.65,2,1,12.23,100,1,14.74,200,2,11.93,200,2,14.9,100,1,ARL,44076709
235,2025-07-17T13:30:02.483131658Z,2025-07-17T13:30:02.483131658Z,10,2,1108,C,A,9,14.9,100,0,166103,29601999,13.2,28,1,13.67,100,1,12.99,100,1,13.93,100,1,12.73,100,1,14,100,1,12.67,100,1,14.2,200,2,12.47,100,1,14.34,100,1,12.46,100,1,14.44,100,1,12.36,200,2,14.57,100,1,12.33,102,2,14.65,2,1,12.23,100,1,14.74,200,2,11.93,200,2,15.28,100,1,ARL,43787985
236,2025-07-17T13:30:02.483131658Z,2025-07-17T13:30:02.483131658Z,10,2,1108,A,A,6,14.57,100,130,166103,29601999,13.2,28,1,13.67,100,1,12.99,100,1,13.93,100,1,12.73,100,1,14,100,1,12.67,100,1,14.2,200,2,12.47,100,1,14.34,100,1,12.46,100,1,14.44,100,1,12.36,200,2,14.57,200,2,12.33,102,2,14.65,2,1,12.23,100,1,14.74,200,2,11.93,200,2,15.28,100,1,ARL,44077497
237,2025-07-17T13:30:02.573606685Z,2025-07-17T13:30:02.573606685Z,10,2,1108,A,B,7,12.33,100,128,167628,29618524,13.2,28,1,13.67,100,1,12.99,100,1,13.93,100,1,12.73,100,1,14,100,1,12.67,100,1,14.2,200,2,12.47,100,1,14.34,100,1,12.46,100,1,14.44,100,1,12.36,200,2,14.57,200,2,12.33,202,3,14.65,2,1,12.23,100,1,14.74,200,2,11.93,200,2,15.28,100,1,ARL,44088633
238,2025-07-17T13:30:02.573623478Z,2025-07-17T13:30:02.573623478Z,10,2,1108,A,A,4,14.34,100,128,168568,29618531,13.2,28,1,13.67,100,1,12.99,100,1,13.93,100,1,12.73,100,1,14,100,1,12.67,100,1,14.2,200,2,12.47,100,1,14.34,200,2,12.46,100,1,14.44,100,1,12.36,200,2,14.57,200,2,12.33,202,3,14.65,2,1,12.23,100,1,14.74,200,2,11.93,200,2,15.28,100,1,ARL,44088637
239,2025-07-17T13:30:06.757383618Z,2025-07-17T13:30:06.757383618Z,10,2,1108,A,A,4,14.27,700,130,165451,30107583,13.2,28,1,13.67,100,1,12.99,100,1,13.93,100,1,12.73,100,1,14,100,1,12.67,100,1,14.2,200,2,12.47,100,1,14.27,700,1,12.46,100,1,14.34,200,2,12.36,200,2,14.44,100,1,12.33,202,3,14.57,200,2,12.23,100,1,14.65,2,1,11.93,200,2,14.74,200,2,ARL,44491681
240,2025-07-17T13:30:07.394882479Z,2025-07-17T13:30:07.394882479Z,10,2,1108,A,A,10,15,700,130,165154,30169157,13.2,28,1,13.67,100,1,12.99,100,1,13.93,100,1,12.73,100,1,14,100,1,12.67,100,1,14.2,200,2,12.47,100,1,14.27,700,1,12.46,100,1,14.34,200,2,12.36,200,2,14.44,100,1,12.33,202,3,14.57,200,2,12.23,100,1,14.65,2,1,11.93,200,2,14.74,200,2,ARL,44533061
241,2025-07-17T13:30:07.594772046Z,2025-07-17T13:30:07.594772046Z,10,2,1108,A,A,9,14.7,700,128,176513,30189080,13.2,28,1,13.67,100,1,12.99,100,1,13.93,100,1,12.73,100,1,14,100,1,12.67,100,1,14.2,200,2,12.47,100,1,14.27,700,1,12.46,100,1,14.34,200,2,12.36,200,2,14.44,100,1,12.33,202,3,14.57,200,2,12.23,100,1,14.65,2,1,11.93,200,2,14.7,700,1,ARL,44545381
242,2025-07-17T13:30:07.663083798Z,2025-07-17T13:30:07.663083798Z,10,2,1108,A,A,7,14.46,700,130,165352,30194197,13.2,28,1,13.67,100,1,12.99,100,1,13.93,100,1,12.73,100,1,14,100,1,12.67,100,1,14.2,200,2,12.47,100,1,14.27,700,1,12.46,100,1,14.34,200,2,12.36,200,2,14.44,100,1,12.33,202,3,14.46,700,1,12.23,100,1,14.57,200,2,11.93,200,2,14.65,2,1,ARL,44548325
243,2025-07-17T13:30:07.663798482Z,2025-07-17T13:30:07.663798482Z,10,2,1108,C,A,10,14.7,700,130,165092,30194234,13.2,28,1,13.67,100,1,12.99,100,1,13.93,100,1,12.73,100,1,14,100,1,12.67,100,1,14.2,200,2,12.47,100,1,14.27,700,1,12.46,100,1,14.34,200,2,12.36,200,2,14.44,100,1,12.33,202,3,14.46,700,1,12.23,100,1,14.57,200,2,11.93,200,2,14.65,2,1,ARL,44545381
244,2025-07-17T13:30:07.914271879Z,2025-07-17T13:30:07.914271879Z,10,2,1108,A,B,10,11.76,700,130,165347,30213834,13.2,28,1,13.67,100,1,12.99,100,1,13.93,100,1,12.73,100,1,14,100,1,12.67,100,1,14.2,200,2,12.47,100,1,14.27,700,1,12.46,100,1,14.34,200,2,12.36,200,2,14.44,100,1,12.33,202,3,14.46,700,1,12.23,100,1,14.57,200,2,11.93,200,2,14.65,2,1,ARL,44560257
245,2025-07-17T13:30:08.025660842Z,2025-07-17T13:30:08.025660842Z,10,2,1108,A,B,9,12.02,700,130,165350,30224657,13.2,28,1,13.67,100,1,12.99,100,1,13.93,100,1,12.73,100,1,14,100,1,12.67,100,1,14.2,200,2,12.47,100,1,14.27,700,1,12.46,100,1,14.34,200,2,12.36,200,2,14.44,100,1,12.33,202,3,14.46,700,1,12.23,100,1,14.57,200,2,12.02,700,1,14.65,2,1,ARL,44565617
246,2025-07-17T13:30:08.114272470Z,2025-07-17T13:30:08.114272470Z,10,2,1108,A,B,8,12.26,700,130,165367,30233944,13.2,28,1,13.67,100,1,12.99,100,1,13.93,100,1,12.73,100,1,14,100,1,12.67,100,1,14.2,200,2,12.47,100,1,14.27,700,1,12.46,100,1,14.34,200,2,12.36,200,2,14.44,100,1,12.33,202,3,14.46,700,1,12.26,700,1,14.57,200,2,12.23,100,1,14.65,2,1,ARL,44570585
247,2025-07-17T13:30:08.115068904Z,2025-07-17T13:30:08.115068904Z,10,2,1108,C,B,10,12.02,700,130,165580,30234078,13.2,28,1,13.67,100,1,12.99,100,1,13.93,100,1,12.73,100,1,14,100,1,12.67,100,1,14.2,200,2,12.47,100,1,14.27,700,1,12.46,100,1,14.34,200,2,12.36,200,2,14.44,100,1,12.33,202,3,14.46,700,1,12.26,700,1,14.57,200,2,12.23,100,1,14.65,2,1,ARL,44565617
248,2025-07-17T13:30:08.394373251Z,2025-07-17T13:30:08.394373251Z,10,2,1108,A,B,0,13.25,11,130,165414,30258008,13.25,11,1,13.67,100,1,13.2,28,1,13.93,100,1,12.99,100,1,14,100,1,12.73,100,1,14.2,200,2,12.67,100,1,14.27,700,1,12.47,100,1,14.34,200,2,12.46,100,1,14.44,100,1,12.36,200,2,14.46,700,1,12.33,202,3,14.57,200,2,12.26,700,1,14.65,2,1,ARL,44586753
249,2025-07-17T13:30:08.402012613Z,2025-07-17T13:30:08.402012613Z,10,2,1108,C,B,1,13.2,28,130,165269,30259240,13.25,11,1,13.67,100,1,12.99,100,1,13.93,100,1,12.73,100,1,14,100,1,12.67,100,1,14.2,200,2,12.47,100,1,14.27,700,1,12.46,100,1,14.34,200,2,12.36,200,2,14.44,100,1,12.33,202,3,14.46,700,1,12.26,700,1,14.57,200,2,12.23,100,1,14.65,2,1,ARL,43820541
250,2025-07-17T13:30:08.512579639Z,2025-07-17T13:30:08.512579639Z,10,2,1108,A,A,4,14.26,700,130,165281,30276907,13.25,11,1,13.67,100,1,12.99,100,1,13.93,100,1,12.73,100,1,14,100,1,12.67,100,1,14.2,200,2,12.47,100,1,14.26,700,1,12.46,100,1,14.27,700,1,12.36,200,2,14.34,200,2,12.33,202,3,14.44,100,1,12.26,700,1,14.46,700,1,12.23,100,1,14.57,200,2,ARL,44598153
251,2025-07-17T13:30:09.329050977Z,2025-07-17T13:30:09.329050977Z,10,2,1108,A,B,10,12.02,700,130,165582,30353905,13.25,11,1,13.67,100,1,12.99,100,1,13.93,100,1,12.73,100,1,14,100,1,12.67,100,1,14.2,200,2,12.47,100,1,14.26,700,1,12.46,100,1,14.27,700,1,12.36,200,2,14.34,200,2,12.33,202,3,14.44,100,1,12.26,700,1,14.46,700,1,12.23,100,1,14.57,200,2,ARL,44641397
252,2025-07-17T13:30:10.081175039Z,2025-07-17T13:30:10.081175039Z,10,2,1108,A,A,0,13.4,10,130,165480,30441651,13.25,11,1,13.4,10,1,12.99,100,1,13.67,100,1,12.73,100,1,13.93,100,1,12.67,100,1,14,100,1,12.47,100,1,14.2,200,2,12.46,100,1,14.26,700,1,12.36,200,2,14.27,700,1,12.33,202,3,14.34,200,2,12.26,700,1,14.44,100,1,12.23,100,1,14.46,700,1,ARL,44719917
253,2025-07-17T13:30:10.082150107Z,2025-07-17T13:30:10.082150107Z,10,2,1108,C,A,10,14.57,100,0,165551,30441855,13.25,11,1,13.4,10,1,12.99,100,1,13.67,100,1,12.73,100,1,13.93,100,1,12.67,100,1,14,100,1,12.47,100,1,14.2,200,2,12.46,100,1,14.26,700,1,12.36,200,2,14.27,700,1,12.33,202,3,14.34,200,2,12.26,700,1,14.44,100,1,12.23,100,1,14.46,700,1,ARL,44076709
254,2025-07-17T13:30:10.082150107Z,2025-07-17T13:30:10.082150107Z,10,2,1108,A,A,7,14.29,100,130,165551,30441855,13.25,11,1,13.4,10,1,12.99,100,1,13.67,100,1,12.73,100,1,13.93,100,1,12.67,100,1,14,100,1,12.47,100,1,14.2,200,2,12.46,100,1,14.26,700,1,12.36,200,2,14.27,700,1,12.33,202,3,14.29,100,1,12.26,700,1,14.34,200,2,12.23,100,1,14.44,100,1,ARL,44719985
255,2025-07-17T13:30:10.082662762Z,2025-07-17T13:30:10.082662762Z,10,2,1108,A,A,7,14.29,100,130,165590,30441930,13.25,11,1,13.4,10,1,12.99,100,1,13.67,100,1,12.73,100,1,13.93,100,1,12.67,100,1,14,100,1,12.47,100,1,14.2,200,2,12.46,100,1,14.26,700,1,12.36,200,2,14.27,700,1,12.33,202,3,14.29,200,2,12.26,700,1,14.34,200,2,12.23,100,1,14.44,100,1,ARL,44720033
256,2025-07-17T13:30:10.084896414Z,2025-07-17T13:30:10.084896414Z,10,2,1108,A,B,6,12.42,700,130,165787,30442720,13.25,11,1,13.4,10,1,12.99,100,1,13.67,100,1,12.73,100,1,13.93,100,1,12.67,100,1,14,100,1,12.47,100,1,14.2,200,2,12.46,100,1,14.26,700,1,12.42,700,1,14.27,700,1,12.36,200,2,14.29,200,2,12.33,202,3,14.34,200,2,12.26,700,1,14.44,100,1,ARL,44720357
257,2025-07-17T13:30:12.194582572Z,2025-07-17T13:30:12.194582572Z,10,2,1108,A,A,9,14.43,2,130,165601,30681385,13.25,11,1,13.4,10,1,12.99,100,1,13.67,100,1,12.73,100,1,13.93,100,1,12.67,100,1,14,100,1,12.47,100,1,14.2,200,2,12.46,100,1,14.26,700,1,12.42,700,1,14.27,700,1,12.36,200,2,14.29,200,2,12.33,202,3,14.34,200,2,12.26,700,1,14.43,2,1,ARL,44904733
258,2025-07-17T13:30:14.128932140Z,2025-07-17T13:30:14.128932140Z,10,2,1108,A,B,7,12.37,700,130,165430,30851531,13.25,11,1,13.4,10,1,12.99,100,1,13.67,100,1,12.73,100,1,13.93,100,1,12.67,100,1,14,100,1,12.47,100,1,14.2,200,2,12.46,100,1,14.26,700,1,12.42,700,1,14.27,700,1,12.37,700,1,14.29,200,2,12.36,200,2,14.34,200,2,12.33,202,3,14.43,2,1,ARL,45025165
259,2025-07-17T13:30:23.695564208Z,2025-07-17T13:30:23.695564208Z,10,2,1108,A,A,0,13.4,12,130,165276,31649134,13.25,11,1,13.4,22,2,12.99,100,1,13.67,100,1,12.73,100,1,13.93,100,1,12.67,100,1,14,100,1,12.47,100,1,14.2,200,2,12.46,100,1,14.26,700,1,12.42,700,1,14.27,700,1,12.37,700,1,14.29,200,2,12.36,200,2,14.34,200,2,12.33,202,3,14.43,2,1,ARL,45593201
260,2025-07-17T13:30:25.512069243Z,2025-07-17T13:30:25.512069243Z,10,2,1108,C,A,0,13.4,10,128,166200,31806233,13.25,11,1,13.4,12,1,12.99,100,1,13.67,100,1,12.73,100,1,13.93,100,1,12.67,100,1,14,100,1,12.47,100,1,14.2,200,2,12.46,100,1,14.26,700,1,12.42,700,1,14.27,700,1,12.37,700,1,14.29,200,2,12.36,200,2,14.34,200,2,12.33,202,3,14.43,2,1,ARL,44719917
261,2025-07-17T13:30:26.553160650Z,2025-07-17T13:30:26.553160650Z,10,2,1108,A,A,0,13.4,10,130,165329,31897785,13.25,11,1,13.4,22,2,12.99,100,1,13.67,100,1,12.73,100,1,13.93,100,1,12.67,100,1,14,100,1,12.47,100,1,14.2,200,2,12.46,100,1,14.26,700,1,12.42,700,1,14.27,700,1,12.37,700,1,14.29,200,2,12.36,200,2,14.34,200,2,12.33,202,3,14.43,2,1,ARL,45748261
262,2025-07-17T13:30:35.240400172Z,2025-07-17T13:30:35.240400172Z,10,2,1108,C,A,0,13.4,10,130,169818,32725426,13.25,11,1,13.4,12,1,12.99,100,1,13.67,100,1,12.73,100,1,13.93,100,1,12.67,100,1,14,100,1,12.47,100,1,14.2,200,2,12.46,100,1,14.26,700,1,12.42,700,1,14.27,700,1,12.37,700,1,14.29,200,2,12.36,200,2,14.34,200,2,12.33,202,3,14.43,2,1,ARL,45748261
263,2025-07-17T13:30:43.952999157Z,2025-07-17T13:30:43.952999157Z,10,2,1108,C,A,0,13.4,12,130,165229,33659635,13.25,11,1,13.67,100,1,12.99,100,1,13.93,100,1,12.73,100,1,14,100,1,12.67,100,1,14.2,200,2,12.47,100,1,14.26,700,1,12.46,100,1,14.27,700,1,12.42,700,1,14.29,200,2,12.37,700,1,14.34,200,2,12.36,200,2,14.43,2,1,12.33,202,3,14.44,100,1,ARL,45593201
264,2025-07-17T13:30:43.953363128Z,2025-07-17T13:30:43.953363128Z,10,2,1108,A,A,0,13.4,24,130,165363,33659657,13.25,11,1,13.4,24,1,12.99,100,1,13.67,100,1,12.73,100,1,13.93,100,1,12.67,100,1,14,100,1,12.47,100,1,14.2,200,2,12.46,100,1,14.26,700,1,12.42,700,1,14.27,700,1,12.37,700,1,14.29,200,2,12.36,200,2,14.34,200,2,12.33,202,3,14.43,2,1,ARL,46613073
265,2025-07-17T13:30:47.814108950Z,2025-07-17T13:30:47.814108950Z,10,2,1108,A,A,0,13.4,10,130,166303,34075767,13.25,11,1,13.4,34,2,12.99,100,1,13.67,100,1,12.73,100,1,13.93,100,1,12.67,100,1,14,100,1,12.47,100,1,14.2,200,2,12.46,100,1,14.26,700,1,12.42,700,1,14.27,700,1,12.37,700,1,14.29,200,2,12.36,200,2,14.34,200,2,12.33,202,3,14.43,2,1,ARL,46784085
266,2025-07-17T13:30:48.271611303Z,2025-07-17T13:30:48.271611303Z,10,2,1108,C,A,0,13.4,10,130,166528,34129837,13.25,11,1,13.4,24,1,12.99,100,1,13.67,100,1,12.73,100,1,13.93,100,1,12.67,100,1,14,100,1,12.47,100,1,14.2,200,2,12.46,100,1,14.26,700,1,12.42,700,1,14.27,700,1,12.37,700,1,14.29,200,2,12.36,200,2,14.34,200,2,12.33,202,3,14.43,2,1,ARL,46784085
267,2025-07-17T13:30:56.518283181Z,2025-07-17T13:30:56.518283181Z,10,2,1108,A,A,0,13.4,10,130,165400,34951153,13.25,11,1,13.4,34,2,12.99,100,1,13.67,100,1,12.73,100,1,13.93,100,1,12.67,100,1,14,100,1,12.47,100,1,14.2,200,2,12.46,100,1,14.26,700,1,12.42,700,1,14.27,700,1,12.37,700,1,14.29,200,2,12.36,200,2,14.34,200,2,12.33,202,3,14.43,2,1,ARL,47164169
268,2025-07-17T13:31:01.011743292Z,2025-07-17T13:31:01.011743292Z,10,2,1108,A,A,4,14.2,700,128,166113,35180694,13.25,11,1,13.4,34,2,12.99,100,1,13.67,100,1,12.73,100,1,13.93,100,1,12.67,100,1,14,100,1,12.47,100,1,14.2,900,3,12.46,100,1,14.26,700,1,12.42,700,1,14.27,700,1,12.37,700,1,14.29,200,2,12.36,200,2,14.34,200,2,12.33,202,3,14.43,2,1,ARL,47376925
269,2025-07-17T13:31:01.028848502Z,2025-07-17T13:31:01.028848502Z,10,2,1108,A,B,6,12.43,700,130,165268,35188622,13.25,11,1,13.4,34,2,12.99,100,1,13.67,100,1,12.73,100,1,13.93,100,1,12.67,100,1,14,100,1,12.47,100,1,14.2,900,3,12.46,100,1,14.26,700,1,12.43,700,1,14.27,700,1,12.42,700,1,14.29,200,2,12.37,700,1,14.34,200,2,12.36,200,2,14.43,2,1,ARL,47383873
270,2025-07-17T13:31:01.131557345Z,2025-07-17T13:31:01.131557345Z,10,2,1108,C,A,0,13.4,10,128,168465,35203355,13.25,11,1,13.4,24,1,12.99,100,1,13.67,100,1,12.73,100,1,13.93,100,1,12.67,100,1,14,100,1,12.47,100,1,14.2,900,3,12.46,100,1,14.26,700,1,12.43,700,1,14.27,700,1,12.42,700,1,14.29,200,2,12.37,700,1,14.34,200,2,12.36,200,2,14.43,2,1,ARL,47164169
271,2025-07-17T13:31:08.376321454Z,2025-07-17T13:31:08.376321454Z,10,2,1108,C,A,0,13.4,24,130,165179,35703639,13.25,11,1,13.67,100,1,12.99,100,1,13.93,100,1,12.73,100,1,14,100,1,12.67,100,1,14.2,900,3,12.47,100,1,14.26,700,1,12.46,100,1,14.27,700,1,12.43,700,1,14.29,200,2,12.42,700,1,14.34,200,2,12.37,700,1,14.43,2,1,12.36,200,2,14.44,100,1,ARL,46613073
272,2025-07-17T13:31:08.376692815Z,2025-07-17T13:31:08.376692815Z,10,2,1108,A,A,0,13.4,18,130,165233,35703653,13.25,11,1,13.4,18,1,12.99,100,1,13.67,100,1,12.73,100,1,13.93,100,1,12.67,100,1,14,100,1,12.47,100,1,14.2,900,3,12.46,100,1,14.26,700,1,12.43,700,1,14.27,700,1,12.42,700,1,14.29,200,2,12.37,700,1,14.34,200,2,12.36,200,2,14.43,2,1,ARL,47873813
273,2025-07-17T13:31:08.377022927Z,2025-07-17T13:31:08.377022927Z,10,2,1108,C,A,7,14.29,100,0,165541,35703666,13.25,11,1,13.4,18,1,12.99,100,1,13.67,100,1,12.73,100,1,13.93,100,1,12.67,100,1,14,100,1,12.47,100,1,14.2,900,3,12.46,100,1,14.26,700,1,12.43,700,1,14.27,700,1,12.42,700,1,14.29,100,1,12.37,700,1,14.34,200,2,12.36,200,2,14.43,2,1,ARL,44720033
274,2025-07-17T13:31:09.399928944Z,2025-07-17T13:31:09.399928944Z,10,2,1108,A,A,7,14.29,100,130,165829,35758774,13.25,11,1,13.4,18,1,12.99,100,1,13.67,100,1,12.73,100,1,13.93,100,1,12.67,100,1,14,100,1,12.47,100,1,14.2,900,3,12.46,100,1,14.26,700,1,12.43,700,1,14.27,700,1,12.42,700,1,14.29,200,2,12.37,700,1,14.34,200,2,12.36,200,2,14.43,2,1,ARL,47927629
275,2025-07-17T13:31:16.538876621Z,2025-07-17T13:31:16.538876621Z,10,2,1108,A,A,0,13.4,10,130,165436,36186495,13.25,11,1,13.4,28,2,12.99,100,1,13.67,100,1,12.73,100,1,13.93,100,1,12.67,100,1,14,100,1,12.47,100,1,14.2,900,3,12.46,100,1,14.26,700,1,12.43,700,1,14.27,700,1,12.42,700,1,14.29,200,2,12.37,700,1,14.34,200,2,12.36,200,2,14.43,2,1,ARL,48315949
276,2025-07-17T13:31:17.448559991Z,2025-07-17T13:31:17.448559991Z,10,2,1108,C,A,0,13.4,10,128,167985,36232894,13.25,11,1,13.4,18,1,12.99,100,1,13.67,100,1,12.73,100,1,13.93,100,1,12.67,100,1,14,100,1,12.47,100,1,14.2,900,3,12.46,100,1,14.26,700,1,12.43,700,1,14.27,700,1,12.42,700,1,14.29,200,2,12.37,700,1,14.34,200,2,12.36,200,2,14.43,2,1,ARL,48315949
277,2025-07-17T13:31:34.835937627Z,2025-07-17T13:31:34.835937627Z,10,2,1108,C,A,0,13.4,18,130,165335,37177882,13.25,11,1,13.67,100,1,12.99,100,1,13.93,100,1,12.73,100,1,14,100,1,12.67,100,1,14.2,900,3,12.47,100,1,14.26,700,1,12.46,100,1,14.27,700,1,12.43,700,1,14.29,200,2,12.42,700,1,14.34,200,2,12.37,700,1,14.43,2,1,12.36,200,2,14.44,100,1,ARL,47873813
278,2025-07-17T13:31:34.836694504Z,2025-07-17T13:31:34.836694504Z,10,2,1108,C,A,6,14.29,100,0,166354,37177896,13.25,11,1,13.67,100,1,12.99,100,1,13.93,100,1,12.73,100,1,14,100,1,12.67,100,1,14.2,900,3,12.47,100,1,14.26,700,1,12.46,100,1,14.27,700,1,12.43,700,1,14.29,100,1,12.42,700,1,14.34,200,2,12.37,700,1,14.43,2,1,12.36,200,2,14.44,100,1,ARL,44719985
279,2025-07-17T13:31:34.837099615Z,2025-07-17T13:31:34.837099615Z,10,2,1108,C,A,6,14.29,100,0,165450,37177905,13.25,11,1,13.67,100,1,12.99,100,1,13.93,100,1,12.73,100,1,14,100,1,12.67,100,1,14.2,900,3,12.47,100,1,14.26,700,1,12.46,100,1,14.27,700,1,12.43,700,1,14.34,200,2,12.42,700,1,14.43,2,1,12.37,700,1,14.44,100,1,12.36,200,2,14.46,700,1,ARL,47927629
280,2025-07-17T13:31:34.837099615Z,2025-07-17T13:31:34.837099615Z,10,2,1108,A,A,10,14.56,100,130,165450,37177905,13.25,11,1,13.67,100,1,12.99,100,1,13.93,100,1,12.73,100,1,14,100,1,12.67,100,1,14.2,900,3,12.47,100,1,14.26,700,1,12.46,100,1,14.27,700,1,12.43,700,1,14.34,200,2,12.42,700,1,14.43,2,1,12.37,700,1,14.44,100,1,12.36,200,2,14.46,700,1,ARL,49226101
281,2025-07-17T13:35:00.187526221Z,2025-07-17T13:35:00.187526221Z,10,2,1108,C,B,10,12.33,2,0,167974,45447658,13.25,11,1,13.67,100,1,12.99,100,1,13.93,100,1,12.73,100,1,14,100,1,12.67,100,1,14.2,900,3,12.47,100,1,14.26,700,1,12.46,100,1,14.27,700,1,12.43,700,1,14.34,200,2,12.42,700,1,14.43,2,1,12.37,700,1,14.44,100,1,12.36,200,2,14.46,700,1,ARL,43692153
282,2025-07-17T13:35:00.187526221Z,2025-07-17T13:35:00.187526221Z,10,2,1108,A,B,2,12.88,2,128,167974,45447658,13.25,11,1,13.67,100,1,12.99,100,1,13.93,100,1,12.88,2,1,14,100,1,12.73,100,1,14.2,900,3,12.67,100,1,14.26,700,1,12.47,100,1,14.27,700,1,12.46,100,1,14.34,200,2,12.43,700,1,14.43,2,1,12.42,700,1,14.44,100,1,12.37,700,1,14.46,700,1,ARL,58709193
283,2025-07-17T13:35:00.187528642Z,2025-07-17T13:35:00.187528642Z,10,2,1108,C,A,7,14.43,2,0,166078,45447661,13.25,11,1,13.67,100,1,12.99,100,1,13.93,100,1,12.88,2,1,14,100,1,12.73,100,1,14.2,900,3,12.67,100,1,14.26,700,1,12.47,100,1,14.27,700,1,12.46,100,1,14.34,200,2,12.43,700,1,14.44,100,1,12.42,700,1,14.46,700,1,12.37,700,1,14.56,200,2,ARL,44904733
284,2025-07-17T13:35:00.187528642Z,2025-07-17T13:35:00.187528642Z,10,2,1108,A,A,1,13.78,2,130,166078,45447661,13.25,11,1,13.67,100,1,12.99,100,1,13.78,2,1,12.88,2,1,13.93,100,1,12.73,100,1,14,100,1,12.67,100,1,14.2,900,3,12.47,100,1,14.26,700,1,12.46,100,1,14.27,700,1,12.43,700,1,14.34,200,2,12.42,700,1,14.44,100,1,12.37,700,1,14.46,700,1,ARL,58709197
285,2025-07-17T13:37:31.076154614Z,2025-07-17T13:37:31.076154614Z,10,2,1108,C,A,10,14.56,100,0,165432,51978366,13.25,11,1,13.67,100,1,12.99,100,1,13.78,2,1,12.88,2,1,13.93,100,1,12.73,100,1,14,100,1,12.67,100,1,14.2,900,3,12.47,100,1,14.26,700,1,12.46,100,1,14.27,700,1,12.43,700,1,14.34,200,2,12.42,700,1,14.44,100,1,12.37,700,1,14.46,700,1,ARL,49226101
286,2025-07-17T13:37:31.076154614Z,2025-07-17T13:37:31.076154614Z,10,2,1108,A,A,7,14.29,100,130,165432,51978366,13.25,11,1,13.67,100,1,12.99,100,1,13.78,2,1,12.88,2,1,13.93,100,1,12.73,100,1,14,100,1,12.67,100,1,14.2,900,3,12.47,100,1,14.26,700,1,12.46,100,1,14.27,700,1,12.43,700,1,14.29,100,1,12.42,700,1,14.34,200,2,12.37,700,1,14.44,100,1,ARL,65160189
287,2025-07-17T13:37:31.076330756Z,2025-07-17T13:37:31.076330756Z,10,2,1108,A,A,7,14.29,100,130,165647,51978372,13.25,11,1,13.67,100,1,12.99,100,1,13.78,2,1,12.88,2,1,13.93,100,1,12.73,100,1,14,100,1,12.67,100,1,14.2,900,3,12.47,100,1,14.26,700,1,12.46,100,1,14.27,700,1,12.43,700,1,14.29,200,2,12.42,700,1,14.34,200,2,12.37,700,1,14.44,100,1,ARL,65160193
288,2025-07-17T13:38:08.679744459Z,2025-07-17T13:38:08.679744459Z,10,2,1108,C,A,7,14.29,100,0,165730,53264917,13.25,11,1,13.67,100,1,12.99,100,1,13.78,2,1,12.88,2,1,13.93,100,1,12.73,100,1,14,100,1,12.67,100,1,14.2,900,3,12.47,100,1,14.26,700,1,12.46,100,1,14.27,700,1,12.43,700,1,14.29,100,1,12.42,700,1,14.34,200,2,12.37,700,1,14.44,100,1,ARL,65160189
289,2025-07-17T13:38:08.679752190Z,2025-07-17T13:38:08.679752190Z,10,2,1108,C,A,7,14.29,100,0,165642,53264918,13.25,11,1,13.67,100,1,12.99,100,1,13.78,2,1,12.88,2,1,13.93,100,1,12.73,100,1,14,100,1,12.67,100,1,14.2,900,3,12.47,100,1,14.26,700,1,12.46,100,1,14.27,700,1,12.43,700,1,14.34,200,2,12.42,700,1,14.44,100,1,12.37,700,1,14.46,700,1,ARL,65160193
290,2025-07-17T13:38:08.679752190Z,2025-07-17T13:38:08.679752190Z,10,2,1108,A,A,10,14.56,100,130,165642,53264918,13.25,11,1,13.67,100,1,12.99,100,1,13.78,2,1,12.88,2,1,13.93,100,1,12.73,100,1,14,100,1,12.67,100,1,14.2,900,3,12.47,100,1,14.26,700,1,12.46,100,1,14.27,700,1,12.43,700,1,14.34,200,2,12.42,700,1,14.44,100,1,12.37,700,1,14.46,700,1,ARL,66501341
291,2025-07-17T13:38:09.686863512Z,2025-07-17T13:38:09.686863512Z,10,2,1108,C,A,10,14.56,100,0,165458,53302839,13.25,11,1,13.67,100,1,12.99,100,1,13.78,2,1,12.88,2,1,13.93,100,1,12.73,100,1,14,100,1,12.67,100,1,14.2,900,3,12.47,100,1,14.26,700,1,12.46,100,1,14.27,700,1,12.43,700,1,14.34,200,2,12.42,700,1,14.44,100,1,12.37,700,1,14.46,700,1,ARL,66501333
292,2025-07-17T13:38:09.686863512Z,2025-07-17T13:38:09.686863512Z,10,2,1108,A,A,7,14.29,100,130,165458,53302839,13.25,11,1,13.67,100,1,12.99,100,1,13.78,2,1,12.88,2,1,13.93,100,1,12.73,100,1,14,100,1,12.67,100,1,14.2,900,3,12.47,100,1,14.26,700,1,12.46,100,1,14.27,700,1,12.43,700,1,14.29,100,1,12.42,700,1,14.34,200,2,12.37,700,1,14.44,100,1,ARL,66538149
293,2025-07-17T13:38:09.708029202Z,2025-07-17T13:38:09.708029202Z,10,2,1108,A,A,7,14.29,100,130,165801,53303094,13.25,11,1,13.67,100,1,12.99,100,1,13.78,2,1,12.88,2,1,13.93,100,1,12.73,100,1,14,100,1,12.67,100,1,14.2,900,3,12.47,100,1,14.26,700,1,12.46,100,1,14.27,700,1,12.43,700,1,14.29,200,2,12.42,700,1,14.34,200,2,12.37,700,1,14.44,100,1,ARL,66538573
294,2025-07-17T13:38:44.678957477Z,2025-07-17T13:38:44.678957477Z,10,2,1108,A,A,0,13.4,15,130,165385,54485050,13.25,11,1,13.4,15,1,12.99,100,1,13.67,100,1,12.88,2,1,13.78,2,1,12.73,100,1,13.93,100,1,12.67,100,1,14,100,1,12.47,100,1,14.2,900,3,12.46,100,1,14.26,700,1,12.43,700,1,14.27,700,1,12.42,700,1,14.29,200,2,12.37,700,1,14.34,200,2,ARL,67832461
295,2025-07-17T13:38:44.679278833Z,2025-07-17T13:38:44.679278833Z,10,2,1108,C,A,8,14.29,100,0,165513,54485052,13.25,11,1,13.4,15,1,12.99,100,1,13.67,100,1,12.88,2,1,13.78,2,1,12.73,100,1,13.93,100,1,12.67,100,1,14,100,1,12.47,100,1,14.2,900,3,12.46,100,1,14.26,700,1,12.43,700,1,14.27,700,1,12.42,700,1,14.29,100,1,12.37,700,1,14.34,200,2,ARL,66538149
296,2025-07-17T13:38:45.695265148Z,2025-07-17T13:38:45.695265148Z,10,2,1108,A,A,8,14.29,100,130,165372,54508575,13.25,11,1,13.4,15,1,12.99,100,1,13.67,100,1,12.88,2,1,13.78,2,1,12.73,100,1,13.93,100,1,12.67,100,1,14,100,1,12.47,100,1,14.2,900,3,12.46,100,1,14.26,700,1,12.43,700,1,14.27,700,1,12.42,700,1,14.29,200,2,12.37,700,1,14.34,200,2,ARL,67857641
297,2025-07-17T13:39:08.713907562Z,2025-07-17T13:39:08.713907562Z,10,2,1108,C,A,0,13.4,15,130,165320,55204868,13.25,11,1,13.67,100,1,12.99,100,1,13.78,2,1,12.88,2,1,13.93,100,1,12.73,100,1,14,100,1,12.67,100,1,14.2,900,3,12.47,100,1,14.26,700,1,12.46,100,1,14.27,700,1,12.43,700,1,14.29,200,2,12.42,700,1,14.34,200,2,12.37,700,1,14.44,100,1,ARL,67832461
298,2025-07-17T13:39:08.714284059Z,2025-07-17T13:39:08.714284059Z,10,2,1108,A,A,0,13.4,24,130,165491,55204884,13.25,11,1,13.4,24,1,12.99,100,1,13.67,100,1,12.88,2,1,13.78,2,1,12.73,100,1,13.93,100,1,12.67,100,1,14,100,1,12.47,100,1,14.2,900,3,12.46,100,1,14.26,700,1,12.43,700,1,14.27,700,1,12.42,700,1,14.29,200,2,12.37,700,1,14.34,200,2,ARL,68625181
299,2025-07-17T13:39:39.996436857Z,2025-07-17T13:39:39.996436857Z,10,2,1108,T,A,0,13.4,1,130,166323,56150102,13.25,11,1,13.4,23,1,12.99,100,1,13.67,100,1,12.88,2,1,13.78,2,1,12.73,100,1,13.93,100,1,12.67,100,1,14,100,1,12.47,100,1,14.2,900,3,12.46,100,1,14.26,700,1,12.43,700,1,14.27,700,1,12.42,700,1,14.29,200,2,12.37,700,1,14.34,200,2,ARL,0
300,2025-07-17T13:39:39.996833282Z,2025-07-17T13:39:39.996833282Z,10,2,1108,C,A,0,13.4,23,130,165052,56150114,13.25,11,1,13.67,100,1,12.99,100,1,13.78,2,1,12.88,2,1,13.93,100,1,12.73,100,1,14,100,1,12.67,100,1,14.2,900,3,12.47,100,1,14.26,700,1,12.46,100,1,14.27,700,1,12.43,700,1,14.29,200,2,12.42,700,1,14.34,200,2,12.37,700,1,14.44,100,1,ARL,68625181
301,2025-07-17T13:39:39.997144158Z,2025-07-17T13:39:39.997144158Z,10,2,1108,C,A,7,14.29,100,0,165357,56150130,13.25,11,1,13.67,100,1,12.99,100,1,13.78,2,1,12.88,2,1,13.93,100,1,12.73,100,1,14,100,1,12.67,100,1,14.2,900,3,12.47,100,1,14.26,700,1,12.46,100,1,14.27,700,1,12.43,700,1,14.29,100,1,12.42,700,1,14.34,200,2,12.37,700,1,14.44,100,1,ARL,66538573
302,2025-07-17T13:39:39.997211562Z,2025-07-17T13:39:39.997211562Z,10,2,1108,A,A,0,13.4,24,130,165311,56150131,13.25,11,1,13.4,24,1,12.99,100,1,13.67,100,1,12.88,2,1,13.78,2,1,12.73,100,1,13.93,100,1,12.67,100,1,14,100,1,12.47,100,1,14.2,900,3,12.46,100,1,14.26,700,1,12.43,700,1,14.27,700,1,12.42,700,1,14.29,100,1,12.37,700,1,14.34,200,2,ARL,69677521
303,2025-07-17T13:39:41.018783466Z,2025-07-17T13:39:41.018783466Z,10,2,1108,A,A,9,14.3,100,130,165467,56183429,13.25,11,1,13.4,24,1,12.99,100,1,13.67,100,1,12.88,2,1,13.78,2,1,12.73,100,1,13.93,100,1,12.67,100,1,14,100,1,12.47,100,1,14.2,900,3,12.46,100,1,14.26,700,1,12.43,700,1,14.27,700,1,12.42,700,1,14.29,100,1,12.37,700,1,14.3,100,1,ARL,69725541
304,2025-07-17T13:40:08.782383621Z,2025-07-17T13:40:08.782383621Z,10,2,1108,C,A,0,13.4,24,130,165426,57235944,13.25,11,1,13.67,100,1,12.99,100,1,13.78,2,1,12.88,2,1,13.93,100,1,12.73,100,1,14,100,1,12.67,100,1,14.2,900,3,12.47,100,1,14.26,700,1,12.46,100,1,14.27,700,1,12.43,700,1,14.29,100,1,12.42,700,1,14.3,100,1,12.37,700,1,14.34,200,2,ARL,69677521
305,2025-07-17T13:40:08.782758499Z,2025-07-17T13:40:08.782758499Z,10,2,1108,A,A,0,13.4,18,130,165479,57235956,13.25,11,1,13.4,18,1,12.99,100,1,13.67,100,1,12.88,2,1,13.78,2,1,12.73,100,1,13.93,100,1,12.67,100,1,14,100,1,12.47,100,1,14.2,900,3,12.46,100,1,14.26,700,1,12.43,700,1,14.27,700,1,12.42,700,1,14.29,100,1,12.37,700,1,14.3,100,1,ARL,70897053
306,2025-07-17T13:41:08.818711250Z,2025-07-17T13:41:08.818711250Z,10,2,1108,C,A,0,13.4,18,130,165322,59313726,13.25,11,1,13.67,100,1,12.99,100,1,13.78,2,1,12.88,2,1,13.93,100,1,12.73,100,1,14,100,1,12.67,100,1,14.2,900,3,12.47,100,1,14.26,700,1,12.46,100,1,14.27,700,1,12.43,700,1,14.29,100,1,12.42,700,1,14.3,100,1,12.37,700,1,14.34,200,2,ARL,70897053
307,2025-07-17T13:41:08.819083504Z,2025-07-17T13:41:08.819083504Z,10,2,1108,A,A,0,13.4,24,130,166041,59313736,13.25,11,1,13.4,24,1,12.99,100,1,13.67,100,1,12.88,2,1,13.78,2,1,12.73,100,1,13.93,100,1,12.67,100,1,14,100,1,12.47,100,1,14.2,900,3,12.46,100,1,14.26,700,1,12.43,700,1,14.27,700,1,12.42,700,1,14.29,100,1,12.37,700,1,14.3,100,1,ARL,73109413
308,2025-07-17T13:41:08.819104931Z,2025-07-17T13:41:08.819104931Z,10,2,1108,C,A,9,14.3,100,0,165581,59313739,13.25,11,1,13.4,24,1,12.99,100,1,13.67,100,1,12.88,2,1,13.78,2,1,12.73,100,1,13.93,100,1,12.67,100,1,14,100,1,12.47,100,1,14.2,900,3,12.46,100,1,14.26,700,1,12.43,700,1,14.27,700,1,12.42,700,1,14.29,100,1,12.37,700,1,14.34,200,2,ARL,69725541
309,2025-07-17T13:41:09.881085734Z,2025-07-17T13:41:09.881085734Z,10,2,1108,A,A,9,14.3,100,130,165459,59383199,13.25,11,1,13.4,24,1,12.99,100,1,13.67,100,1,12.88,2,1,13.78,2,1,12.73,100,1,13.93,100,1,12.67,100,1,14,100,1,12.47,100,1,14.2,900,3,12.46,100,1,14.26,700,1,12.43,700,1,14.27,700,1,12.42,700,1,14.29,100,1,12.37,700,1,14.3,100,1,ARL,73183421
310,2025-07-17T13:41:44.348494744Z,2025-07-17T13:41:44.348494744Z,10,2,1108,C,A,0,13.4,24,130,165361,60614543,13.25,11,1,13.67,100,1,12.99,100,1,13.78,2,1,12.88,2,1,13.93,100,1,12.73,100,1,14,100,1,12.67,100,1,14.2,900,3,12.47,100,1,14.26,700,1,12.46,100,1,14.27,700,1,12.43,700,1,14.29,100,1,12.42,700,1,14.3,100,1,12.37,700,1,14.34,200,2,ARL,73109413
311,2025-07-17T13:41:44.349416601Z,2025-07-17T13:41:44.349416601Z,10,2,1108,C,A,8,14.3,100,0,165376,60614557,13.25,11,1,13.67,100,1,12.99,100,1,13.78,2,1,12.88,2,1,13.93,100,1,12.73,100,1,14,100,1,12.67,100,1,14.2,900,3,12.47,100,1,14.26,700,1,12.46,100,1,14.27,700,1,12.43,700,1,14.29,100,1,12.42,700,1,14.34,200,2,12.37,700,1,14.44,100,1,ARL,73183421
312,2025-07-17T13:41:45.405013016Z,2025-07-17T13:41:45.405013016Z,10,2,1108,A,A,8,14.3,100,130,165828,60651462,13.25,11,1,13.67,100,1,12.99,100,1,13.78,2,1,12.88,2,1,13.93,100,1,12.73,100,1,14,100,1,12.67,100,1,14.2,900,3,12.47,100,1,14.26,700,1,12.46,100,1,14.27,700,1,12.43,700,1,14.29,100,1,12.42,700,1,14.3,100,1,12.37,700,1,14.34,200,2,ARL,74589605
313,2025-07-17T13:42:08.821155108Z,2025-07-17T13:42:08.821155108Z,10,2,1108,C,A,7,14.29,100,0,165715,61488742,13.25,11,1,13.67,100,1,12.99,100,1,13.78,2,1,12.88,2,1,13.93,100,1,12.73,100,1,14,100,1,12.67,100,1,14.2,900,3,12.47,100,1,14.26,700,1,12.46,100,1,14.27,700,1,12.43,700,1,14.3,100,1,12.42,700,1,14.34,200,2,12.37,700,1,14.44,100,1,ARL,67857641
314,2025-07-17T13:42:09.826891682Z,2025-07-17T13:42:09.826891682Z,10,2,1108,A,A,7,14.3,100,130,165656,61523538,13.25,11,1,13.67,100,1,12.99,100,1,13.78,2,1,12.88,2,1,13.93,100,1,12.73,100,1,14,100,1,12.67,100,1,14.2,900,3,12.47,100,1,14.26,700,1,12.46,100,1,14.27,700,1,12.43,700,1,14.3,200,2,12.42,700,1,14.34,200,2,12.37,700,1,14.44,100,1,ARL,75577257
315,2025-07-17T13:43:08.826078491Z,2025-07-17T13:43:08.826078491Z,10,2,1108,C,A,7,14.3,100,0,165634,63579150,13.25,11,1,13.67,100,1,12.99,100,1,13.78,2,1,12.88,2,1,13.93,100,1,12.73,100,1,14,100,1,12.67,100,1,14.2,900,3,12.47,100,1,14.26,700,1,12.46,100,1,14.27,700,1,12.43,700,1,14.3,100,1,12.42,700,1,14.34,200,2,12.37,700,1,14.44,100,1,ARL,75577257
316,2025-07-17T13:43:09.832406764Z,2025-07-17T13:43:09.832406764Z,10,2,1108,A,A,7,14.3,100,130,165651,63604352,13.25,11,1,13.67,100,1,12.99,100,1,13.78,2,1,12.88,2,1,13.93,100,1,12.73,100,1,14,100,1,12.67,100,1,14.2,900,3,12.47,100,1,14.26,700,1,12.46,100,1,14.27,700,1,12.43,700,1,14.3,200,2,12.42,700,1,14.34,200,2,12.37,700,1,14.44,100,1,ARL,77910357
317,2025-07-17T13:46:09.540851349Z,2025-07-17T13:46:09.540851349Z,10,2,1108,C,A,4,14.2,700,130,165550,69578535,13.25,11,1,13.67,100,1,12.99,100,1,13.78,2,1,12.88,2,1,13.93,100,1,12.73,100,1,14,100,1,12.67,100,1,14.2,200,2,12.47,100,1,14.26,700,1,12.46,100,1,14.27,700,1,12.43,700,1,14.3,200,2,12.42,700,1,14.34,200,2,12.37,700,1,14.44,100,1,ARL,47376925
318,2025-07-17T13:46:09.540892810Z,2025-07-17T13:46:09.540892810Z,10,2,1108,A,A,9,14.36,700,130,165423,69578537,13.25,11,1,13.67,100,1,12.99,100,1,13.78,2,1,12.88,2,1,13.93,100,1,12.73,100,1,14,100,1,12.67,100,1,14.2,200,2,12.47,100,1,14.26,700,1,12.46,100,1,14.27,700,1,12.43,700,1,14.3,200,2,12.42,700,1,14.34,200,2,12.37,700,1,14.36,700,1,ARL,84607761
319,2025-07-17T13:46:09.541269186Z,2025-07-17T13:46:09.541269186Z,10,2,1108,C,A,10,14.44,100,0,165390,69578543,13.25,11,1,13.67,100,1,12.99,100,1,13.78,2,1,12.88,2,1,13.93,100,1,12.73,100,1,14,100,1,12.67,100,1,14.2,200,2,12.47,100,1,14.26,700,1,12.46,100,1,14.27,700,1,12.43,700,1,14.3,200,2,12.42,700,1,14.34,200,2,12.37,700,1,14.36,700,1,ARL,43373009
320,2025-07-17T13:46:09.541327298Z,2025-07-17T13:46:09.541327298Z,10,2,1108,C,A,3,14,100,130,165331,69578544,13.25,11,1,13.67,100,1,12.99,100,1,13.78,2,1,12.88,2,1,13.93,100,1,12.73,100,1,14.2,200,2,12.67,100,1,14.26,700,1,12.47,100,1,14.27,700,1,12.46,100,1,14.3,200,2,12.43,700,1,14.34,200,2,12.42,700,1,14.36,700,1,12.37,700,1,14.46,700,1,ARL,43663233
321,2025-07-17T13:46:09.541629920Z,2025-07-17T13:46:09.541629920Z,10,2,1108,C,A,7,14.34,100,0,165336,69578547,13.25,11,1,13.67,100,1,12.99,100,1,13.78,2,1,12.88,2,1,13.93,100,1,12.73,100,1,14.2,200,2,12.67,100,1,14.26,700,1,12.47,100,1,14.27,700,1,12.46,100,1,14.3,200,2,12.43,700,1,14.34,100,1,12.42,700,1,14.36,700,1,12.37,700,1,14.46,700,1,ARL,43755821
322,2025-07-17T13:46:09.541682402Z,2025-07-17T13:46:09.541682402Z,10,2,1108,A,A,6,14.28,100,130,165117,69578551,13.25,11,1,13.67,100,1,12.99,100,1,13.78,2,1,12.88,2,1,13.93,100,1,12.73,100,1,14.2,200,2,12.67,100,1,14.26,700,1,12.47,100,1,14.27,700,1,12.46,100,1,14.28,100,1,12.43,700,1,14.3,200,2,12.42,700,1,14.34,100,1,12.37,700,1,14.36,700,1,ARL,84607809
323,2025-07-17T13:46:09.546381306Z,2025-07-17T13:46:09.546381306Z,10,2,1108,C,A,3,14.2,100,130,165176,69578814,13.25,11,1,13.67,100,1,12.99,100,1,13.78,2,1,12.88,2,1,13.93,100,1,12.73,100,1,14.2,100,1,12.67,100,1,14.26,700,1,12.47,100,1,14.27,700,1,12.46,100,1,14.28,100,1,12.43,700,1,14.3,200,2,12.42,700,1,14.34,100,1,12.37,700,1,14.36,700,1,ARL,43554141
324,2025-07-17T13:46:09.560753276Z,2025-07-17T13:46:09.560753276Z,10,2,1108,C,A,0,13.67,100,130,165344,69579444,13.25,11,1,13.78,2,1,12.99,100,1,13.93,100,1,12.88,2,1,14.2,100,1,12.73,100,1,14.26,700,1,12.67,100,1,14.27,700,1,12.47,100,1,14.28,100,1,12.46,100,1,14.3,200,2,12.43,700,1,14.34,100,1,12.42,700,1,14.36,700,1,12.37,700,1,14.46,700,1,ARL,43953649
325,2025-07-17T13:46:09.560789009Z,2025-07-17T13:46:09.560789009Z,10,2,1108,C,A,8,14.36,700,130,164841,69579446,13.25,11,1,13.78,2,1,12.99,100,1,13.93,100,1,12.88,2,1,14.2,100,1,12.73,100,1,14.26,700,1,12.67,100,1,14.27,700,1,12.47,100,1,14.28,100,1,12.46,100,1,14.3,200,2,12.43,700,1,14.34,100,1,12.42,700,1,14.46,700,1,12.37,700,1,14.47,100,1,ARL,84607761
326,2025-07-17T13:46:09.560803559Z,2025-07-17T13:46:09.560803559Z,10,2,1108,A,A,2,13.94,100,130,165260,69579448,13.25,11,1,13.78,2,1,12.99,100,1,13.93,100,1,12.88,2,1,13.94,100,1,12.73,100,1,14.2,100,1,12.67,100,1,14.26,700,1,12.47,100,1,14.27,700,1,12.46,100,1,14.28,100,1,12.43,700,1,14.3,200,2,12.42,700,1,14.34,100,1,12.37,700,1,14.46,700,1,ARL,84609305
327,2025-07-17T13:46:09.560815603Z,2025-07-17T13:46:09.560815603Z,10,2,1108,C,A,5,14.27,700,130,165417,69579449,13.25,11,1,13.78,2,1,12.99,100,1,13.93,100,1,12.88,2,1,13.94,100,1,12.73,100,1,14.2,100,1,12.67,100,1,14.26,700,1,12.47,100,1,14.28,100,1,12.46,100,1,14.3,200,2,12.43,700,1,14.34,100,1,12.42,700,1,14.46,700,1,12.37,700,1,14.47,100,1,ARL,44491681
328,2025-07-17T13:46:09.561543868Z,2025-07-17T13:46:09.561543868Z,10,2,1108,C,A,4,14.26,700,128,167043,69579488,13.25,11,1,13.78,2,1,12.99,100,1,13.93,100,1,12.88,2,1,13.94,100,1,12.73,100,1,14.2,100,1,12.67,100,1,14.28,100,1,12.47,100,1,14.3,200,2,12.46,100,1,14.34,100,1,12.43,700,1,14.46,700,1,12.42,700,1,14.47,100,1,12.37,700,1,14.49,100,1,ARL,44598153
329,2025-07-17T13:46:09.561788902Z,2025-07-17T13:46:09.561788902Z,10,2,1108,C,A,10,14.63,100,0,166087,69579537,13.25,11,1,13.78,2,1,12.99,100,1,13.93,100,1,12.88,2,1,13.94,100,1,12.73,100,1,14.2,100,1,12.67,100,1,14.28,100,1,12.47,100,1,14.3,200,2,12.46,100,1,14.34,100,1,12.43,700,1,14.46,700,1,12.42,700,1,14.47,100,1,12.37,700,1,14.49,100,1,ARL,84607801
330,2025-07-17T13:46:09.561992206Z,2025-07-17T13:46:09.561992206Z,10,2,1108,A,A,10,14.67,700,130,165245,69579579,13.25,11,1,13.78,2,1,12.99,100,1,13.93,100,1,12.88,2,1,13.94,100,1,12.73,100,1,14.2,100,1,12.67,100,1,14.28,100,1,12.47,100,1,14.3,200,2,12.46,100,1,14.34,100,1,12.43,700,1,14.46,700,1,12.42,700,1,14.47,100,1,12.37,700,1,14.49,100,1,ARL,84609409
331,2025-07-17T13:46:09.565213822Z,2025-07-17T13:46:09.565213822Z,10,2,1108,C,A,0,13.78,2,0,165722,69579892,13.25,11,1,13.93,100,1,12.99,100,1,13.94,100,1,12.88,2,1,14.2,100,1,12.73,100,1,14.28,100,1,12.67,100,1,14.3,200,2,12.47,100,1,14.34,100,1,12.46,100,1,14.46,700,1,12.43,700,1,14.47,100,1,12.42,700,1,14.49,100,1,12.37,700,1,14.67,700,1,ARL,58709197
332,2025-07-17T13:46:09.565213822Z,2025-07-17T13:46:09.565213822Z,10,2,1108,A,A,0,13.93,2,130,165722,69579892,13.25,11,1,13.93,102,2,12.99,100,1,13.94,100,1,12.88,2,1,14.2,100,1,12.73,100,1,14.28,100,1,12.67,100,1,14.3,200,2,12.47,100,1,14.34,100,1,12.46,100,1,14.46,700,1,12.43,700,1,14.47,100,1,12.42,700,1,14.49,100,1,12.37,700,1,14.67,700,1,ARL,84609637
333,2025-07-17T13:46:09.566522227Z,2025-07-17T13:46:09.566522227Z,10,2,1108,C,A,1,13.94,100,130,164837,69579922,13.25,11,1,13.93,102,2,12.99,100,1,14.2,100,1,12.88,2,1,14.28,100,1,12.73,100,1,14.3,200,2,12.67,100,1,14.34,100,1,12.47,100,1,14.46,700,1,12.46,100,1,14.47,100,1,12.43,700,1,14.49,100,1,12.42,700,1,14.67,700,1,12.37,700,1,14.7,700,1,ARL,84609305
334,2025-07-17T13:46:09.566571131Z,2025-07-17T13:46:09.566571131Z,10,2,1108,A,A,2,14.21,100,130,165372,69579923,13.25,11,1,13.93,102,2,12.99,100,1,14.2,100,1,12.88,2,1,14.21,100,1,12.73,100,1,14.28,100,1,12.67,100,1,14.3,200,2,12.47,100,1,14.34,100,1,12.46,100,1,14.46,700,1,12.43,700,1,14.47,100,1,12.42,700,1,14.49,100,1,12.37,700,1,14.67,700,1,ARL,84609733
335,2025-07-17T13:46:09.591386919Z,2025-07-17T13:46:09.591386919Z,10,2,1108,C,A,8,14.49,100,0,165418,69581249,13.25,11,1,13.93,102,2,12.99,100,1,14.2,100,1,12.88,2,1,14.21,100,1,12.73,100,1,14.28,100,1,12.67,100,1,14.3,200,2,12.47,100,1,14.34,100,1,12.46,100,1,14.46,700,1,12.43,700,1,14.47,100,1,12.42,700,1,14.67,700,1,12.37,700,1,14.7,700,1,ARL,84607785
336,2025-07-17T13:46:09.595500037Z,2025-07-17T13:46:09.595500037Z,10,2,1108,A,A,8,14.63,700,128,167010,69582059,13.25,11,1,13.93,102,2,12.99,100,1,14.2,100,1,12.88,2,1,14.21,100,1,12.73,100,1,14.28,100,1,12.67,100,1,14.3,200,2,12.47,100,1,14.34,100,1,12.46,100,1,14.46,700,1,12.43,700,1,14.47,100,1,12.42,700,1,14.63,700,1,12.37,700,1,14.67,700,1,ARL,84612081
337,2025-07-17T13:46:09.610126066Z,2025-07-17T13:46:09.610126066Z,10,2,1108,C,A,5,14.34,100,0,165500,69582709,13.25,11,1,13.93,102,2,12.99,100,1,14.2,100,1,12.88,2,1,14.21,100,1,12.73,100,1,14.28,100,1,12.67,100,1,14.3,200,2,12.47,100,1,14.46,700,1,12.46,100,1,14.47,100,1,12.43,700,1,14.63,700,1,12.42,700,1,14.67,700,1,12.37,700,1,14.7,700,1,ARL,44088637
338,2025-07-17T13:46:09.610126066Z,2025-07-17T13:46:09.610126066Z,10,2,1108,A,A,10,14.91,100,130,165500,69582709,13.25,11,1,13.93,102,2,12.99,100,1,14.2,100,1,12.88,2,1,14.21,100,1,12.73,100,1,14.28,100,1,12.67,100,1,14.3,200,2,12.47,100,1,14.46,700,1,12.46,100,1,14.47,100,1,12.43,700,1,14.63,700,1,12.42,700,1,14.67,700,1,12.37,700,1,14.7,700,1,ARL,84612773
339,2025-07-17T13:46:09.812773551Z,2025-07-17T13:46:09.812773551Z,10,2,1108,A,A,10,14.76,100,130,165292,69586965,13.25,11,1,13.93,102,2,12.99,100,1,14.2,100,1,12.88,2,1,14.21,100,1,12.73,100,1,14.28,100,1,12.67,100,1,14.3,200,2,12.47,100,1,14.46,700,1,12.46,100,1,14.47,100,1,12.43,700,1,14.63,700,1,12.42,700,1,14.67,700,1,12.37,700,1,14.7,700,1,ARL,84618189
340,2025-07-17T13:46:09.812784722Z,2025-07-17T13:46:09.812784722Z,10,2,1108,C,A,1,14.2,100,130,165298,69586966,13.25,11,1,13.93,102,2,12.99,100,1,14.21,100,1,12.88,2,1,14.28,100,1,12.73,100,1,14.3,200,2,12.67,100,1,14.46,700,1,12.47,100,1,14.47,100,1,12.46,100,1,14.63,700,1,12.43,700,1,14.67,700,1,12.42,700,1,14.7,700,1,12.37,700,1,14.76,100,1,ARL,43804081
341,2025-07-17T13:46:09.936730596Z,2025-07-17T13:46:09.936730596Z,10,2,1108,C,A,0,13.93,100,130,165243,69592193,13.25,11,1,13.93,2,1,12.99,100,1,14.21,100,1,12.88,2,1,14.28,100,1,12.73,100,1,14.3,200,2,12.67,100,1,14.46,700,1,12.47,100,1,14.47,100,1,12.46,100,1,14.63,700,1,12.43,700,1,14.67,700,1,12.42,700,1,14.7,700,1,12.37,700,1,14.76,100,1,ARL,44066417
342,2025-07-17T13:46:09.936731544Z,2025-07-17T13:46:09.936731544Z,10,2,1108,A,A,6,14.48,100,130,165288,69592194,13.25,11,1,13.93,2,1,12.99,100,1,14.21,100,1,12.88,2,1,14.28,100,1,12.73,100,1,14.3,200,2,12.67,100,1,14.46,700,1,12.47,100,1,14.47,100,1,12.46,100,1,14.48,100,1,12.43,700,1,14.63,700,1,12.42,700,1,14.67,700,1,12.37,700,1,14.7,700,1,ARL,84624129
343,2025-07-17T13:46:10.046795728Z,2025-07-17T13:46:10.046795728Z,10,2,1108,C,A,9,14.7,700,130,165238,69596523,13.25,11,1,13.93,2,1,12.99,100,1,14.21,100,1,12.88,2,1,14.28,100,1,12.73,100,1,14.3,200,2,12.67,100,1,14.46,700,1,12.47,100,1,14.47,100,1,12.46,100,1,14.48,100,1,12.43,700,1,14.63,700,1,12.42,700,1,14.67,700,1,12.37,700,1,14.76,100,1,ARL,84609321
344,2025-07-17T13:46:10.046796743Z,2025-07-17T13:46:10.046796743Z,10,2,1108,C,A,7,14.63,700,130,166050,69596524,13.25,11,1,13.93,2,1,12.99,100,1,14.21,100,1,12.88,2,1,14.28,100,1,12.73,100,1,14.3,200,2,12.67,100,1,14.46,700,1,12.47,100,1,14.47,100,1,12.46,100,1,14.48,100,1,12.43,700,1,14.67,700,1,12.42,700,1,14.76,100,1,12.37,700,1,14.91,200,2,ARL,84612081
345,2025-07-17T13:46:10.046834863Z,2025-07-17T13:46:10.046834863Z,10,2,1108,A,A,10,14.99,700,0,166313,69596525,13.25,11,1,13.93,2,1,12.99,100,1,14.21,100,1,12.88,2,1,14.28,100,1,12.73,100,1,14.3,200,2,12.67,100,1,14.46,700,1,12.47,100,1,14.47,100,1,12.46,100,1,14.48,100,1,12.43,700,1,14.67,700,1,12.42,700,1,14.76,100,1,12.37,700,1,14.91,200,2,ARL,84628757
346,2025-07-17T13:46:10.046835277Z,2025-07-17T13:46:10.046835277Z,10,2,1108,A,A,9,14.91,700,130,165899,69596526,13.25,11,1,13.93,2,1,12.99,100,1,14.21,100,1,12.88,2,1,14.28,100,1,12.73,100,1,14.3,200,2,12.67,100,1,14.46,700,1,12.47,100,1,14.47,100,1,12.46,100,1,14.48,100,1,12.43,700,1,14.67,700,1,12.42,700,1,14.76,100,1,12.37,700,1,14.91,900,3,ARL,84628761
347,2025-07-17T13:46:10.046924268Z,2025-07-17T13:46:10.046924268Z,10,2,1108,C,A,0,13.93,2,0,165372,69596531,13.25,11,1,14.21,100,1,12.99,100,1,14.28,100,1,12.88,2,1,14.3,200,2,12.73,100,1,14.46,700,1,12.67,100,1,14.47,100,1,12.47,100,1,14.48,100,1,12.46,100,1,14.67,700,1,12.43,700,1,14.76,100,1,12.42,700,1,14.91,900,3,12.37,700,1,14.99,700,1,ARL,84609637
348,2025-07-17T13:46:10.046924268Z,2025-07-17T13:46:10.046924268Z,10,2,1108,A,A,0,14.2,2,130,165372,69596531,13.25,11,1,14.2,2,1,12.99,100,1,14.21,100,1,12.88,2,1,14.28,100,1,12.73,100,1,14.3,200,2,12.67,100,1,14.46,700,1,12.47,100,1,14.47,100,1,12.46,100,1,14.48,100,1,12.43,700,1,14.67,700,1,12.42,700,1,14.76,100,1,12.37,700,1,14.91,900,3,ARL,84628773
349,2025-07-17T13:46:10.047264301Z,2025-07-17T13:46:10.047264301Z,10,2,1108,C,A,2,14.28,100,130,165176,69596542,13.25,11,1,14.2,2,1,12.99,100,1,14.21,100,1,12.88,2,1,14.3,200,2,12.73,100,1,14.46,700,1,12.67,100,1,14.47,100,1,12.47,100,1,14.48,100,1,12.46,100,1,14.67,700,1,12.43,700,1,14.76,100,1,12.42,700,1,14.91,900,3,12.37,700,1,14.99,700,1,ARL,84607809
350,2025-07-17T13:46:10.047313929Z,2025-07-17T13:46:10.047313929Z,10,2,1108,C,A,6,14.67,700,130,165272,69596543,13.25,11,1,14.2,2,1,12.99,100,1,14.21,100,1,12.88,2,1,14.3,200,2,12.73,100,1,14.46,700,1,12.67,100,1,14.47,100,1,12.47,100,1,14.48,100,1,12.46,100,1,14.76,100,1,12.43,700,1,14.91,900,3,12.42,700,1,14.99,700,1,12.37,700,1,15.06,100,1,ARL,84609409
351,2025-07-17T13:46:10.047618250Z,2025-07-17T13:46:10.047618250Z,10,2,1108,A,A,7,14.83,100,128,166092,69596548,13.25,11,1,14.2,2,1,12.99,100,1,14.21,100,1,12.88,2,1,14.3,200,2,12.73,100,1,14.46,700,1,12.67,100,1,14.47,100,1,12.47,100,1,14.48,100,1,12.46,100,1,14.76,100,1,12.43,700,1,14.83,100,1,12.42,700,1,14.91,900,3,12.37,700,1,14.99,700,1,ARL,84628793
352,2025-07-17T13:46:10.047640842Z,2025-07-17T13:46:10.047640842Z,10,2,1108,C,A,3,14.46,700,130,165388,69596550,13.25,11,1,14.2,2,1,12.99,100,1,14.21,100,1,12.88,2,1,14.3,200,2,12.73,100,1,14.47,100,1,12.67,100,1,14.48,100,1,12.47,100,1,14.76,100,1,12.46,100,1,14.83,100,1,12.43,700,1,14.91,900,3,12.42,700,1,14.99,700,1,12.37,700,1,15.06,100,1,ARL,44548325
353,2025-07-17T13:46:10.047719954Z,2025-07-17T13:46:10.047719954Z,10,2,1108,A,A,8,14.95,700,130,165311,69596551,13.25,11,1,14.2,2,1,12.99,100,1,14.21,100,1,12.88,2,1,14.3,200,2,12.73,100,1,14.47,100,1,12.67,100,1,14.48,100,1,12.47,100,1,14.76,100,1,12.46,100,1,14.83,100,1,12.43,700,1,14.91,900,3,12.42,700,1,14.95,700,1,12.37,700,1,14.99,700,1,ARL,84628797
354,2025-07-17T13:46:10.047763743Z,2025-07-17T13:46:10.047763743Z,10,2,1108,C,A,7,14.91,100,0,165329,69596552,13.25,11,1,14.2,2,1,12.99,100,1,14.21,100,1,12.88,2,1,14.3,200,2,12.73,100,1,14.47,100,1,12.67,100,1,14.48,100,1,12.47,100,1,14.76,100,1,12.46,100,1,14.83,100,1,12.43,700,1,14.91,800,2,12.42,700,1,14.95,700,1,12.37,700,1,14.99,700,1,ARL,84609389
355,2025-07-17T13:46:10.047817649Z,2025-07-17T13:46:10.047817649Z,10,2,1108,C,A,10,15.06,100,0,165637,69596553,13.25,11,1,14.2,2,1,12.99,100,1,14.21,100,1,12.88,2,1,14.3,200,2,12.73,100,1,14.47,100,1,12.67,100,1,14.48,100,1,12.47,100,1,14.76,100,1,12.46,100,1,14.83,100,1,12.43,700,1,14.91,800,2,12.42,700,1,14.95,700,1,12.37,700,1,14.99,700,1,ARL,84624201
356,2025-07-17T13:46:10.048363798Z,2025-07-17T13:46:10.048363798Z,10,2,1108,A,A,10,15.14,700,130,165349,69596568,13.25,11,1,14.2,2,1,12.99,100,1,14.21,100,1,12.88,2,1,14.3,200,2,12.73,100,1,14.47,100,1,12.67,100,1,14.48,100,1,12.47,100,1,14.76,100,1,12.46,100,1,14.83,100,1,12.43,700,1,14.91,800,2,12.42,700,1,14.95,700,1,12.37,700,1,14.99,700,1,ARL,84628829
357,2025-07-17T13:46:10.055269067Z,2025-07-17T13:46:10.055269067Z,10,2,1108,C,A,1,14.21,100,130,165081,69596798,13.25,11,1,14.2,2,1,12.99,100,1,14.3,200,2,12.88,2,1,14.47,100,1,12.73,100,1,14.48,100,1,12.67,100,1,14.76,100,1,12.47,100,1,14.83,100,1,12.46,100,1,14.91,800,2,12.43,700,1,14.95,700,1,12.42,700,1,14.99,700,1,12.37,700,1,15.14,700,1,ARL,84609733
358,2025-07-17T13:46:10.055317945Z,2025-07-17T13:46:10.055317945Z,10,2,1108,A,A,3,14.48,100,130,165304,69596799,13.25,11,1,14.2,2,1,12.99,100,1,14.3,200,2,12.88,2,1,14.47,100,1,12.73,100,1,14.48,200,2,12.67,100,1,14.76,100,1,12.47,100,1,14.83,100,1,12.46,100,1,14.91,800,2,12.43,700,1,14.95,700,1,12.42,700,1,14.99,700,1,12.37,700,1,15.14,700,1,ARL,84629093
359,2025-07-17T13:46:10.061246123Z,2025-07-17T13:46:10.061246123Z,10,2,1108,C,A,3,14.48,100,130,164936,69596987,13.25,11,1,14.2,2,1,12.99,100,1,14.3,200,2,12.88,2,1,14.47,100,1,12.73,100,1,14.48,100,1,12.67,100,1,14.76,100,1,12.47,100,1,14.83,100,1,12.46,100,1,14.91,800,2,12.43,700,1,14.95,700,1,12.42,700,1,14.99,700,1,12.37,700,1,15.14,700,1,ARL,84629093
360,2025-07-17T13:46:10.061294728Z,2025-07-17T13:46:10.061294728Z,10,2,1108,A,A,4,14.59,100,130,165187,69596990,13.25,11,1,14.2,2,1,12.99,100,1,14.3,200,2,12.88,2,1,14.47,100,1,12.73,100,1,14.48,100,1,12.67,100,1,14.59,100,1,12.47,100,1,14.76,100,1,12.46,100,1,14.83,100,1,12.43,700,1,14.91,800,2,12.42,700,1,14.95,700,1,12.37,700,1,14.99,700,1,ARL,84629329
361,2025-07-17T13:46:10.109069598Z,2025-07-17T13:46:10.109069598Z,10,2,1108,C,A,7,14.91,100,0,165452,69598154,13.25,11,1,14.2,2,1,12.99,100,1,14.3,200,2,12.88,2,1,14.47,100,1,12.73,100,1,14.48,100,1,12.67,100,1,14.59,100,1,12.47,100,1,14.76,100,1,12.46,100,1,14.83,100,1,12.43,700,1,14.91,700,1,12.42,700,1,14.95,700,1,12.37,700,1,14.99,700,1,ARL,84612773
362,2025-07-17T13:46:10.551316402Z,2025-07-17T13:46:10.551316402Z,10,2,1108,C,A,2,14.47,100,0,165504,69614455,13.25,11,1,14.2,2,1,12.99,100,1,14.3,200,2,12.88,2,1,14.48,100,1,12.73,100,1,14.59,100,1,12.67,100,1,14.76,100,1,12.47,100,1,14.83,100,1,12.46,100,1,14.91,700,1,12.43,700,1,14.95,700,1,12.42,700,1,14.99,700,1,12.37,700,1,15.14,700,1,ARL,84608321
363,2025-07-17T13:46:10.551316402Z,2025-07-17T13:46:10.551316402Z,10,2,1108,A,A,9,15.09,100,130,165504,69614455,13.25,11,1,14.2,2,1,12.99,100,1,14.3,200,2,12.88,2,1,14.48,100,1,12.73,100,1,14.59,100,1,12.67,100,1,14.76,100,1,12.47,100,1,14.83,100,1,12.46,100,1,14.91,700,1,12.43,700,1,14.95,700,1,12.42,700,1,14.99,700,1,12.37,700,1,15.09,100,1,ARL,84650629
364,2025-07-17T13:46:10.904693578Z,2025-07-17T13:46:10.904693578Z,10,2,1108,C,A,4,14.76,100,130,164975,69628783,13.25,11,1,14.2,2,1,12.99,100,1,14.3,200,2,12.88,2,1,14.48,100,1,12.73,100,1,14.59,100,1,12.67,100,1,14.83,100,1,12.47,100,1,14.91,700,1,12.46,100,1,14.95,700,1,12.43,700,1,14.99,700,1,12.42,700,1,15.09,100,1,12.37,700,1,15.14,700,1,ARL,84618189
365,2025-07-17T13:46:11.840717150Z,2025-07-17T13:46:11.840717150Z,10,2,1108,A,A,5,14.87,100,130,165294,69663346,13.25,11,1,14.2,2,1,12.99,100,1,14.3,200,2,12.88,2,1,14.48,100,1,12.73,100,1,14.59,100,1,12.67,100,1,14.83,100,1,12.47,100,1,14.87,100,1,12.46,100,1,14.91,700,1,12.43,700,1,14.95,700,1,12.42,700,1,14.99,700,1,12.37,700,1,15.09,100,1,ARL,84708037
366,2025-07-17T13:46:11.840729407Z,2025-07-17T13:46:11.840729407Z,10,2,1108,C,A,2,14.48,100,130,165380,69663347,13.25,11,1,14.2,2,1,12.99,100,1,14.3,200,2,12.88,2,1,14.59,100,1,12.73,100,1,14.83,100,1,12.67,100,1,14.87,100,1,12.47,100,1,14.91,700,1,12.46,100,1,14.95,700,1,12.43,700,1,14.99,700,1,12.42,700,1,15.09,100,1,12.37,700,1,15.14,700,1,ARL,84624129
367,2025-07-17T13:46:23.920647302Z,2025-07-17T13:46:23.920647302Z,10,2,1108,C,B,2,12.88,2,0,165883,70104076,13.25,11,1,14.2,2,1,12.99,100,1,14.3,200,2,12.73,100,1,14.59,100,1,12.67,100,1,14.83,100,1,12.47,100,1,14.87,100,1,12.46,100,1,14.91,700,1,12.43,700,1,14.95,700,1,12.42,700,1,14.99,700,1,12.37,700,1,15.09,100,1,12.36,200,2,15.14,700,1,ARL,58709193
368,2025-07-17T13:46:23.920647302Z,2025-07-17T13:46:23.920647302Z,10,2,1108,A,B,1,13.12,2,130,165883,70104076,13.25,11,1,14.2,2,1,13.12,2,1,14.3,200,2,12.99,100,1,14.59,100,1,12.73,100,1,14.83,100,1,12.67,100,1,14.87,100,1,12.47,100,1,14.91,700,1,12.46,100,1,14.95,700,1,12.43,700,1,14.99,700,1,12.42,700,1,15.09,100,1,12.37,700,1,15.14,700,1,ARL,85194077
369,2025-07-17T13:46:45.786413307Z,2025-07-17T13:46:45.786413307Z,10,2,1108,C,B,1,13.12,2,0,166297,70834235,13.25,11,1,14.2,2,1,12.99,100,1,14.3,200,2,12.73,100,1,14.59,100,1,12.67,100,1,14.83,100,1,12.47,100,1,14.87,100,1,12.46,100,1,14.91,700,1,12.43,700,1,14.95,700,1,12.42,700,1,14.99,700,1,12.37,700,1,15.09,100,1,12.36,200,2,15.14,700,1,ARL,85194077
370,2025-07-17T13:46:45.786413307Z,2025-07-17T13:46:45.786413307Z,10,2,1108,A,B,1,13.2,2,130,166297,70834235,13.25,11,1,14.2,2,1,13.2,2,1,14.3,200,2,12.99,100,1,14.59,100,1,12.73,100,1,14.83,100,1,12.67,100,1,14.87,100,1,12.47,100,1,14.91,700,1,12.46,100,1,14.95,700,1,12.43,700,1,14.99,700,1,12.42,700,1,15.09,100,1,12.37,700,1,15.14,700,1,ARL,86056033
371,2025-07-17T13:47:34.987001473Z,2025-07-17T13:47:34.987001473Z,10,2,1108,C,B,1,13.2,2,0,165704,72269967,13.25,11,1,14.2,2,1,12.99,100,1,14.3,200,2,12.73,100,1,14.59,100,1,12.67,100,1,14.83,100,1,12.47,100,1,14.87,100,1,12.46,100,1,14.91,700,1,12.43,700,1,14.95,700,1,12.42,700,1,14.99,700,1,12.37,700,1,15.09,100,1,12.36,200,2,15.14,700,1,ARL,86056033
372,2025-07-17T13:47:34.987001473Z,2025-07-17T13:47:34.987001473Z,10,2,1108,A,B,0,13.26,2,130,165704,72269967,13.26,2,1,14.2,2,1,13.25,11,1,14.3,200,2,12.99,100,1,14.59,100,1,12.73,100,1,14.83,100,1,12.67,100,1,14.87,100,1,12.47,100,1,14.91,700,1,12.46,100,1,14.95,700,1,12.43,700,1,14.99,700,1,12.42,700,1,15.09,100,1,12.37,700,1,15.14,700,1,ARL,87750309
373,2025-07-17T13:49:46.533420775Z,2025-07-17T13:49:46.533420775Z,10,2,1108,C,A,1,14.3,100,0,165709,76393090,13.26,2,1,14.2,2,1,13.25,11,1,14.3,100,1,12.99,100,1,14.59,100,1,12.73,100,1,14.83,100,1,12.67,100,1,14.87,100,1,12.47,100,1,14.91,700,1,12.46,100,1,14.95,700,1,12.43,700,1,14.99,700,1,12.42,700,1,15.09,100,1,12.37,700,1,15.14,700,1,ARL,77910357
374,2025-07-17T13:49:46.533566805Z,2025-07-17T13:49:46.533566805Z,10,2,1108,C,A,1,14.3,100,0,165609,76393092,13.26,2,1,14.2,2,1,13.25,11,1,14.59,100,1,12.99,100,1,14.83,100,1,12.73,100,1,14.87,100,1,12.67,100,1,14.91,700,1,12.47,100,1,14.95,700,1,12.46,100,1,14.99,700,1,12.43,700,1,15.09,100,1,12.42,700,1,15.14,700,1,12.37,700,1,15.16,100,1,ARL,74589605
375,2025-07-17T13:49:46.533603070Z,2025-07-17T13:49:46.533603070Z,10,2,1108,C,A,4,14.91,700,130,165592,76393093,13.26,2,1,14.2,2,1,13.25,11,1,14.59,100,1,12.99,100,1,14.83,100,1,12.73,100,1,14.87,100,1,12.67,100,1,14.95,700,1,12.47,100,1,14.99,700,1,12.46,100,1,15.09,100,1,12.43,700,1,15.14,700,1,12.42,700,1,15.16,100,1,12.37,700,1,15.2,100,1,ARL,84628761
376,2025-07-17T13:49:46.533644528Z,2025-07-17T13:49:46.533644528Z,10,2,1108,A,A,6,15.07,700,130,165710,76393094,13.26,2,1,14.2,2,1,13.25,11,1,14.59,100,1,12.99,100,1,14.83,100,1,12.73,100,1,14.87,100,1,12.67,100,1,14.95,700,1,12.47,100,1,14.99,700,1,12.46,100,1,15.07,700,1,12.43,700,1,15.09,100,1,12.42,700,1,15.14,700,1,12.37,700,1,15.16,100,1,ARL,92510741
377,2025-07-17T13:49:46.534390219Z,2025-07-17T13:49:46.534390219Z,10,2,1108,C,A,10,15.2,100,0,165615,76393100,13.26,2,1,14.2,2,1,13.25,11,1,14.59,100,1,12.99,100,1,14.83,100,1,12.73,100,1,14.87,100,1,12.67,100,1,14.95,700,1,12.47,100,1,14.99,700,1,12.46,100,1,15.07,700,1,12.43,700,1,15.09,100,1,12.42,700,1,15.14,700,1,12.37,700,1,15.16,100,1,ARL,84628801
378,2025-07-17T13:56:11.001642441Z,2025-07-17T13:56:11.001642441Z,10,2,1108,A,B,0,13.28,1,128,167785,89819278,13.28,1,1,14.2,2,1,13.26,2,1,14.59,100,1,13.25,11,1,14.83,100,1,12.99,100,1,14.87,100,1,12.73,100,1,14.95,700,1,12.67,100,1,14.99,700,1,12.47,100,1,15.07,700,1,12.46,100,1,15.09,100,1,12.43,700,1,15.14,700,1,12.42,700,1,15.16,100,1,ARL,107702381
379,2025-07-17T13:56:11.005384065Z,2025-07-17T13:56:11.005384065Z,10,2,1108,A,B,0,13.28,10,130,166064,89819705,13.28,11,2,14.2,2,1,13.26,2,1,14.59,100,1,13.25,11,1,14.83,100,1,12.99,100,1,14.87,100,1,12.73,100,1,14.95,700,1,12.67,100,1,14.99,700,1,12.47,100,1,15.07,700,1,12.46,100,1,15.09,100,1,12.43,700,1,15.14,700,1,12.42,700,1,15.16,100,1,ARL,107702861
380,2025-07-17T13:56:11.005385425Z,2025-07-17T13:56:11.005385425Z,10,2,1108,A,A,0,13.94,10,130,165244,89819706,13.28,11,2,13.94,10,1,13.26,2,1,14.2,2,1,13.25,11,1,14.59,100,1,12.99,100,1,14.83,100,1,12.73,100,1,14.87,100,1,12.67,100,1,14.95,700,1,12.47,100,1,14.99,700,1,12.46,100,1,15.07,700,1,12.43,700,1,15.09,100,1,12.42,700,1,15.14,700,1,ARL,107702865
381,2025-07-17T13:56:11.013654317Z,2025-07-17T13:56:11.013654317Z,10,2,1108,A,A,4,14.84,100,130,165540,89820163,13.28,11,2,13.94,10,1,13.26,2,1,14.2,2,1,13.25,11,1,14.59,100,1,12.99,100,1,14.83,100,1,12.73,100,1,14.84,100,1,12.67,100,1,14.87,100,1,12.47,100,1,14.95,700,1,12.46,100,1,14.99,700,1,12.43,700,1,15.07,700,1,12.42,700,1,15.09,100,1,ARL,107703205
382,2025-07-17T13:56:11.026515306Z,2025-07-17T13:56:11.026515306Z,10,2,1108,A,A,4,14.84,100,130,165473,89820408,13.28,11,2,13.94,10,1,13.26,2,1,14.2,2,1,13.25,11,1,14.59,100,1,12.99,100,1,14.83,100,1,12.73,100,1,14.84,200,2,12.67,100,1,14.87,100,1,12.47,100,1,14.95,700,1,12.46,100,1,14.99,700,1,12.43,700,1,15.07,700,1,12.42,700,1,15.09,100,1,ARL,107703433
383,2025-07-17T13:56:11.101751649Z,2025-07-17T13:56:11.101751649Z,10,2,1108,C,B,0,13.28,1,130,165121,89823845,13.28,10,1,13.94,10,1,13.26,2,1,14.2,2,1,13.25,11,1,14.59,100,1,12.99,100,1,14.83,100,1,12.73,100,1,14.84,200,2,12.67,100,1,14.87,100,1,12.47,100,1,14.95,700,1,12.46,100,1,14.99,700,1,12.43,700,1,15.07,700,1,12.42,700,1,15.09,100,1,ARL,107702381
384,2025-07-17T13:56:19.511590204Z,2025-07-17T13:56:19.511590204Z,10,2,1108,C,B,0,13.28,10,130,165138,90148349,13.26,2,1,13.94,10,1,13.25,11,1,14.2,2,1,12.99,100,1,14.59,100,1,12.73,100,1,14.83,100,1,12.67,100,1,14.84,200,2,12.47,100,1,14.87,100,1,12.46,100,1,14.95,700,1,12.43,700,1,14.99,700,1,12.42,700,1,15.07,700,1,12.37,700,1,15.09,100,1,ARL,107702861
385,2025-07-17T13:56:22.511968820Z,2025-07-17T13:56:22.511968820Z,10,2,1108,C,A,0,13.94,10,130,165903,90281309,13.26,2,1,14.2,2,1,13.25,11,1,14.59,100,1,12.99,100,1,14.83,100,1,12.73,100,1,14.84,200,2,12.67,100,1,14.87,100,1,12.47,100,1,14.95,700,1,12.46,100,1,14.99,700,1,12.43,700,1,15.07,700,1,12.42,700,1,15.09,100,1,12.37,700,1,15.14,700,1,ARL,107702865
386,2025-07-17T13:56:22.516990420Z,2025-07-17T13:56:22.516990420Z,10,2,1108,C,A,3,14.84,100,0,165498,90281853,13.26,2,1,14.2,2,1,13.25,11,1,14.59,100,1,12.99,100,1,14.83,100,1,12.73,100,1,14.84,100,1,12.67,100,1,14.87,100,1,12.47,100,1,14.95,700,1,12.46,100,1,14.99,700,1,12.43,700,1,15.07,700,1,12.42,700,1,15.09,100,1,12.37,700,1,15.14,700,1,ARL,107703205
387,2025-07-17T13:56:22.517362170Z,2025-07-17T13:56:22.517362170Z,10,2,1108,C,A,3,14.84,100,0,165484,90281893,13.26,2,1,14.2,2,1,13.25,11,1,14.59,100,1,12.99,100,1,14.83,100,1,12.73,100,1,14.87,100,1,12.67,100,1,14.95,700,1,12.47,100,1,14.99,700,1,12.46,100,1,15.07,700,1,12.43,700,1,15.09,100,1,12.42,700,1,15.14,700,1,12.37,700,1,15.16,100,1,ARL,107703433
388,2025-07-17T13:56:22.517362170Z,2025-07-17T13:56:22.517362170Z,10,2,1108,A,A,10,15.26,100,130,165484,90281893,13.26,2,1,14.2,2,1,13.25,11,1,14.59,100,1,12.99,100,1,14.83,100,1,12.73,100,1,14.87,100,1,12.67,100,1,14.95,700,1,12.47,100,1,14.99,700,1,12.46,100,1,15.07,700,1,12.43,700,1,15.09,100,1,12.42,700,1,15.14,700,1,12.37,700,1,15.16,100,1,ARL,108217173
389,2025-07-17T13:56:40.757635216Z,2025-07-17T13:56:40.757635216Z,10,2,1108,C,A,0,14.2,2,0,165678,90866180,13.26,2,1,14.59,100,1,13.25,11,1,14.83,100,1,12.99,100,1,14.87,100,1,12.73,100,1,14.95,700,1,12.67,100,1,14.99,700,1,12.47,100,1,15.07,700,1,12.46,100,1,15.09,100,1,12.43,700,1,15.14,700,1,12.42,700,1,15.16,100,1,12.37,700,1,15.26,200,2,ARL,84628773
390,2025-07-17T13:56:40.757635216Z,2025-07-17T13:56:40.757635216Z,10,2,1108,A,A,0,14.36,2,130,165678,90866180,13.26,2,1,14.36,2,1,13.25,11,1,14.59,100,1,12.99,100,1,14.83,100,1,12.73,100,1,14.87,100,1,12.67,100,1,14.95,700,1,12.47,100,1,14.99,700,1,12.46,100,1,15.07,700,1,12.43,700,1,15.09,100,1,12.42,700,1,15.14,700,1,12.37,700,1,15.16,100,1,ARL,108872153
391,2025-07-17T13:57:40.141855674Z,2025-07-17T13:57:40.141855674Z,10,2,1108,C,B,0,13.26,2,0,166649,92821039,13.25,11,1,14.36,2,1,12.99,100,1,14.59,100,1,12.73,100,1,14.83,100,1,12.67,100,1,14.87,100,1,12.47,100,1,14.95,700,1,12.46,100,1,14.99,700,1,12.43,700,1,15.07,700,1,12.42,700,1,15.09,100,1,12.37,700,1,15.14,700,1,12.36,200,2,15.16,100,1,ARL,87750309
392,2025-07-17T13:57:40.141855674Z,2025-07-17T13:57:40.141855674Z,10,2,1108,A,B,1,13.12,2,128,166649,92821039,13.25,11,1,14.36,2,1,13.12,2,1,14.59,100,1,12.99,100,1,14.83,100,1,12.73,100,1,14.87,100,1,12.67,100,1,14.95,700,1,12.47,100,1,14.99,700,1,12.46,100,1,15.07,700,1,12.43,700,1,15.09,100,1,12.42,700,1,15.14,700,1,12.37,700,1,15.16,100,1,ARL,111169049
393,2025-07-17T13:57:44.947591620Z,2025-07-17T13:57:44.947591620Z,10,2,1108,C,A,0,14.36,2,0,165617,92961696,13.25,11,1,14.59,100,1,13.12,2,1,14.83,100,1,12.99,100,1,14.87,100,1,12.73,100,1,14.95,700,1,12.67,100,1,14.99,700,1,12.47,100,1,15.07,700,1,12.46,100,1,15.09,100,1,12.43,700,1,15.14,700,1,12.42,700,1,15.16,100,1,12.37,700,1,15.26,200,2,ARL,108872153
394,2025-07-17T13:57:44.947591620Z,2025-07-17T13:57:44.947591620Z,10,2,1108,A,A,0,14.5,2,130,165617,92961696,13.25,11,1,14.5,2,1,13.12,2,1,14.59,100,1,12.99,100,1,14.83,100,1,12.73,100,1,14.87,100,1,12.67,100,1,14.95,700,1,12.47,100,1,14.99,700,1,12.46,100,1,15.07,700,1,12.43,700,1,15.09,100,1,12.42,700,1,15.14,700,1,12.37,700,1,15.16,100,1,ARL,111347121
395,2025-07-17T13:59:50.477745739Z,2025-07-17T13:59:50.477745739Z,10,2,1108,C,B,0,13.25,11,130,165419,96389796,13.12,2,1,14.5,2,1,12.99,100,1,14.59,100,1,12.73,100,1,14.83,100,1,12.67,100,1,14.87,100,1,12.47,100,1,14.95,700,1,12.46,100,1,14.99,700,1,12.43,700,1,15.07,700,1,12.42,700,1,15.09,100,1,12.37,700,1,15.14,700,1,12.36,200,2,15.16,100,1,ARL,44586753
396,2025-07-17T13:59:50.479411482Z,2025-07-17T13:59:50.479411482Z,10,2,1108,C,B,9,12.36,100,0,165502,96389821,13.12,2,1,14.5,2,1,12.99,100,1,14.59,100,1,12.73,100,1,14.83,100,1,12.67,100,1,14.87,100,1,12.47,100,1,14.95,700,1,12.46,100,1,14.99,700,1,12.43,700,1,15.07,700,1,12.42,700,1,15.09,100,1,12.37,700,1,15.14,700,1,12.36,100,1,15.16,100,1,ARL,43787977
397,2025-07-17T13:59:50.479411482Z,2025-07-17T13:59:50.479411482Z,10,2,1108,A,B,4,12.51,100,130,165502,96389821,13.12,2,1,14.5,2,1,12.99,100,1,14.59,100,1,12.73,100,1,14.83,100,1,12.67,100,1,14.87,100,1,12.51,100,1,14.95,700,1,12.47,100,1,14.99,700,1,12.46,100,1,15.07,700,1,12.43,700,1,15.09,100,1,12.42,700,1,15.14,700,1,12.37,700,1,15.16,100,1,ARL,115474337
398,2025-07-17T13:59:50.480698233Z,2025-07-17T13:59:50.480698233Z,10,2,1108,C,B,10,12.36,100,0,165404,96389845,13.12,2,1,14.5,2,1,12.99,100,1,14.59,100,1,12.73,100,1,14.83,100,1,12.67,100,1,14.87,100,1,12.51,100,1,14.95,700,1,12.47,100,1,14.99,700,1,12.46,100,1,15.07,700,1,12.43,700,1,15.09,100,1,12.42,700,1,15.14,700,1,12.37,700,1,15.16,100,1,ARL,43781537
399,2025-07-17T13:59:50.480698233Z,2025-07-17T13:59:50.480698233Z,10,2,1108,A,B,4,12.51,100,130,165404,96389845,13.12,2,1,14.5,2,1,12.99,100,1,14.59,100,1,12.73,100,1,14.83,100,1,12.67,100,1,14.87,100,1,12.51,200,2,14.95,700,1,12.47,100,1,14.99,700,1,12.46,100,1,15.07,700,1,12.43,700,1,15.09,100,1,12.42,700,1,15.14,700,1,12.37,700,1,15.16,100,1,ARL,115474357
400,2025-07-17T14:00:00.062872132Z,2025-07-17T14:00:00.062872132Z,10,2,1108,A,B,1,13.11,100,130,165314,96673952,13.12,2,1,14.5,2,1,13.11,100,1,14.59,100,1,12.99,100,1,14.83,100,1,12.73,100,1,14.87,100,1,12.67,100,1,14.95,700,1,12.51,200,2,14.99,700,1,12.47,100,1,15.07,700,1,12.46,100,1,15.09,100,1,12.43,700,1,15.14,700,1,12.42,700,1,15.16,100,1,ARL,115813253
401,2025-07-17T14:00:00.062890891Z,2025-07-17T14:00:00.062890891Z,10,2,1108,A,A,1,14.51,100,130,165309,96673954,13.12,2,1,14.5,2,1,13.11,100,1,14.51,100,1,12.99,100,1,14.59,100,1,12.73,100,1,14.83,100,1,12.67,100,1,14.87,100,1,12.51,200,2,14.95,700,1,12.47,100,1,14.99,700,1,12.46,100,1,15.07,700,1,12.43,700,1,15.09,100,1,12.42,700,1,15.14,700,1,ARL,115813261
402,2025-07-17T14:02:01.157819863Z,2025-07-17T14:02:01.157819863Z,10,2,1108,C,B,0,13.12,2,0,165739,101310413,13.11,100,1,14.5,2,1,12.99,100,1,14.51,100,1,12.73,100,1,14.59,100,1,12.67,100,1,14.83,100,1,12.51,200,2,14.87,100,1,12.47,100,1,14.95,700,1,12.46,100,1,14.99,700,1,12.43,700,1,15.07,700,1,12.42,700,1,15.09,100,1,12.37,700,1,15.14,700,1,ARL,111169049
403,2025-07-17T14:02:01.157819863Z,2025-07-17T14:02:01.157819863Z,10,2,1108,A,B,0,13.26,2,130,165739,101310413,13.26,2,1,14.5,2,1,13.11,100,1,14.51,100,1,12.99,100,1,14.59,100,1,12.73,100,1,14.83,100,1,12.67,100,1,14.87,100,1,12.51,200,2,14.95,700,1,12.47,100,1,14.99,700,1,12.46,100,1,15.07,700,1,12.43,700,1,15.09,100,1,12.42,700,1,15.14,700,1,ARL,121098337
404,2025-07-17T14:02:01.157820985Z,2025-07-17T14:02:01.157820985Z,10,2,1108,C,A,0,14.5,2,0,165514,101310414,13.26,2,1,14.51,100,1,13.11,100,1,14.59,100,1,12.99,100,1,14.83,100,1,12.73,100,1,14.87,100,1,12.67,100,1,14.95,700,1,12.51,200,2,14.99,700,1,12.47,100,1,15.07,700,1,12.46,100,1,15.09,100,1,12.43,700,1,15.14,700,1,12.42,700,1,15.16,100,1,ARL,111347121
405,2025-07-17T14:02:01.157820985Z,2025-07-17T14:02:01.157820985Z,10,2,1108,A,A,0,14.36,2,130,165514,101310414,13.26,2,1,14.36,2,1,13.11,100,1,14.51,100,1,12.99,100,1,14.59,100,1,12.73,100,1,14.83,100,1,12.67,100,1,14.87,100,1,12.51,200,2,14.95,700,1,12.47,100,1,14.99,700,1,12.46,100,1,15.07,700,1,12.43,700,1,15.09,100,1,12.42,700,1,15.14,700,1,ARL,121098341
406,2025-07-17T14:02:01.283363185Z,2025-07-17T14:02:01.283363185Z,10,2,1108,C,B,1,13.11,100,0,165653,101317376,13.26,2,1,14.36,2,1,12.99,100,1,14.51,100,1,12.73,100,1,14.59,100,1,12.67,100,1,14.83,100,1,12.51,200,2,14.87,100,1,12.47,100,1,14.95,700,1,12.46,100,1,14.99,700,1,12.43,700,1,15.07,700,1,12.42,700,1,15.09,100,1,12.37,700,1,15.14,700,1,ARL,115813253
407,2025-07-17T14:02:01.283363185Z,2025-07-17T14:02:01.283363185Z,10,2,1108,A,B,1,13.25,100,130,165653,101317376,13.26,2,1,14.36,2,1,13.25,100,1,14.51,100,1,12.99,100,1,14.59,100,1,12.73,100,1,14.83,100,1,12.67,100,1,14.87,100,1,12.51,200,2,14.95,700,1,12.47,100,1,14.99,700,1,12.46,100,1,15.07,700,1,12.43,700,1,15.09,100,1,12.42,700,1,15.14,700,1,ARL,121107957
408,2025-07-17T14:02:01.283378637Z,2025-07-17T14:02:01.283378637Z,10,2,1108,C,A,1,14.51,100,0,165951,101317377,13.26,2,1,14.36,2,1,13.25,100,1,14.59,100,1,12.99,100,1,14.83,100,1,12.73,100,1,14.87,100,1,12.67,100,1,14.95,700,1,12.51,200,2,14.99,700,1,12.47,100,1,15.07,700,1,12.46,100,1,15.09,100,1,12.43,700,1,15.14,700,1,12.42,700,1,15.16,100,1,ARL,115813261
409,2025-07-17T14:02:01.283378637Z,2025-07-17T14:02:01.283378637Z,10,2,1108,A,A,1,14.37,100,130,165951,101317377,13.26,2,1,14.36,2,1,13.25,100,1,14.37,100,1,12.99,100,1,14.59,100,1,12.73,100,1,14.83,100,1,12.67,100,1,14.87,100,1,12.51,200,2,14.95,700,1,12.47,100,1,14.99,700,1,12.46,100,1,15.07,700,1,12.43,700,1,15.09,100,1,12.42,700,1,15.14,700,1,ARL,121107961
410,2025-07-17T14:04:21.248740930Z,2025-07-17T14:04:21.248740930Z,10,2,1108,A,A,0,14.35,1,130,165388,106336852,13.26,2,1,14.35,1,1,13.25,100,1,14.36,2,1,12.99,100,1,14.37,100,1,12.73,100,1,14.59,100,1,12.67,100,1,14.83,100,1,12.51,200,2,14.87,100,1,12.47,100,1,14.95,700,1,12.46,100,1,14.99,700,1,12.43,700,1,15.07,700,1,12.42,700,1,15.09,100,1,ARL,126872197
411,2025-07-17T14:04:21.250160548Z,2025-07-17T14:04:21.250160548Z,10,2,1108,C,B,5,12.51,100,0,165352,106336976,13.26,2,1,14.35,1,1,13.25,100,1,14.36,2,1,12.99,100,1,14.37,100,1,12.73,100,1,14.59,100,1,12.67,100,1,14.83,100,1,12.51,100,1,14.87,100,1,12.47,100,1,14.95,700,1,12.46,100,1,14.99,700,1,12.43,700,1,15.07,700,1,12.42,700,1,15.09,100,1,ARL,115474357
412,2025-07-17T14:04:21.250632048Z,2025-07-17T14:04:21.250632048Z,10,2,1108,C,B,5,12.51,100,0,165693,106337002,13.26,2,1,14.35,1,1,13.25,100,1,14.36,2,1,12.99,100,1,14.37,100,1,12.73,100,1,14.59,100,1,12.67,100,1,14.83,100,1,12.47,100,1,14.87,100,1,12.46,100,1,14.95,700,1,12.43,700,1,14.99,700,1,12.42,700,1,15.07,700,1,12.37,700,1,15.09,100,1,ARL,115474337
413,2025-07-17T14:04:21.250632048Z,2025-07-17T14:04:21.250632048Z,10,2,1108,A,B,10,12.36,100,130,165693,106337002,13.26,2,1,14.35,1,1,13.25,100,1,14.36,2,1,12.99,100,1,14.37,100,1,12.73,100,1,14.59,100,1,12.67,100,1,14.83,100,1,12.47,100,1,14.87,100,1,12.46,100,1,14.95,700,1,12.43,700,1,14.99,700,1,12.42,700,1,15.07,700,1,12.37,700,1,15.09,100,1,ARL,126872361
414,2025-07-17T14:04:21.350041949Z,2025-07-17T14:04:21.350041949Z,10,2,1108,C,A,0,14.35,1,128,165990,106339204,13.26,2,1,14.36,2,1,13.25,100,1,14.37,100,1,12.99,100,1,14.59,100,1,12.73,100,1,14.83,100,1,12.67,100,1,14.87,100,1,12.47,100,1,14.95,700,1,12.46,100,1,14.99,700,1,12.43,700,1,15.07,700,1,12.42,700,1,15.09,100,1,12.37,700,1,15.14,700,1,ARL,126872197
415,2025-07-17T14:05:10.258689253Z,2025-07-17T14:05:10.258689253Z,10,2,1108,A,A,0,14.08,1,130,166356,107833096,13.26,2,1,14.08,1,1,13.25,100,1,14.36,2,1,12.99,100,1,14.37,100,1,12.73,100,1,14.59,100,1,12.67,100,1,14.83,100,1,12.47,100,1,14.87,100,1,12.46,100,1,14.95,700,1,12.43,700,1,14.99,700,1,12.42,700,1,15.07,700,1,12.37,700,1,15.09,100,1,ARL,128570149
416,2025-07-17T14:05:10.259348471Z,2025-07-17T14:05:10.259348471Z,10,2,1108,A,A,7,14.98,100,130,165405,107833168,13.26,2,1,14.08,1,1,13.25,100,1,14.36,2,1,12.99,100,1,14.37,100,1,12.73,100,1,14.59,100,1,12.67,100,1,14.83,100,1,12.47,100,1,14.87,100,1,12.46,100,1,14.95,700,1,12.43,700,1,14.98,100,1,12.42,700,1,14.99,700,1,12.37,700,1,15.07,700,1,ARL,128570229
417,2025-07-17T14:05:10.259729446Z,2025-07-17T14:05:10.259729446Z,10,2,1108,A,A,7,14.98,100,130,165790,107833188,13.26,2,1,14.08,1,1,13.25,100,1,14.36,2,1,12.99,100,1,14.37,100,1,12.73,100,1,14.59,100,1,12.67,100,1,14.83,100,1,12.47,100,1,14.87,100,1,12.46,100,1,14.95,700,1,12.43,700,1,14.98,200,2,12.42,700,1,14.99,700,1,12.37,700,1,15.07,700,1,ARL,128570237
418,2025-07-17T14:05:10.262295631Z,2025-07-17T14:05:10.262295631Z,10,2,1108,C,A,2,14.37,100,0,166232,107833310,13.26,2,1,14.08,1,1,13.25,100,1,14.36,2,1,12.99,100,1,14.59,100,1,12.73,100,1,14.83,100,1,12.67,100,1,14.87,100,1,12.47,100,1,14.95,700,1,12.46,100,1,14.98,200,2,12.43,700,1,14.99,700,1,12.42,700,1,15.07,700,1,12.37,700,1,15.09,100,1,ARL,121107961
419,2025-07-17T14:05:10.262295631Z,2025-07-17T14:05:10.262295631Z,10,2,1108,A,A,1,14.09,100,130,166232,107833310,13.26,2,1,14.08,1,1,13.25,100,1,14.09,100,1,12.99,100,1,14.36,2,1,12.73,100,1,14.59,100,1,12.67,100,1,14.83,100,1,12.47,100,1,14.87,100,1,12.46,100,1,14.95,700,1,12.43,700,1,14.98,200,2,12.42,700,1,14.99,700,1,12.37,700,1,15.07,700,1,ARL,128570317
420,2025-07-17T14:05:10.262701351Z,2025-07-17T14:05:10.262701351Z,10,2,1108,C,A,0,14.08,1,130,165176,107833359,13.26,2,1,14.09,100,1,13.25,100,1,14.36,2,1,12.99,100,1,14.59,100,1,12.73,100,1,14.83,100,1,12.67,100,1,14.87,100,1,12.47,100,1,14.95,700,1,12.46,100,1,14.98,200,2,12.43,700,1,14.99,700,1,12.42,700,1,15.07,700,1,12.37,700,1,15.09,100,1,ARL,128570149
421,2025-07-17T14:05:10.264329670Z,2025-07-17T14:05:10.264329670Z,10,2,1108,A,A,9,15.08,100,130,165408,107833404,13.26,2,1,14.09,100,1,13.25,100,1,14.36,2,1,12.99,100,1,14.59,100,1,12.73,100,1,14.83,100,1,12.67,100,1,14.87,100,1,12.47,100,1,14.95,700,1,12.46,100,1,14.98,200,2,12.43,700,1,14.99,700,1,12.42,700,1,15.07,700,1,12.37,700,1,15.08,100,1,ARL,128570449
422,2025-07-17T14:05:10.264425026Z,2025-07-17T14:05:10.264425026Z,10,2,1108,C,A,10,15.09,100,130,165292,107833406,13.26,2,1,14.09,100,1,13.25,100,1,14.36,2,1,12.99,100,1,14.59,100,1,12.73,100,1,14.83,100,1,12.67,100,1,14.87,100,1,12.47,100,1,14.95,700,1,12.46,100,1,14.98,200,2,12.43,700,1,14.99,700,1,12.42,700,1,15.07,700,1,12.37,700,1,15.08,100,1,ARL,84650629
423,2025-07-17T14:05:10.264550510Z,2025-07-17T14:05:10.264550510Z,10,2,1108,A,A,5,14.89,100,130,165213,107833407,13.26,2,1,14.09,100,1,13.25,100,1,14.36,2,1,12.99,100,1,14.59,100,1,12.73,100,1,14.83,100,1,12.67,100,1,14.87,100,1,12.47,100,1,14.89,100,1,12.46,100,1,14.95,700,1,12.43,700,1,14.98,200,2,12.42,700,1,14.99,700,1,12.37,700,1,15.07,700,1,ARL,128570453
424,2025-07-17T14:05:10.269777131Z,2025-07-17T14:05:10.269777131Z,10,2,1108,C,A,2,14.59,100,128,165920,107833716,13.26,2,1,14.09,100,1,13.25,100,1,14.36,2,1,12.99,100,1,14.83,100,1,12.73,100,1,14.87,100,1,12.67,100,1,14.89,100,1,12.47,100,1,14.95,700,1,12.46,100,1,14.98,200,2,12.43,700,1,14.99,700,1,12.42,700,1,15.07,700,1,12.37,700,1,15.08,100,1,ARL,84629329
425,2025-07-17T14:05:10.269832842Z,2025-07-17T14:05:10.269832842Z,10,2,1108,A,A,2,14.37,100,130,165118,107833720,13.26,2,1,14.09,100,1,13.25,100,1,14.36,2,1,12.99,100,1,14.37,100,1,12.73,100,1,14.83,100,1,12.67,100,1,14.87,100,1,12.47,100,1,14.89,100,1,12.46,100,1,14.95,700,1,12.43,700,1,14.98,200,2,12.42,700,1,14.99,700,1,12.37,700,1,15.07,700,1,ARL,128570621
426,2025-07-17T14:05:10.342817229Z,2025-07-17T14:05:10.342817229Z,10,2,1108,A,A,10,15.08,100,130,165568,107837761,13.26,2,1,14.09,100,1,13.25,100,1,14.36,2,1,12.99,100,1,14.37,100,1,12.73,100,1,14.83,100,1,12.67,100,1,14.87,100,1,12.47,100,1,14.89,100,1,12.46,100,1,14.95,700,1,12.43,700,1,14.98,200,2,12.42,700,1,14.99,700,1,12.37,700,1,15.07,700,1,ARL,128573957
427,2025-07-17T14:05:31.418575692Z,2025-07-17T14:05:31.418575692Z,10,2,1108,C,A,1,14.36,2,0,165670,108664911,13.26,2,1,14.09,100,1,13.25,100,1,14.37,100,1,12.99,100,1,14.83,100,1,12.73,100,1,14.87,100,1,12.67,100,1,14.89,100,1,12.47,100,1,14.95,700,1,12.46,100,1,14.98,200,2,12.43,700,1,14.99,700,1,12.42,700,1,15.07,700,1,12.37,700,1,15.08,200,2,ARL,121098341
428,2025-07-17T14:05:31.418575692Z,2025-07-17T14:05:31.418575692Z,10,2,1108,A,A,1,14.26,2,130,165670,108664911,13.26,2,1,14.09,100,1,13.25,100,1,14.26,2,1,12.99,100,1,14.37,100,1,12.73,100,1,14.83,100,1,12.67,100,1,14.87,100,1,12.47,100,1,14.89,100,1,12.46,100,1,14.95,700,1,12.43,700,1,14.98,200,2,12.42,700,1,14.99,700,1,12.37,700,1,15.07,700,1,ARL,129518753
429,2025-07-17T14:06:01.385840471Z,2025-07-17T14:06:01.385840471Z,10,2,1108,C,B,0,13.26,2,0,165588,109685525,13.25,100,1,14.09,100,1,12.99,100,1,14.26,2,1,12.73,100,1,14.37,100,1,12.67,100,1,14.83,100,1,12.47,100,1,14.87,100,1,12.46,100,1,14.89,100,1,12.43,700,1,14.95,700,1,12.42,700,1,14.98,200,2,12.37,700,1,14.99,700,1,12.36,200,2,15.07,700,1,ARL,121098337
430,2025-07-17T14:06:01.385840471Z,2025-07-17T14:06:01.385840471Z,10,2,1108,A,B,1,13.15,2,130,165588,109685525,13.25,100,1,14.09,100,1,13.15,2,1,14.26,2,1,12.99,100,1,14.37,100,1,12.73,100,1,14.83,100,1,12.67,100,1,14.87,100,1,12.47,100,1,14.89,100,1,12.46,100,1,14.95,700,1,12.43,700,1,14.98,200,2,12.42,700,1,14.99,700,1,12.37,700,1,15.07,700,1,ARL,130693973
431,2025-07-17T14:13:11.358751092Z,2025-07-17T14:13:11.358751092Z,10,2,1108,C,A,2,14.37,100,130,165534,123938202,13.25,100,1,14.09,100,1,13.15,2,1,14.26,2,1,12.99,100,1,14.83,100,1,12.73,100,1,14.87,100,1,12.67,100,1,14.89,100,1,12.47,100,1,14.95,700,1,12.46,100,1,14.98,200,2,12.43,700,1,14.99,700,1,12.42,700,1,15.07,700,1,12.37,700,1,15.08,200,2,ARL,128570621
432,2025-07-17T14:13:11.358802966Z,2025-07-17T14:13:11.358802966Z,10,2,1108,A,A,2,14.28,100,130,165690,123938203,13.25,100,1,14.09,100,1,13.15,2,1,14.26,2,1,12.99,100,1,14.28,100,1,12.73,100,1,14.83,100,1,12.67,100,1,14.87,100,1,12.47,100,1,14.89,100,1,12.46,100,1,14.95,700,1,12.43,700,1,14.98,200,2,12.42,700,1,14.99,700,1,12.37,700,1,15.07,700,1,ARL,146956357
433,2025-07-17T14:13:11.423316840Z,2025-07-17T14:13:11.423316840Z,10,2,1108,A,A,3,14.56,100,130,165483,123940437,13.25,100,1,14.09,100,1,13.15,2,1,14.26,2,1,12.99,100,1,14.28,100,1,12.73,100,1,14.56,100,1,12.67,100,1,14.83,100,1,12.47,100,1,14.87,100,1,12.46,100,1,14.89,100,1,12.43,700,1,14.95,700,1,12.42,700,1,14.98,200,2,12.37,700,1,14.99,700,1,ARL,146960005
434,2025-07-17T14:13:11.423317922Z,2025-07-17T14:13:11.423317922Z,10,2,1108,C,A,5,14.87,100,130,165509,123940438,13.25,100,1,14.09,100,1,13.15,2,1,14.26,2,1,12.99,100,1,14.28,100,1,12.73,100,1,14.56,100,1,12.67,100,1,14.83,100,1,12.47,100,1,14.89,100,1,12.46,100,1,14.95,700,1,12.43,700,1,14.98,200,2,12.42,700,1,14.99,700,1,12.37,700,1,15.07,700,1,ARL,84708037
435,2025-07-17T14:13:11.555642984Z,2025-07-17T14:13:11.555642984Z,10,2,1108,A,A,5,14.84,100,130,165557,123942727,13.25,100,1,14.09,100,1,13.15,2,1,14.26,2,1,12.99,100,1,14.28,100,1,12.73,100,1,14.56,100,1,12.67,100,1,14.83,100,1,12.47,100,1,14.84,100,1,12.46,100,1,14.89,100,1,12.43,700,1,14.95,700,1,12.42,700,1,14.98,200,2,12.37,700,1,14.99,700,1,ARL,146962993
436,2025-07-17T14:13:19.230817808Z,2025-07-17T14:13:19.230817808Z,10,2,1108,A,A,7,14.91,700,130,165264,124169794,13.25,100,1,14.09,100,1,13.15,2,1,14.26,2,1,12.99,100,1,14.28,100,1,12.73,100,1,14.56,100,1,12.67,100,1,14.83,100,1,12.47,100,1,14.84,100,1,12.46,100,1,14.89,100,1,12.43,700,1,14.91,700,1,12.42,700,1,14.95,700,1,12.37,700,1,14.98,200,2,ARL,147217629
437,2025-07-17T14:22:28.338009329Z,2025-07-17T14:22:28.338009329Z,10,2,1108,A,A,0,14,1,130,165519,142657338,13.25,100,1,14,1,1,13.15,2,1,14.09,100,1,12.99,100,1,14.26,2,1,12.73,100,1,14.28,100,1,12.67,100,1,14.56,100,1,12.47,100,1,14.83,100,1,12.46,100,1,14.84,100,1,12.43,700,1,14.89,100,1,12.42,700,1,14.91,700,1,12.37,700,1,14.95,700,1,ARL,168073025
438,2025-07-17T14:22:29.993845812Z,2025-07-17T14:22:29.993845812Z,10,2,1108,C,A,1,14.09,100,0,165499,142715813,13.25,100,1,14,1,1,13.15,2,1,14.26,2,1,12.99,100,1,14.28,100,1,12.73,100,1,14.56,100,1,12.67,100,1,14.83,100,1,12.47,100,1,14.84,100,1,12.46,100,1,14.89,100,1,12.43,700,1,14.91,700,1,12.42,700,1,14.95,700,1,12.37,700,1,14.98,200,2,ARL,128570317
439,2025-07-17T14:22:29.993845812Z,2025-07-17T14:22:29.993845812Z,10,2,1108,A,A,1,14.01,100,130,165499,142715813,13.25,100,1,14,1,1,13.15,2,1,14.01,100,1,12.99,100,1,14.26,2,1,12.73,100,1,14.28,100,1,12.67,100,1,14.56,100,1,12.47,100,1,14.83,100,1,12.46,100,1,14.84,100,1,12.43,700,1,14.89,100,1,12.42,700,1,14.91,700,1,12.37,700,1,14.95,700,1,ARL,168141389
440,2025-07-17T14:32:58.232963791Z,2025-07-17T14:32:58.232963791Z,10,2,1108,C,B,0,13.25,100,130,165365,162140358,13.15,2,1,14,1,1,12.99,100,1,14.01,100,1,12.73,100,1,14.26,2,1,12.67,100,1,14.28,100,1,12.47,100,1,14.56,100,1,12.46,100,1,14.83,100,1,12.43,700,1,14.84,100,1,12.42,700,1,14.89,100,1,12.37,700,1,14.91,700,1,12.36,200,2,14.95,700,1,ARL,121107957
441,2025-07-17T14:32:58.713850212Z,2025-07-17T14:32:58.713850212Z,10,2,1108,A,B,1,13.14,100,130,165343,162149922,13.15,2,1,14,1,1,13.14,100,1,14.01,100,1,12.99,100,1,14.26,2,1,12.73,100,1,14.28,100,1,12.67,100,1,14.56,100,1,12.47,100,1,14.83,100,1,12.46,100,1,14.84,100,1,12.43,700,1,14.89,100,1,12.42,700,1,14.91,700,1,12.37,700,1,14.95,700,1,ARL,190326921
442,2025-07-17T14:34:48.346179643Z,2025-07-17T14:34:48.346179643Z,10,2,1108,C,A,0,14,1,130,165316,164925706,13.15,2,1,14.01,100,1,13.14,100,1,14.26,2,1,12.99,100,1,14.28,100,1,12.73,100,1,14.56,100,1,12.67,100,1,14.83,100,1,12.47,100,1,14.84,100,1,12.46,100,1,14.89,100,1,12.43,700,1,14.91,700,1,12.42,700,1,14.95,700,1,12.37,700,1,14.98,200,2,ARL,168073025
443,2025-07-17T14:47:30.547915870Z,2025-07-17T14:47:30.547915870Z,10,2,1108,A,B,0,13.38,33,130,165488,183466992,13.38,33,1,14.01,100,1,13.15,2,1,14.26,2,1,13.14,100,1,14.28,100,1,12.99,100,1,14.56,100,1,12.73,100,1,14.83,100,1,12.67,100,1,14.84,100,1,12.47,100,1,14.89,100,1,12.46,100,1,14.91,700,1,12.43,700,1,14.95,700,1,12.42,700,1,14.98,200,2,ARL,215999733
444,2025-07-17T14:47:30.548180936Z,2025-07-17T14:47:30.548180936Z,10,2,1108,C,B,2,13.14,100,0,165765,183466994,13.38,33,1,14.01,100,1,13.15,2,1,14.26,2,1,12.99,100,1,14.28,100,1,12.73,100,1,14.56,100,1,12.67,100,1,14.83,100,1,12.47,100,1,14.84,100,1,12.46,100,1,14.89,100,1,12.43,700,1,14.91,700,1,12.42,700,1,14.95,700,1,12.37,700,1,14.98,200,2,ARL,190326921
445,2025-07-17T14:47:30.548180936Z,2025-07-17T14:47:30.548180936Z,10,2,1108,A,B,1,13.37,100,130,165765,183466994,13.38,33,1,14.01,100,1,13.37,100,1,14.26,2,1,13.15,2,1,14.28,100,1,12.99,100,1,14.56,100,1,12.73,100,1,14.83,100,1,12.67,100,1,14.84,100,1,12.47,100,1,14.89,100,1,12.46,100,1,14.91,700,1,12.43,700,1,14.95,700,1,12.42,700,1,14.98,200,2,ARL,215999737
446,2025-07-17T14:47:30.548666035Z,2025-07-17T14:47:30.548666035Z,10,2,1108,A,B,6,12.48,100,130,165573,183467001,13.38,33,1,14.01,100,1,13.37,100,1,14.26,2,1,13.15,2,1,14.28,100,1,12.99,100,1,14.56,100,1,12.73,100,1,14.83,100,1,12.67,100,1,14.84,100,1,12.48,100,1,14.89,100,1,12.47,100,1,14.91,700,1,12.46,100,1,14.95,700,1,12.43,700,1,14.98,200,2,ARL,215999741
447,2025-07-17T14:47:30.549175659Z,2025-07-17T14:47:30.549175659Z,10,2,1108,A,B,6,12.48,100,130,165497,183467004,13.38,33,1,14.01,100,1,13.37,100,1,14.26,2,1,13.15,2,1,14.28,100,1,12.99,100,1,14.56,100,1,12.73,100,1,14.83,100,1,12.67,100,1,14.84,100,1,12.48,200,2,14.89,100,1,12.47,100,1,14.91,700,1,12.46,100,1,14.95,700,1,12.43,700,1,14.98,200,2,ARL,215999761
448,2025-07-17T14:47:30.571220121Z,2025-07-17T14:47:30.571220121Z,10,2,1108,C,B,3,12.99,100,130,165262,183468111,13.38,33,1,14.01,100,1,13.37,100,1,14.26,2,1,13.15,2,1,14.28,100,1,12.73,100,1,14.56,100,1,12.67,100,1,14.83,100,1,12.48,200,2,14.84,100,1,12.47,100,1,14.89,100,1,12.46,100,1,14.91,700,1,12.43,700,1,14.95,700,1,12.42,700,1,14.98,200,2,ARL,43805737
449,2025-07-17T14:47:30.571271737Z,2025-07-17T14:47:30.571271737Z,10,2,1108,A,B,3,13.1,100,130,165207,183468112,13.38,33,1,14.01,100,1,13.37,100,1,14.26,2,1,13.15,2,1,14.28,100,1,13.1,100,1,14.56,100,1,12.73,100,1,14.83,100,1,12.67,100,1,14.84,100,1,12.48,200,2,14.89,100,1,12.47,100,1,14.91,700,1,12.46,100,1,14.95,700,1,12.43,700,1,14.98,200,2,ARL,216001413
450,2025-07-17T14:47:37.384441232Z,2025-07-17T14:47:37.384441232Z,10,2,1108,A,B,6,12.5,700,130,169445,183649796,13.38,33,1,14.01,100,1,13.37,100,1,14.26,2,1,13.15,2,1,14.28,100,1,13.1,100,1,14.56,100,1,12.73,100,1,14.83,100,1,12.67,100,1,14.84,100,1,12.5,700,1,14.89,100,1,12.48,200,2,14.91,700,1,12.47,100,1,14.95,700,1,12.46,100,1,14.98,200,2,ARL,216223005
451,2025-07-17T14:52:02.610315566Z,2025-07-17T14:52:02.610315566Z,10,2,1108,T,N,0,13.41,1,130,166311,189559140,13.38,33,1,14.01,100,1,13.37,100,1,14.26,2,1,13.15,2,1,14.28,100,1,13.1,100,1,14.56,100,1,12.73,100,1,14.83,100,1,12.67,100,1,14.84,100,1,12.5,700,1,14.89,100,1,12.48,200,2,14.91,700,1,12.47,100,1,14.95,700,1,12.46,100,1,14.98,200,2,ARL,0
452,2025-07-17T14:52:02.610343819Z,2025-07-17T14:52:02.610343819Z,10,2,1108,A,A,0,13.71,1,130,165283,189559141,13.38,33,1,13.71,1,1,13.37,100,1,14.01,100,1,13.15,2,1,14.26,2,1,13.1,100,1,14.28,100,1,12.73,100,1,14.56,100,1,12.67,100,1,14.83,100,1,12.5,700,1,14.84,100,1,12.48,200,2,14.89,100,1,12.47,100,1,14.91,700,1,12.46,100,1,14.95,700,1,ARL,223347833
453,2025-07-17T14:52:02.611536221Z,2025-07-17T14:52:02.611536221Z,10,2,1108,C,A,0,13.71,1,130,165187,189559156,13.38,33,1,14.01,100,1,13.37,100,1,14.26,2,1,13.15,2,1,14.28,100,1,13.1,100,1,14.56,100,1,12.73,100,1,14.83,100,1,12.67,100,1,14.84,100,1,12.5,700,1,14.89,100,1,12.48,200,2,14.91,700,1,12.47,100,1,14.95,700,1,12.46,100,1,14.98,200,2,ARL,223347833
454,2025-07-17T15:00:11.560513555Z,2025-07-17T15:00:11.560513555Z,10,2,1108,C,B,0,13.38,33,130,165307,200140364,13.37,100,1,14.01,100,1,13.15,2,1,14.26,2,1,13.1,100,1,14.28,100,1,12.73,100,1,14.56,100,1,12.67,100,1,14.83,100,1,12.5,700,1,14.84,100,1,12.48,200,2,14.89,100,1,12.47,100,1,14.91,700,1,12.46,100,1,14.95,700,1,12.43,700,1,14.98,200,2,ARL,215999733
455,2025-07-17T15:00:11.562887948Z,2025-07-17T15:00:11.562887948Z,10,2,1108,C,B,6,12.48,100,0,165834,200140389,13.37,100,1,14.01,100,1,13.15,2,1,14.26,2,1,13.1,100,1,14.28,100,1,12.73,100,1,14.56,100,1,12.67,100,1,14.83,100,1,12.5,700,1,14.84,100,1,12.48,100,1,14.89,100,1,12.47,100,1,14.91,700,1,12.46,100,1,14.95,700,1,12.43,700,1,14.98,200,2,ARL,215999761
456,2025-07-17T15:00:11.562887948Z,2025-07-17T15:00:11.562887948Z,10,2,1108,A,B,5,12.65,100,130,165834,200140389,13.37,100,1,14.01,100,1,13.15,2,1,14.26,2,1,13.1,100,1,14.28,100,1,12.73,100,1,14.56,100,1,12.67,100,1,14.83,100,1,12.65,100,1,14.84,100,1,12.5,700,1,14.89,100,1,12.48,100,1,14.91,700,1,12.47,100,1,14.95,700,1,12.46,100,1,14.98,200,2,ARL,236179089
457,2025-07-17T15:00:12.536052536Z,2025-07-17T15:00:12.536052536Z,10,2,1108,C,B,7,12.48,100,0,165988,200161810,13.37,100,1,14.01,100,1,13.15,2,1,14.26,2,1,13.1,100,1,14.28,100,1,12.73,100,1,14.56,100,1,12.67,100,1,14.83,100,1,12.65,100,1,14.84,100,1,12.5,700,1,14.89,100,1,12.47,100,1,14.91,700,1,12.46,100,1,14.95,700,1,12.43,700,1,14.98,200,2,ARL,215999741
458,2025-07-17T15:00:12.536052536Z,2025-07-17T15:00:12.536052536Z,10,2,1108,A,B,5,12.65,100,130,165988,200161810,13.37,100,1,14.01,100,1,13.15,2,1,14.26,2,1,13.1,100,1,14.28,100,1,12.73,100,1,14.56,100,1,12.67,100,1,14.83,100,1,12.65,200,2,14.84,100,1,12.5,700,1,14.89,100,1,12.47,100,1,14.91,700,1,12.46,100,1,14.95,700,1,12.43,700,1,14.98,200,2,ARL,236206261
459,2025-07-17T15:01:11.658624662Z,2025-07-17T15:01:11.658624662Z,10,2,1108,A,A,0,13.98,10,130,165248,201616674,13.37,100,1,13.98,10,1,13.15,2,1,14.01,100,1,13.1,100,1,14.26,2,1,12.73,100,1,14.28,100,1,12.67,100,1,14.56,100,1,12.65,200,2,14.83,100,1,12.5,700,1,14.84,100,1,12.47,100,1,14.89,100,1,12.46,100,1,14.91,700,1,12.43,700,1,14.95,700,1,ARL,237940713
460,2025-07-17T15:01:12.948220412Z,2025-07-17T15:01:12.948220412Z,10,2,1108,C,A,1,14.01,100,0,165709,201642675,13.37,100,1,13.98,10,1,13.15,2,1,14.26,2,1,13.1,100,1,14.28,100,1,12.73,100,1,14.56,100,1,12.67,100,1,14.83,100,1,12.65,200,2,14.84,100,1,12.5,700,1,14.89,100,1,12.47,100,1,14.91,700,1,12.46,100,1,14.95,700,1,12.43,700,1,14.98,200,2,ARL,168141389
461,2025-07-17T15:01:12.948220412Z,2025-07-17T15:01:12.948220412Z,10,2,1108,A,A,1,13.99,100,130,165709,201642675,13.37,100,1,13.98,10,1,13.15,2,1,13.99,100,1,13.1,100,1,14.26,2,1,12.73,100,1,14.28,100,1,12.67,100,1,14.56,100,1,12.65,200,2,14.83,100,1,12.5,700,1,14.84,100,1,12.47,100,1,14.89,100,1,12.46,100,1,14.91,700,1,12.43,700,1,14.95,700,1,ARL,237978541
462,2025-07-17T15:01:12.948959226Z,2025-07-17T15:01:12.948959226Z,10,2,1108,C,A,5,14.83,100,130,165267,201642712,13.37,100,1,13.98,10,1,13.15,2,1,13.99,100,1,13.1,100,1,14.26,2,1,12.73,100,1,14.28,100,1,12.67,100,1,14.56,100,1,12.65,200,2,14.84,100,1,12.5,700,1,14.89,100,1,12.47,100,1,14.91,700,1,12.46,100,1,14.95,700,1,12.43,700,1,14.98,200,2,ARL,84628793
463,2025-07-17T15:01:12.949317198Z,2025-07-17T15:01:12.949317198Z,10,2,1108,A,A,5,14.61,100,130,166917,201642747,13.37,100,1,13.98,10,1,13.15,2,1,13.99,100,1,13.1,100,1,14.26,2,1,12.73,100,1,14.28,100,1,12.67,100,1,14.56,100,1,12.65,200,2,14.61,100,1,12.5,700,1,14.84,100,1,12.47,100,1,14.89,100,1,12.46,100,1,14.91,700,1,12.43,700,1,14.95,700,1,ARL,237978629
464,2025-07-17T15:01:26.963746832Z,2025-07-17T15:01:26.963746832Z,10,2,1108,C,A,0,13.98,10,128,169536,201984003,13.37,100,1,13.99,100,1,13.15,2,1,14.26,2,1,13.1,100,1,14.28,100,1,12.73,100,1,14.56,100,1,12.67,100,1,14.61,100,1,12.65,200,2,14.84,100,1,12.5,700,1,14.89,100,1,12.47,100,1,14.91,700,1,12.46,100,1,14.95,700,1,12.43,700,1,14.98,200,2,ARL,237940713
465,2025-07-17T15:01:37.513147090Z,2025-07-17T15:01:37.513147090Z,10,2,1108,A,A,0,13.98,10,130,165342,202186180,13.37,100,1,13.98,10,1,13.15,2,1,13.99,100,1,13.1,100,1,14.26,2,1,12.73,100,1,14.28,100,1,12.67,100,1,14.56,100,1,12.65,200,2,14.61,100,1,12.5,700,1,14.84,100,1,12.47,100,1,14.89,100,1,12.46,100,1,14.91,700,1,12.43,700,1,14.95,700,1,ARL,238668633
466,2025-07-17T15:05:36.047029298Z,2025-07-17T15:05:36.047029298Z,10,2,1108,C,A,0,13.98,10,128,173259,207097179,13.37,100,1,13.99,100,1,13.15,2,1,14.26,2,1,13.1,100,1,14.28,100,1,12.73,100,1,14.56,100,1,12.67,100,1,14.61,100,1,12.65,200,2,14.84,100,1,12.5,700,1,14.89,100,1,12.47,100,1,14.91,700,1,12.46,100,1,14.95,700,1,12.43,700,1,14.98,200,2,ARL,238668633
467,2025-07-17T15:10:34.469700487Z,2025-07-17T15:10:34.469700487Z,10,2,1108,C,A,1,14.26,2,0,165786,213735006,13.37,100,1,13.99,100,1,13.15,2,1,14.28,100,1,13.1,100,1,14.56,100,1,12.73,100,1,14.61,100,1,12.67,100,1,14.84,100,1,12.65,200,2,14.89,100,1,12.5,700,1,14.91,700,1,12.47,100,1,14.95,700,1,12.46,100,1,14.98,200,2,12.43,700,1,14.99,700,1,ARL,129518753
468,2025-07-17T15:10:34.469700487Z,2025-07-17T15:10:34.469700487Z,10,2,1108,A,A,1,14.17,2,130,165786,213735006,13.37,100,1,13.99,100,1,13.15,2,1,14.17,2,1,13.1,100,1,14.28,100,1,12.73,100,1,14.56,100,1,12.67,100,1,14.61,100,1,12.65,200,2,14.84,100,1,12.5,700,1,14.89,100,1,12.47,100,1,14.91,700,1,12.46,100,1,14.95,700,1,12.43,700,1,14.98,200,2,ARL,252720897
469,2025-07-17T15:12:52.735249178Z,2025-07-17T15:12:52.735249178Z,10,2,1108,A,A,1,14.03,100,130,165414,216651092,13.37,100,1,13.99,100,1,13.15,2,1,14.03,100,1,13.1,100,1,14.17,2,1,12.73,100,1,14.28,100,1,12.67,100,1,14.56,100,1,12.65,200,2,14.61,100,1,12.5,700,1,14.84,100,1,12.47,100,1,14.89,100,1,12.46,100,1,14.91,700,1,12.43,700,1,14.95,700,1,ARL,256325129
470,2025-07-17T15:13:06.511687613Z,2025-07-17T15:13:06.511687613Z,10,2,1108,A,A,0,13.98,10,130,165844,216995105,13.37,100,1,13.98,10,1,13.15,2,1,13.99,100,1,13.1,100,1,14.03,100,1,12.73,100,1,14.17,2,1,12.67,100,1,14.28,100,1,12.65,200,2,14.56,100,1,12.5,700,1,14.61,100,1,12.47,100,1,14.84,100,1,12.46,100,1,14.89,100,1,12.43,700,1,14.91,700,1,ARL,256739841
471,2025-07-17T15:13:08.653923821Z,2025-07-17T15:13:08.653923821Z,10,2,1108,A,A,2,14.01,100,130,165590,217058300,13.37,100,1,13.98,10,1,13.15,2,1,13.99,100,1,13.1,100,1,14.01,100,1,12.73,100,1,14.03,100,1,12.67,100,1,14.17,2,1,12.65,200,2,14.28,100,1,12.5,700,1,14.56,100,1,12.47,100,1,14.61,100,1,12.46,100,1,14.84,100,1,12.43,700,1,14.89,100,1,ARL,256818881
472,2025-07-17T15:13:08.661521116Z,2025-07-17T15:13:08.661521116Z,10,2,1108,C,A,3,14.03,100,130,165342,217058550,13.37,100,1,13.98,10,1,13.15,2,1,13.99,100,1,13.1,100,1,14.01,100,1,12.73,100,1,14.17,2,1,12.67,100,1,14.28,100,1,12.65,200,2,14.56,100,1,12.5,700,1,14.61,100,1,12.47,100,1,14.84,100,1,12.46,100,1,14.89,100,1,12.43,700,1,14.91,700,1,ARL,256325129
473,2025-07-17T15:14:00.440563034Z,2025-07-17T15:14:00.440563034Z,10,2,1108,C,A,0,13.98,10,130,165325,218096891,13.37,100,1,13.99,100,1,13.15,2,1,14.01,100,1,13.1,100,1,14.17,2,1,12.73,100,1,14.28,100,1,12.67,100,1,14.56,100,1,12.65,200,2,14.61,100,1,12.5,700,1,14.84,100,1,12.47,100,1,14.89,100,1,12.46,100,1,14.91,700,1,12.43,700,1,14.95,700,1,ARL,256739841
474,2025-07-17T15:14:52.381974473Z,2025-07-17T15:14:52.381974473Z,10,2,1108,A,A,0,13.98,10,130,165357,219204095,13.37,100,1,13.98,10,1,13.15,2,1,13.99,100,1,13.1,100,1,14.01,100,1,12.73,100,1,14.17,2,1,12.67,100,1,14.28,100,1,12.65,200,2,14.56,100,1,12.5,700,1,14.61,100,1,12.47,100,1,14.84,100,1,12.46,100,1,14.89,100,1,12.43,700,1,14.91,700,1,ARL,259546169
475,2025-07-17T15:14:56.683144163Z,2025-07-17T15:14:56.683144163Z,10,2,1108,C,A,2,14.01,100,130,165544,219317677,13.37,100,1,13.98,10,1,13.15,2,1,13.99,100,1,13.1,100,1,14.17,2,1,12.73,100,1,14.28,100,1,12.67,100,1,14.56,100,1,12.65,200,2,14.61,100,1,12.5,700,1,14.84,100,1,12.47,100,1,14.89,100,1,12.46,100,1,14.91,700,1,12.43,700,1,14.95,700,1,ARL,256818881
476,2025-07-17T15:15:11.660953613Z,2025-07-17T15:15:11.660953613Z,10,2,1108,A,A,2,14.02,100,130,165165,219726276,13.37,100,1,13.98,10,1,13.15,2,1,13.99,100,1,13.1,100,1,14.02,100,1,12.73,100,1,14.17,2,1,12.67,100,1,14.28,100,1,12.65,200,2,14.56,100,1,12.5,700,1,14.61,100,1,12.47,100,1,14.84,100,1,12.46,100,1,14.89,100,1,12.43,700,1,14.91,700,1,ARL,260184621
477,2025-07-17T15:15:32.408694312Z,2025-07-17T15:15:32.408694312Z,10,2,1108,C,A,0,13.98,10,128,168951,220152194,13.37,100,1,13.99,100,1,13.15,2,1,14.02,100,1,13.1,100,1,14.17,2,1,12.73,100,1,14.28,100,1,12.67,100,1,14.56,100,1,12.65,200,2,14.61,100,1,12.5,700,1,14.84,100,1,12.47,100,1,14.89,100,1,12.46,100,1,14.91,700,1,12.43,700,1,14.95,700,1,ARL,259546169
478,2025-07-17T15:16:31.607077080Z,2025-07-17T15:16:31.607077080Z,10,2,1108,A,A,1,14,100,130,165834,221423516,13.37,100,1,13.99,100,1,13.15,2,1,14,100,1,13.1,100,1,14.02,100,1,12.73,100,1,14.17,2,1,12.67,100,1,14.28,100,1,12.65,200,2,14.56,100,1,12.5,700,1,14.61,100,1,12.47,100,1,14.84,100,1,12.46,100,1,14.89,100,1,12.43,700,1,14.91,700,1,ARL,262279553
479,2025-07-17T15:16:31.614205345Z,2025-07-17T15:16:31.614205345Z,10,2,1108,C,A,2,14.02,100,130,165351,221423706,13.37,100,1,13.99,100,1,13.15,2,1,14,100,1,13.1,100,1,14.17,2,1,12.73,100,1,14.28,100,1,12.67,100,1,14.56,100,1,12.65,200,2,14.61,100,1,12.5,700,1,14.84,100,1,12.47,100,1,14.89,100,1,12.46,100,1,14.91,700,1,12.43,700,1,14.95,700,1,ARL,260184621
480,2025-07-17T15:16:39.373301585Z,2025-07-17T15:16:39.373301585Z,10,2,1108,A,A,0,13.98,10,130,165864,221549244,13.37,100,1,13.98,10,1,13.15,2,1,13.99,100,1,13.1,100,1,14,100,1,12.73,100,1,14.17,2,1,12.67,100,1,14.28,100,1,12.65,200,2,14.56,100,1,12.5,700,1,14.61,100,1,12.47,100,1,14.84,100,1,12.46,100,1,14.89,100,1,12.43,700,1,14.91,700,1,ARL,262432821
481,2025-07-17T15:17:50.916157330Z,2025-07-17T15:17:50.916157330Z,10,2,1108,C,A,0,13.98,10,130,168167,223060323,13.37,100,1,13.99,100,1,13.15,2,1,14,100,1,13.1,100,1,14.17,2,1,12.73,100,1,14.28,100,1,12.67,100,1,14.56,100,1,12.65,200,2,14.61,100,1,12.5,700,1,14.84,100,1,12.47,100,1,14.89,100,1,12.46,100,1,14.91,700,1,12.43,700,1,14.95,700,1,ARL,262432821
482,2025-07-17T15:17:51.938301087Z,2025-07-17T15:17:51.938301087Z,10,2,1108,C,A,1,14,100,130,166302,223092013,13.37,100,1,13.99,100,1,13.15,2,1,14.17,2,1,13.1,100,1,14.28,100,1,12.73,100,1,14.56,100,1,12.67,100,1,14.61,100,1,12.65,200,2,14.84,100,1,12.5,700,1,14.89,100,1,12.47,100,1,14.91,700,1,12.46,100,1,14.95,700,1,12.43,700,1,14.98,200,2,ARL,262279553
483,2025-07-17T15:17:55.957258362Z,2025-07-17T15:17:55.957258362Z,10,2,1108,A,A,1,14.01,100,130,165459,223181022,13.37,100,1,13.99,100,1,13.15,2,1,14.01,100,1,13.1,100,1,14.17,2,1,12.73,100,1,14.28,100,1,12.67,100,1,14.56,100,1,12.65,200,2,14.61,100,1,12.5,700,1,14.84,100,1,12.47,100,1,14.89,100,1,12.46,100,1,14.91,700,1,12.43,700,1,14.95,700,1,ARL,264420961
484,2025-07-17T15:19:23.618215364Z,2025-07-17T15:19:23.618215364Z,10,2,1108,C,A,1,14.01,100,130,165212,224925658,13.37,100,1,13.99,100,1,13.15,2,1,14.17,2,1,13.1,100,1,14.28,100,1,12.73,100,1,14.56,100,1,12.67,100,1,14.61,100,1,12.65,200,2,14.84,100,1,12.5,700,1,14.89,100,1,12.47,100,1,14.91,700,1,12.46,100,1,14.95,700,1,12.43,700,1,14.98,200,2,ARL,264420961
485,2025-07-17T15:19:27.663625107Z,2025-07-17T15:19:27.663625107Z,10,2,1108,A,A,1,14.03,100,130,165804,224999109,13.37,100,1,13.99,100,1,13.15,2,1,14.03,100,1,13.1,100,1,14.17,2,1,12.73,100,1,14.28,100,1,12.67,100,1,14.56,100,1,12.65,200,2,14.61,100,1,12.5,700,1,14.84,100,1,12.47,100,1,14.89,100,1,12.46,100,1,14.91,700,1,12.43,700,1,14.95,700,1,ARL,266714557
486,2025-07-17T15:20:46.704980311Z,2025-07-17T15:20:46.704980311Z,10,2,1108,A,A,1,14.01,100,130,165565,226851430,13.37,100,1,13.99,100,1,13.15,2,1,14.01,100,1,13.1,100,1,14.03,100,1,12.73,100,1,14.17,2,1,12.67,100,1,14.28,100,1,12.65,200,2,14.56,100,1,12.5,700,1,14.61,100,1,12.47,100,1,14.84,100,1,12.46,100,1,14.89,100,1,12.43,700,1,14.91,700,1,ARL,269075833
487,2025-07-17T15:20:46.716532886Z,2025-07-17T15:20:46.716532886Z,10,2,1108,C,A,2,14.03,100,130,165591,226851533,13.37,100,1,13.99,100,1,13.15,2,1,14.01,100,1,13.1,100,1,14.17,2,1,12.73,100,1,14.28,100,1,12.67,100,1,14.56,100,1,12.65,200,2,14.61,100,1,12.5,700,1,14.84,100,1,12.47,100,1,14.89,100,1,12.46,100,1,14.91,700,1,12.43,700,1,14.95,700,1,ARL,266714557
488,2025-07-17T15:23:00.249796874Z,2025-07-17T15:23:00.249796874Z,10,2,1108,C,B,1,13.15,2,0,165898,229397485,13.37,100,1,13.99,100,1,13.1,100,1,14.01,100,1,12.73,100,1,14.17,2,1,12.67,100,1,14.28,100,1,12.65,200,2,14.56,100,1,12.5,700,1,14.61,100,1,12.47,100,1,14.84,100,1,12.46,100,1,14.89,100,1,12.43,700,1,14.91,700,1,12.42,700,1,14.95,700,1,ARL,130693973
489,2025-07-17T15:23:00.249796874Z,2025-07-17T15:23:00.249796874Z,10,2,1108,A,B,1,13.23,2,130,165898,229397485,13.37,100,1,13.99,100,1,13.23,2,1,14.01,100,1,13.1,100,1,14.17,2,1,12.73,100,1,14.28,100,1,12.67,100,1,14.56,100,1,12.65,200,2,14.61,100,1,12.5,700,1,14.84,100,1,12.47,100,1,14.89,100,1,12.46,100,1,14.91,700,1,12.43,700,1,14.95,700,1,ARL,272263853
490,2025-07-17T15:26:04.665993515Z,2025-07-17T15:26:04.665993515Z,10,2,1108,C,A,2,14.17,2,0,165345,232977340,13.37,100,1,13.99,100,1,13.23,2,1,14.01,100,1,13.1,100,1,14.28,100,1,12.73,100,1,14.56,100,1,12.67,100,1,14.61,100,1,12.65,200,2,14.84,100,1,12.5,700,1,14.89,100,1,12.47,100,1,14.91,700,1,12.46,100,1,14.95,700,1,12.43,700,1,14.98,200,2,ARL,252720897
491,2025-07-17T15:26:04.665993515Z,2025-07-17T15:26:04.665993515Z,10,2,1108,A,A,2,14.09,2,130,165345,232977340,13.37,100,1,13.99,100,1,13.23,2,1,14.01,100,1,13.1,100,1,14.09,2,1,12.73,100,1,14.28,100,1,12.67,100,1,14.56,100,1,12.65,200,2,14.61,100,1,12.5,700,1,14.84,100,1,12.47,100,1,14.89,100,1,12.46,100,1,14.91,700,1,12.43,700,1,14.95,700,1,ARL,276751517
492,2025-07-17T15:28:38.882820591Z,2025-07-17T15:28:38.882820591Z,10,2,1108,A,A,0,13.99,100,130,165332,235874491,13.37,100,1,13.99,200,2,13.23,2,1,14.01,100,1,13.1,100,1,14.09,2,1,12.73,100,1,14.28,100,1,12.67,100,1,14.56,100,1,12.65,200,2,14.61,100,1,12.5,700,1,14.84,100,1,12.47,100,1,14.89,100,1,12.46,100,1,14.91,700,1,12.43,700,1,14.95,700,1,ARL,280387693
493,2025-07-17T15:28:38.890623989Z,2025-07-17T15:28:38.890623989Z,10,2,1108,C,A,1,14.01,100,130,165225,235874556,13.37,100,1,13.99,200,2,13.23,2,1,14.09,2,1,13.1,100,1,14.28,100,1,12.73,100,1,14.56,100,1,12.67,100,1,14.61,100,1,12.65,200,2,14.84,100,1,12.5,700,1,14.89,100,1,12.47,100,1,14.91,700,1,12.46,100,1,14.95,700,1,12.43,700,1,14.98,200,2,ARL,269075833
494,2025-07-17T15:28:44.820769301Z,2025-07-17T15:28:44.820769301Z,10,2,1108,C,A,0,13.99,100,130,165313,235961324,13.37,100,1,13.99,100,1,13.23,2,1,14.09,2,1,13.1,100,1,14.28,100,1,12.73,100,1,14.56,100,1,12.67,100,1,14.61,100,1,12.65,200,2,14.84,100,1,12.5,700,1,14.89,100,1,12.47,100,1,14.91,700,1,12.46,100,1,14.95,700,1,12.43,700,1,14.98,200,2,ARL,280387693
495,2025-07-17T15:28:48.918645728Z,2025-07-17T15:28:48.918645728Z,10,2,1108,A,A,1,14.01,100,130,165475,236028551,13.37,100,1,13.99,100,1,13.23,2,1,14.01,100,1,13.1,100,1,14.09,2,1,12.73,100,1,14.28,100,1,12.67,100,1,14.56,100,1,12.65,200,2,14.61,100,1,12.5,700,1,14.84,100,1,12.47,100,1,14.89,100,1,12.46,100,1,14.91,700,1,12.43,700,1,14.95,700,1,ARL,280580873
496,2025-07-17T15:30:23.573067851Z,2025-07-17T15:30:23.573067851Z,10,2,1108,A,A,0,13.82,10,130,165408,237754758,13.37,100,1,13.82,10,1,13.23,2,1,13.99,100,1,13.1,100,1,14.01,100,1,12.73,100,1,14.09,2,1,12.67,100,1,14.28,100,1,12.65,200,2,14.56,100,1,12.5,700,1,14.61,100,1,12.47,100,1,14.84,100,1,12.46,100,1,14.89,100,1,12.43,700,1,14.91,700,1,ARL,282775557
497,2025-07-17T15:30:23.573362522Z,2025-07-17T15:30:23.573362522Z,10,2,1108,A,A,7,14.72,100,130,165837,237754762,13.37,100,1,13.82,10,1,13.23,2,1,13.99,100,1,13.1,100,1,14.01,100,1,12.73,100,1,14.09,2,1,12.67,100,1,14.28,100,1,12.65,200,2,14.56,100,1,12.5,700,1,14.61,100,1,12.47,100,1,14.72,100,1,12.46,100,1,14.84,100,1,12.43,700,1,14.89,100,1,ARL,282775561
498,2025-07-17T15:30:23.574688647Z,2025-07-17T15:30:23.574688647Z,10,2,1108,A,A,7,14.72,100,130,165518,237754776,13.37,100,1,13.82,10,1,13.23,2,1,13.99,100,1,13.1,100,1,14.01,100,1,12.73,100,1,14.09,2,1,12.67,100,1,14.28,100,1,12.65,200,2,14.56,100,1,12.5,700,1,14.61,100,1,12.47,100,1,14.72,200,2,12.46,100,1,14.84,100,1,12.43,700,1,14.89,100,1,ARL,282775577
499,2025-07-17T15:30:23.585025490Z,2025-07-17T15:30:23.585025490Z,10,2,1108,A,A,1,13.84,100,130,165591,237755075,13.37,100,1,13.82,10,1,13.23,2,1,13.84,100,1,13.1,100,1,13.99,100,1,12.73,100,1,14.01,100,1,12.67,100,1,14.09,2,1,12.65,200,2,14.28,100,1,12.5,700,1,14.56,100,1,12.47,100,1,14.61,100,1,12.46,100,1,14.72,200,2,12.43,700,1,14.84,100,1,ARL,282775973
500,2025-07-17T15:30:23.586553674Z,2025-07-17T15:30:23.586553674Z,10,2,1108,C,A,10,14.89,100,0,165697,237755086,13.37,100,1,13.82,10,1,13.23,2,1,13.84,100,1,13.1,100,1,13.99,100,1,12.73,100,1,14.01,100,1,12.67,100,1,14.09,2,1,12.65,200,2,14.28,100,1,12.5,700,1,14.56,100,1,12.47,100,1,14.61,100,1,12.46,100,1,14.72,200,2,12.43,700,1,14.84,100,1,ARL,128570453
501,2025-07-17T15:30:23.586553674Z,2025-07-17T15:30:23.586553674Z,10,2,1108,A,A,8,14.65,100,130,165697,237755086,13.37,100,1,13.82,10,1,13.23,2,1,13.84,100,1,13.1,100,1,13.99,100,1,12.73,100,1,14.01,100,1,12.67,100,1,14.09,2,1,12.65,200,2,14.28,100,1,12.5,700,1,14.56,100,1,12.47,100,1,14.61,100,1,12.46,100,1,14.65,100,1,12.43,700,1,14.72,200,2,ARL,282776013
502,2025-07-17T15:30:23.587416236Z,2025-07-17T15:30:23.587416236Z,10,2,1108,A,A,10,14.81,100,130,165645,237755098,13.37,100,1,13.82,10,1,13.23,2,1,13.84,100,1,13.1,100,1,13.99,100,1,12.73,100,1,14.01,100,1,12.67,100,1,14.09,2,1,12.65,200,2,14.28,100,1,12.5,700,1,14.56,100,1,12.47,100,1,14.61,100,1,12.46,100,1,14.65,100,1,12.43,700,1,14.72,200,2,ARL,282776029
503,2025-07-17T15:30:23.590096343Z,2025-07-17T15:30:23.590096343Z,10,2,1108,A,A,10,14.81,100,130,165449,237755128,13.37,100,1,13.82,10,1,13.23,2,1,13.84,100,1,13.1,100,1,13.99,100,1,12.73,100,1,14.01,100,1,12.67,100,1,14.09,2,1,12.65,200,2,14.28,100,1,12.5,700,1,14.56,100,1,12.47,100,1,14.61,100,1,12.46,100,1,14.65,100,1,12.43,700,1,14.72,200,2,ARL,282776089
504,2025-07-17T15:30:23.591793735Z,2025-07-17T15:30:23.591793735Z,10,2,1108,C,A,3,14.01,100,130,165385,237755138,13.37,100,1,13.82,10,1,13.23,2,1,13.84,100,1,13.1,100,1,13.99,100,1,12.73,100,1,14.09,2,1,12.67,100,1,14.28,100,1,12.65,200,2,14.56,100,1,12.5,700,1,14.61,100,1,12.47,100,1,14.65,100,1,12.46,100,1,14.72,200,2,12.43,700,1,14.81,200,2,ARL,280580873
505,2025-07-17T15:30:23.602827102Z,2025-07-17T15:30:23.602827102Z,10,2,1108,C,A,4,14.28,100,130,165337,237755229,13.37,100,1,13.82,10,1,13.23,2,1,13.84,100,1,13.1,100,1,13.99,100,1,12.73,100,1,14.09,2,1,12.67,100,1,14.56,100,1,12.65,200,2,14.61,100,1,12.5,700,1,14.65,100,1,12.47,100,1,14.72,200,2,12.46,100,1,14.81,200,2,12.43,700,1,14.84,100,1,ARL,146956357
506,2025-07-17T15:30:23.602881129Z,2025-07-17T15:30:23.602881129Z,10,2,1108,A,A,4,14.12,100,130,165331,237755230,13.37,100,1,13.82,10,1,13.23,2,1,13.84,100,1,13.1,100,1,13.99,100,1,12.73,100,1,14.09,2,1,12.67,100,1,14.12,100,1,12.65,200,2,14.56,100,1,12.5,700,1,14.61,100,1,12.47,100,1,14.65,100,1,12.46,100,1,14.72,200,2,12.43,700,1,14.81,200,2,ARL,282776285
507,2025-07-17T15:30:23.951957017Z,2025-07-17T15:30:23.951957017Z,10,2,1108,C,A,2,13.99,100,0,165563,237759683,13.37,100,1,13.82,10,1,13.23,2,1,13.84,100,1,13.1,100,1,14.09,2,1,12.73,100,1,14.12,100,1,12.67,100,1,14.56,100,1,12.65,200,2,14.61,100,1,12.5,700,1,14.65,100,1,12.47,100,1,14.72,200,2,12.46,100,1,14.81,200,2,12.43,700,1,14.84,100,1,ARL,237978541
508,2025-07-17T15:30:23.951957017Z,2025-07-17T15:30:23.951957017Z,10,2,1108,A,A,1,13.83,100,130,165563,237759683,13.37,100,1,13.82,10,1,13.23,2,1,13.83,100,1,13.1,100,1,13.84,100,1,12.73,100,1,14.09,2,1,12.67,100,1,14.12,100,1,12.65,200,2,14.56,100,1,12.5,700,1,14.61,100,1,12.47,100,1,14.65,100,1,12.46,100,1,14.72,200,2,12.43,700,1,14.81,200,2,ARL,282781741
509,2025-07-17T15:30:24.768909757Z,2025-07-17T15:30:24.768909757Z,10,2,1108,C,A,0,13.82,10,130,165057,237771822,13.37,100,1,13.83,100,1,13.23,2,1,13.84,100,1,13.1,100,1,14.09,2,1,12.73,100,1,14.12,100,1,12.67,100,1,14.56,100,1,12.65,200,2,14.61,100,1,12.5,700,1,14.65,100,1,12.47,100,1,14.72,200,2,12.46,100,1,14.81,200,2,12.43,700,1,14.84,100,1,ARL,282775557
510,2025-07-17T15:30:28.617171810Z,2025-07-17T15:30:28.617171810Z,10,2,1108,A,A,4,14.53,700,130,165388,237840336,13.37,100,1,13.83,100,1,13.23,2,1,13.84,100,1,13.1,100,1,14.09,2,1,12.73,100,1,14.12,100,1,12.67,100,1,14.53,700,1,12.65,200,2,14.56,100,1,12.5,700,1,14.61,100,1,12.47,100,1,14.65,100,1,12.46,100,1,14.72,200,2,12.43,700,1,14.81,200,2,ARL,282881853
511,2025-07-17T15:30:30.767048606Z,2025-07-17T15:30:30.767048606Z,10,2,1108,A,A,6,14.6,700,130,165301,237873135,13.37,100,1,13.83,100,1,13.23,2,1,13.84,100,1,13.1,100,1,14.09,2,1,12.73,100,1,14.12,100,1,12.67,100,1,14.53,700,1,12.65,200,2,14.56,100,1,12.5,700,1,14.6,700,1,12.47,100,1,14.61,100,1,12.46,100,1,14.65,100,1,12.43,700,1,14.72,200,2,ARL,282920685
512,2025-07-17T15:30:33.016821395Z,2025-07-17T15:30:33.016821395Z,10,2,1108,A,A,5,14.56,700,130,165702,237915946,13.37,100,1,13.83,100,1,13.23,2,1,13.84,100,1,13.1,100,1,14.09,2,1,12.73,100,1,14.12,100,1,12.67,100,1,14.53,700,1,12.65,200,2,14.56,800,2,12.5,700,1,14.6,700,1,12.47,100,1,14.61,100,1,12.46,100,1,14.65,100,1,12.43,700,1,14.72,200,2,ARL,282969973
513,2025-07-17T15:30:49.985741094Z,2025-07-17T15:30:49.985741094Z,10,2,1108,C,A,2,14.09,2,0,165660,238230724,13.37,100,1,13.83,100,1,13.23,2,1,13.84,100,1,13.1,100,1,14.12,100,1,12.73,100,1,14.53,700,1,12.67,100,1,14.56,800,2,12.65,200,2,14.6,700,1,12.5,700,1,14.61,100,1,12.47,100,1,14.65,100,1,12.46,100,1,14.72,200,2,12.43,700,1,14.81,200,2,ARL,276751517
514,2025-07-17T15:30:49.985741094Z,2025-07-17T15:30:49.985741094Z,10,2,1108,A,A,2,14.02,2,130,165660,238230724,13.37,100,1,13.83,100,1,13.23,2,1,13.84,100,1,13.1,100,1,14.02,2,1,12.73,100,1,14.12,100,1,12.67,100,1,14.53,700,1,12.65,200,2,14.56,800,2,12.5,700,1,14.6,700,1,12.47,100,1,14.61,100,1,12.46,100,1,14.65,100,1,12.43,700,1,14.72,200,2,ARL,283348193
515,2025-07-17T15:30:59.996351383Z,2025-07-17T15:30:59.996351383Z,10,2,1108,C,A,0,13.83,100,130,165171,238442318,13.37,100,1,13.84,100,1,13.23,2,1,14.02,2,1,13.1,100,1,14.12,100,1,12.73,100,1,14.53,700,1,12.67,100,1,14.56,800,2,12.65,200,2,14.6,700,1,12.5,700,1,14.61,100,1,12.47,100,1,14.65,100,1,12.46,100,1,14.72,200,2,12.43,700,1,14.81,200,2,ARL,282781741
516,2025-07-17T15:31:00.002038446Z,2025-07-17T15:31:00.002038446Z,10,2,1108,C,A,0,13.84,100,130,165476,238442443,13.37,100,1,14.02,2,1,13.23,2,1,14.12,100,1,13.1,100,1,14.53,700,1,12.73,100,1,14.56,800,2,12.67,100,1,14.6,700,1,12.65,200,2,14.61,100,1,12.5,700,1,14.65,100,1,12.47,100,1,14.72,200,2,12.46,100,1,14.81,200,2,12.43,700,1,14.84,100,1,ARL,282775973
517,2025-07-17T15:31:00.002313250Z,2025-07-17T15:31:00.002313250Z,10,2,1108,C,A,2,14.53,700,130,165143,238442461,13.37,100,1,14.02,2,1,13.23,2,1,14.12,100,1,13.1,100,1,14.56,800,2,12.73,100,1,14.6,700,1,12.67,100,1,14.61,100,1,12.65,200,2,14.65,100,1,12.5,700,1,14.72,200,2,12.47,100,1,14.81,200,2,12.46,100,1,14.84,100,1,12.43,700,1,14.91,800,2,ARL,282881853
518,2025-07-17T15:31:00.002359969Z,2025-07-17T15:31:00.002359969Z,10,2,1108,A,A,6,14.68,700,130,165244,238442467,13.37,100,1,14.02,2,1,13.23,2,1,14.12,100,1,13.1,100,1,14.56,800,2,12.73,100,1,14.6,700,1,12.67,100,1,14.61,100,1,12.65,200,2,14.65,100,1,12.5,700,1,14.68,700,1,12.47,100,1,14.72,200,2,12.46,100,1,14.81,200,2,12.43,700,1,14.84,100,1,ARL,283592941
519,2025-07-17T15:31:00.002772683Z,2025-07-17T15:31:00.002772683Z,10,2,1108,C,A,7,14.72,100,0,165649,238442486,13.37,100,1,14.02,2,1,13.23,2,1,14.12,100,1,13.1,100,1,14.56,800,2,12.73,100,1,14.6,700,1,12.67,100,1,14.61,100,1,12.65,200,2,14.65,100,1,12.5,700,1,14.68,700,1,12.47,100,1,14.72,100,1,12.46,100,1,14.81,200,2,12.43,700,1,14.84,100,1,ARL,282775577
520,2025-07-17T15:31:00.002788190Z,2025-07-17T15:31:00.002788190Z,10,2,1108,C,A,10,14.91,100,0,165514,238442490,13.37,100,1,14.02,2,1,13.23,2,1,14.12,100,1,13.1,100,1,14.56,800,2,12.73,100,1,14.6,700,1,12.67,100,1,14.61,100,1,12.65,200,2,14.65,100,1,12.5,700,1,14.68,700,1,12.47,100,1,14.72,100,1,12.46,100,1,14.81,200,2,12.43,700,1,14.84,100,1,ARL,282776009
521,2025-07-17T15:31:00.003202003Z,2025-07-17T15:31:00.003202003Z,10,2,1108,C,A,7,14.72,100,0,166269,238442510,13.37,100,1,14.02,2,1,13.23,2,1,14.12,100,1,13.1,100,1,14.56,800,2,12.73,100,1,14.6,700,1,12.67,100,1,14.61,100,1,12.65,200,2,14.65,100,1,12.5,700,1,14.68,700,1,12.47,100,1,14.81,200,2,12.46,100,1,14.84,100,1,12.43,700,1,14.91,700,1,ARL,282775561
522,2025-07-17T15:31:00.006618398Z,2025-07-17T15:31:00.006618398Z,10,2,1108,C,A,5,14.65,100,130,166549,238442608,13.37,100,1,14.02,2,1,13.23,2,1,14.12,100,1,13.1,100,1,14.56,800,2,12.73,100,1,14.6,700,1,12.67,100,1,14.61,100,1,12.65,200,2,14.68,700,1,12.5,700,1,14.81,200,2,12.47,100,1,14.84,100,1,12.46,100,1,14.91,700,1,12.43,700,1,14.96,100,1,ARL,282776013
523,2025-07-17T15:31:00.006784814Z,2025-07-17T15:31:00.006784814Z,10,2,1108,A,A,6,14.79,100,130,165677,238442616,13.37,100,1,14.02,2,1,13.23,2,1,14.12,100,1,13.1,100,1,14.56,800,2,12.73,100,1,14.6,700,1,12.67,100,1,14.61,100,1,12.65,200,2,14.68,700,1,12.5,700,1,14.79,100,1,12.47,100,1,14.81,200,2,12.46,100,1,14.84,100,1,12.43,700,1,14.91,700,1,ARL,283593313
524,2025-07-17T15:31:00.028729168Z,2025-07-17T15:31:00.028729168Z,10,2,1108,C,A,1,14.12,100,130,165310,238443996,13.37,100,1,14.02,2,1,13.23,2,1,14.56,800,2,13.1,100,1,14.6,700,1,12.73,100,1,14.61,100,1,12.67,100,1,14.68,700,1,12.65,200,2,14.79,100,1,12.5,700,1,14.81,200,2,12.47,100,1,14.84,100,1,12.46,100,1,14.91,700,1,12.43,700,1,14.96,100,1,ARL,282776285
525,2025-07-17T15:31:00.028782030Z,2025-07-17T15:31:00.028782030Z,10,2,1108,A,A,1,14.26,100,130,165282,238443998,13.37,100,1,14.02,2,1,13.23,2,1,14.26,100,1,13.1,100,1,14.56,800,2,12.73,100,1,14.6,700,1,12.67,100,1,14.61,100,1,12.65,200,2,14.68,700,1,12.5,700,1,14.79,100,1,12.47,100,1,14.81,200,2,12.46,100,1,14.84,100,1,12.43,700,1,14.91,700,1,ARL,283595181
526,2025-07-17T15:31:00.052941898Z,2025-07-17T15:31:00.052941898Z,10,2,1108,C,A,10,14.96,100,0,165312,238444735,13.37,100,1,14.02,2,1,13.23,2,1,14.26,100,1,13.1,100,1,14.56,800,2,12.73,100,1,14.6,700,1,12.67,100,1,14.61,100,1,12.65,200,2,14.68,700,1,12.5,700,1,14.79,100,1,12.47,100,1,14.81,200,2,12.46,100,1,14.84,100,1,12.43,700,1,14.91,700,1,ARL,283592997
527,2025-07-17T15:31:00.054665340Z,2025-07-17T15:31:00.054665340Z,10,2,1108,C,A,7,14.81,100,0,165507,238444759,13.37,100,1,14.02,2,1,13.23,2,1,14.26,100,1,13.1,100,1,14.56,800,2,12.73,100,1,14.6,700,1,12.67,100,1,14.61,100,1,12.65,200,2,14.68,700,1,12.5,700,1,14.79,100,1,12.47,100,1,14.81,100,1,12.46,100,1,14.84,100,1,12.43,700,1,14.91,700,1,ARL,282776089
528,2025-07-17T15:31:00.054665340Z,2025-07-17T15:31:00.054665340Z,10,2,1108,A,A,10,14.96,100,130,165507,238444759,13.37,100,1,14.02,2,1,13.23,2,1,14.26,100,1,13.1,100,1,14.56,800,2,12.73,100,1,14.6,700,1,12.67,100,1,14.61,100,1,12.65,200,2,14.68,700,1,12.5,700,1,14.79,100,1,12.47,100,1,14.81,100,1,12.46,100,1,14.84,100,1,12.43,700,1,14.91,700,1,ARL,283596721
529,2025-07-17T15:31:00.071243665Z,2025-07-17T15:31:00.071243665Z,10,2,1108,C,A,7,14.81,100,0,165610,238444961,13.37,100,1,14.02,2,1,13.23,2,1,14.26,100,1,13.1,100,1,14.56,800,2,12.73,100,1,14.6,700,1,12.67,100,1,14.61,100,1,12.65,200,2,14.68,700,1,12.5,700,1,14.79,100,1,12.47,100,1,14.84,100,1,12.46,100,1,14.91,700,1,12.43,700,1,14.96,100,1,ARL,282776029
530,2025-07-17T15:31:00.071243665Z,2025-07-17T15:31:00.071243665Z,10,2,1108,A,A,9,14.96,100,130,165610,238444961,13.37,100,1,14.02,2,1,13.23,2,1,14.26,100,1,13.1,100,1,14.56,800,2,12.73,100,1,14.6,700,1,12.67,100,1,14.61,100,1,12.65,200,2,14.68,700,1,12.5,700,1,14.79,100,1,12.47,100,1,14.84,100,1,12.46,100,1,14.91,700,1,12.43,700,1,14.96,200,2,ARL,283596945
531,2025-07-17T15:31:00.347663441Z,2025-07-17T15:31:00.347663441Z,10,2,1108,A,A,1,14.03,100,130,165104,238450791,13.37,100,1,14.02,2,1,13.23,2,1,14.03,100,1,13.1,100,1,14.26,100,1,12.73,100,1,14.56,800,2,12.67,100,1,14.6,700,1,12.65,200,2,14.61,100,1,12.5,700,1,14.68,700,1,12.47,100,1,14.79,100,1,12.46,100,1,14.84,100,1,12.43,700,1,14.91,700,1,ARL,283604173
532,2025-07-17T15:31:04.014425425Z,2025-07-17T15:31:04.014425425Z,10,2,1108,A,A,0,14,100,130,165150,238529875,13.37,100,1,14,100,1,13.23,2,1,14.02,2,1,13.1,100,1,14.03,100,1,12.73,100,1,14.26,100,1,12.67,100,1,14.56,800,2,12.65,200,2,14.6,700,1,12.5,700,1,14.61,100,1,12.47,100,1,14.68,700,1,12.46,100,1,14.79,100,1,12.43,700,1,14.84,100,1,ARL,283694233
533,2025-07-17T15:31:04.124411850Z,2025-07-17T15:31:04.124411850Z,10,2,1108,C,A,2,14.03,100,0,165995,238531822,13.37,100,1,14,100,1,13.23,2,1,14.02,2,1,13.1,100,1,14.26,100,1,12.73,100,1,14.56,800,2,12.67,100,1,14.6,700,1,12.65,200,2,14.61,100,1,12.5,700,1,14.68,700,1,12.47,100,1,14.79,100,1,12.46,100,1,14.84,100,1,12.43,700,1,14.91,700,1,ARL,283604173
534,2025-07-17T15:31:04.124411850Z,2025-07-17T15:31:04.124411850Z,10,2,1108,A,A,1,14.01,100,130,165995,238531822,13.37,100,1,14,100,1,13.23,2,1,14.01,100,1,13.1,100,1,14.02,2,1,12.73,100,1,14.26,100,1,12.67,100,1,14.56,800,2,12.65,200,2,14.6,700,1,12.5,700,1,14.61,100,1,12.47,100,1,14.68,700,1,12.46,100,1,14.79,100,1,12.43,700,1,14.84,100,1,ARL,283695933
535,2025-07-17T15:32:28.644335983Z,2025-07-17T15:32:28.644335983Z,10,2,1108,A,B,0,13.55,10,128,170296,239938946,13.55,10,1,14,100,1,13.37,100,1,14.01,100,1,13.23,2,1,14.02,2,1,13.1,100,1,14.26,100,1,12.73,100,1,14.56,800,2,12.67,100,1,14.6,700,1,12.65,200,2,14.61,100,1,12.5,700,1,14.68,700,1,12.47,100,1,14.79,100,1,12.46,100,1,14.84,100,1,ARL,285545121
536,2025-07-17T15:32:28.653073176Z,2025-07-17T15:32:28.653073176Z,10,2,1108,C,B,1,13.37,100,0,165553,239940048,13.55,10,1,14,100,1,13.23,2,1,14.01,100,1,13.1,100,1,14.02,2,1,12.73,100,1,14.26,100,1,12.67,100,1,14.56,800,2,12.65,200,2,14.6,700,1,12.5,700,1,14.61,100,1,12.47,100,1,14.68,700,1,12.46,100,1,14.79,100,1,12.43,700,1,14.84,100,1,ARL,215999737
537,2025-07-17T15:32:28.653073176Z,2025-07-17T15:32:28.653073176Z,10,2,1108,A,B,1,13.54,100,130,165553,239940048,13.55,10,1,14,100,1,13.54,100,1,14.01,100,1,13.23,2,1,14.02,2,1,13.1,100,1,14.26,100,1,12.73,100,1,14.56,800,2,12.67,100,1,14.6,700,1,12.65,200,2,14.61,100,1,12.5,700,1,14.68,700,1,12.47,100,1,14.79,100,1,12.46,100,1,14.84,100,1,ARL,285545885
538,2025-07-17T15:32:28.653812889Z,2025-07-17T15:32:28.653812889Z,10,2,1108,A,B,8,12.49,100,130,165612,239940096,13.55,10,1,14,100,1,13.54,100,1,14.01,100,1,13.23,2,1,14.02,2,1,13.1,100,1,14.26,100,1,12.73,100,1,14.56,800,2,12.67,100,1,14.6,700,1,12.65,200,2,14.61,100,1,12.5,700,1,14.68,700,1,12.49,100,1,14.79,100,1,12.47,100,1,14.84,100,1,ARL,285545945
539,2025-07-17T15:32:28.653815154Z,2025-07-17T15:32:28.653815154Z,10,2,1108,C,B,5,12.67,100,130,165494,239940097,13.55,10,1,14,100,1,13.54,100,1,14.01,100,1,13.23,2,1,14.02,2,1,13.1,100,1,14.26,100,1,12.73,100,1,14.56,800,2,12.65,200,2,14.6,700,1,12.5,700,1,14.61,100,1,12.49,100,1,14.68,700,1,12.47,100,1,14.79,100,1,12.46,100,1,14.84,100,1,ARL,43663229
540,2025-07-17T15:32:28.654171723Z,2025-07-17T15:32:28.654171723Z,10,2,1108,A,B,4,12.94,100,130,165264,239940109,13.55,10,1,14,100,1,13.54,100,1,14.01,100,1,13.23,2,1,14.02,2,1,13.1,100,1,14.26,100,1,12.94,100,1,14.56,800,2,12.73,100,1,14.6,700,1,12.65,200,2,14.61,100,1,12.5,700,1,14.68,700,1,12.49,100,1,14.79,100,1,12.47,100,1,14.84,100,1,ARL,285545953
541,2025-07-17T15:32:28.656908386Z,2025-07-17T15:32:28.656908386Z,10,2,1108,C,B,9,12.47,100,130,165357,239940358,13.55,10,1,14,100,1,13.54,100,1,14.01,100,1,13.23,2,1,14.02,2,1,13.1,100,1,14.26,100,1,12.94,100,1,14.56,800,2,12.73,100,1,14.6,700,1,12.65,200,2,14.61,100,1,12.5,700,1,14.68,700,1,12.49,100,1,14.79,100,1,12.46,100,1,14.84,100,1,ARL,43554133
542,2025-07-17T15:32:28.657008222Z,2025-07-17T15:32:28.657008222Z,10,2,1108,A,B,5,12.73,100,130,165634,239940359,13.55,10,1,14,100,1,13.54,100,1,14.01,100,1,13.23,2,1,14.02,2,1,13.1,100,1,14.26,100,1,12.94,100,1,14.56,800,2,12.73,200,2,14.6,700,1,12.65,200,2,14.61,100,1,12.5,700,1,14.68,700,1,12.49,100,1,14.79,100,1,12.46,100,1,14.84,100,1,ARL,285546061
543,2025-07-17T15:32:28.666909194Z,2025-07-17T15:32:28.666909194Z,10,2,1108,C,B,3,13.1,100,130,165243,239940810,13.55,10,1,14,100,1,13.54,100,1,14.01,100,1,13.23,2,1,14.02,2,1,12.94,100,1,14.26,100,1,12.73,200,2,14.56,800,2,12.65,200,2,14.6,700,1,12.5,700,1,14.61,100,1,12.49,100,1,14.68,700,1,12.46,100,1,14.79,100,1,12.43,700,1,14.84,100,1,ARL,216001413
544,2025-07-17T15:32:28.666961018Z,2025-07-17T15:32:28.666961018Z,10,2,1108,A,B,2,13.27,100,130,165619,239940813,13.55,10,1,14,100,1,13.54,100,1,14.01,100,1,13.27,100,1,14.02,2,1,13.23,2,1,14.26,100,1,12.94,100,1,14.56,800,2,12.73,200,2,14.6,700,1,12.65,200,2,14.61,100,1,12.5,700,1,14.68,700,1,12.49,100,1,14.79,100,1,12.46,100,1,14.84,100,1,ARL,285546673
545,2025-07-17T15:32:28.674279259Z,2025-07-17T15:32:28.674279259Z,10,2,1108,A,B,7,12.59,100,130,165452,239941057,13.55,10,1,14,100,1,13.54,100,1,14.01,100,1,13.27,100,1,14.02,2,1,13.23,2,1,14.26,100,1,12.94,100,1,14.56,800,2,12.73,200,2,14.6,700,1,12.65,200,2,14.61,100,1,12.59,100,1,14.68,700,1,12.5,700,1,14.79,100,1,12.49,100,1,14.84,100,1,ARL,285546893
546,2025-07-17T15:32:28.771830554Z,2025-07-17T15:32:28.771830554Z,10,2,1108,C,B,0,13.55,10,128,165433,239945992,13.54,100,1,14,100,1,13.27,100,1,14.01,100,1,13.23,2,1,14.02,2,1,12.94,100,1,14.26,100,1,12.73,200,2,14.56,800,2,12.65,200,2,14.6,700,1,12.59,100,1,14.61,100,1,12.5,700,1,14.68,700,1,12.49,100,1,14.79,100,1,12.46,100,1,14.84,100,1,ARL,285545121
547,2025-07-17T15:32:28.806765209Z,2025-07-17T15:32:28.806765209Z,10,2,1108,A,B,6,12.59,100,130,165513,239948319,13.54,100,1,14,100,1,13.27,100,1,14.01,100,1,13.23,2,1,14.02,2,1,12.94,100,1,14.26,100,1,12.73,200,2,14.56,800,2,12.65,200,2,14.6,700,1,12.59,200,2,14.61,100,1,12.5,700,1,14.68,700,1,12.49,100,1,14.79,100,1,12.46,100,1,14.84,100,1,ARL,285553901
548,2025-07-17T15:32:28.850122877Z,2025-07-17T15:32:28.850122877Z,10,2,1108,A,A,0,13.98,100,130,165338,239950805,13.54,100,1,13.98,100,1,13.27,100,1,14,100,1,13.23,2,1,14.01,100,1,12.94,100,1,14.02,2,1,12.73,200,2,14.26,100,1,12.65,200,2,14.56,800,2,12.59,200,2,14.6,700,1,12.5,700,1,14.61,100,1,12.49,100,1,14.68,700,1,12.46,100,1,14.79,100,1,ARL,285556869
549,2025-07-17T15:32:28.856973845Z,2025-07-17T15:32:28.856973845Z,10,2,1108,C,A,1,14,100,130,166262,239951361,13.54,100,1,13.98,100,1,13.27,100,1,14.01,100,1,13.23,2,1,14.02,2,1,12.94,100,1,14.26,100,1,12.73,200,2,14.56,800,2,12.65,200,2,14.6,700,1,12.59,200,2,14.61,100,1,12.5,700,1,14.68,700,1,12.49,100,1,14.79,100,1,12.46,100,1,14.84,100,1,ARL,283694233
550,2025-07-17T15:32:29.573469021Z,2025-07-17T15:32:29.573469021Z,10,2,1108,C,B,0,13.54,100,130,165181,239975997,13.27,100,1,13.98,100,1,13.23,2,1,14.01,100,1,12.94,100,1,14.02,2,1,12.73,200,2,14.26,100,1,12.65,200,2,14.56,800,2,12.59,200,2,14.6,700,1,12.5,700,1,14.61,100,1,12.49,100,1,14.68,700,1,12.46,100,1,14.79,100,1,12.43,700,1,14.84,100,1,ARL,285545885
551,2025-07-17T15:32:29.574202467Z,2025-07-17T15:32:29.574202467Z,10,2,1108,C,B,7,12.49,100,0,165859,239976004,13.27,100,1,13.98,100,1,13.23,2,1,14.01,100,1,12.94,100,1,14.02,2,1,12.73,200,2,14.26,100,1,12.65,200,2,14.56,800,2,12.59,200,2,14.6,700,1,12.5,700,1,14.61,100,1,12.46,100,1,14.68,700,1,12.43,700,1,14.79,100,1,12.42,700,1,14.84,100,1,ARL,285545945
552,2025-07-17T15:32:29.574206685Z,2025-07-17T15:32:29.574206685Z,10,2,1108,C,B,2,12.94,100,130,165181,239976005,13.27,100,1,13.98,100,1,13.23,2,1,14.01,100,1,12.73,200,2,14.02,2,1,12.65,200,2,14.26,100,1,12.59,200,2,14.56,800,2,12.5,700,1,14.6,700,1,12.46,100,1,14.61,100,1,12.43,700,1,14.68,700,1,12.42,700,1,14.79,100,1,12.37,700,1,14.84,100,1,ARL,285545953
553,2025-07-17T15:32:29.574556760Z,2025-07-17T15:32:29.574556760Z,10,2,1108,A,B,3,12.71,100,130,165381,239976069,13.27,100,1,13.98,100,1,13.23,2,1,14.01,100,1,12.73,200,2,14.02,2,1,12.71,100,1,14.26,100,1,12.65,200,2,14.56,800,2,12.59,200,2,14.6,700,1,12.5,700,1,14.61,100,1,12.46,100,1,14.68,700,1,12.43,700,1,14.79,100,1,12.42,700,1,14.84,100,1,ARL,285586093
554,2025-07-17T15:32:29.574968914Z,2025-07-17T15:32:29.574968914Z,10,2,1108,C,B,5,12.59,100,0,165741,239976143,13.27,100,1,13.98,100,1,13.23,2,1,14.01,100,1,12.73,200,2,14.02,2,1,12.71,100,1,14.26,100,1,12.65,200,2,14.56,800,2,12.59,100,1,14.6,700,1,12.5,700,1,14.61,100,1,12.46,100,1,14.68,700,1,12.43,700,1,14.79,100,1,12.42,700,1,14.84,100,1,ARL,285546893
555,2025-07-17T15:32:29.578151593Z,2025-07-17T15:32:29.578151593Z,10,2,1108,C,B,5,12.59,100,0,165645,239976225,13.27,100,1,13.98,100,1,13.23,2,1,14.01,100,1,12.73,200,2,14.02,2,1,12.71,100,1,14.26,100,1,12.65,200,2,14.56,800,2,12.5,700,1,14.6,700,1,12.46,100,1,14.61,100,1,12.43,700,1,14.68,700,1,12.42,700,1,14.79,100,1,12.37,700,1,14.84,100,1,ARL,285553901
556,2025-07-17T15:32:29.578151593Z,2025-07-17T15:32:29.578151593Z,10,2,1108,A,B,10,12.34,100,130,165645,239976225,13.27,100,1,13.98,100,1,13.23,2,1,14.01,100,1,12.73,200,2,14.02,2,1,12.71,100,1,14.26,100,1,12.65,200,2,14.56,800,2,12.5,700,1,14.6,700,1,12.46,100,1,14.61,100,1,12.43,700,1,14.68,700,1,12.42,700,1,14.79,100,1,12.37,700,1,14.84,100,1,ARL,285586189
557,2025-07-17T15:32:29.580767960Z,2025-07-17T15:32:29.580767960Z,10,2,1108,A,B,1,13.26,100,130,165195,239976262,13.27,100,1,13.98,100,1,13.26,100,1,14.01,100,1,13.23,2,1,14.02,2,1,12.73,200,2,14.26,100,1,12.71,100,1,14.56,800,2,12.65,200,2,14.6,700,1,12.5,700,1,14.61,100,1,12.46,100,1,14.68,700,1,12.43,700,1,14.79,100,1,12.42,700,1,14.84,100,1,ARL,285586221
558,2025-07-17T15:32:29.580786478Z,2025-07-17T15:32:29.580786478Z,10,2,1108,C,A,1,14.01,100,0,165567,239976263,13.27,100,1,13.98,100,1,13.26,100,1,14.02,2,1,13.23,2,1,14.26,100,1,12.73,200,2,14.56,800,2,12.71,100,1,14.6,700,1,12.65,200,2,14.61,100,1,12.5,700,1,14.68,700,1,12.46,100,1,14.79,100,1,12.43,700,1,14.84,100,1,12.42,700,1,14.91,700,1,ARL,283695933
559,2025-07-17T15:32:29.580786478Z,2025-07-17T15:32:29.580786478Z,10,2,1108,A,A,1,13.99,100,130,165567,239976263,13.27,100,1,13.98,100,1,13.26,100,1,13.99,100,1,13.23,2,1,14.02,2,1,12.73,200,2,14.26,100,1,12.71,100,1,14.56,800,2,12.65,200,2,14.6,700,1,12.5,700,1,14.61,100,1,12.46,100,1,14.68,700,1,12.43,700,1,14.79,100,1,12.42,700,1,14.84,100,1,ARL,285586225
560,2025-07-17T15:32:29.587027681Z,2025-07-17T15:32:29.587027681Z,10,2,1108,C,B,0,13.27,100,130,165171,239976327,13.26,100,1,13.98,100,1,13.23,2,1,13.99,100,1,12.73,200,2,14.02,2,1,12.71,100,1,14.26,100,1,12.65,200,2,14.56,800,2,12.5,700,1,14.6,700,1,12.46,100,1,14.61,100,1,12.43,700,1,14.68,700,1,12.42,700,1,14.79,100,1,12.37,700,1,14.84,100,1,ARL,285546673
561,2025-07-17T15:32:29.587081086Z,2025-07-17T15:32:29.587081086Z,10,2,1108,A,B,2,13.03,100,130,165384,239976336,13.26,100,1,13.98,100,1,13.23,2,1,13.99,100,1,13.03,100,1,14.02,2,1,12.73,200,2,14.26,100,1,12.71,100,1,14.56,800,2,12.65,200,2,14.6,700,1,12.5,700,1,14.61,100,1,12.46,100,1,14.68,700,1,12.43,700,1,14.79,100,1,12.42,700,1,14.84,100,1,ARL,285586293
562,2025-07-17T15:32:29.659513918Z,2025-07-17T15:32:29.659513918Z,10,2,1108,C,B,3,12.73,100,0,165362,239977574,13.26,100,1,13.98,100,1,13.23,2,1,13.99,100,1,13.03,100,1,14.02,2,1,12.73,100,1,14.26,100,1,12.71,100,1,14.56,800,2,12.65,200,2,14.6,700,1,12.5,700,1,14.61,100,1,12.46,100,1,14.68,700,1,12.43,700,1,14.79,100,1,12.42,700,1,14.84,100,1,ARL,285546061
563,2025-07-17T15:32:29.659513918Z,2025-07-17T15:32:29.659513918Z,10,2,1108,A,B,7,12.46,100,130,165362,239977574,13.26,100,1,13.98,100,1,13.23,2,1,13.99,100,1,13.03,100,1,14.02,2,1,12.73,100,1,14.26,100,1,12.71,100,1,14.56,800,2,12.65,200,2,14.6,700,1,12.5,700,1,14.61,100,1,12.46,200,2,14.68,700,1,12.43,700,1,14.79,100,1,12.42,700,1,14.84,100,1,ARL,285587281
564,2025-07-17T15:33:04.247990788Z,2025-07-17T15:33:04.247990788Z,10,2,1108,A,A,8,14.72,100,130,166080,240885845,13.26,100,1,13.98,100,1,13.23,2,1,13.99,100,1,13.03,100,1,14.02,2,1,12.73,100,1,14.26,100,1,12.71,100,1,14.56,800,2,12.65,200,2,14.6,700,1,12.5,700,1,14.61,100,1,12.46,200,2,14.68,700,1,12.43,700,1,14.72,100,1,12.42,700,1,14.79,100,1,ARL,286680573
565,2025-07-17T15:33:04.248023883Z,2025-07-17T15:33:04.248023883Z,10,2,1108,A,A,8,14.72,100,130,165525,240885847,13.26,100,1,13.98,100,1,13.23,2,1,13.99,100,1,13.03,100,1,14.02,2,1,12.73,100,1,14.26,100,1,12.71,100,1,14.56,800,2,12.65,200,2,14.6,700,1,12.5,700,1,14.61,100,1,12.46,200,2,14.68,700,1,12.43,700,1,14.72,200,2,12.42,700,1,14.79,100,1,ARL,286680577
566,2025-07-17T15:33:04.255546094Z,2025-07-17T15:33:04.255546094Z,10,2,1108,A,A,0,13.84,100,130,165956,240886132,13.26,100,1,13.84,100,1,13.23,2,1,13.98,100,1,13.03,100,1,13.99,100,1,12.73,100,1,14.02,2,1,12.71,100,1,14.26,100,1,12.65,200,2,14.56,800,2,12.5,700,1,14.6,700,1,12.46,200,2,14.61,100,1,12.43,700,1,14.68,700,1,12.42,700,1,14.72,200,2,ARL,286680685
567,2025-07-17T15:33:04.261518776Z,2025-07-17T15:33:04.261518776Z,10,2,1108,C,A,10,14.79,100,0,165543,240886271,13.26,100,1,13.84,100,1,13.23,2,1,13.98,100,1,13.03,100,1,13.99,100,1,12.73,100,1,14.02,2,1,12.71,100,1,14.26,100,1,12.65,200,2,14.56,800,2,12.5,700,1,14.6,700,1,12.46,200,2,14.61,100,1,12.43,700,1,14.68,700,1,12.42,700,1,14.72,200,2,ARL,283593313
568,2025-07-17T15:33:04.261518776Z,2025-07-17T15:33:04.261518776Z,10,2,1108,A,A,8,14.65,100,130,165543,240886271,13.26,100,1,13.84,100,1,13.23,2,1,13.98,100,1,13.03,100,1,13.99,100,1,12.73,100,1,14.02,2,1,12.71,100,1,14.26,100,1,12.65,200,2,14.56,800,2,12.5,700,1,14.6,700,1,12.46,200,2,14.61,100,1,12.43,700,1,14.65,100,1,12.42,700,1,14.68,700,1,ARL,286680905
569,2025-07-17T15:33:04.262845834Z,2025-07-17T15:33:04.262845834Z,10,2,1108,C,A,4,14.26,100,130,165480,240886294,13.26,100,1,13.84,100,1,13.23,2,1,13.98,100,1,13.03,100,1,13.99,100,1,12.73,100,1,14.02,2,1,12.71,100,1,14.56,800,2,12.65,200,2,14.6,700,1,12.5,700,1,14.61,100,1,12.46,200,2,14.65,100,1,12.43,700,1,14.68,700,1,12.42,700,1,14.72,200,2,ARL,283595181
570,2025-07-17T15:33:04.262887184Z,2025-07-17T15:33:04.262887184Z,10,2,1108,C,A,1,13.98,100,130,165476,240886296,13.26,100,1,13.84,100,1,13.23,2,1,13.99,100,1,13.03,100,1,14.02,2,1,12.73,100,1,14.56,800,2,12.71,100,1,14.6,700,1,12.65,200,2,14.61,100,1,12.5,700,1,14.65,100,1,12.46,200,2,14.68,700,1,12.43,700,1,14.72,200,2,12.42,700,1,14.81,100,1,ARL,285556869
571,2025-07-17T15:33:04.262899981Z,2025-07-17T15:33:04.262899981Z,10,2,1108,A,A,3,14.12,100,130,165271,240886297,13.26,100,1,13.84,100,1,13.23,2,1,13.99,100,1,13.03,100,1,14.02,2,1,12.73,100,1,14.12,100,1,12.71,100,1,14.56,800,2,12.65,200,2,14.6,700,1,12.5,700,1,14.61,100,1,12.46,200,2,14.65,100,1,12.43,700,1,14.68,700,1,12.42,700,1,14.72,200,2,ARL,286680917
572,2025-07-17T15:33:04.418674487Z,2025-07-17T15:33:04.418674487Z,10,2,1108,A,A,10,14.81,100,130,165661,240888774,13.26,100,1,13.84,100,1,13.23,2,1,13.99,100,1,13.03,100,1,14.02,2,1,12.73,100,1,14.12,100,1,12.71,100,1,14.56,800,2,12.65,200,2,14.6,700,1,12.5,700,1,14.61,100,1,12.46,200,2,14.65,100,1,12.43,700,1,14.68,700,1,12.42,700,1,14.72,200,2,ARL,286684005
573,2025-07-17T15:33:05.330688486Z,2025-07-17T15:33:05.330688486Z,10,2,1108,C,A,1,13.99,100,0,165731,240911093,13.26,100,1,13.84,100,1,13.23,2,1,14.02,2,1,13.03,100,1,14.12,100,1,12.73,100,1,14.56,800,2,12.71,100,1,14.6,700,1,12.65,200,2,14.61,100,1,12.5,700,1,14.65,100,1,12.46,200,2,14.68,700,1,12.43,700,1,14.72,200,2,12.42,700,1,14.81,200,2,ARL,285586225
574,2025-07-17T15:33:05.330688486Z,2025-07-17T15:33:05.330688486Z,10,2,1108,A,A,1,13.85,100,130,165731,240911093,13.26,100,1,13.84,100,1,13.23,2,1,13.85,100,1,13.03,100,1,14.02,2,1,12.73,100,1,14.12,100,1,12.71,100,1,14.56,800,2,12.65,200,2,14.6,700,1,12.5,700,1,14.61,100,1,12.46,200,2,14.65,100,1,12.43,700,1,14.68,700,1,12.42,700,1,14.72,200,2,ARL,286704785
575,2025-07-17T15:33:06.455814002Z,2025-07-17T15:33:06.455814002Z,10,2,1108,C,A,0,13.84,100,130,165268,240936407,13.26,100,1,13.85,100,1,13.23,2,1,14.02,2,1,13.03,100,1,14.12,100,1,12.73,100,1,14.56,800,2,12.71,100,1,14.6,700,1,12.65,200,2,14.61,100,1,12.5,700,1,14.65,100,1,12.46,200,2,14.68,700,1,12.43,700,1,14.72,200,2,12.42,700,1,14.81,200,2,ARL,286680685
576,2025-07-17T15:33:10.467840054Z,2025-07-17T15:33:10.467840054Z,10,2,1108,A,A,1,13.87,100,130,165288,241000095,13.26,100,1,13.85,100,1,13.23,2,1,13.87,100,1,13.03,100,1,14.02,2,1,12.73,100,1,14.12,100,1,12.71,100,1,14.56,800,2,12.65,200,2,14.6,700,1,12.5,700,1,14.61,100,1,12.46,200,2,14.65,100,1,12.43,700,1,14.68,700,1,12.42,700,1,14.72,200,2,ARL,286828253
577,2025-07-17T15:33:40.986420127Z,2025-07-17T15:33:40.986420127Z,10,2,1108,C,A,2,14.02,2,0,165676,241593788,13.26,100,1,13.85,100,1,13.23,2,1,13.87,100,1,13.03,100,1,14.12,100,1,12.73,100,1,14.56,800,2,12.71,100,1,14.6,700,1,12.65,200,2,14.61,100,1,12.5,700,1,14.65,100,1,12.46,200,2,14.68,700,1,12.43,700,1,14.72,200,2,12.42,700,1,14.81,200,2,ARL,283348193
578,2025-07-17T15:33:40.986420127Z,2025-07-17T15:33:40.986420127Z,10,2,1108,A,A,2,13.95,2,130,165676,241593788,13.26,100,1,13.85,100,1,13.23,2,1,13.87,100,1,13.03,100,1,13.95,2,1,12.73,100,1,14.12,100,1,12.71,100,1,14.56,800,2,12.65,200,2,14.6,700,1,12.5,700,1,14.61,100,1,12.46,200,2,14.65,100,1,12.43,700,1,14.68,700,1,12.42,700,1,14.72,200,2,ARL,287540393
579,2025-07-17T15:33:41.766018916Z,2025-07-17T15:33:41.766018916Z,10,2,1108,A,A,0,13.82,10,130,165655,241612289,13.26,100,1,13.82,10,1,13.23,2,1,13.85,100,1,13.03,100,1,13.87,100,1,12.73,100,1,13.95,2,1,12.71,100,1,14.12,100,1,12.65,200,2,14.56,800,2,12.5,700,1,14.6,700,1,12.46,200,2,14.61,100,1,12.43,700,1,14.65,100,1,12.42,700,1,14.68,700,1,ARL,287560109
580,2025-07-17T15:33:41.766100204Z,2025-07-17T15:33:41.766100204Z,10,2,1108,C,A,1,13.85,100,0,165499,241612294,13.26,100,1,13.82,10,1,13.23,2,1,13.87,100,1,13.03,100,1,13.95,2,1,12.73,100,1,14.12,100,1,12.71,100,1,14.56,800,2,12.65,200,2,14.6,700,1,12.5,700,1,14.61,100,1,12.46,200,2,14.65,100,1,12.43,700,1,14.68,700,1,12.42,700,1,14.72,200,2,ARL,286704785
581,2025-07-17T15:33:41.766100204Z,2025-07-17T15:33:41.766100204Z,10,2,1108,A,A,1,13.83,100,130,165499,241612294,13.26,100,1,13.82,10,1,13.23,2,1,13.83,100,1,13.03,100,1,13.87,100,1,12.73,100,1,13.95,2,1,12.71,100,1,14.12,100,1,12.65,200,2,14.56,800,2,12.5,700,1,14.6,700,1,12.46,200,2,14.61,100,1,12.43,700,1,14.65,100,1,12.42,700,1,14.68,700,1,ARL,287560121
582,2025-07-17T15:33:41.777239400Z,2025-07-17T15:33:41.777239400Z,10,2,1108,A,A,2,13.85,100,130,165266,241612426,13.26,100,1,13.82,10,1,13.23,2,1,13.83,100,1,13.03,100,1,13.85,100,1,12.73,100,1,13.87,100,1,12.71,100,1,13.95,2,1,12.65,200,2,14.12,100,1,12.5,700,1,14.56,800,2,12.46,200,2,14.6,700,1,12.43,700,1,14.61,100,1,12.42,700,1,14.65,100,1,ARL,287560333
583,2025-07-17T15:33:41.783955668Z,2025-07-17T15:33:41.783955668Z,10,2,1108,C,A,3,13.87,100,130,165363,241612450,13.26,100,1,13.82,10,1,13.23,2,1,13.83,100,1,13.03,100,1,13.85,100,1,12.73,100,1,13.95,2,1,12.71,100,1,14.12,100,1,12.65,200,2,14.56,800,2,12.5,700,1,14.6,700,1,12.46,200,2,14.61,100,1,12.43,700,1,14.65,100,1,12.42,700,1,14.68,700,1,ARL,286828253
584,2025-07-17T15:33:42.772976862Z,2025-07-17T15:33:42.772976862Z,10,2,1108,C,A,0,13.82,10,130,164913,241630390,13.26,100,1,13.83,100,1,13.23,2,1,13.85,100,1,13.03,100,1,13.95,2,1,12.73,100,1,14.12,100,1,12.71,100,1,14.56,800,2,12.65,200,2,14.6,700,1,12.5,700,1,14.61,100,1,12.46,200,2,14.65,100,1,12.43,700,1,14.68,700,1,12.42,700,1,14.72,200,2,ARL,287560109
585,2025-07-17T15:34:28.155608087Z,2025-07-17T15:34:28.155608087Z,10,2,1108,A,A,4,14.2,50,130,165473,242513312,13.26,100,1,13.83,100,1,13.23,2,1,13.85,100,1,13.03,100,1,13.95,2,1,12.73,100,1,14.12,100,1,12.71,100,1,14.2,50,1,12.65,200,2,14.56,800,2,12.5,700,1,14.6,700,1,12.46,200,2,14.61,100,1,12.43,700,1,14.65,100,1,12.42,700,1,14.68,700,1,ARL,288723725
586,2025-07-17T15:34:28.156649544Z,2025-07-17T15:34:28.156649544Z,10,2,1108,C,B,5,12.65,100,0,165513,242513329,13.26,100,1,13.83,100,1,13.23,2,1,13.85,100,1,13.03,100,1,13.95,2,1,12.73,100,1,14.12,100,1,12.71,100,1,14.2,50,1,12.65,100,1,14.56,800,2,12.5,700,1,14.6,700,1,12.46,200,2,14.61,100,1,12.43,700,1,14.65,100,1,12.42,700,1,14.68,700,1,ARL,236206261
587,2025-07-17T15:34:28.156719339Z,2025-07-17T15:34:28.156719339Z,10,2,1108,C,B,5,12.65,100,0,165561,242513330,13.26,100,1,13.83,100,1,13.23,2,1,13.85,100,1,13.03,100,1,13.95,2,1,12.73,100,1,14.12,100,1,12.71,100,1,14.2,50,1,12.5,700,1,14.56,800,2,12.46,200,2,14.6,700,1,12.43,700,1,14.61,100,1,12.42,700,1,14.65,100,1,12.37,700,1,14.68,700,1,ARL,236179089
588,2025-07-17T15:34:28.156719339Z,2025-07-17T15:34:28.156719339Z,10,2,1108,A,B,10,12.36,100,130,165561,242513330,13.26,100,1,13.83,100,1,13.23,2,1,13.85,100,1,13.03,100,1,13.95,2,1,12.73,100,1,14.12,100,1,12.71,100,1,14.2,50,1,12.5,700,1,14.56,800,2,12.46,200,2,14.6,700,1,12.43,700,1,14.61,100,1,12.42,700,1,14.65,100,1,12.37,700,1,14.68,700,1,ARL,288723817
